Workbook

Sheet Comparison
A1: Peer Comparison - Nebius vs CoreWeave, IREN (AI Cloud), Oracle OCI, Nscale, Lambda, Crusoe. Template KPI IDs/definitions (peers/coreweave/crwv_kpis.xlsx 'Definitions'; K41-K45 in peers/peer_kpi_template.py). Latest available period per peer; as-of shown per cell. Nebius cells are formulas on Nebius_Inputs. Private-peer values from peers/private/private_peers_values.json (Summary) with their tags. Built 2026-10-04 ET by peers/build_comparison.py.
A3: ID | B3: KPI | C3: Unit | D3: Nebius | E3: Tag | F3: As of | G3: CoreWeave | H3: Tag | I3: As of | J3: IREN | K3: Tag | L3: As of | M3: Oracle OCI | N3: Tag | O3: As of | P3: Nscale | Q3: Tag | R3: As of | S3: Lambda | T3: Tag | U3: As of | V3: Crusoe | W3: Tag | X3: As of | Y3: Peer median (formula; comparable peers) | Z3: Nebius better / worse | AA3: Reason (auto numbers + interpretation) | AB3: Nebius basis note | AC3: Peer basis comment
A4: K01 | B4: Revenue per active MW - period-end reported MW | C4: $M/MW-yr | D4: =Nebius_Inputs!$C$4*4/Nebius_Inputs!$C$20 -> 13.292486 | E4: E | F4: Jun-26 | G4: 6.8666667 | H4: Derived | I4: Jun-26 | J4: 7.0515 | K4: Derived | L4: Jun-26 | M4: n/d | N4: n/d | P4: 3.4716049 | Q4: D | R4: 2026-06-30 | S4: 9.7021277 | T4: D (inputs P) | U4: 2025-06-30 | V4: 2 | W4: E (inputs P/R) | X4: 2026-09-17 | Y4: =MEDIAN(G4,J4,P4,S4,V4) -> 6.8666667 | Z4: Better | AA4: Nebius 13.29 vs peer median 6.87 (range Crusoe 2.00 - Lambda 9.70; n=5); higher revenue density per energized MW (Nebius MW is a Capacity estimate; mixed IT/gross basis) | AB4: Q2'26 AI cloud rev x4 / Jun-26 energized MW (173, Capacity est.) | AC4: Basis differs: CRWV IT-like active MW; IREN 40 MW AI (basis unstated); Oracle no installed MW; Nscale IT MW at 5 active sites (H1'26 x2); Lambda Q2'25 (press MW); Crusoe FY26E rev / ~1 GW GROSS.
A5: K02 | B5: Revenue per active MW - average MW (2024 uses interpolated MW) | C5: $M/MW-yr | D5: =Nebius_Inputs!$C$4*4/AVERAGE(Nebius_Inputs!$C$19,Nebius_Inputs!$C$20) -> 13.350363 | E5: E | F5: Jun-26 | G5: 8.24 | H5: Derived | I5: Jun-26 | J5: 10.476822 | K5: Estimated | L5: Sep-25 | M5: n/d | N5: n/d | P5: n/d | Q5: n/d | S5: n/d | T5: n/d | V5: n/d | W5: n/d | Y5: =MEDIAN(G5,J5) -> 9.358411 | Z5: Better | AA5: Nebius 13.35 vs peer median 9.36 (range CoreWeave 8.24 - IREN 10.48; n=2); same on average MW - the fixed, comparable figure; Blackwell-heavy, mostly new fleet lifts density | AB5: FIXED: average MW (171.5+173)/2, replaces old 13.7 on stale YE25 170 MW
A6: K02b | B6: Revenue per BILLING IT MW - average MW (Capacity billing path) | C6: $M/MW-yr | D6: =Nebius_Inputs!$C$4*4/AVERAGE(Nebius_Inputs!$C$42,Nebius_Inputs!$C$43) -> 13.055524 | E6: E | F6: Jun-26 | G6: =G5 -> 8.24 | H6: Derived | I6: Jun-26 | J6: n/d | K6: n/d | M6: n/d | N6: n/d | P6: n/d | Q6: n/d | S6: n/d | T6: n/d | V6: n/d | W6: n/d | Y6: =G6 -> 8.24 | Z6: Better | AA6: Nebius billed-IT basis (Capacity) vs CoreWeave active (≈billed); other peers n/d billed MW | AB6: NEW: billed-IT twin of K02 for slide alignment with Street $/billed MW test
A7: K03 | B7: Revenue per contracted MW | C7: $M/MW-yr | D7: =Nebius_Inputs!$C$4*4/Nebius_Inputs!$C$22 -> 0.65702857 | E7: D | F7: Jun-26 | G7: 2.7837838 | H7: Derived | I7: Jun-26 | J7: n/d | K7: n/d | M7: n/d | N7: n/d | P7: 0.20525547 | Q7: D | R7: 2026-08-31 | S7: n/d | T7: n/d | V7: 0.33333333 | W7: E (inputs P/R) | X7: 2026-09-17 | Y7: =MEDIAN(G7,P7,V7) -> 0.33333333 | Z7: Better | AA7: Nebius 0.66 vs peer median 0.33 (range Nscale 0.21 - CoreWeave 2.78; n=3); monetises contracted power faster? Nebius has far more unbuilt contracted MW than CRWV | AB7: >3.5 GW is a lower bound -> value is an upper bound
A8: K04 | B8: Contracted / active MW (build-out multiple) | C8: x | D8: =Nebius_Inputs!$C$22/Nebius_Inputs!$C$20 -> 20.231214 | E8: E | F8: Jun-26 | G8: 2.4666667 | H8: Derived | I8: Jun-26 | J8: n/d | K8: n/d | M8: n/d | N8: n/d | P8: 16.91358 | Q8: D | R8: 2026-08-31 | S8: n/d | T8: n/d | V8: 6 | W8: D | X8: 2026-09-17 | Y8: =MEDIAN(G8,P8,V8) -> 6 | Z8: Context | AA8: Nebius 20.23 vs peer median 6.00 (range CoreWeave 2.47 - Nscale 16.91; n=3); build-out multiple: big growth runway but heavy execution/funding need (context, not scored)
A9: K05 | B9: Adj. EBITDA per active MW (average MW) | C9: $M/MW-yr | D9: =Nebius_Inputs!$C$7*4/AVERAGE(Nebius_Inputs!$C$19,Nebius_Inputs!$C$20) -> 6.6345428 | E9: E | F9: Jun-26 | G9: 4.832 | H9: Derived | I9: Jun-26 | J9: n/d | K9: n/d | M9: n/d | N9: n/d | P9: -4.9185185 | Q9: D | R9: 2026-06-30 | S9: n/d | T9: n/d | V9: n/d | W9: n/d | Y9: =MEDIAN(G9,P9) -> -0.043259259 | Z9: Better | AA9: Nebius 6.63 vs peer median -0.04 (range Nscale -4.92 - CoreWeave 4.83; n=2); segment adj. EBITDA per MW well above CRWV-style peers | AB9: AI cloud segment adj. EBITDA
A10: K06 | B10: Revenue per GPU ($K per GPU-year, avg GPUs) | C10: $K/GPU-yr | D10: =Nebius_Inputs!$C$4*4000/Nebius_Inputs!$C$23 -> 28.727943 | E10: E | F10: Jun-26 | G10: 14.506634 | H10: Estimated | I10: Jun-26 | J10: 14.694 | K10: Derived | L10: Sep-25 | M10: n/d | N10: n/d | P10: 11.248 | Q10: E | R10: 2026-06-30 | S10: 18.24 | T10: E (inputs P/R) | U10: 2025-06-30 | V10: n/d | W10: n/d | Y10: =MEDIAN(G10,J10,P10,S10) -> 14.600317 | Z10: Better | AA10: Nebius 28.73 vs peer median 14.60 (range Nscale 11.25 - Lambda 18.24; n=4); revenue per (modeled) GPU | AB10: modeled GPUs | AC10: IREN latest Q3'25. Lambda/Nscale ESTIMATED from GPU counts.
A11: K07 | B11: Implied blended realized price ($/GPU-hr) | C11: $/GPU-hr | D11: =Nebius_Inputs!$C$4*1000000/(Nebius_Inputs!$C$23*Nebius_Inputs!$C$24*24) -> 3.288455 | E11: E | F11: Jun-26 | G11: 1.6605579 | H11: Estimated | I11: Jun-26 | J11: 1.6637228 | K11: Derived | L11: Sep-25 | M11: n/d | N11: n/d | P11: 1.2946593 | Q11: E | R11: 2026-06-30 | S11: 2.0879121 | T11: E (inputs P/R) | U11: 2025-06-30 | V11: n/d | W11: n/d | Y11: =MEDIAN(G11,J11,P11,S11) -> 1.6621404 | Z11: Better | AA11: Nebius 3.29 vs peer median 1.66 (range Nscale 1.29 - Lambda 2.09; n=4); realized $/GPU-hr above peers (modeled GPU base; includes non-GPU revenue) | AB11: incl. non-GPU-hour revenue | AC11: Nebius realized $3.29 includes non-GPU-hour revenue and uses modeled GPUs.
A12: K08 | B12: Fleet-weighted on-demand list price ($/GPU-hr) | C12: $/GPU-hr | D12: =Nebius_Inputs!$C$25 -> 5.5710951 | E12: E | F12: Jun-26 | G12: 9.1956182 | H12: Estimated | I12: Jun-26 | J12: 2 | K12: Estimated | L12: Sep-25 | M12: n/d | N12: n/d | P12: n/d | Q12: n/d | S12: 2.99 | T12: R | U12: 2025-06-16 | V12: 3.9 | W12: R | X12: 2026-10-04 | Y12: =MEDIAN(G12,J12,S12,V12) -> 3.445 | Z12: Context | AA12: Nebius 5.57 vs peer median 3.45 (range IREN 2.00 - CoreWeave 9.20; n=4); list-price context
A13: K09 | B13: Implied utilization (realized $/GPU-hr / weighted list) | C13: % | D13: =Nebius_Inputs!$C$4*1000000/(Nebius_Inputs!$C$23*Nebius_Inputs!$C$24*24)/Nebius_Inputs!$C$25*100 -> 59.027084 | E13: E | F13: Jun-26 | G13: 18.058143 | H13: Estimated | I13: Jun-26 | J13: 83.186141 | K13: Estimated | L13: Sep-25 | M13: n/d | N13: n/d | P13: n/d | Q13: n/d | S13: 69.829836 | T13: E (inputs P/R) | U13: 2025-06-30 | V13: n/d | W13: n/d | Y13: =MEDIAN(G13,S13) -> 43.943989 | Z13: Better | AA13: Nebius 59.03 vs peer median 43.94 (range CoreWeave 18.06 - Lambda 69.83; n=2); price-based 'utilization' (mixes discount with use); not physical utilization | AC13: Not like-for-like (see NONCOMP list in README).; Excluded from median: IREN: vs IREN's own $2.00 assumption, not list
A14: K10 | B14: Cash capex per new active MW (reported MW) | C14: $M/MW | D14: n.m. | E14: n.m. | F14: Jun-26 | G14: 12.844 | H14: Derived | I14: Jun-26 | J14: n/d | K14: n/d | M14: 56.872414 | N14: Estimated | O14: May-26 (FQ4 FY26) | P14: n/d | Q14: n/d | S14: n/d | T14: n/d | V14: n/d | W14: n/d | Y14: =MEDIAN(G14,M14) -> 34.858207 | Z14: n/a | AA14: Nebius n/d. single-quarter capex/MW not meaningful for Nebius (+1.5 MW) | AB14: MW added in Q2'26 only +1.5 (Capacity est.) -> not meaningful
A15: K12 | B15: In-service additions per new active MW (CRWV capex definition) | C15: $M/MW | D15: =(Nebius_Inputs!$C$39-Nebius_Inputs!$C$38)/(Nebius_Inputs!$C$41-Nebius_Inputs!$C$40) -> 19.68069 | E15: E | F15: Dec-25 (FY25) | G15: 18.704 | H15: Derived | I15: Jun-26 | J15: n/d | K15: n/d | M15: n/d | N15: n/d | P15: n/d | Q15: n/d | S15: n/d | T15: n/d | V15: n/d | W15: n/d | Y15: =MEDIAN(G15) -> 18.704 | Z15: In line | AA15: Nebius 19.68 vs peer median 18.70 (range CoreWeave 18.70 - CoreWeave 18.70; n=1); in-service $ per MW added (FY25 basis for Nebius) | AB15: FY25 basis; quarterly n.m.
A16: K13 | B16: Trailing-4Q cash capex per trailing-4Q new active MW | C16: $M/MW | D16: =SUM(Nebius_Inputs!$C$9,Nebius_Inputs!$C$10,Nebius_Inputs!$C$11,Nebius_Inputs!$C$12)/(Nebius_Inputs!$C$20-Nebius_Inputs!$C$18) -> 87.045312 | E16: E | F16: Jun-26 | G16: 19.966602 | H16: Derived | I16: Jun-26 | J16: n/d | K16: n/d | M16: 46.385833 | N16: Estimated | O16: May-26 (FQ4 FY26) | P16: n/d | Q16: n/d | S16: n/d | T16: n/d | V16: n/d | W16: n/d | Y16: =MEDIAN(G16,M16) -> 33.176218 | Z16: Worse | AA16: Nebius 87.05 vs peer median 33.18 (range CoreWeave 19.97 - Oracle OCI 46.39; n=2); capex per MW added is high because capex funds 2027 capacity (not-yet-in-use $7.8B) | AB16: capex funds future (not-yet-in-use) capacity -> inflated | AC16: Oracle FY26 capex / delivered MW (E). Nscale/Lambda/Crusoe n/d.
A17: K14 | B17: Net PP&E per active MW (EoP) | C17: $M/MW | D17: =Nebius_Inputs!$C$13/Nebius_Inputs!$C$20 -> 75.40578 | E17: E | F17: Jun-26 | G17: 31.157333 | H17: Derived | I17: Jun-26 | J17: n/d | K17: n/d | M17: n/d | N17: n/d | P17: 70.709877 | Q17: D | R17: 2026-06-30 | S17: n/d | T17: n/d | V17: 12.5 | W17: D | X17: 2025-05-21 | Y17: =MEDIAN(G17,P17) -> 50.933605 | Z17: Worse | AA17: Nebius 75.41 vs peer median 50.93 (range CoreWeave 31.16 - Nscale 70.71; n=2); net PP&E per active MW inflated by construction-in-progress | AB17: incl. $7.8B not yet in use | AC17: Crusoe 12.5 = Abilene JV shell+power only (excluded from median).; Excluded from median: Crusoe: shell+power only (ex-GPU)
A18: K15 | B18: Gross in-service PP&E per active MW (EoP) | C18: $M/MW | D18: =Nebius_Inputs!$C$15/Nebius_Inputs!$C$20 -> 36.491908 | E18: E | F18: Jun-26 | G18: 27.136 | H18: Derived | I18: Jun-26 | J18: n/d | K18: n/d | M18: n/d | N18: n/d | P18: 20.825926 | Q18: D | R18: 2026-06-30 | S18: n/d | T18: n/d | V18: n/d | W18: n/d | Y18: =MEDIAN(G18,P18) -> 23.980963 | Z18: Worse | AA18: Nebius 36.49 vs peer median 23.98 (range Nscale 20.83 - CoreWeave 27.14; n=2); gross in-service PP&E per MW
A19: K16 | B19: Useful life - technology equipment (GPUs/servers/network) | C19: years | D19: =Nebius_Inputs!$C$32 -> 5 | E19: R | F19: Jun-26 | G19: 6 | H19: Reported | I19: Jun-26 | J19: 5 | K19: Reported | L19: Jun-26 | M19: 6 | N19: Reported | O19: May-26 (FQ4 FY26) | P19: 5.5 | Q19: R | R19: 2026-06-30 | S19: n/d | T19: n/d | V19: n/d | W19: n/d | Y19: =MEDIAN(G19,J19,M19,P19) -> 5.75 | Z19: Better | AA19: Nebius 5.00 vs peer median 5.75 (range IREN 5.00 - CoreWeave 6.00; n=4); shorter life = more conservative accounting (Nebius moved 4->5 yrs in 2026; CRWV/Oracle 6) | AC19: Lives: CRWV 6, Oracle 6, Nscale 5-6, IREN 5, Nebius 5 (from 2026).
A20: K17 | B20: Depreciation yield (D&A x4 / avg in-service gross PP&E) | C20: % | D20: =Nebius_Inputs!$C$8*4/AVERAGE(Nebius_Inputs!$C$14,Nebius_Inputs!$C$15)*100 -> 17.515048 | E20: D | F20: Jun-26 | G20: 15.465749 | H20: Derived | I20: Jun-26 | J20: 14.351359 | K20: Derived | L20: Jun-26 | M20: 13.449246 | N20: Derived | O20: Aug-26 (FQ1 FY27) | P20: 15.670891 | Q20: D | R20: 2026-06-30 | S20: n/d | T20: n/d | V20: n/d | W20: n/d | Y20: =MEDIAN(G20,J20,M20,P20) -> 14.908554 | Z20: Better | AA20: Nebius 17.52 vs peer median 14.91 (range Oracle OCI 13.45 - Nscale 15.67; n=4); higher depreciation yield = more conservative | AB20: group D&A incl. amortization | AC20: IREN incl. mining hardware; Oracle Aug-26 quarter; Nscale H1'26.
A21: K18 | B21: Implied average depreciable life (1 / yield) | C21: years | D21: =100/(Nebius_Inputs!$C$8*4/AVERAGE(Nebius_Inputs!$C$14,Nebius_Inputs!$C$15)*100) -> 5.7093762 | E21: D | F21: Jun-26 | G21: 6.4659009 | H21: Derived | I21: Jun-26 | J21: 6.967981 | K21: Derived | L21: Jun-26 | M21: 7.4353612 | N21: Derived | O21: Aug-26 (FQ1 FY27) | P21: 6.381258 | Q21: D | R21: 2026-06-30 | S21: n/d | T21: n/d | V21: n/d | W21: n/d | Y21: =MEDIAN(G21,J21,M21,P21) -> 6.716941 | Z21: Better | AA21: Nebius 5.71 vs peer median 6.72 (range Nscale 6.38 - Oracle OCI 7.44; n=4); lower implied life = more conservative
A22: K19 | B22: D&A as % of revenue | C22: % | D22: =Nebius_Inputs!$C$8/Nebius_Inputs!$C$4*100 -> 45.173074 | E22: D | F22: Jun-26 | G22: 54.097087 | H22: Derived | I22: Jun-26 | J22: 81.677537 | K22: Derived | L22: Jun-26 | M22: 12.588616 | N22: Derived | O22: May-26 (FQ4 FY26) | P22: 123.75533 | Q22: D | R22: 2026-06-30 | S22: n/d | T22: n/d | V22: n/d | W22: n/d | Y22: =MEDIAN(G22,J22,M22,P22) -> 67.887312 | Z22: Context | AA22: Nebius 45.17 vs peer median 67.89 (range Oracle OCI 12.59 - Nscale 123.76; n=4); D&A burden context | AB22: group D&A / AI cloud revenue
A23: K20 | B23: RPO (ASC 606, EoP) | C23: $B | D23: =Nebius_Inputs!$C$26/1000 -> 37.4906 | E23: R | F23: Jun-26 | G23: 103.7 | H23: Reported | I23: Jun-26 | J23: 5.1 | K23: Reported | L23: Jun-26 | M23: 638 | N23: Reported | O23: May-26 (FQ4 FY26) | P23: 56.4 | Q23: R | R23: 2026-06-30 | S23: n/d | T23: n/d | V23: n/d | W23: n/d | Y23: =MEDIAN(G23,J23,M23,P23) -> 80.05 | Z23: Context | AA23: Nebius 37.49 vs peer median 80.05 (range IREN 5.10 - Oracle OCI 638.00; n=4); absolute size context | AC23: Oracle RPO is company-wide incl. SaaS.
A24: K21 | B24: Revenue backlog (company metric, EoP) | C24: $B | D24: n/d | E24: n/d | G24: 104.2 | H24: Reported | I24: Jun-26 | J24: 16.6 | K24: Reported | L24: Jun-26 | M24: n/d | N24: n/d | P24: 103.4 | Q24: R | R24: 2026-08-31 | S24: n/d | T24: n/d | V24: 140 | W24: R | X24: 2026-09-17 | Y24: =MEDIAN(G24,J24,P24) -> 103.4 | Z24: n/a | AA24: Nebius n/d. company backlog metric (context) | AB24: Not disclosed in Nebius filings / not computable on the same definition | AC24: Crusoe/Nscale company TCV metrics (not ASC 606).; Excluded from median: Crusoe: company TCV metric
A25: K22 | B25: RPO % recognized within 24 months | C25: % | D25: =Nebius_Inputs!$C$27 -> 36 | E25: R | F25: Jun-26 | G25: 41 | H25: Reported | I25: Jun-26 | J25: 43.1 | K25: Derived | L25: Jun-26 | M25: 29 | N25: Estimated | O25: May-26 (FQ4 FY26) | P25: 16 | Q25: R | R25: 2025-12-31 | S25: n/d | T25: n/d | V25: n/d | W25: n/d | Y25: =MEDIAN(G25,J25,M25,P25) -> 35 | Z25: In line | AA25: Nebius 36.00 vs peer median 35.00 (range Nscale 16.00 - IREN 43.10; n=4); share of RPO converting within 24m
A26: K23 | B26: RPO / annualized quarterly revenue | C26: years | D26: =Nebius_Inputs!$C$26/(Nebius_Inputs!$C$4*4) -> 16.303096 | E26: D | F26: Jun-26 | G26: 10.067961 | H26: Derived | I26: Jun-26 | J26: 18.081259 | K26: Derived | L26: Jun-26 | M26: 8.3142202 | N26: Derived | O26: May-26 (FQ4 FY26) | P26: 200.56899 | Q26: D | R26: 2026-06-30 | S26: n/d | T26: n/d | V26: n/d | W26: n/d | Y26: =MEDIAN(G26,J26,M26,P26) -> 14.07461 | Z26: In line | AA26: Nebius 16.30 vs peer median 14.07 (range Oracle OCI 8.31 - Nscale 200.57; n=4); backlog coverage of current run-rate | AC26: Nscale 201 yrs: tiny H1'26 revenue vs $56.4B RPO (pre-ramp).
A27: K24 | B27: Largest customer % of revenue | C27: % | D27: =Nebius_Inputs!$C$28 -> 24 | E27: R | F27: Jun-26 | G27: 36 | H27: Reported | I27: Jun-26 | J27: n/d | K27: n/d | M27: n/d | N27: n/d | P27: 52 | Q27: R | R27: 2026-06-30 | S27: n/d | T27: n/d | V27: n/d | W27: n/d | Y27: =MEDIAN(G27,P27) -> 44 | Z27: Better | AA27: Nebius 24.00 vs peer median 44.00 (range CoreWeave 36.00 - Nscale 52.00; n=2); lower concentration is better | AB27: Customer C (unnamed) | AC27: Nscale H1'26 largest customer 52%. Lambda: Amazon+Microsoft 50% (K26, press).
A28: K25 | B28: 2nd-largest customer % | C28: % | D28: =Nebius_Inputs!$C$29 -> 21 | E28: R | F28: Jun-26 | G28: 26 | H28: Reported | I28: Jun-26 | J28: n/d | K28: n/d | M28: n/d | N28: n/d | P28: n/d | Q28: n/d | S28: n/d | T28: n/d | V28: n/d | W28: n/d | Y28: =MEDIAN(G28) -> 26 | Z28: Better | AA28: Nebius 21.00 vs peer median 26.00 (range CoreWeave 26.00 - CoreWeave 26.00; n=1); lower is better
A29: K26 | B29: Top-N >=10% customers combined % | C29: % | D29: =Nebius_Inputs!$C$28+Nebius_Inputs!$C$29+Nebius_Inputs!$C$30 -> 59 | E29: R | F29: Jun-26 | G29: 72 | H29: Reported | I29: Jun-26 | J29: n/d | K29: n/d | M29: n/d | N29: n/d | P29: n/d | Q29: n/d | S29: 50 | T29: P | U29: 2025-06-30 | V29: n/d | W29: n/d | Y29: =MEDIAN(G29,S29) -> 61 | Z29: In line | AA29: Nebius 59.00 vs peer median 61.00 (range Lambda 50.00 - CoreWeave 72.00; n=2); lower combined concentration is better
A30: K27 | B30: Number of customers >=10% of revenue | C30: # | D30: =Nebius_Inputs!$C$31 -> 3 | E30: R | F30: Jun-26 | G30: 3 | H30: Reported | I30: Jun-26 | J30: n/d | K30: n/d | M30: 0 | N30: Reported | O30: May-26 (FQ4 FY26) | P30: n/d | Q30: n/d | S30: n/d | T30: n/d | V30: n/d | W30: n/d | Y30: =MEDIAN(G30,M30) -> 1.5 | Z30: Worse | AA30: Nebius 3.00 vs peer median 1.50 (range Oracle OCI 0.00 - CoreWeave 3.00; n=2); fewer >=10% customers is better
A31: K28 | B31: Weighted effective cost of debt (principal-weighted, EoP) - all facilities | C31: % | D31: =Nebius_Inputs!$C$33 -> 5.1 | E31: D | F31: Jun-26 | G31: 8.4134342 | H31: Derived | I31: Jun-26 | J31: 1.8523437 | K31: Derived | L31: Jun-26 | M31: 4.8282005 | N31: Derived | O31: May-26 (FQ4 FY26) | P31: 18.726841 | Q31: D | R31: 2026-06-30 | S31: n/d | T31: n/d | V31: n/d | W31: n/d | Y31: =MEDIAN(G31,J31,M31) -> 4.8282005 | Z31: In line | AA31: Nebius 5.10 vs peer median 4.83 (range IREN 1.85 - CoreWeave 8.41; n=3); cheaper debt (converts-heavy) is better | AC31: Nscale 18.7% on legacy $137M (excluded from median); marginal secured: Nscale ~6.25% E, Lambda 6.78% R, Crusoe ~9.1% E (PX09).; Excluded from median: Nscale: legacy $137M debt; marginal secured ~6.25% E (PX09)
A32: K29 | B32: of which DDTL - weighted eff. rate | C32: % | D32: n/d | E32: n/d | G32: 9.6234699 | H32: Derived | I32: Jun-26 | J32: 7.12 | K32: Derived | L32: Jun-26 | M32: n/d | N32: n/d | P32: 11.3 | Q32: R | R32: 2026-06-30 | S32: 6.78 | T32: R | U32: 2026-10-01 | V32: 9.1021429 | W32: E (inputs P) | X32: 2026-09-10 | Y32: =MEDIAN(G32,J32,P32,S32,V32) -> 9.1021429 | Z32: n/a | AA32: Nebius n/d. facility-level rate (context) | AB32: Not disclosed in Nebius filings / not computable on the same definition
A33: K34 | B33: of which Other term loans - weighted eff. rate | C33: % | D33: n/d | E33: n/d | G33: 12 | H33: Derived | I33: Jun-26 | J33: n/d | K33: n/d | M33: 5.29 | N33: Derived | O33: May-26 (FQ4 FY26) | P33: 22.74 | Q33: R | R33: 2026-06-30 | S33: n/d | T33: n/d | V33: 6 | W33: P | X33: 2026-02-20 | Y33: =MEDIAN(G33,M33,P33,V33) -> 9 | Z33: n/a | AA33: Nebius n/d. facility-level rate (context) | AB33: Not disclosed in Nebius filings / not computable on the same definition
A34: K35 | B34: DDTL (secured asset-level) share of principal | C34: % | D34: n/d | E34: n/d | G34: 38.375854 | H34: Derived | I34: Jun-26 | J34: 5.3597043 | K34: Derived | L34: Jun-26 | M34: 0 | N34: Derived | O34: May-26 (FQ4 FY26) | P34: 35.080058 | Q34: D | R34: 2026-06-30 | S34: n/d | T34: n/d | V34: n/d | W34: n/d | Y34: =MEDIAN(G34,J34,M34,P34) -> 20.219881 | Z34: n/a | AA34: Nebius n/d. structure context | AB34: Not disclosed in Nebius filings / not computable on the same definition
A35: K36 | B35: Implied cash cost: contractual interest x4 / avg principal | C35: % | D35: =Nebius_Inputs!$C$34*4/AVERAGE(Nebius_Inputs!$C$36,Nebius_Inputs!$C$37)*100 -> 5.605992 | E35: D | F35: Jun-26 | G35: 7.8023064 | H35: Derived | I35: Jun-26 | J35: 1.7092136 | K35: Derived | L35: Jun-26 | M35: 4.3551672 | N35: Derived | O35: May-26 (FQ4 FY26) | P35: 22.191401 | Q35: D | R35: 2026-06-30 | S35: n/d | T35: n/d | V35: n/d | W35: n/d | Y35: =MEDIAN(G35,J35,M35,P35) -> 6.0787368 | Z35: In line | AA35: Nebius 5.61 vs peer median 6.08 (range IREN 1.71 - Nscale 22.19; n=4); lower cash cost of debt is better | AB35: P&L interest (incl. convert accretion) / avg carrying debt | AC35: IREN finance expense incl. amortization; Oracle interest/avg carrying.
A36: K37 | B36: Company-reported weighted average interest rate | C36: % | D36: n/d | E36: n/d | G36: 8.3 | H36: Reported | I36: Jun-26 | J36: n/d | K36: n/d | M36: n/d | N36: n/d | P36: n/d | Q36: n/d | S36: n/d | T36: n/d | V36: n/d | W36: n/d | Y36: =MEDIAN(G36) -> 8.3 | Z36: n/a | AA36: Nebius n/d. company-reported rate | AB36: Not disclosed in Nebius filings / not computable on the same definition
A37: K38 | B37: Total debt principal (EoP) | C37: $B | D37: =Nebius_Inputs!$C$37/1000 -> 8.5457 | E37: R | F37: Jun-26 | G37: 35.551 | H37: Reported | I37: Jun-26 | J37: 7.705649 | K37: Reported | L37: Jun-26 | M37: 129.541 | N37: Reported | O37: May-26 (FQ4 FY26) | P37: 0.1374 | Q37: D | R37: 2026-06-30 | S37: n/d | T37: n/d | V37: n/d | W37: n/d | Y37: =MEDIAN(G37,J37,M37,P37) -> 21.628325 | Z37: Context | AA37: Nebius 8.55 vs peer median 21.63 (range Nscale 0.14 - Oracle OCI 129.54; n=4); size context | AB37: carrying value (not principal)
A38: K39 | B38: Debt principal / RPO | C38: x | D38: =Nebius_Inputs!$C$37/Nebius_Inputs!$C$26 -> 0.22794247 | E38: D | F38: Jun-26 | G38: 0.34282546 | H38: Derived | I38: Jun-26 | J38: 1.5109116 | K38: Derived | L38: Jun-26 | M38: 0.20304232 | N38: Derived | O38: May-26 (FQ4 FY26) | P38: 0.0024361702 | Q38: D | R38: 2026-06-30 | S38: n/d | T38: n/d | V38: n/d | W38: n/d | Y38: =MEDIAN(G38,J38,M38,P38) -> 0.27293389 | Z38: In line | AA38: Nebius 0.23 vs peer median 0.27 (range Nscale 0.00 - IREN 1.51; n=4); lower debt per $ of backlog is better
A39: K40 | B39: Capitalized interest % of contractual interest | C39: % | D39: =Nebius_Inputs!$C$35/(Nebius_Inputs!$C$34+Nebius_Inputs!$C$35)*100 -> 25.235405 | E39: D | F39: Jun-26 | G39: 13.344595 | H39: Reported | I39: Jun-26 | J39: n/d | K39: n/d | M39: n/d | N39: n/d | P39: 0 | Q39: D | R39: 2026-06-30 | S39: n/d | T39: n/d | V39: n/d | W39: n/d | Y39: =MEDIAN(G39,P39) -> 6.6722973 | Z39: Worse | AA39: Nebius 25.24 vs peer median 6.67 (range Nscale 0.00 - CoreWeave 13.34; n=2); high capitalized share flatters P&L interest
A40: K41 | B40: Company-reported GPU utilization (physical) | C40: % | D40: n/d | E40: n/d | G40: n/d | H40: n/d | J40: n/d | K40: n/d | M40: 97.5 | N40: Reported | O40: May-26 (FQ4 FY26) | P40: n/d | Q40: n/d | S40: n/d | T40: n/d | V40: n/d | W40: n/d | Y40: =MEDIAN(M40) -> 97.5 | Z40: n/a | AA40: Nebius n/d. physical utilization (Oracle only) | AB40: Not disclosed in Nebius filings / not computable on the same definition
A41: K42 | B41: RPO % recognized within 12 months | C41: % | D41: n/d | E41: n/d | G41: n/d | H41: n/d | J41: 17.6 | K41: Derived | L41: Jun-26 | M41: 12 | N41: Reported | O41: May-26 (FQ4 FY26) | P41: n/d | Q41: n/d | S41: n/d | T41: n/d | V41: n/d | W41: n/d | Y41: =MEDIAN(J41,M41) -> 14.8 | Z41: n/a | AA41: Nebius n/d. n/d for Nebius (24m bucket only) | AB41: Not disclosed in Nebius filings / not computable on the same definition
...

Sheet README
A1: Peer comparison workbook (step 5, final) - built 2026-10-04 ET by /workspace/nebius/peers/build_comparison.py
A2: Tabs: Comparison (7 companies x 40 template KPIs, value/tag/as-of, peer median, Nebius better/worse + reason) | Ranking | Nebius_Inputs (sources; Comparison Nebius cells are live formulas) | Contracts_$MWyr | Sites | Chart_Data + Charts (native Excel) | Peer_memos.
A3: Tags: R Reported, P Press-reported (new, private peers), D Derived, E Estimated, n/d not disclosed, n.m. not meaningful. Derived tag = weakest input. Private-peer composite tags kept verbatim.
A4: Nebius rev/MW FIX: old Comparison K01 13.7 = Q2'26 group revenue x4 / YE25 170 MW (stale). Now K01 = AI cloud revenue x4 / Jun-26 energized 173 MW = 13.29 E and K02 = x4 / AVERAGE(171.5, 173) = 13.35 E (Capacity & Power base case incl. plug; identified sites 152-194 at Jun-26). Same definitions as peers' K01/K02.
A5: Inputs read (not edited): peers/coreweave|iren|oracle/*_kpis.xlsx; peers/private/private_peers_values.json; parts/contract_economics.xlsx (GPU Market agent's contract table - market/ and nebius_market.xlsx hold no contract data); filings/nebius_filings.xlsx + nebius_kpi_history.xlsx; shared/findings_log.xlsx; capacity/nebius_capacity.xlsx + site_list.xlsx + site_verification.md; peers/sites/sites.xlsx + site_verification.md.
A6: Charts: PNGs in /workspace/nebius/peers/charts/ (peers/build_charts.py reads this workbook's recalculated values).
A7: Recalc: python3 /workspace/nebius/model/recalc.py peers/comparison.xlsx (LibreOffice) -> copy /tmp/rc/comparison.xlsx back; 0 errors required.
A9: K02b ADDED 2026-10-05 (Peer KPIs): Revenue per average BILLING IT MW. Nebius uses Capacity billing path (Q1/Q2'26). CoreWeave active≈billed so K02b=K02. Microsoft ACV: quote $11.6 / ~$14.5 / $17.1 (stated / gross-read / GPU-derived) — see Nebius_Inputs NOTE_1417 and peers/price_or_mw.xlsx Nebius_Check.

Sheet Ranking
A1: Where Nebius is better / worse - ranked by signed gap vs comparable-peer median (positive = favourable to Nebius). Context and n/a rows listed last.
A3: Rank | B3: ID | C3: KPI | D3: Flag | E3: Nebius | F3: Peer median | G3: Signed gap % (favourable +; vs max(|median|, mean |peer|), computed at build) | H3: Reason
A4: 1 | B4: K05 | C4: Adj. EBITDA per active MW (average MW) | D4: =Comparison!Z9 -> Better | E4: =Comparison!D9 -> 6.6345428 | F4: =Comparison!Y9 -> -0.043259259 | G4: 137 | H4: Nebius 6.63 vs peer median -0.04 (range Nscale -4.92 - CoreWeave 4.83; n=2); segment adj. EBITDA per MW well above CRWV-style peers
A5: 2 | B5: K43 | C5: Incremental annualized revenue per incremental MW (YoY) | D5: =Comparison!Z42 -> Better | E5: =Comparison!D42 -> 15.0375 | F5: =Comparison!Y42 -> 6.8088018 | G5: 115.3 | H5: Nebius 15.04 vs peer median 6.81 (range CoreWeave 5.29 - Oracle OCI 9.31; n=3); marginal revenue per new MW
A6: 3 | B6: K07 | C6: Implied blended realized price ($/GPU-hr) | D6: =Comparison!Z11 -> Better | E6: =Comparison!D11 -> 3.288455 | F6: =Comparison!Y11 -> 1.6621404 | G6: 97 | H6: Nebius 3.29 vs peer median 1.66 (range Nscale 1.29 - Lambda 2.09; n=4); realized $/GPU-hr above peers (modeled GPU base; includes non-GPU revenue)
A7: 4 | B7: K06 | C7: Revenue per GPU ($K per GPU-year, avg GPUs) | D7: =Comparison!Z10 -> Better | E7: =Comparison!D10 -> 28.727943 | F7: =Comparison!Y10 -> 14.600317 | G7: 96.3 | H7: Nebius 28.73 vs peer median 14.60 (range Nscale 11.25 - Lambda 18.24; n=4); revenue per (modeled) GPU
A8: 5 | B8: K01 | C8: Revenue per active MW - period-end reported MW | D8: =Comparison!Z4 -> Better | E8: =Comparison!D4 -> 13.292486 | F8: =Comparison!Y4 -> 6.8666667 | G8: 93.6 | H8: Nebius 13.29 vs peer median 6.87 (range Crusoe 2.00 - Lambda 9.70; n=5); higher revenue density per energized MW (Nebius MW is a Capacity estimate; mixed IT/gross basis)
A9: 6 | B9: K44 | C9: Annualized revenue / avg gross GPU-compute hardware in service | D9: =Comparison!Z43 -> Better | E9: =Comparison!D43 -> 0.46501658 | F9: =Comparison!Y43 -> 0.26948927 | G9: 72.6 | H9: Nebius 0.47 vs peer median 0.27 (range IREN 0.20 - CoreWeave 0.34; n=2); asset turn on GPU hardware
A10: 7 | B10: K24 | C10: Largest customer % of revenue | D10: =Comparison!Z27 -> Better | E10: =Comparison!D27 -> 24 | F10: =Comparison!Y27 -> 44 | G10: 45.5 | H10: Nebius 24.00 vs peer median 44.00 (range CoreWeave 36.00 - Nscale 52.00; n=2); lower concentration is better
A11: 8 | B11: K02 | C11: Revenue per active MW - average MW (2024 uses interpolated MW) | D11: =Comparison!Z5 -> Better | E11: =Comparison!D5 -> 13.350363 | F11: =Comparison!Y5 -> 9.358411 | G11: 42.7 | H11: Nebius 13.35 vs peer median 9.36 (range CoreWeave 8.24 - IREN 10.48; n=2); same on average MW - the fixed, comparable figure; Blackwell-heavy, mostly new fleet lifts density
A12: 9 | B12: K09 | C12: Implied utilization (realized $/GPU-hr / weighted list) | D12: =Comparison!Z13 -> Better | E12: =Comparison!D13 -> 59.027084 | F12: =Comparison!Y13 -> 43.943989 | G12: 34.3 | H12: Nebius 59.03 vs peer median 43.94 (range CoreWeave 18.06 - Lambda 69.83; n=2); price-based 'utilization' (mixes discount with use); not physical utilization
A13: 10 | B13: K03 | C13: Revenue per contracted MW | D13: =Comparison!Z7 -> Better | E13: =Comparison!D7 -> 0.65702857 | F13: =Comparison!Y7 -> 0.33333333 | G13: 29.2 | H13: Nebius 0.66 vs peer median 0.33 (range Nscale 0.21 - CoreWeave 2.78; n=3); monetises contracted power faster? Nebius has far more unbuilt contracted MW than CRWV
A14: 11 | B14: K25 | C14: 2nd-largest customer % | D14: =Comparison!Z28 -> Better | E14: =Comparison!D28 -> 21 | F14: =Comparison!Y28 -> 26 | G14: 19.2 | H14: Nebius 21.00 vs peer median 26.00 (range CoreWeave 26.00 - CoreWeave 26.00; n=1); lower is better
A15: 12 | B15: K17 | C15: Depreciation yield (D&A x4 / avg in-service gross PP&E) | D15: =Comparison!Z20 -> Better | E15: =Comparison!D20 -> 17.515048 | F15: =Comparison!Y20 -> 14.908554 | G15: 17.5 | H15: Nebius 17.52 vs peer median 14.91 (range Oracle OCI 13.45 - Nscale 15.67; n=4); higher depreciation yield = more conservative
A16: 13 | B16: K18 | C16: Implied average depreciable life (1 / yield) | D16: =Comparison!Z21 -> Better | E16: =Comparison!D21 -> 5.7093762 | F16: =Comparison!Y21 -> 6.716941 | G16: 14.8 | H16: Nebius 5.71 vs peer median 6.72 (range Nscale 6.38 - Oracle OCI 7.44; n=4); lower implied life = more conservative
A17: 14 | B17: K16 | C17: Useful life - technology equipment (GPUs/servers/network) | D17: =Comparison!Z19 -> Better | E17: =Comparison!D19 -> 5 | F17: =Comparison!Y19 -> 5.75 | G17: 13 | H17: Nebius 5.00 vs peer median 5.75 (range IREN 5.00 - CoreWeave 6.00; n=4); shorter life = more conservative accounting (Nebius moved 4->5 yrs in 2026; CRWV/Oracle 6)
A18: 15 | B18: K39 | C18: Debt principal / RPO | D18: =Comparison!Z38 -> In line | E18: =Comparison!D38 -> 0.22794247 | F18: =Comparison!Y38 -> 0.27293389 | G18: 8.7 | H18: Nebius 0.23 vs peer median 0.27 (range Nscale 0.00 - IREN 1.51; n=4); lower debt per $ of backlog is better
A19: 16 | B19: K36 | C19: Implied cash cost: contractual interest x4 / avg principal | D19: =Comparison!Z35 -> In line | E19: =Comparison!D35 -> 5.605992 | F19: =Comparison!Y35 -> 6.0787368 | G19: 5.2 | H19: Nebius 5.61 vs peer median 6.08 (range IREN 1.71 - Nscale 22.19; n=4); lower cash cost of debt is better
A20: 17 | B20: K23 | C20: RPO / annualized quarterly revenue | D20: =Comparison!Z26 -> In line | E20: =Comparison!D26 -> 16.303096 | F20: =Comparison!Y26 -> 14.07461 | G20: 3.8 | H20: Nebius 16.30 vs peer median 14.07 (range Oracle OCI 8.31 - Nscale 200.57; n=4); backlog coverage of current run-rate
A21: 18 | B21: K26 | C21: Top-N >=10% customers combined % | D21: =Comparison!Z29 -> In line | E21: =Comparison!D29 -> 59 | F21: =Comparison!Y29 -> 61 | G21: 3.3 | H21: Nebius 59.00 vs peer median 61.00 (range Lambda 50.00 - CoreWeave 72.00; n=2); lower combined concentration is better
A22: 19 | B22: K22 | C22: RPO % recognized within 24 months | D22: =Comparison!Z25 -> In line | E22: =Comparison!D25 -> 36 | F22: =Comparison!Y25 -> 35 | G22: 2.9 | H22: Nebius 36.00 vs peer median 35.00 (range Nscale 16.00 - IREN 43.10; n=4); share of RPO converting within 24m
A23: 20 | B23: K12 | C23: In-service additions per new active MW (CRWV capex definition) | D23: =Comparison!Z15 -> In line | E23: =Comparison!D15 -> 19.68069 | F23: =Comparison!Y15 -> 18.704 | G23: -5.2 | H23: Nebius 19.68 vs peer median 18.70 (range CoreWeave 18.70 - CoreWeave 18.70; n=1); in-service $ per MW added (FY25 basis for Nebius)
A24: 21 | B24: K28 | C24: Weighted effective cost of debt (principal-weighted, EoP) - all facilities | D24: =Comparison!Z31 -> In line | E24: =Comparison!D31 -> 5.1 | F24: =Comparison!Y31 -> 4.8282005 | G24: -5.4 | H24: Nebius 5.10 vs peer median 4.83 (range IREN 1.85 - CoreWeave 8.41; n=3); cheaper debt (converts-heavy) is better
A25: 22 | B25: K14 | C25: Net PP&E per active MW (EoP) | D25: =Comparison!Z17 -> Worse | E25: =Comparison!D17 -> 75.40578 | F25: =Comparison!Y17 -> 50.933605 | G25: -48 | H25: Nebius 75.41 vs peer median 50.93 (range CoreWeave 31.16 - Nscale 70.71; n=2); net PP&E per active MW inflated by construction-in-progress
A26: 23 | B26: K15 | C26: Gross in-service PP&E per active MW (EoP) | D26: =Comparison!Z18 -> Worse | E26: =Comparison!D18 -> 36.491908 | F26: =Comparison!Y18 -> 23.980963 | G26: -52.2 | H26: Nebius 36.49 vs peer median 23.98 (range Nscale 20.83 - CoreWeave 27.14; n=2); gross in-service PP&E per MW
A27: 24 | B27: K27 | C27: Number of customers >=10% of revenue | D27: =Comparison!Z30 -> Worse | E27: =Comparison!D30 -> 3 | F27: =Comparison!Y30 -> 1.5 | G27: -100 | H27: Nebius 3.00 vs peer median 1.50 (range Oracle OCI 0.00 - CoreWeave 3.00; n=2); fewer >=10% customers is better
A28: 25 | B28: K13 | C28: Trailing-4Q cash capex per trailing-4Q new active MW | D28: =Comparison!Z16 -> Worse | E28: =Comparison!D16 -> 87.045312 | F28: =Comparison!Y16 -> 33.176218 | G28: -162.4 | H28: Nebius 87.05 vs peer median 33.18 (range CoreWeave 19.97 - Oracle OCI 46.39; n=2); capex per MW added is high because capex funds 2027 capacity (not-yet-in-use $7.8B)
A29: 26 | B29: K40 | C29: Capitalized interest % of contractual interest | D29: =Comparison!Z39 -> Worse | E29: =Comparison!D39 -> 25.235405 | F29: =Comparison!Y39 -> 6.6722973 | G29: -278.2 | H29: Nebius 25.24 vs peer median 6.67 (range Nscale 0.00 - CoreWeave 13.34; n=2); high capitalized share flatters P&L interest
B30: K04 | C30: Contracted / active MW (build-out multiple) | D30: =Comparison!Z8 -> Context | E30: =Comparison!D8 -> 20.231214 | F30: =Comparison!Y8 -> 6 | H30: Nebius 20.23 vs peer median 6.00 (range CoreWeave 2.47 - Nscale 16.91; n=3); build-out multiple: big growth runway but heavy execution/funding need (context, not scored)
B31: K08 | C31: Fleet-weighted on-demand list price ($/GPU-hr) | D31: =Comparison!Z12 -> Context | E31: =Comparison!D12 -> 5.5710951 | F31: =Comparison!Y12 -> 3.445 | H31: Nebius 5.57 vs peer median 3.45 (range IREN 2.00 - CoreWeave 9.20; n=4); list-price context
B32: K10 | C32: Cash capex per new active MW (reported MW) | D32: =Comparison!Z14 -> n/a | E32: =Comparison!D14 -> n.m. | F32: =Comparison!Y14 -> 34.858207 | H32: Nebius n/d. single-quarter capex/MW not meaningful for Nebius (+1.5 MW)
B33: K19 | C33: D&A as % of revenue | D33: =Comparison!Z22 -> Context | E33: =Comparison!D22 -> 45.173074 | F33: =Comparison!Y22 -> 67.887312 | H33: Nebius 45.17 vs peer median 67.89 (range Oracle OCI 12.59 - Nscale 123.76; n=4); D&A burden context
B34: K20 | C34: RPO (ASC 606, EoP) | D34: =Comparison!Z23 -> Context | E34: =Comparison!D23 -> 37.4906 | F34: =Comparison!Y23 -> 80.05 | H34: Nebius 37.49 vs peer median 80.05 (range IREN 5.10 - Oracle OCI 638.00; n=4); absolute size context
B35: K21 | C35: Revenue backlog (company metric, EoP) | D35: =Comparison!Z24 -> n/a | E35: =Comparison!D24 -> n/d | F35: =Comparison!Y24 -> 103.4 | H35: Nebius n/d. company backlog metric (context)
B36: K29 | C36: of which DDTL - weighted eff. rate | D36: =Comparison!Z32 -> n/a | E36: =Comparison!D32 -> n/d | F36: =Comparison!Y32 -> 9.1021429 | H36: Nebius n/d. facility-level rate (context)
B37: K34 | C37: of which Other term loans - weighted eff. rate | D37: =Comparison!Z33 -> n/a | E37: =Comparison!D33 -> n/d | F37: =Comparison!Y33 -> 9 | H37: Nebius n/d. facility-level rate (context)
B38: K35 | C38: DDTL (secured asset-level) share of principal | D38: =Comparison!Z34 -> n/a | E38: =Comparison!D34 -> n/d | F38: =Comparison!Y34 -> 20.219881 | H38: Nebius n/d. structure context
B39: K37 | C39: Company-reported weighted average interest rate | D39: =Comparison!Z36 -> n/a | E39: =Comparison!D36 -> n/d | F39: =Comparison!Y36 -> 8.3 | H39: Nebius n/d. company-reported rate
B40: K38 | C40: Total debt principal (EoP) | D40: =Comparison!Z37 -> Context | E40: =Comparison!D37 -> 8.5457 | F40: =Comparison!Y37 -> 21.628325 | H40: Nebius 8.55 vs peer median 21.63 (range Nscale 0.14 - Oracle OCI 129.54; n=4); size context
B41: K41 | C41: Company-reported GPU utilization (physical) | D41: =Comparison!Z40 -> n/a | E41: =Comparison!D40 -> n/d | F41: =Comparison!Y40 -> 97.5 | H41: Nebius n/d. physical utilization (Oracle only)
...

Sheet Nebius_Inputs
A1: Nebius inputs for the Comparison tab (Q2'26 = quarter ended 30-Jun-2026 unless stated). Comparison Nebius cells are live formulas on column C.
A3: ID | B3: Item | C3: Value | D3: Unit | E3: Tag | F3: Source (Nebius workspace file / row)
A4: N01 | B4: AI cloud segment revenue Q2'26 | C4: 574.9 | D4: $M | E4: R | F4: filings/nebius_filings.xlsx Quarterly 'Segment revenue - Nebius AI cloud'; 6-K 2026-08-12
A5: N02 | B5: AI cloud segment revenue Q2'25 | C5: 93.7 | D5: $M | E5: R | F5: filings/nebius_filings.xlsx Quarterly
A6: N03 | B6: Group revenue Q2'26 (memo) | C6: 582.3 | D6: $M | E6: R | F6: filings/nebius_filings.xlsx Quarterly
A7: N04 | B7: AI cloud adj. EBITDA Q2'26 | C7: 285.7 | D7: $M | E7: R | F7: filings/nebius_filings.xlsx Quarterly
A8: N05 | B8: D&A Q2'26 (group) | C8: 259.7 | D8: $M | E8: R | F8: filings/nebius_filings.xlsx Quarterly
A9: N06 | B9: Cash capex Q3'25 | C9: 955.5 | D9: $M | E9: R | F9: filings/nebius_filings.xlsx Quarterly
A10: N07 | B10: Cash capex Q4'25 | C10: 2056 | D10: $M | E10: R | F10: filings/nebius_filings.xlsx Quarterly
A11: N08 | B11: Cash capex Q1'26 | C11: 2472.9 | D11: $M | E11: R | F11: filings/nebius_filings.xlsx Quarterly
A12: N09 | B12: Cash capex Q2'26 | C12: 5657.4 | D12: $M | E12: R | F12: filings/nebius_filings.xlsx Quarterly
A13: N10 | B13: PP&E net 30-Jun-26 | C13: 13045.2 | D13: $M | E13: R | F13: filings/nebius_filings.xlsx Quarterly
A14: N11 | B14: Gross in-service PP&E 31-Mar-26 (gross 7,976.6 - not yet in use 2,427.9) | C14: 5548.7 | D14: $M | E14: D | F14: filings/nebius_kpi_history.xlsx KPI row 26 (Q1'26 interim FS Note 7)
A15: N12 | B15: Gross in-service PP&E 30-Jun-26 (gross 14,149.5 - not yet in use 7,836.4) | C15: 6313.1 | D15: $M | E15: D | F15: filings/nebius_kpi_history.xlsx KPI row 26 (Q2'26 interim FS Note 7)
... A41: N38 | B41: Energized MW 31-Dec-25 | C41: 170 | D41: MW | E41: E | F41: filings/nebius_kpi_history.xlsx KPI row 28 (ties to mgmt ~170)
A42: N_BILL_Q1 | B42: Billing IT MW Q1'26 (Capacity row 147) | C42: 165.46 | D42: E | E42: capacity/nebius_capacity.xlsx
A43: N_BILL_Q2 | B43: Billing IT MW Q2'26 (Capacity row 147) | C43: 186.82 | D43: E | E43: capacity/nebius_capacity.xlsx
A44: NOTE_1417 | B44: Microsoft ACV alignment: $11.60 on stated 300 MW | ~$14.5 on Capacity gross→IT (~240) | $17.08 on GPU-derived 203.7 IT MW. Same contract, three readings.

Sheet Contracts_$MWyr
A1: Hyperscaler / neocloud / AI-lab contract economics: implied $M per MW-yr = TCV / term / MW (8,760 h/yr for $/GPU-hr). 'Reused' rows are the GPU Market agent's entries in parts/contract_economics.xlsx (Deals/Normalized; nothing contract-related exists in market/ or nebius_market.xlsx) - cited, not re-researched; their values shown in cols R-T and checked vs ours in col U. 'New' rows added here with sources. Facility leases at the bottom are NOT compute prices (shell+power only). Never fabricated: n/d where undisclosed.
A3: ID | B3: Status | C3: Provider | D3: Customer | E3: Category | F3: Signed | G3: TCV ($M) | H3: TCV tag | I3: Term (yrs) | J3: MW (as stated) | K3: MW basis | L3: IT MW (normalized) | M3: IT MW method | N3: Chip | O3: GPUs | P3: GPU tag | Q3: TCV / yr ($M) | R3: Market agent $M/MW-yr (stated MW) | S3: Market agent $M/IT MW-yr | T3: Market agent $/GPU-hr | U3: Check: ours - market ($M/MW-yr) | V3: $M per MW-yr (stated MW) | W3: $M per IT MW-yr | X3: $ per GPU-hr | Y3: Source | Z3: Notes / conflicts
A4: N1 | B4: Reused | C4: Nebius | D4: Microsoft | E4: Neocloud-hyperscaler | F4: 2025-09-08 | G4: 17392.9 | H4: R | I4: 5 | J4: 300 | K4: unlabeled (likely gross) | L4: 203.666 | M4: D: 100k GB300 / 491 per IT MW | N4: GB300 NVL72 (P) | O4: 100000 | P4: P (floor) | Q4: =IF(AND(ISNUMBER(G4),ISNUMBER(I4)),G4/I4,"n/d") -> 3478.58 | R4: 11.595 | S4: 17.08 | T4: 3.971 | U4: =IF(AND(ISNUMBER(S4),ISNUMBER(W4)),ROUND(W4-S4,2),IF(AND(ISNUMBER(R4),ISNUMBER(V4)),ROUND(V4-R4,2),"")) -> 0 | V4: =IF(AND(ISNUMBER(Q4),ISNUMBER(J4)),Q4/J4,"n/d") -> 11.595267 | W4: =IF(AND(ISNUMBER(Q4),ISNUMBER(L4)),Q4/L4,"n/d") -> 17.079827 | X4: =IF(AND(ISNUMBER(G4),ISNUMBER(I4),ISNUMBER(O4)),G4*1000000/(O4*I4*8760),"n/d") -> 3.9709817 | Y4: 6-K 2025-09-08 (SEC) | parts/contract_economics.xlsx (GPU Market agent) Deals/Normalized N1 | Z4: Prepay-adjusted 18.56 / $4.32 (market). Capacity read of 300 MW as gross ~230-250 IT -> 14.5 per IT MW (market Notes_Method).
A5: N1o | B5: Reused | C5: Nebius | D5: Microsoft (incl. option) | E5: Neocloud-hyperscaler | F5: 2025-09-08 | G5: 19400 | H5: R (up to) | I5: 5 | J5: 300 | K5: unlabeled | L5: 203.666 | M5: as N1 | N5: GB300 (P) | O5: 100000 | P5: P (floor) | Q5: =IF(AND(ISNUMBER(G5),ISNUMBER(I5)),G5/I5,"n/d") -> 3880 | R5: 12.933 | S5: 19.051 | T5: 4.429 | U5: =IF(AND(ISNUMBER(S5),ISNUMBER(W5)),ROUND(W5-S5,2),IF(AND(ISNUMBER(R5),ISNUMBER(V5)),ROUND(V5-R5,2),"")) -> 0 | V5: =IF(AND(ISNUMBER(Q5),ISNUMBER(J5)),Q5/J5,"n/d") -> 12.933333 | W5: =IF(AND(ISNUMBER(Q5),ISNUMBER(L5)),Q5/L5,"n/d") -> 19.050799 | X5: =IF(AND(ISNUMBER(G5),ISNUMBER(I5),ISNUMBER(O5)),G5*1000000/(O5*I5*8760),"n/d") -> 4.4292237 | Y5: parts/contract_economics.xlsx (GPU Market agent) N1o | Z5: Upside case.
A6: N2 | B6: Reused | C6: Nebius | D6: Meta #1 | E6: Neocloud-hyperscaler | F6: 2025-11-01 | G6: 2880.7 | H6: R | I6: 5 | J6: n/d | K6: not disclosed | L6: 50 | M6: E (LOW): unsourced secondary ~50 MW | N6: n/d | Q6: =IF(AND(ISNUMBER(G6),ISNUMBER(I6)),G6/I6,"n/d") -> 576.14 | S6: 11.523 | U6: =IF(AND(ISNUMBER(S6),ISNUMBER(W6)),ROUND(W6-S6,2),IF(AND(ISNUMBER(R6),ISNUMBER(V6)),ROUND(V6-R6,2),"")) -> 0 | V6: =IF(AND(ISNUMBER(Q6),ISNUMBER(J6)),Q6/J6,"n/d") -> n/d | W6: =IF(AND(ISNUMBER(Q6),ISNUMBER(L6)),Q6/L6,"n/d") -> 11.5228 | X6: =IF(AND(ISNUMBER(G6),ISNUMBER(I6),ISNUMBER(O6)),G6*1000000/(O6*I6*8760),"n/d") -> n/d | Y6: 6-K 2025-11-12 | parts/contract_economics.xlsx (GPU Market agent) N2 | Z6: IT MW is a low-confidence estimate (market); Nebius filings tie no MW to the contract.
A7: N3 | B7: Reused | C7: Nebius | D7: Meta #2 (dedicated) | E7: Neocloud-hyperscaler | F7: 2026-03-13 | G7: 12000 | H7: R | I7: 5 | J7: n/d | K7: not disclosed | N7: Vera Rubin NVL72 | Q7: =IF(AND(ISNUMBER(G7),ISNUMBER(I7)),G7/I7,"n/d") -> 2400 | U7: =IF(AND(ISNUMBER(S7),ISNUMBER(W7)),ROUND(W7-S7,2),IF(AND(ISNUMBER(R7),ISNUMBER(V7)),ROUND(V7-R7,2),"")) | V7: =IF(AND(ISNUMBER(Q7),ISNUMBER(J7)),Q7/J7,"n/d") -> n/d | W7: =IF(AND(ISNUMBER(Q7),ISNUMBER(L7)),Q7/L7,"n/d") -> n/d | X7: =IF(AND(ISNUMBER(G7),ISNUMBER(I7),ISNUMBER(O7)),G7*1000000/(O7*I7*8760),"n/d") -> n/d | Y7: 6-K 2026-03-16 | parts/contract_economics.xlsx (GPU Market agent) N3 | Z7: Break-even ~149 IT MW to match Anthropic-Nscale $16.16M (market).
A8: N4 | B8: Reused | C8: Nebius | D8: Meta #2 backstop (contingent) | E8: Neocloud-hyperscaler | F8: 2026-03-13 | G8: 15000 | H8: R (up to, contingent) | I8: 5 | J8: n/d | N8: n/d | Q8: =IF(AND(ISNUMBER(G8),ISNUMBER(I8)),G8/I8,"n/d") -> 3000 | U8: =IF(AND(ISNUMBER(S8),ISNUMBER(W8)),ROUND(W8-S8,2),IF(AND(ISNUMBER(R8),ISNUMBER(V8)),ROUND(V8-R8,2),"")) | V8: =IF(AND(ISNUMBER(Q8),ISNUMBER(J8)),Q8/J8,"n/d") -> n/d | W8: =IF(AND(ISNUMBER(Q8),ISNUMBER(L8)),Q8/L8,"n/d") -> n/d | X8: =IF(AND(ISNUMBER(G8),ISNUMBER(I8),ISNUMBER(O8)),G8*1000000/(O8*I8*8760),"n/d") -> n/d | Y8: 6-K 2026-03-16 | parts/contract_economics.xlsx (GPU Market agent) N4 | Z8: Contingent; excluded from normalized comps.
A9: NAGG1 | B9: Reused (KPI) | C9: Nebius | D9: 4 'landmark' Q2'26 customers (unnamed) | E9: Neocloud-mixed | F9: Q2'26 | G9: n/d | J9: n/d | N9: n/d | Q9: =IF(AND(ISNUMBER(G9),ISNUMBER(I9)),G9/I9,"n/d") -> n/d | R9: 20-25 (ACV/MW, R) | U9: =IF(AND(ISNUMBER(S9),ISNUMBER(W9)),ROUND(W9-S9,2),IF(AND(ISNUMBER(R9),ISNUMBER(V9)),ROUND(V9-R9,2),"")) | V9: =IF(AND(ISNUMBER(Q9),ISNUMBER(J9)),Q9/J9,"n/d") -> n/d | W9: =IF(AND(ISNUMBER(Q9),ISNUMBER(L9)),Q9/L9,"n/d") -> n/d | X9: =IF(AND(ISNUMBER(G9),ISNUMBER(I9),ISNUMBER(O9)),G9*1000000/(O9*I9*8760),"n/d") -> n/d | Y9: Q2'26 letter p.2-4 (filings MW_Disclosures) | parts/contract_economics.xlsx (GPU Market agent) Notes_Method | Z9: Company aggregate: deals averaged >$1B TCV, ACV $20-25M/MW; Q2 deals >$20M/MW vs 2026 base $12M/MW; Q3 short-term >$40M/MW. Basis not stated (Filings: likely IT/active).
A10: P1 | B10: Reused | C10: IREN | D10: Microsoft | E10: Neocloud-hyperscaler | F10: 2025-11-03 | G10: 9700 | H10: R | I10: 5 | J10: 200 | K10: IT | L10: 200 | M10: R | N10: GB300 NVL72 | O10: 98200 | P10: E (200 x 491) | Q10: =IF(AND(ISNUMBER(G10),ISNUMBER(I10)),G10/I10,"n/d") -> 1940 | R10: 9.7 | S10: 9.7 | T10: 2.255 | U10: =IF(AND(ISNUMBER(S10),ISNUMBER(W10)),ROUND(W10-S10,2),IF(AND(ISNUMBER(R10),ISNUMBER(V10)),ROUND(V10-R10,2),"")) -> 0 | V10: =IF(AND(ISNUMBER(Q10),ISNUMBER(J10)),Q10/J10,"n/d") -> 9.7 | W10: =IF(AND(ISNUMBER(Q10),ISNUMBER(L10)),Q10/L10,"n/d") -> 9.7 | X10: =IF(AND(ISNUMBER(G10),ISNUMBER(I10),ISNUMBER(O10)),G10*1000000/(O10*I10*8760),"n/d") -> 2.2552056 | Y10: 8-K 2025-11-03 | parts/contract_economics.xlsx (GPU Market agent) P1 | Z10: Prepay-adjusted 10.28 (market).
A11: NEW1 | B11: New | C11: IREN | D11: NVIDIA | E11: Neocloud-chip vendor | F11: 2026-05 (8-K) | G11: 3400 | H11: R | I11: 5 | J11: 60 | K11: unlabeled (existing Childress halls; air-cooled) | N11: NVIDIA Blackwell (air-cooled) | P11: n/d | Q11: =IF(AND(ISNUMBER(G11),ISNUMBER(I11)),G11/I11,"n/d") -> 680 | U11: =IF(AND(ISNUMBER(S11),ISNUMBER(W11)),ROUND(W11-S11,2),IF(AND(ISNUMBER(R11),ISNUMBER(V11)),ROUND(V11-R11,2),"")) | V11: =IF(AND(ISNUMBER(Q11),ISNUMBER(J11)),Q11/J11,"n/d") -> 11.333333 | W11: =IF(AND(ISNUMBER(Q11),ISNUMBER(L11)),Q11/L11,"n/d") -> n/d | X11: =IF(AND(ISNUMBER(G11),ISNUMBER(I11),ISNUMBER(O11)),G11*1000000/(O11*I11*8760),"n/d") -> n/d | Y11: https://iren.gcs-web.com/news-releases/news-release-details/iren-secures-34bn-ai-cloud-contract-nvidia ; peers/iren (FY26 10-K backlog) | Z11: ~60 MW of existing Childress capacity; ramp from early 2027 (peers/sites site_verification.md). Below IREN's 'recent 3-yr >$20M/IT MW' claim.
A12: PAGG | B12: Reused (KPI) | C12: IREN | D12: recent 3-yr contracts (unnamed) | E12: Neocloud-mixed | F12: FY26 | G12: n/d | I12: 3 | J12: n/d | K12: IT | N12: n/d | Q12: =IF(AND(ISNUMBER(G12),ISNUMBER(I12)),G12/I12,"n/d") -> n/d | R12: >20 (R) | U12: =IF(AND(ISNUMBER(S12),ISNUMBER(W12)),ROUND(W12-S12,2),IF(AND(ISNUMBER(R12),ISNUMBER(V12)),ROUND(V12-R12,2),"")) | V12: =IF(AND(ISNUMBER(Q12),ISNUMBER(J12)),Q12/J12,"n/d") -> n/d | W12: =IF(AND(ISNUMBER(Q12),ISNUMBER(L12)),Q12/L12,"n/d") -> n/d | X12: =IF(AND(ISNUMBER(G12),ISNUMBER(I12),ISNUMBER(O12)),G12*1000000/(O12*I12*8760),"n/d") -> n/d | Y12: parts/contract_economics.xlsx (GPU Market agent) Notes_Method | Z12: Company statement only.
A13: P2 | B13: Reused | C13: Nscale | D13: Microsoft (all SOWs) | E13: Neocloud-hyperscaler | F13: 2025-09..2026-04 | G13: 43800 | H13: R (up to) | I13: 5.5 | J13: n/a | L13: 596.474 | M13: D: 191.6k/491 + 66k/320 | N13: GB300 + Vera Rubin | O13: 257600 | P13: R (sum) | Q13: =IF(AND(ISNUMBER(G13),ISNUMBER(I13)),G13/I13,"n/d") -> 7963.6364 | S13: 13.351 | T13: 3.529 | U13: =IF(AND(ISNUMBER(S13),ISNUMBER(W13)),ROUND(W13-S13,2),IF(AND(ISNUMBER(R13),ISNUMBER(V13)),ROUND(V13-R13,2),"")) -> 0 | V13: =IF(AND(ISNUMBER(Q13),ISNUMBER(J13)),Q13/J13,"n/d") -> n/d | W13: =IF(AND(ISNUMBER(Q13),ISNUMBER(L13)),Q13/L13,"n/d") -> 13.351188 | X13: =IF(AND(ISNUMBER(G13),ISNUMBER(I13),ISNUMBER(O13)),G13*1000000/(O13*I13*8760),"n/d") -> 3.5290796 | Y13: Nscale S-1 2026-09-18 | parts/contract_economics.xlsx (GPU Market agent) P2
A14: P2a | B14: Reused | C14: Nscale (Aker JV) | D14: Microsoft - Narvik | E14: Neocloud-hyperscaler | F14: 2025-09-17 | G14: 6200 | H14: R | I14: 5 | J14: n/a | L14: 105.906 | M14: D: 52k/491 | N14: GB300 | O14: 52000 | P14: R | Q14: =IF(AND(ISNUMBER(G14),ISNUMBER(I14)),G14/I14,"n/d") -> 1240 | S14: 11.708 | T14: 2.722 | U14: =IF(AND(ISNUMBER(S14),ISNUMBER(W14)),ROUND(W14-S14,2),IF(AND(ISNUMBER(R14),ISNUMBER(V14)),ROUND(V14-R14,2),"")) -> 0 | V14: =IF(AND(ISNUMBER(Q14),ISNUMBER(J14)),Q14/J14,"n/d") -> n/d | W14: =IF(AND(ISNUMBER(Q14),ISNUMBER(L14)),Q14/L14,"n/d") -> 11.708496 | X14: =IF(AND(ISNUMBER(G14),ISNUMBER(I14),ISNUMBER(O14)),G14*1000000/(O14*I14*8760),"n/d") -> 2.7221637 | Y14: akernscale.com PR | parts/contract_economics.xlsx (GPU Market agent) P2a | Z14: Within P2.
A15: P2b | B15: Reused | C15: Nscale | D15: Microsoft ex-Narvik | E15: Neocloud-hyperscaler | G15: 37600 | H15: D | I15: 5.5 | J15: n/a | L15: 490.568 | M15: D | N15: GB300 + Vera Rubin | O15: 205600 | P15: R (sum) | Q15: =IF(AND(ISNUMBER(G15),ISNUMBER(I15)),G15/I15,"n/d") -> 6836.3636 | S15: 13.936 | T15: 3.796 | U15: =IF(AND(ISNUMBER(S15),ISNUMBER(W15)),ROUND(W15-S15,2),IF(AND(ISNUMBER(R15),ISNUMBER(V15)),ROUND(V15-R15,2),"")) -> 0 | V15: =IF(AND(ISNUMBER(Q15),ISNUMBER(J15)),Q15/J15,"n/d") -> n/d | W15: =IF(AND(ISNUMBER(Q15),ISNUMBER(L15)),Q15/L15,"n/d") -> 13.935609 | X15: =IF(AND(ISNUMBER(G15),ISNUMBER(I15),ISNUMBER(O15)),G15*1000000/(O15*I15*8760),"n/d") -> 3.795753 | Y15: parts/contract_economics.xlsx (GPU Market agent) P2b | Z15: Residual.
A16: O1 | B16: Reused | C16: Nscale | D16: Anthropic | E16: Neocloud-AI lab | F16: 2026-08-25 | G16: 44600 | H16: R (up to) | I16: 6 | J16: 460 | K16: IT | L16: 460 | M16: R (S-1 site #17) | N16: Vera Rubin NVL72 | O16: 147200 | P16: E (460 x 320) | Q16: =IF(AND(ISNUMBER(G16),ISNUMBER(I16)),G16/I16,"n/d") -> 7433.3333 | R16: 16.159 | S16: 16.159 | T16: 5.765 | U16: =IF(AND(ISNUMBER(S16),ISNUMBER(W16)),ROUND(W16-S16,2),IF(AND(ISNUMBER(R16),ISNUMBER(V16)),ROUND(V16-R16,2),"")) -> 0 | V16: =IF(AND(ISNUMBER(Q16),ISNUMBER(J16)),Q16/J16,"n/d") -> 16.15942 | W16: =IF(AND(ISNUMBER(Q16),ISNUMBER(L16)),Q16/L16,"n/d") -> 16.15942 | X16: =IF(AND(ISNUMBER(G16),ISNUMBER(I16),ISNUMBER(O16)),G16*1000000/(O16*I16*8760),"n/d") -> 5.7646334 | Y16: Nscale S-1 | parts/contract_economics.xlsx (GPU Market agent) O1
A17: P3 | B17: Reused | C17: Lambda | D17: Microsoft | E17: Neocloud-hyperscaler | F17: 2025-11-03 | G17: n/d | H17: 'multibillion' | J17: n/d | N17: GB300 NVL72 (partly) | Q17: =IF(AND(ISNUMBER(G17),ISNUMBER(I17)),G17/I17,"n/d") -> n/d | U17: =IF(AND(ISNUMBER(S17),ISNUMBER(W17)),ROUND(W17-S17,2),IF(AND(ISNUMBER(R17),ISNUMBER(V17)),ROUND(V17-R17,2),"")) | V17: =IF(AND(ISNUMBER(Q17),ISNUMBER(J17)),Q17/J17,"n/d") -> n/d | W17: =IF(AND(ISNUMBER(Q17),ISNUMBER(L17)),Q17/L17,"n/d") -> n/d | X17: =IF(AND(ISNUMBER(G17),ISNUMBER(I17),ISNUMBER(O17)),G17*1000000/(O17*I17*8760),"n/d") -> n/d | Y17: lambda.ai blog 2025-11-03 | parts/contract_economics.xlsx (GPU Market agent) P3 | Z17: No economics public.
A18: NEW2 | B18: New | C18: Lambda | D18: Anthropic | E18: Neocloud-AI lab | F18: 2026-09-01 (press) | G18: 35000 | H18: P | I18: 6 | J18: 350 | K18: unlabeled (Hut 8 Beacon Point TX) | N18: n/d | Q18: =IF(AND(ISNUMBER(G18),ISNUMBER(I18)),G18/I18,"n/d") -> 5833.3333 | U18: =IF(AND(ISNUMBER(S18),ISNUMBER(W18)),ROUND(W18-S18,2),IF(AND(ISNUMBER(R18),ISNUMBER(V18)),ROUND(V18-R18,2),"")) | V18: =IF(AND(ISNUMBER(Q18),ISNUMBER(J18)),Q18/J18,"n/d") -> 16.666667 | W18: =IF(AND(ISNUMBER(Q18),ISNUMBER(L18)),Q18/L18,"n/d") -> n/d | X18: =IF(AND(ISNUMBER(G18),ISNUMBER(I18),ISNUMBER(O18)),G18*1000000/(O18*I18*8760),"n/d") -> n/d | Y18: WSJ via theenergymag.com (peers/private private_peers.xlsx L21/L12) | Z18: Not confirmed by Lambda; NVIDIA holds the Hut 8 lease (row F6).
A19: NEW3 | B19: New | C19: Lambda | D19: NVIDIA (GPU leaseback, main tranche) | E19: Neocloud-chip vendor | F19: 2025-09-08 (press) | G19: 1300 | H19: P | I19: 4 | J19: n/d | N19: NVIDIA GPUs (type n/d) | O19: 10000 | P19: P | Q19: =IF(AND(ISNUMBER(G19),ISNUMBER(I19)),G19/I19,"n/d") -> 325 | U19: =IF(AND(ISNUMBER(S19),ISNUMBER(W19)),ROUND(W19-S19,2),IF(AND(ISNUMBER(R19),ISNUMBER(V19)),ROUND(V19-R19,2),"")) | V19: =IF(AND(ISNUMBER(Q19),ISNUMBER(J19)),Q19/J19,"n/d") -> n/d | W19: =IF(AND(ISNUMBER(Q19),ISNUMBER(L19)),Q19/L19,"n/d") -> n/d | X19: =IF(AND(ISNUMBER(G19),ISNUMBER(I19),ISNUMBER(O19)),G19*1000000/(O19*I19*8760),"n/d") -> 3.7100457 | Y19: DCD citing The Information (private_peers L18/L19) | Z19: Total reported $1.5B / ~18k GPUs (incl. +$200M / 8k GPUs) -> $2.38/GPU-hr on the total; private_peers uses the $1.3B/10k tranche = $3.71.
A20: P4 | B20: Reused | C20: CoreWeave | D20: Meta #1 | E20: Neocloud-hyperscaler | F20: 2025-09-30 | G20: 14200 | H20: R (up to) | I20: 6.22 | J20: n/d | N20: GB300 (P) | Q20: =IF(AND(ISNUMBER(G20),ISNUMBER(I20)),G20/I20,"n/d") -> 2282.9582 | U20: =IF(AND(ISNUMBER(S20),ISNUMBER(W20)),ROUND(W20-S20,2),IF(AND(ISNUMBER(R20),ISNUMBER(V20)),ROUND(V20-R20,2),"")) | V20: =IF(AND(ISNUMBER(Q20),ISNUMBER(J20)),Q20/J20,"n/d") -> n/d | W20: =IF(AND(ISNUMBER(Q20),ISNUMBER(L20)),Q20/L20,"n/d") -> n/d | X20: =IF(AND(ISNUMBER(G20),ISNUMBER(I20),ISNUMBER(O20)),G20*1000000/(O20*I20*8760),"n/d") -> n/d | Y20: 8-K 2025-09-30 | parts/contract_economics.xlsx (GPU Market agent) P4
A21: P5 | B21: Reused | C21: CoreWeave | D21: Meta #2 | E21: Neocloud-hyperscaler | F21: 2026-04-09 | G21: 21000 | H21: R (up to) | I21: 6.73 | J21: n/d | N21: incl. Vera Rubin | Q21: =IF(AND(ISNUMBER(G21),ISNUMBER(I21)),G21/I21,"n/d") -> 3120.3566 | U21: =IF(AND(ISNUMBER(S21),ISNUMBER(W21)),ROUND(W21-S21,2),IF(AND(ISNUMBER(R21),ISNUMBER(V21)),ROUND(V21-R21,2),"")) | V21: =IF(AND(ISNUMBER(Q21),ISNUMBER(J21)),Q21/J21,"n/d") -> n/d | W21: =IF(AND(ISNUMBER(Q21),ISNUMBER(L21)),Q21/L21,"n/d") -> n/d | X21: =IF(AND(ISNUMBER(G21),ISNUMBER(I21),ISNUMBER(O21)),G21*1000000/(O21*I21*8760),"n/d") -> n/d | Y21: 8-K | parts/contract_economics.xlsx (GPU Market agent) P5
A22: P6 | B22: Reused | C22: CoreWeave | D22: OpenAI T1 | E22: Neocloud-AI lab | F22: 2025-03-10 | G22: 11900 | H22: R (up to) | I22: 5 | J22: n/d | N22: n/d | Q22: =IF(AND(ISNUMBER(G22),ISNUMBER(I22)),G22/I22,"n/d") -> 2380 | U22: =IF(AND(ISNUMBER(S22),ISNUMBER(W22)),ROUND(W22-S22,2),IF(AND(ISNUMBER(R22),ISNUMBER(V22)),ROUND(V22-R22,2),"")) | V22: =IF(AND(ISNUMBER(Q22),ISNUMBER(J22)),Q22/J22,"n/d") -> n/d | W22: =IF(AND(ISNUMBER(Q22),ISNUMBER(L22)),Q22/L22,"n/d") -> n/d | X22: =IF(AND(ISNUMBER(G22),ISNUMBER(I22),ISNUMBER(O22)),G22*1000000/(O22*I22*8760),"n/d") -> n/d | Y22: parts/contract_economics.xlsx (GPU Market agent) P6 | Z22: $350M CRWV equity to OpenAI.
A23: P7 | B23: Reused | C23: CoreWeave | D23: OpenAI T2 | E23: Neocloud-AI lab | F23: 2025-05-15 | G23: 4000 | H23: R (up to) | I23: 3.9 | J23: n/d | N23: n/d | Q23: =IF(AND(ISNUMBER(G23),ISNUMBER(I23)),G23/I23,"n/d") -> 1025.641 | U23: =IF(AND(ISNUMBER(S23),ISNUMBER(W23)),ROUND(W23-S23,2),IF(AND(ISNUMBER(R23),ISNUMBER(V23)),ROUND(V23-R23,2),"")) | V23: =IF(AND(ISNUMBER(Q23),ISNUMBER(J23)),Q23/J23,"n/d") -> n/d | W23: =IF(AND(ISNUMBER(Q23),ISNUMBER(L23)),Q23/L23,"n/d") -> n/d | X23: =IF(AND(ISNUMBER(G23),ISNUMBER(I23),ISNUMBER(O23)),G23*1000000/(O23*I23*8760),"n/d") -> n/d | Y23: parts/contract_economics.xlsx (GPU Market agent) P7
A24: P8 | B24: Reused | C24: CoreWeave | D24: OpenAI T3 | E24: Neocloud-AI lab | F24: 2025-09-25 | G24: 6500 | H24: R (up to) | I24: 5.68 | J24: n/d | N24: n/d | Q24: =IF(AND(ISNUMBER(G24),ISNUMBER(I24)),G24/I24,"n/d") -> 1144.3662 | U24: =IF(AND(ISNUMBER(S24),ISNUMBER(W24)),ROUND(W24-S24,2),IF(AND(ISNUMBER(R24),ISNUMBER(V24)),ROUND(V24-R24,2),"")) | V24: =IF(AND(ISNUMBER(Q24),ISNUMBER(J24)),Q24/J24,"n/d") -> n/d | W24: =IF(AND(ISNUMBER(Q24),ISNUMBER(L24)),Q24/L24,"n/d") -> n/d | X24: =IF(AND(ISNUMBER(G24),ISNUMBER(I24),ISNUMBER(O24)),G24*1000000/(O24*I24*8760),"n/d") -> n/d | Y24: parts/contract_economics.xlsx (GPU Market agent) P8 | Z24: OpenAI total ~$22.4B.
A25: NEW4 | B25: New | C25: CoreWeave | D25: Jane Street | E25: Neocloud-other | F25: 2026-04-15 | G25: 6000 | H25: R | J25: n/d | N25: Vera Rubin (part) | Q25: =IF(AND(ISNUMBER(G25),ISNUMBER(I25)),G25/I25,"n/d") -> n/d | U25: =IF(AND(ISNUMBER(S25),ISNUMBER(W25)),ROUND(W25-S25,2),IF(AND(ISNUMBER(R25),ISNUMBER(V25)),ROUND(V25-R25,2),"")) | V25: =IF(AND(ISNUMBER(Q25),ISNUMBER(J25)),Q25/J25,"n/d") -> n/d | W25: =IF(AND(ISNUMBER(Q25),ISNUMBER(L25)),Q25/L25,"n/d") -> n/d | X25: =IF(AND(ISNUMBER(G25),ISNUMBER(I25),ISNUMBER(O25)),G25*1000000/(O25*I25*8760),"n/d") -> n/d | Y25: https://www.coreweave.com/news/jane-street-signs-6-billion-ai-cloud-agreement-with-coreweave | Z25: Term/MW not disclosed; plus $1B equity investment by Jane Street.
A26: NEW5 | B26: New | C26: CoreWeave | D26: Anthropic | E26: Neocloud-AI lab | F26: 2026-04-10 | G26: n/d | H26: R (no value) | J26: n/d | N26: n/d | Q26: =IF(AND(ISNUMBER(G26),ISNUMBER(I26)),G26/I26,"n/d") -> n/d | U26: =IF(AND(ISNUMBER(S26),ISNUMBER(W26)),ROUND(W26-S26,2),IF(AND(ISNUMBER(R26),ISNUMBER(V26)),ROUND(V26-R26,2),"")) | V26: =IF(AND(ISNUMBER(Q26),ISNUMBER(J26)),Q26/J26,"n/d") -> n/d | W26: =IF(AND(ISNUMBER(Q26),ISNUMBER(L26)),Q26/L26,"n/d") -> n/d | X26: =IF(AND(ISNUMBER(G26),ISNUMBER(I26),ISNUMBER(O26)),G26*1000000/(O26*I26*8760),"n/d") -> n/d | Y26: https://coreweave.com/news/coreweave-announces-multi-year-agreement-with-anthropic | Z26: Multi-year; no value.
A27: NEW6 | B27: New | C27: Crusoe | D27: Jane Street | E27: Neocloud-other | F27: 2026-09-04 (press) | G27: 13000 | H27: P | I27: 5 | J27: n/d | N27: n/d | Q27: =IF(AND(ISNUMBER(G27),ISNUMBER(I27)),G27/I27,"n/d") -> 2600 | U27: =IF(AND(ISNUMBER(S27),ISNUMBER(W27)),ROUND(W27-S27,2),IF(AND(ISNUMBER(R27),ISNUMBER(V27)),ROUND(V27-R27,2),"")) | V27: =IF(AND(ISNUMBER(Q27),ISNUMBER(J27)),Q27/J27,"n/d") -> n/d | W27: =IF(AND(ISNUMBER(Q27),ISNUMBER(L27)),Q27/L27,"n/d") -> n/d | X27: =IF(AND(ISNUMBER(G27),ISNUMBER(I27),ISNUMBER(O27)),G27*1000000/(O27*I27*8760),"n/d") -> n/d | Y27: DCD citing Bloomberg (private_peers C17)
A28: NEW7 | B28: New | C28: Crusoe | D28: Meta | E28: Neocloud-hyperscaler | F28: 2026-06-19 (press) | G28: n/d | J28: 1600 | K28: unlabeled (Childress TX + Warrenton MO) | N28: n/d | Q28: =IF(AND(ISNUMBER(G28),ISNUMBER(I28)),G28/I28,"n/d") -> n/d | U28: =IF(AND(ISNUMBER(S28),ISNUMBER(W28)),ROUND(W28-S28,2),IF(AND(ISNUMBER(R28),ISNUMBER(V28)),ROUND(V28-R28,2),"")) | V28: =IF(AND(ISNUMBER(Q28),ISNUMBER(J28)),Q28/J28,"n/d") -> n/d | W28: =IF(AND(ISNUMBER(Q28),ISNUMBER(L28)),Q28/L28,"n/d") -> n/d | X28: =IF(AND(ISNUMBER(G28),ISNUMBER(I28),ISNUMBER(O28)),G28*1000000/(O28*I28*8760),"n/d") -> n/d | Y28: DCD citing Bloomberg (private_peers C14) | Z28: Value/term n/d.
A29: NEW8 | B29: New | C29: Crusoe | D29: Microsoft (Abilene 900 MW campus) | E29: Neocloud-hyperscaler | F29: 2026-03-27 | G29: n/d | J29: 900 | K29: gross (2 x 336 MW IT = 672 IT) | L29: 672 | M29: R | N29: n/d | Q29: =IF(AND(ISNUMBER(G29),ISNUMBER(I29)),G29/I29,"n/d") -> n/d | U29: =IF(AND(ISNUMBER(S29),ISNUMBER(W29)),ROUND(W29-S29,2),IF(AND(ISNUMBER(R29),ISNUMBER(V29)),ROUND(V29-R29,2),"")) | V29: =IF(AND(ISNUMBER(Q29),ISNUMBER(J29)),Q29/J29,"n/d") -> n/d | W29: =IF(AND(ISNUMBER(Q29),ISNUMBER(L29)),Q29/L29,"n/d") -> n/d | X29: =IF(AND(ISNUMBER(G29),ISNUMBER(I29),ISNUMBER(O29)),G29*1000000/(O29*I29*8760),"n/d") -> n/d | Y29: Crusoe PR 2026-03-27 (private_peers C13) | Z29: First building mid-2027; value n/d.
