Workbook

Sheet Comparison
A1: Peer Comparison - Nebius vs CoreWeave, IREN (AI Cloud), Oracle OCI, Nscale, Lambda, Crusoe. Template KPI IDs/definitions (peers/coreweave/crwv_kpis.xlsx 'Definitions'; K41-K45 in peers/peer_kpi_template.py). Latest available period per peer; as-of shown per cell. Nebius cells are formulas on Nebius_Inputs. Private-peer values from peers/private/private_peers_values.json (Summary) with their tags. Built 2026-10-04 ET; v0.9e refresh 2026-10-08 ET by peers/build_comparison.py (Nebius_Inputs locks from model v0.9e: billed IT MW YE26 258 base / 284 high; FY27 avg 531.8 base / 659.2 high, engine-linked. Shares: 358.56M with new converts as debt (< $313) / 376.65M if-converted (> $325). Next Nebius print: Q3'26 results ~Nov 10 (est.) - date not announced by the company.
A3: ID | B3: KPI | C3: Unit | D3: Nebius | E3: Tag | F3: As of | G3: CoreWeave | H3: Tag | I3: As of | J3: IREN | K3: Tag | L3: As of | M3: Oracle OCI | N3: Tag | O3: As of | P3: Nscale | Q3: Tag | R3: As of | S3: Lambda | T3: Tag | U3: As of | V3: Crusoe | W3: Tag | X3: As of | Y3: Peer median (formula; comparable peers) | Z3: Nebius better / worse | AA3: Reason (auto numbers + interpretation) | AB3: Nebius basis note | AC3: Peer basis comment
A4: K01 | B4: Revenue per active MW - period-end reported MW | C4: $M/MW-yr | D4: =Nebius_Inputs!$C$4*4/Nebius_Inputs!$C$20 -> 11.915026 | E4: E | F4: Jun-26 | G4: 6.8666667 | H4: Derived | I4: Jun-26 | J4: 7.0515 | K4: Derived | L4: Jun-26 | M4: n/d | N4: n/d | P4: 3.4716049 | Q4: D | R4: 2026-06-30 | S4: 9.7021277 | T4: D (inputs P) | U4: 2025-06-30 | V4: 2 | W4: E (inputs P/R) | X4: 2026-09-17 | Y4: =MEDIAN(G4,J4,P4,S4,V4) -> 6.8666667 | Z4: Better | AA4: Nebius 11.92 vs peer median 6.87 (range Crusoe 2.00 - Lambda 9.70; n=5); higher revenue density per energized MW (Nebius MW is a Capacity estimate; mixed IT/gross basis) | AB4: Q2'26 AI cloud rev x4 / Jun-26 energized MW (193, Capacity base case, E) | AC4: Basis differs: CRWV IT-like active MW; IREN 40 MW AI (basis unstated); Oracle no installed MW; Nscale IT MW at 5 active sites (H1'26 x2); Lambda Q2'25 (press MW); Crusoe FY26E rev / ~1 GW GROSS.
A5: K02 | B5: Revenue per active MW - average MW (2024 uses interpolated MW) | C5: $M/MW-yr | D5: =Nebius_Inputs!$C$4*4/AVERAGE(Nebius_Inputs!$C$19,Nebius_Inputs!$C$20) -> 12.280908 | E5: E | F5: Jun-26 | G5: 8.24 | H5: Derived | I5: Jun-26 | J5: 10.476822 | K5: Estimated | L5: Sep-25 | M5: n/d | N5: n/d | P5: n/d | Q5: n/d | S5: n/d | T5: n/d | V5: n/d | W5: n/d | Y5: =MEDIAN(G5,J5) -> 9.358411 | Z5: Better | AA5: Nebius 12.28 vs peer median 9.36 (range CoreWeave 8.24 - IREN 10.48; n=2); same on average MW - the fixed, comparable figure; Blackwell-heavy, mostly new fleet lifts density | AB5: average energized MW (181.5+193)/2 = 187.25 (Capacity base case, E); replaces old 13.7 on stale YE25 170 MW
A6: K02b | B6: Revenue per BILLING IT MW - average MW (billed-IT basis; Nebius = Capacity billing path) | C6: $M/MW-yr | D6: =Nebius_Inputs!$C$4*4/AVERAGE(Nebius_Inputs!$C$42,Nebius_Inputs!$C$43) -> 13.055448 | E6: E | F6: Jun-26 | G6: 8.24 | H6: Derived | I6: Jun-26 | J6: n/d | K6: n/d | M6: n/d | N6: n/d | P6: n/d | Q6: n/d | S6: n/d | T6: n/d | V6: n/d | W6: n/d | Y6: =MEDIAN(G6) -> 8.24 | Z6: Better | AA6: Nebius 13.06 vs peer median 8.24 (range CoreWeave 8.24 - CoreWeave 8.24; n=1); same numerator on average BILLING IT MW (billed-IT basis; Nebius Capacity billing path, CoreWeave active~billed) - the basis the v0.9e Judge slide / Drivers use for $/billed MW | AB6: BILLED-IT basis: Q2'26 AI cloud rev x4 / AVERAGE(Capacity billing IT MW Q1'26, Q2'26) (row 147; Vineland billed tranches + other sites lagged 1Q). Not energized/gross MW. Same billed-IT basis as the forward $/billed MW memo (YE26 258/284; FY27 avg 531.8/659.2 engine-linked; model v0.9e - see Nebius_Inputs). | AC6: CoreWeave K02b = K02 per crwv_kpis.xlsx K02b row (active power ~ billed; no separate billing series). IREN/Oracle/Nscale/Lambda/Crusoe disclose no billed-MW series -> n/d (not inferred). Median n=1: treat as directional.
A7: K03 | B7: Revenue per contracted MW | C7: $M/MW-yr | D7: =Nebius_Inputs!$C$4*4/Nebius_Inputs!$C$22 -> 0.65702857 | E7: D | F7: Jun-26 | G7: 2.7837838 | H7: Derived | I7: Jun-26 | J7: n/d | K7: n/d | M7: n/d | N7: n/d | P7: 0.20525547 | Q7: D | R7: 2026-08-31 | S7: n/d | T7: n/d | V7: 0.33333333 | W7: E (inputs P/R) | X7: 2026-09-17 | Y7: =MEDIAN(G7,P7,V7) -> 0.33333333 | Z7: Better | AA7: Nebius 0.66 vs peer median 0.33 (range Nscale 0.21 - CoreWeave 2.78; n=3); monetises contracted power faster? Nebius has far more unbuilt contracted MW than CRWV | AB7: >3.5 GW is a lower bound -> value is an upper bound
A8: K04 | B8: Contracted / active MW (build-out multiple) | C8: x | D8: =Nebius_Inputs!$C$22/Nebius_Inputs!$C$20 -> 18.134715 | E8: E | F8: Jun-26 | G8: 2.4666667 | H8: Derived | I8: Jun-26 | J8: n/d | K8: n/d | M8: n/d | N8: n/d | P8: 16.91358 | Q8: D | R8: 2026-08-31 | S8: n/d | T8: n/d | V8: 6 | W8: D | X8: 2026-09-17 | Y8: =MEDIAN(G8,P8,V8) -> 6 | Z8: Context | AA8: Nebius 18.13 vs peer median 6.00 (range CoreWeave 2.47 - Nscale 16.91; n=3); build-out multiple: big growth runway but heavy execution/funding need (context, not scored)
A9: K05 | B9: Adj. EBITDA per active MW (average MW) | C9: $M/MW-yr | D9: =Nebius_Inputs!$C$7*4/AVERAGE(Nebius_Inputs!$C$19,Nebius_Inputs!$C$20) -> 6.1030708 | E9: E | F9: Jun-26 | G9: 4.832 | H9: Derived | I9: Jun-26 | J9: n/d | K9: n/d | M9: n/d | N9: n/d | P9: -4.9185185 | Q9: D | R9: 2026-06-30 | S9: n/d | T9: n/d | V9: n/d | W9: n/d | Y9: =MEDIAN(G9,P9) -> -0.043259259 | Z9: Better | AA9: Nebius 6.10 vs peer median -0.04 (range Nscale -4.92 - CoreWeave 4.83; n=2); segment adj. EBITDA per MW well above CRWV-style peers | AB9: AI cloud segment adj. EBITDA
A10: K06 | B10: Revenue per GPU ($K per GPU-year, avg GPUs) | C10: $K/GPU-yr | D10: =Nebius_Inputs!$C$4*4000/Nebius_Inputs!$C$23 -> 26.512025 | E10: E | F10: Jun-26 | G10: 14.506634 | H10: Estimated | I10: Jun-26 | J10: 14.694 | K10: Derived | L10: Sep-25 | M10: n/d | N10: n/d | P10: 11.248 | Q10: E | R10: 2026-06-30 | S10: 18.24 | T10: E (inputs P/R) | U10: 2025-06-30 | V10: n/d | W10: n/d | Y10: =MEDIAN(G10,J10,P10,S10) -> 14.600317 | Z10: Better | AA10: Nebius 26.51 vs peer median 14.60 (range Nscale 11.25 - Lambda 18.24; n=4); revenue per (modeled) GPU | AB10: modeled GPUs | AC10: IREN latest Q3'25. Lambda/Nscale ESTIMATED from GPU counts.
A11: K07 | B11: Implied blended realized price ($/GPU-hr) | C11: $/GPU-hr | D11: =Nebius_Inputs!$C$4*1000000/(Nebius_Inputs!$C$23*Nebius_Inputs!$C$24*24) -> 3.0348014 | E11: E | F11: Jun-26 | G11: 1.6605579 | H11: Estimated | I11: Jun-26 | J11: 1.6637228 | K11: Derived | L11: Sep-25 | M11: n/d | N11: n/d | P11: 1.2946593 | Q11: E | R11: 2026-06-30 | S11: 2.0879121 | T11: E (inputs P/R) | U11: 2025-06-30 | V11: n/d | W11: n/d | Y11: =MEDIAN(G11,J11,P11,S11) -> 1.6621404 | Z11: Better | AA11: Nebius 3.03 vs peer median 1.66 (range Nscale 1.29 - Lambda 2.09; n=4); realized $/GPU-hr above peers (modeled GPU base; includes non-GPU revenue) | AB11: incl. non-GPU-hour revenue | AC11: Nebius realized $3.29 includes non-GPU-hour revenue and uses modeled GPUs.
A12: K08 | B12: Fleet-weighted on-demand list price ($/GPU-hr) | C12: $/GPU-hr | D12: =Nebius_Inputs!$C$25 -> 5.6063348 | E12: E | F12: Jun-26 | G12: 9.1956182 | H12: Estimated | I12: Jun-26 | J12: 2 | K12: Estimated | L12: Sep-25 | M12: n/d | N12: n/d | P12: n/d | Q12: n/d | S12: 2.99 | T12: R | U12: 2025-06-16 | V12: 3.9 | W12: R | X12: 2026-10-04 | Y12: =MEDIAN(G12,J12,S12,V12) -> 3.445 | Z12: Context | AA12: Nebius 5.61 vs peer median 3.45 (range IREN 2.00 - CoreWeave 9.20; n=4); list-price context
A13: K09 | B13: Implied utilization (realized $/GPU-hr / weighted list) | C13: % | D13: =Nebius_Inputs!$C$4*1000000/(Nebius_Inputs!$C$23*Nebius_Inputs!$C$24*24)/Nebius_Inputs!$C$25*100 -> 54.131647 | E13: E | F13: Jun-26 | G13: 18.058143 | H13: Estimated | I13: Jun-26 | J13: 83.186141 | K13: Estimated | L13: Sep-25 | M13: n/d | N13: n/d | P13: n/d | Q13: n/d | S13: 69.829836 | T13: E (inputs P/R) | U13: 2025-06-30 | V13: n/d | W13: n/d | Y13: =MEDIAN(G13,S13) -> 43.943989 | Z13: Better | AA13: Nebius 54.13 vs peer median 43.94 (range CoreWeave 18.06 - Lambda 69.83; n=2); price-based 'utilization' (mixes discount with use); not physical utilization | AC13: Not like-for-like (see NONCOMP list in README).; Excluded from median: IREN: vs IREN's own $2.00 assumption, not list
A14: K10 | B14: Cash capex per new active MW (reported MW) | C14: $M/MW | D14: n.m. | E14: n.m. | F14: Jun-26 | G14: 12.844 | H14: Derived | I14: Jun-26 | J14: n/d | K14: n/d | M14: 56.872414 | N14: Estimated | O14: May-26 (FQ4 FY26) | P14: n/d | Q14: n/d | S14: n/d | T14: n/d | V14: n/d | W14: n/d | Y14: =MEDIAN(G14,M14) -> 34.858207 | Z14: n/a | AA14: Nebius n/d. single-quarter capex/MW not meaningful for Nebius (+1.5 MW) | AB14: MW added in Q2'26 only +1.5 (Capacity est.) -> not meaningful
A15: K12 | B15: In-service additions per new active MW (CRWV capex definition) | C15: $M/MW | D15: =(Nebius_Inputs!$C$39-Nebius_Inputs!$C$38)/(Nebius_Inputs!$C$41-Nebius_Inputs!$C$40) -> 19.68069 | E15: E | F15: Dec-25 (FY25) | G15: 18.704 | H15: Derived | I15: Jun-26 | J15: n/d | K15: n/d | M15: n/d | N15: n/d | P15: n/d | Q15: n/d | S15: n/d | T15: n/d | V15: n/d | W15: n/d | Y15: =MEDIAN(G15) -> 18.704 | Z15: In line | AA15: Nebius 19.68 vs peer median 18.70 (range CoreWeave 18.70 - CoreWeave 18.70; n=1); in-service $ per MW added (FY25 basis for Nebius) | AB15: FY25 basis; quarterly n.m.
A16: K13 | B16: Trailing-4Q cash capex per trailing-4Q new active MW | C16: $M/MW | D16: =SUM(Nebius_Inputs!$C$9,Nebius_Inputs!$C$10,Nebius_Inputs!$C$11,Nebius_Inputs!$C$12)/(Nebius_Inputs!$C$20-Nebius_Inputs!$C$18) -> 77.914685 | E16: E | F16: Jun-26 | G16: 19.966602 | H16: Derived | I16: Jun-26 | J16: n/d | K16: n/d | M16: 46.385833 | N16: Estimated | O16: May-26 (FQ4 FY26) | P16: n/d | Q16: n/d | S16: n/d | T16: n/d | V16: n/d | W16: n/d | Y16: =MEDIAN(G16,M16) -> 33.176218 | Z16: Worse | AA16: Nebius 77.91 vs peer median 33.18 (range CoreWeave 19.97 - Oracle OCI 46.39; n=2); capex per MW added is high because capex funds 2027 capacity (not-yet-in-use $7.8B) | AB16: capex funds future (not-yet-in-use) capacity -> inflated | AC16: Oracle FY26 capex / delivered MW (E). Nscale/Lambda/Crusoe n/d.
A17: K14 | B17: Net PP&E per active MW (EoP) | C17: $M/MW | D17: =Nebius_Inputs!$C$13/Nebius_Inputs!$C$20 -> 67.59171 | E17: E | F17: Jun-26 | G17: 31.157333 | H17: Derived | I17: Jun-26 | J17: n/d | K17: n/d | M17: n/d | N17: n/d | P17: 70.709877 | Q17: D | R17: 2026-06-30 | S17: n/d | T17: n/d | V17: 12.5 | W17: D | X17: 2025-05-21 | Y17: =MEDIAN(G17,P17) -> 50.933605 | Z17: Worse | AA17: Nebius 67.59 vs peer median 50.93 (range CoreWeave 31.16 - Nscale 70.71; n=2); net PP&E per active MW inflated by construction-in-progress | AB17: incl. $7.8B not yet in use | AC17: Crusoe 12.5 = Abilene JV shell+power only (excluded from median).; Excluded from median: Crusoe: shell+power only (ex-GPU)
A18: K15 | B18: Gross in-service PP&E per active MW (EoP) | C18: $M/MW | D18: =Nebius_Inputs!$C$15/Nebius_Inputs!$C$20 -> 32.710363 | E18: E | F18: Jun-26 | G18: 27.136 | H18: Derived | I18: Jun-26 | J18: n/d | K18: n/d | M18: n/d | N18: n/d | P18: 20.825926 | Q18: D | R18: 2026-06-30 | S18: n/d | T18: n/d | V18: n/d | W18: n/d | Y18: =MEDIAN(G18,P18) -> 23.980963 | Z18: Worse | AA18: Nebius 32.71 vs peer median 23.98 (range Nscale 20.83 - CoreWeave 27.14; n=2); gross in-service PP&E per MW
A19: K16 | B19: Useful life - technology equipment (GPUs/servers/network) | C19: years | D19: =Nebius_Inputs!$C$32 -> 5 | E19: R | F19: Jun-26 | G19: 6 | H19: Reported | I19: Jun-26 | J19: 5 | K19: Reported | L19: Jun-26 | M19: 6 | N19: Reported | O19: May-26 (FQ4 FY26) | P19: 5.5 | Q19: R | R19: 2026-06-30 | S19: n/d | T19: n/d | V19: n/d | W19: n/d | Y19: =MEDIAN(G19,J19,M19,P19) -> 5.75 | Z19: Better | AA19: Nebius 5.00 vs peer median 5.75 (range IREN 5.00 - CoreWeave 6.00; n=4); shorter life = more conservative accounting (Nebius moved 4->5 yrs in 2026; CRWV/Oracle 6) | AC19: Lives: CRWV 6, Oracle 6, Nscale 5-6, IREN 5, Nebius 5 (from 2026).
A20: K17 | B20: Depreciation yield (D&A x4 / avg in-service gross PP&E) | C20: % | D20: =Nebius_Inputs!$C$8*4/AVERAGE(Nebius_Inputs!$C$14,Nebius_Inputs!$C$15)*100 -> 17.515048 | E20: D | F20: Jun-26 | G20: 15.465749 | H20: Derived | I20: Jun-26 | J20: 14.351359 | K20: Derived | L20: Jun-26 | M20: 13.449246 | N20: Derived | O20: Aug-26 (FQ1 FY27) | P20: 15.670891 | Q20: D | R20: 2026-06-30 | S20: n/d | T20: n/d | V20: n/d | W20: n/d | Y20: =MEDIAN(G20,J20,M20,P20) -> 14.908554 | Z20: Better | AA20: Nebius 17.52 vs peer median 14.91 (range Oracle OCI 13.45 - Nscale 15.67; n=4); higher depreciation yield = more conservative | AB20: group D&A incl. amortization | AC20: IREN incl. mining hardware; Oracle Aug-26 quarter; Nscale H1'26.
A21: K18 | B21: Implied average depreciable life (1 / yield) | C21: years | D21: =100/(Nebius_Inputs!$C$8*4/AVERAGE(Nebius_Inputs!$C$14,Nebius_Inputs!$C$15)*100) -> 5.7093762 | E21: D | F21: Jun-26 | G21: 6.4659009 | H21: Derived | I21: Jun-26 | J21: 6.967981 | K21: Derived | L21: Jun-26 | M21: 7.4353612 | N21: Derived | O21: Aug-26 (FQ1 FY27) | P21: 6.381258 | Q21: D | R21: 2026-06-30 | S21: n/d | T21: n/d | V21: n/d | W21: n/d | Y21: =MEDIAN(G21,J21,M21,P21) -> 6.716941 | Z21: Better | AA21: Nebius 5.71 vs peer median 6.72 (range Nscale 6.38 - Oracle OCI 7.44; n=4); lower implied life = more conservative | AC21: CoreWeave K18 read straight from crwv_kpis.xlsx K18 (= 100/K17; pack fixed 2026-10-08 - was 100/K16 = 16.67 after its K02b row insert). Build asserts K18 = 100/K17 in every public pack.
A22: K19 | B22: D&A as % of revenue | C22: % | D22: =Nebius_Inputs!$C$8/Nebius_Inputs!$C$4*100 -> 45.173074 | E22: D | F22: Jun-26 | G22: 54.097087 | H22: Derived | I22: Jun-26 | J22: 81.677537 | K22: Derived | L22: Jun-26 | M22: 12.588616 | N22: Derived | O22: May-26 (FQ4 FY26) | P22: 123.75533 | Q22: D | R22: 2026-06-30 | S22: n/d | T22: n/d | V22: n/d | W22: n/d | Y22: =MEDIAN(G22,J22,M22,P22) -> 67.887312 | Z22: Context | AA22: Nebius 45.17 vs peer median 67.89 (range Oracle OCI 12.59 - Nscale 123.76; n=4); D&A burden context | AB22: group D&A / AI cloud revenue
A23: K20 | B23: RPO (ASC 606, EoP) | C23: $B | D23: =Nebius_Inputs!$C$26/1000 -> 37.4906 | E23: R | F23: Jun-26 | G23: 103.7 | H23: Reported | I23: Jun-26 | J23: 5.1 | K23: Reported | L23: Jun-26 | M23: 638 | N23: Reported | O23: May-26 (FQ4 FY26) | P23: 56.4 | Q23: R | R23: 2026-06-30 | S23: n/d | T23: n/d | V23: n/d | W23: n/d | Y23: =MEDIAN(G23,J23,M23,P23) -> 80.05 | Z23: Context | AA23: Nebius 37.49 vs peer median 80.05 (range IREN 5.10 - Oracle OCI 638.00; n=4); absolute size context | AC23: Oracle RPO is company-wide incl. SaaS.
A24: K21 | B24: Revenue backlog (company metric, EoP) | C24: $B | D24: n/d | E24: n/d | G24: 104.2 | H24: Reported | I24: Jun-26 | J24: 16.6 | K24: Reported | L24: Jun-26 | M24: n/d | N24: n/d | P24: 103.4 | Q24: R | R24: 2026-08-31 | S24: 50 | T24: P | U24: 2026-09-30 | V24: 140 | W24: R | X24: 2026-09-17 | Y24: =MEDIAN(G24,J24,P24,S24) -> 76.7 | Z24: n/a | AA24: Nebius n/d. company backlog metric (context) | AB24: Not disclosed in Nebius filings / not computable on the same definition | AC24: Crusoe/Nscale company TCV metrics (not ASC 606).; Excluded from median: Crusoe: company TCV metric
A25: K22 | B25: RPO % recognized within 24 months | C25: % | D25: =Nebius_Inputs!$C$27 -> 36 | E25: R | F25: Jun-26 | G25: 41 | H25: Reported | I25: Jun-26 | J25: 43.1 | K25: Derived | L25: Jun-26 | M25: 29 | N25: Estimated | O25: May-26 (FQ4 FY26) | P25: 16 | Q25: R | R25: 2025-12-31 | S25: n/d | T25: n/d | V25: n/d | W25: n/d | Y25: =MEDIAN(G25,J25,M25,P25) -> 35 | Z25: In line | AA25: Nebius 36.00 vs peer median 35.00 (range Nscale 16.00 - IREN 43.10; n=4); share of RPO converting within 24m
A26: K23 | B26: RPO / annualized quarterly revenue | C26: years | D26: =Nebius_Inputs!$C$26/(Nebius_Inputs!$C$4*4) -> 16.303096 | E26: D | F26: Jun-26 | G26: 10.067961 | H26: Derived | I26: Jun-26 | J26: 18.081259 | K26: Derived | L26: Jun-26 | M26: 8.3142202 | N26: Derived | O26: May-26 (FQ4 FY26) | P26: 200.56899 | Q26: D | R26: 2026-06-30 | S26: n/d | T26: n/d | V26: n/d | W26: n/d | Y26: =MEDIAN(G26,J26,M26,P26) -> 14.07461 | Z26: In line | AA26: Nebius 16.30 vs peer median 14.07 (range Oracle OCI 8.31 - Nscale 200.57; n=4); backlog coverage of current run-rate | AC26: Nscale 201 yrs: tiny H1'26 revenue vs $56.4B RPO (pre-ramp).
A27: K24 | B27: Largest customer % of revenue | C27: % | D27: =Nebius_Inputs!$C$28 -> 24 | E27: R | F27: Jun-26 | G27: 36 | H27: Reported | I27: Jun-26 | J27: n/d | K27: n/d | M27: n/d | N27: n/d | P27: 52 | Q27: R | R27: 2026-06-30 | S27: n/d | T27: n/d | V27: n/d | W27: n/d | Y27: =MEDIAN(G27,P27) -> 44 | Z27: Better | AA27: Nebius 24.00 vs peer median 44.00 (range CoreWeave 36.00 - Nscale 52.00; n=2); lower concentration is better | AB27: Customer C (unnamed) | AC27: Nscale H1'26 largest customer 52%. Lambda: Amazon+Microsoft 50% (K26, press).
A28: K25 | B28: 2nd-largest customer % | C28: % | D28: =Nebius_Inputs!$C$29 -> 21 | E28: R | F28: Jun-26 | G28: 26 | H28: Reported | I28: Jun-26 | J28: n/d | K28: n/d | M28: n/d | N28: n/d | P28: n/d | Q28: n/d | S28: n/d | T28: n/d | V28: n/d | W28: n/d | Y28: =MEDIAN(G28) -> 26 | Z28: Better | AA28: Nebius 21.00 vs peer median 26.00 (range CoreWeave 26.00 - CoreWeave 26.00; n=1); lower is better
A29: K26 | B29: Top-N >=10% customers combined % | C29: % | D29: =Nebius_Inputs!$C$28+Nebius_Inputs!$C$29+Nebius_Inputs!$C$30 -> 59 | E29: R | F29: Jun-26 | G29: 72 | H29: Reported | I29: Jun-26 | J29: n/d | K29: n/d | M29: n/d | N29: n/d | P29: n/d | Q29: n/d | S29: 50 | T29: P | U29: 2025-06-30 | V29: n/d | W29: n/d | Y29: =MEDIAN(G29,S29) -> 61 | Z29: In line | AA29: Nebius 59.00 vs peer median 61.00 (range Lambda 50.00 - CoreWeave 72.00; n=2); lower combined concentration is better
A30: K27 | B30: Number of customers >=10% of revenue | C30: # | D30: =Nebius_Inputs!$C$31 -> 3 | E30: R | F30: Jun-26 | G30: 3 | H30: Reported | I30: Jun-26 | J30: n/d | K30: n/d | M30: 0 | N30: Reported | O30: May-26 (FQ4 FY26) | P30: n/d | Q30: n/d | S30: n/d | T30: n/d | V30: n/d | W30: n/d | Y30: =MEDIAN(G30,M30) -> 1.5 | Z30: Worse | AA30: Nebius 3.00 vs peer median 1.50 (range Oracle OCI 0.00 - CoreWeave 3.00; n=2); fewer >=10% customers is better
A31: K28 | B31: Weighted effective cost of debt (principal-weighted, EoP) - all facilities | C31: % | D31: =Nebius_Inputs!$C$33 -> 5.1 | E31: D | F31: Jun-26 | G31: 8.4134342 | H31: Derived | I31: Jun-26 | J31: 1.8523437 | K31: Derived | L31: Jun-26 | M31: 4.8282005 | N31: Derived | O31: May-26 (FQ4 FY26) | P31: 18.726841 | Q31: D | R31: 2026-06-30 | S31: n/d | T31: n/d | V31: n/d | W31: n/d | Y31: =MEDIAN(G31,J31,M31) -> 4.8282005 | Z31: In line | AA31: Nebius 5.10 vs peer median 4.83 (range IREN 1.85 - CoreWeave 8.41; n=3); cheaper debt (converts-heavy) is better | AC31: Nscale 18.7% on legacy $137M (excluded from median); marginal secured: Nscale ~6.25% E, Lambda 6.78% R, Crusoe ~9.1% E (PX09).; Excluded from median: Nscale: legacy $137M debt; marginal secured ~6.25% E (PX09)
A32: K29 | B32: of which DDTL - weighted eff. rate | C32: % | D32: n/d | E32: n/d | G32: 9.6234699 | H32: Derived | I32: Jun-26 | J32: 7.12 | K32: Derived | L32: Jun-26 | M32: n/d | N32: n/d | P32: 11.3 | Q32: R | R32: 2026-06-30 | S32: 6.78 | T32: R | U32: 2026-10-01 | V32: 9.1021429 | W32: E (inputs P) | X32: 2026-09-10 | Y32: =MEDIAN(G32,J32,P32,S32,V32) -> 9.1021429 | Z32: n/a | AA32: Nebius n/d. facility-level rate (context) | AB32: Not disclosed in Nebius filings / not computable on the same definition
A33: K34 | B33: of which Other term loans - weighted eff. rate | C33: % | D33: n/d | E33: n/d | G33: 12 | H33: Derived | I33: Jun-26 | J33: n/d | K33: n/d | M33: 5.29 | N33: Derived | O33: May-26 (FQ4 FY26) | P33: 22.74 | Q33: R | R33: 2026-06-30 | S33: n/d | T33: n/d | V33: 6 | W33: P | X33: 2026-02-20 | Y33: =MEDIAN(G33,M33,P33,V33) -> 9 | Z33: n/a | AA33: Nebius n/d. facility-level rate (context) | AB33: Not disclosed in Nebius filings / not computable on the same definition
A34: K35 | B34: DDTL (secured asset-level) share of principal | C34: % | D34: n/d | E34: n/d | G34: 38.375854 | H34: Derived | I34: Jun-26 | J34: 5.3597043 | K34: Derived | L34: Jun-26 | M34: 0 | N34: Derived | O34: May-26 (FQ4 FY26) | P34: 35.080058 | Q34: D | R34: 2026-06-30 | S34: n/d | T34: n/d | V34: n/d | W34: n/d | Y34: =MEDIAN(G34,J34,M34,P34) -> 20.219881 | Z34: n/a | AA34: Nebius n/d. structure context | AB34: Not disclosed in Nebius filings / not computable on the same definition
A35: K36 | B35: Implied cash cost: contractual interest x4 / avg principal | C35: % | D35: =Nebius_Inputs!$C$34*4/AVERAGE(Nebius_Inputs!$C$36,Nebius_Inputs!$C$37)*100 -> 5.605992 | E35: D | F35: Jun-26 | G35: 7.8023064 | H35: Derived | I35: Jun-26 | J35: 1.7092136 | K35: Derived | L35: Jun-26 | M35: 4.3551672 | N35: Derived | O35: May-26 (FQ4 FY26) | P35: 22.191401 | Q35: D | R35: 2026-06-30 | S35: n/d | T35: n/d | V35: n/d | W35: n/d | Y35: =MEDIAN(G35,J35,M35,P35) -> 6.0787368 | Z35: In line | AA35: Nebius 5.61 vs peer median 6.08 (range IREN 1.71 - Nscale 22.19; n=4); lower cash cost of debt is better | AB35: P&L interest (incl. convert accretion) / avg carrying debt | AC35: IREN finance expense incl. amortization; Oracle interest/avg carrying.
A36: K37 | B36: Company-reported weighted average interest rate | C36: % | D36: n/d | E36: n/d | G36: 8.3 | H36: Reported | I36: Jun-26 | J36: n/d | K36: n/d | M36: n/d | N36: n/d | P36: n/d | Q36: n/d | S36: n/d | T36: n/d | V36: n/d | W36: n/d | Y36: =MEDIAN(G36) -> 8.3 | Z36: n/a | AA36: Nebius n/d. company-reported rate | AB36: Not disclosed in Nebius filings / not computable on the same definition
A37: K38 | B37: Total debt principal (EoP) | C37: $B | D37: =Nebius_Inputs!$C$37/1000 -> 8.5457 | E37: R | F37: Jun-26 | G37: 35.551 | H37: Reported | I37: Jun-26 | J37: 7.705649 | K37: Reported | L37: Jun-26 | M37: 129.541 | N37: Reported | O37: May-26 (FQ4 FY26) | P37: 0.1374 | Q37: D | R37: 2026-06-30 | S37: n/d | T37: n/d | V37: n/d | W37: n/d | Y37: =MEDIAN(G37,J37,M37,P37) -> 21.628325 | Z37: Context | AA37: Nebius 8.55 vs peer median 21.63 (range Nscale 0.14 - Oracle OCI 129.54; n=4); size context | AB37: carrying value (not principal)
A38: K39 | B38: Debt principal / RPO | C38: x | D38: =Nebius_Inputs!$C$37/Nebius_Inputs!$C$26 -> 0.22794247 | E38: D | F38: Jun-26 | G38: 0.34282546 | H38: Derived | I38: Jun-26 | J38: 1.5109116 | K38: Derived | L38: Jun-26 | M38: 0.20304232 | N38: Derived | O38: May-26 (FQ4 FY26) | P38: 0.0024361702 | Q38: D | R38: 2026-06-30 | S38: n/d | T38: n/d | V38: n/d | W38: n/d | Y38: =MEDIAN(G38,J38,M38,P38) -> 0.27293389 | Z38: In line | AA38: Nebius 0.23 vs peer median 0.27 (range Nscale 0.00 - IREN 1.51; n=4); lower debt per $ of backlog is better
A39: K40 | B39: Capitalized interest % of contractual interest | C39: % | D39: =Nebius_Inputs!$C$35/(Nebius_Inputs!$C$34+Nebius_Inputs!$C$35)*100 -> 25.235405 | E39: D | F39: Jun-26 | G39: 13.344595 | H39: Reported | I39: Jun-26 | J39: n/d | K39: n/d | M39: n/d | N39: n/d | P39: 0 | Q39: D | R39: 2026-06-30 | S39: n/d | T39: n/d | V39: n/d | W39: n/d | Y39: =MEDIAN(G39,P39) -> 6.6722973 | Z39: Worse | AA39: Nebius 25.24 vs peer median 6.67 (range Nscale 0.00 - CoreWeave 13.34; n=2); high capitalized share flatters P&L interest
A40: K41 | B40: Company-reported GPU utilization (physical) | C40: % | D40: n/d | E40: n/d | G40: n/d | H40: n/d | J40: n/d | K40: n/d | M40: 97.5 | N40: Reported | O40: May-26 (FQ4 FY26) | P40: n/d | Q40: n/d | S40: n/d | T40: n/d | V40: n/d | W40: n/d | Y40: =MEDIAN(M40) -> 97.5 | Z40: n/a | AA40: Nebius n/d. physical utilization (Oracle only) | AB40: Not disclosed in Nebius filings / not computable on the same definition
A41: K42 | B41: RPO % recognized within 12 months | C41: % | D41: n/d | E41: n/d | G41: n/d | H41: n/d | J41: 17.6 | K41: Derived | L41: Jun-26 | M41: 12 | N41: Reported | O41: May-26 (FQ4 FY26) | P41: n/d | Q41: n/d | S41: n/d | T41: n/d | V41: n/d | W41: n/d | Y41: =MEDIAN(J41,M41) -> 14.8 | Z41: n/a | AA41: Nebius n/d. n/d for Nebius (24m bucket only) | AB41: Not disclosed in Nebius filings / not computable on the same definition
...

Sheet README
A1: Peer comparison workbook (step 5, final) - built 2026-10-04 ET; v0.9d REFRESH 2026-10-05 ET; share-basis / K18 refresh 2026-10-08 ET; MODEL v0.9e LOCK REFRESH 2026-10-08 ~10:00 ET (prior pack kept as peers/comparison_pre_v09e_backup.xlsx) by /workspace/nebius/peers/build_comparison.py (prior pack 08:31 ET kept as peers/comparison_0831_prev.xlsx; 10-05 pack as peers/comparison_pre_oct8_backup.xlsx)
A2: Tabs: Comparison (7 companies x 40 template KPIs, value/tag/as-of, peer median, Nebius better/worse + reason) | Ranking | Nebius_Inputs (sources; Comparison Nebius cells are live formulas) | Contracts_$MWyr | Sites | Chart_Data + Charts (native Excel) | Peer_memos.
A3: Tags: R Reported, P Press-reported (new, private peers), D Derived, E Estimated, n/d not disclosed, n.m. not meaningful. Derived tag = weakest input. Private-peer composite tags kept verbatim.
A4: Nebius rev/MW FIX: old Comparison K01 13.7 = Q2'26 group revenue x4 / YE25 170 MW (stale). Now K01 = AI cloud revenue x4 / Jun-26 energized 193 MW = 11.92 E and K02 = x4 / AVERAGE(181.5, 193) = 12.28 E (switched Oct 8 ~23:30 ET from v1 173 / 171.5) (Capacity & Power base case incl. plug; identified sites 152-194 at Jun-26). Same definitions as peers' K01/K02.
A5: Inputs read (not edited): peers/coreweave|iren|oracle/*_kpis.xlsx; peers/private/private_peers_values.json; parts/contract_economics.xlsx (GPU Market agent's contract table - market/ and nebius_market.xlsx hold no contract data); filings/nebius_filings.xlsx + nebius_kpi_history.xlsx; shared/findings_log.xlsx; capacity/nebius_capacity.xlsx + site_list.xlsx + site_verification.md; peers/sites/sites.xlsx + site_verification.md.
A6: Charts: PNGs in /workspace/nebius/peers/charts/ (peers/build_charts.py reads this workbook's recalculated values).
A7: Recalc: python3 /workspace/nebius/model/recalc.py peers/comparison.xlsx (LibreOffice) -> copy /tmp/rc/comparison.xlsx back; 0 errors required.
A8: 2026-10-08 ~23:15 ET: Abilene active base 421 -> 618 MW [D on R] (Oracle FQ1 FY27 call Sep 10: 6 of 8 bldgs, 618 MW, 75% delivered; IT vs gross basis unstated); low/base/high 200/421/421 -> 421/618/618, YE26 421/632/843 -> 618/721/824, announced numeric ~843 -> ~824 IT implied. Sites rows cross-checked vs the four site appendices (cols Q-R). No KPI, median or ranking moves (Abilene is a Sites/context row only).
A10: K02b (added 2026-10-05; now generated by this script, previously hand-patched into the 08:31 pack): Revenue per average BILLING IT MW = Q2'26 AI cloud rev x4 / AVERAGE(Capacity billing IT MW Q1'26, Q2'26) (Nebius_Inputs N_BILL_Q1/Q2, capacity row 147). BILLED-IT basis, not energized/gross. CoreWeave K02b = K02 (crwv_kpis.xlsx K02b row; active ~ billed). Other peers n/d. Microsoft ACV: $14.49M per IT MW [E, house] = model Contracts!E12 (Nebius_Inputs NOTE_1417; earlier 11.6 / 17.1 readings superseded Oct 9).
A11: SHARE-COUNT CONVENTION (2026-10-08 ~08:45 ET; filings/fd_share_bridge.md, parsed): N_FD_DEBT 358.56M (358,558,306, line 55) = new Feb-2030/Feb-2034 converts as debt below their conversion prices ($313.46 / $324.65, lines 20-21); N_FD_IFCONV 376.65M (376,648,956, line 23) = all if-converted above $324.65; between the two prices only the 2030s convert (369,564,496). N_FD_V09D 358.34M = v0.9d historical memo. '376.6M primary' dropped. No Nebius per-share or EV-per-MW figure exists in this workbook or peers/charts, so no KPI, ranking or chart value depends on it; v0.9e: build asserts model Inputs F473/F474 = these two values.
A12: FY27 BILLED-MW LOCKS - MODEL v0.9e (2026-10-08 ~10:00 ET; source of truth, read live by label via peers/nebius_locks.py model_locks()): BASE 531.84 = model/nebius_model.xlsx Drivers!B34 / HIGH 659.16 = Drivers!C34 (non-Vineland 349.51 / 476.83 + Vineland 182.33 billed MW-yr = engine Microsoft FY27 revenue $2,643.8M / $14.5M). Forward memo: Street $12.3B / 531.84 = 23.13 blended; EX-MICROSOFT (12,300 - 2,643.8) / (531.84 - 182.33) = 27.63 = the figure to use against peers (peer $/MW has no $14.5M Microsoft anchor); high path 18.66 blended. $16M coverage: 768.75 MW needed = 1.45x base / 1.17x high. Chart: peers/charts/nebius_billing_lock.png.
A13: HISTORY (superseded, not inputs): Oct 8 ~08:45 ET the FY27 locks were Capacity's tranche pair 536.48 / 663.8 with Microsoft $2,711M on 186.97 MW (ex-MSFT 27.44, blended 22.93); before that model v0.9d 474.96 / 645.4 (energized-lagged). Both are retired by v0.9e (the Judge_Slide 475/645 flag is closed). Prior pack: comparison_pre_v09e_backup.xlsx.
... A19: 2026-10-08 ~23:30 ET (coordinator decision): Nebius energized MW switched from the outdated capacity/nebius_capacity_v1.xlsx 45 / 171.5 / 173 to the current lock 50 / 181.5 / 193 (Quarterly MW J130/M130/N130 = filings KPI row 30, Checks r22); identified sites 157-229; modeled GPUs 80,047.5 -> 86,738 and fleet list $5.571 -> $5.606 follow the same lock. Peer values re-read from the existing peer packs only (no new peer KPIs).

Sheet Ranking
A1: Where Nebius is better / worse - ranked by signed gap vs comparable-peer median (positive = favourable to Nebius). Context and n/a rows listed last. Recomputed 2026-10-05 ET after v0.9d Nebius_Inputs refresh (K02b now scored in rank order); rebuilt 2026-10-08 ET (CRWV K18 read from fixed pack; share-count convention 358.56M debt / 376.65M if-converted; ~10:00 ET Nebius locks re-pointed to model v0.9e - no ranked KPI uses shares or forward MW, so ranks unchanged).
A3: Rank | B3: ID | C3: KPI | D3: Flag | E3: Nebius | F3: Peer median | G3: Signed gap % (favourable +; vs max(|median|, mean |peer|), computed at build) | H3: Reason
A4: 1 | B4: K05 | C4: Adj. EBITDA per active MW (average MW) | D4: =Comparison!Z9 -> Better | E4: =Comparison!D9 -> 6.1030708 | F4: =Comparison!Y9 -> -0.043259259 | G4: 126.1 | H4: Nebius 6.10 vs peer median -0.04 (range Nscale -4.92 - CoreWeave 4.83; n=2); segment adj. EBITDA per MW well above CRWV-style peers
A5: 2 | B5: K43 | C5: Incremental annualized revenue per incremental MW (YoY) | D5: =Comparison!Z42 -> Better | E5: =Comparison!D42 -> 13.46014 | F5: =Comparison!Y42 -> 6.8088018 | G5: 93.2 | H5: Nebius 13.46 vs peer median 6.81 (range CoreWeave 5.29 - Oracle OCI 9.31; n=3); marginal revenue per new MW
A6: 3 | B6: K07 | C6: Implied blended realized price ($/GPU-hr) | D6: =Comparison!Z11 -> Better | E6: =Comparison!D11 -> 3.0348014 | F6: =Comparison!Y11 -> 1.6621404 | G6: 81.9 | H6: Nebius 3.03 vs peer median 1.66 (range Nscale 1.29 - Lambda 2.09; n=4); realized $/GPU-hr above peers (modeled GPU base; includes non-GPU revenue)
A7: 4 | B7: K06 | C7: Revenue per GPU ($K per GPU-year, avg GPUs) | D7: =Comparison!Z10 -> Better | E7: =Comparison!D10 -> 26.512025 | F7: =Comparison!Y10 -> 14.600317 | G7: 81.2 | H7: Nebius 26.51 vs peer median 14.60 (range Nscale 11.25 - Lambda 18.24; n=4); revenue per (modeled) GPU
A8: 5 | B8: K01 | C8: Revenue per active MW - period-end reported MW | D8: =Comparison!Z4 -> Better | E8: =Comparison!D4 -> 11.915026 | F8: =Comparison!Y4 -> 6.8666667 | G8: 73.5 | H8: Nebius 11.92 vs peer median 6.87 (range Crusoe 2.00 - Lambda 9.70; n=5); higher revenue density per energized MW (Nebius MW is a Capacity estimate; mixed IT/gross basis)
A9: 6 | B9: K44 | C9: Annualized revenue / avg gross GPU-compute hardware in service | D9: =Comparison!Z43 -> Better | E9: =Comparison!D43 -> 0.46501658 | F9: =Comparison!Y43 -> 0.26948927 | G9: 72.6 | H9: Nebius 0.47 vs peer median 0.27 (range IREN 0.20 - CoreWeave 0.34; n=2); asset turn on GPU hardware
A10: 7 | B10: K02b | C10: Revenue per BILLING IT MW - average MW (billed-IT basis; Nebius = Capacity billing path) | D10: =Comparison!Z6 -> Better | E10: =Comparison!D6 -> 13.055448 | F10: =Comparison!Y6 -> 8.24 | G10: 58.4 | H10: Nebius 13.06 vs peer median 8.24 (range CoreWeave 8.24 - CoreWeave 8.24; n=1); same numerator on average BILLING IT MW (billed-IT basis; Nebius Capacity billing path, CoreWeave active~billed) - the basis the v0.9e Judge slide / Drivers use for $/billed MW
A11: 8 | B11: K24 | C11: Largest customer % of revenue | D11: =Comparison!Z27 -> Better | E11: =Comparison!D27 -> 24 | F11: =Comparison!Y27 -> 44 | G11: 45.5 | H11: Nebius 24.00 vs peer median 44.00 (range CoreWeave 36.00 - Nscale 52.00; n=2); lower concentration is better
A12: 9 | B12: K02 | C12: Revenue per active MW - average MW (2024 uses interpolated MW) | D12: =Comparison!Z5 -> Better | E12: =Comparison!D5 -> 12.280908 | F12: =Comparison!Y5 -> 9.358411 | G12: 31.2 | H12: Nebius 12.28 vs peer median 9.36 (range CoreWeave 8.24 - IREN 10.48; n=2); same on average MW - the fixed, comparable figure; Blackwell-heavy, mostly new fleet lifts density
A13: 10 | B13: K03 | C13: Revenue per contracted MW | D13: =Comparison!Z7 -> Better | E13: =Comparison!D7 -> 0.65702857 | F13: =Comparison!Y7 -> 0.33333333 | G13: 29.2 | H13: Nebius 0.66 vs peer median 0.33 (range Nscale 0.21 - CoreWeave 2.78; n=3); monetises contracted power faster? Nebius has far more unbuilt contracted MW than CRWV
A14: 11 | B14: K09 | C14: Implied utilization (realized $/GPU-hr / weighted list) | D14: =Comparison!Z13 -> Better | E14: =Comparison!D13 -> 54.131647 | F14: =Comparison!Y13 -> 43.943989 | G14: 23.2 | H14: Nebius 54.13 vs peer median 43.94 (range CoreWeave 18.06 - Lambda 69.83; n=2); price-based 'utilization' (mixes discount with use); not physical utilization
A15: 12 | B15: K25 | C15: 2nd-largest customer % | D15: =Comparison!Z28 -> Better | E15: =Comparison!D28 -> 21 | F15: =Comparison!Y28 -> 26 | G15: 19.2 | H15: Nebius 21.00 vs peer median 26.00 (range CoreWeave 26.00 - CoreWeave 26.00; n=1); lower is better
A16: 13 | B16: K17 | C16: Depreciation yield (D&A x4 / avg in-service gross PP&E) | D16: =Comparison!Z20 -> Better | E16: =Comparison!D20 -> 17.515048 | F16: =Comparison!Y20 -> 14.908554 | G16: 17.5 | H16: Nebius 17.52 vs peer median 14.91 (range Oracle OCI 13.45 - Nscale 15.67; n=4); higher depreciation yield = more conservative
A17: 14 | B17: K18 | C17: Implied average depreciable life (1 / yield) | D17: =Comparison!Z21 -> Better | E17: =Comparison!D21 -> 5.7093762 | F17: =Comparison!Y21 -> 6.716941 | G17: 14.8 | H17: Nebius 5.71 vs peer median 6.72 (range Nscale 6.38 - Oracle OCI 7.44; n=4); lower implied life = more conservative
A18: 15 | B18: K16 | C18: Useful life - technology equipment (GPUs/servers/network) | D18: =Comparison!Z19 -> Better | E18: =Comparison!D19 -> 5 | F18: =Comparison!Y19 -> 5.75 | G18: 13 | H18: Nebius 5.00 vs peer median 5.75 (range IREN 5.00 - CoreWeave 6.00; n=4); shorter life = more conservative accounting (Nebius moved 4->5 yrs in 2026; CRWV/Oracle 6)
A19: 16 | B19: K39 | C19: Debt principal / RPO | D19: =Comparison!Z38 -> In line | E19: =Comparison!D38 -> 0.22794247 | F19: =Comparison!Y38 -> 0.27293389 | G19: 8.7 | H19: Nebius 0.23 vs peer median 0.27 (range Nscale 0.00 - IREN 1.51; n=4); lower debt per $ of backlog is better
A20: 17 | B20: K36 | C20: Implied cash cost: contractual interest x4 / avg principal | D20: =Comparison!Z35 -> In line | E20: =Comparison!D35 -> 5.605992 | F20: =Comparison!Y35 -> 6.0787368 | G20: 5.2 | H20: Nebius 5.61 vs peer median 6.08 (range IREN 1.71 - Nscale 22.19; n=4); lower cash cost of debt is better
A21: 18 | B21: K23 | C21: RPO / annualized quarterly revenue | D21: =Comparison!Z26 -> In line | E21: =Comparison!D26 -> 16.303096 | F21: =Comparison!Y26 -> 14.07461 | G21: 3.8 | H21: Nebius 16.30 vs peer median 14.07 (range Oracle OCI 8.31 - Nscale 200.57; n=4); backlog coverage of current run-rate
A22: 19 | B22: K26 | C22: Top-N >=10% customers combined % | D22: =Comparison!Z29 -> In line | E22: =Comparison!D29 -> 59 | F22: =Comparison!Y29 -> 61 | G22: 3.3 | H22: Nebius 59.00 vs peer median 61.00 (range Lambda 50.00 - CoreWeave 72.00; n=2); lower combined concentration is better
A23: 20 | B23: K22 | C23: RPO % recognized within 24 months | D23: =Comparison!Z25 -> In line | E23: =Comparison!D25 -> 36 | F23: =Comparison!Y25 -> 35 | G23: 2.9 | H23: Nebius 36.00 vs peer median 35.00 (range Nscale 16.00 - IREN 43.10; n=4); share of RPO converting within 24m
A24: 21 | B24: K12 | C24: In-service additions per new active MW (CRWV capex definition) | D24: =Comparison!Z15 -> In line | E24: =Comparison!D15 -> 19.68069 | F24: =Comparison!Y15 -> 18.704 | G24: -5.2 | H24: Nebius 19.68 vs peer median 18.70 (range CoreWeave 18.70 - CoreWeave 18.70; n=1); in-service $ per MW added (FY25 basis for Nebius)
A25: 22 | B25: K28 | C25: Weighted effective cost of debt (principal-weighted, EoP) - all facilities | D25: =Comparison!Z31 -> In line | E25: =Comparison!D31 -> 5.1 | F25: =Comparison!Y31 -> 4.8282005 | G25: -5.4 | H25: Nebius 5.10 vs peer median 4.83 (range IREN 1.85 - CoreWeave 8.41; n=3); cheaper debt (converts-heavy) is better
A26: 23 | B26: K14 | C26: Net PP&E per active MW (EoP) | D26: =Comparison!Z17 -> Worse | E26: =Comparison!D17 -> 67.59171 | F26: =Comparison!Y17 -> 50.933605 | G26: -32.7 | H26: Nebius 67.59 vs peer median 50.93 (range CoreWeave 31.16 - Nscale 70.71; n=2); net PP&E per active MW inflated by construction-in-progress
A27: 24 | B27: K15 | C27: Gross in-service PP&E per active MW (EoP) | D27: =Comparison!Z18 -> Worse | E27: =Comparison!D18 -> 32.710363 | F27: =Comparison!Y18 -> 23.980963 | G27: -36.4 | H27: Nebius 32.71 vs peer median 23.98 (range Nscale 20.83 - CoreWeave 27.14; n=2); gross in-service PP&E per MW
A28: 25 | B28: K27 | C28: Number of customers >=10% of revenue | D28: =Comparison!Z30 -> Worse | E28: =Comparison!D30 -> 3 | F28: =Comparison!Y30 -> 1.5 | G28: -100 | H28: Nebius 3.00 vs peer median 1.50 (range Oracle OCI 0.00 - CoreWeave 3.00; n=2); fewer >=10% customers is better
A29: 26 | B29: K13 | C29: Trailing-4Q cash capex per trailing-4Q new active MW | D29: =Comparison!Z16 -> Worse | E29: =Comparison!D16 -> 77.914685 | F29: =Comparison!Y16 -> 33.176218 | G29: -134.9 | H29: Nebius 77.91 vs peer median 33.18 (range CoreWeave 19.97 - Oracle OCI 46.39; n=2); capex per MW added is high because capex funds 2027 capacity (not-yet-in-use $7.8B)
A30: 27 | B30: K40 | C30: Capitalized interest % of contractual interest | D30: =Comparison!Z39 -> Worse | E30: =Comparison!D39 -> 25.235405 | F30: =Comparison!Y39 -> 6.6722973 | G30: -278.2 | H30: Nebius 25.24 vs peer median 6.67 (range Nscale 0.00 - CoreWeave 13.34; n=2); high capitalized share flatters P&L interest
B31: K04 | C31: Contracted / active MW (build-out multiple) | D31: =Comparison!Z8 -> Context | E31: =Comparison!D8 -> 18.134715 | F31: =Comparison!Y8 -> 6 | H31: Nebius 18.13 vs peer median 6.00 (range CoreWeave 2.47 - Nscale 16.91; n=3); build-out multiple: big growth runway but heavy execution/funding need (context, not scored)
B32: K08 | C32: Fleet-weighted on-demand list price ($/GPU-hr) | D32: =Comparison!Z12 -> Context | E32: =Comparison!D12 -> 5.6063348 | F32: =Comparison!Y12 -> 3.445 | H32: Nebius 5.61 vs peer median 3.45 (range IREN 2.00 - CoreWeave 9.20; n=4); list-price context
B33: K10 | C33: Cash capex per new active MW (reported MW) | D33: =Comparison!Z14 -> n/a | E33: =Comparison!D14 -> n.m. | F33: =Comparison!Y14 -> 34.858207 | H33: Nebius n/d. single-quarter capex/MW not meaningful for Nebius (+1.5 MW)
B34: K19 | C34: D&A as % of revenue | D34: =Comparison!Z22 -> Context | E34: =Comparison!D22 -> 45.173074 | F34: =Comparison!Y22 -> 67.887312 | H34: Nebius 45.17 vs peer median 67.89 (range Oracle OCI 12.59 - Nscale 123.76; n=4); D&A burden context
B35: K20 | C35: RPO (ASC 606, EoP) | D35: =Comparison!Z23 -> Context | E35: =Comparison!D23 -> 37.4906 | F35: =Comparison!Y23 -> 80.05 | H35: Nebius 37.49 vs peer median 80.05 (range IREN 5.10 - Oracle OCI 638.00; n=4); absolute size context
B36: K21 | C36: Revenue backlog (company metric, EoP) | D36: =Comparison!Z24 -> n/a | E36: =Comparison!D24 -> n/d | F36: =Comparison!Y24 -> 76.7 | H36: Nebius n/d. company backlog metric (context)
B37: K29 | C37: of which DDTL - weighted eff. rate | D37: =Comparison!Z32 -> n/a | E37: =Comparison!D32 -> n/d | F37: =Comparison!Y32 -> 9.1021429 | H37: Nebius n/d. facility-level rate (context)
B38: K34 | C38: of which Other term loans - weighted eff. rate | D38: =Comparison!Z33 -> n/a | E38: =Comparison!D33 -> n/d | F38: =Comparison!Y33 -> 9 | H38: Nebius n/d. facility-level rate (context)
B39: K35 | C39: DDTL (secured asset-level) share of principal | D39: =Comparison!Z34 -> n/a | E39: =Comparison!D34 -> n/d | F39: =Comparison!Y34 -> 20.219881 | H39: Nebius n/d. structure context
B40: K37 | C40: Company-reported weighted average interest rate | D40: =Comparison!Z36 -> n/a | E40: =Comparison!D36 -> n/d | F40: =Comparison!Y36 -> 8.3 | H40: Nebius n/d. company-reported rate
B41: K38 | C41: Total debt principal (EoP) | D41: =Comparison!Z37 -> Context | E41: =Comparison!D37 -> 8.5457 | F41: =Comparison!Y37 -> 21.628325 | H41: Nebius 8.55 vs peer median 21.63 (range Nscale 0.14 - Oracle OCI 129.54; n=4); size context
...

Sheet Nebius_Inputs
A1: Nebius inputs for the Comparison tab (Q2'26 = quarter ended 30-Jun-2026 unless stated). Comparison Nebius cells are live formulas on column C.
A3: ID | B3: Item | C3: Value | D3: Unit | E3: Tag | F3: Source (Nebius workspace file / row)
A4: N01 | B4: AI cloud segment revenue Q2'26 | C4: 574.9 | D4: $M | E4: R | F4: filings/nebius_filings.xlsx Quarterly 'Segment revenue - Nebius AI cloud'; 6-K 2026-08-12
A5: N02 | B5: AI cloud segment revenue Q2'25 | C5: 93.7 | D5: $M | E5: R | F5: filings/nebius_filings.xlsx Quarterly
A6: N03 | B6: Group revenue Q2'26 (memo) | C6: 582.3 | D6: $M | E6: R | F6: filings/nebius_filings.xlsx Quarterly
A7: N04 | B7: AI cloud adj. EBITDA Q2'26 | C7: 285.7 | D7: $M | E7: R | F7: filings/nebius_filings.xlsx Quarterly
A8: N05 | B8: D&A Q2'26 (group) | C8: 259.7 | D8: $M | E8: R | F8: filings/nebius_filings.xlsx Quarterly
A9: N06 | B9: Cash capex Q3'25 | C9: 955.5 | D9: $M | E9: R | F9: filings/nebius_filings.xlsx Quarterly
A10: N07 | B10: Cash capex Q4'25 | C10: 2056 | D10: $M | E10: R | F10: filings/nebius_filings.xlsx Quarterly
A11: N08 | B11: Cash capex Q1'26 | C11: 2472.9 | D11: $M | E11: R | F11: filings/nebius_filings.xlsx Quarterly
A12: N09 | B12: Cash capex Q2'26 | C12: 5657.4 | D12: $M | E12: R | F12: filings/nebius_filings.xlsx Quarterly
A13: N10 | B13: PP&E net 30-Jun-26 | C13: 13045.2 | D13: $M | E13: R | F13: filings/nebius_filings.xlsx Quarterly
A14: N11 | B14: Gross in-service PP&E 31-Mar-26 (gross 7,976.6 - not yet in use 2,427.9) | C14: 5548.7 | D14: $M | E14: D | F14: filings/nebius_kpi_history.xlsx KPI row 26 (Q1'26 interim FS Note 7)
A15: N12 | B15: Gross in-service PP&E 30-Jun-26 (gross 14,149.5 - not yet in use 7,836.4) | C15: 6313.1 | D15: $M | E15: D | F15: filings/nebius_kpi_history.xlsx KPI row 26 (Q2'26 interim FS Note 7)
... A55: N_GUIDE_HI | B55: YE26 run-rate guide - high | C55: 9000 | D55: $M | E55: R | F55: model/nebius_model.xlsx Judge_Slide C33
A57: Forward memo - $ per BILLED IT MW (live formulas on the model v0.9e lock rows above; context only, NOT scored and NOT in Comparison medians)
A58: D_YE26_LO_BASE | B58: YE26 guide low / YE26 BASE billing ($7B / ~258) | C58: =$C$54/$C$47 -> 27.163368 | D58: $M/billed IT MW-yr | E58: D | F58: ties to model/nebius_model.xlsx Judge_Slide B40 (27.16); price_or_mw Implied_Price F6
A59: D_YE26_HI_HIGH | B59: YE26 guide high / YE26 HIGH billing ($9B / ~284) | C59: =$C$55/$C$48 -> 31.66784 | D59: $M/billed IT MW-yr | E59: D | F59: ties to model/nebius_model.xlsx Judge_Slide C41 (31.67); price_or_mw Implied_Price F7
A60: D_STREET_FY27_BASE | B60: Street FY27 / FY27 avg BASE billed, engine-linked ($12.3B / ~531.8) - BLENDED memo (incl. $14.5M Microsoft anchor) | C60: =$C$53/$C$49 -> 23.127214 | D60: $M/billed IT MW-yr | E60: D | F60: ~23.1; ties to model/nebius_model.xlsx Drivers B10 (23.13) / model/nebius_model.xlsx Judge_Slide B16; price_or_mw Implied_Price F5
A61: D_STREET_FY27_NONMSFT | B61: Street FY27 EX-MICROSOFT / FY27 BASE billed ex-Vineland (($12.3B - MSFT) / (531.8 - 182.3)) - USE AGAINST PEERS | C61: =($C$53-$C$51)/($C$49-$C$52) -> 27.627758 | D61: $M/billed IT MW-yr | E61: D | F61: (12,300 - 2,643.8) / (531.84 - 182.33) = 27.63; ties to model/nebius_model.xlsx Drivers B9 / model/nebius_model.xlsx Judge_Slide B20 (~$27.6M, Grok Bot). Peer $/MW has no $14.5M Microsoft anchor.
A62: D_STREET_FY27_HIGH | B62: Street FY27 / FY27 avg HIGH billed, engine-linked ($12.3B / ~659.2) - blended | C62: =$C$53/$C$50 -> 18.660198 | D62: $M/billed IT MW-yr | E62: D | F62: high path; price_or_mw Implied_Price F24
A63: D_STREET_FY27_NONMSFT_HIGH | B63: Street FY27 EX-MICROSOFT / FY27 HIGH billed ex-Vineland - high path | C63: =($C$53-$C$51)/($C$50-$C$52) -> 20.250972 | D63: $M/billed IT MW-yr | E63: D | F63: Vineland billed MW-yr identical on both paths (model/nebius_model.xlsx Drivers B33 = C33)
A64: D_COV16_BASE | B64: MW coverage at $16M comps: (Street / $16M) / FY27 BASE billed (x) | C64: =($C$53/16)/$C$49 -> 1.4454509 | D64: x | E64: D | F64: ties to model/nebius_model.xlsx Drivers B38 (1.445x; 768.75 MW needed)
A65: D_COV16_HIGH | B65: MW coverage at $16M comps: (Street / $16M) / FY27 HIGH billed (x) | C65: =($C$53/16)/$C$50 -> 1.1662624 | D65: x | E65: D | F65: ties to model/nebius_model.xlsx Drivers C38 (1.166x)
A66: D_FD_CONV_SENS | B66: Share convention spread: if-converted FD vs debt-convention FD (%) | C66: =($C$45/$C$44-1)*100 -> 5.0453858 | D66: % | E66: D | F66: ~+5.0%. No Nebius per-share or EV-per-MW figure exists in this workbook/charts, so no KPI value depends on the convention.
A67: D_K02B_BASE_MW | B67: Q2'26 average billing IT MW (K02b denominator) | C67: =AVERAGE($C$42,$C$43) -> 176.14103 | D67: IT MW | E67: E | F67: capacity row 147 M:N average
A68: D_YE26_VS_Q2 | B68: YE26 BASE / HIGH billing vs Q2'26 average billing (x) | C68: =$C$47/AVERAGE($C$42,$C$43) -> 1.4630322 | D68: x | E68: D | F68: base-path billing build multiple to YE26 (HIGH: next row)
A69: D_YE26H_VS_Q2 | B69: YE26 HIGH billing vs Q2'26 average billing (x) | C69: =$C$48/AVERAGE($C$42,$C$43) -> 1.6134799 | D69: x | E69: D
A71: NOTE_1417 | B71: Microsoft ACV: $14.49M per IT MW [E, house] = model v0.9e Contracts!E12 = $17,392.9M / (5 x 240 IT MW est.); agrees with the Drivers 14.5 input (Inputs!F111). Neither company states the contract MW. HISTORY (superseded Oct 9 2026): 11.60 on 300 MW (site size, not contract MW) and 17.08 GPU-derived (retired).
A72: NOTE_FD | B72: SHARE-COUNT CONVENTION (2026-10-08, filings/fd_share_bridge.md): the new Feb-2030 ($3.45B, conv. $313.46) and Feb-2034 ($2.30B, conv. $324.65) notes count as DEBT while the share price is below their conversion prices -> N_FD_DEBT 358.56M with the $5.75B face in debt; IF-CONVERTED above -> N_FD_IFCONV 376.65M with ALL convert debt removed from EV. Between $313.46 and $324.65 only the 2030s convert: 369.56M (D). At the filings/fd_share_bridge.md reference $237.15 (10/7 close [R, third-party quote]) both are out of the money -> debt convention. Never mix share and debt sides. N_FD_V09D 358.34M is the v0.9d historical (6/30, pre-exchange) value only. No per-share or EV/MW metric in this workbook.
A73: NOTE_FY27 | B73: FY27 BILLED-MW LOCKS (model v0.9e = source of truth, read via peers/nebius_locks.py model_locks()): BASE 531.84 (model/nebius_model.xlsx Drivers!B34) / HIGH 659.16 (Drivers!C34) = non-Vineland path 349.51 / 476.83 + Vineland billed MW-yr 182.33 (engine Microsoft FY27 revenue $2,643.8M / $14.5M). Street blended $12.3B / 531.84 = 23.13 (memo); PEER COMPARATOR = D_STREET_FY27_NONMSFT = (12,300 - 2,643.8) / 349.51 = 27.63 (= Drivers!B9). At $16M comps the Street needs 768.75 MW = 1.45x base / 1.17x high (D_COV16_*). YE26 unchanged 257.7 / 284.2.
A74: NOTE_LOCKSRC | B74: LOCK SOURCE (v0.9e): YE26 = model/nebius_model.xlsx Judge_Slide B34/B35 = capacity row 147 col P 257.66; FY27 / Microsoft / hurdle = model/nebius_model.xlsx Drivers rows 9-10, 30-39; FD = model/nebius_model.xlsx Inputs F473/F474 (= filings/fd_share_bridge.md). Build asserts model version v0.9e, FD 358.56/376.65 (model = Filings), YE26 257.7/284.2, FY27 531.8/659.2, MSFT $2,643.8M, hurdle ~27.6 / blended ~23.1, and that price_or_mw.xlsx Implied_Price D7/F7 = 284.2 MW / $31.67M and Street row D5 = 531.84 MW / $23.13M re-read and matched. Yellow = current lock rows.
A75: NOTE_K02B | B75: K02b keeps the BILLED-IT basis: denominators N_BILL_Q1/Q2 are Capacity billing IT MW (not energized N16/N17). Comparison K02b and every forward $/billed MW memo above share that basis.

Sheet Contracts_$MWyr
A1: Hyperscaler / neocloud / AI-lab contract economics: implied $M per MW-yr = TCV / term / MW (8,760 h/yr for $/GPU-hr). 'Reused' rows are the GPU Market agent's entries in parts/contract_economics.xlsx (Deals/Normalized; nothing contract-related exists in market/ or nebius_market.xlsx) - cited, not re-researched; their values shown in cols R-T and checked vs ours in col U. 'New' rows added here with sources. Facility leases at the bottom are NOT compute prices (shell+power only). Never fabricated: n/d where undisclosed.
A3: ID | B3: Status | C3: Provider | D3: Customer | E3: Category | F3: Signed | G3: TCV ($M) | H3: TCV tag | I3: Term (yrs) | J3: MW (as stated) | K3: MW basis | L3: IT MW (normalized) | M3: IT MW method | N3: Chip | O3: GPUs | P3: GPU tag | Q3: TCV / yr ($M) | R3: Market agent $M/MW-yr (stated MW) | S3: Market agent $M/IT MW-yr | T3: Market agent $/GPU-hr | U3: Check: ours - market ($M/MW-yr) | V3: $M per MW-yr (stated MW) | W3: $M per IT MW-yr | X3: $ per GPU-hr | Y3: Source | Z3: Notes / conflicts
A4: N1 | B4: Reused | C4: Nebius | D4: Microsoft | E4: Neocloud-hyperscaler | F4: 2025-09-08 | G4: 17392.9 | H4: R | I4: 5 | J4: n/d (not stated) | K4: not stated by Nebius/Microsoft (300 MW = Vineland site size) | L4: 240 | M4: E (house): model v0.9e Inputs!F216 MSFT_MW = 240 IT MW est.; $/IT MW = Contracts!E12 | N4: GB300 NVL72 (P) | O4: 100000 | P4: P (floor) | Q4: =IF(AND(ISNUMBER(G4),ISNUMBER(I4)),G4/I4,"n/d") -> 3478.58 | T4: 3.971 | U4: =IF(AND(ISNUMBER(S4),ISNUMBER(W4)),ROUND(W4-S4,2),IF(AND(ISNUMBER(R4),ISNUMBER(V4)),ROUND(V4-R4,2),"")) | V4: =IF(AND(ISNUMBER(Q4),ISNUMBER(J4)),Q4/J4,"n/d") -> n/d | W4: =IF(AND(ISNUMBER(Q4),ISNUMBER(L4)),Q4/L4,"n/d") -> 14.494083 | X4: =IF(AND(ISNUMBER(G4),ISNUMBER(I4),ISNUMBER(O4)),G4*1000000/(O4*I4*8760),"n/d") -> 3.9709817 | Y4: 6-K 2025-09-08 (SEC) | model/nebius_model.xlsx v0.9e Contracts!E12 | parts/contract_economics.xlsx (GPU Market agent) Deals/Normalized N1 | Z4: $14.49M per IT MW [E, house] (model Contracts!E12 = 17,392.9 / (5 x 240 IT MW est.)); agrees with the Drivers 14.5 input (Inputs!F111). HISTORY (superseded Oct 9 2026, not current values): 11.60 on 300 MW (site size, not stated contract MW); 17.08 on GPU-derived 203.7 IT MW (100k GB300 / 491; retired by GPU Market); market prepay-adjusted 18.56 rests on the same GPU-derived MW.
A5: N1o | B5: HISTORY (superseded) | C5: Nebius | D5: Microsoft (incl. option) - HISTORY | E5: Neocloud-hyperscaler | F5: 2025-09-08 | G5: 19400 | H5: R (up to) | I5: 5 | J5: 300 | K5: unlabeled | L5: 203.666 | M5: as N1 | N5: GB300 (P) | O5: 100000 | P5: P (floor) | Q5: =IF(AND(ISNUMBER(G5),ISNUMBER(I5)),G5/I5,"n/d") -> 3880 | R5: 12.933 | S5: 19.051 | T5: 4.429 | U5: =IF(AND(ISNUMBER(S5),ISNUMBER(W5)),ROUND(W5-S5,2),IF(AND(ISNUMBER(R5),ISNUMBER(V5)),ROUND(V5-R5,2),"")) -> 0 | V5: =IF(AND(ISNUMBER(Q5),ISNUMBER(J5)),Q5/J5,"n/d") -> 12.933333 | W5: =IF(AND(ISNUMBER(Q5),ISNUMBER(L5)),Q5/L5,"n/d") -> 19.050799 | X5: =IF(AND(ISNUMBER(G5),ISNUMBER(I5),ISNUMBER(O5)),G5*1000000/(O5*I5*8760),"n/d") -> 4.4292237 | Y5: parts/contract_economics.xlsx (GPU Market agent) N1o | Z5: HISTORY - superseded: 300 MW is gross site size, not stated contract MW (Vineland 'scalable up to 300 MW', 2024 20-F; Nebius/Microsoft state no contract MW). 12.93 = $19,400M / 5 / 300 is retired (Oct 9 2026 ET); not a current value.
A6: N2 | B6: Reused | C6: Nebius | D6: Meta #1 | E6: Neocloud-hyperscaler | F6: 2025-11-01 | G6: 2880.7 | H6: R | I6: 5 | J6: n/d | K6: not disclosed | L6: 50 | M6: E: ~50 IT MW team estimate (model Contracts!D23:D24 = 48.0 MW; Capacity tranches list n/d) | N6: n/d | Q6: =IF(AND(ISNUMBER(G6),ISNUMBER(I6)),G6/I6,"n/d") -> 576.14 | S6: 11.523 | U6: =IF(AND(ISNUMBER(S6),ISNUMBER(W6)),ROUND(W6-S6,2),IF(AND(ISNUMBER(R6),ISNUMBER(V6)),ROUND(V6-R6,2),"")) -> 0 | V6: =IF(AND(ISNUMBER(Q6),ISNUMBER(J6)),Q6/J6,"n/d") -> n/d | W6: =IF(AND(ISNUMBER(Q6),ISNUMBER(L6)),Q6/L6,"n/d") -> 11.5228 | X6: =IF(AND(ISNUMBER(G6),ISNUMBER(I6),ISNUMBER(O6)),G6*1000000/(O6*I6*8760),"n/d") -> n/d | Y6: 6-K 2025-11-12 | parts/contract_economics.xlsx (GPU Market agent) N2 | Z6: IT MW is a low-confidence estimate (market); Nebius filings tie no MW to the contract.
A7: N3 | B7: Reused | C7: Nebius | D7: Meta #2 (dedicated) | E7: Neocloud-hyperscaler | F7: 2026-03-13 | G7: 12000 | H7: R | I7: 5 | J7: n/d | K7: not disclosed | N7: Vera Rubin NVL72 | Q7: =IF(AND(ISNUMBER(G7),ISNUMBER(I7)),G7/I7,"n/d") -> 2400 | U7: =IF(AND(ISNUMBER(S7),ISNUMBER(W7)),ROUND(W7-S7,2),IF(AND(ISNUMBER(R7),ISNUMBER(V7)),ROUND(V7-R7,2),"")) | V7: =IF(AND(ISNUMBER(Q7),ISNUMBER(J7)),Q7/J7,"n/d") -> n/d | W7: =IF(AND(ISNUMBER(Q7),ISNUMBER(L7)),Q7/L7,"n/d") -> n/d | X7: =IF(AND(ISNUMBER(G7),ISNUMBER(I7),ISNUMBER(O7)),G7*1000000/(O7*I7*8760),"n/d") -> n/d | Y7: 6-K 2026-03-16 | parts/contract_economics.xlsx (GPU Market agent) N3 | Z7: Break-even ~149 IT MW to match Anthropic-Nscale $16.16M (market).
A8: N4 | B8: Reused | C8: Nebius | D8: Meta #2 backstop (contingent) | E8: Neocloud-hyperscaler | F8: 2026-03-13 | G8: 15000 | H8: R (up to, contingent) | I8: 5 | J8: n/d | N8: n/d | Q8: =IF(AND(ISNUMBER(G8),ISNUMBER(I8)),G8/I8,"n/d") -> 3000 | U8: =IF(AND(ISNUMBER(S8),ISNUMBER(W8)),ROUND(W8-S8,2),IF(AND(ISNUMBER(R8),ISNUMBER(V8)),ROUND(V8-R8,2),"")) | V8: =IF(AND(ISNUMBER(Q8),ISNUMBER(J8)),Q8/J8,"n/d") -> n/d | W8: =IF(AND(ISNUMBER(Q8),ISNUMBER(L8)),Q8/L8,"n/d") -> n/d | X8: =IF(AND(ISNUMBER(G8),ISNUMBER(I8),ISNUMBER(O8)),G8*1000000/(O8*I8*8760),"n/d") -> n/d | Y8: 6-K 2026-03-16 | parts/contract_economics.xlsx (GPU Market agent) N4 | Z8: Contingent; excluded from normalized comps.
A9: NAGG1 | B9: Reused (KPI) | C9: Nebius | D9: 4 'landmark' Q2'26 customers (unnamed) | E9: Neocloud-mixed | F9: Q2'26 | G9: n/d | J9: n/d | N9: n/d | Q9: =IF(AND(ISNUMBER(G9),ISNUMBER(I9)),G9/I9,"n/d") -> n/d | R9: 20-25 (ACV/MW, R) | U9: =IF(AND(ISNUMBER(S9),ISNUMBER(W9)),ROUND(W9-S9,2),IF(AND(ISNUMBER(R9),ISNUMBER(V9)),ROUND(V9-R9,2),"")) | V9: =IF(AND(ISNUMBER(Q9),ISNUMBER(J9)),Q9/J9,"n/d") -> n/d | W9: =IF(AND(ISNUMBER(Q9),ISNUMBER(L9)),Q9/L9,"n/d") -> n/d | X9: =IF(AND(ISNUMBER(G9),ISNUMBER(I9),ISNUMBER(O9)),G9*1000000/(O9*I9*8760),"n/d") -> n/d | Y9: Q2'26 letter p.2-4 (filings MW_Disclosures) | parts/contract_economics.xlsx (GPU Market agent) Notes_Method | Z9: Company aggregate: deals averaged >$1B TCV, ACV $20-25M/MW; Q2 deals >$20M/MW vs 2026 base $12M/MW; Q3 short-term >$40M/MW. Basis not stated (Filings: likely IT/active).
A10: P1 | B10: Reused | C10: IREN | D10: Microsoft | E10: Neocloud-hyperscaler | F10: 2025-11-03 | G10: 9700 | H10: R | I10: 5 | J10: 200 | K10: IT | L10: 200 | M10: R | N10: GB300 NVL72 | O10: 98200 | P10: E (200 x 491) | Q10: =IF(AND(ISNUMBER(G10),ISNUMBER(I10)),G10/I10,"n/d") -> 1940 | R10: 9.7 | S10: 9.7 | T10: 2.255 | U10: =IF(AND(ISNUMBER(S10),ISNUMBER(W10)),ROUND(W10-S10,2),IF(AND(ISNUMBER(R10),ISNUMBER(V10)),ROUND(V10-R10,2),"")) -> 0 | V10: =IF(AND(ISNUMBER(Q10),ISNUMBER(J10)),Q10/J10,"n/d") -> 9.7 | W10: =IF(AND(ISNUMBER(Q10),ISNUMBER(L10)),Q10/L10,"n/d") -> 9.7 | X10: =IF(AND(ISNUMBER(G10),ISNUMBER(I10),ISNUMBER(O10)),G10*1000000/(O10*I10*8760),"n/d") -> 2.2552056 | Y10: 8-K 2025-11-03 | parts/contract_economics.xlsx (GPU Market agent) P1 | Z10: Prepay-adjusted 10.28 (market).
A11: NEW1 | B11: New | C11: IREN | D11: NVIDIA | E11: Neocloud-chip vendor | F11: 2026-05 (8-K) | G11: 3400 | H11: R | I11: 5 | J11: 60 | K11: unlabeled (existing Childress halls; air-cooled) | N11: NVIDIA Blackwell (air-cooled) | P11: n/d | Q11: =IF(AND(ISNUMBER(G11),ISNUMBER(I11)),G11/I11,"n/d") -> 680 | U11: =IF(AND(ISNUMBER(S11),ISNUMBER(W11)),ROUND(W11-S11,2),IF(AND(ISNUMBER(R11),ISNUMBER(V11)),ROUND(V11-R11,2),"")) | V11: =IF(AND(ISNUMBER(Q11),ISNUMBER(J11)),Q11/J11,"n/d") -> 11.333333 | W11: =IF(AND(ISNUMBER(Q11),ISNUMBER(L11)),Q11/L11,"n/d") -> n/d | X11: =IF(AND(ISNUMBER(G11),ISNUMBER(I11),ISNUMBER(O11)),G11*1000000/(O11*I11*8760),"n/d") -> n/d | Y11: https://iren.gcs-web.com/news-releases/news-release-details/iren-secures-34bn-ai-cloud-contract-nvidia ; peers/iren (FY26 10-K backlog) | Z11: ~60 MW of existing Childress capacity; ramp from early 2027 (peers/sites site_verification.md). Below IREN's 'recent 3-yr >$20M/IT MW' claim.
A12: PAGG | B12: Reused (KPI) | C12: IREN | D12: recent 3-yr contracts (unnamed) | E12: Neocloud-mixed | F12: FY26 | G12: n/d | I12: 3 | J12: n/d | K12: IT | N12: n/d | Q12: =IF(AND(ISNUMBER(G12),ISNUMBER(I12)),G12/I12,"n/d") -> n/d | R12: >20 (R) | U12: =IF(AND(ISNUMBER(S12),ISNUMBER(W12)),ROUND(W12-S12,2),IF(AND(ISNUMBER(R12),ISNUMBER(V12)),ROUND(V12-R12,2),"")) | V12: =IF(AND(ISNUMBER(Q12),ISNUMBER(J12)),Q12/J12,"n/d") -> n/d | W12: =IF(AND(ISNUMBER(Q12),ISNUMBER(L12)),Q12/L12,"n/d") -> n/d | X12: =IF(AND(ISNUMBER(G12),ISNUMBER(I12),ISNUMBER(O12)),G12*1000000/(O12*I12*8760),"n/d") -> n/d | Y12: parts/contract_economics.xlsx (GPU Market agent) Notes_Method | Z12: Company statement only.
A13: P2 | B13: Reused | C13: Nscale | D13: Microsoft (all SOWs) | E13: Neocloud-hyperscaler | F13: 2025-09..2026-04 | G13: 43800 | H13: R (up to) | I13: 5.5 | J13: n/a | L13: 596.474 | M13: D: 191.6k/491 + 66k/320 | N13: GB300 + Vera Rubin | O13: 257600 | P13: R (sum) | Q13: =IF(AND(ISNUMBER(G13),ISNUMBER(I13)),G13/I13,"n/d") -> 7963.6364 | S13: 13.351 | T13: 3.529 | U13: =IF(AND(ISNUMBER(S13),ISNUMBER(W13)),ROUND(W13-S13,2),IF(AND(ISNUMBER(R13),ISNUMBER(V13)),ROUND(V13-R13,2),"")) -> 0 | V13: =IF(AND(ISNUMBER(Q13),ISNUMBER(J13)),Q13/J13,"n/d") -> n/d | W13: =IF(AND(ISNUMBER(Q13),ISNUMBER(L13)),Q13/L13,"n/d") -> 13.351188 | X13: =IF(AND(ISNUMBER(G13),ISNUMBER(I13),ISNUMBER(O13)),G13*1000000/(O13*I13*8760),"n/d") -> 3.5290796 | Y13: Nscale S-1 2026-09-18 | parts/contract_economics.xlsx (GPU Market agent) P2
A14: P2a | B14: Reused | C14: Nscale (Aker JV) | D14: Microsoft - Narvik | E14: Neocloud-hyperscaler | F14: 2025-09-17 | G14: 6200 | H14: R | I14: 5 | J14: n/a | L14: 105.906 | M14: D: 52k/491 | N14: GB300 | O14: 52000 | P14: R | Q14: =IF(AND(ISNUMBER(G14),ISNUMBER(I14)),G14/I14,"n/d") -> 1240 | S14: 11.708 | T14: 2.722 | U14: =IF(AND(ISNUMBER(S14),ISNUMBER(W14)),ROUND(W14-S14,2),IF(AND(ISNUMBER(R14),ISNUMBER(V14)),ROUND(V14-R14,2),"")) -> 0 | V14: =IF(AND(ISNUMBER(Q14),ISNUMBER(J14)),Q14/J14,"n/d") -> n/d | W14: =IF(AND(ISNUMBER(Q14),ISNUMBER(L14)),Q14/L14,"n/d") -> 11.708496 | X14: =IF(AND(ISNUMBER(G14),ISNUMBER(I14),ISNUMBER(O14)),G14*1000000/(O14*I14*8760),"n/d") -> 2.7221637 | Y14: akernscale.com PR | parts/contract_economics.xlsx (GPU Market agent) P2a | Z14: Within P2.
