Workbook

Sheet README
A1: payback_dilution.xlsx - Nebius Peer KPIs bot - built 2026-10-04 (ET) by peers/build_payback_dilution.py. Recalculated in LibreOffice: 0 error cells.
A3: QUESTION 1: Does Nebius's ~22-month payback on $20-25M/MW reconcile only on a GROSS-MW reading? (moves Modeling PT $46 -> $147)
A4: Exact Nebius wording (S1, Q2'26 letter Aug 12 2026): 'ACV per MW is stepping up(1): $12M 2026 base; >$20M Q2 deals; >$40M Q3 short-term capacity deals'; 'Payback period(2)(3) 1 year 10 months for deals closed in Q2'.
A5: fn(1) 'ACV - Annual contract value.' fn(2) 'Methodology is on a revenue recognition basis, excluding any prepayment.' fn(3) 'Estimated payback period for new deals signed in Q2, based on forecast costs and contracted future capacity, including capacity not yet built.'
A6: Body: 'yield of $20-25 million per megawatt'; 'the expected payback period for the associated capex and related operating costs for Q2 deals is 1 year and 10 months, down from our two-to-three year payback period previously.' Call (S2): '<two-year payback'. NO IT vs gross basis anywhere.
A7: Method: Payback = compute capex per IT MW / (ACV per Nebius-MW x f - opex per IT MW) x 12, f = 1 (IT) or 1.2/1.3/1.4 (gross). Prepayments excluded (fn 2). Leased capacity: shell is rent inside opex.
A8: Key point: within any one deal payback is basis-invariant (Payback_ACV cols Z = AA). The basis only matters because Nebius's ACV/MW is being compared with per-IT-MW capex benchmarks.
A9: VERDICT: NO - it does not reconcile ONLY on gross. IT reading ($22.5M per IT MW, leased, opex $4.5M/IT MW-yr) = 19.3 months at IREN's DISCLOSED GB300 capex ($29M/IT MW, Dell PO) and 22.7 months at the ~$34M/IT MW implied by IREN's own '>$20M per MW (IT), ~2 year payback' (same capex/(revenue - direct costs) definition, explicit IT basis).
A10: The gross reading is REQUIRED only if Nebius's compute capex is ~$40M+/IT MW (Capacity base $40.3M / Modeling $41.3M: IT 26.8-27.5 mo vs gross x1.2/1.3/1.4 = 21.5/19.5/17.9 mo), or if the ~50% segment EBITDA margin is used. 22 mo on IT needs <= $33.0M/IT MW (range $28.4-37.6M at ACV $20-25M); on gross x1.3 <= $45.4M. Confidence IT reading is right: MEDIUM (~60%).
A11: Sensitivities: compute capex (+$1M/IT MW = +0.67 mo on IT reading); opex (+$1M/IT MW-yr = +1.2-1.6 mo); ACV $20 vs $25 (IT @ $29M: 22.5 vs 17.0 mo); gross factor 1.2 vs 1.4 (@ $40.3M: 21.5 vs 17.9 mo). The capex number (third-party estimate vs IREN's disclosed purchase price) is the single swing factor.
A12: Counter-evidence (kept): Capacity finds YE25 in-service servers+network at only $18.4M per active MW (S18) - Nebius's own MW may run close to gross, or it buys cheaper; Filings (21:39 ET) leans gross at $41M capex/IT MW.
A14: QUESTION 2: Dilution curve. Primary fit (Dilution_Fit F1): CoreWeave rev/avg MW = 10.88 - 5.68 x ramp ratio (R^2 0.79, n=10) -> factor 1 - k x ramp, k = 0.52 (0.43-0.62 at +/-1 SE). ln(MW) fit fails on full sample (R^2 0.07).
... A20: Not edited: capacity/, model/, filings/, parts/ (values copied with cell citations).

Sheet Payback_ACV
A1: Payback / ACV test - peer deals vs Nebius. Payback (months) = capex per MW / (ACV per MW x cash margin) x 12; prepayments EXCLUDED (Nebius fn 2, IREN fn 3 basis). $M; MW.
A2: Within one deal, payback is identical on IT and gross MW (both numerator and denominator scale by the same factor) - columns Z vs AA prove it. The IT/gross question only bites when a per-MW benchmark on one basis is applied to per-MW revenue on another: see Basis_Sensitivity.
A4: Shared assumption | C4: Value | D4: Tag | E4: Source / note
A5: Opex per IT MW-yr for LEASED capacity (rent + power + ops) | C5: 4.5 | D5: E | E5: S14 Modeling PB_Opex (range 4-5)
A6: Default gross/IT factor (PUE-type) where basis must be converted | C6: 1.3 | D6: E | E6: S11 base PUE 1.2-1.3; sensitivity 1.2-1.4 in Basis_Sensitivity
A7: GB300 NVL72 compute (server+network+storage) $k per GPU | C7: 81.94 | D7: E | E7: S11 CapexPerMW GB300 base
A8: GB300 GPUs per IT MW | C8: 491.17 | D8: E | E8: S11
A9: Vera Rubin NVL72 compute $k per GPU | C9: 94.44 | D9: E | E9: S11 VR base
A10: Vera Rubin GPUs per IT MW | C10: 320.43 | D10: E | E10: S11
A11: GB200 NVL72 compute $k per GPU | C11: 54.17 | D11: E | E11: S11 GB200 base
A12: GB200 GPUs per IT MW | C12: 538.32 | D12: E | E12: S11
A13: B300 HGX compute $k per GPU | C13: 80 | D13: E | E13: S11 B300 base
A14: B300 GPUs per IT MW | C14: 501.57 | D14: E | E14: S11
A15: Owned DC shell + power $M per IT MW | C15: 12.5 | D15: E | E15: S11 base (range 8-17.6); Crusoe Abilene $12.5M/MW (S13)
A16: IREN Horizon DC build $M per IT MW | C16: 6.5 | D16: D | E16: S7 ($300-350M / 50 MW IT)
A17: IREN Microsoft project EBITDA margin | C17: 0.85 | D17: R | E17: S4
A18: Nebius AI cloud adj. EBITDA margin Q2'26 (segment, incl. overhead) | C18: =285.7/574.9 -> 0.49695599 | D18: D | E18: S17
A19: Oracle AI-infra CASH margin, analyst-day example: 1 - (35% x $6.4B)/$10B | C19: =1-0.35*6.4/10 -> 0.776 | D19: D | E19: S12 (assumes the 65% compute cost is non-cash depreciation; E element)
A22: ID | B22: Deal | C22: Provider | D22: Chip | E22: ACV $M/yr | F22: tag | G22: Stated MW | H22: Stated basis (IT/gross) | I22: MW tag | J22: Gross/IT factor | K22: tag | L22: IT MW | M22: Gross MW | N22: ACV $M per IT MW-yr | O22: ACV $M per gross MW-yr | P22: Compute capex $M (GPUs+network+storage) | Q22: tag | R22: Compute $M per IT MW | S22: DC shell+power $M per IT MW (0 = leased, rent in opex) | T22: tag | U22: Total capex $M per IT MW | V22: Total capex $M per gross MW | W22: Cash margin (EBITDA/rev) | X22: tag | Y22: Payback compute-only (months) | Z22: Payback total capex, IT basis (months) | AA22: Payback total capex, gross basis (months) | AB22: Reported payback (months) | AC22: Payback tag | AD22: Sources | AE22: Notes
A23: P1 | B23: IREN - Microsoft (Childress Horizon 1-4), 5 yr | C23: IREN | D23: GB300 | E23: =9700/5 -> 1940 | F23: D | G23: 200 | H23: IT | I23: R | J23: =$C$6 -> 1.3 | K23: E | L23: =IF(H23="gross",G23/J23,G23) -> 200 | M23: =IF(H23="gross",G23,G23*J23) -> 260 | N23: =E23/L23 -> 9.7 | O23: =E23/M23 -> 7.4615385 | P23: 5800 | Q23: R | R23: =P23/L23 -> 29 | S23: =$C$16 -> 6.5 | T23: D | U23: =R23+S23 -> 35.5 | V23: =U23*L23/M23 -> 27.307692 | W23: =$C$17 -> 0.85 | X23: R | Y23: =R23/(N23*W23)*12 -> 42.207398 | Z23: =U23/(N23*W23)*12 -> 51.667677 | AA23: =V23/(O23*W23)*12 -> 51.667677 | AB23: n-d | AC23: D | AD23: S3,S4,S7 | AE23: Capex = Dell GPU+ancillaries $5.8B (R). ACV $1.94B = IREN ARR (R). Gross MW not stated for Horizon; factor is the sensitivity default. 85% = IREN's own project EBITDA margin (owned power).
A24: P1b | B24: IREN - recent 3-yr contracts (FY26 PR), per 1 IT MW | C24: IREN | D24: GB300-class | E24: 20 | F24: R | G24: 1 | H24: IT | I24: R | J24: =$C$6 -> 1.3 | K24: E | L24: =IF(H24="gross",G24/J24,G24) -> 1 | M24: =IF(H24="gross",G24,G24*J24) -> 1.3 | N24: =E24/L24 -> 20 | O24: =E24/M24 -> 15.384615 | P24: =5800/200 -> 29 | Q24: E | R24: =P24/L24 -> 29 | S24: =$C$16 -> 6.5 | T24: D | U24: =R24+S24 -> 35.5 | V24: =U24*L24/M24 -> 27.307692 | W24: =$C$17 -> 0.85 | X24: E | Y24: =R24/(N24*W24)*12 -> 20.470588 | Z24: =U24/(N24*W24)*12 -> 25.058824 | AA24: =V24/(O24*W24)*12 -> 25.058824 | AB24: 24 | AC24: E | AD24: S5,S3,S4 | AE24: '>$20m revenue per MW (IT), representing a ~2 year payback' (R; IREN def = GPU+ancillaries capex / (revenue - direct costs)). Capex = IREN Microsoft $29M/IT MW applied (E); margin = Microsoft project margin applied (E). Model gives ~20.5 mo vs reported ~24 -> IREN's own implied capex ~$34M/IT MW.
A25: C1 | B25: CoreWeave fleet Q2'26 (all contracts; no deal-level MW disclosed) | C25: CoreWeave | D25: Mixed | E25: =2575*4 -> 10300 | F25: D | G25: =(1000+1500)/2 -> 1250 | H25: IT | I25: E | J25: =$C$6 -> 1.3 | K25: E | L25: =IF(H25="gross",G25/J25,G25) -> 1250 | M25: =IF(H25="gross",G25,G25*J25) -> 1625 | N25: =E25/L25 -> 8.24 | O25: =E25/M25 -> 6.3384615 | P25: =(31352+40704)/2 -> 36028 | Q25: D | R25: =P25/L25 -> 28.8224 | S25: 0 | T25: R | U25: =R25+S25 -> 28.8224 | V25: =U25*L25/M25 -> 22.171077 | W25: =1510/2575 -> 0.58640777 | X25: D | Y25: =R25/(N25*W25)*12 -> 71.578808 | Z25: =U25/(N25*W25)*12 -> 71.578808 | AA25: =V25/(O25*W25)*12 -> 71.578808 | AB25: n-d | AC25: E | AD25: S8 | AE25: Avg active MW (CRWV 'active power' ~ IT-like, E). Capex = avg in-service gross PP&E (incl. leasehold improvements; DCs leased so shell = 0, rent inside adj. EBITDA). Fleet-level: includes older Hopper at lower $/MW and capacity still ramping - an upper bound on deal payback. Deal MW for Meta/OpenAI n-d.
A26: N1 | B26: Nscale - Microsoft, all SOWs (TX, Narvik, Loughton, Sines), 5.5 yr | C26: Nscale | D26: GB300 + VR | E26: =43800/5.5 -> 7963.6364 | F26: D | G26: 596.47 | H26: IT | I26: D | J26: =$C$6 -> 1.3 | K26: E | L26: =IF(H26="gross",G26/J26,G26) -> 596.47 | M26: =IF(H26="gross",G26,G26*J26) -> 775.411 | N26: =E26/L26 -> 13.351277 | O26: =E26/M26 -> 10.270213 | P26: =(191600*$C$7+66000*$C$9)/1000 -> 21932.744 | Q26: E | R26: =P26/L26 -> 36.770909 | S26: =$C$15 -> 12.5 | T26: E | U26: =R26+S26 -> 49.270909 | V26: =U26*L26/M26 -> 37.900699 | W26: =$C$17 -> 0.85 | X26: E | Y26: =R26/(N26*W26)*12 -> 38.881577 | Z26: =U26/(N26*W26)*12 -> 52.099083 | AA26: =V26/(O26*W26)*12 -> 52.099083 | AB26: n-d | AC26: E | AD26: S9,S10,S11 | AE26: IT MW derived from 191.6k GB300/491 + 66k VR/320 (S10). Capex n-d -> GPU count x unit cost (E). Margin n-d (Nscale adj. EBITDA negative) -> IREN owned-power project margin applied (E). S-1: payback 'within the initial contract term' only.
A27: N1a | B27: of which Nscale/Aker - Microsoft Narvik, 5 yr | C27: Nscale | D27: GB300 | E27: =6200/5 -> 1240 | F27: D | G27: 105.91 | H27: IT | I27: D | J27: =$C$6 -> 1.3 | K27: E | L27: =IF(H27="gross",G27/J27,G27) -> 105.91 | M27: =IF(H27="gross",G27,G27*J27) -> 137.683 | N27: =E27/L27 -> 11.708054 | O27: =E27/M27 -> 9.0061954 | P27: =52000*$C$7/1000 -> 4260.88 | Q27: E | R27: =P27/L27 -> 40.23114 | S27: =$C$15 -> 12.5 | T27: E | U27: =R27+S27 -> 52.73114 | V27: =U27*L27/M27 -> 40.562415 | W27: =$C$17 -> 0.85 | X27: E | Y27: =R27/(N27*W27)*12 -> 48.510968 | Z27: =U27/(N27*W27)*12 -> 63.583548 | AA27: =V27/(O27*W27)*12 -> 63.583548 | AB27: n-d | AC27: E | AD27: S10,S11 | AE27: 52,000 GB300 (R) / 491 per IT MW (E).
A28: N2 | B28: Nscale - Anthropic (Monarch WV), Vera Rubin, 6 yr | C28: Nscale | D28: Vera Rubin | E28: =44600/6 -> 7433.3333 | F28: D | G28: 460 | H28: IT | I28: R | J28: =$C$6 -> 1.3 | K28: E | L28: =IF(H28="gross",G28/J28,G28) -> 460 | M28: =IF(H28="gross",G28,G28*J28) -> 598 | N28: =E28/L28 -> 16.15942 | O28: =E28/M28 -> 12.430323 | P28: =460*$C$10*$C$9/1000 -> 13920.248 | Q28: E | R28: =P28/L28 -> 30.261409 | S28: =$C$15 -> 12.5 | T28: E | U28: =R28+S28 -> 42.761409 | V28: =U28*L28/M28 -> 32.893392 | W28: =$C$17 -> 0.85 | X28: E | Y28: =R28/(N28*W28)*12 -> 26.437823 | Z28: =U28/(N28*W28)*12 -> 37.358424 | AA28: =V28/(O28*W28)*12 -> 37.358424 | AB28: n-d | AC28: E | AD28: S9,S10,S11 | AE28: 460 IT MW contracted (S-1 site table, R). GPUs n-d (redacted) -> density x unit cost (E). Monarch gross/IT 8/6.5 GW = 1.23 (S11 Peers).
A29: O1 | B29: Oracle - OpenAI (Stargate incl. Abilene), ~5 yr | C29: Oracle | D29: GB200 mix | E29: =300000/5 -> 60000 | F29: P | G29: 4500 | H29: gross | I29: E | J29: 1.2 | K29: E | L29: =IF(H29="gross",G29/J29,G29) -> 3750 | M29: =IF(H29="gross",G29,G29*J29) -> 4500 | N29: =E29/L29 -> 16 | O29: =E29/M29 -> 13.333333 | P29: =L29*$C$12*$C$11/1000 -> 109352.98 | Q29: E | R29: =P29/L29 -> 29.160794 | S29: 0 | T29: E | U29: =R29+S29 -> 29.160794 | V29: =U29*L29/M29 -> 24.300662 | W29: =$C$19 -> 0.776 | X29: D | Y29: =R29/(N29*W29)*12 -> 28.183757 | Z29: =U29/(N29*W29)*12 -> 28.183757 | AA29: =V29/(O29*W29)*12 -> 28.183757 | AB29: n-d | AC29: E | AD29: S19,S12,S13 | AE29: 4.5 GW unlabeled; read as gross (Abilene 450k GB200 / 1.2 GW = 375 GPUs/MW < 449/gross MW) -> factor 1.2 (E). Oracle leases shells from developers (Crusoe/Blue Owl JV) so shell = 0 and rent sits in the 35% site/DC/power cost bucket (S12).
A30: NB1 | B30: Nebius - Microsoft (Vineland), 5 yr committed | C30: Nebius | D30: GB300 | E30: =17392.9/5 -> 3478.58 | F30: D | G30: 300 | H30: gross | I30: E | J30: =$C$6 -> 1.3 | K30: E | L30: =IF(H30="gross",G30/J30,G30) -> 230.76923 | M30: =IF(H30="gross",G30,G30*J30) -> 300 | N30: =E30/L30 -> 15.073847 | O30: =E30/M30 -> 11.595267 | P30: =100000*$C$7/1000 -> 8194 | Q30: E | R30: =P30/L30 -> 35.507333 | S30: 0 | T30: R | U30: =R30+S30 -> 35.507333 | V30: =U30*L30/M30 -> 27.313333 | W30: =1-$C$5/N30 -> 0.7014697 | X30: E | Y30: =R30/(N30*W30)*12 -> 40.296404 | Z30: =U30/(N30*W30)*12 -> 40.296404 | AA30: =V30/(O30*W30)*12 -> 40.296404 | AB30: n-d | AC30: E | AD30: S10,S11,S14 | AE30: 'up to 300 MW' unlabeled; Capacity reads gross. GPU-derived IT MW = 100k/491 = 203.7 (ACV $17.1M/IT MW). Capex: >100k GB300 (P) x unit cost (E). Vineland = build-to-suit lease (rent in opex). Margin = 1 - opex/ACV per IT MW (E). Prepayment 40% excluded.
A31: NB2 | B31: Nebius - Meta #1 (Nov-2025), 5 yr | C31: Nebius | D31: n-d (B300?) | E31: =2880.7/5 -> 576.14 | F31: D | G31: 50 | H31: IT | I31: E | J31: =$C$6 -> 1.3 | K31: E | L31: =IF(H31="gross",G31/J31,G31) -> 50 | M31: =IF(H31="gross",G31,G31*J31) -> 65 | N31: =E31/L31 -> 11.5228 | O31: =E31/M31 -> 8.8636923 | P31: =L31*$C$14*$C$13/1000 -> 2006.28 | Q31: E | R31: =P31/L31 -> 40.1256 | S31: 0 | T31: E | U31: =R31+S31 -> 40.1256 | V31: =U31*L31/M31 -> 30.865846 | W31: =1-$C$5/N31 -> 0.60946992 | X31: E | Y31: =R31/(N31*W31)*12 -> 68.563422 | Z31: =U31/(N31*W31)*12 -> 68.563422 | AA31: =V31/(O31*W31)*12 -> 68.563422 | AB31: n-d | AC31: E | AD31: S10,S11 | AE31: MW not disclosed: ~50 MW is a LOW-confidence estimate (S10). Chip unverified. Reference only.
A32: NB3 | B32: Nebius - Meta #2 (Mar-2026), dedicated Vera Rubin, 5 yr | C32: Nebius | D32: Vera Rubin | E32: =12000/5 -> 2400 | F32: D | G32: n-d | H32: n-d | I32: n-d | J32: n-d | K32: n-d | L32: n-d | M32: n-d | N32: n-d | O32: n-d | P32: n-d | Q32: n-d | R32: n-d | S32: n-d | T32: n-d | U32: n-d | V32: n-d | W32: n-d | X32: n-d | Y32: n-d | Z32: n-d | AA32: n-d | AB32: n-d | AC32: n-d | AD32: S10 | AE32: MW and GPUs not disclosed -> per-MW metrics and payback n-d. At $16.2M/IT MW (Nscale-Anthropic VR) it would be ~148 IT MW.
A33: NQ-A | B33: Nebius Q2'26 deals - reading A: $22.5M per IT MW, Capacity GB300 compute capex | C33: Nebius | D33: GB300 (assumed) | E33: 22.5 | F33: R | G33: 1 | H33: IT | I33: E | J33: =$C$6 -> 1.3 | K33: E | L33: =IF(H33="gross",G33/J33,G33) -> 1 | M33: =IF(H33="gross",G33,G33*J33) -> 1.3 | N33: =E33/L33 -> 22.5 | O33: =E33/M33 -> 17.307692 | P33: =$C$8*$C$7/1000 -> 40.24647 | Q33: E | R33: =P33/L33 -> 40.24647 | S33: 0 | T33: E | U33: =R33+S33 -> 40.24647 | V33: =U33*L33/M33 -> 30.958823 | W33: =1-$C$5/N33 -> 0.8 | X33: E | Y33: =R33/(N33*W33)*12 -> 26.83098 | Z33: =U33/(N33*W33)*12 -> 26.83098 | AA33: =V33/(O33*W33)*12 -> 26.83098 | AB33: 22 | AC33: E | AD33: S1,S2,S11,S14 | AE33: ACV = midpoint of '$20-25 million per megawatt' (R). Leased/colo capacity assumed (most late-2026 capacity is colo/build-to-suit). Reported 22 = '1 year 10 months'.
A34: NQ-B | B34: Nebius Q2'26 deals - reading A': $22.5M per IT MW, IREN-disclosed GB300 capex ($29M/IT MW) | C34: Nebius | D34: GB300 (assumed) | E34: 22.5 | F34: R | G34: 1 | H34: IT | I34: E | J34: =$C$6 -> 1.3 | K34: E | L34: =IF(H34="gross",G34/J34,G34) -> 1 | M34: =IF(H34="gross",G34,G34*J34) -> 1.3 | N34: =E34/L34 -> 22.5 | O34: =E34/M34 -> 17.307692 | P34: =5800/200 -> 29 | Q34: D | R34: =P34/L34 -> 29 | S34: 0 | T34: E | U34: =R34+S34 -> 29 | V34: =U34*L34/M34 -> 22.307692 | W34: =1-$C$5/N34 -> 0.8 | X34: E | Y34: =R34/(N34*W34)*12 -> 19.333333 | Z34: =U34/(N34*W34)*12 -> 19.333333 | AA34: =V34/(O34*W34)*12 -> 19.333333 | AB34: 22 | AC34: E | AD34: S1,S3,S14 | AE34: Same as NQ-A but compute capex = IREN's actual Dell purchase price per IT MW (D).
A35: NQ-C | B35: Nebius Q2'26 deals - reading B: $22.5M per GROSS MW, Capacity GB300 compute capex | C35: Nebius | D35: GB300 (assumed) | E35: 22.5 | F35: R | G35: 1 | H35: gross | I35: E | J35: =$C$6 -> 1.3 | K35: E | L35: =IF(H35="gross",G35/J35,G35) -> 0.76923077 | M35: =IF(H35="gross",G35,G35*J35) -> 1 | N35: =E35/L35 -> 29.25 | O35: =E35/M35 -> 22.5 | P35: =L35*$C$8*$C$7/1000 -> 30.958823 | Q35: E | R35: =P35/L35 -> 40.24647 | S35: 0 | T35: E | U35: =R35+S35 -> 40.24647 | V35: =U35*L35/M35 -> 30.958823 | W35: =1-$C$5/N35 -> 0.84615385 | X35: E | Y35: =R35/(N35*W35)*12 -> 19.51344 | Z35: =U35/(N35*W35)*12 -> 19.51344 | AA35: =V35/(O35*W35)*12 -> 19.51344 | AB35: 22 | AC35: E | AD35: S1,S11,S14 | AE35: Gross reading: ACV per IT MW = 22.5 x factor.
A37: Memo (not MW-based)
A38: OR-hyp | B38: Oracle analyst-day example: $60B / 6 yr AI contract, $6.4B cost/yr; compute 65% treated as straight-line depreciation over 6 yr -> capex = 0.65 x 6.4 x 6 | E38: 10 | F38: R | P38: =0.65*6.4*6 -> 24.96 | Q38: E | W38: =$C$19 -> 0.776 | X38: D | Z38: =P38/(E38*W38)*12 -> 38.597938 | AC38: E | AD38: S12
A39: X-AB | B39: Crusoe Abilene (DC developer; facility only): $15B / 1,200 MW = DC shell+power $M per MW (basis unlabeled); lease revenue to Oracle n-d -> payback n-d | S39: =15000/1200 -> 12.5 | T39: D | Z39: n-d | AD39: S13
A40: Peer band | B40: Peer deal payback (total capex) - min / median / max over P1, N1, N1a, N2, O1 (deal-level rows; excludes CoreWeave fleet) | Y40: =MIN(Z23,Z26,Z27,Z28,Z29) -> 28.183757 | Z40: =MEDIAN(Z23,Z26,Z27,Z28,Z29) -> 51.667677 | AA40: =MAX(Z23,Z26,Z27,Z28,Z29) -> 63.583548 | AC40: E
B41: Peer deal payback (compute-only) - min / median / max over the same rows | Y41: =MIN(Y23,Y26,Y27,Y28,Y29) -> 26.437823 | Z41: =MEDIAN(Y23,Y26,Y27,Y28,Y29) -> 38.881577 | AA41: =MAX(Y23,Y26,Y27,Y28,Y29) -> 48.510968 | AC41: E

Sheet Basis_Sensitivity
A1: Does Nebius's ~22-month payback on $20-25M/MW reconcile only on a GROSS-MW reading? Payback = capex per IT MW / (ACV per Nebius-MW x f - opex per IT MW) x 12, f = 1 (IT reading) or gross/IT factor (gross reading).
A3: Inputs
A4: ACV per MW - low / mid / high ($M/yr) | B4: 20 | C4: 22.5 | D4: 25 | F4: R | G4: S1/S2 '$20-25 million per megawatt'
A5: Nebius payback target (months) | B5: 22 | F5: R | G5: S1 '1 year 10 months' (fn: revenue-recognition basis, ex-prepayment, incl. related operating costs)
A6: Opex per IT MW-yr, leased capacity ($M) | B6: =Payback_ACV!$C$5 -> 4.5 | F6: E | G6: S14
A7: Gross/IT factor sensitivity (PUE-type) | B7: 1.2 | C7: 1.3 | D7: 1.4 | F7: E | G7: S11 (GB300/VR base PUE 1.2; Hopper 1.3); Nscale Monarch 1.23, AIB 1.30
A8: Benchmark peer margin, IREN project EBITDA | B8: =Payback_ACV!$C$17 -> 0.85 | F8: R | G8: S4
A10: Capex benchmarks ($M per IT MW, prepayments ignored) | B10: Value | C10: Tag | D10: Source
A11: b1 IREN actual: Dell GB300 GPUs + ancillaries $5.8B / 200 IT MW (compute only) | B11: =5800/200 -> 29 | C11: D | D11: S3/S4
A12: b2 IREN-implied: '>$20M/IT MW ~2-yr payback' at 85% margin = 24/12 x 20 x 85% | B12: =24/12*20*$B$8 -> 34 | C12: D | D12: S5/S4
A13: b3 Capacity GB300 compute LOW | B13: 35.47 | C13: E | D13: S11
A14: b4 Capacity GB300 compute BASE (= 491 x $81.9k) | B14: =Payback_ACV!$C$8*Payback_ACV!$C$7/1000 -> 40.24647 | C14: E | D14: S11
A15: b5 Modeling leased GB300 (PB_CapGB) | B15: 41.3 | C15: E | D15: S14
A16: b6 Capacity GB300 compute HIGH | B16: 52.53 | C16: E | D16: S11
A17: b7 Capacity Vera Rubin compute BASE (= 320 x $94.4k) | B17: =Payback_ACV!$C$10*Payback_ACV!$C$9/1000 -> 30.261409 | C17: E | D17: S11 (Modeling uses 41 for Rubin: S14)
A18: b8 GB300 OWNED full stack base (compute + $12.5M shell) | B18: 52.75 | C18: E | D18: S11 - only relevant if Nebius owns the shell (opex then excludes rent)
A21: Table A - implied payback (months) by capex benchmark x MW reading
B22: IT @ $20 | C22: IT @ $22.5 | D22: IT @ $25 | E22: Gross x1.2 @ $22.5 | F22: Gross x1.3 @ $22.5 | G22: Gross x1.4 @ $22.5 | H22: Gross x1.3 @ $20 | I22: Gross x1.3 @ $25 | J22: Tag
A23: =A11 -> b1 IREN actual: Dell GB300 GPUs + ancillaries $5.8B / 200 IT MW (compute only) | B23: =$B$11/($B$4*1-$B$6)*12 -> 22.451613 | C23: =$B$11/($C$4*1-$B$6)*12 -> 19.333333 | D23: =$B$11/($D$4*1-$B$6)*12 -> 16.97561 | E23: =$B$11/($C$4*$B$7-$B$6)*12 -> 15.466667 | F23: =$B$11/($C$4*$C$7-$B$6)*12 -> 14.060606 | G23: =$B$11/($C$4*$D$7-$B$6)*12 -> 12.888889 | H23: =$B$11/($B$4*$C$7-$B$6)*12 -> 16.186047 | I23: =$B$11/($D$4*$C$7-$B$6)*12 -> 12.428571 | J23: E
A24: =A12 -> b2 IREN-implied: '>$20M/IT MW ~2-yr payback' at 85% margin = 24/12 x 20 x 85% | B24: =$B$12/($B$4*1-$B$6)*12 -> 26.322581 | C24: =$B$12/($C$4*1-$B$6)*12 -> 22.666667 | D24: =$B$12/($D$4*1-$B$6)*12 -> 19.902439 | E24: =$B$12/($C$4*$B$7-$B$6)*12 -> 18.133333 | F24: =$B$12/($C$4*$C$7-$B$6)*12 -> 16.484848 | G24: =$B$12/($C$4*$D$7-$B$6)*12 -> 15.111111 | H24: =$B$12/($B$4*$C$7-$B$6)*12 -> 18.976744 | I24: =$B$12/($D$4*$C$7-$B$6)*12 -> 14.571429 | J24: E
A25: =A13 -> b3 Capacity GB300 compute LOW | B25: =$B$13/($B$4*1-$B$6)*12 -> 27.460645 | C25: =$B$13/($C$4*1-$B$6)*12 -> 23.646667 | D25: =$B$13/($D$4*1-$B$6)*12 -> 20.762927 | E25: =$B$13/($C$4*$B$7-$B$6)*12 -> 18.917333 | F25: =$B$13/($C$4*$C$7-$B$6)*12 -> 17.197576 | G25: =$B$13/($C$4*$D$7-$B$6)*12 -> 15.764444 | H25: =$B$13/($B$4*$C$7-$B$6)*12 -> 19.797209 | I25: =$B$13/($D$4*$C$7-$B$6)*12 -> 15.201429 | J25: E
A26: =A14 -> b4 Capacity GB300 compute BASE (= 491 x $81.9k) | B26: =$B$14/($B$4*1-$B$6)*12 -> 31.158557 | C26: =$B$14/($C$4*1-$B$6)*12 -> 26.83098 | D26: =$B$14/($D$4*1-$B$6)*12 -> 23.558909 | E26: =$B$14/($C$4*$B$7-$B$6)*12 -> 21.464784 | F26: =$B$14/($C$4*$C$7-$B$6)*12 -> 19.51344 | G26: =$B$14/($C$4*$D$7-$B$6)*12 -> 17.88732 | H26: =$B$14/($B$4*$C$7-$B$6)*12 -> 22.463146 | I26: =$B$14/($D$4*$C$7-$B$6)*12 -> 17.248487 | J26: E
A27: =A15 -> b5 Modeling leased GB300 (PB_CapGB) | B27: =$B$15/($B$4*1-$B$6)*12 -> 31.974194 | C27: =$B$15/($C$4*1-$B$6)*12 -> 27.533333 | D27: =$B$15/($D$4*1-$B$6)*12 -> 24.17561 | E27: =$B$15/($C$4*$B$7-$B$6)*12 -> 22.026667 | F27: =$B$15/($C$4*$C$7-$B$6)*12 -> 20.024242 | G27: =$B$15/($C$4*$D$7-$B$6)*12 -> 18.355556 | H27: =$B$15/($B$4*$C$7-$B$6)*12 -> 23.051163 | I27: =$B$15/($D$4*$C$7-$B$6)*12 -> 17.7 | J27: E
A28: =A16 -> b6 Capacity GB300 compute HIGH | B28: =$B$16/($B$4*1-$B$6)*12 -> 40.668387 | C28: =$B$16/($C$4*1-$B$6)*12 -> 35.02 | D28: =$B$16/($D$4*1-$B$6)*12 -> 30.749268 | E28: =$B$16/($C$4*$B$7-$B$6)*12 -> 28.016 | F28: =$B$16/($C$4*$C$7-$B$6)*12 -> 25.469091 | G28: =$B$16/($C$4*$D$7-$B$6)*12 -> 23.346667 | H28: =$B$16/($B$4*$C$7-$B$6)*12 -> 29.31907 | I28: =$B$16/($D$4*$C$7-$B$6)*12 -> 22.512857 | J28: E
A29: =A17 -> b7 Capacity Vera Rubin compute BASE (= 320 x $94.4k) | B29: =$B$17/($B$4*1-$B$6)*12 -> 23.428188 | C29: =$B$17/($C$4*1-$B$6)*12 -> 20.174273 | D29: =$B$17/($D$4*1-$B$6)*12 -> 17.713996 | E29: =$B$17/($C$4*$B$7-$B$6)*12 -> 16.139418 | F29: =$B$17/($C$4*$C$7-$B$6)*12 -> 14.672198 | G29: =$B$17/($C$4*$D$7-$B$6)*12 -> 13.449515 | H29: =$B$17/($B$4*$C$7-$B$6)*12 -> 16.890089 | I29: =$B$17/($D$4*$C$7-$B$6)*12 -> 12.969175 | J29: E
A30: =A18 -> b8 GB300 OWNED full stack base (compute + $12.5M shell) | B30: =$B$18/($B$4*1-$B$6)*12 -> 40.83871 | C30: =$B$18/($C$4*1-$B$6)*12 -> 35.166667 | D30: =$B$18/($D$4*1-$B$6)*12 -> 30.878049 | E30: =$B$18/($C$4*$B$7-$B$6)*12 -> 28.133333 | F30: =$B$18/($C$4*$C$7-$B$6)*12 -> 25.575758 | G30: =$B$18/($C$4*$D$7-$B$6)*12 -> 23.444444 | H30: =$B$18/($B$4*$C$7-$B$6)*12 -> 29.44186 | I30: =$B$18/($D$4*$C$7-$B$6)*12 -> 22.607143 | J30: E
A32: Table B - compute capex per IT MW REQUIRED to hit 22 months = 22/12 x (ACV x f - opex)
B33: IT (f=1) | C33: Gross x1.2 | D33: Gross x1.3 | E33: Gross x1.4
A34: ACV $20M/MW | B34: =$B$5/12*($B$4*1-$B$6) -> 28.416667 | C34: =$B$5/12*($B$4*$B$7-$B$6) -> 35.75 | D34: =$B$5/12*($B$4*$C$7-$B$6) -> 39.416667 | E34: =$B$5/12*($B$4*$D$7-$B$6) -> 43.083333 | G34: D/E
A35: ACV $22.5M/MW | B35: =$B$5/12*($C$4*1-$B$6) -> 33 | C35: =$B$5/12*($C$4*$B$7-$B$6) -> 41.25 | D35: =$B$5/12*($C$4*$C$7-$B$6) -> 45.375 | E35: =$B$5/12*($C$4*$D$7-$B$6) -> 49.5 | G35: D/E
A36: ACV $25M/MW | B36: =$B$5/12*($D$4*1-$B$6) -> 37.583333 | C36: =$B$5/12*($D$4*$B$7-$B$6) -> 46.75 | D36: =$B$5/12*($D$4*$C$7-$B$6) -> 51.333333 | E36: =$B$5/12*($D$4*$D$7-$B$6) -> 55.916667 | G36: D/E
A38: Table C - margin-based variant (payback = capex / (ACV x f x margin)), ACV $22.5M
B39: IT @ b1 IREN $29M | C39: IT @ b4 Capacity $40.3M | D39: Gross x1.3 @ b1 | E39: Gross x1.3 @ b4 | F39: Margin
A40: Nebius AI cloud adj. EBITDA margin Q2'26 (segment, after overhead) - D | B40: =$B$11/($C$4*1*$F40)*12 -> 31.122809 | C40: =$B$14/($C$4*1*$F40)*12 -> 43.192525 | D40: =$B$11/($C$4*$C$7*$F40)*12 -> 23.940623 | E40: =$B$14/($C$4*$C$7*$F40)*12 -> 33.225019 | F40: =Payback_ACV!$C$18 -> 0.49695599
A41: CoreWeave adj. EBITDA margin Q2'26 (after DC rent) - D | B41: =$B$11/($C$4*1*$F41)*12 -> 26.375276 | C41: =$B$14/($C$4*1*$F41)*12 -> 36.603853 | D41: =$B$11/($C$4*$C$7*$F41)*12 -> 20.288674 | E41: =$B$14/($C$4*$C$7*$F41)*12 -> 28.15681 | F41: =Payback_ACV!W25 -> 0.58640777
A42: Oracle AI-infra cash margin (analyst-day example) - D/E | B42: =$B$11/($C$4*1*$F42)*12 -> 19.931271 | C42: =$B$14/($C$4*1*$F42)*12 -> 27.660804 | D42: =$B$11/($C$4*$C$7*$F42)*12 -> 15.331747 | E42: =$B$14/($C$4*$C$7*$F42)*12 -> 21.277542 | F42: =Payback_ACV!$C$19 -> 0.776
A43: Leased deal-level: 1 - opex/ACV at $22.5M IT - E | B43: =$B$11/($C$4*1*$F43)*12 -> 19.333333 | C43: =$B$14/($C$4*1*$F43)*12 -> 26.83098 | D43: =$B$11/($C$4*$C$7*$F43)*12 -> 14.871795 | E43: =$B$14/($C$4*$C$7*$F43)*12 -> 20.639215 | F43: =1-$B$6/$C$4 -> 0.8
A44: IREN Microsoft project EBITDA margin (owned power) - R | B44: =$B$11/($C$4*1*$F44)*12 -> 18.196078 | C44: =$B$14/($C$4*1*$F44)*12 -> 25.252687 | D44: =$B$11/($C$4*$C$7*$F44)*12 -> 13.996983 | E44: =$B$14/($C$4*$C$7*$F44)*12 -> 19.425144 | F44: =Payback_ACV!$C$17 -> 0.85
A46: Table D - opex sensitivity ($M per IT MW-yr), ACV $22.5M, payback months
B47: IT @ b1 | C47: IT @ b2 | D47: IT @ b4 | E47: Gross x1.3 @ b4 | F47: Gross x1.3 @ b5 | G47: Opex
...

Sheet Dilution_Data
A1: Revenue per average active MW vs capacity. Avg MW = (open+close)/2; ramp ratio = MW added in quarter / average MW; rev/MW annualized (x4).
A3: Company | B3: Quarter | C3: Qtrs since series start | D3: Open MW | E3: Close MW | F3: MW tag | G3: Avg MW | H3: New MW | I3: Ramp ratio (new/avg) | J3: ln(avg MW) | K3: Revenue $M (qtr) | L3: Rev tag | M3: Rev per avg MW ($M/MW-yr) | N3: In fit? | O3: Source / caveat
A4: CoreWeave | B4: Q1'24 | C4: 1 | D4: 70 | E4: 142.5 | F4: E | G4: =(D4+E4)/2 -> 106.25 | H4: =E4-D4 -> 72.5 | I4: =H4/G4 -> 0.68235294 | J4: =LN(G4) -> 4.6657948 | K4: 188.684 | L4: R | M4: =K4*4/G4 -> 7.1033976 | N4: Y | O4: S8 crwv_kpis Inputs I09E/I01. 2024 MW straight-line interpolated (E); 'more than' MW wording adds +/-10-50 MW noise.
A5: CoreWeave | B5: Q2'24 | C5: 2 | D5: 142.5 | E5: 215 | F5: E | G5: =(D5+E5)/2 -> 178.75 | H5: =E5-D5 -> 72.5 | I5: =H5/G5 -> 0.40559441 | J5: =LN(G5) -> 5.1859882 | K5: 395.371 | L5: R | M5: =K5*4/G5 -> 8.8474629 | N5: Y | O5: S8 crwv_kpis Inputs I09E/I01. 2024 MW straight-line interpolated (E); 'more than' MW wording adds +/-10-50 MW noise.
A6: CoreWeave | B6: Q3'24 | C6: 3 | D6: 215 | E6: 287.5 | F6: E | G6: =(D6+E6)/2 -> 251.25 | H6: =E6-D6 -> 72.5 | I6: =H6/G6 -> 0.28855721 | J6: =LN(G6) -> 5.5264485 | K6: 583.941 | L6: R | M6: =K6*4/G6 -> 9.2965731 | N6: Y | O6: S8 crwv_kpis Inputs I09E/I01. 2024 MW straight-line interpolated (E); 'more than' MW wording adds +/-10-50 MW noise.
A7: CoreWeave | B7: Q4'24 | C7: 4 | D7: 287.5 | E7: 360 | F7: E | G7: =(D7+E7)/2 -> 323.75 | H7: =E7-D7 -> 72.5 | I7: =H7/G7 -> 0.22393822 | J7: =LN(G7) -> 5.7799716 | K7: 747.43 | L7: R | M7: =K7*4/G7 -> 9.2346564 | N7: Y | O7: S8 crwv_kpis Inputs I09E/I01. 2024 MW straight-line interpolated (E); 'more than' MW wording adds +/-10-50 MW noise.
A8: CoreWeave | B8: Q1'25 | C8: 5 | D8: 360 | E8: 420 | F8: R | G8: =(D8+E8)/2 -> 390 | H8: =E8-D8 -> 60 | I8: =H8/G8 -> 0.15384615 | J8: =LN(G8) -> 5.9661467 | K8: 981.632 | L8: R | M8: =K8*4/G8 -> 10.068021 | N8: Y | O8: S8 crwv_kpis Inputs I09E/I01. 2024 MW straight-line interpolated (E); 'more than' MW wording adds +/-10-50 MW noise.
A9: CoreWeave | B9: Q2'25 | C9: 6 | D9: 420 | E9: 470 | F9: R | G9: =(D9+E9)/2 -> 445 | H9: =E9-D9 -> 50 | I9: =H9/G9 -> 0.11235955 | J9: =LN(G9) -> 6.0980743 | K9: 1212.788 | L9: R | M9: =K9*4/G9 -> 10.901465 | N9: Y | O9: S8 crwv_kpis Inputs I09E/I01. 2024 MW straight-line interpolated (E); 'more than' MW wording adds +/-10-50 MW noise.
A10: CoreWeave | B10: Q3'25 | C10: 7 | D10: 470 | E10: 590 | F10: R | G10: =(D10+E10)/2 -> 530 | H10: =E10-D10 -> 120 | I10: =H10/G10 -> 0.22641509 | J10: =LN(G10) -> 6.272877 | K10: 1364.676 | L10: R | M10: =K10*4/G10 -> 10.299442 | N10: Y | O10: S8 crwv_kpis Inputs I09E/I01. 2024 MW straight-line interpolated (E); 'more than' MW wording adds +/-10-50 MW noise.
A11: CoreWeave | B11: Q4'25 | C11: 8 | D11: 590 | E11: 850 | F11: R | G11: =(D11+E11)/2 -> 720 | H11: =E11-D11 -> 260 | I11: =H11/G11 -> 0.36111111 | J11: =LN(G11) -> 6.5792512 | K11: 1572 | L11: R | M11: =K11*4/G11 -> 8.7333333 | N11: Y | O11: S8 crwv_kpis Inputs I09E/I01. 2024 MW straight-line interpolated (E); 'more than' MW wording adds +/-10-50 MW noise.
A12: CoreWeave | B12: Q1'26 | C12: 9 | D12: 850 | E12: 1000 | F12: R | G12: =(D12+E12)/2 -> 925 | H12: =E12-D12 -> 150 | I12: =H12/G12 -> 0.16216216 | J12: =LN(G12) -> 6.8297937 | K12: 2078 | L12: R | M12: =K12*4/G12 -> 8.9859459 | N12: Y | O12: S8 crwv_kpis Inputs I09E/I01. 2024 MW straight-line interpolated (E); 'more than' MW wording adds +/-10-50 MW noise.
A13: CoreWeave | B13: Q2'26 | C13: 10 | D13: 1000 | E13: 1500 | F13: R | G13: =(D13+E13)/2 -> 1250 | H13: =E13-D13 -> 500 | I13: =H13/G13 -> 0.4 | J13: =LN(G13) -> 7.1308988 | K13: 2575 | L13: R | M13: =K13*4/G13 -> 8.24 | N13: Y | O13: S8 crwv_kpis Inputs I09E/I01. 2024 MW straight-line interpolated (E); 'more than' MW wording adds +/-10-50 MW noise.
A14: IREN | B14: Q2'24 | C14: 1 | D14: 1.14446 | E14: 1.14446 | F14: E | G14: =(D14+E14)/2 -> 1.14446 | H14: =E14-D14 -> 0 | I14: =H14/G14 -> 0 | J14: =LN(G14) -> 0.13493293 | K14: 2.538 | L14: R | M14: =K14*4/G14 -> 8.8705588 | N14: N | O14: iren_kpis Inputs I09E (MW = GPUs/713, E) and I01 AI Cloud revenue. Tiny MW (1-3) - shown for shape; NOT used in fit.
A15: IREN | B15: Q3'24 | C15: 2 | D15: 1.14446 | E15: 1.14446 | F15: E | G15: =(D15+E15)/2 -> 1.14446 | H15: =E15-D15 -> 0 | I15: =H15/G15 -> 0 | J15: =LN(G15) -> 0.13493293 | K15: 3.189 | L15: R | M15: =K15*4/G15 -> 11.145868 | N15: N | O15: iren_kpis Inputs I09E (MW = GPUs/713, E) and I01 AI Cloud revenue. Tiny MW (1-3) - shown for shape; NOT used in fit.
... A19: IREN | B19: Q3'25 | C19: 6 | D19: 2.6647966 | E19: 2.9453015 | F19: E | G19: =(D19+E19)/2 -> 2.8050491 | H19: =E19-D19 -> 0.28050491 | I19: =H19/G19 -> 0.1 | J19: =LN(G19) -> 1.031421 | K19: 7.347 | L19: R | M19: =K19*4/G19 -> 10.476822 | N19: N | O19: iren_kpis Inputs I09E (MW = GPUs/713, E) and I01 AI Cloud revenue. Tiny MW (1-3) - shown for shape; NOT used in fit.
A20: IREN | B20: Q2'26 | C20: 9 | D20: n-d | E20: 40 | F20: R | G20: n-d | H20: n-d | I20: n-d | J20: n-d | K20: 70.515 | L20: R | M20: =K20*4/E20 -> 7.0515 | N20: N | O20: 40 MW is the only reported AI MW (period-end, basis unstated). Rev / PERIOD-END MW (avg n-d: Mar-26 MW n-d). Not in fit.
A21: Nebius | B21: Q3'24 | C21: 1 | D21: 25 | E21: 25 | F21: E | G21: =(D21+E21)/2 -> 25 | H21: =E21-D21 -> 0 | I21: =H21/G21 -> 0 | J21: =LN(G21) -> 3.2188758 | K21: 27.1 | L21: R | M21: =K21*4/G21 -> 4.336 | N21: N | O21: S15 nebius_kpi_history KPI rows 28 (Capacity energized MW incl. plug, mixed IT/gross, E) and 6 (AI cloud revenue, R). Back-test only.
A22: Nebius | B22: Q4'24 | C22: 2 | D22: 25 | E22: 25 | F22: E | G22: =(D22+E22)/2 -> 25 | H22: =E22-D22 -> 0 | I22: =H22/G22 -> 0 | J22: =LN(G22) -> 3.2188758 | K22: 23.8 | L22: R | M22: =K22*4/G22 -> 3.808 | N22: N | O22: S15 nebius_kpi_history KPI rows 28 (Capacity energized MW incl. plug, mixed IT/gross, E) and 6 (AI cloud revenue, R). Back-test only.
A23: Nebius | B23: Q1'25 | C23: 3 | D23: 25 | E23: 40 | F23: E | G23: =(D23+E23)/2 -> 32.5 | H23: =E23-D23 -> 15 | I23: =H23/G23 -> 0.46153846 | J23: =LN(G23) -> 3.4812401 | K23: 41.4 | L23: R | M23: =K23*4/G23 -> 5.0953846 | N23: N | O23: S15 nebius_kpi_history KPI rows 28 (Capacity energized MW incl. plug, mixed IT/gross, E) and 6 (AI cloud revenue, R). Back-test only.
A24: Nebius | B24: Q2'25 | C24: 4 | D24: 40 | E24: 45 | F24: E | G24: =(D24+E24)/2 -> 42.5 | H24: =E24-D24 -> 5 | I24: =H24/G24 -> 0.11764706 | J24: =LN(G24) -> 3.7495041 | K24: 93.7 | L24: R | M24: =K24*4/G24 -> 8.8188235 | N24: N | O24: S15 nebius_kpi_history KPI rows 28 (Capacity energized MW incl. plug, mixed IT/gross, E) and 6 (AI cloud revenue, R). Back-test only.
A25: Nebius | B25: Q3'25 | C25: 5 | D25: 45 | E25: 62.5 | F25: E | G25: =(D25+E25)/2 -> 53.75 | H25: =E25-D25 -> 17.5 | I25: =H25/G25 -> 0.3255814 | J25: =LN(G25) -> 3.9843437 | K25: 131.1 | L25: R | M25: =K25*4/G25 -> 9.7562791 | N25: N | O25: S15 nebius_kpi_history KPI rows 28 (Capacity energized MW incl. plug, mixed IT/gross, E) and 6 (AI cloud revenue, R). Back-test only.
A26: Nebius | B26: Q4'25 | C26: 6 | D26: 62.5 | E26: 170 | F26: E | G26: =(D26+E26)/2 -> 116.25 | H26: =E26-D26 -> 107.5 | I26: =H26/G26 -> 0.92473118 | J26: =LN(G26) -> 4.755743 | K26: 214.1 | L26: R | M26: =K26*4/G26 -> 7.3668817 | N26: N | O26: S15 nebius_kpi_history KPI rows 28 (Capacity energized MW incl. plug, mixed IT/gross, E) and 6 (AI cloud revenue, R). Back-test only.
A27: Nebius | B27: Q1'26 | C27: 7 | D27: 170 | E27: 171.5 | F27: E | G27: =(D27+E27)/2 -> 170.75 | H27: =E27-D27 -> 1.5 | I27: =H27/G27 -> 0.0087847731 | J27: =LN(G27) -> 5.1402005 | K27: 389.7 | L27: R | M27: =K27*4/G27 -> 9.1291362 | N27: N | O27: S15 nebius_kpi_history KPI rows 28 (Capacity energized MW incl. plug, mixed IT/gross, E) and 6 (AI cloud revenue, R). Back-test only.
A28: Nebius | B28: Q2'26 | C28: 8 | D28: 171.5 | E28: 173 | F28: E | G28: =(D28+E28)/2 -> 172.25 | H28: =E28-D28 -> 1.5 | I28: =H28/G28 -> 0.0087082729 | J28: =LN(G28) -> 5.1489469 | K28: 574.9 | L28: R | M28: =K28*4/G28 -> 13.350363 | N28: N | O28: S15 nebius_kpi_history KPI rows 28 (Capacity energized MW incl. plug, mixed IT/gross, E) and 6 (AI cloud revenue, R). Back-test only.

Sheet Dilution_Fit
A1: Dilution fits (live LINEST-equivalents: SLOPE / INTERCEPT / RSQ / STEYX). Primary: rev/avg MW = a + b x ramp ratio -> dilution factor = 1 - k x ramp, k = -b/a.
A3: Fit | B3: Intercept a | C3: Slope b | D3: R^2 | E3: SE of slope | F3: k = -b/a | G3: k low (b+SE) | H3: k high (b-SE) | I3: n | J3: Tag
A4: F1 CoreWeave Q1'24-Q2'26: rev/MW vs ramp ratio (PRIMARY) | B4: =INTERCEPT(Dilution_Data!$M$4:$M$13,Dilution_Data!$I$4:$I$13) -> 10.883154 | C4: =SLOPE(Dilution_Data!$M$4:$M$13,Dilution_Data!$I$4:$I$13) -> -5.6761716 | D4: =RSQ(Dilution_Data!$M$4:$M$13,Dilution_Data!$I$4:$I$13) -> 0.78668014 | E4: =STEYX(Dilution_Data!$M$4:$M$13,Dilution_Data!$I$4:$I$13)/SQRT(DEVSQ(Dilution_Data!$I$4:$I$13)) -> 1.045026 | F4: =-C4/B4 -> 0.52155575 | G4: =-(C4+E4)/B4 -> 0.4255334 | H4: =-(C4-E4)/B4 -> 0.61757809 | I4: =COUNT(Dilution_Data!$M$4:$M$13) -> 10 | J4: D/E
A5: F2 CoreWeave Q1'25-Q2'26 (reported MW only): rev/MW vs ramp ratio | B5: =INTERCEPT(Dilution_Data!$M$8:$M$13,Dilution_Data!$I$8:$I$13) -> 11.194289 | C5: =SLOPE(Dilution_Data!$M$8:$M$13,Dilution_Data!$I$8:$I$13) -> -7.0185512 | D5: =RSQ(Dilution_Data!$M$8:$M$13,Dilution_Data!$I$8:$I$13) -> 0.64489033 | E5: =STEYX(Dilution_Data!$M$8:$M$13,Dilution_Data!$I$8:$I$13)/SQRT(DEVSQ(Dilution_Data!$I$8:$I$13)) -> 2.6040888 | F5: =-C5/B5 -> 0.62697608 | G5: =-(C5+E5)/B5 -> 0.39434952 | H5: =-(C5-E5)/B5 -> 0.85960264 | I5: =COUNT(Dilution_Data!$M$8:$M$13) -> 6 | J5: D/E
A6: F3 CoreWeave Q1'24-Q2'26: rev/MW vs ln(avg MW) | B6: =INTERCEPT(Dilution_Data!$M$4:$M$13,Dilution_Data!$J$4:$J$13) -> 6.8938145 | C6: =SLOPE(Dilution_Data!$M$4:$M$13,Dilution_Data!$J$4:$J$13) -> 0.37931305 | D6: =RSQ(Dilution_Data!$M$4:$M$13,Dilution_Data!$J$4:$J$13) -> 0.069504413 | E6: =STEYX(Dilution_Data!$M$4:$M$13,Dilution_Data!$J$4:$J$13)/SQRT(DEVSQ(Dilution_Data!$J$4:$J$13)) -> 0.4906861 | F6: n/a | G6: n/a | H6: n/a | I6: =COUNT(Dilution_Data!$M$4:$M$13) -> 10 | J6: D/E
A7: F4 CoreWeave Q1'25-Q2'26: rev/MW vs ln(avg MW) (scale effect; confounded with ramp) | B7: =INTERCEPT(Dilution_Data!$M$8:$M$13,Dilution_Data!$J$8:$J$13) -> 22.82639 | C7: =SLOPE(Dilution_Data!$M$8:$M$13,Dilution_Data!$J$8:$J$13) -> -2.0508282 | D7: =RSQ(Dilution_Data!$M$8:$M$13,Dilution_Data!$J$8:$J$13) -> 0.79196997 | E7: =STEYX(Dilution_Data!$M$8:$M$13,Dilution_Data!$J$8:$J$13)/SQRT(DEVSQ(Dilution_Data!$J$8:$J$13)) -> 0.52554261 | F7: n/a | G7: n/a | H7: n/a | I7: =COUNT(Dilution_Data!$M$8:$M$13) -> 6 | J7: D/E
A8: F5 Nebius Q1'25-Q2'26: rev/MW vs ramp ratio (info: confounded by Hopper->Blackwell repricing) | B8: =INTERCEPT(Dilution_Data!$M$23:$M$28,Dilution_Data!$I$23:$I$28) -> 10.360148 | C8: =SLOPE(Dilution_Data!$M$23:$M$28,Dilution_Data!$I$23:$I$28) -> -4.6800552 | D8: =RSQ(Dilution_Data!$M$23:$M$28,Dilution_Data!$I$23:$I$28) -> 0.36264381 | E8: =STEYX(Dilution_Data!$M$23:$M$28,Dilution_Data!$I$23:$I$28)/SQRT(DEVSQ(Dilution_Data!$I$23:$I$28)) -> 3.1022154 | F8: =-C8/B8 -> 0.45173632 | G8: =-(C8+E8)/B8 -> 0.15229897 | H8: =-(C8-E8)/B8 -> 0.75117368 | I8: =COUNT(Dilution_Data!$M$23:$M$28) -> 6 | J8: D/E
A9: F6 IREN Q2'24-Q3'25 (MW estimated, 1-3 MW): rev/MW vs ramp ratio (info) | B9: =INTERCEPT(Dilution_Data!$M$14:$M$19,Dilution_Data!$I$14:$I$19) -> 9.3179206 | C9: =SLOPE(Dilution_Data!$M$14:$M$19,Dilution_Data!$I$14:$I$19) -> -4.4160148 | D9: =RSQ(Dilution_Data!$M$14:$M$19,Dilution_Data!$I$14:$I$19) -> 0.30241215 | E9: =STEYX(Dilution_Data!$M$14:$M$19,Dilution_Data!$I$14:$I$19)/SQRT(DEVSQ(Dilution_Data!$I$14:$I$19)) -> 3.3535159 | F9: =-C9/B9 -> 0.47392707 | G9: =-(C9+E9)/B9 -> 0.11402747 | H9: =-(C9-E9)/B9 -> 0.83382666 | I9: =COUNT(Dilution_Data!$M$14:$M$19) -> 6 | J9: D/E
A11: Selected dilution coefficients (k) for Nebius_Path
A12: k LOW dilution (F1 slope + 1 SE) | B12: =G4 -> 0.4255334 | C12: E
A13: k BASE (F1) | B13: =F4 -> 0.52155575 | C13: E
A14: k HIGH dilution (F1 slope - 1 SE) | B14: =H4 -> 0.61757809 | C14: E
A15: Cross-check: k from F2 (2025-26 reported only) | B15: =F5 -> 0.62697608 | C15: E
A17: Back-test: CRWV k applied to IREN and Nebius (implied 'undiluted' rev/MW = actual / (1 - k x ramp))
A18: Company / quarter | B18: Ramp ratio | C18: Actual rev/MW | D18: Factor (1-k*ramp) | E18: Undiluted rev/MW | F18: F1 fitted (CRWV only) | G18: Note
A19: =Dilution_Data!A4&" "&Dilution_Data!B4 -> CoreWeave Q1'24 | B19: =Dilution_Data!I4 -> 0.68235294 | C19: =Dilution_Data!M4 -> 7.1033976 | D19: =1-$B$13*B19 -> 0.6441149 | E19: =C19/D19 -> 11.028153 | F19: =$B$4+$C$4*B19 -> 7.0100018
A20: =Dilution_Data!A5&" "&Dilution_Data!B5 -> CoreWeave Q2'24 | B20: =Dilution_Data!I5 -> 0.40559441 | C20: =Dilution_Data!M5 -> 8.8474629 | D20: =1-$B$13*B20 -> 0.78845991 | E20: =C20/D20 -> 11.221196 | F20: =$B$4+$C$4*B20 -> 8.5809308
A21: =Dilution_Data!A6&" "&Dilution_Data!B6 -> CoreWeave Q3'24 | B21: =Dilution_Data!I6 -> 0.28855721 | C21: =Dilution_Data!M6 -> 9.2965731 | D21: =1-$B$13*B21 -> 0.84950133 | E21: =C21/D21 -> 10.943565 | F21: =$B$4+$C$4*B21 -> 9.245254
A22: =Dilution_Data!A7&" "&Dilution_Data!B7 -> CoreWeave Q4'24 | B22: =Dilution_Data!I7 -> 0.22393822 | C22: =Dilution_Data!M7 -> 9.2346564 | D22: =1-$B$13*B22 -> 0.88320373 | E22: =C22/D22 -> 10.455862 | F22: =$B$4+$C$4*B22 -> 9.6120424
A23: =Dilution_Data!A8&" "&Dilution_Data!B8 -> CoreWeave Q1'25 | B23: =Dilution_Data!I8 -> 0.15384615 | C23: =Dilution_Data!M8 -> 10.068021 | D23: =1-$B$13*B23 -> 0.91976065 | E23: =C23/D23 -> 10.946348 | F23: =$B$4+$C$4*B23 -> 10.009897
A24: =Dilution_Data!A9&" "&Dilution_Data!B9 -> CoreWeave Q2'25 | B24: =Dilution_Data!I9 -> 0.11235955 | C24: =Dilution_Data!M9 -> 10.901465 | D24: =1-$B$13*B24 -> 0.94139823 | E24: =C24/D24 -> 11.580078 | F24: =$B$4+$C$4*B24 -> 10.245382
A25: =Dilution_Data!A10&" "&Dilution_Data!B10 -> CoreWeave Q3'25 | B25: =Dilution_Data!I10 -> 0.22641509 | C25: =Dilution_Data!M10 -> 10.299442 | D25: =1-$B$13*B25 -> 0.88191191 | E25: =C25/D25 -> 11.678538 | F25: =$B$4+$C$4*B25 -> 9.5979833
A26: =Dilution_Data!A11&" "&Dilution_Data!B11 -> CoreWeave Q4'25 | B26: =Dilution_Data!I11 -> 0.36111111 | C26: =Dilution_Data!M11 -> 8.7333333 | D26: =1-$B$13*B26 -> 0.81166043 | E26: =C26/D26 -> 10.759836 | F26: =$B$4+$C$4*B26 -> 8.8334256
A27: =Dilution_Data!A12&" "&Dilution_Data!B12 -> CoreWeave Q1'26 | B27: =Dilution_Data!I12 -> 0.16216216 | C27: =Dilution_Data!M12 -> 8.9859459 | D27: =1-$B$13*B27 -> 0.91542339 | E27: =C27/D27 -> 9.8161638 | F27: =$B$4+$C$4*B27 -> 9.962694
A28: =Dilution_Data!A13&" "&Dilution_Data!B13 -> CoreWeave Q2'26 | B28: =Dilution_Data!I13 -> 0.4 | C28: =Dilution_Data!M13 -> 8.24 | D28: =1-$B$13*B28 -> 0.7913777 | E28: =C28/D28 -> 10.412222 | F28: =$B$4+$C$4*B28 -> 8.6126856
A29: =Dilution_Data!A14&" "&Dilution_Data!B14 -> IREN Q2'24 | B29: =Dilution_Data!I14 -> 0 | C29: =Dilution_Data!M14 -> 8.8705588 | D29: =1-$B$13*B29 -> 1 | E29: =C29/D29 -> 8.8705588
A30: =Dilution_Data!A15&" "&Dilution_Data!B15 -> IREN Q3'24 | B30: =Dilution_Data!I15 -> 0 | C30: =Dilution_Data!M15 -> 11.145868 | D30: =1-$B$13*B30 -> 1 | E30: =C30/D30 -> 11.145868
A31: =Dilution_Data!A16&" "&Dilution_Data!B16 -> IREN Q4'24 | B31: =Dilution_Data!I16 -> 0.79646018 | C31: =Dilution_Data!M16 -> 5.5967345 | D31: =1-$B$13*B31 -> 0.58460162 | E31: =C31/D31 -> 9.5735871
A32: =Dilution_Data!A17&" "&Dilution_Data!B17 -> IREN Q1'25 | B32: =Dilution_Data!I17 -> 0 | C32: =Dilution_Data!M17 -> 5.3866097 | D32: =1-$B$13*B32 -> 1 | E32: =C32/D32 -> 5.3866097
A33: =Dilution_Data!A18&" "&Dilution_Data!B18 -> IREN Q2'25 | B33: =Dilution_Data!I18 -> 0.0021074816 | C33: =Dilution_Data!M18 -> 10.462843 | D33: =1-$B$13*B33 -> 0.99890083 | E33: =C33/D33 -> 10.474356
A34: =Dilution_Data!A19&" "&Dilution_Data!B19 -> IREN Q3'25 | B34: =Dilution_Data!I19 -> 0.1 | C34: =Dilution_Data!M19 -> 10.476822 | D34: =1-$B$13*B34 -> 0.94784443 | E34: =C34/D34 -> 11.053314
A35: =Dilution_Data!A21&" "&Dilution_Data!B21 -> Nebius Q3'24 | B35: =Dilution_Data!I21 -> 0 | C35: =Dilution_Data!M21 -> 4.336 | D35: =1-$B$13*B35 -> 1 | E35: =C35/D35 -> 4.336
A36: =Dilution_Data!A22&" "&Dilution_Data!B22 -> Nebius Q4'24 | B36: =Dilution_Data!I22 -> 0 | C36: =Dilution_Data!M22 -> 3.808 | D36: =1-$B$13*B36 -> 1 | E36: =C36/D36 -> 3.808
A37: =Dilution_Data!A23&" "&Dilution_Data!B23 -> Nebius Q1'25 | B37: =Dilution_Data!I23 -> 0.46153846 | C37: =Dilution_Data!M23 -> 5.0953846 | D37: =1-$B$13*B37 -> 0.75928196 | E37: =C37/D37 -> 6.7107937
A38: =Dilution_Data!A24&" "&Dilution_Data!B24 -> Nebius Q2'25 | B38: =Dilution_Data!I24 -> 0.11764706 | C38: =Dilution_Data!M24 -> 8.8188235 | D38: =1-$B$13*B38 -> 0.9386405 | E38: =C38/D38 -> 9.3953154
A39: =Dilution_Data!A25&" "&Dilution_Data!B25 -> Nebius Q3'25 | B39: =Dilution_Data!I25 -> 0.3255814 | C39: =Dilution_Data!M25 -> 9.7562791 | D39: =1-$B$13*B39 -> 0.83019115 | E39: =C39/D39 -> 11.751847
A40: =Dilution_Data!A26&" "&Dilution_Data!B26 -> Nebius Q4'25 | B40: =Dilution_Data!I26 -> 0.92473118 | C40: =Dilution_Data!M26 -> 7.3668817 | D40: =1-$B$13*B40 -> 0.51770114 | E40: =C40/D40 -> 14.229989
A41: =Dilution_Data!A27&" "&Dilution_Data!B27 -> Nebius Q1'26 | B41: =Dilution_Data!I27 -> 0.0087847731 | C41: =Dilution_Data!M27 -> 9.1291362 | D41: =1-$B$13*B41 -> 0.99541825 | E41: =C41/D41 -> 9.1711561
A42: =Dilution_Data!A28&" "&Dilution_Data!B28 -> Nebius Q2'26 | B42: =Dilution_Data!I28 -> 0.0087082729 | C42: =Dilution_Data!M28 -> 13.350363 | D42: =1-$B$13*B42 -> 0.99545815 | E42: =C42/D42 -> 13.411275
A44: Read: CRWV rev/MW falls ~0.57 $M/MW-yr per +0.1 of ramp ratio (R^2 ~0.79, 10 qtrs). IREN's one big ramp quarter (Q4'24, ramp ~0.8) sits on the same line (actual 5.6 vs ~9-11 in steady quarters). ln(MW) has no explanatory power on the full CRWV sample (R^2 ~0.07); on 2025-26 alone it fits (R^2 ~0.79) but that window is also the high-ramp window - treat scale dilution as unproven. Nebius Q4'25 (ramp 0.92) diluted LESS than CRWV k predicts (undiluted ~14 vs ~9-13 around it) - Microsoft Vineland tranches billed quickly.

Sheet Nebius_Path
A1: Nebius quarterly revenue per average energized IT MW, Q3'26-Q4'27. rev/MW_q = SS_q x (1 - k x ramp_q); SS_q = (MW_Q2'26 x L0 + (avgMW_q - MW_Q2'26) x P_new) / avgMW_q; L0 = Q2'26 AI cloud revenue x4 / avg(Q1'26, Q2'26) MW of the same case. MW = Capacity 'Energized MW low/base/high - IT-normalized' (values copied, not edited). Bands: LOW = P_new low + k high; BASE = P_new base + k base; HIGH = P_new high + k low.
A3: Q2'26 Nebius AI cloud revenue ($M) | B3: =Dilution_Data!K28 -> 574.9 | C3: R | D3: S15
A4: P_new LOW: incremental-MW price = '$12M 2026 base' ACV/MW | B4: 12 | C4: R | D4: S1
A5: P_new BASE: = Nebius-Microsoft $17.1M per IT MW (~midpoint of $12M base and $22.5M Q2 deals) | B5: =17392.9/5/(100000/Payback_ACV!$C$8) -> 17.085741 | C5: D | D5: S10/S11
A6: P_new HIGH: = midpoint of Q2-deal '$20-25M per MW' (IT reading) | B6: 22.5 | C6: R | D6: S1
A7: k LOW dilution | B7: =Dilution_Fit!B12 -> 0.4255334 | C7: E | D7: Dilution_Fit
A8: k BASE | B8: =Dilution_Fit!B13 -> 0.52155575 | C8: E | D8: Dilution_Fit
A9: k HIGH dilution | B9: =Dilution_Fit!B14 -> 0.61757809 | C9: E | D9: Dilution_Fit
A11: Quarter | B11: Q1'26 | C11: Q2'26 | D11: Q3'26 | E11: Q4'26 | F11: Q1'27 | G11: Q2'27 | H11: Q3'27 | I11: Q4'27 | J11: Tag | K11: FY27 sum / source
A12: MW CASE: LOW (Capacity Quarterly MW row 135 'Energized MW low - IT-normalized')
A13: End-of-quarter energized IT MW | B13: 143.48951 | C13: 146.48951 | D13: 181.48951 | E13: 189.48951 | F13: 256.96643 | G13: 404.35105 | H13: 553.46957 | I13: 794.61375 | J13: E | K13: S16 row 135, cols M-T
A14: Average MW | C14: =(B13+C13)/2 -> 144.98951 | D14: =(C13+D13)/2 -> 163.98951 | E14: =(D13+E13)/2 -> 185.48951 | F14: =(E13+F13)/2 -> 223.22797 | G14: =(F13+G13)/2 -> 330.65874 | H14: =(G13+H13)/2 -> 478.91031 | I14: =(H13+I13)/2 -> 674.04166
A15: New MW in quarter | C15: =C13-B13 -> 3 | D15: =D13-C13 -> 35 | E15: =E13-D13 -> 8 | F15: =F13-E13 -> 67.476923 | G15: =G13-F13 -> 147.38462 | H15: =H13-G13 -> 149.11852 | I15: =I13-H13 -> 241.14418
A16: Ramp ratio (new / avg) | C16: =C15/C14 -> 0.020691152 | D16: =D15/D14 -> 0.21342829 | E16: =E15/E14 -> 0.043129123 | F16: =F15/F14 -> 0.30227808 | G16: =G15/G14 -> 0.44573029 | H16: =H15/H14 -> 0.31137045 | I16: =I15/I14 -> 0.35775858
A17: L0 = Q2'26 rev x4 / avg Q2'26 MW (this case) | C17: =$B$3*4/C14 -> 15.860458 | J17: D/E
A18: Rev per avg IT MW - LOW ($M/MW-yr) | C18: =$C$17 -> 15.860458 | D18: =(MIN(D14,$C$13)*$C$17+MAX(D14-$C$13,0)*$B$4)/D14*(1-$B$9*D16) -> 13.412248 | E18: =(MIN(E14,$C$13)*$C$17+MAX(E14-$C$13,0)*$B$4)/E14*(1-$B$9*E16) -> 14.647946 | F18: =(MIN(F14,$C$13)*$C$17+MAX(F14-$C$13,0)*$B$4)/F14*(1-$B$9*F16) -> 11.820267 | G18: =(MIN(G14,$C$13)*$C$17+MAX(G14-$C$13,0)*$B$4)/G14*(1-$B$9*G16) -> 9.9362011 | H18: =(MIN(H14,$C$13)*$C$17+MAX(H14-$C$13,0)*$B$4)/H14*(1-$B$9*H16) -> 10.646223 | I18: =(MIN(I14,$C$13)*$C$17+MAX(I14-$C$13,0)*$B$4)/I14*(1-$B$9*I16) -> 10.002297 | J18: E
A19: Rev per avg IT MW - BASE ($M/MW-yr) | C19: =$C$17 -> 15.860458 | D19: =(MIN(D14,$C$13)*$C$17+MAX(D14-$C$13,0)*$B$5)/D14*(1-$B$8*D16) -> 14.211155 | E19: =(MIN(E14,$C$13)*$C$17+MAX(E14-$C$13,0)*$B$5)/E14*(1-$B$8*E16) -> 15.755515 | F19: =(MIN(F14,$C$13)*$C$17+MAX(F14-$C$13,0)*$B$5)/F14*(1-$B$8*F16) -> 13.714786 | G19: =(MIN(G14,$C$13)*$C$17+MAX(G14-$C$13,0)*$B$5)/G14*(1-$B$8*G16) -> 12.697129 | H19: =(MIN(H14,$C$13)*$C$17+MAX(H14-$C$13,0)*$B$5)/H14*(1-$B$8*H16) -> 13.997141 | I19: =(MIN(I14,$C$13)*$C$17+MAX(I14-$C$13,0)*$B$5)/I14*(1-$B$8*I16) -> 13.681092 | J19: E
A20: Rev per avg IT MW - HIGH ($M/MW-yr) | C20: =$C$17 -> 15.860458 | D20: =(MIN(D14,$C$13)*$C$17+MAX(D14-$C$13,0)*$B$6)/D14*(1-$B$7*D16) -> 15.064181 | E20: =(MIN(E14,$C$13)*$C$17+MAX(E14-$C$13,0)*$B$6)/E14*(1-$B$7*E16) -> 16.939746 | F20: =(MIN(F14,$C$13)*$C$17+MAX(F14-$C$13,0)*$B$6)/F14*(1-$B$7*F16) -> 15.809202 | G20: =(MIN(G14,$C$13)*$C$17+MAX(G14-$C$13,0)*$B$6)/G14*(1-$B$7*G16) -> 15.848801 | H20: =(MIN(H14,$C$13)*$C$17+MAX(H14-$C$13,0)*$B$6)/H14*(1-$B$7*H16) -> 17.756966 | I20: =(MIN(I14,$C$13)*$C$17+MAX(I14-$C$13,0)*$B$6)/I14*(1-$B$7*I16) -> 17.851343 | J20: E
A21: Implied AI cloud revenue - BASE band ($M, qtr) [memo] | C21: =$B$3 -> 574.9 | D21: =D19*D14/4 -> 582.62009 | E21: =E19*E14/4 -> 730.6207 | F21: =F19*F14/4 -> 765.38094 | G21: =G19*G14/4 -> 1049.6041 | H21: =H19*H14/4 -> 1675.8438 | I21: =I19*I14/4 -> 2305.4064 | J21: E | K21: =SUM(F21:I21) -> 5796.2353
A22: Implied FY27 revenue LOW band / HIGH band ($M) [memo, cols K / L] | J22: E | K22: =F18*F14/4+G18*G14/4+H18*H14/4+I18*I14/4 -> 4441.1642 | L22: =F20*F14/4+G20*G14/4+H20*H14/4+I20*I14/4 -> 7326.536
A24: MW CASE: BASE (Capacity Quarterly MW row 136 'Energized MW base - IT-normalized')
A25: End-of-quarter energized IT MW | B25: 170.98951 | C25: 182.48951 | D25: 216.98951 | E25: 301.72028 | F25: 453.79492 | G25: 629.5408 | H25: 812.61375 | I25: 1081.9246 | J25: E | K25: S16 row 136, cols M-T
A26: Average MW | C26: =(B25+C25)/2 -> 176.73951 | D26: =(C25+D25)/2 -> 199.73951 | E26: =(D25+E25)/2 -> 259.3549 | F26: =(E25+F25)/2 -> 377.7576 | G26: =(F25+G25)/2 -> 541.66786 | H26: =(G25+H25)/2 -> 721.07728 | I26: =(H25+I25)/2 -> 947.26918
A27: New MW in quarter | C27: =C25-B25 -> 11.5 | D27: =D25-C25 -> 34.5 | E27: =E25-D25 -> 84.730769 | F27: =F25-E25 -> 152.07464 | G27: =G25-F25 -> 175.74588 | H27: =H25-G25 -> 183.07295 | I27: =I25-H25 -> 269.31085
A28: Ramp ratio (new / avg) | C28: =C27/C26 -> 0.065067511 | D28: =D27/D26 -> 0.17272497 | E28: =E27/E26 -> 0.32669817 | F28: =F27/F26 -> 0.40257203 | G28: =G27/G26 -> 0.32445322 | H28: =H27/H26 -> 0.25388811 | I28: =I27/I26 -> 0.28430235
A29: L0 = Q2'26 rev x4 / avg Q2'26 MW (this case) | C29: =$B$3*4/C26 -> 13.011239 | J29: D/E
A30: Rev per avg IT MW - LOW ($M/MW-yr) | C30: =$C$29 -> 13.011239 | D30: =(MIN(D26,$C$25)*$C$29+MAX(D26-$C$25,0)*$B$4)/D26*(1-$B$9*D28) -> 11.545298 | E30: =(MIN(E26,$C$25)*$C$29+MAX(E26-$C$25,0)*$B$4)/E26*(1-$B$9*E28) -> 10.146836 | F30: =(MIN(F26,$C$25)*$C$29+MAX(F26-$C$25,0)*$B$4)/F26*(1-$B$9*F28) -> 9.3836251 | G30: =(MIN(G26,$C$25)*$C$29+MAX(G26-$C$25,0)*$B$4)/G26*(1-$B$9*G28) -> 9.8679213 | H30: =(MIN(H26,$C$25)*$C$29+MAX(H26-$C$25,0)*$B$4)/H26*(1-$B$9*H28) -> 10.334247 | I30: =(MIN(I26,$C$25)*$C$29+MAX(I26-$C$25,0)*$B$4)/I26*(1-$B$9*I28) -> 10.053661 | J30: E
A31: Rev per avg IT MW - BASE ($M/MW-yr) | C31: =$C$29 -> 13.011239 | D31: =(MIN(D26,$C$25)*$C$29+MAX(D26-$C$25,0)*$B$5)/D26*(1-$B$8*D28) -> 12.159297 | E31: =(MIN(E26,$C$25)*$C$29+MAX(E26-$C$25,0)*$B$5)/E26*(1-$B$8*E28) -> 11.796044 | F31: =(MIN(F26,$C$25)*$C$29+MAX(F26-$C$25,0)*$B$5)/F26*(1-$B$8*F28) -> 11.943298 | G31: =(MIN(G26,$C$25)*$C$29+MAX(G26-$C$25,0)*$B$5)/G26*(1-$B$8*G28) -> 13.054064 | H31: =(MIN(H26,$C$25)*$C$29+MAX(H26-$C$25,0)*$B$5)/H26*(1-$B$8*H28) -> 13.928676 | I31: =(MIN(I26,$C$25)*$C$29+MAX(I26-$C$25,0)*$B$5)/I26*(1-$B$8*I28) -> 13.883722 | J31: E
A32: Rev per avg IT MW - HIGH ($M/MW-yr) | C32: =$C$29 -> 13.011239 | D32: =(MIN(D26,$C$25)*$C$29+MAX(D26-$C$25,0)*$B$6)/D26*(1-$B$7*D28) -> 12.814151 | E32: =(MIN(E26,$C$25)*$C$29+MAX(E26-$C$25,0)*$B$6)/E26*(1-$B$7*E28) -> 13.623647 | F32: =(MIN(F26,$C$25)*$C$29+MAX(F26-$C$25,0)*$B$6)/F26*(1-$B$7*F28) -> 14.84694 | G32: =(MIN(G26,$C$25)*$C$29+MAX(G26-$C$25,0)*$B$6)/G26*(1-$B$7*G28) -> 16.638098 | H32: =(MIN(H26,$C$25)*$C$29+MAX(H26-$C$25,0)*$B$6)/H26*(1-$B$7*H28) -> 17.927185 | I32: =(MIN(I26,$C$25)*$C$29+MAX(I26-$C$25,0)*$B$6)/I26*(1-$B$7*I28) -> 18.171106 | J32: E
A33: Implied AI cloud revenue - BASE band ($M, qtr) [memo] | C33: =$B$3 -> 574.9 | D33: =D31*D26/4 -> 607.173 | E33: =E31*E26/4 -> 764.84046 | F33: =F31*F26/4 -> 1127.9179 | G33: =G31*G26/4 -> 1767.7417 | H33: =H31*H26/4 -> 2510.9129 | I33: =I31*I26/4 -> 3287.9055 | J33: E | K33: =SUM(F33:I33) -> 8694.478
A34: Implied FY27 revenue LOW band / HIGH band ($M) [memo, cols K / L] | J34: E | K34: =F30*F26/4+G30*G26/4+H30*H26/4+I30*I26/4 -> 6466.2964 | L34: =F32*F26/4+G32*G26/4+H32*H26/4+I32*I26/4 -> 11190.17
A36: MW CASE: HIGH (Capacity Quarterly MW row 137 'Energized MW high - IT-normalized')
A37: End-of-quarter energized IT MW | B37: 198.48951 | C37: 218.48951 | D37: 252.48951 | E37: 413.95105 | F37: 650.62341 | G37: 854.73056 | H37: 1071.7579 | I37: 1369.2355 | J37: E | K37: S16 row 137, cols M-T
A38: Average MW | C38: =(B37+C37)/2 -> 208.48951 | D38: =(C37+D37)/2 -> 235.48951 | E38: =(D37+E37)/2 -> 333.22028 | F38: =(E37+F37)/2 -> 532.28723 | G38: =(F37+G37)/2 -> 752.67699 | H38: =(G37+H37)/2 -> 963.24425 | I38: =(H37+I37)/2 -> 1220.4967
A39: New MW in quarter | C39: =C37-B37 -> 20 | D39: =D37-C37 -> 34 | E39: =E37-D37 -> 161.46154 | F39: =F37-E37 -> 236.67236 | G39: =G37-F37 -> 204.10715 | H39: =H37-G37 -> 217.02738 | I39: =I37-H37 -> 297.47752
A40: Ramp ratio (new / avg) | C40: =C39/C38 -> 0.095928087 | D40: =D39/D38 -> 0.1443801 | E40: =E39/E38 -> 0.48454896 | F40: =F39/F38 -> 0.4446328 | G40: =G39/G38 -> 0.27117495 | H40: =H39/H38 -> 0.22530877 | I40: =I39/I38 -> 0.2437348
A41: L0 = Q2'26 rev x4 / avg Q2'26 MW (this case) | C41: =$B$3*4/C38 -> 11.029811 | J41: D/E
A42: Rev per avg IT MW - LOW ($M/MW-yr) | C42: =$C$41 -> 11.029811 | D42: =(MIN(D38,$C$37)*$C$41+MAX(D38-$C$37,0)*$B$4)/D38*(1-$B$9*D40) -> 10.11012 | E42: =(MIN(E38,$C$37)*$C$41+MAX(E38-$C$37,0)*$B$4)/E38*(1-$B$9*E40) -> 7.9632584 | F42: =(MIN(F38,$C$37)*$C$41+MAX(F38-$C$37,0)*$B$4)/F38*(1-$B$9*F40) -> 8.415972 | G42: =(MIN(G38,$C$37)*$C$41+MAX(G38-$C$37,0)*$B$4)/G38*(1-$B$9*G40) -> 9.755875 | H42: =(MIN(H38,$C$37)*$C$41+MAX(H38-$C$37,0)*$B$4)/H38*(1-$B$9*H40) -> 10.140807 | I42: =(MIN(I38,$C$37)*$C$41+MAX(I38-$C$37,0)*$B$4)/I38*(1-$B$9*I40) -> 10.04616 | J42: E
A43: Rev per avg IT MW - BASE ($M/MW-yr) | C43: =$C$41 -> 11.029811 | D43: =(MIN(D38,$C$37)*$C$41+MAX(D38-$C$37,0)*$B$5)/D38*(1-$B$8*D40) -> 10.603499 | E43: =(MIN(E38,$C$37)*$C$41+MAX(E38-$C$37,0)*$B$5)/E38*(1-$B$8*E40) -> 9.8005291 | F43: =(MIN(F38,$C$37)*$C$41+MAX(F38-$C$37,0)*$B$5)/F38*(1-$B$8*F40) -> 11.214207 | G43: =(MIN(G38,$C$37)*$C$41+MAX(G38-$C$37,0)*$B$5)/G38*(1-$B$8*G40) -> 13.159951 | H43: =(MIN(H38,$C$37)*$C$41+MAX(H38-$C$37,0)*$B$5)/H38*(1-$B$8*H40) -> 13.86575 | I43: =(MIN(I38,$C$37)*$C$41+MAX(I38-$C$37,0)*$B$5)/I38*(1-$B$8*I40) -> 13.96748 | J43: E
A44: Rev per avg IT MW - HIGH ($M/MW-yr) | C44: =$C$41 -> 11.029811 | D44: =(MIN(D38,$C$37)*$C$41+MAX(D38-$C$37,0)*$B$6)/D38*(1-$B$7*D40) -> 11.129316 | E44: =(MIN(E38,$C$37)*$C$41+MAX(E38-$C$37,0)*$B$6)/E38*(1-$B$7*E40) -> 11.890534 | F44: =(MIN(F38,$C$37)*$C$41+MAX(F38-$C$37,0)*$B$6)/F38*(1-$B$7*F40) -> 14.425481 | G44: =(MIN(G38,$C$37)*$C$41+MAX(G38-$C$37,0)*$B$6)/G38*(1-$B$7*G40) -> 16.958248 | H44: =(MIN(H38,$C$37)*$C$41+MAX(H38-$C$37,0)*$B$6)/H38*(1-$B$7*H40) -> 17.990482 | I44: =(MIN(I38,$C$37)*$C$41+MAX(I38-$C$37,0)*$B$6)/I38*(1-$B$7*I40) -> 18.325972 | J44: E
...

Sheet Sources
A1: ID | B1: What it supports (quoted where possible) | C1: URL / local path
A2: S1 | B2: Nebius Q2'26 shareholder letter (6-K Ex.99.2, Aug 12 2026): cover 'ACV per MW is stepping up(1): $12M 2026 base; >$20M Q2 deals; >$40M Q3 short-term'; 'Payback period(2)(3) 1 year 10 months for deals closed in Q2'; fn(2) 'revenue recognition basis, excluding any prepayment'; fn(3) 'based on forecast costs and contracted future capacity, including capacity not yet built'; body 'yield of $20-25 million per megawatt'; 'expected payback period for the associated capex and related operating costs ... 1 year and 10 months'. NO IT/gross MW basis stated. | C2: https://www.sec.gov/Archives/edgar/data/1513845/000110465926094568/tm2622968d1_ex99-2.htm ; local /workspace/nebius/src/q2_26.txt
A3: S2 | B3: Nebius Q2'26 earnings call (Aug 12 2026): CEO 'mid-term contracts of one to three years ... yield of $20 million-$25 million per megawatt, with upfront payments that cover 50%-60% of the associated CapEx'; CFO 'more than $20 million per megawatt deals and less than two-year payback'. No MW basis. | C3: /workspace/nebius/filings/altdata/transcripts/transcript_q2-2026.txt
A4: S3 | B4: IREN-Microsoft PR (Nov 3 2025): 5-yr, ~$9.7bn TCV, 20% prepayment, GB300, 200MW critical IT load (Horizon 1-4); Dell GPUs + ancillary equipment ~$5.8bn. | C4: https://www.sec.gov/Archives/edgar/data/1878848/000114036125040072/ef20058139_ex99-1.htm
A5: S4 | B5: IREN investor presentation (8-K, Nov 3 2025): '$1.94bn ARR', '85% Estimated Project EBITDA Margin' (after power, R&M, other direct operating costs incl. DC operating costs; before overhead/financing), '$5.8bn estimated GPU capex, including ancillaries' (deployment services, servers, InfiniBand, cabling, software, licensing). 'Microsoft contract scales IREN's footprint to 100k GPUs'. | C5: https://iren.gcs-web.com/static-files/87a13320-156c-4f88-8589-dee2d10faa81
A6: S5 | B6: IREN FY26 results PR (Aug 27 2026): 'Recent 3-year contracts >$20m revenue per MW (IT), representing a ~2 year payback(3)'; 'Active discussions at ~$25m per MW (IT)'; prepayments 45-55% of GPU capex; fn3 'Payback period estimated based on estimated capital expenditure for GPUs and ancillaries divided by contracted revenue less estimated direct costs.' | C6: https://www.sec.gov/Archives/edgar/data/1878848/000187884826000051/irenreportsfy26results.htm ; local comps_raw/iren_fy26pr__irenreportsfy26results.htm.txt
A7: S6 | B7: IREN Horizon 1 delivered (Aug 13 2026): four 50MW (IT load) liquid-cooled deployments; IREN targets 480MW (gross) 2026 / 1.2GW (gross) 2027 - IREN labels both bases. | C7: https://www.sec.gov/Archives/edgar/data/1878848/000114036126032638/ef20080141_ex99-1.htm
A8: S7 | B8: IREN Horizon DC build cost ~$300-350M per 50MW IT = $6-7M/IT MW (Capacity team Peers tab S26). | C8: /workspace/nebius/capacity/gpu_mw_capex.xlsx (Peers)
A9: S8 | B9: CoreWeave revenue, adj. EBITDA, in-service gross PP&E, active MW (8-K PRs, 10-Q/10-K) as compiled in peer KPI workbook (Inputs I01, I02, I05S, I09/I09E). | C9: /workspace/nebius/peers/coreweave/crwv_kpis.xlsx ; https://www.sec.gov/Archives/edgar/data/1769628/000176962826000366/crwv-20260630.htm
A10: S9 | B10: Nscale S-1 (Sep 18 2026): GPU counts by site/customer; Monarch WV 460 IT MW contracted (Anthropic); 'We expect average cash payback to occur within the initial contract term' (no figure); adj. EBITDA negative. | C10: https://www.sec.gov/Archives/edgar/data/2110365/000119312526395475/ck0002110365-20260918.htm ; local comps_raw/nscale_s1.htm.txt
A11: S10 | B11: Contract economics (TCV, term, MW, GPU counts, MW basis) for Nebius-Microsoft/Meta, Nscale-Microsoft/Anthropic, Oracle-OpenAI with per-deal sources. | C11: /workspace/nebius/parts/contract_economics.xlsx (Deals, Normalized)
A12: S11 | B12: GPUs per IT MW and capex per IT MW by generation (third-party price build-up; Estimated): GB300 server+network $81.9k/GPU, 491 GPUs/IT MW -> $40.3M/IT MW compute (low 35.5, high 52.5); VR $94.4k/GPU, 320/IT MW -> $30.3M; owned DC shell+power $12.5M/IT MW base. | C12: /workspace/nebius/capacity/gpu_mw_capex.xlsx (GPUsPerMW, CapexPerMW)
... A20: S19 | B20: Oracle-OpenAI ~$300B / ~5 yrs / 4.5 GW (WSJ; not confirmed by Oracle by name) - press. | C20: /workspace/nebius/parts/contract_economics.xlsx (O2)
