Workbook

Sheet README
A1: Peer KPI comps - IREN Ltd (NASDAQ: IREN), AI Cloud perimeter, calendar Q1'24-Q2'26. Built 2026-10-05 (ET) for the Nebius (NBIS) project. File: /workspace/nebius/peers/iren/iren_kpis.xlsx; builder: build_iren_kpis.py (same folder) on shared engine /workspace/nebius/peers/peer_kpi_template.py.
A2: TEMPLATE: identical to peers/coreweave/crwv_kpis.xlsx - same row IDs (I01-I27, K01-K40), definitions D1-D8, tag colours and sourcing rules. Phase-2 extensions: I28-I32 / K41-K45 (useful life, reported GPU utilization, RPO<12m, incremental rev per incremental MW, revenue / GPU hardware, segment gross margin); I40+ / M01+ are IREN-specific memo rows (mining split).
A3: FISCAL MAPPING: IREN FY ends 30-Jun, so fiscal quarters end on calendar quarter-ends -> exact mapping (Q1'24 = FQ3 FY24 Mar-24 ... Q2'26 = FQ4 FY26 Jun-26). See Fiscal_Map tab and row 2 of KPIs/Inputs.
A4: PERIMETER: I01 = AI Cloud Services segment revenue; MW/GPUs = AI only. Bitcoin mining shown separately (I40, I44-I48, M01-M04). Capex, D&A, PP&E, debt are company-wide (not segmented) - KPIs mixing perimeters are suppressed (n/d with explanation) or labelled company-wide.
A5: ACCOUNTING BASIS: IFRS for FQ3 FY24-FQ3 FY25 (6-K / 20-F); US GAAP from FY25 10-K (FY24/FY25 recast). Basis breaks are flagged on each input.
A6: TAGS / COLOURS: blue = Reported; black = Derived (arithmetic; formula in Sources); orange = Estimated (assumption); grey n/d. KPI tag = weakest input.
A7: UNITS: $M unless stated; $/MW KPIs annualized ($M per MW-year); $/GPU in $K per GPU-year.
A8: Multi-peer Comparison tab: /workspace/nebius/peers/comparison.xlsx (built by peers/build_comparison.py).

Sheet KPIs
A1: KPIs - IREN (IREN) - AI Cloud perimeter - quarterly, Nebius definitions (Definitions tab). Value row = live formula; row below = tag (weakest input). Row 2 = fiscal quarter mapped to each calendar column.
E2: FQ2 FY24 (Dec-23) | F2: FQ3 FY24 (Mar-24) | G2: FQ4 FY24 (Jun-24) | H2: FQ1 FY25 (Sep-24) | I2: FQ2 FY25 (Dec-24) | J2: FQ3 FY25 (Mar-25) | K2: FQ4 FY25 (Jun-25) | L2: FQ1 FY26 (Sep-25) | M2: FQ2 FY26 (Dec-25) | N2: FQ3 FY26 (Mar-26) | O2: FQ4 FY26 (Jun-26)
A3: ID | B3: KPI | C3: Unit | D3: Def | E3: Q4'23* | F3: Q1'24 | G3: Q2'24 | H3: Q3'24 | I3: Q4'24 | J3: Q1'25 | K3: Q2'25 | L3: Q3'25 | M3: Q4'25 | N3: Q1'26 | O3: Q2'26 | P3: Method / caveat (IREN (IREN) - AI Cloud perimeter)
A4: A. Revenue per MW ($M per MW-year, annualized: quarterly revenue x 4 / MW)
A5: K01 | B5: Revenue per active MW - period-end MW | C5: $M/MW-yr | D5: D1 | E5: n/d | F5: n/d | G5: n/d | H5: n/d | I5: n/d | J5: n/d | K5: n/d | L5: n/d | M5: n/d | N5: n/d | O5: =IFERROR(Inputs!O4*4/Inputs!O12,"n/d") -> 7.0515 | P5: AI Cloud revenue x4 / operating AI MW. Only Jun-26 MW reported (~40MW, basis unstated). IREN FY26 PR: recent 3-yr contracts '>$20m revenue per MW (IT)', active discussions at ~$25m/MW -> fleet 7.1 reflects legacy Hopper/on-demand mix and capacity live <1 quarter.
B6: tag | E6: n/d | F6: n/d | G6: n/d | H6: n/d | I6: n/d | J6: n/d | K6: n/d | L6: n/d | M6: n/d | N6: n/d | O6: Derived
A7: K02 | B7: Revenue per active MW - average MW | C7: $M/MW-yr | D7: D1 | E7: n/d | F7: n/d | G7: =IFERROR(Inputs!G4*4/Inputs!G54,"n/d") -> 8.8705588 | H7: =IFERROR(Inputs!H4*4/Inputs!H54,"n/d") -> 11.145868 | I7: =IFERROR(Inputs!I4*4/Inputs!I54,"n/d") -> 5.5967345 | J7: =IFERROR(Inputs!J4*4/Inputs!J54,"n/d") -> 5.3866097 | K7: =IFERROR(Inputs!K4*4/Inputs!K54,"n/d") -> 10.462843 | L7: =IFERROR(Inputs!L4*4/Inputs!L54,"n/d") -> 10.476822 | M7: n/d | N7: n/d | O7: n/d | P7: Average-MW variant. MW ESTIMATED from GPUs / 713 per IT-MW through Sep-25; Dec-25/Mar-26 MW n/d so Q4'25-Q2'26 n/d.
B8: tag | E8: n/d | F8: n/d | G8: Estimated | H8: Estimated | I8: Estimated | J8: Estimated | K8: Estimated | L8: Estimated | M8: n/d | N8: n/d | O8: n/d
A9: K03 | B9: Revenue per contracted MW | C9: $M/MW-yr | D9: D1 | E9: n/d | F9: n/d | G9: n/d | H9: n/d | I9: n/d | J9: n/d | K9: n/d | L9: n/d | M9: n/d | N9: n/d | O9: n/d | P9: n/d - no contracted-MW metric (Microsoft = 4 x 50MW IT Horizons; other contracts' MW not disclosed).
B10: tag | E10: n/d | F10: n/d | G10: n/d | H10: n/d | I10: n/d | J10: n/d | K10: n/d | L10: n/d | M10: n/d | N10: n/d | O10: n/d
A11: K04 | B11: Contracted / active MW (build-out multiple) | C11: x | D11: D1 | E11: n/d | F11: n/d | G11: n/d | H11: n/d | I11: n/d | J11: n/d | K11: n/d | L11: n/d | M11: n/d | N11: n/d | O11: n/d | P11: n/d (no contracted MW).
B12: tag | E12: n/d | F12: n/d | G12: n/d | H12: n/d | I12: n/d | J12: n/d | K12: n/d | L12: n/d | M12: n/d | N12: n/d | O12: n/d
A13: K05 | B13: Adj. EBITDA per active MW (average MW) | C13: $M/MW-yr | D13: D1 | E13: n/d | F13: n/d | G13: n/d | H13: n/d | I13: n/d | J13: n/d | K13: n/d | L13: n/d | M13: n/d | N13: n/d | O13: n/d | P13: n/d - IREN reports Adj. EBITDA only company-wide (memo I47; FY26 $245.7M incl. mining). See K45 for AI segment gross margin.
B14: tag | E14: n/d | F14: n/d | G14: n/d | H14: n/d | I14: n/d | J14: n/d | K14: n/d | L14: n/d | M14: n/d | N14: n/d | O14: n/d
A15: B. Revenue per GPU and implied utilization
A16: K06 | B16: Revenue per GPU ($K per GPU-year, avg GPUs) | C16: $K/GPU-yr | D16: D2 | E16: n/d | F16: n/d | G16: =IFERROR(Inputs!G4*4000/Inputs!G52,"n/d") -> 12.441176 | H16: =IFERROR(Inputs!H4*4000/Inputs!H52,"n/d") -> 15.632353 | I16: =IFERROR(Inputs!I4*4000/Inputs!I52,"n/d") -> 7.8495575 | J16: =IFERROR(Inputs!J4*4000/Inputs!J52,"n/d") -> 7.5548523 | K16: =IFERROR(Inputs!K4*4000/Inputs!K52,"n/d") -> 14.674394 | L16: =IFERROR(Inputs!L4*4000/Inputs!L52,"n/d") -> 14.694 | M16: n/d | N16: n/d | O16: n/d | P16: Avg GPUs (I11A) reported except Sep-24 (Estimated). Last computable Q3'25 (GPU counts stop). Q2'26 memo M07 uses estimated period-end GPUs.
B17: tag | E17: n/d | F17: n/d | G17: Derived | H17: Estimated | I17: Estimated | J17: Derived | K17: Derived | L17: Derived | M17: n/d | N17: n/d | O17: n/d
A18: K07 | B18: Implied blended realized price ($/GPU-hr) | C18: $/GPU-hr | D18: D2 | E18: n/d | F18: n/d | G18: =IFERROR(Inputs!G4*1000000/(Inputs!G52*Inputs!G29*24),"n/d") -> 1.4241273 | H18: =IFERROR(Inputs!H4*1000000/(Inputs!H52*Inputs!H29*24),"n/d") -> 1.7699675 | I18: =IFERROR(Inputs!I4*1000000/(Inputs!I52*Inputs!I29*24),"n/d") -> 0.88876331 | J18: =IFERROR(Inputs!J4*1000000/(Inputs!J52*Inputs!J29*24),"n/d") -> 0.8744042 | K18: =IFERROR(Inputs!K4*1000000/(Inputs!K52*Inputs!K29*24),"n/d") -> 1.6797612 | L18: =IFERROR(Inputs!L4*1000000/(Inputs!L52*Inputs!L29*24),"n/d") -> 1.6637228 | M18: n/d | N18: n/d | O18: n/d | P18: All-in AI revenue per GPU-hour on operating GPUs. Note: IREN H100/H200 fleet; GPUs listed as 'operating' may include unrented capacity.
B19: tag | E19: n/d | F19: n/d | G19: Derived | H19: Estimated | I19: Estimated | J19: Derived | K19: Derived | L19: Derived | M19: n/d | N19: n/d | O19: n/d
A20: K08 | B20: Fleet-weighted on-demand list price ($/GPU-hr) | C20: $/GPU-hr | D20: D3 | E20: n/d | F20: =IFERROR(Inputs!F56,"n/d") -> 2 | G20: =IFERROR(Inputs!G56,"n/d") -> 2 | H20: =IFERROR(Inputs!H56,"n/d") -> 2 | I20: =IFERROR(Inputs!I56,"n/d") -> 2 | J20: =IFERROR(Inputs!J56,"n/d") -> 2 | K20: =IFERROR(Inputs!K56,"n/d") -> 2 | L20: =IFERROR(Inputs!L56,"n/d") -> 2 | M20: n/d | N20: n/d | O20: n/d | P20: ESTIMATED: IREN publishes no list price; uses IREN's own $2.00/GPU-hr 100%-uptime revenue assumption (Q1 FY25 PR). Different basis from CRWV/Nebius (on-demand list).
B21: tag | E21: n/d | F21: Estimated | G21: Estimated | H21: Estimated | I21: Estimated | J21: Estimated | K21: Estimated | L21: Estimated | M21: n/d | N21: n/d | O21: n/d
A22: K09 | B22: Implied utilization (realized $/GPU-hr / weighted list) | C22: % | D22: D3 | E22: n/d | F22: n/d | G22: =IFERROR(Inputs!G4*1000000/(Inputs!G52*Inputs!G29*24)/Inputs!G56*100,"n/d") -> 71.206367 | H22: =IFERROR(Inputs!H4*1000000/(Inputs!H52*Inputs!H29*24)/Inputs!H56*100,"n/d") -> 88.498375 | I22: =IFERROR(Inputs!I4*1000000/(Inputs!I52*Inputs!I29*24)/Inputs!I56*100,"n/d") -> 44.438165 | J22: =IFERROR(Inputs!J4*1000000/(Inputs!J52*Inputs!J29*24)/Inputs!J56*100,"n/d") -> 43.72021 | K22: =IFERROR(Inputs!K4*1000000/(Inputs!K52*Inputs!K29*24)/Inputs!K56*100,"n/d") -> 83.988061 | L22: =IFERROR(Inputs!L4*1000000/(Inputs!L52*Inputs!L29*24)/Inputs!L56*100,"n/d") -> 83.186141 | M22: n/d | N22: n/d | O22: n/d | P22: Realized $/GPU-hr / IREN's own $2.00 assumption -> closer to a physical-utilization x price-realization index than CRWV/Nebius (list-based, which embeds contract discounts). Not comparable 1:1.
B23: tag | E23: n/d | F23: n/d | G23: Estimated | H23: Estimated | I23: Estimated | J23: Estimated | K23: Estimated | L23: Estimated | M23: n/d | N23: n/d | O23: n/d
A24: C. Capex per MW ($M per MW)
A25: K10 | B25: Cash capex per new active MW | C25: $M/MW | D25: D4 | E25: n/d | F25: n/d | G25: n/d | H25: n/d | I25: n/d | J25: n/d | K25: n/d | L25: n/d | M25: n/d | N25: n/d | O25: n/d | P25: n/d - capex is company-wide (mining + AI; no split) and AI MW is n/d quarterly. Context: FY26 cash capex $4.33B vs +~37MW operating AI MW = $116M/MW, meaningless because $3.66B sits in CIP (Childress Horizons, Sweetwater) not yet operating.
B26: tag | E26: n/d | F26: n/d | G26: n/d | H26: n/d | I26: n/d | J26: n/d | K26: n/d | L26: n/d | M26: n/d | N26: n/d | O26: n/d
A27: K11 | B27: Cash capex per new active MW (incl. estimated MW) | C27: $M/MW | D27: D4 | E27: n/d | F27: n/d | G27: n/d | H27: n/d | I27: n/d | J27: n/d | K27: n/d | L27: n/d | M27: n/d | N27: n/d | O27: n/d | P27: n/d (see K10).
B28: tag | E28: n/d | F28: n/d | G28: n/d | H28: n/d | I28: n/d | J28: n/d | K28: n/d | L28: n/d | M28: n/d | N28: n/d | O28: n/d
A29: K12 | B29: In-service additions per new active MW | C29: $M/MW | D29: D4 | E29: n/d | F29: n/d | G29: n/d | H29: n/d | I29: n/d | J29: n/d | K29: n/d | L29: n/d | M29: n/d | N29: n/d | O29: n/d | P29: n/d (no AI new-MW series).
B30: tag | E30: n/d | F30: n/d | G30: n/d | H30: n/d | I30: n/d | J30: n/d | K30: n/d | L30: n/d | M30: n/d | N30: n/d | O30: n/d
A31: K13 | B31: Trailing-4Q cash capex per trailing-4Q new active MW | C31: $M/MW | D31: D4 | E31: n/d | F31: n/d | G31: n/d | H31: n/d | I31: n/d | J31: n/d | K31: n/d | L31: n/d | M31: n/d | N31: n/d | O31: n/d | P31: Suppressed: trailing-4Q company capex / AI MW added would be ~116 $M/MW (timing + perimeter mismatch). See memo M06 (GPU hardware per AI MW).
B32: tag | E32: n/d | F32: n/d | G32: n/d | H32: n/d | I32: n/d | J32: n/d | K32: n/d | L32: n/d | M32: n/d | N32: n/d | O32: n/d
A33: K14 | B33: Net PP&E per active MW (EoP) | C33: $M/MW | D33: D4 | E33: n/d | F33: n/d | G33: n/d | H33: n/d | I33: n/d | J33: n/d | K33: n/d | L33: n/d | M33: n/d | N33: n/d | O33: n/d | P33: n/d on AI perimeter (net PP&E is company-wide). Company-wide analogue in memo M05 (net PP&E / total operating DC MW).
B34: tag | E34: n/d | F34: n/d | G34: n/d | H34: n/d | I34: n/d | J34: n/d | K34: n/d | L34: n/d | M34: n/d | N34: n/d | O34: n/d
A35: K15 | B35: Gross in-service PP&E per active MW (EoP) | C35: $M/MW | D35: D4 | E35: n/d | F35: n/d | G35: n/d | H35: n/d | I35: n/d | J35: n/d | K35: n/d | L35: n/d | M35: n/d | N35: n/d | O35: n/d | P35: n/d on AI perimeter. AI-only analogue: memo M06 = GPU hardware gross / AI MW.
B36: tag | E36: n/d | F36: n/d | G36: n/d | H36: n/d | I36: n/d | J36: n/d | K36: n/d | L36: n/d | M36: n/d | N36: n/d | O36: n/d
A37: D. D&A useful lives and depreciation yield
A38: K16 | B38: Useful life - GPU / server equipment | C38: years | D38: D5 | E38: n/d | F38: =IFERROR(Inputs!F31,"n/d") -> 5 | G38: =IFERROR(Inputs!G31,"n/d") -> 5 | H38: =IFERROR(Inputs!H31,"n/d") -> 5 | I38: =IFERROR(Inputs!I31,"n/d") -> 5 | J38: =IFERROR(Inputs!J31,"n/d") -> 5 | K38: =IFERROR(Inputs!K31,"n/d") -> 5 | L38: =IFERROR(Inputs!L31,"n/d") -> 5 | M38: =IFERROR(Inputs!M31,"n/d") -> 5 | ... O38: =IFERROR(Inputs!O31,"n/d") -> 5 | P38: 10-K FY26 / FY25 / 20-F FY24 useful-life table: HPC (GPU) hardware 5 yrs; mining hardware 4 yrs (2 yrs for S19j Pro/S19 Pro from FY24); buildings 20. No change to GPU life FY24-FY26. Nebius: 4->5 yrs from 1-Jan-2026; CRWV 6 yrs.
B39: tag | E39: n/d | F39: Reported | G39: Reported | H39: Reported | I39: Reported | J39: Reported | K39: Reported | L39: Reported | M39: Reported | N39: Reported | O39: Reported
A40: K17 | B40: Depreciation yield (D&A x4 / avg in-service gross PP&E) | C40: % | D40: D5 | E40: n/d | F40: n/d | G40: =IFERROR(Inputs!G6*4/((Inputs!F57+Inputs!G57)/2)*100,"n/d") -> 29.173424 | H40: =IFERROR(Inputs!H6*4/((Inputs!G57+Inputs!H57)/2)*100,"n/d") -> 21.555296 | I40: =IFERROR(Inputs!I6*4/((Inputs!H57+Inputs!I57)/2)*100,"n/d") -> 14.774968 | J40: =IFERROR(Inputs!J6*4/((Inputs!I57+Inputs!J57)/2)*100,"n/d") -> 14.656716 | K40: =IFERROR(Inputs!K6*4/((Inputs!J57+Inputs!K57)/2)*100,"n/d") -> 15.226899 | L40: =IFERROR(Inputs!L6*4/((Inputs!K57+Inputs!L57)/2)*100,"n/d") -> 17.989985 | M40: =IFERROR(Inputs!M6*4/((Inputs!L57+Inputs!M57)/2)*100,"n/d") -> 18.052806 | N40: =IFERROR(Inputs!N6*4/((Inputs!M57+Inputs!N57)/2)*100,"n/d") -> 18.634414 | O40: =IFERROR(Inputs!O6*4/((Inputs!N57+Inputs!O57)/2)*100,"n/d") -> 14.351359 | P40: Company-wide D&A x4 / avg in-service gross PP&E (gross - CIP - impairment). Q3'24-Q1'25 IFRS, Q2'25 straddles IFRS->GAAP. High yields reflect 2-4 yr mining hardware lives; falling to ~10% as GPU (5y) and buildings (20y) dominate.
...

Sheet Inputs
A1: Inputs - IREN (IREN) - AI Cloud perimeter. Reported (blue), derived (black), estimated (orange), n/d (grey). Per-cell source detail on Sources tab. Row 2 = fiscal quarter / period end mapped to each calendar column.
E2: FQ2 FY24 (Dec-23) | F2: FQ3 FY24 (Mar-24) | G2: FQ4 FY24 (Jun-24) | H2: FQ1 FY25 (Sep-24) | I2: FQ2 FY25 (Dec-24) | J2: FQ3 FY25 (Mar-25) | K2: FQ4 FY25 (Jun-25) | L2: FQ1 FY26 (Sep-25) | M2: FQ2 FY26 (Dec-25) | N2: FQ3 FY26 (Mar-26) | O2: FQ4 FY26 (Jun-26)
A3: ID | B3: Item | C3: Unit | D3: Tag mix | E3: Q4'23* | F3: Q1'24 | G3: Q2'24 | H3: Q3'24 | I3: Q4'24 | J3: Q1'25 | K3: Q2'25 | L3: Q3'25 | M3: Q4'25 | N3: Q1'26 | O3: Q2'26 | P3: Source summary / notes
A4: I01 | B4: AI Cloud Services revenue (segment) | C4: $M | D4: Derived/Reported | E4: n/d | F4: 0.567 | G4: 2.538 | H4: 3.189 | I4: 2.661 | J4: 3.581 | K4: 6.963 | L4: 7.347 | M4: 17.298 | N4: 33.635 | O4: 70.515 | P4: 6-K FQ3 FY25 (Mar-25 qtr; IFRS) - interim FS / MD&A Ex.99.4 / PR, filed 2025-05; 10-K FY26 (FYE 30-Jun-2026), filed 2026-08-27; 10-Q FQ1 FY26 (Sep-25 qtr), filed 2025-11-06; 10-Q FQ2 FY26 (Dec-25 qtr), filed 2026-02-05; 10-Q FQ3 FY26 (Mar-26 qtr), filed 2026-05-07; 10-K FY25 (FYE 30-Jun-2025; first US GAAP annual; incl. unaudited quarterly table), filed 2025-08-28 | NOTE: KPI perimeter = AI Cloud Services segment only (all AI revenue generated in Canada through FY26 Q3 per 10-Q; Childress Texas from H2 CY26). 2024 quarters (FQ3-FQ4 FY24) are IFRS; from FY25 10-K onward US GAAP (FY24/FY25 recast).
A5: I02 | B5: Adj. EBITDA of KPI perimeter (AI segment) | C5: $M | D5: n/d | E5: n/d | F5: n/d | G5: n/d | H5: n/d | I5: n/d | J5: n/d | K5: n/d | L5: n/d | M5: n/d | N5: n/d | O5: n/d | P5: | NOTE: n/d: IREN reports Adj. EBITDA only company-wide (memo I47). Segment measure is gross profit excl. D&A (see K45).
A6: I03 | B6: Depreciation & amortization (company-wide, P&L) | C6: $M | D6: Derived/Reported | E6: n/d | F6: 8.692 | G6: 26.78 | H6: 33.931 | I6: 36.077 | J6: 47.311 | K6: 63.817 | L6: 85.226 | M6: 99.176 | N6: 121.245 | O6: 112.082 | P6: 6-K FQ3 FY24 (Mar-24 qtr; IFRS) - Ex.99.1 results PR / Ex.99.3 interim financial statements, filed 2024-05-15; Form 20-F FY24 (FYE 30-Jun-2024; IFRS), filed 2024-08-28; 10-Q FQ1 FY26 (Sep-25 qtr), filed 2025-11-06; 10-Q FQ3 FY26 (Mar-26 qtr), filed 2026-05-07; 10-K FY25 (FYE 30-Jun-2025; first US GAAP annual; incl. unaudited quarterly table), filed 2025-08-28; 10-K FY26 (FYE 30-Jun-2026), filed 2026-08-27 | NOTE: Company-wide (mining + AI + buildings); IREN does not allocate D&A to segments.
A7: I04 | B7: Cash capex (company-wide: PP&E net of hardware prepayments + computer/mining hardware incl. prepayments) | C7: $M | D7: Derived/Reported | E7: n/d | F7: n/d | G7: 296.6 | H7: 383.4 | I7: 187.6 | J7: 443.8 | K7: 357.9 | L7: 280.6 | M7: 719.1 | N7: 1355.3 | O7: 1978.2 | P7: Form 20-F FY24 (FYE 30-Jun-2024; IFRS), filed 2024-08-28; 10-Q FQ1 FY26 (Sep-25 qtr), filed 2025-11-06; 10-Q FQ2 FY26 (Dec-25 qtr), filed 2026-02-05; 10-Q FQ3 FY26 (Mar-26 qtr), filed 2026-05-07; 10-K FY25 (FYE 30-Jun-2025; first US GAAP annual; incl. unaudited quarterly table), filed 2025-08-28; 10-K FY26 (FYE 30-Jun-2026), filed 2026-08-27 | NOTE: Company-wide; not split AI vs mining. FY26 capex is predominantly AI (Childress Horizon GPU halls, BC ASIC->GPU conversions, GPUs) but no split is disclosed.
A8: I05 | B8: Gross property, plant & equipment (EoP) | C8: $M | D8: Derived/Reported | E8: n/d | F8: 427.51 | G8: 538.026 | H8: 1010.401 | I8: 1288.15 | J8: 1699.48 | K8: 2112.2 | L8: 2396.859 | M8: 3553.7 | N8: 4987 | O8: 7663.316 | P8: 6-K FQ3 FY24 (Mar-24 qtr; IFRS) - Ex.99.1 results PR / Ex.99.3 interim financial statements, filed 2024-05-15; Form 20-F FY24 (FYE 30-Jun-2024; IFRS), filed 2024-08-28; 6-K FQ1 FY25 (Sep-24 qtr; IFRS) - interim FS + results PR, filed 2024-11; 6-K FQ2 FY25 (Dec-24 qtr; IFRS) - interim FS / MD&A Ex.99.4 / PR, filed 2025-02; 6-K FQ3 FY25 (Mar-25 qtr; IFRS) - interim FS / MD&A Ex.99.4 / PR, filed 2025-05; 10-K FY25 (FYE 30-Jun-2025; first US GAAP annual; incl. unaudited quarterly table), filed 2025-08-28; 10-Q FQ1 FY26 (Sep-25 qtr), filed 2025-11-06; 10-Q FQ2 FY26 (Dec-25 qtr), filed 2026-02-05; 10-Q FQ3 FY26 (Mar-26 qtr), filed 2026-05-07; 10-K FY26 (FYE 30-Jun-2026), filed 2026-08-27 | NOTE: IFRS (to Mar-25) shows accumulated impairment separately from gross; GAAP (Jun-25+) likewise ('Less: Impairment'). Basis break between Mar-25 and Jun-25.
A9: I06 | B9: Construction in progress / development assets (EoP; not in service) | C9: $M | D9: Reported | E9: n/d | F9: 76.904 | G9: 102.946 | H9: 153.625 | I9: 177.639 | J9: 213.763 | K9: 237.734 | L9: 464.832 | M9: 1038.321 | N9: 2089.371 | O9: 3657.072 | P9: 6-K FQ3 FY24 (Mar-24 qtr; IFRS) - Ex.99.1 results PR / Ex.99.3 interim financial statements, filed 2024-05-15; Form 20-F FY24 (FYE 30-Jun-2024; IFRS), filed 2024-08-28; 6-K FQ1 FY25 (Sep-24 qtr; IFRS) - interim FS + results PR, filed 2024-11; 6-K FQ2 FY25 (Dec-24 qtr; IFRS) - interim FS / MD&A Ex.99.4 / PR, filed 2025-02; 6-K FQ3 FY25 (Mar-25 qtr; IFRS) - interim FS / MD&A Ex.99.4 / PR, filed 2025-05; 10-K FY25 (FYE 30-Jun-2025; first US GAAP annual; incl. unaudited quarterly table), filed 2025-08-28; 10-Q FQ1 FY26 (Sep-25 qtr), filed 2025-11-06; 10-Q FQ2 FY26 (Dec-25 qtr), filed 2026-02-05; 10-Q FQ3 FY26 (Mar-26 qtr), filed 2026-05-07; 10-K FY26 (FYE 30-Jun-2026), filed 2026-08-27
A10: I07 | B10: Property, plant & equipment, net (EoP) | C10: $M | D10: Reported | E10: n/d | F10: 357.081 | G10: 441.371 | H10: 965.994 | I10: 1209.339 | J10: 1575.107 | K10: 1930.567 | L10: 2115.436 | M10: 3170.5 | N10: 4369.9 | O10: 6753.183 | P10: 6-K FQ3 FY24 (Mar-24 qtr; IFRS) - Ex.99.1 results PR / Ex.99.3 interim financial statements, filed 2024-05-15; Form 20-F FY24 (FYE 30-Jun-2024; IFRS), filed 2024-08-28; 6-K FQ1 FY25 (Sep-24 qtr; IFRS) - interim FS + results PR, filed 2024-11; 6-K FQ2 FY25 (Dec-24 qtr; IFRS) - interim FS / MD&A Ex.99.4 / PR, filed 2025-02; 6-K FQ3 FY25 (Mar-25 qtr; IFRS) - interim FS / MD&A Ex.99.4 / PR, filed 2025-05; 10-K FY25 (FYE 30-Jun-2025; first US GAAP annual; incl. unaudited quarterly table), filed 2025-08-28; 10-Q FQ1 FY26 (Sep-25 qtr), filed 2025-11-06; 10-Q FQ2 FY26 (Dec-25 qtr), filed 2026-02-05; 10-Q FQ3 FY26 (Mar-26 qtr), filed 2026-05-07; 10-K FY26 (FYE 30-Jun-2026), filed 2026-08-27
A11: I08 | B11: Technology equipment, gross (CRWV row; n/d - see I31 GPU hardware, I48 mining hardware) | C11: $M | D11: n/d | E11: n/d | F11: n/d | G11: n/d | H11: n/d | I11: n/d | J11: n/d | K11: n/d | L11: n/d | M11: n/d | N11: n/d | O11: n/d
A12: I09 | B12: Operating AI Cloud capacity, reported (EoP) | C12: MW | D12: Reported | E12: n/d | F12: n/d | G12: n/d | H12: n/d | I12: n/d | J12: n/d | K12: n/d | L12: n/d | M12: n/d | N12: n/d | O12: 40 | P12: 10-K FY26 (FYE 30-Jun-2026), filed 2026-08-27 | NOTE: Only AI MW figure IREN has disclosed. Basis (IT vs gross) not stated. Earlier quarters estimated from GPUs (I09E). Dec-25/Mar-26: n/d (GPU counts no longer disclosed; Horizon 1 at Childress (50MW IT) delivered to Microsoft only after FY26 per FY26 PR).
A13: I10 | B13: Contracted AI MW (EoP) | C13: MW | D13: n/d | E13: n/d | F13: n/d | G13: n/d | H13: n/d | I13: n/d | J13: n/d | K13: n/d | L13: n/d | M13: n/d | N13: n/d | O13: n/d | P13: | NOTE: n/d as a metric. FY26 PR: Microsoft contract = four 50MW (IT) liquid-cooled 'Horizon' deployments at Childress (=200MW IT, D) - not entered because other contracts' MW are not disclosed.
A14: I11 | B14: AI GPUs operating, reported (EoP) | C14: GPUs | D14: Reported | E14: n/d | F14: 816 | G14: 816 | H14: n/d | I14: 1896 | J14: 1896 | K14: 1900 | L14: 2100 | M14: n/d | N14: n/d | O14: n/d | P14: 6-K FQ3 FY24 (Mar-24 qtr; IFRS) - Ex.99.1 results PR / Ex.99.3 interim financial statements, filed 2024-05-15; FY24 results PR (6-K Ex.99.1, 2024-08-28); 6-K FQ3 FY25 (Mar-25 qtr; IFRS) - interim FS / MD&A Ex.99.4 / PR, filed 2025-05; 10-K FY25 (FYE 30-Jun-2025; first US GAAP annual; incl. unaudited quarterly table), filed 2025-08-28; 10-Q FQ1 FY26 (Sep-25 qtr), filed 2025-11-06 | NOTE: Dec-25 onward IREN discloses only GPUs 'installed or contracted/on order' (e.g., 140k expansion target, Q1 FY26 PR) - not operating counts. Sep-24 estimated in I11E.
A15: I12 | B15: Hopper price proxy: IREN's own revenue assumption ($/GPU-hr at 100% uptime) | C15: $/GPU-hr | D15: Estimated | E15: n/d | F15: 2 | G15: 2 | H15: 2 | I15: 2 | J15: 2 | K15: 2 | L15: 2 | M15: n/d | N15: n/d | O15: n/d | P15: 6-K FQ1 FY25 (Sep-24 qtr; IFRS) - interim FS + results PR, filed 2024-11 | NOTE: IREN publishes no on-demand list price ('contact sales'). The $2.00 is IREN's own assumed realized rate, so K09 for IREN is closer to a utilization ratio than CRWV/Nebius (list-based). Not comparable 1:1.
A16: I13 | B16: Blackwell list price | C16: $/GPU-hr | D16: n/d | E16: n/d | F16: n/d | G16: n/d | H16: n/d | I16: n/d | J16: n/d | K16: n/d | L16: n/d | M16: n/d | N16: n/d | O16: n/d | P16: | NOTE: No public list price.
A17: I14 | B17: RPO (ASC 606, EoP) | C17: $B | D17: Reported | E17: n/d | F17: n/d | G17: n/d | H17: n/d | I17: n/d | J17: n/d | K17: n/d | L17: 0.195027 | M17: 0.289411 | N17: 0.710272 | O17: 5.1 | P17: 10-Q FQ1 FY26 (Sep-25 qtr), filed 2025-11-06; 10-Q FQ2 FY26 (Dec-25 qtr), filed 2026-02-05; 10-Q FQ3 FY26 (Mar-26 qtr), filed 2026-05-07; 10-K FY26 (FYE 30-Jun-2026), filed 2026-08-27 | NOTE: Pre-Sep-25 n/d (no RPO disclosure under IFRS 6-Ks / FY25 10-K). Microsoft $9.7B TCV enters RPO only as tranches are delivered and accepted (nil at Dec-25/Mar-26).
A18: I15 | B18: Contracted backlog incl. non-RPO (RPO + undelivered Microsoft TCV / ASC 842 lease value) | C18: $B | D18: Derived/Reported | E18: n/d | F18: n/d | G18: n/d | H18: n/d | I18: n/d | J18: n/d | K18: n/d | L18: n/d | M18: 9.989 | N18: 10.41 | O18: 16.6 | P18: 10-Q FQ2 FY26 (Dec-25 qtr), filed 2026-02-05; 10-Q FQ3 FY26 (Mar-26 qtr), filed 2026-05-07; 10-K FY26 (FYE 30-Jun-2026), filed 2026-08-27 | NOTE: Dec-25/Mar-26 are lower bounds (other signed-not-delivered contracts not quantified in filings).
A19: I16 | B19: RPO % expected to be recognized within 24 months | C19: % | D19: Derived | E19: n/d | F19: n/d | G19: n/d | H19: n/d | I19: n/d | J19: n/d | K19: n/d | L19: 95.8 | M19: 98.7 | N19: 80.7 | O19: 43.1 | P19: 10-Q FQ1 FY26 (Sep-25 qtr), filed 2025-11-06; 10-Q FQ2 FY26 (Dec-25 qtr), filed 2026-02-05; 10-Q FQ3 FY26 (Mar-26 qtr), filed 2026-05-07; 10-K FY26 (FYE 30-Jun-2026), filed 2026-08-27
A20: I17 | B20: Largest customer, % of quarter revenue | C20: % | D20: n/d | E20: n/d | F20: n/d | G20: n/d | H20: n/d | I20: n/d | J20: n/d | K20: n/d | L20: n/d | M20: n/d | N20: n/d | O20: n/d | P20: | NOTE: n/d for AI Cloud. Mining: 97%/98%/100% of FY25/FY24/FY23 revenue via 3/3/2 mining pool operators (FY25 10-K) - pools are not end-customers in the CRWV sense. Microsoft ($9.7B) and NVIDIA ($3.4B) are the 'substantial majority' of contracted value at Jun-26 (backlog, not revenue).
A21: I18 | B21: 2nd-largest customer % | C21: % | D21: n/d | E21: n/d | F21: n/d | G21: n/d | H21: n/d | I21: n/d | J21: n/d | K21: n/d | L21: n/d | M21: n/d | N21: n/d | O21: n/d
A22: I19 | B22: 3rd-largest customer % | C22: % | D22: n/d | E22: n/d | F22: n/d | G22: n/d | H22: n/d | I22: n/d | J22: n/d | K22: n/d | L22: n/d | M22: n/d | N22: n/d | O22: n/d
A23: I20 | B23: Customers >=10% of revenue (count) | C23: # | D23: n/d | E23: n/d | F23: n/d | G23: n/d | H23: n/d | I23: n/d | J23: n/d | K23: n/d | L23: n/d | M23: n/d | N23: n/d | O23: n/d
A24: I21 | B24: Finance expense (P&L; incl. issuance-cost amortization & lease interest) | C24: $M | D24: Derived/Reported | E24: n/d | F24: n/d | G24: n/d | H24: 0.022 | I24: 6.253 | J24: 4.119 | K24: 5.182 | L24: 9.28 | M24: 10.668 | N24: 14.837 | O24: 24.466 | P24: 10-Q FQ1 FY26 (Sep-25 qtr), filed 2025-11-06; 6-K FQ2 FY25 (Dec-24 qtr; IFRS) - interim FS / MD&A Ex.99.4 / PR, filed 2025-02; 10-Q FQ3 FY26 (Mar-26 qtr), filed 2026-05-07; 10-K FY25 (FYE 30-Jun-2025; first US GAAP annual; incl. unaudited quarterly table), filed 2025-08-28; 10-K FY26 (FYE 30-Jun-2026), filed 2026-08-27 | NOTE: Not contractual coupon interest (IREN gives contractual interest only annually: FY26 $37.2M, FY25 $9.1M per 10-K debt note). Zero debt Mar-24-Sep-24.
A25: I22 | B25: Capitalized interest | C25: $M | D25: n/d | E25: n/d | F25: n/d | G25: n/d | H25: n/d | I25: n/d | J25: n/d | K25: n/d | L25: n/d | M25: n/d | N25: n/d | O25: n/d | P25: | NOTE: Not disclosed quarterly.
A26: I23 | B26: Total debt principal (EoP; excl. finance leases) | C26: $M | D26: Reported | E26: n/d | F26: 0 | G26: 0 | H26: 0 | I26: 440 | J26: 440 | K26: 990 | L26: 990 | M26: 3745.699 | N26: 3745.699 | O26: 7705.649 | P26: 6-K FQ3 FY24 (Mar-24 qtr; IFRS) - Ex.99.1 results PR / Ex.99.3 interim financial statements, filed 2024-05-15; Form 20-F FY24 (FYE 30-Jun-2024; IFRS), filed 2024-08-28; 6-K FQ1 FY25 (Sep-24 qtr; IFRS) - interim FS + results PR, filed 2024-11; 6-K FQ2 FY25 (Dec-24 qtr; IFRS) - interim FS / MD&A Ex.99.4 / PR, filed 2025-02; 6-K FQ3 FY25 (Mar-25 qtr; IFRS) - interim FS / MD&A Ex.99.4 / PR, filed 2025-05; 10-K FY25 (FYE 30-Jun-2025; first US GAAP annual; incl. unaudited quarterly table), filed 2025-08-28; 10-Q FQ1 FY26 (Sep-25 qtr), filed 2025-11-06; 10-Q FQ2 FY26 (Dec-25 qtr), filed 2026-02-05; 10-Q FQ3 FY26 (Mar-26 qtr), filed 2026-05-07; 10-K FY26 (FYE 30-Jun-2026), filed 2026-08-27
A27: I24 | B27: Company-reported weighted average interest rate | C27: % | D27: n/d | E27: n/d | F27: n/d | G27: n/d | H27: n/d | I27: n/d | J27: n/d | K27: n/d | L27: n/d | M27: n/d | N27: n/d | O27: n/d
A28: I25 | B28: Company-definition capex | C28: $M | D28: n/d | E28: n/d | F28: n/d | G28: n/d | H28: n/d | I28: n/d | J28: n/d | K28: n/d | L28: n/d | M28: n/d | N28: n/d | O28: n/d
A29: I26 | B29: Days in quarter | C29: days | D29: Reported | E29: n/d | F29: 91 | G29: 91 | H29: 92 | I29: 92 | J29: 90 | K29: 91 | L29: 92 | M29: 92 | N29: 90 | O29: 91 | P29: calendar
A30: I27 | B30: Data center sites (operating) | C30: # | D30: n/d | E30: n/d | F30: n/d | G30: n/d | H30: n/d | I30: n/d | J30: n/d | K30: n/d | L30: n/d | M30: n/d | N30: n/d | O30: n/d
A31: I28 | B31: Useful life - HPC / GPU hardware | C31: years | D31: Reported | E31: n/d | F31: 5 | G31: 5 | H31: 5 | I31: 5 | J31: 5 | K31: 5 | L31: 5 | M31: 5 | N31: 5 | O31: 5 | P31: Form 20-F FY24 (FYE 30-Jun-2024; IFRS), filed 2024-08-28; 10-K FY25 (FYE 30-Jun-2025; first US GAAP annual; incl. unaudited quarterly table), filed 2025-08-28; 10-K FY26 (FYE 30-Jun-2026), filed 2026-08-27 | NOTE: Mining hardware 4 yrs (S19j Pro/S19 Pro shortened to 2 yrs in FY24); buildings 20; other 3-10. No change to HPC life disclosed FY24-FY26.
A32: I29 | B32: Company-reported GPU utilization | C32: % | D32: n/d | E32: n/d | F32: n/d | G32: n/d | H32: n/d | I32: n/d | J32: n/d | K32: n/d | L32: n/d | M32: n/d | N32: n/d | O32: n/d
A33: I30 | B33: RPO % expected to be recognized within 12 months | C33: % | D33: Derived | E33: n/d | F33: n/d | G33: n/d | H33: n/d | I33: n/d | J33: n/d | K33: n/d | L33: 47.9 | M33: 51.9 | N33: 43.4 | O33: 17.6 | P33: 10-Q FQ1 FY26 (Sep-25 qtr), filed 2025-11-06; 10-Q FQ2 FY26 (Dec-25 qtr), filed 2026-02-05; 10-Q FQ3 FY26 (Mar-26 qtr), filed 2026-05-07; 10-K FY26 (FYE 30-Jun-2026), filed 2026-08-27
A34: I31 | B34: GPU / HPC hardware, gross at cost (EoP; owned, excl. finance-lease ROU) | C34: $M | D34: Reported | E34: n/d | F34: 29.603 | G34: 33.315 | H34: 33.678 | I34: 68.19 | J34: 69.406 | K34: 76.001 | L34: 106.047 | M34: 550.636 | N34: 811.39 | O34: 2034.811 | P34: 6-K FQ3 FY24 (Mar-24 qtr; IFRS) - Ex.99.1 results PR / Ex.99.3 interim financial statements, filed 2024-05-15; Form 20-F FY24 (FYE 30-Jun-2024; IFRS), filed 2024-08-28; 6-K FQ1 FY25 (Sep-24 qtr; IFRS) - interim FS + results PR, filed 2024-11; 6-K FQ2 FY25 (Dec-24 qtr; IFRS) - interim FS / MD&A Ex.99.4 / PR, filed 2025-02; 6-K FQ3 FY25 (Mar-25 qtr; IFRS) - interim FS / MD&A Ex.99.4 / PR, filed 2025-05; 10-K FY25 (FYE 30-Jun-2025; first US GAAP annual; incl. unaudited quarterly table), filed 2025-08-28; 10-Q FQ1 FY26 (Sep-25 qtr), filed 2025-11-06; 10-Q FQ2 FY26 (Dec-25 qtr), filed 2026-02-05; 10-Q FQ3 FY26 (Mar-26 qtr), filed 2026-05-07; 10-K FY26 (FYE 30-Jun-2026), filed 2026-08-27 | NOTE: Excludes GPU finance-lease right-of-use assets (I49) and GPUs in CIP/prepayments. In-service AI hardware, so the cleanest AI-only asset base.
A35: I32 | B35: AI Cloud segment cost of revenue (excl. D&A) | C35: $M | D35: Derived/Reported | E35: n/d | F35: n/d | G35: n/d | H35: 0.232 | I35: 0.275 | J35: 0.336 | K35: 0.476 | L35: 0.728 | M35: 2.395 | N35: 4.597 | O35: 9.212 | P35: 10-Q FQ1 FY26 (Sep-25 qtr), filed 2025-11-06; 10-Q FQ2 FY26 (Dec-25 qtr), filed 2026-02-05; 10-Q FQ3 FY26 (Mar-26 qtr), filed 2026-05-07; 10-K FY25 (FYE 30-Jun-2025; first US GAAP annual; incl. unaudited quarterly table), filed 2025-08-28; 10-K FY26 (FYE 30-Jun-2026), filed 2026-08-27 | NOTE: Mostly electricity. IFRS 2024 quarters: no segment cost split.
A36: I40 | B36: Bitcoin mining revenue (segment) | C36: $M | D36: Derived/Reported | E36: n/d | F36: 53.383 | G36: 54.26 | H36: 49.575 | I36: 113.483 | J36: 141.242 | K36: 180.33 | L36: 232.948 | M36: 167.394 | N36: 111.16 | O36: 66.71 | P36: 6-K FQ3 FY25 (Mar-25 qtr; IFRS) - interim FS / MD&A Ex.99.4 / PR, filed 2025-05; 10-K FY26 (FYE 30-Jun-2026), filed 2026-08-27; 10-Q FQ1 FY26 (Sep-25 qtr), filed 2025-11-06; 10-Q FQ2 FY26 (Dec-25 qtr), filed 2026-02-05; 10-Q FQ3 FY26 (Mar-26 qtr), filed 2026-05-07; 10-K FY25 (FYE 30-Jun-2025; first US GAAP annual; incl. unaudited quarterly table), filed 2025-08-28
A37: I42 | B37: Accumulated impairment of PP&E (EoP) | C37: $M | D37: Reported | E37: n/d | F37: 25.714 | G37: 25.605 | H37: 6.941 | I37: 6.934 | J37: 6.942 | K37: 0.385 | L37: 16.177 | M37: 36.3 | N37: 171.5 | O37: 484.491 | P37: 6-K FQ3 FY24 (Mar-24 qtr; IFRS) - Ex.99.1 results PR / Ex.99.3 interim financial statements, filed 2024-05-15; Form 20-F FY24 (FYE 30-Jun-2024; IFRS), filed 2024-08-28; 6-K FQ1 FY25 (Sep-24 qtr; IFRS) - interim FS + results PR, filed 2024-11; 6-K FQ2 FY25 (Dec-24 qtr; IFRS) - interim FS / MD&A Ex.99.4 / PR, filed 2025-02; 6-K FQ3 FY25 (Mar-25 qtr; IFRS) - interim FS / MD&A Ex.99.4 / PR, filed 2025-05; 10-K FY25 (FYE 30-Jun-2025; first US GAAP annual; incl. unaudited quarterly table), filed 2025-08-28; 10-Q FQ1 FY26 (Sep-25 qtr), filed 2025-11-06; 10-Q FQ2 FY26 (Dec-25 qtr), filed 2026-02-05; 10-Q FQ3 FY26 (Mar-26 qtr), filed 2026-05-07; 10-K FY26 (FYE 30-Jun-2026), filed 2026-08-27
A38: I43 | B38: Total operating data-center capacity, company (all uses; gross MW) | C38: MW | D38: Derived/Reported | E38: n/d | F38: 260 | G38: 260 | H38: 360 | I38: 510 | J38: 660 | K38: 810 | L38: 810 | M38: 810 | N38: n/d | O38: 420 | P38: 6-K FQ3 FY24 (Mar-24 qtr; IFRS) - Ex.99.1 results PR / Ex.99.3 interim financial statements, filed 2024-05-15; Form 20-F FY24 (FYE 30-Jun-2024; IFRS), filed 2024-08-28; FY24 results PR (6-K Ex.99.1, 2024-08-28); 6-K FQ2 FY25 (Dec-24 qtr; IFRS) - interim FS / MD&A Ex.99.4 / PR, filed 2025-02; 6-K FQ3 FY25 (Mar-25 qtr; IFRS) - interim FS / MD&A Ex.99.4 / PR, filed 2025-05; 10-K FY25 (FYE 30-Jun-2025; first US GAAP annual; incl. unaudited quarterly table), filed 2025-08-28; 10-Q FQ1 FY26 (Sep-25 qtr), filed 2025-11-06; 10-Q FQ2 FY26 (Dec-25 qtr), filed 2026-02-05; 10-K FY26 (FYE 30-Jun-2026), filed 2026-08-27 | NOTE: Several values are boilerplate 'as of PR date' (5-7 weeks after quarter-end). Gross/grid basis; AI 40MW basis unstated -> sum is approximate.
A39: I44 | B39: Bitcoin mining capacity (MW), reported | C39: MW | D39: Reported | E39: n/d | F39: n/d | G39: n/d | H39: n/d | I39: n/d | J39: n/d | K39: n/d | L39: n/d | M39: n/d | N39: n/d | O39: 380 | P39: 10-K FY26 (FYE 30-Jun-2026), filed 2026-08-27
A40: I45 | B40: Installed hashrate (EoP) | C40: EH/s | D40: Reported | E40: n/d | F40: 10 | G40: 10 | H40: 21 | I40: 31 | J40: 37 | K40: 50 | L40: 50 | M40: 46 | N40: 38 | O40: 23.2 | P40: 6-K FQ3 FY24 (Mar-24 qtr; IFRS) - Ex.99.1 results PR / Ex.99.3 interim financial statements, filed 2024-05-15; Form 20-F FY24 (FYE 30-Jun-2024; IFRS), filed 2024-08-28; 6-K FQ1 FY25 (Sep-24 qtr; IFRS) - interim FS + results PR, filed 2024-11; 6-K FQ2 FY25 (Dec-24 qtr; IFRS) - interim FS / MD&A Ex.99.4 / PR, filed 2025-02; 6-K FQ3 FY25 (Mar-25 qtr; IFRS) - interim FS / MD&A Ex.99.4 / PR, filed 2025-05; 10-K FY25 (FYE 30-Jun-2025; first US GAAP annual; incl. unaudited quarterly table), filed 2025-08-28; 10-Q FQ1 FY26 (Sep-25 qtr), filed 2025-11-06; 10-Q FQ2 FY26 (Dec-25 qtr), filed 2026-02-05; 10-Q FQ3 FY26 (Mar-26 qtr), filed 2026-05-07; 10-K FY26 (FYE 30-Jun-2026), filed 2026-08-27
...

Sheet Debt_Facilities
A1: Debt by facility - IREN (IREN) - AI Cloud perimeter. Principal ($M) and effective interest rate (%) as printed in each period-end debt table. Excludes leases. Weighted rates exclude facilities without a disclosed rate from the denominator.
A2: Effective rates as printed in the FY26 10-K debt note (Note 23) and FY26 10-Qs; for the 2029/2030 converts the same instrument-level effective rate is applied to earlier snapshots (Dec-24-Sep-25). Converts were partly repurchased in Dec-25 (2030: 440->212.3; 2029: 550->233.4). 'Other debt' has no disclosed rate and is excluded from weighted-rate denominators. Mar-24-Sep-24: no debt outstanding (FY24 contractual interest nil).
A4: Facility | B4: Category | C4: Mar-24 principal | D4: Mar-24 eff. rate % | E4: Jun-24 principal | F4: Jun-24 eff. rate % | G4: Sep-24 principal | H4: Sep-24 eff. rate % | I4: Dec-24 principal | J4: Dec-24 eff. rate % | K4: Mar-25 principal | L4: Mar-25 eff. rate % | M4: Jun-25 principal | N4: Jun-25 eff. rate % | O4: Sep-25 principal | P4: Sep-25 eff. rate % | Q4: Dec-25 principal | R4: Dec-25 eff. rate % | S4: Mar-26 principal | T4: Mar-26 eff. rate % | U4: Jun-26 principal | V4: Jun-26 eff. rate %
A5: 3.25% convertible senior notes due 2030 (issued Dec-24) | B5: Converts | I5: 440 | J5: 3.87 | K5: 440 | L5: 3.87 | M5: 440 | N5: 3.87 | O5: 440 | P5: 3.87 | Q5: 212.31 | R5: 3.87 | S5: 212.31 | T5: 3.87 | U5: 212.31 | V5: 3.87
A6: 3.50% convertible senior notes due 2029 (issued Jun-25) | B6: Converts | M6: 550 | N6: 4.22 | O6: 550 | P6: 4.22 | Q6: 233.389 | R6: 4.22 | S6: 233.389 | T6: 4.22 | U6: 233.389 | V6: 4.22
A7: 0.00% convertible senior notes due 2031 (issued Dec-25) | B7: Converts | Q7: 1000 | R7: 0.37 | S7: 1000 | T7: 0.37 | U7: 1000 | V7: 0.37
A8: 0.25% convertible senior notes due 2032 (issued Dec-25) | B8: Converts | Q8: 1150 | R8: 0.45 | S8: 1150 | T8: 0.45 | U8: 1150 | V8: 0.45
A9: 1.00% convertible senior notes due Jun-2033 (issued Dec-25) | B9: Converts | Q9: 1150 | R9: 1.18 | S9: 1150 | T9: 1.18 | U9: 1150 | V9: 1.18
A10: 1.00% convertible senior notes due Dec-2033 (issued FY26 H2) | B10: Converts | U10: 3000 | V10: 1.18
A11: GPU delayed-draw term loan (non-recourse, SOFR+2.25%; $1,545M facility) | B11: DDTL | U11: 413 | V11: 7.12
A12: USPP senior secured notes (5.96% coupon; $2,100M programme) | B12: Senior notes | U12: 525 | V12: 7.05
A13: Other debt (various) | B13: Other term loans | U13: 21.95
A15: Total principal | C15: =SUM(C5:C13) -> 0 | E15: =SUM(E5:E13) -> 0 | G15: =SUM(G5:G13) -> 0 | I15: =SUM(I5:I13) -> 440 | K15: =SUM(K5:K13) -> 440 | M15: =SUM(M5:M13) -> 990 | O15: =SUM(O5:O13) -> 990 | Q15: =SUM(Q5:Q13) -> 3745.699 | S15: =SUM(S5:S13) -> 3745.699 | U15: =SUM(U5:U13) -> 7705.649
A16: Check vs Inputs I23 (total debt principal) | C16: =C15-Inputs!F26 -> 0 | E16: =E15-Inputs!G26 -> 0 | G16: =G15-Inputs!H26 -> 0 | I16: =I15-Inputs!I26 -> 0 | K16: =K15-Inputs!J26 -> 0 | M16: =M15-Inputs!K26 -> 0 | O16: =O15-Inputs!L26 -> 0 | Q16: =Q15-Inputs!M26 -> 0 | S16: =S15-Inputs!N26 -> 0 | U16: =U15-Inputs!O26 -> 0
A17: WEIGHTED EFFECTIVE COST OF DEBT (principal-weighted, facilities with disclosed rate) | D17: =IFERROR(SUMPRODUCT(C5:C13,D5:D13)/SUMPRODUCT((D5:D13<>"")*C5:C13),"n/d") -> n/d | F17: =IFERROR(SUMPRODUCT(E5:E13,F5:F13)/SUMPRODUCT((F5:F13<>"")*E5:E13),"n/d") -> n/d | H17: =IFERROR(SUMPRODUCT(G5:G13,H5:H13)/SUMPRODUCT((H5:H13<>"")*G5:G13),"n/d") -> n/d | J17: =IFERROR(SUMPRODUCT(I5:I13,J5:J13)/SUMPRODUCT((J5:J13<>"")*I5:I13),"n/d") -> 3.87 | L17: =IFERROR(SUMPRODUCT(K5:K13,L5:L13)/SUMPRODUCT((L5:L13<>"")*K5:K13),"n/d") -> 3.87 | N17: =IFERROR(SUMPRODUCT(M5:M13,N5:N13)/SUMPRODUCT((N5:N13<>"")*M5:M13),"n/d") -> 4.0644444 | P17: =IFERROR(SUMPRODUCT(O5:O13,P5:P13)/SUMPRODUCT((P5:P13<>"")*O5:O13),"n/d") -> 4.0644444 | R17: =IFERROR(SUMPRODUCT(Q5:Q13,R5:R13)/SUMPRODUCT((R5:R13<>"")*Q5:Q13),"n/d") -> 1.0815181 | T17: =IFERROR(SUMPRODUCT(S5:S13,T5:T13)/SUMPRODUCT((T5:T13<>"")*S5:S13),"n/d") -> 1.0815181 | V17: =IFERROR(SUMPRODUCT(U5:U13,V5:V13)/SUMPRODUCT((V5:V13<>"")*U5:U13),"n/d") -> 1.8523437
A18: DDTL: principal / weighted eff. rate | C18: =SUMIF($B$5:$B$13,"DDTL",C5:C13) -> 0 | D18: =IFERROR(SUMPRODUCT(($B$5:$B$13="DDTL")*C5:C13*D5:D13)/SUMPRODUCT(($B$5:$B$13="DDTL")*(D5:D13<>"")*C5:C13),"n/d") -> n/d | E18: =SUMIF($B$5:$B$13,"DDTL",E5:E13) -> 0 | F18: =IFERROR(SUMPRODUCT(($B$5:$B$13="DDTL")*E5:E13*F5:F13)/SUMPRODUCT(($B$5:$B$13="DDTL")*(F5:F13<>"")*E5:E13),"n/d") -> n/d | G18: =SUMIF($B$5:$B$13,"DDTL",G5:G13) -> 0 | H18: =IFERROR(SUMPRODUCT(($B$5:$B$13="DDTL")*G5:G13*H5:H13)/SUMPRODUCT(($B$5:$B$13="DDTL")*(H5:H13<>"")*G5:G13),"n/d") -> n/d | I18: =SUMIF($B$5:$B$13,"DDTL",I5:I13) -> 0 | J18: =IFERROR(SUMPRODUCT(($B$5:$B$13="DDTL")*I5:I13*J5:J13)/SUMPRODUCT(($B$5:$B$13="DDTL")*(J5:J13<>"")*I5:I13),"n/d") -> n/d | K18: =SUMIF($B$5:$B$13,"DDTL",K5:K13) -> 0 | L18: =IFERROR(SUMPRODUCT(($B$5:$B$13="DDTL")*K5:K13*L5:L13)/SUMPRODUCT(($B$5:$B$13="DDTL")*(L5:L13<>"")*K5:K13),"n/d") -> n/d | M18: =SUMIF($B$5:$B$13,"DDTL",M5:M13) -> 0 | N18: =IFERROR(SUMPRODUCT(($B$5:$B$13="DDTL")*M5:M13*N5:N13)/SUMPRODUCT(($B$5:$B$13="DDTL")*(N5:N13<>"")*M5:M13),"n/d") -> n/d | O18: =SUMIF($B$5:$B$13,"DDTL",O5:O13) -> 0 | P18: =IFERROR(SUMPRODUCT(($B$5:$B$13="DDTL")*O5:O13*P5:P13)/SUMPRODUCT(($B$5:$B$13="DDTL")*(P5:P13<>"")*O5:O13),"n/d") -> n/d | Q18: =SUMIF($B$5:$B$13,"DDTL",Q5:Q13) -> 0 | R18: =IFERROR(SUMPRODUCT(($B$5:$B$13="DDTL")*Q5:Q13*R5:R13)/SUMPRODUCT(($B$5:$B$13="DDTL")*(R5:R13<>"")*Q5:Q13),"n/d") -> n/d | S18: =SUMIF($B$5:$B$13,"DDTL",S5:S13) -> 0 | T18: =IFERROR(SUMPRODUCT(($B$5:$B$13="DDTL")*S5:S13*T5:T13)/SUMPRODUCT(($B$5:$B$13="DDTL")*(T5:T13<>"")*S5:S13),"n/d") -> n/d | U18: =SUMIF($B$5:$B$13,"DDTL",U5:U13) -> 413 | V18: =IFERROR(SUMPRODUCT(($B$5:$B$13="DDTL")*U5:U13*V5:V13)/SUMPRODUCT(($B$5:$B$13="DDTL")*(V5:V13<>"")*U5:U13),"n/d") -> 7.12
A19: Senior notes: principal / weighted eff. rate | C19: =SUMIF($B$5:$B$13,"Senior notes",C5:C13) -> 0 | D19: =IFERROR(SUMPRODUCT(($B$5:$B$13="Senior notes")*C5:C13*D5:D13)/SUMPRODUCT(($B$5:$B$13="Senior notes")*(D5:D13<>"")*C5:C13),"n/d") -> n/d | E19: =SUMIF($B$5:$B$13,"Senior notes",E5:E13) -> 0 | F19: =IFERROR(SUMPRODUCT(($B$5:$B$13="Senior notes")*E5:E13*F5:F13)/SUMPRODUCT(($B$5:$B$13="Senior notes")*(F5:F13<>"")*E5:E13),"n/d") -> n/d | G19: =SUMIF($B$5:$B$13,"Senior notes",G5:G13) -> 0 | H19: =IFERROR(SUMPRODUCT(($B$5:$B$13="Senior notes")*G5:G13*H5:H13)/SUMPRODUCT(($B$5:$B$13="Senior notes")*(H5:H13<>"")*G5:G13),"n/d") -> n/d | I19: =SUMIF($B$5:$B$13,"Senior notes",I5:I13) -> 0 | J19: =IFERROR(SUMPRODUCT(($B$5:$B$13="Senior notes")*I5:I13*J5:J13)/SUMPRODUCT(($B$5:$B$13="Senior notes")*(J5:J13<>"")*I5:I13),"n/d") -> n/d | K19: =SUMIF($B$5:$B$13,"Senior notes",K5:K13) -> 0 | L19: =IFERROR(SUMPRODUCT(($B$5:$B$13="Senior notes")*K5:K13*L5:L13)/SUMPRODUCT(($B$5:$B$13="Senior notes")*(L5:L13<>"")*K5:K13),"n/d") -> n/d | M19: =SUMIF($B$5:$B$13,"Senior notes",M5:M13) -> 0 | N19: =IFERROR(SUMPRODUCT(($B$5:$B$13="Senior notes")*M5:M13*N5:N13)/SUMPRODUCT(($B$5:$B$13="Senior notes")*(N5:N13<>"")*M5:M13),"n/d") -> n/d | O19: =SUMIF($B$5:$B$13,"Senior notes",O5:O13) -> 0 | P19: =IFERROR(SUMPRODUCT(($B$5:$B$13="Senior notes")*O5:O13*P5:P13)/SUMPRODUCT(($B$5:$B$13="Senior notes")*(P5:P13<>"")*O5:O13),"n/d") -> n/d | Q19: =SUMIF($B$5:$B$13,"Senior notes",Q5:Q13) -> 0 | R19: =IFERROR(SUMPRODUCT(($B$5:$B$13="Senior notes")*Q5:Q13*R5:R13)/SUMPRODUCT(($B$5:$B$13="Senior notes")*(R5:R13<>"")*Q5:Q13),"n/d") -> n/d | S19: =SUMIF($B$5:$B$13,"Senior notes",S5:S13) -> 0 | T19: =IFERROR(SUMPRODUCT(($B$5:$B$13="Senior notes")*S5:S13*T5:T13)/SUMPRODUCT(($B$5:$B$13="Senior notes")*(T5:T13<>"")*S5:S13),"n/d") -> n/d | U19: =SUMIF($B$5:$B$13,"Senior notes",U5:U13) -> 525 | V19: =IFERROR(SUMPRODUCT(($B$5:$B$13="Senior notes")*U5:U13*V5:V13)/SUMPRODUCT(($B$5:$B$13="Senior notes")*(V5:V13<>"")*U5:U13),"n/d") -> 7.05
A20: Converts: principal / weighted eff. rate | C20: =SUMIF($B$5:$B$13,"Converts",C5:C13) -> 0 | D20: =IFERROR(SUMPRODUCT(($B$5:$B$13="Converts")*C5:C13*D5:D13)/SUMPRODUCT(($B$5:$B$13="Converts")*(D5:D13<>"")*C5:C13),"n/d") -> n/d | E20: =SUMIF($B$5:$B$13,"Converts",E5:E13) -> 0 | F20: =IFERROR(SUMPRODUCT(($B$5:$B$13="Converts")*E5:E13*F5:F13)/SUMPRODUCT(($B$5:$B$13="Converts")*(F5:F13<>"")*E5:E13),"n/d") -> n/d | G20: =SUMIF($B$5:$B$13,"Converts",G5:G13) -> 0 | H20: =IFERROR(SUMPRODUCT(($B$5:$B$13="Converts")*G5:G13*H5:H13)/SUMPRODUCT(($B$5:$B$13="Converts")*(H5:H13<>"")*G5:G13),"n/d") -> n/d | I20: =SUMIF($B$5:$B$13,"Converts",I5:I13) -> 440 | J20: =IFERROR(SUMPRODUCT(($B$5:$B$13="Converts")*I5:I13*J5:J13)/SUMPRODUCT(($B$5:$B$13="Converts")*(J5:J13<>"")*I5:I13),"n/d") -> 3.87 | K20: =SUMIF($B$5:$B$13,"Converts",K5:K13) -> 440 | L20: =IFERROR(SUMPRODUCT(($B$5:$B$13="Converts")*K5:K13*L5:L13)/SUMPRODUCT(($B$5:$B$13="Converts")*(L5:L13<>"")*K5:K13),"n/d") -> 3.87 | M20: =SUMIF($B$5:$B$13,"Converts",M5:M13) -> 990 | N20: =IFERROR(SUMPRODUCT(($B$5:$B$13="Converts")*M5:M13*N5:N13)/SUMPRODUCT(($B$5:$B$13="Converts")*(N5:N13<>"")*M5:M13),"n/d") -> 4.0644444 | O20: =SUMIF($B$5:$B$13,"Converts",O5:O13) -> 990 | P20: =IFERROR(SUMPRODUCT(($B$5:$B$13="Converts")*O5:O13*P5:P13)/SUMPRODUCT(($B$5:$B$13="Converts")*(P5:P13<>"")*O5:O13),"n/d") -> 4.0644444 | Q20: =SUMIF($B$5:$B$13,"Converts",Q5:Q13) -> 3745.699 | R20: =IFERROR(SUMPRODUCT(($B$5:$B$13="Converts")*Q5:Q13*R5:R13)/SUMPRODUCT(($B$5:$B$13="Converts")*(R5:R13<>"")*Q5:Q13),"n/d") -> 1.0815181 | S20: =SUMIF($B$5:$B$13,"Converts",S5:S13) -> 3745.699 | T20: =IFERROR(SUMPRODUCT(($B$5:$B$13="Converts")*S5:S13*T5:T13)/SUMPRODUCT(($B$5:$B$13="Converts")*(T5:T13<>"")*S5:S13),"n/d") -> 1.0815181 | U20: =SUMIF($B$5:$B$13,"Converts",U5:U13) -> 6745.699 | V20: =IFERROR(SUMPRODUCT(($B$5:$B$13="Converts")*U5:U13*V5:V13)/SUMPRODUCT(($B$5:$B$13="Converts")*(V5:V13<>"")*U5:U13),"n/d") -> 1.1253157
A21: OEM / vendor financing: principal / weighted eff. rate | C21: =SUMIF($B$5:$B$13,"OEM / vendor financing",C5:C13) -> 0 | D21: =IFERROR(SUMPRODUCT(($B$5:$B$13="OEM / vendor financing")*C5:C13*D5:D13)/SUMPRODUCT(($B$5:$B$13="OEM / vendor financing")*(D5:D13<>"")*C5:C13),"n/d") -> n/d | E21: =SUMIF($B$5:$B$13,"OEM / vendor financing",E5:E13) -> 0 | F21: =IFERROR(SUMPRODUCT(($B$5:$B$13="OEM / vendor financing")*E5:E13*F5:F13)/SUMPRODUCT(($B$5:$B$13="OEM / vendor financing")*(F5:F13<>"")*E5:E13),"n/d") -> n/d | G21: =SUMIF($B$5:$B$13,"OEM / vendor financing",G5:G13) -> 0 | H21: =IFERROR(SUMPRODUCT(($B$5:$B$13="OEM / vendor financing")*G5:G13*H5:H13)/SUMPRODUCT(($B$5:$B$13="OEM / vendor financing")*(H5:H13<>"")*G5:G13),"n/d") -> n/d | I21: =SUMIF($B$5:$B$13,"OEM / vendor financing",I5:I13) -> 0 | J21: =IFERROR(SUMPRODUCT(($B$5:$B$13="OEM / vendor financing")*I5:I13*J5:J13)/SUMPRODUCT(($B$5:$B$13="OEM / vendor financing")*(J5:J13<>"")*I5:I13),"n/d") -> n/d | K21: =SUMIF($B$5:$B$13,"OEM / vendor financing",K5:K13) -> 0 | L21: =IFERROR(SUMPRODUCT(($B$5:$B$13="OEM / vendor financing")*K5:K13*L5:L13)/SUMPRODUCT(($B$5:$B$13="OEM / vendor financing")*(L5:L13<>"")*K5:K13),"n/d") -> n/d | M21: =SUMIF($B$5:$B$13,"OEM / vendor financing",M5:M13) -> 0 | N21: =IFERROR(SUMPRODUCT(($B$5:$B$13="OEM / vendor financing")*M5:M13*N5:N13)/SUMPRODUCT(($B$5:$B$13="OEM / vendor financing")*(N5:N13<>"")*M5:M13),"n/d") -> n/d | O21: =SUMIF($B$5:$B$13,"OEM / vendor financing",O5:O13) -> 0 | P21: =IFERROR(SUMPRODUCT(($B$5:$B$13="OEM / vendor financing")*O5:O13*P5:P13)/SUMPRODUCT(($B$5:$B$13="OEM / vendor financing")*(P5:P13<>"")*O5:O13),"n/d") -> n/d | Q21: =SUMIF($B$5:$B$13,"OEM / vendor financing",Q5:Q13) -> 0 | R21: =IFERROR(SUMPRODUCT(($B$5:$B$13="OEM / vendor financing")*Q5:Q13*R5:R13)/SUMPRODUCT(($B$5:$B$13="OEM / vendor financing")*(R5:R13<>"")*Q5:Q13),"n/d") -> n/d | S21: =SUMIF($B$5:$B$13,"OEM / vendor financing",S5:S13) -> 0 | T21: =IFERROR(SUMPRODUCT(($B$5:$B$13="OEM / vendor financing")*S5:S13*T5:T13)/SUMPRODUCT(($B$5:$B$13="OEM / vendor financing")*(T5:T13<>"")*S5:S13),"n/d") -> n/d | U21: =SUMIF($B$5:$B$13,"OEM / vendor financing",U5:U13) -> 0 | V21: =IFERROR(SUMPRODUCT(($B$5:$B$13="OEM / vendor financing")*U5:U13*V5:V13)/SUMPRODUCT(($B$5:$B$13="OEM / vendor financing")*(V5:V13<>"")*U5:U13),"n/d") -> n/d
A22: Revolver: principal / weighted eff. rate | C22: =SUMIF($B$5:$B$13,"Revolver",C5:C13) -> 0 | D22: =IFERROR(SUMPRODUCT(($B$5:$B$13="Revolver")*C5:C13*D5:D13)/SUMPRODUCT(($B$5:$B$13="Revolver")*(D5:D13<>"")*C5:C13),"n/d") -> n/d | E22: =SUMIF($B$5:$B$13,"Revolver",E5:E13) -> 0 | F22: =IFERROR(SUMPRODUCT(($B$5:$B$13="Revolver")*E5:E13*F5:F13)/SUMPRODUCT(($B$5:$B$13="Revolver")*(F5:F13<>"")*E5:E13),"n/d") -> n/d | G22: =SUMIF($B$5:$B$13,"Revolver",G5:G13) -> 0 | H22: =IFERROR(SUMPRODUCT(($B$5:$B$13="Revolver")*G5:G13*H5:H13)/SUMPRODUCT(($B$5:$B$13="Revolver")*(H5:H13<>"")*G5:G13),"n/d") -> n/d | I22: =SUMIF($B$5:$B$13,"Revolver",I5:I13) -> 0 | J22: =IFERROR(SUMPRODUCT(($B$5:$B$13="Revolver")*I5:I13*J5:J13)/SUMPRODUCT(($B$5:$B$13="Revolver")*(J5:J13<>"")*I5:I13),"n/d") -> n/d | K22: =SUMIF($B$5:$B$13,"Revolver",K5:K13) -> 0 | L22: =IFERROR(SUMPRODUCT(($B$5:$B$13="Revolver")*K5:K13*L5:L13)/SUMPRODUCT(($B$5:$B$13="Revolver")*(L5:L13<>"")*K5:K13),"n/d") -> n/d | M22: =SUMIF($B$5:$B$13,"Revolver",M5:M13) -> 0 | N22: =IFERROR(SUMPRODUCT(($B$5:$B$13="Revolver")*M5:M13*N5:N13)/SUMPRODUCT(($B$5:$B$13="Revolver")*(N5:N13<>"")*M5:M13),"n/d") -> n/d | O22: =SUMIF($B$5:$B$13,"Revolver",O5:O13) -> 0 | P22: =IFERROR(SUMPRODUCT(($B$5:$B$13="Revolver")*O5:O13*P5:P13)/SUMPRODUCT(($B$5:$B$13="Revolver")*(P5:P13<>"")*O5:O13),"n/d") -> n/d | Q22: =SUMIF($B$5:$B$13,"Revolver",Q5:Q13) -> 0 | R22: =IFERROR(SUMPRODUCT(($B$5:$B$13="Revolver")*Q5:Q13*R5:R13)/SUMPRODUCT(($B$5:$B$13="Revolver")*(R5:R13<>"")*Q5:Q13),"n/d") -> n/d | S22: =SUMIF($B$5:$B$13,"Revolver",S5:S13) -> 0 | T22: =IFERROR(SUMPRODUCT(($B$5:$B$13="Revolver")*S5:S13*T5:T13)/SUMPRODUCT(($B$5:$B$13="Revolver")*(T5:T13<>"")*S5:S13),"n/d") -> n/d | U22: =SUMIF($B$5:$B$13,"Revolver",U5:U13) -> 0 | V22: =IFERROR(SUMPRODUCT(($B$5:$B$13="Revolver")*U5:U13*V5:V13)/SUMPRODUCT(($B$5:$B$13="Revolver")*(V5:V13<>"")*U5:U13),"n/d") -> n/d
A23: Other term loans: principal / weighted eff. rate | C23: =SUMIF($B$5:$B$13,"Other term loans",C5:C13) -> 0 | D23: =IFERROR(SUMPRODUCT(($B$5:$B$13="Other term loans")*C5:C13*D5:D13)/SUMPRODUCT(($B$5:$B$13="Other term loans")*(D5:D13<>"")*C5:C13),"n/d") -> n/d | E23: =SUMIF($B$5:$B$13,"Other term loans",E5:E13) -> 0 | F23: =IFERROR(SUMPRODUCT(($B$5:$B$13="Other term loans")*E5:E13*F5:F13)/SUMPRODUCT(($B$5:$B$13="Other term loans")*(F5:F13<>"")*E5:E13),"n/d") -> n/d | G23: =SUMIF($B$5:$B$13,"Other term loans",G5:G13) -> 0 | H23: =IFERROR(SUMPRODUCT(($B$5:$B$13="Other term loans")*G5:G13*H5:H13)/SUMPRODUCT(($B$5:$B$13="Other term loans")*(H5:H13<>"")*G5:G13),"n/d") -> n/d | I23: =SUMIF($B$5:$B$13,"Other term loans",I5:I13) -> 0 | J23: =IFERROR(SUMPRODUCT(($B$5:$B$13="Other term loans")*I5:I13*J5:J13)/SUMPRODUCT(($B$5:$B$13="Other term loans")*(J5:J13<>"")*I5:I13),"n/d") -> n/d | K23: =SUMIF($B$5:$B$13,"Other term loans",K5:K13) -> 0 | L23: =IFERROR(SUMPRODUCT(($B$5:$B$13="Other term loans")*K5:K13*L5:L13)/SUMPRODUCT(($B$5:$B$13="Other term loans")*(L5:L13<>"")*K5:K13),"n/d") -> n/d | M23: =SUMIF($B$5:$B$13,"Other term loans",M5:M13) -> 0 | N23: =IFERROR(SUMPRODUCT(($B$5:$B$13="Other term loans")*M5:M13*N5:N13)/SUMPRODUCT(($B$5:$B$13="Other term loans")*(N5:N13<>"")*M5:M13),"n/d") -> n/d | O23: =SUMIF($B$5:$B$13,"Other term loans",O5:O13) -> 0 | P23: =IFERROR(SUMPRODUCT(($B$5:$B$13="Other term loans")*O5:O13*P5:P13)/SUMPRODUCT(($B$5:$B$13="Other term loans")*(P5:P13<>"")*O5:O13),"n/d") -> n/d | Q23: =SUMIF($B$5:$B$13,"Other term loans",Q5:Q13) -> 0 | R23: =IFERROR(SUMPRODUCT(($B$5:$B$13="Other term loans")*Q5:Q13*R5:R13)/SUMPRODUCT(($B$5:$B$13="Other term loans")*(R5:R13<>"")*Q5:Q13),"n/d") -> n/d | S23: =SUMIF($B$5:$B$13,"Other term loans",S5:S13) -> 0 | T23: =IFERROR(SUMPRODUCT(($B$5:$B$13="Other term loans")*S5:S13*T5:T13)/SUMPRODUCT(($B$5:$B$13="Other term loans")*(T5:T13<>"")*S5:S13),"n/d") -> n/d | U23: =SUMIF($B$5:$B$13,"Other term loans",U5:U13) -> 21.95 | V23: =IFERROR(SUMPRODUCT(($B$5:$B$13="Other term loans")*U5:U13*V5:V13)/SUMPRODUCT(($B$5:$B$13="Other term loans")*(V5:V13<>"")*U5:U13),"n/d") -> n/d
A24: Share of principal: DDTL % | D24: =IFERROR(C18/C15*100,"n/d") -> n/d | F24: =IFERROR(E18/E15*100,"n/d") -> n/d | H24: =IFERROR(G18/G15*100,"n/d") -> n/d | J24: =IFERROR(I18/I15*100,"n/d") -> 0 | L24: =IFERROR(K18/K15*100,"n/d") -> 0 | N24: =IFERROR(M18/M15*100,"n/d") -> 0 | P24: =IFERROR(O18/O15*100,"n/d") -> 0 | R24: =IFERROR(Q18/Q15*100,"n/d") -> 0 | T24: =IFERROR(S18/S15*100,"n/d") -> 0 | V24: =IFERROR(U18/U15*100,"n/d") -> 5.3597043
A26: POST-PERIOD (not in Jun-26): Aug-2026 $2.4B GPU financing (Blue Owl / PIMCO) at 9.0% fixed (FY26 PR / 8-K). Marginal secured GPU cost ~7-9% vs 1.9% blended (converts-heavy).
A27: Finance leases (GPU leases, liability $243.8M at Jun-26) excluded, consistent with CRWV/Nebius template.

Sheet Sources
A1: Input ID | B1: Item | C1: Period | D1: Value | E1: Tag | F1: Document | G1: Section / page / formula | H1: URL
A2: I01 | B2: AI Cloud Services revenue (segment) | C2: Q1'24 | D2: 0.567 | E2: Reported | F2: 6-K FQ3 FY25 (Mar-25 qtr; IFRS) - interim FS / MD&A Ex.99.4 / PR, filed 2025-05 | G2: FQ3 FY25 6-K Ex.99.4 MD&A table, 3m to 31-Mar-24 comparative 'AI cloud service revenue 567' (IFRS) | H2: https://www.sec.gov/Archives/edgar/data/1878848/000187884825000043/iren-20250331_d2.htm
A3: I01 | B3: AI Cloud Services revenue (segment) | C3: Q2'24 | D3: 2.538 | E3: Derived | F3: 10-K FY26 (FYE 30-Jun-2026), filed 2026-08-27 | G3: calc: FY24 3.105 (FY26 10-K segment note, US GAAP recast) - 9M FY24 0.567 (IFRS, FQ3 FY25 MD&A) -> mixed basis | H3: https://www.sec.gov/Archives/edgar/data/1878848/000187884826000052/iren-20260630.htm
A4: I01 | B4: AI Cloud Services revenue (segment) | C4: Q3'24 | D4: 3.189 | E4: Reported | F4: 10-Q FQ1 FY26 (Sep-25 qtr), filed 2025-11-06 | G4: Q1 FY26 10-Q segment note comparative (3m Sep-24) | H4: https://www.sec.gov/Archives/edgar/data/1878848/000187884825000081/iren-20250930.htm
A5: I01 | B5: AI Cloud Services revenue (segment) | C5: Q4'24 | D5: 2.661 | E5: Reported | F5: 10-Q FQ2 FY26 (Dec-25 qtr), filed 2026-02-05 | G5: Q2 FY26 10-Q comparative (3m Dec-24) | H5: https://www.sec.gov/Archives/edgar/data/1878848/000187884826000015/iren-20251231.htm
A6: I01 | B6: AI Cloud Services revenue (segment) | C6: Q1'25 | D6: 3.581 | E6: Reported | F6: 10-Q FQ3 FY26 (Mar-26 qtr), filed 2026-05-07 | G6: Q3 FY26 10-Q comparative (3m Mar-25) | H6: https://www.sec.gov/Archives/edgar/data/1878848/000187884826000026/iren-20260331.htm
A7: I01 | B7: AI Cloud Services revenue (segment) | C7: Q2'25 | D7: 6.963 | E7: Reported | F7: 10-K FY25 (FYE 30-Jun-2025; first US GAAP annual; incl. unaudited quarterly table), filed 2025-08-28 | G7: FY25 10-K unaudited quarterly table (Jun-25 qtr 6,963) | H7: https://www.sec.gov/Archives/edgar/data/1878848/000187884825000063/iren-20250630.htm
A8: I01 | B8: AI Cloud Services revenue (segment) | C8: Q3'25 | D8: 7.347 | E8: Reported | F8: 10-Q FQ1 FY26 (Sep-25 qtr), filed 2025-11-06 | G8: Q1 FY26 10-Q segment note | H8: https://www.sec.gov/Archives/edgar/data/1878848/000187884825000081/iren-20250930.htm
A9: I01 | B9: AI Cloud Services revenue (segment) | C9: Q4'25 | D9: 17.298 | E9: Reported | F9: 10-Q FQ2 FY26 (Dec-25 qtr), filed 2026-02-05 | G9: Q2 FY26 10-Q segment note | H9: https://www.sec.gov/Archives/edgar/data/1878848/000187884826000015/iren-20251231.htm
A10: I01 | B10: AI Cloud Services revenue (segment) | C10: Q1'26 | D10: 33.635 | E10: Reported | F10: 10-Q FQ3 FY26 (Mar-26 qtr), filed 2026-05-07 | G10: Q3 FY26 10-Q segment note | H10: https://www.sec.gov/Archives/edgar/data/1878848/000187884826000026/iren-20260331.htm
A11: I01 | B11: AI Cloud Services revenue (segment) | C11: Q2'26 | D11: 70.515 | E11: Derived | F11: 10-K FY26 (FYE 30-Jun-2026), filed 2026-08-27 | G11: calc: FY26 128.795 (FY26 10-K segment note) - 9M 58.280 (Q3 FY26 10-Q) | H11: https://www.sec.gov/Archives/edgar/data/1878848/000187884826000052/iren-20260630.htm
A12: I03 | B12: Depreciation & amortization (company-wide, P&L) | C12: Q1'24 | D12: 8.692 | E12: Reported | F12: 6-K FQ3 FY24 (Mar-24 qtr; IFRS) - Ex.99.1 results PR / Ex.99.3 interim financial statements, filed 2024-05-15 | G12: FQ3 FY24 6-K Ex.99.3 P&L 'Depreciation (8,692)' (IFRS) | H12: https://www.sec.gov/Archives/edgar/data/1878848/000114036124026268/ef20027345_ex99-3.htm
A13: I03 | B13: Depreciation & amortization (company-wide, P&L) | C13: Q2'24 | D13: 26.78 | E13: Derived | F13: Form 20-F FY24 (FYE 30-Jun-2024; IFRS), filed 2024-08-28 | G13: calc: FY24 50.650 (20-F Note 6) - 9M 23.870 (6-K) (IFRS) | H13: https://www.sec.gov/Archives/edgar/data/1878848/000162828024038677/iren-20240630.htm
... A103: I23 | B103: Total debt principal (EoP; excl. finance leases) | C103: Q2'26 | D103: 7705.649 | E103: Reported | F103: 10-K FY26 (FYE 30-Jun-2026), filed 2026-08-27 | G103: Debt note principal (see Debt_Facilities). Excludes GPU finance leases ($243.8M liability at Jun-26). | H103: https://www.sec.gov/Archives/edgar/data/1878848/000187884826000052/iren-20260630.htm
A104: I26 | B104: Days in quarter | C104: Q1'24 | D104: 91 | E104: Reported | F104: calendar | G104: calendar
A105: I26 | B105: Days in quarter | C105: Q2'24 | D105: 91 | E105: Reported | F105: calendar | G105: calendar
A106: I26 | B106: Days in quarter | C106: Q3'24 | D106: 92 | E106: Reported | F106: calendar | G106: calendar
A107: I26 | B107: Days in quarter | C107: Q4'24 | D107: 92 | E107: Reported | F107: calendar | G107: calendar
A108: I26 | B108: Days in quarter | C108: Q1'25 | D108: 90 | E108: Reported | F108: calendar | G108: calendar
A109: I26 | B109: Days in quarter | C109: Q2'25 | D109: 91 | E109: Reported | F109: calendar | G109: calendar
A110: I26 | B110: Days in quarter | C110: Q3'25 | D110: 92 | E110: Reported | F110: calendar | G110: calendar
A111: I26 | B111: Days in quarter | C111: Q4'25 | D111: 92 | E111: Reported | F111: calendar | G111: calendar
A112: I26 | B112: Days in quarter | C112: Q1'26 | D112: 90 | E112: Reported | F112: calendar | G112: calendar
A113: I26 | B113: Days in quarter | C113: Q2'26 | D113: 91 | E113: Reported | F113: calendar | G113: calendar
A114: I28 | B114: Useful life - HPC / GPU hardware | C114: Q1'24 | D114: 5 | E114: Reported | F114: Form 20-F FY24 (FYE 30-Jun-2024; IFRS), filed 2024-08-28 | G114: 20-F FY24: 'HPC hardware is depreciated over 5 years' | H114: https://www.sec.gov/Archives/edgar/data/1878848/000162828024038677/iren-20240630.htm
A115: I28 | B115: Useful life - HPC / GPU hardware | C115: Q2'24 | D115: 5 | E115: Reported | F115: Form 20-F FY24 (FYE 30-Jun-2024; IFRS), filed 2024-08-28 | G115: same | H115: https://www.sec.gov/Archives/edgar/data/1878848/000162828024038677/iren-20240630.htm
A116: I28 | B116: Useful life - HPC / GPU hardware | C116: Q3'24 | D116: 5 | E116: Reported | F116: 10-K FY25 (FYE 30-Jun-2025; first US GAAP annual; incl. unaudited quarterly table), filed 2025-08-28 | G116: 10-K FY25 useful-life table 'HPC hardware 5' | H116: https://www.sec.gov/Archives/edgar/data/1878848/000187884825000063/iren-20250630.htm
A117: I28 | B117: Useful life - HPC / GPU hardware | C117: Q4'24 | D117: 5 | E117: Reported | F117: 10-K FY25 (FYE 30-Jun-2025; first US GAAP annual; incl. unaudited quarterly table), filed 2025-08-28 | G117: 10-K FY25 useful-life table 'HPC hardware 5' | H117: https://www.sec.gov/Archives/edgar/data/1878848/000187884825000063/iren-20250630.htm
A118: I28 | B118: Useful life - HPC / GPU hardware | C118: Q1'25 | D118: 5 | E118: Reported | F118: 10-K FY25 (FYE 30-Jun-2025; first US GAAP annual; incl. unaudited quarterly table), filed 2025-08-28 | G118: 10-K FY25 useful-life table 'HPC hardware 5' | H118: https://www.sec.gov/Archives/edgar/data/1878848/000187884825000063/iren-20250630.htm
A119: I28 | B119: Useful life - HPC / GPU hardware | C119: Q2'25 | D119: 5 | E119: Reported | F119: 10-K FY25 (FYE 30-Jun-2025; first US GAAP annual; incl. unaudited quarterly table), filed 2025-08-28 | G119: 10-K FY25 useful-life table 'HPC hardware 5' | H119: https://www.sec.gov/Archives/edgar/data/1878848/000187884825000063/iren-20250630.htm
A120: I28 | B120: Useful life - HPC / GPU hardware | C120: Q3'25 | D120: 5 | E120: Reported | F120: 10-K FY26 (FYE 30-Jun-2026), filed 2026-08-27 | G120: 10-K FY26 table 'HPC hardware 5' | H120: https://www.sec.gov/Archives/edgar/data/1878848/000187884826000052/iren-20260630.htm
A121: I28 | B121: Useful life - HPC / GPU hardware | C121: Q4'25 | D121: 5 | E121: Reported | F121: 10-K FY26 (FYE 30-Jun-2026), filed 2026-08-27 | G121: 10-K FY26 table 'HPC hardware 5' | H121: https://www.sec.gov/Archives/edgar/data/1878848/000187884826000052/iren-20260630.htm
A122: I28 | B122: Useful life - HPC / GPU hardware | C122: Q1'26 | D122: 5 | E122: Reported | F122: 10-K FY26 (FYE 30-Jun-2026), filed 2026-08-27 | G122: 10-K FY26 table 'HPC hardware 5' | H122: https://www.sec.gov/Archives/edgar/data/1878848/000187884826000052/iren-20260630.htm
A123: I28 | B123: Useful life - HPC / GPU hardware | C123: Q2'26 | D123: 5 | E123: Reported | F123: 10-K FY26 (FYE 30-Jun-2026), filed 2026-08-27 | G123: 10-K FY26 table 'HPC hardware 5' | H123: https://www.sec.gov/Archives/edgar/data/1878848/000187884826000052/iren-20260630.htm
A124: I30 | B124: RPO % expected to be recognized within 12 months | C124: Q3'25 | D124: 47.9 | E124: Derived | F124: 10-Q FQ1 FY26 (Sep-25 qtr), filed 2025-11-06 | G124: calc: 93.363/195.027 | H124: https://www.sec.gov/Archives/edgar/data/1878848/000187884825000081/iren-20250930.htm
