Workbook

Sheet Assumptions
A1: Input | B1: Value | C1: Unit | D1: Tag | E1: Source / note
A2: Lives
A3: Life scenario A (yrs) | B3: 4 | C3: yrs | D3: Reported (pre-2026 policy) | E3: https://www.sec.gov/Archives/edgar/data/1513845/000110465926052948/nbis-20251231x20f.htm
A4: Life scenario B (yrs) - Nebius policy from 1/1/26 | B4: 5 | C4: yrs | D4: Reported | E4: https://www.sec.gov/Archives/edgar/data/1513845/000110465926094844/nbis-20260812xex99d2.htm Note 1
A5: Life scenario C (yrs) | B5: 6 | C5: yrs | D5: Reported (peer policy: CRWV/GOOGL/ORCL) | E5: v1 Peers sheet
A6: Shell & power (owned) / colo fit-out life | B6: 18 | C6: yrs | D6: Estimated (user assumption) | E6: User instruction 2026-10-04
A7: Existing 6/30 non-server PP&E blended life | B7: 12 | C7: yrs | D7: Estimated | E7: As v1
A8: Capex per IT MW by generation ($M) - Capacity's base case
A9: Hopper H100/H200: GPU/server + network/storage per IT MW | B9: 25.9 | C9: $M/IT MW | D9: Estimated (Capacity base) | E9: /workspace/nebius/capacity/gpu_mw_capex.xlsx + .md (team Capacity & Power) CapexPerMW base split
A10: Hopper H100/H200: DC shell + power, owned, per IT MW | B10: 10 | C10: $M/IT MW | D10: Estimated (Capacity base) | E10: /workspace/nebius/capacity/gpu_mw_capex.xlsx + .md (team Capacity & Power)
A11: Hopper H100/H200: colo capex (no shell) per IT MW | B11: 26.9 | C11: $M/IT MW | D11: Estimated (Capacity base) | E11: /workspace/nebius/capacity/gpu_mw_capex.xlsx + .md (team Capacity & Power) 'Colo capex Base'
A12: Hopper H100/H200: owned all-in per IT MW | B12: =$B$9+$B$10 | C12: $M/IT MW | D12: Derived | E12: GPU+net + shell (Capacity: B200 42, GB200 42, GB300 53)
A13: B200 (HGX): GPU/server + network/storage per IT MW | B13: 32.4 | C13: $M/IT MW | D13: Estimated (Capacity base) | E13: /workspace/nebius/capacity/gpu_mw_capex.xlsx + .md (team Capacity & Power) CapexPerMW base split
A14: B200 (HGX): DC shell + power, owned, per IT MW | B14: 10 | C14: $M/IT MW | D14: Estimated (Capacity base) | E14: /workspace/nebius/capacity/gpu_mw_capex.xlsx + .md (team Capacity & Power)
A15: B200 (HGX): colo capex (no shell) per IT MW | B15: 33.4 | C15: $M/IT MW | D15: Estimated (Capacity base) | E15: /workspace/nebius/capacity/gpu_mw_capex.xlsx + .md (team Capacity & Power) 'Colo capex Base'
A16: B200 (HGX): owned all-in per IT MW | B16: =$B$13+$B$14 | C16: $M/IT MW | D16: Derived | E16: GPU+net + shell (Capacity: B200 42, GB200 42, GB300 53)
A17: GB200 NVL72: GPU/server + network/storage per IT MW | B17: 29.2 | C17: $M/IT MW | D17: Estimated (Capacity base) | E17: /workspace/nebius/capacity/gpu_mw_capex.xlsx + .md (team Capacity & Power) CapexPerMW base split
A18: GB200 NVL72: DC shell + power, owned, per IT MW | B18: 12.5 | C18: $M/IT MW | D18: Estimated (Capacity base) | E18: /workspace/nebius/capacity/gpu_mw_capex.xlsx + .md (team Capacity & Power)
A19: GB200 NVL72: colo capex (no shell) per IT MW | B19: 30.2 | C19: $M/IT MW | D19: Estimated (Capacity base) | E19: /workspace/nebius/capacity/gpu_mw_capex.xlsx + .md (team Capacity & Power) 'Colo capex Base'
A20: GB200 NVL72: owned all-in per IT MW | B20: =$B$17+$B$18 | C20: $M/IT MW | D20: Derived | E20: GPU+net + shell (Capacity: B200 42, GB200 42, GB300 53)
A21: B300 (HGX): GPU/server + network/storage per IT MW | B21: 40.1 | C21: $M/IT MW | D21: Estimated (Capacity base) | E21: /workspace/nebius/capacity/gpu_mw_capex.xlsx + .md (team Capacity & Power) CapexPerMW base split
A22: B300 (HGX): DC shell + power, owned, per IT MW | B22: 10 | C22: $M/IT MW | D22: Estimated (Capacity base) | E22: /workspace/nebius/capacity/gpu_mw_capex.xlsx + .md (team Capacity & Power)
A23: B300 (HGX): colo capex (no shell) per IT MW | B23: 41.1 | C23: $M/IT MW | D23: Estimated (Capacity base) | E23: /workspace/nebius/capacity/gpu_mw_capex.xlsx + .md (team Capacity & Power) 'Colo capex Base'
A24: B300 (HGX): owned all-in per IT MW | B24: =$B$21+$B$22 | C24: $M/IT MW | D24: Derived | E24: GPU+net + shell (Capacity: B200 42, GB200 42, GB300 53)
A25: GB300 NVL72: GPU/server + network/storage per IT MW | B25: 40.2 | C25: $M/IT MW | D25: Estimated (Capacity base) | E25: /workspace/nebius/capacity/gpu_mw_capex.xlsx + .md (team Capacity & Power) CapexPerMW base split
A26: GB300 NVL72: DC shell + power, owned, per IT MW | B26: 12.5 | C26: $M/IT MW | D26: Estimated (Capacity base) | E26: /workspace/nebius/capacity/gpu_mw_capex.xlsx + .md (team Capacity & Power)
A27: GB300 NVL72: colo capex (no shell) per IT MW | B27: 41.3 | C27: $M/IT MW | D27: Estimated (Capacity base) | E27: /workspace/nebius/capacity/gpu_mw_capex.xlsx + .md (team Capacity & Power) 'Colo capex Base'
A28: GB300 NVL72: owned all-in per IT MW | B28: =$B$25+$B$26 | C28: $M/IT MW | D28: Derived | E28: GPU+net + shell (Capacity: B200 42, GB200 42, GB300 53)
A29: Vera Rubin NVL72: GPU/server + network/storage per IT MW | B29: 30.3 | C29: $M/IT MW | D29: Estimated (Capacity base) | E29: /workspace/nebius/capacity/gpu_mw_capex.xlsx + .md (team Capacity & Power) CapexPerMW base split
A30: Vera Rubin NVL72: DC shell + power, owned, per IT MW | B30: 12.5 | C30: $M/IT MW | D30: Estimated (Capacity base) | E30: /workspace/nebius/capacity/gpu_mw_capex.xlsx + .md (team Capacity & Power)
A31: Vera Rubin NVL72: colo capex (no shell) per IT MW | B31: 31.3 | C31: $M/IT MW | D31: Estimated (Capacity base) | E31: /workspace/nebius/capacity/gpu_mw_capex.xlsx + .md (team Capacity & Power) 'Colo capex Base'
A32: Vera Rubin NVL72: owned all-in per IT MW | B32: =$B$29+$B$30 | C32: $M/IT MW | D32: Derived | E32: GPU+net + shell (Capacity: B200 42, GB200 42, GB300 53)
A33: Gross (facility) MW per IT MW | B33: 1.25 | C33: x | D33: Derived (Capacity) | E33: Vineland 300 MW gross ~ 230-250 MW IT => 1.2-1.3; Capacity PUE base 1.20-1.30
A34: Nebius ACV/MW basis = gross MW? (1 = gross, 0 = IT) | B34: 1 | C34: flag | D34: Estimated | E34: Microsoft $11.6M/gross MW-yr ~ the '2026 base ~$12M' in Q2 letter => ACV quoted on gross/contracted MW (Capacity). Not stated by Nebius
A35: Opex per MW
A36: Power cost | B36: 139 | C36: $/MWh | D36: Estimated (Capacity range 93-185, midpoint) | E36: Team inputs relayed 2026-10-04 18:20 ET (Capacity physical evidence / Filings); Bloom is a power purchase (opex), not capex
A37: Average load factor on gross MW | B37: 0.9 | C37: % | D37: Estimated | E37: Calibrates to Capacity's ~$1.1M per gross MW-yr at midpoint: 139 x 8,760 x 0.9 = $1.10M
A38: Power cost per gross MW-yr | B38: =$B$36*8760*$B$37/1000000 | C38: $M | D38: Derived
A39: Colo rent per IT MW-yr (leased sites only) | B39: 2.25 | C39: $M | D39: Estimated (Capacity range 2.0-2.5) | E39: /workspace/nebius/capacity/gpu_mw_capex.xlsx + .md (team Capacity & Power) peers: colo rent $165-205/kW-mo
A40: Q2'26 AI cloud segment adj. EBITDA margin (calibration) | B40: 0.497 | C40: % | D40: Reported | E40: /workspace/nebius/filings/nebius_fact_base.md
...

Sheet Sites
A1: # | B1: Site | C1: Country | D1: Tracker type | E1: Ownership tag (v2) | F1: YE26 MW low | G1: YE26 MW base | H1: YE26 MW high | I1: MW basis | J1: Owned base MW | K1: Source
A2: 1 | B2: Mantsala DC #1 | C2: Finland | D2: Owned greenfield | E2: Owned | F2: 75 | G2: 75 | H2: 75 | I2: not disclosed (PUE ~1.1) | J2: =IF(LEFT(E2,5)="Owned",G2,0) | K2: /workspace/nebius/capacity/site_list.xlsx (team Capacity & Power)
A3: 2 | B3: Mantsala DC #2 | C3: Finland | D3: Owned (implied) | E3: Owned | F3: 0 | G3: 0 | H3: 0 | I3: n/d | J3: =IF(LEFT(E3,5)="Owned",G3,0) | K3: /workspace/nebius/capacity/site_list.xlsx (team Capacity & Power)
A4: 3 | B4: Lappeenranta | C4: Finland | D4: Owned per Nebius; developer says Nebius 'operating Polarnode's campus' | E4: Unknown (conflict) | F4: 0 | G4: 0 | H4: 0 | I4: n/d | J4: =IF(LEFT(E4,5)="Owned",G4,0) | K4: /workspace/nebius/capacity/site_list.xlsx (team Capacity & Power)
A5: 4 | B5: Paris Equinix PA10 | C5: France | D5: Colocation | E5: Leased | F5: 5 | G5: 5 | H5: 5 | I5: n/d | J5: =IF(LEFT(E5,5)="Owned",G5,0) | K5: /workspace/nebius/capacity/site_list.xlsx (team Capacity & Power)
A6: 5 | B6: Bethune | C6: France | D6: Colocation per 20-F | E6: Leased | F6: 0 | G6: 120 | H6: 120 | I6: n/d | J6: =IF(LEFT(E6,5)="Owned",G6,0) | K6: /workspace/nebius/capacity/site_list.xlsx (team Capacity & Power)
A7: 6 | B7: France 2nd colo | C7: France | D7: Colocation | E7: Leased | F7: 0 | G7: 0 | H7: 0 | I7: n/d | J7: =IF(LEFT(E7,5)="Owned",G7,0) | K7: /workspace/nebius/capacity/site_list.xlsx (team Capacity & Power)
A8: 7 | B8: Keflavik Verne | C8: Iceland | D8: Colocation | E8: Leased | F8: 10 | G8: 10 | H8: 10 | I8: n/d | J8: =IF(LEFT(E8,5)="Owned",G8,0) | K8: /workspace/nebius/capacity/site_list.xlsx (team Capacity & Power)
A9: 8 | B9: London Longcross (Ark) | C9: UK | D9: Colocation | E9: Leased | F9: 16 | G9: 19 | H9: 19 | I9: gross (Capacity inference) | J9: =IF(LEFT(E9,5)="Owned",G9,0) | K9: /workspace/nebius/capacity/site_list.xlsx (team Capacity & Power)
A10: 9 | B10: Harlow Kao | C10: UK | D10: Colocation | E10: Leased | F10: 0 | G10: 0 | H10: 4.4 | I10: n/d | J10: =IF(LEFT(E10,5)="Owned",G10,0) | K10: /workspace/nebius/capacity/site_list.xlsx (team Capacity & Power)
A11: 10 | B11: UK 3rd site | C11: UK | D11: not disclosed (likely colo - inference) | E11: Unknown | F11: 0 | G11: 0 | H11: 0 | I11: n/d | J11: =IF(LEFT(E11,5)="Owned",G11,0) | K11: /workspace/nebius/capacity/site_list.xlsx (team Capacity & Power)
A12: 11 | B12: Modi'in Mega Or | C12: Israel | D12: Colocation | E12: Leased | F12: 8 | G12: 8 | H12: 8 | I12: IT (Capacity) | J12: =IF(LEFT(E12,5)="Owned",G12,0) | K12: /workspace/nebius/capacity/site_list.xlsx (team Capacity & Power)
A13: 12 | B13: Masmiyya | C13: Israel | D13: Colocation | E13: Leased | F13: 0 | G13: 22 | H13: 22 | I13: n/d | J13: =IF(LEFT(E13,5)="Owned",G13,0) | K13: /workspace/nebius/capacity/site_list.xlsx (team Capacity & Power)
... A24: 23 | B24: AIB southeastern US | C24: USA | D24: Colocation/leased 12-yr | E24: Leased | F24: 0 | G24: 0 | H24: 0 | I24: IT (50 MW critical IT) | J24: =IF(LEFT(E24,5)="Owned",G24,0) | K24: /workspace/nebius/capacity/site_list.xlsx (team Capacity & Power)
B25: TOTAL | F25: =SUM(F2:F24) | G25: =SUM(G2:G24) | H25: =SUM(H2:H24) | J25: =SUM(J2:J24)
B27: Owned share of YE26 base MW | J27: =J25/G25
B28: Leased (incl. Vineland) share | J28: =SUMPRODUCT((LEFT(E2:E24,6)="Leased")*G2:G24)/G25
B29: Unknown: Lappeenranta, UK 3rd (0 MW in YE26 base) - run owned and leased (Cohorts both; fleet owned-share 0%/100% in md)

Sheet MW
A1: Capacity energized MW (identified sites) - /workspace/nebius/capacity/nebius_capacity.xlsx 'Quarterly MW' (pasted values, blue) | C1: Q2 2026 | D1: Q3 2026 | E1: Q4 2026 | F1: Q1 2027 | G1: Q2 2027 | H1: Q3 2027 | I1: Q4 2027 | J1: Q1 2028 | K1: Q2 2028 | L1: Q3 2028 | M1: Q4 2028 | N1: Q1 2029 | O1: Q2 2029 | P1: Q3 2029 | Q1: Q4 2029 | R1: Q1 2030 | S1: Q2 2030 | T1: Q3 2030 | U1: Q4 2030
A2: Energized MW, identified sites - low (mixed basis) | B2: Capacity Quarterly MW (sum of site rows; ties to COMPANY rows) | C2: 152 | D2: 182 | E2: 185 | F2: 270.4 | G2: 394.4 | H2: 509 | I2: 764 | J2: 824 | K2: 994 | L2: 1019 | M2: 1539 | N2: 1539 | O2: 1769 | P2: 1769 | Q2: 2289 | R2: 2289 | S2: 2289 | T2: 2289 | U2: 2839
A3: of which IT-basis sites (Vineland, AIB) - low | B3: Capacity Basis column = IT | C3: 41 | D3: 65 | E3: 65 | F3: 65 | G3: 115 | H3: 168 | I3: 238 | J3: 263 | K3: 263 | L3: 288 | M3: 288 | N3: 288 | O3: 288 | P3: 288 | Q3: 288 | R3: 288 | S3: 288 | T3: 288 | U3: 288
A4: of which Vineland (IT) - low | B4: Capacity | C4: 33 | D4: 57 | E4: 57 | F4: 57 | G4: 107 | H4: 160 | I4: 230 | J4: 230 | K4: 230 | L4: 230 | M4: 230 | N4: 230 | O4: 230 | P4: 230 | Q4: 230 | R4: 230 | S4: 230 | T4: 230 | U4: 230
A5: of which owned sites (Independence, Butler PA, Birmingham, Lappeenranta, Mantsala) - low | B5: Capacity Sites 'Ownership type' | C5: 75 | D5: 75 | E5: 75 | F5: 75 | G5: 75 | H5: 100 | I5: 210 | J5: 245 | K5: 415 | L5: 415 | M5: 815 | N5: 815 | O5: 1045 | P5: 1045 | Q5: 1565 | R5: 1565 | S5: 1565 | T5: 1565 | U5: 2115
A6: Energized MW, identified sites - base (mixed basis) | B6: Capacity Quarterly MW (sum of site rows; ties to COMPANY rows) | C6: 173 | D6: 207.5 | E6: 304.5 | F6: 444.7 | G6: 591.7 | H6: 751.5 | I6: 1069 | J6: 1181.5 | K6: 1376.5 | L6: 1389 | M6: 1799 | N6: 1799 | O6: 2219 | P6: 2219 | Q6: 2804 | R6: 2804 | S6: 2804 | T6: 2804 | U6: 3379
A7: of which IT-basis sites (Vineland, AIB) - base | B7: Capacity Basis column = IT | C7: 47 | D7: 74 | E7: 89.8 | F7: 126.5 | G7: 176.5 | H7: 225.5 | I7: 273 | J7: 285.5 | K7: 285.5 | L7: 298 | M7: 298 | N7: 298 | O7: 298 | P7: 298 | Q7: 298 | R7: 298 | S7: 298 | T7: 298 | U7: 298
A8: of which Vineland (IT) - base | B8: Capacity | C8: 39 | D8: 66 | E8: 81.8 | F8: 118.5 | G8: 168.5 | H8: 205 | I8: 240 | J8: 240 | K8: 240 | L8: 240 | M8: 240 | N8: 240 | O8: 240 | P8: 240 | Q8: 240 | R8: 240 | S8: 240 | T8: 240 | U8: 240
A9: of which owned sites (Independence, Butler PA, Birmingham, Lappeenranta, Mantsala) - base | B9: Capacity Sites 'Ownership type' | C9: 75 | D9: 75 | E9: 75 | F9: 87.5 | G9: 117.5 | H9: 210 | I9: 410 | J9: 510 | K9: 705 | L9: 705 | M9: 1055 | N9: 1055 | O9: 1475 | P9: 1475 | Q9: 2060 | R9: 2060 | S9: 2060 | T9: 2060 | U9: 2635
A10: Energized MW, identified sites - high (mixed basis) | B10: Capacity Quarterly MW (sum of site rows; ties to COMPANY rows) | C10: 194 | D10: 233 | E10: 424 | F10: 619 | G10: 789 | H10: 994 | I10: 1374 | J10: 1539 | K10: 1759 | L10: 1759 | M10: 2059 | N10: 2059 | O10: 2669 | P10: 2669 | Q10: 3319 | R10: 3319 | S10: 3319 | T10: 3319 | U10: 3919
A11: of which IT-basis sites (Vineland, AIB) - high | B11: Capacity Basis column = IT | C11: 53 | D11: 83 | E11: 114.6 | F11: 188 | G11: 238 | H11: 283 | I11: 308 | J11: 308 | K11: 308 | L11: 308 | M11: 308 | N11: 308 | O11: 308 | P11: 308 | Q11: 308 | R11: 308 | S11: 308 | T11: 308 | U11: 308
A12: of which Vineland (IT) - high | B12: Capacity | C12: 45 | D12: 75 | E12: 106.6 | F12: 180 | G12: 230 | H12: 250 | I12: 250 | J12: 250 | K12: 250 | L12: 250 | M12: 250 | N12: 250 | O12: 250 | P12: 250 | Q12: 250 | R12: 250 | S12: 250 | T12: 250 | U12: 250
A13: of which owned sites (Independence, Butler PA, Birmingham, Lappeenranta, Mantsala) - high | B13: Capacity Sites 'Ownership type' | C13: 75 | D13: 75 | E13: 75 | F13: 100 | G13: 160 | H13: 320 | I13: 610 | J13: 775 | K13: 995 | L13: 995 | M13: 1295 | N13: 1295 | O13: 1905 | P13: 1905 | Q13: 2555 | R13: 2555 | S13: 2555 | T13: 2555 | U13: 3155
A15: Selected energized MW (mixed) | C15: =CHOOSE(Assumptions!$B$91,C2,C6,C10) | D15: =CHOOSE(Assumptions!$B$91,D2,D6,D10) | E15: =CHOOSE(Assumptions!$B$91,E2,E6,E10) | F15: =CHOOSE(Assumptions!$B$91,F2,F6,F10) | G15: =CHOOSE(Assumptions!$B$91,G2,G6,G10) | H15: =CHOOSE(Assumptions!$B$91,H2,H6,H10) | I15: =CHOOSE(Assumptions!$B$91,I2,I6,I10) | J15: =CHOOSE(Assumptions!$B$91,J2,J6,J10) | ... U15: =CHOOSE(Assumptions!$B$91,U2,U6,U10)
A16: Selected IT-basis MW | C16: =CHOOSE(Assumptions!$B$91,C3,C7,C11) | D16: =CHOOSE(Assumptions!$B$91,D3,D7,D11) | E16: =CHOOSE(Assumptions!$B$91,E3,E7,E11) | F16: =CHOOSE(Assumptions!$B$91,F3,F7,F11) | G16: =CHOOSE(Assumptions!$B$91,G3,G7,G11) | H16: =CHOOSE(Assumptions!$B$91,H3,H7,H11) | I16: =CHOOSE(Assumptions!$B$91,I3,I7,I11) | J16: =CHOOSE(Assumptions!$B$91,J3,J7,J11) | ... U16: =CHOOSE(Assumptions!$B$91,U3,U7,U11)
A17: Selected Vineland IT MW | C17: =CHOOSE(Assumptions!$B$91,C4,C8,C12) | D17: =CHOOSE(Assumptions!$B$91,D4,D8,D12) | E17: =CHOOSE(Assumptions!$B$91,E4,E8,E12) | F17: =CHOOSE(Assumptions!$B$91,F4,F8,F12) | G17: =CHOOSE(Assumptions!$B$91,G4,G8,G12) | H17: =CHOOSE(Assumptions!$B$91,H4,H8,H12) | I17: =CHOOSE(Assumptions!$B$91,I4,I8,I12) | J17: =CHOOSE(Assumptions!$B$91,J4,J8,J12) | ... U17: =CHOOSE(Assumptions!$B$91,U4,U8,U12)
A18: Selected owned-site MW | C18: =CHOOSE(Assumptions!$B$91,C5,C9,C13) | D18: =CHOOSE(Assumptions!$B$91,D5,D9,D13) | E18: =CHOOSE(Assumptions!$B$91,E5,E9,E13) | F18: =CHOOSE(Assumptions!$B$91,F5,F9,F13) | G18: =CHOOSE(Assumptions!$B$91,G5,G9,G13) | H18: =CHOOSE(Assumptions!$B$91,H5,H9,H13) | I18: =CHOOSE(Assumptions!$B$91,I5,I9,I13) | J18: =CHOOSE(Assumptions!$B$91,J5,J9,J13) | ... U18: =CHOOSE(Assumptions!$B$91,U5,U9,U13)
A19: Energized GROSS MW (unknown basis treated as gross; IT x PUE) | C19: =C15-C16+C16*Assumptions!$B$33 | D19: =D15-D16+D16*Assumptions!$B$33 | E19: =E15-E16+E16*Assumptions!$B$33 | F19: =F15-F16+F16*Assumptions!$B$33 | G19: =G15-G16+G16*Assumptions!$B$33 | H19: =H15-H16+H16*Assumptions!$B$33 | I19: =I15-I16+I16*Assumptions!$B$33 | J19: =J15-J16+J16*Assumptions!$B$33 | ... U19: =U15-U16+U16*Assumptions!$B$33
A20: + Unseen-site gross MW (cumulative from Q4'26) | C20: =IF(0>=2,(0-1)*Assumptions!$B$92,0) | D20: =IF(1>=2,(1-1)*Assumptions!$B$92,0) | E20: =IF(2>=2,(2-1)*Assumptions!$B$92,0) | F20: =IF(3>=2,(3-1)*Assumptions!$B$92,0) | G20: =IF(4>=2,(4-1)*Assumptions!$B$92,0) | H20: =IF(5>=2,(5-1)*Assumptions!$B$92,0) | I20: =IF(6>=2,(6-1)*Assumptions!$B$92,0) | J20: =IF(7>=2,(7-1)*Assumptions!$B$92,0) | K20: =IF(8>=2,(8-1)*Assumptions!$B$92,0) | L20: =IF(9>=2,(9-1)*Assumptions!$B$92,0) | M20: =IF(10>=2,(10-1)*Assumptions!$B$92,0) | N20: =IF(11>=2,(11-1)*Assumptions!$B$92,0) | O20: =IF(12>=2,(12-1)*Assumptions!$B$92,0) | P20: =IF(13>=2,(13-1)*Assumptions!$B$92,0) | Q20: =IF(14>=2,(14-1)*Assumptions!$B$92,0) | R20: =IF(15>=2,(15-1)*Assumptions!$B$92,0) | S20: =IF(16>=2,(16-1)*Assumptions!$B$92,0) | T20: =IF(17>=2,(17-1)*Assumptions!$B$92,0) | U20: =IF(18>=2,(18-1)*Assumptions!$B$92,0)
A21: Energized gross MW incl. unseen | C21: =C19+C20 | D21: =D19+D20 | E21: =E19+E20 | F21: =F19+F20 | G21: =G19+G20 | H21: =H19+H20 | I21: =I19+I20 | J21: =J19+J20 | ... U21: =U19+U20
A22: IT-equivalent energized MW incl. unseen (gross / PUE) | C22: =C21/Assumptions!$B$33 | D22: =D21/Assumptions!$B$33 | E22: =E21/Assumptions!$B$33 | F22: =F21/Assumptions!$B$33 | G22: =G21/Assumptions!$B$33 | H22: =H21/Assumptions!$B$33 | I22: =I21/Assumptions!$B$33 | J22: =J21/Assumptions!$B$33 | ... U22: =U21/Assumptions!$B$33
A23: IT MW energized in quarter (additions) | C23: =IF(0=0,0,C22-None22) | D23: =IF(1=0,0,D22-C22) | E23: =IF(2=0,0,E22-D22) | F23: =IF(3=0,0,F22-E22) | G23: =IF(4=0,0,G22-F22) | H23: =IF(5=0,0,H22-G22) | I23: =IF(6=0,0,I22-H22) | J23: =IF(7=0,0,J22-I22) | K23: =IF(8=0,0,K22-J22) | L23: =IF(9=0,0,L22-K22) | M23: =IF(10=0,0,M22-L22) | N23: =IF(11=0,0,N22-M22) | O23: =IF(12=0,0,O22-N22) | P23: =IF(13=0,0,P22-O22) | Q23: =IF(14=0,0,Q22-P22) | R23: =IF(15=0,0,R22-Q22) | S23: =IF(16=0,0,S22-R22) | T23: =IF(17=0,0,T22-S22) | U23: =IF(18=0,0,U22-T22)
A24: Vineland gross MW | C24: =C17*Assumptions!$B$33 | D24: =D17*Assumptions!$B$33 | E24: =E17*Assumptions!$B$33 | F24: =F17*Assumptions!$B$33 | G24: =G17*Assumptions!$B$33 | H24: =H17*Assumptions!$B$33 | I24: =I17*Assumptions!$B$33 | J24: =J17*Assumptions!$B$33 | ... U24: =U17*Assumptions!$B$33
A25: BILLING gross MW (energized shifted by billing lag; lag 0/1/2 supported) | C25: =IF(Assumptions!$B$90=0,C21,IF(Assumptions!$B$90=1,IF(0>=1,INDEX($C$21:$U$21,0),C21),IF(0>=2,INDEX($C$21:$U$21,0-1),$C$21))) | D25: =IF(Assumptions!$B$90=0,D21,IF(Assumptions!$B$90=1,IF(1>=1,INDEX($C$21:$U$21,1),D21),IF(1>=2,INDEX($C$21:$U$21,1-1),$C$21))) | E25: =IF(Assumptions!$B$90=0,E21,IF(Assumptions!$B$90=1,IF(2>=1,INDEX($C$21:$U$21,2),E21),IF(2>=2,INDEX($C$21:$U$21,2-1),$C$21))) | F25: =IF(Assumptions!$B$90=0,F21,IF(Assumptions!$B$90=1,IF(3>=1,INDEX($C$21:$U$21,3),F21),IF(3>=2,INDEX($C$21:$U$21,3-1),$C$21))) | G25: =IF(Assumptions!$B$90=0,G21,IF(Assumptions!$B$90=1,IF(4>=1,INDEX($C$21:$U$21,4),G21),IF(4>=2,INDEX($C$21:$U$21,4-1),$C$21))) | H25: =IF(Assumptions!$B$90=0,H21,IF(Assumptions!$B$90=1,IF(5>=1,INDEX($C$21:$U$21,5),H21),IF(5>=2,INDEX($C$21:$U$21,5-1),$C$21))) | I25: =IF(Assumptions!$B$90=0,I21,IF(Assumptions!$B$90=1,IF(6>=1,INDEX($C$21:$U$21,6),I21),IF(6>=2,INDEX($C$21:$U$21,6-1),$C$21))) | J25: =IF(Assumptions!$B$90=0,J21,IF(Assumptions!$B$90=1,IF(7>=1,INDEX($C$21:$U$21,7),J21),IF(7>=2,INDEX($C$21:$U$21,7-1),$C$21))) | K25: =IF(Assumptions!$B$90=0,K21,IF(Assumptions!$B$90=1,IF(8>=1,INDEX($C$21:$U$21,8),K21),IF(8>=2,INDEX($C$21:$U$21,8-1),$C$21))) | L25: =IF(Assumptions!$B$90=0,L21,IF(Assumptions!$B$90=1,IF(9>=1,INDEX($C$21:$U$21,9),L21),IF(9>=2,INDEX($C$21:$U$21,9-1),$C$21))) | M25: =IF(Assumptions!$B$90=0,M21,IF(Assumptions!$B$90=1,IF(10>=1,INDEX($C$21:$U$21,10),M21),IF(10>=2,INDEX($C$21:$U$21,10-1),$C$21))) | N25: =IF(Assumptions!$B$90=0,N21,IF(Assumptions!$B$90=1,IF(11>=1,INDEX($C$21:$U$21,11),N21),IF(11>=2,INDEX($C$21:$U$21,11-1),$C$21))) | O25: =IF(Assumptions!$B$90=0,O21,IF(Assumptions!$B$90=1,IF(12>=1,INDEX($C$21:$U$21,12),O21),IF(12>=2,INDEX($C$21:$U$21,12-1),$C$21))) | P25: =IF(Assumptions!$B$90=0,P21,IF(Assumptions!$B$90=1,IF(13>=1,INDEX($C$21:$U$21,13),P21),IF(13>=2,INDEX($C$21:$U$21,13-1),$C$21))) | Q25: =IF(Assumptions!$B$90=0,Q21,IF(Assumptions!$B$90=1,IF(14>=1,INDEX($C$21:$U$21,14),Q21),IF(14>=2,INDEX($C$21:$U$21,14-1),$C$21))) | R25: =IF(Assumptions!$B$90=0,R21,IF(Assumptions!$B$90=1,IF(15>=1,INDEX($C$21:$U$21,15),R21),IF(15>=2,INDEX($C$21:$U$21,15-1),$C$21))) | S25: =IF(Assumptions!$B$90=0,S21,IF(Assumptions!$B$90=1,IF(16>=1,INDEX($C$21:$U$21,16),S21),IF(16>=2,INDEX($C$21:$U$21,16-1),$C$21))) | T25: =IF(Assumptions!$B$90=0,T21,IF(Assumptions!$B$90=1,IF(17>=1,INDEX($C$21:$U$21,17),T21),IF(17>=2,INDEX($C$21:$U$21,17-1),$C$21))) | U25: =IF(Assumptions!$B$90=0,U21,IF(Assumptions!$B$90=1,IF(18>=1,INDEX($C$21:$U$21,18),U21),IF(18>=2,INDEX($C$21:$U$21,18-1),$C$21)))
A26: Billing gross MW ex-Vineland | C26: =IF(Assumptions!$B$90=0,C21-C24,IF(Assumptions!$B$90=1,IF(0>=1,INDEX($C$21:$U$21,0)-INDEX($C$24:$U$24,0),C21-C24),IF(0>=2,INDEX($C$21:$U$21,0-1)-INDEX($C$24:$U$24,0-1),$C$21-$C$24))) | D26: =IF(Assumptions!$B$90=0,D21-D24,IF(Assumptions!$B$90=1,IF(1>=1,INDEX($C$21:$U$21,1)-INDEX($C$24:$U$24,1),D21-D24),IF(1>=2,INDEX($C$21:$U$21,1-1)-INDEX($C$24:$U$24,1-1),$C$21-$C$24))) | E26: =IF(Assumptions!$B$90=0,E21-E24,IF(Assumptions!$B$90=1,IF(2>=1,INDEX($C$21:$U$21,2)-INDEX($C$24:$U$24,2),E21-E24),IF(2>=2,INDEX($C$21:$U$21,2-1)-INDEX($C$24:$U$24,2-1),$C$21-$C$24))) | F26: =IF(Assumptions!$B$90=0,F21-F24,IF(Assumptions!$B$90=1,IF(3>=1,INDEX($C$21:$U$21,3)-INDEX($C$24:$U$24,3),F21-F24),IF(3>=2,INDEX($C$21:$U$21,3-1)-INDEX($C$24:$U$24,3-1),$C$21-$C$24))) | G26: =IF(Assumptions!$B$90=0,G21-G24,IF(Assumptions!$B$90=1,IF(4>=1,INDEX($C$21:$U$21,4)-INDEX($C$24:$U$24,4),G21-G24),IF(4>=2,INDEX($C$21:$U$21,4-1)-INDEX($C$24:$U$24,4-1),$C$21-$C$24))) | H26: =IF(Assumptions!$B$90=0,H21-H24,IF(Assumptions!$B$90=1,IF(5>=1,INDEX($C$21:$U$21,5)-INDEX($C$24:$U$24,5),H21-H24),IF(5>=2,INDEX($C$21:$U$21,5-1)-INDEX($C$24:$U$24,5-1),$C$21-$C$24))) | I26: =IF(Assumptions!$B$90=0,I21-I24,IF(Assumptions!$B$90=1,IF(6>=1,INDEX($C$21:$U$21,6)-INDEX($C$24:$U$24,6),I21-I24),IF(6>=2,INDEX($C$21:$U$21,6-1)-INDEX($C$24:$U$24,6-1),$C$21-$C$24))) | J26: =IF(Assumptions!$B$90=0,J21-J24,IF(Assumptions!$B$90=1,IF(7>=1,INDEX($C$21:$U$21,7)-INDEX($C$24:$U$24,7),J21-J24),IF(7>=2,INDEX($C$21:$U$21,7-1)-INDEX($C$24:$U$24,7-1),$C$21-$C$24))) | K26: =IF(Assumptions!$B$90=0,K21-K24,IF(Assumptions!$B$90=1,IF(8>=1,INDEX($C$21:$U$21,8)-INDEX($C$24:$U$24,8),K21-K24),IF(8>=2,INDEX($C$21:$U$21,8-1)-INDEX($C$24:$U$24,8-1),$C$21-$C$24))) | L26: =IF(Assumptions!$B$90=0,L21-L24,IF(Assumptions!$B$90=1,IF(9>=1,INDEX($C$21:$U$21,9)-INDEX($C$24:$U$24,9),L21-L24),IF(9>=2,INDEX($C$21:$U$21,9-1)-INDEX($C$24:$U$24,9-1),$C$21-$C$24))) | M26: =IF(Assumptions!$B$90=0,M21-M24,IF(Assumptions!$B$90=1,IF(10>=1,INDEX($C$21:$U$21,10)-INDEX($C$24:$U$24,10),M21-M24),IF(10>=2,INDEX($C$21:$U$21,10-1)-INDEX($C$24:$U$24,10-1),$C$21-$C$24))) | N26: =IF(Assumptions!$B$90=0,N21-N24,IF(Assumptions!$B$90=1,IF(11>=1,INDEX($C$21:$U$21,11)-INDEX($C$24:$U$24,11),N21-N24),IF(11>=2,INDEX($C$21:$U$21,11-1)-INDEX($C$24:$U$24,11-1),$C$21-$C$24))) | O26: =IF(Assumptions!$B$90=0,O21-O24,IF(Assumptions!$B$90=1,IF(12>=1,INDEX($C$21:$U$21,12)-INDEX($C$24:$U$24,12),O21-O24),IF(12>=2,INDEX($C$21:$U$21,12-1)-INDEX($C$24:$U$24,12-1),$C$21-$C$24))) | P26: =IF(Assumptions!$B$90=0,P21-P24,IF(Assumptions!$B$90=1,IF(13>=1,INDEX($C$21:$U$21,13)-INDEX($C$24:$U$24,13),P21-P24),IF(13>=2,INDEX($C$21:$U$21,13-1)-INDEX($C$24:$U$24,13-1),$C$21-$C$24))) | Q26: =IF(Assumptions!$B$90=0,Q21-Q24,IF(Assumptions!$B$90=1,IF(14>=1,INDEX($C$21:$U$21,14)-INDEX($C$24:$U$24,14),Q21-Q24),IF(14>=2,INDEX($C$21:$U$21,14-1)-INDEX($C$24:$U$24,14-1),$C$21-$C$24))) | R26: =IF(Assumptions!$B$90=0,R21-R24,IF(Assumptions!$B$90=1,IF(15>=1,INDEX($C$21:$U$21,15)-INDEX($C$24:$U$24,15),R21-R24),IF(15>=2,INDEX($C$21:$U$21,15-1)-INDEX($C$24:$U$24,15-1),$C$21-$C$24))) | S26: =IF(Assumptions!$B$90=0,S21-S24,IF(Assumptions!$B$90=1,IF(16>=1,INDEX($C$21:$U$21,16)-INDEX($C$24:$U$24,16),S21-S24),IF(16>=2,INDEX($C$21:$U$21,16-1)-INDEX($C$24:$U$24,16-1),$C$21-$C$24))) | T26: =IF(Assumptions!$B$90=0,T21-T24,IF(Assumptions!$B$90=1,IF(17>=1,INDEX($C$21:$U$21,17)-INDEX($C$24:$U$24,17),T21-T24),IF(17>=2,INDEX($C$21:$U$21,17-1)-INDEX($C$24:$U$24,17-1),$C$21-$C$24))) | U26: =IF(Assumptions!$B$90=0,U21-U24,IF(Assumptions!$B$90=1,IF(18>=1,INDEX($C$21:$U$21,18)-INDEX($C$24:$U$24,18),U21-U24),IF(18>=2,INDEX($C$21:$U$21,18-1)-INDEX($C$24:$U$24,18-1),$C$21-$C$24)))
A27: Owned share of cumulative energized MW (selected) | C27: =IF(C15>0,C18/C15,0) | D27: =IF(D15>0,D18/D15,0) | E27: =IF(E15>0,E18/E15,0) | F27: =IF(F15>0,F18/F15,0) | G27: =IF(G15>0,G18/G15,0) | H27: =IF(H15>0,H18/H15,0) | I27: =IF(I15>0,I18/I15,0) | J27: =IF(J15>0,J18/J15,0) | ... U27: =IF(U15>0,U18/U15,0)
A28: Note: FY owned share of energized ADDITIONS (feeds capex mix) is on the Model sheet. Q2'26 column = starting point (energized at 6/30/26 per Capacity).

Sheet Microsoft
A1: Microsoft (Vineland) tranche model - take-or-pay 'irrespective of actual utilization'; haircut = SLA/service credits + per-tranche termination (NOT demand)
A2: Tranche | B2: Scheduled (contract/letter) | C2: Capacity base billing start | D2: Capacity bear billing start | E2: Selected start | F2: Terminate? (1 = cancelled) | G2: Quarterly revenue $M (TCV/9/20) | H2: Source / tag
A3: T1 | B3: Q4 2025 | C3: Q4 2025 | D3: Q4 2025 | E3: =CHOOSE(Assumptions!$B$160,B3,C3,D3) | F3: 0 | G3: =Assumptions!$B$161/9/20*(1-Assumptions!$B$53)*(1-F3) | H3: Equal split (Estimated); dates: 20-F (T1 Nov-25, T2 Feb-26), Q2 letter (two tranches Jul/Aug-26), Capacity estimates T5-T9
A4: T2 | B4: Q1 2026 | C4: Q1 2026 | D4: Q1 2026 | E4: =CHOOSE(Assumptions!$B$160,B4,C4,D4) | F4: 0 | G4: =Assumptions!$B$161/9/20*(1-Assumptions!$B$53)*(1-F4) | H4: Equal split (Estimated); dates: 20-F (T1 Nov-25, T2 Feb-26), Q2 letter (two tranches Jul/Aug-26), Capacity estimates T5-T9
A5: T3 | B5: Q3 2026 | C5: Q3 2026 | D5: Q3 2026 | E5: =CHOOSE(Assumptions!$B$160,B5,C5,D5) | F5: 0 | G5: =Assumptions!$B$161/9/20*(1-Assumptions!$B$53)*(1-F5) | H5: Equal split (Estimated); dates: 20-F (T1 Nov-25, T2 Feb-26), Q2 letter (two tranches Jul/Aug-26), Capacity estimates T5-T9
A6: T4 | B6: Q3 2026 | C6: Q3 2026 | D6: Q3 2026 | E6: =CHOOSE(Assumptions!$B$160,B6,C6,D6) | F6: 0 | G6: =Assumptions!$B$161/9/20*(1-Assumptions!$B$53)*(1-F6) | H6: Equal split (Estimated); dates: 20-F (T1 Nov-25, T2 Feb-26), Q2 letter (two tranches Jul/Aug-26), Capacity estimates T5-T9
A7: T5 | B7: Q3 2026 | C7: Q2 2027 | D7: Q3 2027 | E7: =CHOOSE(Assumptions!$B$160,B7,C7,D7) | F7: 0 | G7: =Assumptions!$B$161/9/20*(1-Assumptions!$B$53)*(1-F7) | H7: Equal split (Estimated); dates: 20-F (T1 Nov-25, T2 Feb-26), Q2 letter (two tranches Jul/Aug-26), Capacity estimates T5-T9
A8: T6 | B8: Q3 2026 | C8: Q2 2027 | D8: Q3 2027 | E8: =CHOOSE(Assumptions!$B$160,B8,C8,D8) | F8: 0 | G8: =Assumptions!$B$161/9/20*(1-Assumptions!$B$53)*(1-F8) | H8: Equal split (Estimated); dates: 20-F (T1 Nov-25, T2 Feb-26), Q2 letter (two tranches Jul/Aug-26), Capacity estimates T5-T9
A9: T7 | B9: Q3 2026 | C9: Q3 2027 | D9: Q4 2027 | E9: =CHOOSE(Assumptions!$B$160,B9,C9,D9) | F9: 0 | G9: =Assumptions!$B$161/9/20*(1-Assumptions!$B$53)*(1-F9) | H9: Equal split (Estimated); dates: 20-F (T1 Nov-25, T2 Feb-26), Q2 letter (two tranches Jul/Aug-26), Capacity estimates T5-T9
A10: T8 | B10: Q3 2026 | C10: Q3 2027 | D10: Q4 2027 | E10: =CHOOSE(Assumptions!$B$160,B10,C10,D10) | F10: 0 | G10: =Assumptions!$B$161/9/20*(1-Assumptions!$B$53)*(1-F10) | H10: Equal split (Estimated); dates: 20-F (T1 Nov-25, T2 Feb-26), Q2 letter (two tranches Jul/Aug-26), Capacity estimates T5-T9
A11: T9 | B11: Q3 2026 | C11: Q3 2027 | D11: Q1 2028 | E11: =CHOOSE(Assumptions!$B$160,B11,C11,D11) | F11: 0 | G11: =Assumptions!$B$161/9/20*(1-Assumptions!$B$53)*(1-F11) | H11: Equal split (Estimated); dates: 20-F (T1 Nov-25, T2 Feb-26), Q2 letter (two tranches Jul/Aug-26), Capacity estimates T5-T9
A13: Quarter | B13: Q4 2025 | C13: Q1 2026 | D13: Q2 2026 | E13: Q3 2026 | F13: Q4 2026 | G13: Q1 2027 | H13: Q2 2027 | I13: Q3 2027 | J13: Q4 2027 | K13: Q1 2028 | L13: Q2 2028 | M13: Q3 2028 | N13: Q4 2028 | O13: Q1 2029 | P13: Q2 2029 | Q13: Q3 2029 | R13: Q4 2029 | S13: Q1 2030 | T13: Q2 2030 | U13: Q3 2030 | V13: Q4 2030 | W13: Q1 2031 | X13: Q2 2031 | Y13: Q3 2031 | Z13: Q4 2031
A14: Revenue $M | B14: =SUMPRODUCT(($G$3:$G$11)*(MATCH($E$3:$E$11,$B$13:$Z$13,0)<=COLUMN()-1)*(MATCH($E$3:$E$11,$B$13:$Z$13,0)>COLUMN()-21)) | C14: =SUMPRODUCT(($G$3:$G$11)*(MATCH($E$3:$E$11,$B$13:$Z$13,0)<=COLUMN()-1)*(MATCH($E$3:$E$11,$B$13:$Z$13,0)>COLUMN()-21)) | D14: =SUMPRODUCT(($G$3:$G$11)*(MATCH($E$3:$E$11,$B$13:$Z$13,0)<=COLUMN()-1)*(MATCH($E$3:$E$11,$B$13:$Z$13,0)>COLUMN()-21)) | E14: =SUMPRODUCT(($G$3:$G$11)*(MATCH($E$3:$E$11,$B$13:$Z$13,0)<=COLUMN()-1)*(MATCH($E$3:$E$11,$B$13:$Z$13,0)>COLUMN()-21)) | F14: =SUMPRODUCT(($G$3:$G$11)*(MATCH($E$3:$E$11,$B$13:$Z$13,0)<=COLUMN()-1)*(MATCH($E$3:$E$11,$B$13:$Z$13,0)>COLUMN()-21)) | G14: =SUMPRODUCT(($G$3:$G$11)*(MATCH($E$3:$E$11,$B$13:$Z$13,0)<=COLUMN()-1)*(MATCH($E$3:$E$11,$B$13:$Z$13,0)>COLUMN()-21)) | H14: =SUMPRODUCT(($G$3:$G$11)*(MATCH($E$3:$E$11,$B$13:$Z$13,0)<=COLUMN()-1)*(MATCH($E$3:$E$11,$B$13:$Z$13,0)>COLUMN()-21)) | I14: =SUMPRODUCT(($G$3:$G$11)*(MATCH($E$3:$E$11,$B$13:$Z$13,0)<=COLUMN()-1)*(MATCH($E$3:$E$11,$B$13:$Z$13,0)>COLUMN()-21)) | ... Z14: =SUMPRODUCT(($G$3:$G$11)*(MATCH($E$3:$E$11,$B$13:$Z$13,0)<=COLUMN()-1)*(MATCH($E$3:$E$11,$B$13:$Z$13,0)>COLUMN()-21))
A15: Billing tranches | B15: =SUMPRODUCT((1-$F$3:$F$11)*(MATCH($E$3:$E$11,$B$13:$Z$13,0)<=COLUMN()-1)*(MATCH($E$3:$E$11,$B$13:$Z$13,0)>COLUMN()-21)) | C15: =SUMPRODUCT((1-$F$3:$F$11)*(MATCH($E$3:$E$11,$B$13:$Z$13,0)<=COLUMN()-1)*(MATCH($E$3:$E$11,$B$13:$Z$13,0)>COLUMN()-21)) | D15: =SUMPRODUCT((1-$F$3:$F$11)*(MATCH($E$3:$E$11,$B$13:$Z$13,0)<=COLUMN()-1)*(MATCH($E$3:$E$11,$B$13:$Z$13,0)>COLUMN()-21)) | E15: =SUMPRODUCT((1-$F$3:$F$11)*(MATCH($E$3:$E$11,$B$13:$Z$13,0)<=COLUMN()-1)*(MATCH($E$3:$E$11,$B$13:$Z$13,0)>COLUMN()-21)) | F15: =SUMPRODUCT((1-$F$3:$F$11)*(MATCH($E$3:$E$11,$B$13:$Z$13,0)<=COLUMN()-1)*(MATCH($E$3:$E$11,$B$13:$Z$13,0)>COLUMN()-21)) | G15: =SUMPRODUCT((1-$F$3:$F$11)*(MATCH($E$3:$E$11,$B$13:$Z$13,0)<=COLUMN()-1)*(MATCH($E$3:$E$11,$B$13:$Z$13,0)>COLUMN()-21)) | H15: =SUMPRODUCT((1-$F$3:$F$11)*(MATCH($E$3:$E$11,$B$13:$Z$13,0)<=COLUMN()-1)*(MATCH($E$3:$E$11,$B$13:$Z$13,0)>COLUMN()-21)) | I15: =SUMPRODUCT((1-$F$3:$F$11)*(MATCH($E$3:$E$11,$B$13:$Z$13,0)<=COLUMN()-1)*(MATCH($E$3:$E$11,$B$13:$Z$13,0)>COLUMN()-21)) | ... Z15: =SUMPRODUCT((1-$F$3:$F$11)*(MATCH($E$3:$E$11,$B$13:$Z$13,0)<=COLUMN()-1)*(MATCH($E$3:$E$11,$B$13:$Z$13,0)>COLUMN()-21))
A17: Q2'26 check: equal-split T1+T2 = $193M/qtr vs top customer 24% x $582.3M = ~$140M (Capacity) - either T1/T2 smaller than 1/9 or customer C is not Microsoft
A18: FY2026 Microsoft revenue | B18: =SUMPRODUCT(($B$14:$Z$14)*(RIGHT($B$13:$Z$13,4)="2026"))
A19: FY2027 Microsoft revenue | B19: =SUMPRODUCT(($B$14:$Z$14)*(RIGHT($B$13:$Z$13,4)="2027"))
A20: FY2028 Microsoft revenue | B20: =SUMPRODUCT(($B$14:$Z$14)*(RIGHT($B$13:$Z$13,4)="2028"))
A21: Total billed over life (TCV after SLA/terminations) | B21: =SUM(G3:G11)*20
A22: PV at Q3'26 of Microsoft revenue Q3'26-Q4'31 at WACC (Microsoft through 2031 only partly visible in the 2030 horizon) | B22: =SUMPRODUCT($B$14:$Z$14*(COLUMN($B$14:$Z$14)>=5)*(1+Assumptions!$B$149)^(-(COLUMN($B$14:$Z$14)-5)/4))
A23: Genset ceiling run-rate (4 tranches) $M/yr | B23: =4*Assumptions!$B$161/9/5

Sheet Rev_MW
A1: Bottom-up revenue from billing-MW path ($M) - leg 3 re-run | C1: Q3 2026 | D1: Q4 2026 | E1: Q1 2027 | F1: Q2 2027 | G1: Q3 2027 | H1: Q4 2027 | I1: Q1 2028 | J1: Q2 2028 | K1: Q3 2028 | L1: Q4 2028 | M1: Q1 2029 | N1: Q2 2029 | O1: Q3 2029 | P1: Q4 2029 | Q1: Q1 2030 | R1: Q2 2030 | S1: Q3 2030 | T1: Q4 2030
A2: Billing gross MW ex-Vineland | C2: =MW!D26 | D2: =MW!E26 | E2: =MW!F26 | F2: =MW!G26 | G2: =MW!H26 | H2: =MW!I26 | I2: =MW!J26 | J2: =MW!K26 | ... T2: =MW!U26
A3: Installed-book MW (Q2'26 billing level, at $12M) | C3: =MIN(C2,MW!$C$26) | D3: =MIN(D2,MW!$C$26) | E3: =MIN(E2,MW!$C$26) | F3: =MIN(F2,MW!$C$26) | G3: =MIN(G2,MW!$C$26) | H3: =MIN(H2,MW!$C$26) | I3: =MIN(I2,MW!$C$26) | J3: =MIN(J2,MW!$C$26) | ... T3: =MIN(T2,MW!$C$26)
A4: Incremental MW (at Q2-deal ACV) | C4: =C2-C3 | D4: =D2-D3 | E4: =E2-E3 | F4: =F2-F3 | G4: =G2-G3 | H4: =H2-H3 | I4: =I2-I3 | J4: =J2-J3 | ... T4: =T2-T3
A5: Non-Microsoft revenue | C5: =(C3*Assumptions!$B$44+C4*Assumptions!$B$93)/4*(1+Assumptions!$B$94*Assumptions!$B$95) | D5: =(D3*Assumptions!$B$44+D4*Assumptions!$B$93)/4*(1+Assumptions!$B$94*Assumptions!$B$95) | E5: =(E3*Assumptions!$B$44+E4*Assumptions!$B$93)/4*(1+Assumptions!$B$94*Assumptions!$B$95) | F5: =(F3*Assumptions!$B$44+F4*Assumptions!$B$93)/4*(1+Assumptions!$B$94*Assumptions!$B$95) | G5: =(G3*Assumptions!$B$44+G4*Assumptions!$B$93)/4*(1+Assumptions!$B$94*Assumptions!$B$95) | H5: =(H3*Assumptions!$B$44+H4*Assumptions!$B$93)/4*(1+Assumptions!$B$94*Assumptions!$B$95) | I5: =(I3*Assumptions!$B$44+I4*Assumptions!$B$93)/4*(1+Assumptions!$B$94*Assumptions!$B$95) | J5: =(J3*Assumptions!$B$44+J4*Assumptions!$B$93)/4*(1+Assumptions!$B$94*Assumptions!$B$95) | ... T5: =(T3*Assumptions!$B$44+T4*Assumptions!$B$93)/4*(1+Assumptions!$B$94*Assumptions!$B$95)
A6: Microsoft revenue (Microsoft sheet) | C6: =INDEX(Microsoft!$B$14:$Z$14,MATCH(C$1,Microsoft!$B$13:$Z$13,0)) | D6: =INDEX(Microsoft!$B$14:$Z$14,MATCH(D$1,Microsoft!$B$13:$Z$13,0)) | E6: =INDEX(Microsoft!$B$14:$Z$14,MATCH(E$1,Microsoft!$B$13:$Z$13,0)) | F6: =INDEX(Microsoft!$B$14:$Z$14,MATCH(F$1,Microsoft!$B$13:$Z$13,0)) | G6: =INDEX(Microsoft!$B$14:$Z$14,MATCH(G$1,Microsoft!$B$13:$Z$13,0)) | H6: =INDEX(Microsoft!$B$14:$Z$14,MATCH(H$1,Microsoft!$B$13:$Z$13,0)) | I6: =INDEX(Microsoft!$B$14:$Z$14,MATCH(I$1,Microsoft!$B$13:$Z$13,0)) | J6: =INDEX(Microsoft!$B$14:$Z$14,MATCH(J$1,Microsoft!$B$13:$Z$13,0)) | ... T6: =INDEX(Microsoft!$B$14:$Z$14,MATCH(T$1,Microsoft!$B$13:$Z$13,0))
A7: TOTAL bottom-up revenue | C7: =C5+C6 | D7: =D5+D6 | E7: =E5+E6 | F7: =F5+F6 | G7: =G5+G6 | H7: =H5+H6 | I7: =I5+I6 | J7: =J5+J6 | ... T7: =T5+T6
A8: Blackwell (incremental-MW) revenue, non-Microsoft | C8: =C4*Assumptions!$B$93/4*(1+Assumptions!$B$94*Assumptions!$B$95) | D8: =D4*Assumptions!$B$93/4*(1+Assumptions!$B$94*Assumptions!$B$95) | E8: =E4*Assumptions!$B$93/4*(1+Assumptions!$B$94*Assumptions!$B$95) | F8: =F4*Assumptions!$B$93/4*(1+Assumptions!$B$94*Assumptions!$B$95) | G8: =G4*Assumptions!$B$93/4*(1+Assumptions!$B$94*Assumptions!$B$95) | H8: =H4*Assumptions!$B$93/4*(1+Assumptions!$B$94*Assumptions!$B$95) | I8: =I4*Assumptions!$B$93/4*(1+Assumptions!$B$94*Assumptions!$B$95) | J8: =J4*Assumptions!$B$93/4*(1+Assumptions!$B$94*Assumptions!$B$95) | ... T8: =T4*Assumptions!$B$93/4*(1+Assumptions!$B$94*Assumptions!$B$95)
A9: Price-cycle phase-in (0-100% over 4 qtrs from Rubin launch) | C9: =MIN(1,MAX(0,(0-Assumptions!$B$98+1)/4)) | D9: =MIN(1,MAX(0,(1-Assumptions!$B$98+1)/4)) | E9: =MIN(1,MAX(0,(2-Assumptions!$B$98+1)/4)) | F9: =MIN(1,MAX(0,(3-Assumptions!$B$98+1)/4)) | G9: =MIN(1,MAX(0,(4-Assumptions!$B$98+1)/4)) | H9: =MIN(1,MAX(0,(5-Assumptions!$B$98+1)/4)) | I9: =MIN(1,MAX(0,(6-Assumptions!$B$98+1)/4)) | J9: =MIN(1,MAX(0,(7-Assumptions!$B$98+1)/4)) | K9: =MIN(1,MAX(0,(8-Assumptions!$B$98+1)/4)) | L9: =MIN(1,MAX(0,(9-Assumptions!$B$98+1)/4)) | M9: =MIN(1,MAX(0,(10-Assumptions!$B$98+1)/4)) | N9: =MIN(1,MAX(0,(11-Assumptions!$B$98+1)/4)) | O9: =MIN(1,MAX(0,(12-Assumptions!$B$98+1)/4)) | P9: =MIN(1,MAX(0,(13-Assumptions!$B$98+1)/4)) | Q9: =MIN(1,MAX(0,(14-Assumptions!$B$98+1)/4)) | R9: =MIN(1,MAX(0,(15-Assumptions!$B$98+1)/4)) | S9: =MIN(1,MAX(0,(16-Assumptions!$B$98+1)/4)) | T9: =MIN(1,MAX(0,(17-Assumptions!$B$98+1)/4))
A10: PRICE-CYCLE revenue hit = cut x phase x Blackwell rev x (on-demand + reserved x renewal share) | C10: =-Assumptions!$B$97*C9*C8*(Assumptions!$B$94+Assumptions!$B$99*Assumptions!$B$100) | D10: =-Assumptions!$B$97*D9*D8*(Assumptions!$B$94+Assumptions!$B$99*Assumptions!$B$100) | E10: =-Assumptions!$B$97*E9*E8*(Assumptions!$B$94+Assumptions!$B$99*Assumptions!$B$100) | F10: =-Assumptions!$B$97*F9*F8*(Assumptions!$B$94+Assumptions!$B$99*Assumptions!$B$100) | G10: =-Assumptions!$B$97*G9*G8*(Assumptions!$B$94+Assumptions!$B$99*Assumptions!$B$100) | H10: =-Assumptions!$B$97*H9*H8*(Assumptions!$B$94+Assumptions!$B$99*Assumptions!$B$100) | I10: =-Assumptions!$B$97*I9*I8*(Assumptions!$B$94+Assumptions!$B$99*Assumptions!$B$100) | J10: =-Assumptions!$B$97*J9*J8*(Assumptions!$B$94+Assumptions!$B$99*Assumptions!$B$100) | ... T10: =-Assumptions!$B$97*T9*T8*(Assumptions!$B$94+Assumptions!$B$99*Assumptions!$B$100)
A11: Consensus quarterly revenue (MarketScreener) | C11: 904.1 | D11: 1452 | E11: 2175 | F11: 2646 | G11: 3304 | H11: 4052
A13: FY2027 bottom-up revenue | B13: =SUMPRODUCT(($C$7:$T$7)*(RIGHT($C$1:$T$1,4)="2027"))
A14: FY2027 consensus revenue | B14: 12300
A15: Gap vs consensus | B15: =B13-B14
A16: Gap % | B16: =B15/B14
A17: $/share at constant EV/FY27 revenue (308.69M sh) | B17: =B15*(Assumptions!$B$152/B14)/Assumptions!$B$154
A18: FY2026 H2 bottom-up vs consensus H2 (2,356) | B18: =SUMPRODUCT(($C$7:$T$7)*(RIGHT($C$1:$T$1,4)="2026"))
A19: FY2027 price-cycle revenue hit (= EBITDA hit; costs fixed; 5-yr life unchanged) | B19: =SUMPRODUCT(($C$10:$T$10)*(RIGHT($C$1:$T$1,4)="2027"))
A20: as % of FY27 bottom-up revenue | B20: =B19/$B$13
A21: scaled to FY27 consensus revenue ($12.3B) | B21: =B20*12300
A22: as % of FY27 consensus EBITDA ($6,728M) | B22: =B21/6728
A23: FY2028 price-cycle revenue hit | B23: =SUMPRODUCT(($C$10:$T$10)*(RIGHT($C$1:$T$1,4)="2028"))
A24: Calibration: Q2'26 implied = MW!C ex-Vin (Q1'26 energized ~134 MW) x $12M/4 + MSFT T1+T2 $193M = ~$595M vs $582.3M reported
A25: Oct 1 hike effect = on-demand share 4% x 19% = ~+0.8% of revenue (applied to non-MSFT revenue)

Sheet Model
A1: Fleet quarterly model ($M) | C1: Q3 2026 | D1: Q4 2026 | E1: Q1 2027 | F1: Q2 2027 | G1: Q3 2027 | H1: Q4 2027 | I1: Q1 2028 | J1: Q2 2028 | K1: Q3 2028 | L1: Q4 2028 | M1: Q1 2029 | N1: Q2 2029 | O1: Q3 2029 | P1: Q4 2029 | Q1: Q1 2030 | R1: Q2 2030 | S1: Q3 2030 | T1: Q4 2030
A2: Quarter index (0 = Q3'26) | C2: 0 | D2: 1 | E2: 2 | F2: 3 | G2: 4 | H2: 5 | I2: 6 | J2: 7 | K2: 8 | L2: 9 | M2: 10 | N2: 11 | O2: 12 | P2: 13 | Q2: 14 | R2: 15 | S2: 16 | T2: 17
A3: Fiscal year | C3: 2026 | D3: 2026 | E3: 2027 | F3: 2027 | G3: 2027 | H3: 2027 | I3: 2028 | J3: 2028 | K3: 2028 | L3: 2028 | M3: 2029 | N3: 2029 | O3: 2029 | P3: 2029 | Q3: 2030 | R3: 2030 | S3: 2030 | T3: 2030
A4: Capex - consensus basis (FY26-28; FY29-30 extrapolated) | C4: =(Assumptions!$B$108-Assumptions!$B$109)/2 | D4: =(Assumptions!$B$108-Assumptions!$B$109)/2 | E4: =Assumptions!$B$110/4 | F4: =Assumptions!$B$110/4 | G4: =Assumptions!$B$110/4 | H4: =Assumptions!$B$110/4 | I4: =Assumptions!$B$111*Assumptions!$B$116 | J4: =Assumptions!$B$111*Assumptions!$B$117 | K4: =Assumptions!$B$111*Assumptions!$B$118 | L4: =Assumptions!$B$111*Assumptions!$B$119 | M4: =Assumptions!$B$111*(1+Assumptions!$B$112)/4 | N4: =Assumptions!$B$111*(1+Assumptions!$B$112)/4 | O4: =Assumptions!$B$111*(1+Assumptions!$B$112)/4 | P4: =Assumptions!$B$111*(1+Assumptions!$B$112)/4 | Q4: =Assumptions!$B$111*(1+Assumptions!$B$112)*(1+Assumptions!$B$113)/4 | R4: =Assumptions!$B$111*(1+Assumptions!$B$112)*(1+Assumptions!$B$113)/4 | S4: =Assumptions!$B$111*(1+Assumptions!$B$112)*(1+Assumptions!$B$113)/4 | T4: =Assumptions!$B$111*(1+Assumptions!$B$112)*(1+Assumptions!$B$113)/4
A5: Owned share of capex (FY energized additions, Capacity tracker) | C5: =CHOOSE(Assumptions!$B$79,IFERROR(IF(MW!E15-MW!C15>0,(MW!E18-MW!C18)/(MW!E15-MW!C15),MW!E18/MW!E15),0),0,1) | D5: =CHOOSE(Assumptions!$B$79,IFERROR(IF(MW!E15-MW!C15>0,(MW!E18-MW!C18)/(MW!E15-MW!C15),MW!E18/MW!E15),0),0,1) | E5: =CHOOSE(Assumptions!$B$79,IFERROR(IF(MW!I15-MW!E15>0,(MW!I18-MW!E18)/(MW!I15-MW!E15),MW!I18/MW!I15),0),0,1) | F5: =CHOOSE(Assumptions!$B$79,IFERROR(IF(MW!I15-MW!E15>0,(MW!I18-MW!E18)/(MW!I15-MW!E15),MW!I18/MW!I15),0),0,1) | G5: =CHOOSE(Assumptions!$B$79,IFERROR(IF(MW!I15-MW!E15>0,(MW!I18-MW!E18)/(MW!I15-MW!E15),MW!I18/MW!I15),0),0,1) | H5: =CHOOSE(Assumptions!$B$79,IFERROR(IF(MW!I15-MW!E15>0,(MW!I18-MW!E18)/(MW!I15-MW!E15),MW!I18/MW!I15),0),0,1) | I5: =CHOOSE(Assumptions!$B$79,IFERROR(IF(MW!M15-MW!I15>0,(MW!M18-MW!I18)/(MW!M15-MW!I15),MW!M18/MW!M15),0),0,1) | J5: =CHOOSE(Assumptions!$B$79,IFERROR(IF(MW!M15-MW!I15>0,(MW!M18-MW!I18)/(MW!M15-MW!I15),MW!M18/MW!M15),0),0,1) | K5: =CHOOSE(Assumptions!$B$79,IFERROR(IF(MW!M15-MW!I15>0,(MW!M18-MW!I18)/(MW!M15-MW!I15),MW!M18/MW!M15),0),0,1) | L5: =CHOOSE(Assumptions!$B$79,IFERROR(IF(MW!M15-MW!I15>0,(MW!M18-MW!I18)/(MW!M15-MW!I15),MW!M18/MW!M15),0),0,1) | M5: =CHOOSE(Assumptions!$B$79,IFERROR(IF(MW!Q15-MW!M15>0,(MW!Q18-MW!M18)/(MW!Q15-MW!M15),MW!Q18/MW!Q15),0),0,1) | N5: =CHOOSE(Assumptions!$B$79,IFERROR(IF(MW!Q15-MW!M15>0,(MW!Q18-MW!M18)/(MW!Q15-MW!M15),MW!Q18/MW!Q15),0),0,1) | O5: =CHOOSE(Assumptions!$B$79,IFERROR(IF(MW!Q15-MW!M15>0,(MW!Q18-MW!M18)/(MW!Q15-MW!M15),MW!Q18/MW!Q15),0),0,1) | P5: =CHOOSE(Assumptions!$B$79,IFERROR(IF(MW!Q15-MW!M15>0,(MW!Q18-MW!M18)/(MW!Q15-MW!M15),MW!Q18/MW!Q15),0),0,1) | Q5: =CHOOSE(Assumptions!$B$79,IFERROR(IF(MW!U15-MW!Q15>0,(MW!U18-MW!Q18)/(MW!U15-MW!Q15),MW!U18/MW!U15),0),0,1) | R5: =CHOOSE(Assumptions!$B$79,IFERROR(IF(MW!U15-MW!Q15>0,(MW!U18-MW!Q18)/(MW!U15-MW!Q15),MW!U18/MW!U15),0),0,1) | S5: =CHOOSE(Assumptions!$B$79,IFERROR(IF(MW!U15-MW!Q15>0,(MW!U18-MW!Q18)/(MW!U15-MW!Q15),MW!U18/MW!U15),0),0,1) | T5: =CHOOSE(Assumptions!$B$79,IFERROR(IF(MW!U15-MW!Q15>0,(MW!U18-MW!Q18)/(MW!U15-MW!Q15),MW!U18/MW!U15),0),0,1)
A6: GPU+network share of capex (consensus basis) | C6: =Assumptions!$B$80 | D6: =Assumptions!$B$80 | E6: =IF(E2>=Assumptions!$B$81,Assumptions!$B$29,Assumptions!$B$25)/(IF(E2>=Assumptions!$B$81,Assumptions!$B$29,Assumptions!$B$25)+E5*IF(E2>=Assumptions!$B$81,Assumptions!$B$30,Assumptions!$B$26)+(1-E5)*(IF(E2>=Assumptions!$B$81,Assumptions!$B$31,Assumptions!$B$27)-IF(E2>=Assumptions!$B$81,Assumptions!$B$29,Assumptions!$B$25))) | F6: =IF(F2>=Assumptions!$B$81,Assumptions!$B$29,Assumptions!$B$25)/(IF(F2>=Assumptions!$B$81,Assumptions!$B$29,Assumptions!$B$25)+F5*IF(F2>=Assumptions!$B$81,Assumptions!$B$30,Assumptions!$B$26)+(1-F5)*(IF(F2>=Assumptions!$B$81,Assumptions!$B$31,Assumptions!$B$27)-IF(F2>=Assumptions!$B$81,Assumptions!$B$29,Assumptions!$B$25))) | G6: =IF(G2>=Assumptions!$B$81,Assumptions!$B$29,Assumptions!$B$25)/(IF(G2>=Assumptions!$B$81,Assumptions!$B$29,Assumptions!$B$25)+G5*IF(G2>=Assumptions!$B$81,Assumptions!$B$30,Assumptions!$B$26)+(1-G5)*(IF(G2>=Assumptions!$B$81,Assumptions!$B$31,Assumptions!$B$27)-IF(G2>=Assumptions!$B$81,Assumptions!$B$29,Assumptions!$B$25))) | H6: =IF(H2>=Assumptions!$B$81,Assumptions!$B$29,Assumptions!$B$25)/(IF(H2>=Assumptions!$B$81,Assumptions!$B$29,Assumptions!$B$25)+H5*IF(H2>=Assumptions!$B$81,Assumptions!$B$30,Assumptions!$B$26)+(1-H5)*(IF(H2>=Assumptions!$B$81,Assumptions!$B$31,Assumptions!$B$27)-IF(H2>=Assumptions!$B$81,Assumptions!$B$29,Assumptions!$B$25))) | I6: =IF(I2>=Assumptions!$B$81,Assumptions!$B$29,Assumptions!$B$25)/(IF(I2>=Assumptions!$B$81,Assumptions!$B$29,Assumptions!$B$25)+I5*IF(I2>=Assumptions!$B$81,Assumptions!$B$30,Assumptions!$B$26)+(1-I5)*(IF(I2>=Assumptions!$B$81,Assumptions!$B$31,Assumptions!$B$27)-IF(I2>=Assumptions!$B$81,Assumptions!$B$29,Assumptions!$B$25))) | J6: =IF(J2>=Assumptions!$B$81,Assumptions!$B$29,Assumptions!$B$25)/(IF(J2>=Assumptions!$B$81,Assumptions!$B$29,Assumptions!$B$25)+J5*IF(J2>=Assumptions!$B$81,Assumptions!$B$30,Assumptions!$B$26)+(1-J5)*(IF(J2>=Assumptions!$B$81,Assumptions!$B$31,Assumptions!$B$27)-IF(J2>=Assumptions!$B$81,Assumptions!$B$29,Assumptions!$B$25))) | K6: =IF(K2>=Assumptions!$B$81,Assumptions!$B$29,Assumptions!$B$25)/(IF(K2>=Assumptions!$B$81,Assumptions!$B$29,Assumptions!$B$25)+K5*IF(K2>=Assumptions!$B$81,Assumptions!$B$30,Assumptions!$B$26)+(1-K5)*(IF(K2>=Assumptions!$B$81,Assumptions!$B$31,Assumptions!$B$27)-IF(K2>=Assumptions!$B$81,Assumptions!$B$29,Assumptions!$B$25))) | L6: =IF(L2>=Assumptions!$B$81,Assumptions!$B$29,Assumptions!$B$25)/(IF(L2>=Assumptions!$B$81,Assumptions!$B$29,Assumptions!$B$25)+L5*IF(L2>=Assumptions!$B$81,Assumptions!$B$30,Assumptions!$B$26)+(1-L5)*(IF(L2>=Assumptions!$B$81,Assumptions!$B$31,Assumptions!$B$27)-IF(L2>=Assumptions!$B$81,Assumptions!$B$29,Assumptions!$B$25))) | ... T6: =IF(T2>=Assumptions!$B$81,Assumptions!$B$29,Assumptions!$B$25)/(IF(T2>=Assumptions!$B$81,Assumptions!$B$29,Assumptions!$B$25)+T5*IF(T2>=Assumptions!$B$81,Assumptions!$B$30,Assumptions!$B$26)+(1-T5)*(IF(T2>=Assumptions!$B$81,Assumptions!$B$31,Assumptions!$B$27)-IF(T2>=Assumptions!$B$81,Assumptions!$B$29,Assumptions!$B$25)))
A7: Path: IT MW whose GPUs are bought this qtr (energized at t + lagb - pglag) | C7: =IF((C2+1+Assumptions!$B$90-Assumptions!$B$85)+1<=19,INDEX(MW!$C$23:$U$23,(C2+1+Assumptions!$B$90-Assumptions!$B$85)+1),AVERAGE(MW!$R$23:$U$23)) | D7: =IF((D2+1+Assumptions!$B$90-Assumptions!$B$85)+1<=19,INDEX(MW!$C$23:$U$23,(D2+1+Assumptions!$B$90-Assumptions!$B$85)+1),AVERAGE(MW!$R$23:$U$23)) | E7: =IF((E2+1+Assumptions!$B$90-Assumptions!$B$85)+1<=19,INDEX(MW!$C$23:$U$23,(E2+1+Assumptions!$B$90-Assumptions!$B$85)+1),AVERAGE(MW!$R$23:$U$23)) | F7: =IF((F2+1+Assumptions!$B$90-Assumptions!$B$85)+1<=19,INDEX(MW!$C$23:$U$23,(F2+1+Assumptions!$B$90-Assumptions!$B$85)+1),AVERAGE(MW!$R$23:$U$23)) | G7: =IF((G2+1+Assumptions!$B$90-Assumptions!$B$85)+1<=19,INDEX(MW!$C$23:$U$23,(G2+1+Assumptions!$B$90-Assumptions!$B$85)+1),AVERAGE(MW!$R$23:$U$23)) | H7: =IF((H2+1+Assumptions!$B$90-Assumptions!$B$85)+1<=19,INDEX(MW!$C$23:$U$23,(H2+1+Assumptions!$B$90-Assumptions!$B$85)+1),AVERAGE(MW!$R$23:$U$23)) | I7: =IF((I2+1+Assumptions!$B$90-Assumptions!$B$85)+1<=19,INDEX(MW!$C$23:$U$23,(I2+1+Assumptions!$B$90-Assumptions!$B$85)+1),AVERAGE(MW!$R$23:$U$23)) | J7: =IF((J2+1+Assumptions!$B$90-Assumptions!$B$85)+1<=19,INDEX(MW!$C$23:$U$23,(J2+1+Assumptions!$B$90-Assumptions!$B$85)+1),AVERAGE(MW!$R$23:$U$23)) | ... T7: =IF((T2+1+Assumptions!$B$90-Assumptions!$B$85)+1<=19,INDEX(MW!$C$23:$U$23,(T2+1+Assumptions!$B$90-Assumptions!$B$85)+1),AVERAGE(MW!$R$23:$U$23))
A8: Path: IT MW whose shell is built this qtr (energized at t + shlag) | C8: =IF((C2+1+Assumptions!$B$86)+1<=19,INDEX(MW!$C$23:$U$23,(C2+1+Assumptions!$B$86)+1),AVERAGE(MW!$R$23:$U$23)) | D8: =IF((D2+1+Assumptions!$B$86)+1<=19,INDEX(MW!$C$23:$U$23,(D2+1+Assumptions!$B$86)+1),AVERAGE(MW!$R$23:$U$23)) | E8: =IF((E2+1+Assumptions!$B$86)+1<=19,INDEX(MW!$C$23:$U$23,(E2+1+Assumptions!$B$86)+1),AVERAGE(MW!$R$23:$U$23)) | F8: =IF((F2+1+Assumptions!$B$86)+1<=19,INDEX(MW!$C$23:$U$23,(F2+1+Assumptions!$B$86)+1),AVERAGE(MW!$R$23:$U$23)) | G8: =IF((G2+1+Assumptions!$B$86)+1<=19,INDEX(MW!$C$23:$U$23,(G2+1+Assumptions!$B$86)+1),AVERAGE(MW!$R$23:$U$23)) | H8: =IF((H2+1+Assumptions!$B$86)+1<=19,INDEX(MW!$C$23:$U$23,(H2+1+Assumptions!$B$86)+1),AVERAGE(MW!$R$23:$U$23)) | I8: =IF((I2+1+Assumptions!$B$86)+1<=19,INDEX(MW!$C$23:$U$23,(I2+1+Assumptions!$B$86)+1),AVERAGE(MW!$R$23:$U$23)) | J8: =IF((J2+1+Assumptions!$B$86)+1<=19,INDEX(MW!$C$23:$U$23,(J2+1+Assumptions!$B$86)+1),AVERAGE(MW!$R$23:$U$23)) | ... T8: =IF((T2+1+Assumptions!$B$86)+1<=19,INDEX(MW!$C$23:$U$23,(T2+1+Assumptions!$B$86)+1),AVERAGE(MW!$R$23:$U$23))
A9: Path: GPU/IT capex (owned: GPU+net by gen; leased: leased $/IT MW by gen - GB300 before VR switch, VR after) | C9: =C7*(C5*IF(C2>=Assumptions!$B$81,Assumptions!$B$29,Assumptions!$B$25)+(1-C5)*IF(C2>=Assumptions!$B$81,Assumptions!$B$89,Assumptions!$B$88)) | D9: =D7*(D5*IF(D2>=Assumptions!$B$81,Assumptions!$B$29,Assumptions!$B$25)+(1-D5)*IF(D2>=Assumptions!$B$81,Assumptions!$B$89,Assumptions!$B$88)) | E9: =E7*(E5*IF(E2>=Assumptions!$B$81,Assumptions!$B$29,Assumptions!$B$25)+(1-E5)*IF(E2>=Assumptions!$B$81,Assumptions!$B$89,Assumptions!$B$88)) | F9: =F7*(F5*IF(F2>=Assumptions!$B$81,Assumptions!$B$29,Assumptions!$B$25)+(1-F5)*IF(F2>=Assumptions!$B$81,Assumptions!$B$89,Assumptions!$B$88)) | G9: =G7*(G5*IF(G2>=Assumptions!$B$81,Assumptions!$B$29,Assumptions!$B$25)+(1-G5)*IF(G2>=Assumptions!$B$81,Assumptions!$B$89,Assumptions!$B$88)) | H9: =H7*(H5*IF(H2>=Assumptions!$B$81,Assumptions!$B$29,Assumptions!$B$25)+(1-H5)*IF(H2>=Assumptions!$B$81,Assumptions!$B$89,Assumptions!$B$88)) | I9: =I7*(I5*IF(I2>=Assumptions!$B$81,Assumptions!$B$29,Assumptions!$B$25)+(1-I5)*IF(I2>=Assumptions!$B$81,Assumptions!$B$89,Assumptions!$B$88)) | J9: =J7*(J5*IF(J2>=Assumptions!$B$81,Assumptions!$B$29,Assumptions!$B$25)+(1-J5)*IF(J2>=Assumptions!$B$81,Assumptions!$B$89,Assumptions!$B$88)) | ... T9: =T7*(T5*IF(T2>=Assumptions!$B$81,Assumptions!$B$29,Assumptions!$B$25)+(1-T5)*IF(T2>=Assumptions!$B$81,Assumptions!$B$89,Assumptions!$B$88))
A10: Path: shell/power capex (owned share only) | C10: =C8*C5*IF(C2>=Assumptions!$B$81,Assumptions!$B$30,Assumptions!$B$26) | D10: =D8*D5*IF(D2>=Assumptions!$B$81,Assumptions!$B$30,Assumptions!$B$26) | E10: =E8*E5*IF(E2>=Assumptions!$B$81,Assumptions!$B$30,Assumptions!$B$26) | F10: =F8*F5*IF(F2>=Assumptions!$B$81,Assumptions!$B$30,Assumptions!$B$26) | G10: =G8*G5*IF(G2>=Assumptions!$B$81,Assumptions!$B$30,Assumptions!$B$26) | H10: =H8*H5*IF(H2>=Assumptions!$B$81,Assumptions!$B$30,Assumptions!$B$26) | I10: =I8*I5*IF(I2>=Assumptions!$B$81,Assumptions!$B$30,Assumptions!$B$26) | J10: =J8*J5*IF(J2>=Assumptions!$B$81,Assumptions!$B$30,Assumptions!$B$26) | ... T10: =T8*T5*IF(T2>=Assumptions!$B$81,Assumptions!$B$30,Assumptions!$B$26)
A11: Capex - path-consistent basis | C11: =C9+C10 | D11: =D9+D10 | E11: =E9+E10 | F11: =F9+F10 | G11: =G9+G10 | H11: =H9+H10 | I11: =I9+I10 | J11: =J9+J10 | ... T11: =T9+T10
A12: CAPEX USED (basis toggle) | C12: =IF(Assumptions!$B$84=1,C4,C11) | D12: =IF(Assumptions!$B$84=1,D4,D11) | E12: =IF(Assumptions!$B$84=1,E4,E11) | F12: =IF(Assumptions!$B$84=1,F4,F11) | G12: =IF(Assumptions!$B$84=1,G4,G11) | H12: =IF(Assumptions!$B$84=1,H4,H11) | I12: =IF(Assumptions!$B$84=1,I4,I11) | J12: =IF(Assumptions!$B$84=1,J4,J11) | ... T12: =IF(Assumptions!$B$84=1,T4,T11)
A13: Capex-implied IT MW bought (consensus capex / all-in $ per IT MW) | C13: =C4/(IF(C2>=Assumptions!$B$81,Assumptions!$B$29,Assumptions!$B$25)+C5*IF(C2>=Assumptions!$B$81,Assumptions!$B$30,Assumptions!$B$26)+(1-C5)*(IF(C2>=Assumptions!$B$81,Assumptions!$B$31,Assumptions!$B$27)-IF(C2>=Assumptions!$B$81,Assumptions!$B$29,Assumptions!$B$25))) | D13: =D4/(IF(D2>=Assumptions!$B$81,Assumptions!$B$29,Assumptions!$B$25)+D5*IF(D2>=Assumptions!$B$81,Assumptions!$B$30,Assumptions!$B$26)+(1-D5)*(IF(D2>=Assumptions!$B$81,Assumptions!$B$31,Assumptions!$B$27)-IF(D2>=Assumptions!$B$81,Assumptions!$B$29,Assumptions!$B$25))) | E13: =E4/(IF(E2>=Assumptions!$B$81,Assumptions!$B$29,Assumptions!$B$25)+E5*IF(E2>=Assumptions!$B$81,Assumptions!$B$30,Assumptions!$B$26)+(1-E5)*(IF(E2>=Assumptions!$B$81,Assumptions!$B$31,Assumptions!$B$27)-IF(E2>=Assumptions!$B$81,Assumptions!$B$29,Assumptions!$B$25))) | F13: =F4/(IF(F2>=Assumptions!$B$81,Assumptions!$B$29,Assumptions!$B$25)+F5*IF(F2>=Assumptions!$B$81,Assumptions!$B$30,Assumptions!$B$26)+(1-F5)*(IF(F2>=Assumptions!$B$81,Assumptions!$B$31,Assumptions!$B$27)-IF(F2>=Assumptions!$B$81,Assumptions!$B$29,Assumptions!$B$25))) | G13: =G4/(IF(G2>=Assumptions!$B$81,Assumptions!$B$29,Assumptions!$B$25)+G5*IF(G2>=Assumptions!$B$81,Assumptions!$B$30,Assumptions!$B$26)+(1-G5)*(IF(G2>=Assumptions!$B$81,Assumptions!$B$31,Assumptions!$B$27)-IF(G2>=Assumptions!$B$81,Assumptions!$B$29,Assumptions!$B$25))) | H13: =H4/(IF(H2>=Assumptions!$B$81,Assumptions!$B$29,Assumptions!$B$25)+H5*IF(H2>=Assumptions!$B$81,Assumptions!$B$30,Assumptions!$B$26)+(1-H5)*(IF(H2>=Assumptions!$B$81,Assumptions!$B$31,Assumptions!$B$27)-IF(H2>=Assumptions!$B$81,Assumptions!$B$29,Assumptions!$B$25))) | I13: =I4/(IF(I2>=Assumptions!$B$81,Assumptions!$B$29,Assumptions!$B$25)+I5*IF(I2>=Assumptions!$B$81,Assumptions!$B$30,Assumptions!$B$26)+(1-I5)*(IF(I2>=Assumptions!$B$81,Assumptions!$B$31,Assumptions!$B$27)-IF(I2>=Assumptions!$B$81,Assumptions!$B$29,Assumptions!$B$25))) | J13: =J4/(IF(J2>=Assumptions!$B$81,Assumptions!$B$29,Assumptions!$B$25)+J5*IF(J2>=Assumptions!$B$81,Assumptions!$B$30,Assumptions!$B$26)+(1-J5)*(IF(J2>=Assumptions!$B$81,Assumptions!$B$31,Assumptions!$B$27)-IF(J2>=Assumptions!$B$81,Assumptions!$B$29,Assumptions!$B$25))) | ... T13: =T4/(IF(T2>=Assumptions!$B$81,Assumptions!$B$29,Assumptions!$B$25)+T5*IF(T2>=Assumptions!$B$81,Assumptions!$B$30,Assumptions!$B$26)+(1-T5)*(IF(T2>=Assumptions!$B$81,Assumptions!$B$31,Assumptions!$B$27)-IF(T2>=Assumptions!$B$81,Assumptions!$B$29,Assumptions!$B$25)))
A14: GPU+network capex | C14: =IF(Assumptions!$B$84=1,C12*C6,C9) | D14: =IF(Assumptions!$B$84=1,D12*D6,D9) | E14: =IF(Assumptions!$B$84=1,E12*E6,E9) | F14: =IF(Assumptions!$B$84=1,F12*F6,F9) | G14: =IF(Assumptions!$B$84=1,G12*G6,G9) | H14: =IF(Assumptions!$B$84=1,H12*H6,H9) | I14: =IF(Assumptions!$B$84=1,I12*I6,I9) | J14: =IF(Assumptions!$B$84=1,J12*J6,J9) | ... T14: =IF(Assumptions!$B$84=1,T12*T6,T9)
A15: Shell/power/fit-out capex | C15: =C12-C14 | D15: =D12-D14 | E15: =E12-E14 | F15: =F12-F14 | G15: =G12-G14 | H15: =H12-H14 | I15: =I12-I14 | J15: =J12-J14 | ... T15: =T12-T14
A16: Effective capex->in-service lag for GPUs (consensus: lage; path: lagb - pglag) | B16: =IF(Assumptions!$B$84=1,Assumptions!$B$83,MAX(0,Assumptions!$B$90-Assumptions!$B$85))
A17: GPU+network placed in service (capex lagged by capex->energized; 6/30 not-in-use first) | C17: =Assumptions!$B$105*Assumptions!$B$80*Assumptions!$B$106 | D17: =Assumptions!$B$105*Assumptions!$B$80*(1-Assumptions!$B$106) | E17: =IF(E2>=$B$16,INDEX($C$14:$T$14,E2-$B$16+1),0) | F17: =IF(F2>=$B$16,INDEX($C$14:$T$14,F2-$B$16+1),0) | G17: =IF(G2>=$B$16,INDEX($C$14:$T$14,G2-$B$16+1),0) | H17: =IF(H2>=$B$16,INDEX($C$14:$T$14,H2-$B$16+1),0) | I17: =IF(I2>=$B$16,INDEX($C$14:$T$14,I2-$B$16+1),0) | J17: =IF(J2>=$B$16,INDEX($C$14:$T$14,J2-$B$16+1),0) | K17: =IF(K2>=$B$16,INDEX($C$14:$T$14,K2-$B$16+1),0) | L17: =IF(L2>=$B$16,INDEX($C$14:$T$14,L2-$B$16+1),0) | ... T17: =IF(T2>=$B$16,INDEX($C$14:$T$14,T2-$B$16+1),0)
A18: Non-GPU placed in service | C18: =Assumptions!$B$105*(1-Assumptions!$B$80)*Assumptions!$B$106 | D18: =Assumptions!$B$105*(1-Assumptions!$B$80)*(1-Assumptions!$B$106) | E18: =IF(E2>=Assumptions!$B$83,INDEX($C$15:$T$15,E2-Assumptions!$B$83+1),0) | F18: =IF(F2>=Assumptions!$B$83,INDEX($C$15:$T$15,F2-Assumptions!$B$83+1),0) | G18: =IF(G2>=Assumptions!$B$83,INDEX($C$15:$T$15,G2-Assumptions!$B$83+1),0) | H18: =IF(H2>=Assumptions!$B$83,INDEX($C$15:$T$15,H2-Assumptions!$B$83+1),0) | I18: =IF(I2>=Assumptions!$B$83,INDEX($C$15:$T$15,I2-Assumptions!$B$83+1),0) | J18: =IF(J2>=Assumptions!$B$83,INDEX($C$15:$T$15,J2-Assumptions!$B$83+1),0) | K18: =IF(K2>=Assumptions!$B$83,INDEX($C$15:$T$15,K2-Assumptions!$B$83+1),0) | L18: =IF(L2>=Assumptions!$B$83,INDEX($C$15:$T$15,L2-Assumptions!$B$83+1),0) | ... T18: =IF(T2>=Assumptions!$B$83,INDEX($C$15:$T$15,T2-Assumptions!$B$83+1),0)
A19: Gross GPU+network in service (end of qtr) | C19: =Assumptions!$B$102+SUM($C$17:C17) | D19: =Assumptions!$B$102+SUM($C$17:D17) | E19: =Assumptions!$B$102+SUM($C$17:E17) | F19: =Assumptions!$B$102+SUM($C$17:F17) | G19: =Assumptions!$B$102+SUM($C$17:G17) | H19: =Assumptions!$B$102+SUM($C$17:H17) | I19: =Assumptions!$B$102+SUM($C$17:I17) | J19: =Assumptions!$B$102+SUM($C$17:J17) | ... T19: =Assumptions!$B$102+SUM($C$17:T17)
A20: Gross GPU+network BILLING (in service lagged by energized->billing) | C20: =IF(C2>=Assumptions!$B$90,INDEX($C$19:$T$19,C2-Assumptions!$B$90+1),Assumptions!$B$102) | D20: =IF(D2>=Assumptions!$B$90,INDEX($C$19:$T$19,D2-Assumptions!$B$90+1),Assumptions!$B$102) | E20: =IF(E2>=Assumptions!$B$90,INDEX($C$19:$T$19,E2-Assumptions!$B$90+1),Assumptions!$B$102) | F20: =IF(F2>=Assumptions!$B$90,INDEX($C$19:$T$19,F2-Assumptions!$B$90+1),Assumptions!$B$102) | G20: =IF(G2>=Assumptions!$B$90,INDEX($C$19:$T$19,G2-Assumptions!$B$90+1),Assumptions!$B$102) | H20: =IF(H2>=Assumptions!$B$90,INDEX($C$19:$T$19,H2-Assumptions!$B$90+1),Assumptions!$B$102) | I20: =IF(I2>=Assumptions!$B$90,INDEX($C$19:$T$19,I2-Assumptions!$B$90+1),Assumptions!$B$102) | J20: =IF(J2>=Assumptions!$B$90,INDEX($C$19:$T$19,J2-Assumptions!$B$90+1),Assumptions!$B$102) | ... T20: =IF(T2>=Assumptions!$B$90,INDEX($C$19:$T$19,T2-Assumptions!$B$90+1),Assumptions!$B$102)
A21: Gross non-GPU in service | C21: =Assumptions!$B$104+SUM($C$18:C18) | D21: =Assumptions!$B$104+SUM($C$18:D18) | E21: =Assumptions!$B$104+SUM($C$18:E18) | F21: =Assumptions!$B$104+SUM($C$18:F18) | G21: =Assumptions!$B$104+SUM($C$18:G18) | H21: =Assumptions!$B$104+SUM($C$18:H18) | I21: =Assumptions!$B$104+SUM($C$18:I18) | J21: =Assumptions!$B$104+SUM($C$18:J18) | ... T21: =Assumptions!$B$104+SUM($C$18:T18)
A22: GPU+network D&A at life L1 | C22: =IF(C2<(4*Assumptions!$B$3)-Assumptions!$B$103,Assumptions!$B$102/(4*Assumptions!$B$3),0)+SUMPRODUCT($C$17:C17,(((C2-$C$2:C2)=0)*0.5+(((C2-$C$2:C2)>0)*((C2-$C$2:C2)<(4*Assumptions!$B$3)))+(((C2-$C$2:C2)=(4*Assumptions!$B$3))*0.5))/(4*Assumptions!$B$3)) | D22: =IF(D2<(4*Assumptions!$B$3)-Assumptions!$B$103,Assumptions!$B$102/(4*Assumptions!$B$3),0)+SUMPRODUCT($C$17:D17,(((D2-$C$2:D2)=0)*0.5+(((D2-$C$2:D2)>0)*((D2-$C$2:D2)<(4*Assumptions!$B$3)))+(((D2-$C$2:D2)=(4*Assumptions!$B$3))*0.5))/(4*Assumptions!$B$3)) | E22: =IF(E2<(4*Assumptions!$B$3)-Assumptions!$B$103,Assumptions!$B$102/(4*Assumptions!$B$3),0)+SUMPRODUCT($C$17:E17,(((E2-$C$2:E2)=0)*0.5+(((E2-$C$2:E2)>0)*((E2-$C$2:E2)<(4*Assumptions!$B$3)))+(((E2-$C$2:E2)=(4*Assumptions!$B$3))*0.5))/(4*Assumptions!$B$3)) | F22: =IF(F2<(4*Assumptions!$B$3)-Assumptions!$B$103,Assumptions!$B$102/(4*Assumptions!$B$3),0)+SUMPRODUCT($C$17:F17,(((F2-$C$2:F2)=0)*0.5+(((F2-$C$2:F2)>0)*((F2-$C$2:F2)<(4*Assumptions!$B$3)))+(((F2-$C$2:F2)=(4*Assumptions!$B$3))*0.5))/(4*Assumptions!$B$3)) | G22: =IF(G2<(4*Assumptions!$B$3)-Assumptions!$B$103,Assumptions!$B$102/(4*Assumptions!$B$3),0)+SUMPRODUCT($C$17:G17,(((G2-$C$2:G2)=0)*0.5+(((G2-$C$2:G2)>0)*((G2-$C$2:G2)<(4*Assumptions!$B$3)))+(((G2-$C$2:G2)=(4*Assumptions!$B$3))*0.5))/(4*Assumptions!$B$3)) | H22: =IF(H2<(4*Assumptions!$B$3)-Assumptions!$B$103,Assumptions!$B$102/(4*Assumptions!$B$3),0)+SUMPRODUCT($C$17:H17,(((H2-$C$2:H2)=0)*0.5+(((H2-$C$2:H2)>0)*((H2-$C$2:H2)<(4*Assumptions!$B$3)))+(((H2-$C$2:H2)=(4*Assumptions!$B$3))*0.5))/(4*Assumptions!$B$3)) | I22: =IF(I2<(4*Assumptions!$B$3)-Assumptions!$B$103,Assumptions!$B$102/(4*Assumptions!$B$3),0)+SUMPRODUCT($C$17:I17,(((I2-$C$2:I2)=0)*0.5+(((I2-$C$2:I2)>0)*((I2-$C$2:I2)<(4*Assumptions!$B$3)))+(((I2-$C$2:I2)=(4*Assumptions!$B$3))*0.5))/(4*Assumptions!$B$3)) | J22: =IF(J2<(4*Assumptions!$B$3)-Assumptions!$B$103,Assumptions!$B$102/(4*Assumptions!$B$3),0)+SUMPRODUCT($C$17:J17,(((J2-$C$2:J2)=0)*0.5+(((J2-$C$2:J2)>0)*((J2-$C$2:J2)<(4*Assumptions!$B$3)))+(((J2-$C$2:J2)=(4*Assumptions!$B$3))*0.5))/(4*Assumptions!$B$3)) | ... T22: =IF(T2<(4*Assumptions!$B$3)-Assumptions!$B$103,Assumptions!$B$102/(4*Assumptions!$B$3),0)+SUMPRODUCT($C$17:T17,(((T2-$C$2:T2)=0)*0.5+(((T2-$C$2:T2)>0)*((T2-$C$2:T2)<(4*Assumptions!$B$3)))+(((T2-$C$2:T2)=(4*Assumptions!$B$3))*0.5))/(4*Assumptions!$B$3))
