Workbook

Sheet Legend
A1: 03_depreciation.xlsx - Nebius Skeptic (Red Team). Built 2026-10-04 ET.
A2: Blue font/shaded = hard-coded input (sourced or assumption, see Assumptions col D/E). Black = formula.
A3: Cohort/vintage method: each quarter's GPU placed-in-service amount is a cohort depreciated straight-line over 4/5/6 yrs (half-quarter convention). 6/30/26 in-service base depreciated over remaining life (life - avg age).
A4: EBITDA is consensus through FY28 (MarketScreener), then extrapolated as FY28-implied EBITDA yield x gross GPU in service. Capex FY26-28 consensus, flat thereafter (input).
A5: FCF ignores working capital/prepayments (Q2'26 OCF +$2.25B was prepayment-driven), taxes (NOLs), SBC and lease payments. Book life changes EBIT, not cash; it matters for value through the replacement capex needed at the true economic life (Reverse_DCF).
A6: Sheets: Assumptions, Model (quarterly Q3'26-Q4'30), Annual, Horizons (6m/1y/3y), Reverse_DCF, Peers, Charts.

Sheet Assumptions
A1: Input | B1: Value | C1: Unit | D1: Tag | E1: Source / note
A2: Useful lives (scenario columns on Model sheet)
A3: Life scenario A (yrs) - Nebius pre-2026 policy | B3: 4 | C3: yrs | D3: Reported (policy) | E3: https://www.sec.gov/Archives/edgar/data/1513845/000110465926052948/nbis-20251231x20f.htm Note 2: server & network 4.0 yrs (FY2025)
A4: Life scenario B (yrs) - Nebius stated policy from 1/1/26 | B4: 5 | C4: yrs | D4: Reported (policy) | E4: https://www.sec.gov/Archives/edgar/data/1513845/000110465926094844/nbis-20260812xex99d2.htm Note 1 p.F-10; /workspace/nebius/filings/nebius_fact_base.md
A5: Life scenario C (yrs) - CoreWeave/Alphabet/Oracle-style | B5: 6 | C5: yrs | D5: Reported (peer policy) | E5: See Peers sheet
A6: Non-GPU (DC/infra) blended life | B6: 12 | C6: yrs | D6: Estimated | E6: Nebius: buildings 20y, infrastructure 3-10y, other 2-10y (20-F Note 2); 12y blended is an assumption
A7: Asset base at 30-Jun-2026 (Reported)
A8: Server & network equipment, gross, in service | B8: 5197.7 | C8: $M | D8: Reported | E8: https://www.sec.gov/Archives/edgar/data/1513845/000110465926094844/nbis-20260812xex99d2.htm Note 7
A9: Avg age of in-service server base at 6/30/26 | B9: 4 | C9: quarters | D9: Estimated | E9: 60% of gross added in 2025, 40% in 1H26 (Note 7 gross 3,123.6 YE25 -> 5,197.7) => ~4 qtrs
A10: Other in-service PP&E gross (infra 332.5 + other 189.5 + land/bldg 593.4) | B10: 1115.4 | C10: $M | D10: Reported (sum) | E10: https://www.sec.gov/Archives/edgar/data/1513845/000110465926094844/nbis-20260812xex99d2.htm Note 7; land not separately split - depreciated anyway (slightly overstates D&A)
A11: Assets not yet in use | B11: 7836.4 | C11: $M | D11: Reported | E11: https://www.sec.gov/Archives/edgar/data/1513845/000110465926094844/nbis-20260812xex99d2.htm Note 7
A12: Share of not-yet-in-use placed in service in Q3'26 (rest Q4'26) | B12: 0.5 | C12: % | D12: Estimated | E12: Q1 letter: 'significantly increase our capacity in place in 3Q'
A13: GPU/server share of capex and of not-yet-in-use | B13: 0.79 | C13: % | D13: Estimated (mgmt via secondary) | E13: Mgmt on Q4'25 call: ~79% GPUs, ~20% data center, <1% power (secondary transcript summary: https://www.youtube.com/watch?v=JDCUSh2okgc) - verify vs transcript
A14: Capex-to-in-service lag | B14: 2 | C14: quarters | D14: Estimated | E14: Assumption; Q2 not-yet-in-use 7.8B vs Q2 capex 5.7B suggests >1 quarter
A15: Capex (consensus / guidance / extrapolation)
A16: FY2026 capex | B16: 23207 | C16: $M | D16: Estimated (consensus) | E16: https://www.marketscreener.com/quote/stock/NEBIUS-GROUP-8037501/finances/ ; guide $20-25B (https://assets.nebius.com/assets/a6ecfd85-a6cb-4967-8ef7-9a25bd261f9c/SHLQ226.pdf)
A17: 1H2026 capex actual | B17: 8130.3 | C17: $M | D17: Reported | E17: /workspace/nebius/filings/nebius_fact_base.md
A18: FY2027 capex | B18: 29135 | C18: $M | D18: Estimated (consensus) | E18: https://www.marketscreener.com/quote/stock/NEBIUS-GROUP-8037501/finances/
A19: FY2028 capex | B19: 38885 | C19: $M | D19: Estimated (consensus) | E19: https://www.marketscreener.com/quote/stock/NEBIUS-GROUP-8037501/finances/
A20: FY2029 capex growth vs FY28 | B20: 0 | C20: % | D20: Estimated (extrapolation) | E20: No consensus beyond FY28; flat ~$38.9B ~ 1.3GW/yr at ~$30M/MW, consistent with '>1GW/yr from 2027' guide
A21: FY2030 capex growth vs FY29 | B21: 0 | C21: % | D21: Estimated (extrapolation) | E21: as above
A22: All-in capex per MW | B22: 30 | C22: $M/MW | D22: Estimated (third party) | E22: ~$30M/MW sell-side/SA estimate; only used to translate yields into $/MW
A23: EBITDA / revenue (FY26-FY28 consensus; FY29+ extrapolated) - quarterly FY26-27 consensus is entered on Model sheet (blue)
A24: FY2028 adj. EBITDA consensus | B24: 13978 | C24: $M | D24: Estimated (consensus) | E24: https://www.marketscreener.com/quote/stock/NEBIUS-GROUP-8037501/finances/
A25: FY2028 revenue consensus | B25: 22983 | C25: $M | D25: Estimated (consensus) | E25: https://www.marketscreener.com/quote/stock/NEBIUS-GROUP-8037501/finances/
A26: FY28 quarterly weight Q1 | B26: 0.22 | C26: % | D26: Estimated | E26: Assumed ramp (sums to 100%)
A27: FY28 quarterly weight Q2 | B27: 0.24 | C27: % | D27: Estimated | E27: Assumed ramp (sums to 100%)
A28: FY28 quarterly weight Q3 | B28: 0.26 | C28: % | D28: Estimated | E28: Assumed ramp (sums to 100%)
A29: FY28 quarterly weight Q4 | B29: 0.28 | C29: % | D29: Estimated | E29: Assumed ramp (sums to 100%)
A30: FY29+ EBITDA yield override (annual EBITDA / gross GPU in service); blank = consensus-implied | C30: % | D30: Scenario input | E30: Blank uses FY28 consensus-implied yield (Model!C52). Reference points: installed base $12M/MW ~30%; Q2 deals $20M/MW ~51% (see Reverse_DCF notes)
A31: 1H2026 actuals (for FY2026 roll-up)
A32: 1H26 revenue | B32: 981.3 | C32: $M | D32: Reported | E32: /workspace/nebius/filings/nebius_fact_base.md
A33: 1H26 adj. EBITDA | B33: 365.7 | C33: $M | D33: Reported | E33: /workspace/nebius/filings/nebius_fact_base.md
A34: 1H26 D&A (at 5-yr policy) | B34: 471.7 | C34: $M | D34: Reported | E34: /workspace/nebius/filings/nebius_fact_base.md
A35: 1H26 D&A reduction from 4->5 yr change | B35: 86.1 | C35: $M | D35: Reported | E35: /workspace/nebius/filings/nebius_fact_base.md (Q2 -$43.0M; FY26 est. -$167.6M)
A36: Financing / cash interest
A37: Convert 2.00% 2029 (remaining): principal / coupon | B37: 87.5 | C37: $M | D37: 0.02 | E37: Reported (/workspace/nebius/filings/nebius_fact_base.md Converts)
A38: Convert 3.00% 2031 (remaining): principal / coupon | B38: 87.5 | C38: $M | D38: 0.03 | E38: Reported (/workspace/nebius/filings/nebius_fact_base.md Converts)
A39: Convert 1.00% 9/2030: principal / coupon | B39: 1581.25 | C39: $M | D39: 0.01 | E39: Reported (/workspace/nebius/filings/nebius_fact_base.md Converts)
A40: Convert 2.75% 9/2032: principal / coupon | B40: 1581.25 | C40: $M | D40: 0.0275 | E40: Reported (/workspace/nebius/filings/nebius_fact_base.md Converts)
...

Sheet Model
A1: Quarter | C1: Q3 2026 | D1: Q4 2026 | E1: Q1 2027 | F1: Q2 2027 | G1: Q3 2027 | H1: Q4 2027 | I1: Q1 2028 | J1: Q2 2028 | K1: Q3 2028 | L1: Q4 2028 | M1: Q1 2029 | N1: Q2 2029 | O1: Q3 2029 | P1: Q4 2029 | Q1: Q1 2030 | R1: Q2 2030 | S1: Q3 2030 | T1: Q4 2030
A2: Index | C2: 0 | D2: 1 | E2: 2 | F2: 3 | G2: 4 | H2: 5 | I2: 6 | J2: 7 | K2: 8 | L2: 9 | M2: 10 | N2: 11 | O2: 12 | P2: 13 | Q2: 14 | R2: 15 | S2: 16 | T2: 17
A3: Fiscal year | C3: 2026 | D3: 2026 | E3: 2027 | F3: 2027 | G3: 2027 | H3: 2027 | I3: 2028 | J3: 2028 | K3: 2028 | L3: 2028 | M3: 2029 | N3: 2029 | O3: 2029 | P3: 2029 | Q3: 2030 | R3: 2030 | S3: 2030 | T3: 2030
A4: GPU generation placed in service (label) | C4: =IF(C2<2,"Blackwell (B200/B300/GB300)",IF(C2<12,"Vera Rubin","Rubin Ultra / next")) | D4: =IF(D2<2,"Blackwell (B200/B300/GB300)",IF(D2<12,"Vera Rubin","Rubin Ultra / next")) | E4: =IF(E2<2,"Blackwell (B200/B300/GB300)",IF(E2<12,"Vera Rubin","Rubin Ultra / next")) | F4: =IF(F2<2,"Blackwell (B200/B300/GB300)",IF(F2<12,"Vera Rubin","Rubin Ultra / next")) | G4: =IF(G2<2,"Blackwell (B200/B300/GB300)",IF(G2<12,"Vera Rubin","Rubin Ultra / next")) | H4: =IF(H2<2,"Blackwell (B200/B300/GB300)",IF(H2<12,"Vera Rubin","Rubin Ultra / next")) | I4: =IF(I2<2,"Blackwell (B200/B300/GB300)",IF(I2<12,"Vera Rubin","Rubin Ultra / next")) | J4: =IF(J2<2,"Blackwell (B200/B300/GB300)",IF(J2<12,"Vera Rubin","Rubin Ultra / next")) | ... T4: =IF(T2<2,"Blackwell (B200/B300/GB300)",IF(T2<12,"Vera Rubin","Rubin Ultra / next"))
A6: Revenue | B6: $M | C6: 904.1 | D6: 1452 | E6: 2175 | F6: 2646 | G6: 3304 | H6: 4052 | I6: =Assumptions!$B$25*Assumptions!$B$26 | J6: =Assumptions!$B$25*Assumptions!$B$27 | K6: =Assumptions!$B$25*Assumptions!$B$28 | L6: =Assumptions!$B$25*Assumptions!$B$29 | M6: =M7/(Assumptions!$B$24/Assumptions!$B$25) | N6: =N7/(Assumptions!$B$24/Assumptions!$B$25) | O6: =O7/(Assumptions!$B$24/Assumptions!$B$25) | P6: =P7/(Assumptions!$B$24/Assumptions!$B$25) | Q6: =Q7/(Assumptions!$B$24/Assumptions!$B$25) | R6: =R7/(Assumptions!$B$24/Assumptions!$B$25) | S6: =S7/(Assumptions!$B$24/Assumptions!$B$25) | T6: =T7/(Assumptions!$B$24/Assumptions!$B$25)
A7: Adj. EBITDA | B7: $M | C7: 354.7 | D7: 670.7 | E7: 1277 | F7: 1581 | G7: 1883 | H7: 2372 | I7: =Assumptions!$B$24*Assumptions!$B$26 | J7: =Assumptions!$B$24*Assumptions!$B$27 | K7: =Assumptions!$B$24*Assumptions!$B$28 | L7: =Assumptions!$B$24*Assumptions!$B$29 | M7: =IF(Assumptions!$B$30="",$C$52,Assumptions!$B$30)/4*L16 | N7: =IF(Assumptions!$B$30="",$C$52,Assumptions!$B$30)/4*M16 | O7: =IF(Assumptions!$B$30="",$C$52,Assumptions!$B$30)/4*N16 | P7: =IF(Assumptions!$B$30="",$C$52,Assumptions!$B$30)/4*O16 | Q7: =IF(Assumptions!$B$30="",$C$52,Assumptions!$B$30)/4*P16 | R7: =IF(Assumptions!$B$30="",$C$52,Assumptions!$B$30)/4*Q16 | S7: =IF(Assumptions!$B$30="",$C$52,Assumptions!$B$30)/4*R16 | T7: =IF(Assumptions!$B$30="",$C$52,Assumptions!$B$30)/4*S16
A8: Adj. EBITDA margin | B8: % | C8: =C7/C6 | D8: =D7/D6 | E8: =E7/E6 | F8: =F7/F6 | G8: =G7/G6 | H8: =H7/H6 | I8: =I7/I6 | J8: =J7/J6 | ... T8: =T7/T6
A9: Q3'26-Q4'27 = MarketScreener quarterly consensus (blue); FY28 = annual consensus x weights; FY29+ = EBITDA yield x prior-qtr gross GPU in service
A10: Capex (total) | B10: $M | C10: =(Assumptions!$B$16-Assumptions!$B$17)/2 | D10: =(Assumptions!$B$16-Assumptions!$B$17)/2 | E10: =Assumptions!$B$18/4 | F10: =Assumptions!$B$18/4 | G10: =Assumptions!$B$18/4 | H10: =Assumptions!$B$18/4 | I10: =Assumptions!$B$19/4 | J10: =Assumptions!$B$19/4 | K10: =Assumptions!$B$19/4 | L10: =Assumptions!$B$19/4 | M10: =Assumptions!$B$19*(1+Assumptions!$B$20)/4 | N10: =Assumptions!$B$19*(1+Assumptions!$B$20)/4 | O10: =Assumptions!$B$19*(1+Assumptions!$B$20)/4 | P10: =Assumptions!$B$19*(1+Assumptions!$B$20)/4 | Q10: =Assumptions!$B$19*(1+Assumptions!$B$20)*(1+Assumptions!$B$21)/4 | R10: =Assumptions!$B$19*(1+Assumptions!$B$20)*(1+Assumptions!$B$21)/4 | S10: =Assumptions!$B$19*(1+Assumptions!$B$20)*(1+Assumptions!$B$21)/4 | T10: =Assumptions!$B$19*(1+Assumptions!$B$20)*(1+Assumptions!$B$21)/4
A11: GPU/server capex | B11: $M | C11: =C10*Assumptions!$B$13 | D11: =D10*Assumptions!$B$13 | E11: =E10*Assumptions!$B$13 | F11: =F10*Assumptions!$B$13 | G11: =G10*Assumptions!$B$13 | H11: =H10*Assumptions!$B$13 | I11: =I10*Assumptions!$B$13 | J11: =J10*Assumptions!$B$13 | ... T11: =T10*Assumptions!$B$13
A12: Non-GPU capex (DC/infra/power) | B12: $M | C12: =C10*(1-Assumptions!$B$13) | D12: =D10*(1-Assumptions!$B$13) | E12: =E10*(1-Assumptions!$B$13) | F12: =F10*(1-Assumptions!$B$13) | G12: =G10*(1-Assumptions!$B$13) | H12: =H10*(1-Assumptions!$B$13) | I12: =I10*(1-Assumptions!$B$13) | J12: =J10*(1-Assumptions!$B$13) | ... T12: =T10*(1-Assumptions!$B$13)
A14: GPU placed in service (cohort = column) | B14: $M | C14: =(IF(C$2=0,Assumptions!$B$11*Assumptions!$B$12,0)+IF(C$2=1,Assumptions!$B$11*(1-Assumptions!$B$12),0)+IF(C$2>=Assumptions!$B$14,INDEX($C$10:$T$10,C$2-Assumptions!$B$14+1),0))*Assumptions!$B$13 | D14: =(IF(D$2=0,Assumptions!$B$11*Assumptions!$B$12,0)+IF(D$2=1,Assumptions!$B$11*(1-Assumptions!$B$12),0)+IF(D$2>=Assumptions!$B$14,INDEX($C$10:$T$10,D$2-Assumptions!$B$14+1),0))*Assumptions!$B$13 | E14: =(IF(E$2=0,Assumptions!$B$11*Assumptions!$B$12,0)+IF(E$2=1,Assumptions!$B$11*(1-Assumptions!$B$12),0)+IF(E$2>=Assumptions!$B$14,INDEX($C$10:$T$10,E$2-Assumptions!$B$14+1),0))*Assumptions!$B$13 | F14: =(IF(F$2=0,Assumptions!$B$11*Assumptions!$B$12,0)+IF(F$2=1,Assumptions!$B$11*(1-Assumptions!$B$12),0)+IF(F$2>=Assumptions!$B$14,INDEX($C$10:$T$10,F$2-Assumptions!$B$14+1),0))*Assumptions!$B$13 | G14: =(IF(G$2=0,Assumptions!$B$11*Assumptions!$B$12,0)+IF(G$2=1,Assumptions!$B$11*(1-Assumptions!$B$12),0)+IF(G$2>=Assumptions!$B$14,INDEX($C$10:$T$10,G$2-Assumptions!$B$14+1),0))*Assumptions!$B$13 | H14: =(IF(H$2=0,Assumptions!$B$11*Assumptions!$B$12,0)+IF(H$2=1,Assumptions!$B$11*(1-Assumptions!$B$12),0)+IF(H$2>=Assumptions!$B$14,INDEX($C$10:$T$10,H$2-Assumptions!$B$14+1),0))*Assumptions!$B$13 | I14: =(IF(I$2=0,Assumptions!$B$11*Assumptions!$B$12,0)+IF(I$2=1,Assumptions!$B$11*(1-Assumptions!$B$12),0)+IF(I$2>=Assumptions!$B$14,INDEX($C$10:$T$10,I$2-Assumptions!$B$14+1),0))*Assumptions!$B$13 | J14: =(IF(J$2=0,Assumptions!$B$11*Assumptions!$B$12,0)+IF(J$2=1,Assumptions!$B$11*(1-Assumptions!$B$12),0)+IF(J$2>=Assumptions!$B$14,INDEX($C$10:$T$10,J$2-Assumptions!$B$14+1),0))*Assumptions!$B$13 | ... T14: =(IF(T$2=0,Assumptions!$B$11*Assumptions!$B$12,0)+IF(T$2=1,Assumptions!$B$11*(1-Assumptions!$B$12),0)+IF(T$2>=Assumptions!$B$14,INDEX($C$10:$T$10,T$2-Assumptions!$B$14+1),0))*Assumptions!$B$13
A15: Non-GPU placed in service | B15: $M | C15: =(IF(C$2=0,Assumptions!$B$11*Assumptions!$B$12,0)+IF(C$2=1,Assumptions!$B$11*(1-Assumptions!$B$12),0)+IF(C$2>=Assumptions!$B$14,INDEX($C$10:$T$10,C$2-Assumptions!$B$14+1),0))*(1-Assumptions!$B$13) | D15: =(IF(D$2=0,Assumptions!$B$11*Assumptions!$B$12,0)+IF(D$2=1,Assumptions!$B$11*(1-Assumptions!$B$12),0)+IF(D$2>=Assumptions!$B$14,INDEX($C$10:$T$10,D$2-Assumptions!$B$14+1),0))*(1-Assumptions!$B$13) | E15: =(IF(E$2=0,Assumptions!$B$11*Assumptions!$B$12,0)+IF(E$2=1,Assumptions!$B$11*(1-Assumptions!$B$12),0)+IF(E$2>=Assumptions!$B$14,INDEX($C$10:$T$10,E$2-Assumptions!$B$14+1),0))*(1-Assumptions!$B$13) | F15: =(IF(F$2=0,Assumptions!$B$11*Assumptions!$B$12,0)+IF(F$2=1,Assumptions!$B$11*(1-Assumptions!$B$12),0)+IF(F$2>=Assumptions!$B$14,INDEX($C$10:$T$10,F$2-Assumptions!$B$14+1),0))*(1-Assumptions!$B$13) | G15: =(IF(G$2=0,Assumptions!$B$11*Assumptions!$B$12,0)+IF(G$2=1,Assumptions!$B$11*(1-Assumptions!$B$12),0)+IF(G$2>=Assumptions!$B$14,INDEX($C$10:$T$10,G$2-Assumptions!$B$14+1),0))*(1-Assumptions!$B$13) | H15: =(IF(H$2=0,Assumptions!$B$11*Assumptions!$B$12,0)+IF(H$2=1,Assumptions!$B$11*(1-Assumptions!$B$12),0)+IF(H$2>=Assumptions!$B$14,INDEX($C$10:$T$10,H$2-Assumptions!$B$14+1),0))*(1-Assumptions!$B$13) | I15: =(IF(I$2=0,Assumptions!$B$11*Assumptions!$B$12,0)+IF(I$2=1,Assumptions!$B$11*(1-Assumptions!$B$12),0)+IF(I$2>=Assumptions!$B$14,INDEX($C$10:$T$10,I$2-Assumptions!$B$14+1),0))*(1-Assumptions!$B$13) | J15: =(IF(J$2=0,Assumptions!$B$11*Assumptions!$B$12,0)+IF(J$2=1,Assumptions!$B$11*(1-Assumptions!$B$12),0)+IF(J$2>=Assumptions!$B$14,INDEX($C$10:$T$10,J$2-Assumptions!$B$14+1),0))*(1-Assumptions!$B$13) | ... T15: =(IF(T$2=0,Assumptions!$B$11*Assumptions!$B$12,0)+IF(T$2=1,Assumptions!$B$11*(1-Assumptions!$B$12),0)+IF(T$2>=Assumptions!$B$14,INDEX($C$10:$T$10,T$2-Assumptions!$B$14+1),0))*(1-Assumptions!$B$13)
A16: Cumulative gross GPU/server in service (incl. 6/30 base, no retirements) | B16: $M | C16: =Assumptions!$B$8+SUM($C$14:C14) | D16: =Assumptions!$B$8+SUM($C$14:D14) | E16: =Assumptions!$B$8+SUM($C$14:E14) | F16: =Assumptions!$B$8+SUM($C$14:F14) | G16: =Assumptions!$B$8+SUM($C$14:G14) | H16: =Assumptions!$B$8+SUM($C$14:H14) | I16: =Assumptions!$B$8+SUM($C$14:I14) | J16: =Assumptions!$B$8+SUM($C$14:J14) | ... T16: =Assumptions!$B$8+SUM($C$14:T14)
A17: Construction-in-progress memo: cum. capex not yet in service (from Q3'26) | B17: $M | C17: =SUM($C$10:C10)+Assumptions!$B$11-SUM($C$14:C14)-SUM($C$15:C15) | D17: =SUM($C$10:D10)+Assumptions!$B$11-SUM($C$14:D14)-SUM($C$15:D15) | E17: =SUM($C$10:E10)+Assumptions!$B$11-SUM($C$14:E14)-SUM($C$15:E15) | F17: =SUM($C$10:F10)+Assumptions!$B$11-SUM($C$14:F14)-SUM($C$15:F15) | G17: =SUM($C$10:G10)+Assumptions!$B$11-SUM($C$14:G14)-SUM($C$15:G15) | H17: =SUM($C$10:H10)+Assumptions!$B$11-SUM($C$14:H14)-SUM($C$15:H15) | I17: =SUM($C$10:I10)+Assumptions!$B$11-SUM($C$14:I14)-SUM($C$15:I15) | J17: =SUM($C$10:J10)+Assumptions!$B$11-SUM($C$14:J14)-SUM($C$15:J15) | ... T17: =SUM($C$10:T10)+Assumptions!$B$11-SUM($C$14:T14)-SUM($C$15:T15)
A19: DEPRECIATION @ life scenario A | B19: =Assumptions!$B$3
A20: Existing 6/30 server base | B20: $M | C20: =IF(C$2<4*Assumptions!$B$3-Assumptions!$B$9,Assumptions!$B$8/(4*Assumptions!$B$3)*IF(C$2>=Assumptions!$B$53,1-Assumptions!$B$51,1),0) | D20: =IF(D$2<4*Assumptions!$B$3-Assumptions!$B$9,Assumptions!$B$8/(4*Assumptions!$B$3)*IF(D$2>=Assumptions!$B$53,1-Assumptions!$B$51,1),0) | E20: =IF(E$2<4*Assumptions!$B$3-Assumptions!$B$9,Assumptions!$B$8/(4*Assumptions!$B$3)*IF(E$2>=Assumptions!$B$53,1-Assumptions!$B$51,1),0) | F20: =IF(F$2<4*Assumptions!$B$3-Assumptions!$B$9,Assumptions!$B$8/(4*Assumptions!$B$3)*IF(F$2>=Assumptions!$B$53,1-Assumptions!$B$51,1),0) | G20: =IF(G$2<4*Assumptions!$B$3-Assumptions!$B$9,Assumptions!$B$8/(4*Assumptions!$B$3)*IF(G$2>=Assumptions!$B$53,1-Assumptions!$B$51,1),0) | H20: =IF(H$2<4*Assumptions!$B$3-Assumptions!$B$9,Assumptions!$B$8/(4*Assumptions!$B$3)*IF(H$2>=Assumptions!$B$53,1-Assumptions!$B$51,1),0) | I20: =IF(I$2<4*Assumptions!$B$3-Assumptions!$B$9,Assumptions!$B$8/(4*Assumptions!$B$3)*IF(I$2>=Assumptions!$B$53,1-Assumptions!$B$51,1),0) | J20: =IF(J$2<4*Assumptions!$B$3-Assumptions!$B$9,Assumptions!$B$8/(4*Assumptions!$B$3)*IF(J$2>=Assumptions!$B$53,1-Assumptions!$B$51,1),0) | ... T20: =IF(T$2<4*Assumptions!$B$3-Assumptions!$B$9,Assumptions!$B$8/(4*Assumptions!$B$3)*IF(T$2>=Assumptions!$B$53,1-Assumptions!$B$51,1),0)
A21: New GPU cohorts (half-quarter convention) | B21: $M | C21: =(SUMPRODUCT($C$14:$T$14,--($C$2:$T$2<C$2),--($C$2:$T$2>C$2-4*Assumptions!$B$3))+0.5*C$14+0.5*SUMPRODUCT($C$14:$T$14,--($C$2:$T$2=C$2-4*Assumptions!$B$3)))/(4*Assumptions!$B$3) | D21: =(SUMPRODUCT($C$14:$T$14,--($C$2:$T$2<D$2),--($C$2:$T$2>D$2-4*Assumptions!$B$3))+0.5*D$14+0.5*SUMPRODUCT($C$14:$T$14,--($C$2:$T$2=D$2-4*Assumptions!$B$3)))/(4*Assumptions!$B$3) | E21: =(SUMPRODUCT($C$14:$T$14,--($C$2:$T$2<E$2),--($C$2:$T$2>E$2-4*Assumptions!$B$3))+0.5*E$14+0.5*SUMPRODUCT($C$14:$T$14,--($C$2:$T$2=E$2-4*Assumptions!$B$3)))/(4*Assumptions!$B$3) | F21: =(SUMPRODUCT($C$14:$T$14,--($C$2:$T$2<F$2),--($C$2:$T$2>F$2-4*Assumptions!$B$3))+0.5*F$14+0.5*SUMPRODUCT($C$14:$T$14,--($C$2:$T$2=F$2-4*Assumptions!$B$3)))/(4*Assumptions!$B$3) | G21: =(SUMPRODUCT($C$14:$T$14,--($C$2:$T$2<G$2),--($C$2:$T$2>G$2-4*Assumptions!$B$3))+0.5*G$14+0.5*SUMPRODUCT($C$14:$T$14,--($C$2:$T$2=G$2-4*Assumptions!$B$3)))/(4*Assumptions!$B$3) | H21: =(SUMPRODUCT($C$14:$T$14,--($C$2:$T$2<H$2),--($C$2:$T$2>H$2-4*Assumptions!$B$3))+0.5*H$14+0.5*SUMPRODUCT($C$14:$T$14,--($C$2:$T$2=H$2-4*Assumptions!$B$3)))/(4*Assumptions!$B$3) | I21: =(SUMPRODUCT($C$14:$T$14,--($C$2:$T$2<I$2),--($C$2:$T$2>I$2-4*Assumptions!$B$3))+0.5*I$14+0.5*SUMPRODUCT($C$14:$T$14,--($C$2:$T$2=I$2-4*Assumptions!$B$3)))/(4*Assumptions!$B$3) | J21: =(SUMPRODUCT($C$14:$T$14,--($C$2:$T$2<J$2),--($C$2:$T$2>J$2-4*Assumptions!$B$3))+0.5*J$14+0.5*SUMPRODUCT($C$14:$T$14,--($C$2:$T$2=J$2-4*Assumptions!$B$3)))/(4*Assumptions!$B$3) | ... T21: =(SUMPRODUCT($C$14:$T$14,--($C$2:$T$2<T$2),--($C$2:$T$2>T$2-4*Assumptions!$B$3))+0.5*T$14+0.5*SUMPRODUCT($C$14:$T$14,--($C$2:$T$2=T$2-4*Assumptions!$B$3)))/(4*Assumptions!$B$3)
A22: Non-GPU (existing + new) | B22: $M | C22: =Assumptions!$B$10/(4*Assumptions!$B$6)+(SUMPRODUCT($C$15:$T$15,--($C$2:$T$2<C$2))+0.5*C$15)/(4*Assumptions!$B$6) | D22: =Assumptions!$B$10/(4*Assumptions!$B$6)+(SUMPRODUCT($C$15:$T$15,--($C$2:$T$2<D$2))+0.5*D$15)/(4*Assumptions!$B$6) | E22: =Assumptions!$B$10/(4*Assumptions!$B$6)+(SUMPRODUCT($C$15:$T$15,--($C$2:$T$2<E$2))+0.5*E$15)/(4*Assumptions!$B$6) | F22: =Assumptions!$B$10/(4*Assumptions!$B$6)+(SUMPRODUCT($C$15:$T$15,--($C$2:$T$2<F$2))+0.5*F$15)/(4*Assumptions!$B$6) | G22: =Assumptions!$B$10/(4*Assumptions!$B$6)+(SUMPRODUCT($C$15:$T$15,--($C$2:$T$2<G$2))+0.5*G$15)/(4*Assumptions!$B$6) | H22: =Assumptions!$B$10/(4*Assumptions!$B$6)+(SUMPRODUCT($C$15:$T$15,--($C$2:$T$2<H$2))+0.5*H$15)/(4*Assumptions!$B$6) | I22: =Assumptions!$B$10/(4*Assumptions!$B$6)+(SUMPRODUCT($C$15:$T$15,--($C$2:$T$2<I$2))+0.5*I$15)/(4*Assumptions!$B$6) | J22: =Assumptions!$B$10/(4*Assumptions!$B$6)+(SUMPRODUCT($C$15:$T$15,--($C$2:$T$2<J$2))+0.5*J$15)/(4*Assumptions!$B$6) | ... T22: =Assumptions!$B$10/(4*Assumptions!$B$6)+(SUMPRODUCT($C$15:$T$15,--($C$2:$T$2<T$2))+0.5*T$15)/(4*Assumptions!$B$6)
A23: Impairment charge | B23: $M | C23: =IF(C$2=Assumptions!$B$53,Assumptions!$B$51*Assumptions!$B$8*MAX(0,4*Assumptions!$B$3-Assumptions!$B$9-C$2)/(4*Assumptions!$B$3),0) | D23: =IF(D$2=Assumptions!$B$53,Assumptions!$B$51*Assumptions!$B$8*MAX(0,4*Assumptions!$B$3-Assumptions!$B$9-D$2)/(4*Assumptions!$B$3),0) | E23: =IF(E$2=Assumptions!$B$53,Assumptions!$B$51*Assumptions!$B$8*MAX(0,4*Assumptions!$B$3-Assumptions!$B$9-E$2)/(4*Assumptions!$B$3),0) | F23: =IF(F$2=Assumptions!$B$53,Assumptions!$B$51*Assumptions!$B$8*MAX(0,4*Assumptions!$B$3-Assumptions!$B$9-F$2)/(4*Assumptions!$B$3),0) | G23: =IF(G$2=Assumptions!$B$53,Assumptions!$B$51*Assumptions!$B$8*MAX(0,4*Assumptions!$B$3-Assumptions!$B$9-G$2)/(4*Assumptions!$B$3),0) | H23: =IF(H$2=Assumptions!$B$53,Assumptions!$B$51*Assumptions!$B$8*MAX(0,4*Assumptions!$B$3-Assumptions!$B$9-H$2)/(4*Assumptions!$B$3),0) | I23: =IF(I$2=Assumptions!$B$53,Assumptions!$B$51*Assumptions!$B$8*MAX(0,4*Assumptions!$B$3-Assumptions!$B$9-I$2)/(4*Assumptions!$B$3),0) | J23: =IF(J$2=Assumptions!$B$53,Assumptions!$B$51*Assumptions!$B$8*MAX(0,4*Assumptions!$B$3-Assumptions!$B$9-J$2)/(4*Assumptions!$B$3),0) | ... T23: =IF(T$2=Assumptions!$B$53,Assumptions!$B$51*Assumptions!$B$8*MAX(0,4*Assumptions!$B$3-Assumptions!$B$9-T$2)/(4*Assumptions!$B$3),0)
A24: Total D&A | B24: $M | C24: =C20+C21+C22 | D24: =D20+D21+D22 | E24: =E20+E21+E22 | F24: =F20+F21+F22 | G24: =G20+G21+G22 | H24: =H20+H21+H22 | I24: =I20+I21+I22 | J24: =J20+J21+J22 | ... T24: =T20+T21+T22
A25: EBIT (adj.; pre-SBC) = EBITDA - D&A - impairment | B25: $M | C25: =C$7-C24-C23 | D25: =D$7-D24-D23 | E25: =E$7-E24-E23 | F25: =F$7-F24-F23 | G25: =G$7-G24-G23 | H25: =H$7-H24-H23 | I25: =I$7-I24-I23 | J25: =J$7-J24-J23 | ... T25: =T$7-T24-T23
A26: EBIT margin | B26: % | C26: =C25/C$6 | D26: =D25/D$6 | E26: =E25/E$6 | F26: =F25/F$6 | G26: =G25/G$6 | H26: =H25/H$6 | I26: =I25/I$6 | J26: =J25/J$6 | ... T26: =T25/T$6
A27: D&A / revenue | B27: % | C27: =C24/C$6 | D27: =D24/D$6 | E27: =E24/E$6 | F27: =F24/F$6 | G27: =G24/G$6 | H27: =H24/H$6 | I27: =I24/I$6 | J27: =J24/J$6 | ... T27: =T24/T$6
A29: DEPRECIATION @ life scenario B | B29: =Assumptions!$B$4
A30: Existing 6/30 server base | B30: $M | C30: =IF(C$2<4*Assumptions!$B$4-Assumptions!$B$9,Assumptions!$B$8/(4*Assumptions!$B$4)*IF(C$2>=Assumptions!$B$53,1-Assumptions!$B$51,1),0) | D30: =IF(D$2<4*Assumptions!$B$4-Assumptions!$B$9,Assumptions!$B$8/(4*Assumptions!$B$4)*IF(D$2>=Assumptions!$B$53,1-Assumptions!$B$51,1),0) | E30: =IF(E$2<4*Assumptions!$B$4-Assumptions!$B$9,Assumptions!$B$8/(4*Assumptions!$B$4)*IF(E$2>=Assumptions!$B$53,1-Assumptions!$B$51,1),0) | F30: =IF(F$2<4*Assumptions!$B$4-Assumptions!$B$9,Assumptions!$B$8/(4*Assumptions!$B$4)*IF(F$2>=Assumptions!$B$53,1-Assumptions!$B$51,1),0) | G30: =IF(G$2<4*Assumptions!$B$4-Assumptions!$B$9,Assumptions!$B$8/(4*Assumptions!$B$4)*IF(G$2>=Assumptions!$B$53,1-Assumptions!$B$51,1),0) | H30: =IF(H$2<4*Assumptions!$B$4-Assumptions!$B$9,Assumptions!$B$8/(4*Assumptions!$B$4)*IF(H$2>=Assumptions!$B$53,1-Assumptions!$B$51,1),0) | I30: =IF(I$2<4*Assumptions!$B$4-Assumptions!$B$9,Assumptions!$B$8/(4*Assumptions!$B$4)*IF(I$2>=Assumptions!$B$53,1-Assumptions!$B$51,1),0) | J30: =IF(J$2<4*Assumptions!$B$4-Assumptions!$B$9,Assumptions!$B$8/(4*Assumptions!$B$4)*IF(J$2>=Assumptions!$B$53,1-Assumptions!$B$51,1),0) | ... T30: =IF(T$2<4*Assumptions!$B$4-Assumptions!$B$9,Assumptions!$B$8/(4*Assumptions!$B$4)*IF(T$2>=Assumptions!$B$53,1-Assumptions!$B$51,1),0)
A31: New GPU cohorts (half-quarter convention) | B31: $M | C31: =(SUMPRODUCT($C$14:$T$14,--($C$2:$T$2<C$2),--($C$2:$T$2>C$2-4*Assumptions!$B$4))+0.5*C$14+0.5*SUMPRODUCT($C$14:$T$14,--($C$2:$T$2=C$2-4*Assumptions!$B$4)))/(4*Assumptions!$B$4) | D31: =(SUMPRODUCT($C$14:$T$14,--($C$2:$T$2<D$2),--($C$2:$T$2>D$2-4*Assumptions!$B$4))+0.5*D$14+0.5*SUMPRODUCT($C$14:$T$14,--($C$2:$T$2=D$2-4*Assumptions!$B$4)))/(4*Assumptions!$B$4) | E31: =(SUMPRODUCT($C$14:$T$14,--($C$2:$T$2<E$2),--($C$2:$T$2>E$2-4*Assumptions!$B$4))+0.5*E$14+0.5*SUMPRODUCT($C$14:$T$14,--($C$2:$T$2=E$2-4*Assumptions!$B$4)))/(4*Assumptions!$B$4) | F31: =(SUMPRODUCT($C$14:$T$14,--($C$2:$T$2<F$2),--($C$2:$T$2>F$2-4*Assumptions!$B$4))+0.5*F$14+0.5*SUMPRODUCT($C$14:$T$14,--($C$2:$T$2=F$2-4*Assumptions!$B$4)))/(4*Assumptions!$B$4) | G31: =(SUMPRODUCT($C$14:$T$14,--($C$2:$T$2<G$2),--($C$2:$T$2>G$2-4*Assumptions!$B$4))+0.5*G$14+0.5*SUMPRODUCT($C$14:$T$14,--($C$2:$T$2=G$2-4*Assumptions!$B$4)))/(4*Assumptions!$B$4) | H31: =(SUMPRODUCT($C$14:$T$14,--($C$2:$T$2<H$2),--($C$2:$T$2>H$2-4*Assumptions!$B$4))+0.5*H$14+0.5*SUMPRODUCT($C$14:$T$14,--($C$2:$T$2=H$2-4*Assumptions!$B$4)))/(4*Assumptions!$B$4) | I31: =(SUMPRODUCT($C$14:$T$14,--($C$2:$T$2<I$2),--($C$2:$T$2>I$2-4*Assumptions!$B$4))+0.5*I$14+0.5*SUMPRODUCT($C$14:$T$14,--($C$2:$T$2=I$2-4*Assumptions!$B$4)))/(4*Assumptions!$B$4) | J31: =(SUMPRODUCT($C$14:$T$14,--($C$2:$T$2<J$2),--($C$2:$T$2>J$2-4*Assumptions!$B$4))+0.5*J$14+0.5*SUMPRODUCT($C$14:$T$14,--($C$2:$T$2=J$2-4*Assumptions!$B$4)))/(4*Assumptions!$B$4) | ... T31: =(SUMPRODUCT($C$14:$T$14,--($C$2:$T$2<T$2),--($C$2:$T$2>T$2-4*Assumptions!$B$4))+0.5*T$14+0.5*SUMPRODUCT($C$14:$T$14,--($C$2:$T$2=T$2-4*Assumptions!$B$4)))/(4*Assumptions!$B$4)
A32: Non-GPU (existing + new) | B32: $M | C32: =Assumptions!$B$10/(4*Assumptions!$B$6)+(SUMPRODUCT($C$15:$T$15,--($C$2:$T$2<C$2))+0.5*C$15)/(4*Assumptions!$B$6) | D32: =Assumptions!$B$10/(4*Assumptions!$B$6)+(SUMPRODUCT($C$15:$T$15,--($C$2:$T$2<D$2))+0.5*D$15)/(4*Assumptions!$B$6) | E32: =Assumptions!$B$10/(4*Assumptions!$B$6)+(SUMPRODUCT($C$15:$T$15,--($C$2:$T$2<E$2))+0.5*E$15)/(4*Assumptions!$B$6) | F32: =Assumptions!$B$10/(4*Assumptions!$B$6)+(SUMPRODUCT($C$15:$T$15,--($C$2:$T$2<F$2))+0.5*F$15)/(4*Assumptions!$B$6) | G32: =Assumptions!$B$10/(4*Assumptions!$B$6)+(SUMPRODUCT($C$15:$T$15,--($C$2:$T$2<G$2))+0.5*G$15)/(4*Assumptions!$B$6) | H32: =Assumptions!$B$10/(4*Assumptions!$B$6)+(SUMPRODUCT($C$15:$T$15,--($C$2:$T$2<H$2))+0.5*H$15)/(4*Assumptions!$B$6) | I32: =Assumptions!$B$10/(4*Assumptions!$B$6)+(SUMPRODUCT($C$15:$T$15,--($C$2:$T$2<I$2))+0.5*I$15)/(4*Assumptions!$B$6) | J32: =Assumptions!$B$10/(4*Assumptions!$B$6)+(SUMPRODUCT($C$15:$T$15,--($C$2:$T$2<J$2))+0.5*J$15)/(4*Assumptions!$B$6) | ... T32: =Assumptions!$B$10/(4*Assumptions!$B$6)+(SUMPRODUCT($C$15:$T$15,--($C$2:$T$2<T$2))+0.5*T$15)/(4*Assumptions!$B$6)
A33: Impairment charge | B33: $M | C33: =IF(C$2=Assumptions!$B$53,Assumptions!$B$51*Assumptions!$B$8*MAX(0,4*Assumptions!$B$4-Assumptions!$B$9-C$2)/(4*Assumptions!$B$4),0) | D33: =IF(D$2=Assumptions!$B$53,Assumptions!$B$51*Assumptions!$B$8*MAX(0,4*Assumptions!$B$4-Assumptions!$B$9-D$2)/(4*Assumptions!$B$4),0) | E33: =IF(E$2=Assumptions!$B$53,Assumptions!$B$51*Assumptions!$B$8*MAX(0,4*Assumptions!$B$4-Assumptions!$B$9-E$2)/(4*Assumptions!$B$4),0) | F33: =IF(F$2=Assumptions!$B$53,Assumptions!$B$51*Assumptions!$B$8*MAX(0,4*Assumptions!$B$4-Assumptions!$B$9-F$2)/(4*Assumptions!$B$4),0) | G33: =IF(G$2=Assumptions!$B$53,Assumptions!$B$51*Assumptions!$B$8*MAX(0,4*Assumptions!$B$4-Assumptions!$B$9-G$2)/(4*Assumptions!$B$4),0) | H33: =IF(H$2=Assumptions!$B$53,Assumptions!$B$51*Assumptions!$B$8*MAX(0,4*Assumptions!$B$4-Assumptions!$B$9-H$2)/(4*Assumptions!$B$4),0) | I33: =IF(I$2=Assumptions!$B$53,Assumptions!$B$51*Assumptions!$B$8*MAX(0,4*Assumptions!$B$4-Assumptions!$B$9-I$2)/(4*Assumptions!$B$4),0) | J33: =IF(J$2=Assumptions!$B$53,Assumptions!$B$51*Assumptions!$B$8*MAX(0,4*Assumptions!$B$4-Assumptions!$B$9-J$2)/(4*Assumptions!$B$4),0) | ... T33: =IF(T$2=Assumptions!$B$53,Assumptions!$B$51*Assumptions!$B$8*MAX(0,4*Assumptions!$B$4-Assumptions!$B$9-T$2)/(4*Assumptions!$B$4),0)
A34: Total D&A | B34: $M | C34: =C30+C31+C32 | D34: =D30+D31+D32 | E34: =E30+E31+E32 | F34: =F30+F31+F32 | G34: =G30+G31+G32 | H34: =H30+H31+H32 | I34: =I30+I31+I32 | J34: =J30+J31+J32 | ... T34: =T30+T31+T32
A35: EBIT (adj.; pre-SBC) = EBITDA - D&A - impairment | B35: $M | C35: =C$7-C34-C33 | D35: =D$7-D34-D33 | E35: =E$7-E34-E33 | F35: =F$7-F34-F33 | G35: =G$7-G34-G33 | H35: =H$7-H34-H33 | I35: =I$7-I34-I33 | J35: =J$7-J34-J33 | ... T35: =T$7-T34-T33
A36: EBIT margin | B36: % | C36: =C35/C$6 | D36: =D35/D$6 | E36: =E35/E$6 | F36: =F35/F$6 | G36: =G35/G$6 | H36: =H35/H$6 | I36: =I35/I$6 | J36: =J35/J$6 | ... T36: =T35/T$6
A37: D&A / revenue | B37: % | C37: =C34/C$6 | D37: =D34/D$6 | E37: =E34/E$6 | F37: =F34/F$6 | G37: =G34/G$6 | H37: =H34/H$6 | I37: =I34/I$6 | J37: =J34/J$6 | ... T37: =T34/T$6
A39: DEPRECIATION @ life scenario C | B39: =Assumptions!$B$5
A40: Existing 6/30 server base | B40: $M | C40: =IF(C$2<4*Assumptions!$B$5-Assumptions!$B$9,Assumptions!$B$8/(4*Assumptions!$B$5)*IF(C$2>=Assumptions!$B$53,1-Assumptions!$B$51,1),0) | D40: =IF(D$2<4*Assumptions!$B$5-Assumptions!$B$9,Assumptions!$B$8/(4*Assumptions!$B$5)*IF(D$2>=Assumptions!$B$53,1-Assumptions!$B$51,1),0) | E40: =IF(E$2<4*Assumptions!$B$5-Assumptions!$B$9,Assumptions!$B$8/(4*Assumptions!$B$5)*IF(E$2>=Assumptions!$B$53,1-Assumptions!$B$51,1),0) | F40: =IF(F$2<4*Assumptions!$B$5-Assumptions!$B$9,Assumptions!$B$8/(4*Assumptions!$B$5)*IF(F$2>=Assumptions!$B$53,1-Assumptions!$B$51,1),0) | G40: =IF(G$2<4*Assumptions!$B$5-Assumptions!$B$9,Assumptions!$B$8/(4*Assumptions!$B$5)*IF(G$2>=Assumptions!$B$53,1-Assumptions!$B$51,1),0) | H40: =IF(H$2<4*Assumptions!$B$5-Assumptions!$B$9,Assumptions!$B$8/(4*Assumptions!$B$5)*IF(H$2>=Assumptions!$B$53,1-Assumptions!$B$51,1),0) | I40: =IF(I$2<4*Assumptions!$B$5-Assumptions!$B$9,Assumptions!$B$8/(4*Assumptions!$B$5)*IF(I$2>=Assumptions!$B$53,1-Assumptions!$B$51,1),0) | J40: =IF(J$2<4*Assumptions!$B$5-Assumptions!$B$9,Assumptions!$B$8/(4*Assumptions!$B$5)*IF(J$2>=Assumptions!$B$53,1-Assumptions!$B$51,1),0) | ... T40: =IF(T$2<4*Assumptions!$B$5-Assumptions!$B$9,Assumptions!$B$8/(4*Assumptions!$B$5)*IF(T$2>=Assumptions!$B$53,1-Assumptions!$B$51,1),0)
A41: New GPU cohorts (half-quarter convention) | B41: $M | C41: =(SUMPRODUCT($C$14:$T$14,--($C$2:$T$2<C$2),--($C$2:$T$2>C$2-4*Assumptions!$B$5))+0.5*C$14+0.5*SUMPRODUCT($C$14:$T$14,--($C$2:$T$2=C$2-4*Assumptions!$B$5)))/(4*Assumptions!$B$5) | D41: =(SUMPRODUCT($C$14:$T$14,--($C$2:$T$2<D$2),--($C$2:$T$2>D$2-4*Assumptions!$B$5))+0.5*D$14+0.5*SUMPRODUCT($C$14:$T$14,--($C$2:$T$2=D$2-4*Assumptions!$B$5)))/(4*Assumptions!$B$5) | E41: =(SUMPRODUCT($C$14:$T$14,--($C$2:$T$2<E$2),--($C$2:$T$2>E$2-4*Assumptions!$B$5))+0.5*E$14+0.5*SUMPRODUCT($C$14:$T$14,--($C$2:$T$2=E$2-4*Assumptions!$B$5)))/(4*Assumptions!$B$5) | F41: =(SUMPRODUCT($C$14:$T$14,--($C$2:$T$2<F$2),--($C$2:$T$2>F$2-4*Assumptions!$B$5))+0.5*F$14+0.5*SUMPRODUCT($C$14:$T$14,--($C$2:$T$2=F$2-4*Assumptions!$B$5)))/(4*Assumptions!$B$5) | G41: =(SUMPRODUCT($C$14:$T$14,--($C$2:$T$2<G$2),--($C$2:$T$2>G$2-4*Assumptions!$B$5))+0.5*G$14+0.5*SUMPRODUCT($C$14:$T$14,--($C$2:$T$2=G$2-4*Assumptions!$B$5)))/(4*Assumptions!$B$5) | H41: =(SUMPRODUCT($C$14:$T$14,--($C$2:$T$2<H$2),--($C$2:$T$2>H$2-4*Assumptions!$B$5))+0.5*H$14+0.5*SUMPRODUCT($C$14:$T$14,--($C$2:$T$2=H$2-4*Assumptions!$B$5)))/(4*Assumptions!$B$5) | I41: =(SUMPRODUCT($C$14:$T$14,--($C$2:$T$2<I$2),--($C$2:$T$2>I$2-4*Assumptions!$B$5))+0.5*I$14+0.5*SUMPRODUCT($C$14:$T$14,--($C$2:$T$2=I$2-4*Assumptions!$B$5)))/(4*Assumptions!$B$5) | J41: =(SUMPRODUCT($C$14:$T$14,--($C$2:$T$2<J$2),--($C$2:$T$2>J$2-4*Assumptions!$B$5))+0.5*J$14+0.5*SUMPRODUCT($C$14:$T$14,--($C$2:$T$2=J$2-4*Assumptions!$B$5)))/(4*Assumptions!$B$5) | ... T41: =(SUMPRODUCT($C$14:$T$14,--($C$2:$T$2<T$2),--($C$2:$T$2>T$2-4*Assumptions!$B$5))+0.5*T$14+0.5*SUMPRODUCT($C$14:$T$14,--($C$2:$T$2=T$2-4*Assumptions!$B$5)))/(4*Assumptions!$B$5)
A42: Non-GPU (existing + new) | B42: $M | C42: =Assumptions!$B$10/(4*Assumptions!$B$6)+(SUMPRODUCT($C$15:$T$15,--($C$2:$T$2<C$2))+0.5*C$15)/(4*Assumptions!$B$6) | D42: =Assumptions!$B$10/(4*Assumptions!$B$6)+(SUMPRODUCT($C$15:$T$15,--($C$2:$T$2<D$2))+0.5*D$15)/(4*Assumptions!$B$6) | E42: =Assumptions!$B$10/(4*Assumptions!$B$6)+(SUMPRODUCT($C$15:$T$15,--($C$2:$T$2<E$2))+0.5*E$15)/(4*Assumptions!$B$6) | F42: =Assumptions!$B$10/(4*Assumptions!$B$6)+(SUMPRODUCT($C$15:$T$15,--($C$2:$T$2<F$2))+0.5*F$15)/(4*Assumptions!$B$6) | G42: =Assumptions!$B$10/(4*Assumptions!$B$6)+(SUMPRODUCT($C$15:$T$15,--($C$2:$T$2<G$2))+0.5*G$15)/(4*Assumptions!$B$6) | H42: =Assumptions!$B$10/(4*Assumptions!$B$6)+(SUMPRODUCT($C$15:$T$15,--($C$2:$T$2<H$2))+0.5*H$15)/(4*Assumptions!$B$6) | I42: =Assumptions!$B$10/(4*Assumptions!$B$6)+(SUMPRODUCT($C$15:$T$15,--($C$2:$T$2<I$2))+0.5*I$15)/(4*Assumptions!$B$6) | J42: =Assumptions!$B$10/(4*Assumptions!$B$6)+(SUMPRODUCT($C$15:$T$15,--($C$2:$T$2<J$2))+0.5*J$15)/(4*Assumptions!$B$6) | ... T42: =Assumptions!$B$10/(4*Assumptions!$B$6)+(SUMPRODUCT($C$15:$T$15,--($C$2:$T$2<T$2))+0.5*T$15)/(4*Assumptions!$B$6)
A43: Impairment charge | B43: $M | C43: =IF(C$2=Assumptions!$B$53,Assumptions!$B$51*Assumptions!$B$8*MAX(0,4*Assumptions!$B$5-Assumptions!$B$9-C$2)/(4*Assumptions!$B$5),0) | D43: =IF(D$2=Assumptions!$B$53,Assumptions!$B$51*Assumptions!$B$8*MAX(0,4*Assumptions!$B$5-Assumptions!$B$9-D$2)/(4*Assumptions!$B$5),0) | E43: =IF(E$2=Assumptions!$B$53,Assumptions!$B$51*Assumptions!$B$8*MAX(0,4*Assumptions!$B$5-Assumptions!$B$9-E$2)/(4*Assumptions!$B$5),0) | F43: =IF(F$2=Assumptions!$B$53,Assumptions!$B$51*Assumptions!$B$8*MAX(0,4*Assumptions!$B$5-Assumptions!$B$9-F$2)/(4*Assumptions!$B$5),0) | G43: =IF(G$2=Assumptions!$B$53,Assumptions!$B$51*Assumptions!$B$8*MAX(0,4*Assumptions!$B$5-Assumptions!$B$9-G$2)/(4*Assumptions!$B$5),0) | H43: =IF(H$2=Assumptions!$B$53,Assumptions!$B$51*Assumptions!$B$8*MAX(0,4*Assumptions!$B$5-Assumptions!$B$9-H$2)/(4*Assumptions!$B$5),0) | I43: =IF(I$2=Assumptions!$B$53,Assumptions!$B$51*Assumptions!$B$8*MAX(0,4*Assumptions!$B$5-Assumptions!$B$9-I$2)/(4*Assumptions!$B$5),0) | J43: =IF(J$2=Assumptions!$B$53,Assumptions!$B$51*Assumptions!$B$8*MAX(0,4*Assumptions!$B$5-Assumptions!$B$9-J$2)/(4*Assumptions!$B$5),0) | ... T43: =IF(T$2=Assumptions!$B$53,Assumptions!$B$51*Assumptions!$B$8*MAX(0,4*Assumptions!$B$5-Assumptions!$B$9-T$2)/(4*Assumptions!$B$5),0)
A44: Total D&A | B44: $M | C44: =C40+C41+C42 | D44: =D40+D41+D42 | E44: =E40+E41+E42 | F44: =F40+F41+F42 | G44: =G40+G41+G42 | H44: =H40+H41+H42 | I44: =I40+I41+I42 | J44: =J40+J41+J42 | ... T44: =T40+T41+T42
A45: EBIT (adj.; pre-SBC) = EBITDA - D&A - impairment | B45: $M | C45: =C$7-C44-C43 | D45: =D$7-D44-D43 | E45: =E$7-E44-E43 | F45: =F$7-F44-F43 | G45: =G$7-G44-G43 | H45: =H$7-H44-H43 | I45: =I$7-I44-I43 | J45: =J$7-J44-J43 | ... T45: =T$7-T44-T43
...

Sheet Annual
A1: $M | B1: Basis | C1: FY2026 | D1: FY2027 | E1: FY2028 | F1: FY2029 | G1: FY2030
A2: Revenue | B2: FY26 incl. 1H actual | C2: =SUMIF(Model!$C$3:$T$3,2026,Model!$C$6:$T$6)+Assumptions!$B$32 | D2: =SUMIF(Model!$C$3:$T$3,2027,Model!$C$6:$T$6) | E2: =SUMIF(Model!$C$3:$T$3,2028,Model!$C$6:$T$6) | F2: =SUMIF(Model!$C$3:$T$3,2029,Model!$C$6:$T$6) | G2: =SUMIF(Model!$C$3:$T$3,2030,Model!$C$6:$T$6)
A3: Adj. EBITDA | B3: FY26 incl. 1H actual | C3: =SUMIF(Model!$C$3:$T$3,2026,Model!$C$7:$T$7)+Assumptions!$B$33 | D3: =SUMIF(Model!$C$3:$T$3,2027,Model!$C$7:$T$7) | E3: =SUMIF(Model!$C$3:$T$3,2028,Model!$C$7:$T$7) | F3: =SUMIF(Model!$C$3:$T$3,2029,Model!$C$7:$T$7) | G3: =SUMIF(Model!$C$3:$T$3,2030,Model!$C$7:$T$7)
A4: Capex | B4: FY26 incl. 1H actual | C4: =SUMIF(Model!$C$3:$T$3,2026,Model!$C$10:$T$10)+Assumptions!$B$17 | D4: =SUMIF(Model!$C$3:$T$3,2027,Model!$C$10:$T$10) | E4: =SUMIF(Model!$C$3:$T$3,2028,Model!$C$10:$T$10) | F4: =SUMIF(Model!$C$3:$T$3,2029,Model!$C$10:$T$10) | G4: =SUMIF(Model!$C$3:$T$3,2030,Model!$C$10:$T$10)
A5: D&A @ 4-yr | B5: FY26 1H restated to life (D) | C5: =SUMIF(Model!$C$3:$T$3,2026,Model!$C$24:$T$24)+(Assumptions!$B$34-4*Assumptions!$B$35+4*Assumptions!$B$35*5/Assumptions!$B$3) | D5: =SUMIF(Model!$C$3:$T$3,2027,Model!$C$24:$T$24) | E5: =SUMIF(Model!$C$3:$T$3,2028,Model!$C$24:$T$24) | F5: =SUMIF(Model!$C$3:$T$3,2029,Model!$C$24:$T$24) | G5: =SUMIF(Model!$C$3:$T$3,2030,Model!$C$24:$T$24)
A6: Impairment @ 4-yr | C6: =SUMIF(Model!$C$3:$T$3,2026,Model!$C$23:$T$23) | D6: =SUMIF(Model!$C$3:$T$3,2027,Model!$C$23:$T$23) | E6: =SUMIF(Model!$C$3:$T$3,2028,Model!$C$23:$T$23) | F6: =SUMIF(Model!$C$3:$T$3,2029,Model!$C$23:$T$23) | G6: =SUMIF(Model!$C$3:$T$3,2030,Model!$C$23:$T$23)
A7: EBIT @ 4-yr | B7: EBITDA less D&A less impairment | C7: =C3-C5-C6 | D7: =D3-D5-D6 | E7: =E3-E5-E6 | F7: =F3-F5-F6 | G7: =G3-G5-G6
A8: EBIT margin @ 4-yr | C8: =C7/C2 | D8: =D7/D2 | E8: =E7/E2 | F8: =F7/F2 | G8: =G7/G2
A9: D&A @ 5-yr | B9: FY26 1H restated to life (D) | C9: =SUMIF(Model!$C$3:$T$3,2026,Model!$C$34:$T$34)+(Assumptions!$B$34-4*Assumptions!$B$35+4*Assumptions!$B$35*5/Assumptions!$B$4) | D9: =SUMIF(Model!$C$3:$T$3,2027,Model!$C$34:$T$34) | E9: =SUMIF(Model!$C$3:$T$3,2028,Model!$C$34:$T$34) | F9: =SUMIF(Model!$C$3:$T$3,2029,Model!$C$34:$T$34) | G9: =SUMIF(Model!$C$3:$T$3,2030,Model!$C$34:$T$34)
A10: Impairment @ 5-yr | C10: =SUMIF(Model!$C$3:$T$3,2026,Model!$C$33:$T$33) | D10: =SUMIF(Model!$C$3:$T$3,2027,Model!$C$33:$T$33) | E10: =SUMIF(Model!$C$3:$T$3,2028,Model!$C$33:$T$33) | F10: =SUMIF(Model!$C$3:$T$3,2029,Model!$C$33:$T$33) | G10: =SUMIF(Model!$C$3:$T$3,2030,Model!$C$33:$T$33)
A11: EBIT @ 5-yr | B11: EBITDA less D&A less impairment | C11: =C3-C9-C10 | D11: =D3-D9-D10 | E11: =E3-E9-E10 | F11: =F3-F9-F10 | G11: =G3-G9-G10
A12: EBIT margin @ 5-yr | C12: =C11/C2 | D12: =D11/D2 | E12: =E11/E2 | F12: =F11/F2 | G12: =G11/G2
A13: D&A @ 6-yr | B13: FY26 1H restated to life (D) | C13: =SUMIF(Model!$C$3:$T$3,2026,Model!$C$44:$T$44)+(Assumptions!$B$34-4*Assumptions!$B$35+4*Assumptions!$B$35*5/Assumptions!$B$5) | D13: =SUMIF(Model!$C$3:$T$3,2027,Model!$C$44:$T$44) | E13: =SUMIF(Model!$C$3:$T$3,2028,Model!$C$44:$T$44) | F13: =SUMIF(Model!$C$3:$T$3,2029,Model!$C$44:$T$44) | G13: =SUMIF(Model!$C$3:$T$3,2030,Model!$C$44:$T$44)
A14: Impairment @ 6-yr | C14: =SUMIF(Model!$C$3:$T$3,2026,Model!$C$43:$T$43) | D14: =SUMIF(Model!$C$3:$T$3,2027,Model!$C$43:$T$43) | E14: =SUMIF(Model!$C$3:$T$3,2028,Model!$C$43:$T$43) | F14: =SUMIF(Model!$C$3:$T$3,2029,Model!$C$43:$T$43) | G14: =SUMIF(Model!$C$3:$T$3,2030,Model!$C$43:$T$43)
A15: EBIT @ 6-yr | B15: EBITDA less D&A less impairment | C15: =C3-C13-C14 | D15: =D3-D13-D14 | E15: =E3-E13-E14 | F15: =F3-F13-F14 | G15: =G3-G13-G14
A16: EBIT margin @ 6-yr | C16: =C15/C2 | D16: =D15/D2 | E16: =E15/E2 | F16: =F15/F2 | G16: =G15/G2
A17: Cash interest | B17: H2'26 only | C17: =SUMIF(Model!$C$3:$T$3,2026,Model!$C$50:$T$50) | D17: =SUMIF(Model!$C$3:$T$3,2027,Model!$C$50:$T$50) | E17: =SUMIF(Model!$C$3:$T$3,2028,Model!$C$50:$T$50) | F17: =SUMIF(Model!$C$3:$T$3,2029,Model!$C$50:$T$50) | G17: =SUMIF(Model!$C$3:$T$3,2030,Model!$C$50:$T$50)
A18: Interest on extra funding | C18: =SUMIF(Model!$C$3:$T$3,2026,Model!$C$51:$T$51) | D18: =SUMIF(Model!$C$3:$T$3,2027,Model!$C$51:$T$51) | E18: =SUMIF(Model!$C$3:$T$3,2028,Model!$C$51:$T$51) | F18: =SUMIF(Model!$C$3:$T$3,2029,Model!$C$51:$T$51) | G18: =SUMIF(Model!$C$3:$T$3,2030,Model!$C$51:$T$51)
A19: FCF (EBITDA-capex-interest) | B19: FY26 = H2 only | C19: =SUMIF(Model!$C$3:$T$3,2026,Model!$C$54:$T$54) | D19: =SUMIF(Model!$C$3:$T$3,2027,Model!$C$54:$T$54) | E19: =SUMIF(Model!$C$3:$T$3,2028,Model!$C$54:$T$54) | F19: =SUMIF(Model!$C$3:$T$3,2029,Model!$C$54:$T$54) | G19: =SUMIF(Model!$C$3:$T$3,2030,Model!$C$54:$T$54)
A20: External funding need, year-end (cumulative) | C20: =INDEX(Model!$C$56:$T$56,MATCH("Q4 2026",Model!$C$1:$T$1,0)) | D20: =INDEX(Model!$C$56:$T$56,MATCH("Q4 2027",Model!$C$1:$T$1,0)) | E20: =INDEX(Model!$C$56:$T$56,MATCH("Q4 2028",Model!$C$1:$T$1,0)) | F20: =INDEX(Model!$C$56:$T$56,MATCH("Q4 2029",Model!$C$1:$T$1,0)) | G20: =INDEX(Model!$C$56:$T$56,MATCH("Q4 2030",Model!$C$1:$T$1,0))
A21: Memo: consensus FCF (MarketScreener) | C21: -17500 | D21: -23148 | E21: -25500 | F21: n/a | G21: n/a
A22: Memo: 1H26 D&A at life L = 471.7 - 344.4 + 344.4x5/L, where 344.4 = 4 x 86.1 (since D4 - D5 = D5/4). FY26 company est. benefit: $167.6M on YE25 assets.

Sheet Horizons
A1: Mark | B1: Quarter shown | C1: Run-rate (qtr x4) $M: | D1: EBITDA | E1: D&A 4y | F1: D&A 5y | G1: D&A 6y | H1: EBIT 4y | I1: EBIT 5y | J1: EBIT 6y | K1: FCF | L1: Cum. external funding need
A2: 6-month (Apr-2027) | B2: Q1 2027 | D2: =INDEX(Model!$C$7:$T$7,MATCH($B2,Model!$C$1:$T$1,0))*4 | E2: =INDEX(Model!$C$24:$T$24,MATCH($B2,Model!$C$1:$T$1,0))*4 | F2: =INDEX(Model!$C$34:$T$34,MATCH($B2,Model!$C$1:$T$1,0))*4 | G2: =INDEX(Model!$C$44:$T$44,MATCH($B2,Model!$C$1:$T$1,0))*4 | H2: =INDEX(Model!$C$25:$T$25,MATCH($B2,Model!$C$1:$T$1,0))*4 | I2: =INDEX(Model!$C$35:$T$35,MATCH($B2,Model!$C$1:$T$1,0))*4 | J2: =INDEX(Model!$C$45:$T$45,MATCH($B2,Model!$C$1:$T$1,0))*4 | K2: =INDEX(Model!$C$54:$T$54,MATCH($B2,Model!$C$1:$T$1,0))*4 | L2: =INDEX(Model!$C$56:$T$56,MATCH($B2,Model!$C$1:$T$1,0))*1
A3: 1-year (Oct-2027) | B3: Q3 2027 | D3: =INDEX(Model!$C$7:$T$7,MATCH($B3,Model!$C$1:$T$1,0))*4 | E3: =INDEX(Model!$C$24:$T$24,MATCH($B3,Model!$C$1:$T$1,0))*4 | F3: =INDEX(Model!$C$34:$T$34,MATCH($B3,Model!$C$1:$T$1,0))*4 | G3: =INDEX(Model!$C$44:$T$44,MATCH($B3,Model!$C$1:$T$1,0))*4 | H3: =INDEX(Model!$C$25:$T$25,MATCH($B3,Model!$C$1:$T$1,0))*4 | I3: =INDEX(Model!$C$35:$T$35,MATCH($B3,Model!$C$1:$T$1,0))*4 | J3: =INDEX(Model!$C$45:$T$45,MATCH($B3,Model!$C$1:$T$1,0))*4 | K3: =INDEX(Model!$C$54:$T$54,MATCH($B3,Model!$C$1:$T$1,0))*4 | L3: =INDEX(Model!$C$56:$T$56,MATCH($B3,Model!$C$1:$T$1,0))*1
A4: 3-year (Oct-2029) | B4: Q3 2029 | D4: =INDEX(Model!$C$7:$T$7,MATCH($B4,Model!$C$1:$T$1,0))*4 | E4: =INDEX(Model!$C$24:$T$24,MATCH($B4,Model!$C$1:$T$1,0))*4 | F4: =INDEX(Model!$C$34:$T$34,MATCH($B4,Model!$C$1:$T$1,0))*4 | G4: =INDEX(Model!$C$44:$T$44,MATCH($B4,Model!$C$1:$T$1,0))*4 | H4: =INDEX(Model!$C$25:$T$25,MATCH($B4,Model!$C$1:$T$1,0))*4 | I4: =INDEX(Model!$C$35:$T$35,MATCH($B4,Model!$C$1:$T$1,0))*4 | J4: =INDEX(Model!$C$45:$T$45,MATCH($B4,Model!$C$1:$T$1,0))*4 | K4: =INDEX(Model!$C$54:$T$54,MATCH($B4,Model!$C$1:$T$1,0))*4 | L4: =INDEX(Model!$C$56:$T$56,MATCH($B4,Model!$C$1:$T$1,0))*1

Sheet Reverse_DCF
A1: Item | B1: 4-yr | C1: 5-yr | D1: 6-yr | E1: Note
A2: PV of FCF Q3'26-Q4'30 | B2: =SUMPRODUCT(Model!$C$54:$T$54,Model!$C$57:$T$57) | C2: =SUMPRODUCT(Model!$C$54:$T$54,Model!$C$57:$T$57) | D2: =SUMPRODUCT(Model!$C$54:$T$54,Model!$C$57:$T$57) | E2: Same for all lives (book life does not change cash)
A3: FY2030 EBITDA | B3: =Annual!G3 | C3: =Annual!G3 | D3: =Annual!G3
A4: Steady-state replacement capex = annualized Q4'30 D&A at that life | B4: =4*(Model!$T$20+Model!$T$21+Model!$T$22) | C4: =4*(Model!$T$30+Model!$T$31+Model!$T$32) | D4: =4*(Model!$T$40+Model!$T$41+Model!$T$42) | E4: Economic life = book life assumption
A5: Gross GPU in service within life (Q4'30) | B5: =4*Assumptions!$B$3*(Model!$T$20+Model!$T$21) | C5: =4*Assumptions!$B$4*(Model!$T$30+Model!$T$31) | D5: =4*Assumptions!$B$5*(Model!$T$40+Model!$T$41)
A6: Terminal FCF (yr 2031) | B6: =(B3*(1+Assumptions!$B$56)-B4*(1+Assumptions!$B$56))*(1-Assumptions!$B$57)-Assumptions!$B$56*B5 | C6: =(C3*(1+Assumptions!$B$56)-C4*(1+Assumptions!$B$56))*(1-Assumptions!$B$57)-Assumptions!$B$56*C5 | D6: =(D3*(1+Assumptions!$B$56)-D4*(1+Assumptions!$B$56))*(1-Assumptions!$B$57)-Assumptions!$B$56*D5 | E6: (1-t)(EBITDA - replacement) - g x gross (growth reinvestment)
A7: Terminal value (end-2030) | B7: =B6/(Assumptions!$B$55-Assumptions!$B$56) | C7: =C6/(Assumptions!$B$55-Assumptions!$B$56) | D7: =D6/(Assumptions!$B$55-Assumptions!$B$56)
A8: PV of terminal value | B8: =B7*Model!$T$57 | C8: =C7*Model!$T$57 | D8: =D7*Model!$T$57
A9: Model EV | B9: =B2+B8 | C9: =C2+C8 | D9: =D2+D8
A10: Model value per share | B10: =(B9+Assumptions!$B$59)/Assumptions!$B$60 | C10: =(C9+Assumptions!$B$59)/Assumptions!$B$60 | D10: =(D9+Assumptions!$B$59)/Assumptions!$B$60 | E10: vs $242.81
A11: Upside/(downside) vs price | B11: =B10/Assumptions!$B$61-1 | C11: =C10/Assumptions!$B$61-1 | D11: =D10/Assumptions!$B$61-1
A12: REQUIRED FY2030 EBITDA to justify market EV | B12: =((Assumptions!$B$58-B2)/Model!$T$57*(Assumptions!$B$55-Assumptions!$B$56)+Assumptions!$B$56*B5)/((1-Assumptions!$B$57)*(1+Assumptions!$B$56))+B4 | C12: =((Assumptions!$B$58-C2)/Model!$T$57*(Assumptions!$B$55-Assumptions!$B$56)+Assumptions!$B$56*C5)/((1-Assumptions!$B$57)*(1+Assumptions!$B$56))+C4 | D12: =((Assumptions!$B$58-D2)/Model!$T$57*(Assumptions!$B$55-Assumptions!$B$56)+Assumptions!$B$56*D5)/((1-Assumptions!$B$57)*(1+Assumptions!$B$56))+D4 | E12: Holds interim FCF fixed (conservative: higher EBITDA would also lift interim FCF)
A13: Required EBITDA yield on gross GPU in service | B13: =B12/B5 | C13: =C12/C5 | D13: =D12/D5
A14: Modeled FY2030 EBITDA yield | B14: =B3/B5 | C14: =C3/C5 | D14: =D3/D5
A15: Required revenue per MW (yield x capex/MW x GPU share / FY28 margin) | B15: =B13*Assumptions!$B$22*Assumptions!$B$13/(Assumptions!$B$24/Assumptions!$B$25) | C15: =C13*Assumptions!$B$22*Assumptions!$B$13/(Assumptions!$B$24/Assumptions!$B$25) | D15: =D13*Assumptions!$B$22*Assumptions!$B$13/(Assumptions!$B$24/Assumptions!$B$25) | E15: Compare: installed base ~$12M/MW; Q2 deals $20-25M/MW; Q3 short-term >$40M/MW (Q2 letter)
A16: Implied terminal EV / FY2030 EBITDA | B16: =B7/B3 | C16: =C7/C3 | D16: =D7/D3
A18: Reference yields (Derived): EBITDA yield = $/MW x EBITDA margin / (capex per MW x GPU share). Installed base $12M x 60.8% / ($30M x 0.79) = 30.8%; Q2 deals $20M => 51.3%; $25M => 64.1%.

Sheet Peers
A1: Company | B1: Asset class | C1: Book useful life | D1: Recent change | E1: Source | F1: Tag
A2: Nebius | B2: Server & network equipment | C2: 5 yrs (from 1/1/26) | D2: 4 -> 5 yrs; -$43.0M Q2'26 D&A, ~-$167.6M FY26 est. | E2: https://www.sec.gov/Archives/edgar/data/1513845/000110465926094844/nbis-20260812xex99d2.htm ; /workspace/nebius/filings/nebius_fact_base.md | F2: Reported
A3: Nebius (prior) | B3: Server & network equipment | C3: 4 yrs | D3: 'Our main assets, GPUs, are currently depreciated over four years' (20-F p.56) | E3: https://www.sec.gov/Archives/edgar/data/1513845/000110465926052948/nbis-20251231x20f.htm | F3: Reported
A4: CoreWeave | B4: Technology equipment (incl. GPUs) | C4: 6 yrs | D4: 5 -> 6 yrs from 1/1/2023 | E4: https://gpuinsights.net/server-useful-life-gpu-depreciation-2026/ (summarizing CRWV FY25 10-K) | F4: Reported (via secondary)
A5: Microsoft | B5: Servers & network equipment | C5: 2-6 yrs | D5: 4 -> 6 yrs from FY2023 (+$3.7B op. income FY23) | E5: https://www.yieldtheory.app/research/michael-burry-ai-depreciation ; MSFT FY26 10-K | F5: Reported (via secondary)
A6: Alphabet | B6: Servers & some network equipment | C6: 6 yrs | D6: to 6 yrs from 2023 (-$3.9B depreciation 2023) | E6: https://gpuinsights.net/server-useful-life-gpu-depreciation-2026/ | F6: Reported (via secondary)
A7: Meta | B7: Servers & network assets | C7: 5-5.5 yrs | D7: most to 5.5 yrs from Jan-2025 (~-$2.9B 2025 depreciation) | E7: https://www.yieldtheory.app/research/michael-burry-ai-depreciation | F7: Reported (via secondary)
A8: Amazon | B8: Servers; subset of servers/networking | C8: 6 yrs; subset 5 yrs | D8: 5->6 (2024) then subset 6->5 (2025) citing AI/ML pace (+$1.4B depreciation) | E8: https://www.cnbc.com/2025/11/14/ai-gpu-depreciation-coreweave-nvidia-michael-burry.html | F8: Reported (via secondary)
A9: Oracle | B9: Servers & network equipment | C9: 6 yrs | D9: 5 -> 6 yrs from FY2025 (-$733M opex) | E9: https://www.yieldtheory.app/research/michael-burry-ai-depreciation | F9: Reported (via secondary)
A10: IREN | B10: GPUs | C10: not found | D10: FY26 10-K has a useful-life schedule; GPU figure not extracted. Some GPU financings use 36-month terms | E10: https://bizety.com/2025/09/23/gpu-depreciation-coreweave-vs-nebius/ | F10: not disclosed/not found
A11: Lambda | B11: GPUs | C11: not found (private) | F11: not disclosed/not found
A13: Note: secondary summaries used for peers; primary 10-K pages not re-read in this pass - verify before publishing.

Sheet Charts
A1: PNG charts generated by dep/charts.py (python mirror of this workbook; values cross-checked vs LibreOffice recalculation)
