Workbook

Sheet Comps
A1: Company | B1: Ticker / status | C1: Latest period used | D1: Period end | E1: Revenue backlog / RPO ($M) | F1: Backlog basis | G1: Contracted power (MW) | H1: Active / billing power (MW) | I1: MW basis / date | J1: Revenue LTM ($M) | K1: Revenue latest Q ($M) | L1: Revenue latest Q annualized ($M) | M1: Revenue YoY latest Q (%) | N1: Revenue per active MW (annualized Q, $M/MW) | O1: Adj. EBITDA LTM ($M) | P1: Adj. EBITDA latest Q ($M) | Q1: Adj. EBITDA margin LTM (%) | R1: Adj. EBITDA margin latest Q (%) | S1: Adj. EBITDA NTM consensus ($M) | T1: Forward revenue: FY guide / cons / reported est. ($M) | U1: Forward revenue basis | V1: Wtd avg effective cost of debt (%) | W1: Recent issuance coupons / spreads | X1: Total debt, latest BS ($M, ex-leases) | Y1: Cash & equivalents, latest BS ($M, ex-restricted) | Z1: Preferred stock ($M) | AA1: Pro forma debt adj. after BS date ($M) | AB1: Pro forma cash adj. after BS date ($M) | AC1: Pro forma bridge | AD1: Pro forma total debt ($M) | AE1: Pro forma cash ($M) | AF1: Top customer (% of revenue, latest period) | AG1: Named anchor customers | AH1: Share price ($) | AI1: Price date | AJ1: Shares, latest reported basis (M) | AK1: Shares, pro forma economic (M) | AL1: Market cap / equity value, reported basis ($M) | AM1: Market cap / equity value, pro forma ($M) | AN1: Aggregator EV ($M, StockAnalysis; incl. leases) | AO1: EV, reported basis ($M) | AP1: EV, pro forma ($M) [used for multiples] | AQ1: EV / contracted MW ($M/MW) | AR1: EV / active MW ($M/MW) | AS1: EV / LTM adj. EBITDA (x) | AT1: EV / annualized Q adj. EBITDA (x) | AU1: EV / NTM adj. EBITDA consensus (x) | AV1: EV / LTM revenue (x) | AW1: EV / annualized Q revenue (x) | AX1: EV / forward revenue (x) | AY1: Reported vs estimate | AZ1: Notes / gaps
A2: Nebius Group | B2: NBIS (Nasdaq) | C2: Q2 2026 (6-K filed 2026-08-12) | D2: 2026-06-30 | E2: 37490.6 | F2: ASC 606 RPO | G2: 3500 | H2: 170 | I2: Contracted '>3.5 GW' (Q1'26 letter, 2026-05-13; YE26 target 5 GW). Active ~170 MW at YE2025 (latest actual disclosed) | J2: 1355.1 | K2: 582.3 | L2: =IF(K2="","",K2*4) -> 2329.2 | M2: 454 | N2: =IF(OR(K2="",H2=""),"",K2*4/H2) -> 13.701176 | O2: 375.5 | P2: 236.2 | Q2: =IF(OR(O2="",J2=""),"",O2/J2*100) -> 27.710132 | R2: =IF(OR(P2="",K2=""),"",P2/K2*100) -> 40.563284 | S2: 5411.7 | T2: 3200 | U2: FY26 guidance midpoint $3.0-3.4B (reaffirmed Q2) | V2: 5.09 | W2: Aug-26 converts: 0.50% 2030 ($3.45B) & 4.50% 2034 ($2.3B); Jul-26 $775M GPU-backed facility SOFR+2.50%; Mar-26 converts 1.25% 2031 / 2.63% 2033 | X2: 8545.7 | Y2: 8042.1 | Z2: 0 | AA2: 5725 | AB2: 6455 | AC2: +$775M secured facility (assumed fully drawn; drawn amount not disclosed); +$5,750M Aug converts; -$800M 2029/31 notes exchanged (face; carrying ~= $802M); cash +$775M +~$5,680M est. net convert proceeds (Skeptic sheet basis). Ignores Q3 op. cash flow/capex/ATM | AD2: =IF(X2="","",X2+N(AA2)) -> 14270.7 | AE2: =IF(Y2="","",Y2+N(AB2)) -> 14497.1 | AF2: 24 | AG2: Microsoft, Meta (strategic LT contracts); Reflection, Cohere (Q2 deals); Customer C = 24%, D = 21%, E = 14% of Q2 rev (unnamed) | AH2: 242.81 | AI2: 2026-10-02 (close) | AJ2: 292.92115 | AK2: 308.72 | AL2: =IF(AH2="","",AH2*AJ2) -> 71124.185 | AM2: =IF(AH2="","",AH2*AK2) -> 74960.303 | AN2: 68710 | AO2: =IF(AL2="","",AL2+N(X2)-N(Y2)+N(Z2)) -> 71627.785 | AP2: =IF(AM2="","",AM2+N(AD2)-N(AE2)+N(Z2)) -> 74733.903 | AQ2: =IF(OR(AP2="",G2=""),"",AP2/G2) -> 21.352544 | AR2: =IF(OR(AP2="",H2=""),"",AP2/H2) -> 439.6112 | AS2: =IF(OR(AP2="",O2=""),"",IF(O2<=0,"n/m",AP2/O2)) -> 199.02504 | AT2: =IF(OR(AP2="",P2=""),"",IF(P2<=0,"n/m",AP2/(P2*4))) -> 79.100236 | AU2: =IF(OR(AP2="",S2=""),"",AP2/S2) -> 13.809691 | AV2: =IF(OR(AP2="",J2=""),"",AP2/J2) -> 55.150102 | AW2: =IF(OR(AP2="",K2=""),"",AP2/(K2*4)) -> 32.085653 | AX2: =IF(OR(AP2="",T2=""),"",AP2/T2) -> 23.354345 | AY2: Reported (filings); NTM = consensus estimate; MW = company disclosure | AZ2: LTM = H1'26 + (FY25 529.8 - H1'25 156.0); LTM EBITDA = 365.7 + (-64.9 - -74.7). Reported-basis shares = 271.86M + 21.07M NVIDIA pre-funded warrants. Active MW is stale (YE25) so EV/active MW and rev/MW overstate; no period-end active/connected MW disclosed for Q2. YE26 connected guidance 800MW-1GW. NTM consensus = Q4'26-Q3'27 quarterly cons (MarketScreener via Skeptic sheet).
A3: CoreWeave | B3: CRWV (Nasdaq) | C3: Q2 2026 (10-Q filed 2026-08-12) | D3: 2026-06-30 | E3: 103700 | F3: ASC 606 RPO $103.7B (company 'revenue backlog' $104.2B; excl. >$25B added early Q3) | G3: 3700 | H3: 1500 | I3: ~3.7 GW contracted / 1.5 GW active at 2026-06-30 (Q2 PR); YE26 active guide >1.85 GW | J3: 7590 | K3: 2575 | L3: =IF(K3="","",K3*4) -> 10300 | M3: 112.5 | N3: =IF(OR(K3="",H3=""),"",K3*4/H3) -> 6.8666667 | O3: 4400 | P3: 1510 | Q3: =IF(OR(O3="",J3=""),"",O3/J3*100) -> 57.971014 | R3: =IF(OR(P3="",K3=""),"",P3/K3*100) -> 58.640777 | S3: 14372 | T3: 12800 | U3: FY26 guidance midpoint $12.4-13.2B (Q2 call) | V3: 8.41 | W3: Sep-26 2.875% converts 2033 ($4.2B incl. option); Aug-26 DDTL 5.5 $2.6B (Ba2/BB+); Jun-26 9.625% notes 2032, 8.50% EUR notes 2032; Apr-26 9.75% notes 2031, 1.75% converts 2032; DDTL 5.0 SOFR+4.50% | X3: 35068 | Y3: 5539 | Z3: 0 | AA3: 4200 | AB3: 3638.2 | AC3: +$4,200M Sep-22 2.875% converts (option exercised); cash +$4,137.0M est. net proceeds - $498.8M base capped call (additional capped call cost not disclosed). DDTL 5.5 undrawn: excluded. Shares already at 2026-07-31 count | AD3: =IF(X3="","",X3+N(AA3)) -> 39268 | AE3: =IF(Y3="","",Y3+N(AB3)) -> 9177.2 | AF3: 36 | AG3: Customer A 36% (historically Microsoft; unnamed in 10-Q), B 26%, C 10% of Q2 rev; OpenAI (up to ~$6.5B order + earlier), Meta (~$21.0B Mar-26 order) | AH3: 89.62 | AI3: 2026-10-02 (close) | AJ3: 551.5366 | AK3: 551.5366 | AL3: =IF(AH3="","",AH3*AJ3) -> 49428.71 | AM3: =IF(AH3="","",AH3*AK3) -> 49428.71 | AN3: 95460 | AO3: =IF(AL3="","",AL3+N(X3)-N(Y3)+N(Z3)) -> 78957.71 | AP3: =IF(AM3="","",AM3+N(AD3)-N(AE3)+N(Z3)) -> 79519.51 | AQ3: =IF(OR(AP3="",G3=""),"",AP3/G3) -> 21.49176 | AR3: =IF(OR(AP3="",H3=""),"",AP3/H3) -> 53.013007 | AS3: =IF(OR(AP3="",O3=""),"",IF(O3<=0,"n/m",AP3/O3)) -> 18.072616 | AT3: =IF(OR(AP3="",P3=""),"",IF(P3<=0,"n/m",AP3/(P3*4))) -> 13.165482 | AU3: =IF(OR(AP3="",S3=""),"",AP3/S3) -> 5.5329467 | AV3: =IF(OR(AP3="",J3=""),"",AP3/J3) -> 10.476879 | AW3: =IF(OR(AP3="",K3=""),"",AP3/(K3*4)) -> 7.7203408 | AX3: =IF(OR(AP3="",T3=""),"",AP3/T3) -> 6.2124617 | AY3: Reported (filings); NTM = calendarized consensus estimate | AZ3: LTM = FY25 5,131 - H1'25 2,194 + H1'26 4,653. LTM adj. EBITDA = FY25 3,093 - 1,360 + 2,667. Debt = recourse + non-recourse carrying (ex leases). Cash incl. $15M marketable securities. NTM EBITDA = 0.25xFY26 cons 7,569 + 0.75xFY27 cons 16,640 (Skeptic sheet: Yahoo/MarketScreener). Aggregator EV $95.46B includes ~$16.5B lease liabilities -> not comparable.
A4: IREN | B4: IREN (Nasdaq) | C4: Q4 FY26 / FY ended 2026-06-30 (10-K filed 2026-08-27) | D4: 2026-06-30 | E4: 16600 | F4: RPO $5.1B + contracted lease value $11.4B (ASC 842) | G4: 5000 | H4: 420 | I4: ~5 GW grid connection agreements (10-K); operating = ~380 MW Bitcoin + ~40 MW AI Cloud at 2026-06-30 | J4: 707 | K4: 137.2 | L4: =IF(K4="","",K4*4) -> 548.8 | M4: -26.7 | N4: =IF(OR(K4="",H4=""),"",K4*4/H4) -> 1.3066667 | O4: 245.7 | P4: 19.2 | Q4: =IF(OR(O4="",J4=""),"",O4/J4*100) -> 34.752475 | R4: =IF(OR(P4="",K4=""),"",P4/K4*100) -> 13.994169 | U4: No revenue guidance; $4bn contracted ARR target for YE26 capacity (ARR, not revenue) | V4: 1.85 | W4: May-26 1.00% converts 2033 ($3.0B); USPP 5.96% fixed; DDTL SOFR+2.25% (swapped ~3.80%+spread); Aug-26 $2.4B Blue Owl/PIMCO GPU financing at 9.0% fixed (staged, undrawn at 10-K) | X4: 7593 | Y4: 5895.6 | Z4: 0 | AA4: 0 | AB4: 0 | AC4: Shares 380.19M (6/30) -> 394.06M (8/14), incl. 12.6M for Mirantis acquisition; post-6/30 ATM proceeds not separately disclosed -> no cash adj.; Aug-26 $2.4B financing undrawn -> excluded | AD4: =IF(X4="","",X4+N(AA4)) -> 7593 | AE4: =IF(Y4="","",Y4+N(AB4)) -> 5895.6 | AG4: Microsoft ($9.7B, 5-yr), NVIDIA ($3.4B, 5-yr) = 'substantial majority' of contracted revenue; also Perplexity, Cohere, Figure AI, Together AI, Fluidstack | AH4: 41.76 | AI4: 2026-10-02 (close) | AJ4: 380.19361 | AK4: 394.05865 | AL4: =IF(AH4="","",AH4*AJ4) -> 15876.885 | AM4: =IF(AH4="","",AH4*AK4) -> 16455.889 | AO4: =IF(AL4="","",AL4+N(X4)-N(Y4)+N(Z4)) -> 17574.285 | AP4: =IF(AM4="","",AM4+N(AD4)-N(AE4)+N(Z4)) -> 18153.289 | AQ4: =IF(OR(AP4="",G4=""),"",AP4/G4) -> 3.6306578 | AR4: =IF(OR(AP4="",H4=""),"",AP4/H4) -> 43.222117 | AS4: =IF(OR(AP4="",O4=""),"",IF(O4<=0,"n/m",AP4/O4)) -> 73.883961 | AT4: =IF(OR(AP4="",P4=""),"",IF(P4<=0,"n/m",AP4/(P4*4))) -> 236.37095 | AU4: =IF(OR(AP4="",S4=""),"",AP4/S4) | AV4: =IF(OR(AP4="",J4=""),"",AP4/J4) -> 25.676505 | AW4: =IF(OR(AP4="",K4=""),"",AP4/(K4*4)) -> 33.078151 | AX4: =IF(OR(AP4="",T4=""),"",AP4/T4) | AY4: Reported (filings) | AZ4: Top-customer % of revenue not disclosed (FY26 revenue 82% Bitcoin mining, no customer). Revenue/EBITDA still Bitcoin-heavy, so revenue- and EBITDA-based multiples are not comparable to AI-cloud peers. AI-only Q4 rev $70.5M / 40 MW = ~$7.1M per MW annualized. Contracted MW is grid power (gross), not IT MW.
A5: Oracle (consolidated) | B5: ORCL (NYSE) | C5: Q1 FY27 (10-Q filed 2026-09-11) | D5: 2026-08-31 | E5: 664000 | F5: ASC 606 RPO (company-wide; predominantly OCI per mgmt) | I5: Not disclosed in filings (Q1 PR: delivered 850 MW additional capacity in the quarter) | J5: 71776 | K5: 19345 | L5: =IF(K5="","",K5*4) -> 77380 | M5: 29.6 | N5: =IF(OR(K5="",H5=""),"",K5*4/H5) | O5: 38752 | P5: 11213 | Q5: =IF(OR(O5="",J5=""),"",O5/J5*100) -> 53.990192 | R5: =IF(OR(P5="",K5=""),"",P5/K5*100) -> 57.963298 | T5: 90000 | U5: FY27 (May-27) revenue guidance 'at least $90B' | V5: 4.48 | W5: Feb-26 $25B notes: 4.55% 2029 ... 6.85% 2066 (fixed-tranche wtd coupon 5.82%) + FRN 2029; 6.50% Series D mandatory convertible preferred | X5: 125337 | Y5: 37077 | Z5: 4954 | AA5: 0 | AB5: 0 | AC5: Share count already 2026-09-07 (post $20B ATM); no material post-BS debt events found | AD5: =IF(X5="","",X5+N(AA5)) -> 125337 | AE5: =IF(Y5="","",Y5+N(AB5)) -> 37077 | AG5: OpenAI (Stargate) and other AI labs; customer % not disclosed | AH5: 142.3 | AI5: 2026-10-02 (close) | AJ5: 3023.736 | AK5: 3023.736 | AL5: =IF(AH5="","",AH5*AJ5) -> 430277.63 | AM5: =IF(AH5="","",AH5*AK5) -> 430277.63 | AO5: =IF(AL5="","",AL5+N(X5)-N(Y5)+N(Z5)) -> 523491.63 | AP5: =IF(AM5="","",AM5+N(AD5)-N(AE5)+N(Z5)) -> 523491.63 | AQ5: =IF(OR(AP5="",G5=""),"",AP5/G5) | AR5: =IF(OR(AP5="",H5=""),"",AP5/H5) | AS5: =IF(OR(AP5="",O5=""),"",IF(O5<=0,"n/m",AP5/O5)) -> 13.508764 | AT5: =IF(OR(AP5="",P5=""),"",IF(P5<=0,"n/m",AP5/(P5*4))) -> 11.671534 | AU5: =IF(OR(AP5="",S5=""),"",AP5/S5) | AV5: =IF(OR(AP5="",J5=""),"",AP5/J5) -> 7.2934077 | AW5: =IF(OR(AP5="",K5=""),"",AP5/(K5*4)) -> 6.7652059 | AX5: =IF(OR(AP5="",T5=""),"",AP5/T5) -> 5.8165737 | AY5: Reported (filings); EBITDA derived | AZ5: Adj. EBITDA (derived, not company-reported) = GAAP op. income + depreciation + amortization + SBC; LTM = FY26 - Q1FY26 + Q1FY27 (XBRL). Cost of debt = annualized Q1 interest expense / avg debt (net of capitalized interest -> understated). EV includes $4,954M preferred. Whole-company EV; OCI not separable.
A6: Oracle - OCI segment (memo) | B6: ORCL segment | C6: Q1 FY27 | D6: 2026-08-31 | F6: RPO not split by segment | I6: n/d | J6: 22142 | K6: 7388 | L6: =IF(K6="","",K6*4) -> 29552 | M6: 120.7 | N6: =IF(OR(K6="",H6=""),"",K6*4/H6) | Q6: =IF(OR(O6="",J6=""),"",O6/J6*100) | R6: =IF(OR(P6="",K6=""),"",P6/K6*100) | AD6: =IF(X6="","",X6+N(AA6)) | AE6: =IF(Y6="","",Y6+N(AB6)) | AL6: =IF(AH6="","",AH6*AJ6) | AM6: =IF(AH6="","",AH6*AK6) | AO6: =IF(AL6="","",AL6+N(X6)-N(Y6)+N(Z6)) | AP6: =IF(AM6="","",AM6+N(AD6)-N(AE6)+N(Z6)) | AQ6: =IF(OR(AP6="",G6=""),"",AP6/G6) | AR6: =IF(OR(AP6="",H6=""),"",AP6/H6) | AS6: =IF(OR(AP6="",O6=""),"",IF(O6<=0,"n/m",AP6/O6)) | AT6: =IF(OR(AP6="",P6=""),"",IF(P6<=0,"n/m",AP6/(P6*4))) | AU6: =IF(OR(AP6="",S6=""),"",AP6/S6) | AV6: =IF(OR(AP6="",J6=""),"",AP6/J6) | AW6: =IF(OR(AP6="",K6=""),"",AP6/(K6*4)) | AX6: =IF(OR(AP6="",T6=""),"",AP6/T6) | AY6: Reported (cloud infrastructure revenue line) | AZ6: Cloud infrastructure (IaaS) revenue only. LTM = FY26 18,101 - Q1FY26 3,347 + Q1FY27 7,388. No segment EBITDA, debt or EV -> valuation multiples left blank.
A7: Nscale | B7: Private (S-1 filed 2026-09-18) | C7: H1 2026 (S-1) | D7: 2026-06-30 | E7: 103400 | F7: TCV of signed contracts at 2026-08-31 (not ASC 606 RPO); ~$2.6B active | G7: 1370 | I7: ~1.37 GW active + contracted at 2026-08-31; active MW not split out (~25k active GPUs of 461k) | J7: 163.2 | L7: =IF(K7="","",K7*4) | M7: 1252 | N7: =IF(OR(K7="",H7=""),"",K7*4/H7) | O7: -265.6 | Q7: =IF(OR(O7="",J7=""),"",O7/J7*100) -> -162.7451 | R7: =IF(OR(P7="",K7=""),"",P7/K7*100) | W7: Macquarie senior facility SOFR+7.50% (eff. 21.5%); Iceland DDTL SOFR+5.50%; Sep-26 $3.36B pre-IPO convertible notes (terms not disclosed) | X7: 137.4 | Y7: 1478.4 | Z7: 0 | AA7: 0 | AB7: 0 | AC7: Sep-26 $2.36B convertible notes funded (+$1B NVIDIA Nov) not added: convert to equity at IPO; valuation basis stale vs that round | AD7: =IF(X7="","",X7+N(AA7)) -> 137.4 | AE7: =IF(Y7="","",Y7+N(AB7)) -> 1478.4 | AF7: 52 | AG7: Microsoft (up to $43.8B through 2033), Anthropic (up to $44.6B, Aug-26) = ~85% of TCV; OpenAI | AI7: Series C 2026-03-09 | AL7: 14600 | AM7: 14600 | AO7: =IF(AL7="","",AL7+N(X7)-N(Y7)+N(Z7)) -> 13259 | AP7: =IF(AM7="","",AM7+N(AD7)-N(AE7)+N(Z7)) -> 13259 | AQ7: =IF(OR(AP7="",G7=""),"",AP7/G7) -> 9.6781022 | AR7: =IF(OR(AP7="",H7=""),"",AP7/H7) | AS7: =IF(OR(AP7="",O7=""),"",IF(O7<=0,"n/m",AP7/O7)) -> n/m | AT7: =IF(OR(AP7="",P7=""),"",IF(P7<=0,"n/m",AP7/(P7*4))) | AU7: =IF(OR(AP7="",S7=""),"",AP7/S7) | AV7: =IF(OR(AP7="",J7=""),"",AP7/J7) -> 81.243873 | AW7: =IF(OR(AP7="",K7=""),"",AP7/(K7*4)) | AX7: =IF(OR(AP7="",T7=""),"",AP7/T7) | AY7: Reported (S-1) for financials; valuation = last private round | AZ7: Equity value = Series C valuation $14.6B (Mar-26), pre-convert; FT-reported IPO target ~$35B not used. LTM = H1'26 140.6 + FY25 33.0 - H1'25 10.4; LTM adj. EBITDA = -199.2 + -81.7 - (-15.3). YoY is H1/H1 (no quarterly split). Weighted avg cost of debt not computable (debt small, mixed).
A8: Crusoe | B8: Private | C8: Series F (2026-09-17) | D8: 2026-09-17 | E8: 140000 | F8: '$140B+' total contract value (company PR; term not disclosed) | G8: 6000 | H8: 1000 | I8: '6GW+ gross contracted', '~1 GW gross delivered and operational' (Series F PR) | L8: =IF(K8="","",K8*4) | N8: =IF(OR(K8="",H8=""),"",K8*4/H8) | Q8: =IF(OR(O8="",J8=""),"",O8/J8*100) | R8: =IF(OR(P8="",K8=""),"",P8/K8*100) | T8: 2000 | U8: 'On track for $2B' 2026 revenue (Newcomer, from financials obtained) - ESTIMATE | W8: Not disclosed | AC8: No balance sheet disclosed | AD8: =IF(X8="","",X8+N(AA8)) | AE8: =IF(Y8="","",Y8+N(AB8)) | AG8: OpenAI, Microsoft, Meta (Bloomberg) | AI8: Series F 2026-09-17 | AL8: 30900 | AM8: 30900 | AO8: =IF(AL8="","",AL8+N(X8)-N(Y8)+N(Z8)) -> 30900 | AP8: =IF(AM8="","",AM8+N(AD8)-N(AE8)+N(Z8)) -> 30900 | AQ8: =IF(OR(AP8="",G8=""),"",AP8/G8) -> 5.15 | AR8: =IF(OR(AP8="",H8=""),"",AP8/H8) -> 30.9 | AS8: =IF(OR(AP8="",O8=""),"",IF(O8<=0,"n/m",AP8/O8)) | AT8: =IF(OR(AP8="",P8=""),"",IF(P8<=0,"n/m",AP8/(P8*4))) | AU8: =IF(OR(AP8="",S8=""),"",AP8/S8) | AV8: =IF(OR(AP8="",J8=""),"",AP8/J8) | AW8: =IF(OR(AP8="",K8=""),"",AP8/(K8*4)) | AX8: =IF(OR(AP8="",T8=""),"",AP8/T8) -> 15.45 | AY8: Company PR / press; revenue = press estimate | AZ8: EV proxy = $30.9B post-money equity only (debt/cash not disclosed) -> EV understated vs. levered peers. Gross MW (not IT MW); revenue includes data-center development mix.
A9: Lambda | B9: Private | C9: Series E (Nov-2025); press Aug-2026 | D9: 2025-11 / 2026-08 | F9: Not disclosed | I9: Not disclosed (target '3GW' liquid-cooled capacity; ~15 US data centers) | L9: =IF(K9="","",K9*4) | N9: =IF(OR(K9="",H9=""),"",K9*4/H9) | Q9: =IF(OR(O9="",J9=""),"",O9/J9*100) | R9: =IF(OR(P9="",K9=""),"",P9/K9*100) | T9: 1500 | U9: '>$1.5B' 2026 revenue (Bloomberg-reported expectation) - ESTIMATE; $760M ARR end-2025 (Sacra estimate) | W9: Oct-26 $1B IG fixed-rate DDTL (Baa1/A(low); rate n/d); Aug-26 ~$1B broadly syndicated loan; earlier $917M GPU-backed debt | AC9: No balance sheet disclosed | AD9: =IF(X9="","",X9+N(AA9)) | AE9: =IF(Y9="","",Y9+N(AB9)) | AG9: Microsoft (multi-billion, multi-year GB300 deal), NVIDIA (~$1.5B / 18k GPU leaseback) | AI9: Series E 2025-11 | AL9: 5900 | AM9: 5900 | AO9: =IF(AL9="","",AL9+N(X9)-N(Y9)+N(Z9)) -> 5900 | AP9: =IF(AM9="","",AM9+N(AD9)-N(AE9)+N(Z9)) -> 5900 | AQ9: =IF(OR(AP9="",G9=""),"",AP9/G9) | AR9: =IF(OR(AP9="",H9=""),"",AP9/H9) | AS9: =IF(OR(AP9="",O9=""),"",IF(O9<=0,"n/m",AP9/O9)) | AT9: =IF(OR(AP9="",P9=""),"",IF(P9<=0,"n/m",AP9/(P9*4))) | AU9: =IF(OR(AP9="",S9=""),"",AP9/S9) | AV9: =IF(OR(AP9="",J9=""),"",AP9/J9) | AW9: =IF(OR(AP9="",K9=""),"",AP9/(K9*4)) | AX9: =IF(OR(AP9="",T9=""),"",AP9/T9) -> 3.9333333 | AY9: Press / estimates only | AZ9: Equity value = $5.9B Series E post-money (PitchBook cites $5.43B); in talks for up to $3B at $12B+ (Bloomberg, not closed). No MW, EBITDA, or debt totals -> most multiples blank.
A11: Legend: blue-shaded cells are Excel formulas; others are sourced inputs (see Comps_Sources). Multiples use PRO FORMA EV. EV = equity value + debt (ex-leases, carrying) - unrestricted cash + preferred. Private-company 'EV' = last post-money equity value only (no net debt). Prices: Yahoo Finance close 2026-10-02 (close).
A12: Blank = not disclosed / not found (reason in Notes). 'n/m' = negative EBITDA. MW definitions differ (IT vs gross/grid power); see MW basis column.
A14: Revenue per MW block (latest-quarter annualized revenue / active billing MW)
A15: Company | B15: Annualized Q revenue ($M) | C15: Active MW | D15: Revenue per active MW ($M/MW) | E15: Basis / caveat | F15: Source
A16: CoreWeave (period-end MW) | B16: 10300 | C16: 1500 | D16: =B16/C16 -> 6.8666667 | E16: Q2'26 rev x4 / 1.5 GW active at 6/30 (understates: MW ramped ~1.0->1.5 GW in Q2) | F16: https://www.sec.gov/Archives/edgar/data/1769628/000176962826000362/coreweave2q26earningspress.htm
A17: CoreWeave (avg Q2 MW est.) | B17: 10300 | C17: 1250 | D17: =B17/C17 -> 8.24 | E17: ESTIMATE: avg of ~1.0 GW (1.5 GW less 'nearly 500 MW' added) and 1.5 GW | F17: https://www.sec.gov/Archives/edgar/data/1769628/000176962826000362/coreweave2q26earningspress.htm
A18: IREN - AI Cloud only | B18: 282 | C18: 40 | D18: =B18/C18 -> 7.05 | E18: Q4 FY26 AI Cloud rev x4 / ~40 MW operating AI capacity at 6/30 | F18: https://www.sec.gov/Archives/edgar/data/1878848/000187884826000052/iren-20260630.htm
A19: IREN - total | B19: 548.8 | C19: 420 | D19: =B19/C19 -> 1.3066667 | E19: Includes Bitcoin mining (~380 MW); not comparable | F19: https://www.sec.gov/Archives/edgar/data/1878848/000187884826000051/irenreportsfy26results.htm
A20: Nebius (stale MW) | B20: 2329.2 | C20: 170 | D20: =B20/C20 -> 13.701176 | E20: Q2'26 rev x4 / ~170 MW active at YE2025 (latest disclosed) -> OVERSTATES; Q2 active MW not disclosed | F20: https://www.sec.gov/Archives/edgar/data/1513845/000110465926013946/tm266173d1_ex99-2.htm
A21: Crusoe (estimate) | B21: 2000 | C21: 1000 | D21: =B21/C21 -> 2 | E21: ESTIMATE: 2026E $2B (press) / ~1 GW gross operational; gross not IT MW | F21: https://www.globenewswire.com/news-release/2026/09/17/3364326/0/en/crusoe-raises-3-9-billion-series-f-for-its-vertically-integrated-ai-infrastructure-platform.html
A23: Company-disclosed contracted yields (new deals, not realized): Nebius Q2 deals $20-25M ACV per MW (Q2 letter); IREN recent 3-yr contracts >$20M revenue per IT MW (FY26 PR). Test vs ~$12M/MW implied by price (Skeptic).

Sheet EV_Bridge
A1: Company | B1: Basis | C1: Market cap ($M) | D1: + Debt ($M) | E1: - Cash ($M) | F1: + Preferred ($M) | G1: EV ($M) | H1: Shares (M) | I1: Notes | J1: Source
A2: Nebius Group | B2: Aggregator (StockAnalysis, incl. leases) | G2: 68710 | I2: From Skeptic sheet; debt incl. operating/finance leases | J2: https://stockanalysis.com/stocks/nbis/statistics/
A3: Nebius Group | B3: Reported basis (latest BS) | C3: =Comps!AL2 -> 71124.185 | D3: =Comps!X2 -> 8545.7 | E3: =Comps!Y2 -> 8042.1 | F3: =N(Comps!Z2) -> 0 | G3: =Comps!AO2 -> 71627.785 | H3: =Comps!AJ2 -> 292.92115 | I3: Q2 2026 (6-K filed 2026-08-12)
A4: Nebius Group | B4: Pro forma (post-BS events) | C4: =Comps!AM2 -> 74960.303 | D4: =Comps!AD2 -> 14270.7 | E4: =Comps!AE2 -> 14497.1 | F4: =N(Comps!Z2) -> 0 | G4: =Comps!AP2 -> 74733.903 | H4: =Comps!AK2 -> 308.72 | I4: +$775M secured facility (assumed fully drawn; drawn amount not disclosed); +$5,750M Aug converts; -$800M 2029/31 notes exchanged (face; carrying ~= $802M); cash +$775M +~$5,680M est. net convert proceeds (Skeptic sheet basis). Ignores Q3 op. cash flow/capex/ATM
A5: CoreWeave | B5: Aggregator (StockAnalysis, incl. leases) | G5: 95460 | I5: From Skeptic sheet; debt incl. operating/finance leases | J5: https://stockanalysis.com/stocks/crwv/statistics/
A6: CoreWeave | B6: Reported basis (latest BS) | C6: =Comps!AL3 -> 49428.71 | D6: =Comps!X3 -> 35068 | E6: =Comps!Y3 -> 5539 | F6: =N(Comps!Z3) -> 0 | G6: =Comps!AO3 -> 78957.71 | H6: =Comps!AJ3 -> 551.5366 | I6: Q2 2026 (10-Q filed 2026-08-12)
A7: CoreWeave | B7: Pro forma (post-BS events) | C7: =Comps!AM3 -> 49428.71 | D7: =Comps!AD3 -> 39268 | E7: =Comps!AE3 -> 9177.2 | F7: =N(Comps!Z3) -> 0 | G7: =Comps!AP3 -> 79519.51 | H7: =Comps!AK3 -> 551.5366 | I7: +$4,200M Sep-22 2.875% converts (option exercised); cash +$4,137.0M est. net proceeds - $498.8M base capped call (additional capped call cost not disclosed). DDTL 5.5 undrawn: excluded. Shares already at 2026-07-31 count
A8: IREN | B8: Aggregator (StockAnalysis, incl. leases) | I8: Not retrieved (site blocks automated fetch)
A9: IREN | B9: Reported basis (latest BS) | C9: =Comps!AL4 -> 15876.885 | D9: =Comps!X4 -> 7593 | E9: =Comps!Y4 -> 5895.6 | F9: =N(Comps!Z4) -> 0 | G9: =Comps!AO4 -> 17574.285 | H9: =Comps!AJ4 -> 380.19361 | I9: Q4 FY26 / FY ended 2026-06-30 (10-K filed 2026-08-27)
A10: IREN | B10: Pro forma (post-BS events) | C10: =Comps!AM4 -> 16455.889 | D10: =Comps!AD4 -> 7593 | E10: =Comps!AE4 -> 5895.6 | F10: =N(Comps!Z4) -> 0 | G10: =Comps!AP4 -> 18153.289 | H10: =Comps!AK4 -> 394.05865 | I10: Shares 380.19M (6/30) -> 394.06M (8/14), incl. 12.6M for Mirantis acquisition; post-6/30 ATM proceeds not separately disclosed -> no cash adj.; Aug-26 $2.4B financing undrawn -> excluded
A11: Oracle (consolidated) | B11: Aggregator (StockAnalysis, incl. leases) | I11: Not retrieved (site blocks automated fetch)
A12: Oracle (consolidated) | B12: Reported basis (latest BS) | C12: =Comps!AL5 -> 430277.63 | D12: =Comps!X5 -> 125337 | E12: =Comps!Y5 -> 37077 | F12: =N(Comps!Z5) -> 4954 | G12: =Comps!AO5 -> 523491.63 | H12: =Comps!AJ5 -> 3023.736 | I12: Q1 FY27 (10-Q filed 2026-09-11)
A13: Oracle (consolidated) | B13: Pro forma (post-BS events) | C13: =Comps!AM5 -> 430277.63 | D13: =Comps!AD5 -> 125337 | E13: =Comps!AE5 -> 37077 | F13: =N(Comps!Z5) -> 4954 | G13: =Comps!AP5 -> 523491.63 | H13: =Comps!AK5 -> 3023.736 | I13: Share count already 2026-09-07 (post $20B ATM); no material post-BS debt events found
A15: Reconciliation vs Skeptic sheet (/workspace/nebius/skeptic/01_priced_in.xlsx)
A16: Nebius pro forma EV: this file 74734 vs Skeptic $74,730M - same bridge (308.72M sh, debt 14,270.7, cash 14,497.1); difference = rounding.
A17: Nebius $775M facility: 6-K FS note dates agreement 2026-07-10; Skeptic cites 2026-07-17 press release (announcement date). Same facility.
A18: Nebius exchanged notes: Skeptic deducts $800M face; 6/30 carrying of 80% of 2029/2031 series = 0.8x(504.1+498.4) = $802M -> immaterial.
A19: CoreWeave EV: Skeptic uses aggregator $95.46B (debt incl. ~$16.5B leases, pre-Sep converts). This file: pro forma ex-leases 79520. Skeptic's 3.6x FY27 rev / 5.7x FY27 EBITDA multiples are on the lease-inclusive EV; on this file's EV: 3.03x FY27 rev / 4.78x FY27 EBITDA.
A20: Nebius shares: StockAnalysis 274.1M vs company 271.86M (6/30) - aggregator basis undisclosed; this file uses company count + warrants.
A21: Nebius row reconciled vs Filings & Capital fact base (/workspace/nebius/filings/nebius_fact_base.md): revenue, adj. EBITDA, RPO 37,490.6, debt 8,545.7, cash 8,042.1, customers C/D/E 24/21/14%, shares, warrants, MW (>3.5 GW May-26; ~170 MW active YE25) all match. Fact base notes $775M drawn amount not disclosed.
A22: Nebius aggregator EV ($68.71B) uses 6/30 BS incl. leases, excludes warrants/Aug converts/exchange shares -> understated vs pro forma.

Sheet Comps_Sources
A1: company | B1: metric | C1: value | D1: period | E1: source_url | F1: note | G1: tag
A2: Nebius | B2: RPO | C2: 37490.6 | D2: 2026-06-30 | E2: https://www.sec.gov/Archives/edgar/data/1513845/000110465926094844/nbis-20260812xex99d2.htm | F2: Note: Revenue - RPO $37,490.6M; 36% within 24 months | G2: Reported
A3: Nebius | B3: Contracted power (MW) | C3: 3500 | D3: as of 2026-05-13 | E3: https://www.sec.gov/Archives/edgar/data/1513845/000110465926059872/tm2614392d1_ex99-2.htm | F3: 'Contracted capacity already exceeds 3.5 GW'; Q2 letter raises YE26 target to 5 GW (current figure not stated) | G3: Reported (floor)
A4: Nebius | B4: YE26 contracted target / connected guidance | C4: 5,000 MW / 800-1,000 MW | D4: FY2026 guidance | E4: https://www.sec.gov/Archives/edgar/data/1513845/000110465926094568/tm2622968d1_ex99-2.htm | F4: Connected 800MW-1GW reaffirmed on Q2 call: https://www.fool.com/earnings/call-transcripts/2026/08/19/nebius-nbis-q2-2026-earnings-call-transcript/ | G4: Guidance
A5: Nebius | B5: Active power (MW) | C5: 170 | D5: 2025-12-31 | E5: https://www.sec.gov/Archives/edgar/data/1513845/000110465926013946/tm266173d1_ex99-2.htm | F5: '~170 MW of active power' at YE25; no later actual disclosed | G5: Reported (stale)
A6: Nebius | B6: Revenue Q2'26 | C6: 582.3 | D6: Q2 2026 | E6: https://www.sec.gov/Archives/edgar/data/1513845/000110465926094568/tm2622968d1_ex99-1.htm | G6: Reported
A7: Nebius | B7: Revenue H1'26 / H1'25 | C7: 981.3 / 156.0 | D7: H1 | E7: https://www.sec.gov/Archives/edgar/data/1513845/000110465926094568/tm2622968d1_ex99-1.htm | G7: Reported
A8: Nebius | B8: Revenue FY2025 | C8: 529.8 | D8: FY2025 | E8: https://www.sec.gov/Archives/edgar/data/1513845/000110465926052948/nbis-20251231x20f.htm | F8: XBRL Revenues CY2025 (data.sec.gov companyfacts CIK0001513845) | G8: Reported
A9: Nebius | B9: Revenue LTM | C9: 1355.1 | D9: LTM to 2026-06-30 | E9: derived | F9: 981.3 + 529.8 - 156.0 | G9: Derived
A10: Nebius | B10: Revenue YoY Q2 | C10: 454 | D10: Q2 2026 | E10: https://www.sec.gov/Archives/edgar/data/1513845/000110465926094568/tm2622968d1_ex99-1.htm | G10: Reported
A11: Nebius | B11: Adj. EBITDA Q2'26 / H1'26 / H1'25 | C11: 236.2 / 365.7 / -74.7 | E11: https://www.sec.gov/Archives/edgar/data/1513845/000110465926094568/tm2622968d1_ex99-1.htm | G11: Reported
A12: Nebius | B12: Adj. EBITDA FY2025 | C12: -64.9 | D12: FY2025 | E12: https://www.sec.gov/Archives/edgar/data/1513845/000110465926013946/tm266173d1_ex99-2.htm | F12: Q4'25 letter table | G12: Reported
A13: Nebius | B13: Adj. EBITDA LTM | C13: 375.5 | D13: LTM | E13: derived | F13: 365.7 + (-64.9 - -74.7) | G13: Derived
A14: Nebius | B14: NTM adj. EBITDA consensus | C14: 5411.7 | D14: Q4'26-Q3'27 | E14: https://www.marketscreener.com/quote/stock/NEBIUS-GROUP-8037501/finances/ | F14: Sum of quarterly cons 670.7+1277+1581+1883 as captured in Skeptic sheet 2026-10-04 | G14: Estimate (consensus)
A15: Nebius | B15: FY26 revenue guidance | C15: 3,000-3,400 | D15: FY2026 | E15: https://www.tradingkey.com/news/transcripts/262106466-tradingkey | F15: Reaffirmed Q2; adj. EBITDA margin ~40% | G15: Guidance
A16: Nebius | B16: Wtd effective cost of debt (%) | C16: 5.09 | D16: 2026-06-30 | E16: https://www.sec.gov/Archives/edgar/data/1513845/000110465926094844/nbis-20260812xex99d2.htm | F16: Principal-weighted effective rates of 6 convert series (Note 12) | G16: Derived
A17: Nebius | B17: Aug-26 converts 0.50% 2030 / 4.50% 2034 | C17: 3,450 / 2,300 | D17: 2026-08-24 | E17: https://www.sec.gov/Archives/edgar/data/1513845/000110465926100347/tm2623863d1_ex99-1.htm | G17: Reported
A18: Nebius | B18: Secured facility SOFR+2.50% | C18: 775 | D18: 2026-07-10 | E18: https://www.sec.gov/Archives/edgar/data/1513845/000110465926094844/nbis-20260812xex99d2.htm | F18: Subsequent events note | G18: Reported
A19: Nebius | B19: Debt (current + non-current, carrying) | C19: 8545.7 | D19: 2026-06-30 | E19: https://www.sec.gov/Archives/edgar/data/1513845/000110465926094568/tm2622968d1_ex99-1.htm | F19: 46.7 + 8,499.0 | G19: Reported
A20: Nebius | B20: Cash & equivalents | C20: 8042.1 | D20: 2026-06-30 | E20: https://www.sec.gov/Archives/edgar/data/1513845/000110465926094568/tm2622968d1_ex99-1.htm | F20: Excl. restricted cash 1,056.0 | G20: Reported
A21: Nebius | B21: Est. net proceeds Aug converts | C21: 5680 | D21: 2026-08 | E21: https://www.sec.gov/Archives/edgar/data/1513845/000110465926098924/tm2623617d1_ex99-1.htm | F21: Per Skeptic sheet (company estimate incl. option) | G21: Estimate (company)
A22: Nebius | B22: Top customer % revenue | C22: 24 | D22: Q2 2026 | E22: https://www.sec.gov/Archives/edgar/data/1513845/000110465926094844/nbis-20260812xex99d2.htm | F22: Customer C 24%, D 21%, E 14% (unnamed) | G22: Reported
A23: Nebius | B23: Anchors Microsoft/Meta | E23: https://www.sec.gov/Archives/edgar/data/1513845/000110465926059872/tm2614392d1_ex99-2.htm | F23: Q1 letter names Microsoft, Meta strategic contracts; Q2 letter names Reflection, Cohere | G23: Reported
A24: Nebius | B24: Shares outstanding | C24: 271.85522 | D24: 2026-06-30 | E24: https://www.sec.gov/Archives/edgar/data/1513845/000110465926094568/tm2622968d1_ex99-1.htm | G24: Reported
A25: Nebius | B25: NVIDIA pre-funded warrant shares | C25: 21.065936 | D25: 2026-03-11 | E25: https://www.sec.gov/Archives/edgar/data/1513845/000110465926094844/nbis-20260812xex99d2.htm | F25: Note 14; exercise price $0.0001 | G25: Reported
A26: Nebius | B26: Exchange shares | C26: 15.8 | D26: 2026-08-24 | E26: https://www.sec.gov/Archives/edgar/data/1513845/000110465926100347/tm2623863d1_ex99-1.htm | F26: ~15.8M Class A for $800M of 2029/2031 notes | G26: Reported
A27: Nebius | B27: Share price | C27: 242.81 | D27: 2026-10-02 (close) | E27: https://query1.finance.yahoo.com/v8/finance/chart/NBIS?range=10d&interval=1d | F27: Matches Skeptic sheet | G27: Market
A28: Nebius | B28: Aggregator EV | C28: 68710 | D28: 2026-10-04 | E28: https://stockanalysis.com/stocks/nbis/statistics/ | F28: Via Skeptic sheet | G28: Aggregator
A29: CoreWeave | B29: RPO | C29: 103700 | D29: 2026-06-30 | E29: https://data.sec.gov/api/xbrl/companyfacts/CIK0001769628.json | F29: XBRL RevenueRemainingPerformanceObligation; PR 'revenue backlog' ~$104B ($104.2B deck) | G29: Reported
A30: CoreWeave | B30: Contracted / active power (MW) | C30: 3,700 / 1,500 | D30: 2026-06-30 | E30: https://www.sec.gov/Archives/edgar/data/1769628/000176962826000362/coreweave2q26earningspress.htm | F30: 'approximately 3.7 GW' contracted; active 'reach 1.5 GW' | G30: Reported
A31: CoreWeave | B31: Revenue Q2'26 / Q2'25 | C31: 2,575 / 1,212 | D31: Q2 | E31: https://www.sec.gov/Archives/edgar/data/1769628/000176962826000362/coreweave2q26earningspress.htm | G31: Reported
A32: CoreWeave | B32: Revenue FY2025 | C32: 5131 | D32: FY2025 | E32: https://data.sec.gov/api/xbrl/companyfacts/CIK0001769628.json | G32: Reported
A33: CoreWeave | B33: Revenue LTM | C33: 7590 | D33: LTM | E33: derived | F33: 5,131 - 2,194 + 4,653 | G33: Derived
A34: CoreWeave | B34: Adj. EBITDA Q2 / H1'26 / H1'25 | C34: 1,510 / 2,667 / 1,360 | E34: https://www.sec.gov/Archives/edgar/data/1769628/000176962826000362/coreweave2q26earningspress.htm | G34: Reported
A35: CoreWeave | B35: Adj. EBITDA FY2025 | C35: 3093 | D35: FY2025 | E35: https://www.sec.gov/Archives/edgar/data/1769628/000176962826000094/coreweave4q25earningspress.htm | G35: Reported
A36: CoreWeave | B36: Adj. EBITDA LTM | C36: 4400 | D36: LTM | E36: derived | F36: 3,093 - 1,360 + 2,667 | G36: Derived
A37: CoreWeave | B37: NTM adj. EBITDA (calendarized cons) | C37: 14372 | D37: Oct-26-Sep-27 | E37: https://finance.yahoo.com/quote/CRWV/analysis/ | F37: 0.25 x FY26 7,569 + 0.75 x FY27 16,640 (Skeptic sheet; MarketScreener/Yahoo) | G37: Estimate (consensus)
A38: CoreWeave | B38: FY26 revenue guidance | C38: 12,400-13,200 | D38: FY2026 | E38: https://s205.q4cdn.com/133937190/files/doc_financials/2026/q2/CRWV-US-CORRECTED-TRANSCRIPT-CoreWeave-Q2-2026-Earnings-Call-11August2026.pdf | G38: Guidance
A39: CoreWeave | B39: Wtd effective cost of debt (%) | C39: 8.41 | D39: 2026-06-30 | E39: https://www.sec.gov/Archives/edgar/data/1769628/000176962826000366/crwv-20260630.htm | F39: Principal-weighted effective rates, Note 10 debt table | G39: Derived
A40: CoreWeave | B40: Sep-26 2.875% converts 2033 | C40: 4200 | D40: 2026-09-22 | E40: https://www.sec.gov/Archives/edgar/data/1769628/000176962826000432/crwv-20260917.htm | F40: $3.7B + $0.5B option exercised; net proceeds est. $3,644.5M/$4,137.0M; capped call $498.8M (base): https://www.sec.gov/Archives/edgar/data/1769628/000176962826000432/ex991pricing.htm | G40: Reported
...
