Workbook

Sheet Cover
A1: Nebius (NBIS) driver-based model
A2: VERSION v0.8b – DRAFT FOR REVIEW (v0.8 + funding stack: prepay / ABS / uncontracted pricing toggles; backstop at $52.6M owned Rubin)
A3: Build date: 2026-10-04. v0.3 base approved (terminal excludes Q4'30 spend for post-horizon MW and that MW; GPU capex lead 3 qtrs vs billing; history scenario-invariant; bear replacement at bear price path; bull Blackwell 6.25% cut after Rubin + next-gen -1.7%/yr).
A4: v0.7d changes (each a Bridge step): (1) new shares added to Sh_Basic / fully diluted at the headline issue price (Shares tab plan rows; authority check vs ~82M); (2) off-B/S commitments weight 50% -> 0%: the $19.0B energy + lease commitments are the same rent / power already deducted in EBITDA (double count removed; EV unchanged, equity +$9.5B); (3) Vineland T5-T9 billing aligned to Capacity v2 billing-start quarters (no extra 4-qtr ramp / 50% start quarter): FY27 $447M -> $1,159.5M; (4) HEADLINE PT = SELF-CONSISTENT: ATM, equity top-ups and re-funded converts issued at the solved PT itself (fixed point); spot ($242.81) and path issuance kept as MEMO rows that depend on market access at today's price. v0.7c changes kept: shared floor bridge, Rubin $16.2M derived premium, fit-out out of leased Rubin, idle Vineland MW, 3-yr option, run-off residual, re-sized funding, Vineland T1-T4 bear sensitivity.
A5: Key outputs (live, current scenario)
A6: Scenario | B6: =CHOOSE(Scen,"BULL","BASE","BEAR") -> BASE
A7: DCF EV ($M) | B7: =V_EV -> -898.81401
A8: FD value / share ($) | B8: =V_PS -> 0.01
A9: 12-month PT ($) | B9: =V_PT -> 3.970466
A10: First quarter liquidity < 0 | B10: =Liq_NegQ -> none to Q4'30
A11: Market EV ($M) | B11: =V_MKTEV -> 74654.719
A12: NOTE: Headline PT = self-consistent issuance; spot-issuance PT is a memo that assumes continued market access at today's price.
A13: Notes - open items
A14: OPEN: FY26 capex below the $20-25B guide (Aug 12 2026 call): v0.3 $18.1B (~$1.9B short); v0.4 split lead $16.7B (~$3.3B short); possible early 2027 shell/power or deposits not in the path. Check: Checks 'FY26 capex vs company guide'. | B14: Owner: Filings / Capacity
A15: HEADLINE PT is SELF-CONSISTENT (PTBasis 1): every new share is issued at the solved PT. Base $4.00 / gross $12.70 / bull $401 / bear $0 (no positive fixed point - existing equity under water at any issue price). MEMO (depends on market access at today's price): spot $242.81 issuance base $88.9 / bull $364 / bear $33.9; path to PT over 8 qtrs base $30.3 / bull $390 / bear $0. Shares needed vs ~82M authority: base ~11.0B issued + 2.3B convert reserve; bull ~87M + 22M; bear unbounded -> EGM / not financeable on these terms. | B15: Owner: Capacity
A16: v0.7d: off-B/S commitments weight 0% (rent / power already in EBITDA; in-horizon rent + power $11.7B, FY30 run-rate $3.9B/yr vs $19.0B commitments; not in capex). MSFT T5-T9 billing at Capacity v2 start quarters (T5-T6 Q2'27, T7-T9 Q3'27, full run-rate): FY27 T5-T9 $1,159.5M (was $447M with extra 4-qtr ramp + 50% start quarter). Billing lag 1 qtr unchanged. | B16: Owner: GPU Market
A17: OPEN: AIB CLT1 prepayment (undisclosed; default $0) and Inferize price (press $100-150M, toggle off). | B17: Owner: Filings
A18: OPEN: Vineland shutdown default OFF (VinShutSel 0); scenarios/weights are Capacity judgment (prob-weighted Q4'26 loss ~$68M at $14.5M/IT MW-yr vs Capacity ~$67M); SLA credits undisclosed; genset power saving not credited. | B18: Owner: Capacity
A19: OPEN: Capacity proposed MW path is a scenario only (MWSel 4) until Capacity's Tuesday file; new-deal $/MW basis (IT vs gross) medium-low confidence; short-term share 10% is an estimate. | B19: Owner: Capacity / Filings
A20: OPEN: ARR scope / whether $3.0B ARR includes signed-not-billing tranches; unexplained ARR residual ~$0.6B shown as a line, not plugged. | B20: Owner: Filings
A21: OPEN: YE27 ~950 MW IT normalization is a placeholder pending Capacity's basis column. | B21: Owner: Capacity
A22: OPEN: Q3'26 transfer into service (model $4,702M) pending Q3 filing; depreciation start dates (material weakness) flagged. | B22: Owner: Filings
A23: FLAGS: DCF EV (-$0.9B) below asset floor EV ($5.6B pre-tax; ~$1.3B after tax): floor is pre-tax and excludes uncontracted reinvestment; DCF most sensitive to Rubin $/MW, GPU life and tax. Bull EV >> 3x base; bear EV < 0; FY26 capex $17.6B below guide; issuance far above authority in base/bear. See Checks. | B23: Owner: Modeling / GPU Market
A24: v0.8 results (static; solved values; live toggles StopBuild / BackstopMW / StopCommitWt on Inputs)
A25: v0.8 STOP BUILDING (StopBuild=1; Estimated): only signed capacity is built after Q1'27 billing (= sites energized by YE26), plus Meta backstop MW if on. ATM plan and 2027 plan converts are off; equity top-ups only to the $1.0B buffer, at the self-consistent PT. Base: EV $9.8B (build plan -$0.9B), self-consistent PT $13.9, spot memo $19.2, ~138M new shares (convert refunding at PT) vs ~82M authority, YE27 liquidity $3.3B. This includes $3.7B of signed lease + energy commitments for the cut MW (50% x pro-rata share). At 0% it is $27.3 and at 100% $0.5. Bull $125.4 / bear $0 (EV -$2.6B) / gross $15.6. Asset floor $24.3/sh (self-consistent) sits between the 50% and 0% commitment cases. | B25: Owner: Modeling
A26: v0.8 BREAKEVEN NEW-DEAL PRICE ($M per IT MW-yr). Unit NPV = 0, after tax and corporate costs (Payback_Floor G): leased GB300 17.9 / 18.4 / 18.9 at 9 / 10 / 11% WACC; owned Rubin ($52.6M) 18.2 / 18.9 / 19.6. Full model (GB300 and Rubin prices scaled together, Rubin = 1.0125x GB300): build EV = stop EV at GB300 $16.2 / $16.9 / $17.6M; build PT = stop PT at $15.7 / $16.3 / $16.9M. Today: $16.0M GB300 / $16.2M Rubin. Solved by bisection, 2026-10-05. | B26: Owner: Modeling
A27: v0.8 WHAT HAS TO BE TRUE for a self-consistent PT of $242.81 (GB300 / Rubin $M per IT MW-yr): (A) price only, $24.4 / $24.7; (B) WACC 9% + GPU life 6 yrs, $18.9 / $19.2; (C) B + bull Rubin capex ($45.8M owned / $33.3M leased), $17.5 / $17.8; (D) WACC 10% + life 6 + bull Rubin capex, $19.4 / $19.7; (E) WACC 9% only, $20.5 / $20.7. Even at $242.81, authority need is ~170-210M shares vs ~82M. | B27: Owner: Modeling
A28: v0.8 META BACKSTOP toggle (BackstopMW 0/150/190; FY25 20-F p.75 terms Reported, MW mapping Derived / low): placed on the owned Rubin halls, billing from Q3'27, $16M ($14.5M bear) placeholder. It counts as contracted, is off-RPO and is EXCLUDED from the asset floor. Build plan base PT $4.0 -> $6.6 / $6.9 (150 / 190 MW). Stop-building $13.9 -> $21.9 / $24.1. v0.8b builds stop-case backstop MW at $52.6M owned Rubin (v0.8 had $26.2 / $29.6 at the ~$40M path rate). In the build plan the halls are already in the Capacity path at their own site rates. At $16M the backstop is below the $19.6M owned-Rubin breakeven, so stop EV falls ($9.8B -> $9.0B); PT rises because the cut-MW commitments shrink. In bear, 190 MW exceeds the YE27 uncontracted fleet by ~34 MW. | B28: Owner: Filings / Capacity
A29: v0.8 FUNDING RECONCILIATION (Funding tab): Capacity ~$17.5B uncontracted capex vs model capex Q3'26-Q4'27 $43.3B = uncontracted new-build $32.0B (capex spent ahead of go-live for 2028 MW + model path vs CSV) + contracted-MW $10.3B + maintenance / lease prepay $1.1B. Equity need Q3'26-Q4'30 $41.7B = capex $111.0B - EBITDA $61.7B + tax / interest $1.8B - net new prepayments $3.7B + convert maturities $8.0B + liquidity build $4.6B - converts $18.4B. Uncontracted split per Capacity uncontracted_split.csv: model YE27 non-contract MW 418 vs CSV ~430-480 incl. 96 MW existing self-serve; stop cut 271 MW at YE27 vs CSV 2027 go-lives 255 MW. | B29: Owner: Capacity / Modeling
A30: v0.8b FUNDING STACK (Funding_Stack tab; self-consistent PT, 11% WACC unless stated). BUILD: base $4.0 -> +prepay 55% $13.5 -> +ABS 50% $13.9 -> +uncontracted $20M $108.4 -> $22.5M $171.0 -> +backstop 190 $159.3 (backstop at $16M replaces $22.5M MW). All layers: (b) blended WACC 10.7% (ABS 5.4% of capex) $173.2; (c) 9% $266.0 = UPPER BOUND, double counts cheap debt; (d) Skeptic full stack (prepay 55%, ABS 50%, Rubin $20M, 9%) at uncontracted $20M $207.7 / $22.5M $283.6. | B30: Owner: Modeling
A31: v0.8b STOP BUILDING with the same layers: base $13.9; prepay and uncontracted-price layers do nothing (no new deals); ABS 50% $11.2 (idle cash pays interest); +backstop 190 $15.7; (b) blended 8.8% $24.3; (c) 9% $23.5; (d) $16.7. Shares needed: build all-layers 102-133M, (c) / (d22.5) ~85M vs ~82M authority; stop 79-172M. | B31: Owner: Modeling
A32: v0.8b CAVEATS: with self-consistent issuance, financing mix moves PT only through cost and timing (prepayments valued as interest-free customer funding, no price concession); cheap debt shows up only through WACC. The uncontracted premium on 2028-30 vintages persists into the terminal value (renewal after Q4'30 not modelled). Legacy 147 MW GPU-hour fleet not repriced. ABS only on new contracted-MW capex; it displaces 2027 plan converts first. Convert coupons funded by top-ups are not charged in the self-consistent equity value (pre-existing; ABS interest is charged). | B32: Owner: Modeling

Sheet README
A1: Nebius (NBIS) driver model - README
A3: Save path: /workspace/nebius/model/nebius_model.xlsx. Quarterly Q1'24-Q2'26 actuals (Hist, tagged Reported/Derived/Estimated/Not disclosed + best estimate + source), Q3'26-Q4'30 forecast, FY roll-ups AI:AO.
A4: Scenario: Inputs!D4 (1 Bull / 2 Base / 3 Bear). Blue = input; orange = placeholder; yellow = estimated/consensus; black = formula.
A5: Flow: Inputs -> Sites (contracted / energized [Capacity file] / mgmt-connected; MWSel; BillLag; PUE basis) -> Pricing -> Contracts (tranches, power ceiling, Q4 bridge) -> Revenue (3 books) -> Capex_DA (vintage cohorts, PISLag, impairment, cap. interest, dep-yield) -> Financing -> PnL -> CashFlow -> Shares -> Valuation (DCF, dilution solve, EV bridge, EV/MW) -> KPIs / Outputs / Sensitivity / Checks.
A6: Circularity: no Excel iterative calc needed. Valuation solves value/share by 15 unrolled fixed-point steps; DilPxMode 1 = SharePx for quarterly dilution.
A7: Converts: DilMethod 1 if-converted all / 2 ITM only (default; step dilution at conversion prices) / 3 net-share. Converted principal is removed from debt (Checks row 1).
A8: Static snapshot tables on Outputs / Sensitivity / Valuation memo rows / Checks (bull 3x, scenario-invariance) come from LibreOffice recalcs in snap.py; re-run snap.py after changing inputs.

Sheet Bridge
A1: EV bridge v0.1 -> v0.3 -> v0.4 (STATIC, filled by snap.py)
A2: Base scenario. Each row = cumulative settings recomputed in the CURRENT model (bug fixes such as the renewal-formula bracket and scenario-invariant history are in every row). $B and $/share are FD value/share.
A4: Step | B4: DCF EV $B | C4: Change $B | D4: FD $/share | E4: Change $/sh | F4: 12m PT $ | G4: FY26 rev $M | H4: FY27 rev $M | I4: FY28 rev $M | J4: FY27 EBITDA $M | K4: YE27 liquidity $M | L4: First neg. qtr
A5: v0.1 (as reported) | B5: 41.053548 | D5: 103.5364 | F5: 116.99613 | G5: 2400.637 | H5: 8242.0189 | I5: 22266.612 | J5: 4575.8582 | K5: -4456.7617 | L5: Q4'27
A6: + fleet ratio forecast-only / capex on driver MW (FixMgmt) | B6: 46.917572 | C6: 5.8640242 | D6: 121.61057 | E6: 18.074176 | F6: 137.41995 | G6: 2400.637 | H6: 8242.0189 | I6: 22266.612 | J6: 4606.0461 | K6: -4408.0848 | L6: Q4'27
A7: + terminal on Q4'30 exit incl. Q1'31 MW (include both) | B7: 100.18581 | C7: 53.268235 | D7: 270.29726 | E7: 148.68669 | F7: 305.43591 | G7: 2400.637 | H7: 8242.0189 | I7: 22266.612 | J7: 4606.0461 | K7: -4408.0848 | L7: Q4'27
A8: + TV run-off floor | B8: 100.18581 | C8: 0 | D8: 270.29726 | E8: 0 | F8: 305.43591 | G8: 2400.637 | H8: 8242.0189 | I8: 22266.612 | J8: 4606.0461 | K8: -4408.0848 | L8: Q4'27
A9: + owned-site O&M | B9: 89.065186 | C9: -11.12062 | D9: 240.34647 | E9: -29.950795 | F9: 271.59151 | G9: 2400.637 | H9: 8242.0189 | I9: 22266.612 | J9: 4517.4726 | K9: -4518.475 | L9: Q4'27
A10: + H2'26 repricing (= v0.2) | B10: 99.881943 | C10: 10.816757 | D10: 269.45258 | E10: 29.106113 | F10: 304.48142 | G10: 2425.3295 | H10: 8517.5153 | I10: 22648.736 | J10: 4713.075 | K10: -4310.0666 | L10: Q4'27
A11: + exclude both Q4'30 spend & Q1'31 MW | B11: 86.363741 | C11: -13.518202 | D11: 233.0828 | E11: -36.369776 | F11: 263.38357 | G11: 2425.3295 | H11: 8517.5153 | I11: 22648.736 | J11: 4713.075 | K11: -4310.0666 | L11: Q4'27
A12: + GPU capex lead 3 qtrs (= v0.3) | B12: 94.115788 | C12: 7.7520471 | D12: 248.1935 | E12: 15.110692 | F12: 280.45865 | G12: 2425.3295 | H12: 8517.5153 | I12: 22648.736 | J12: 4713.075 | K12: -7264.9716 | L12: Q2'27
A13: + split capex lead: shell/power 3, GPUs 2 qtrs | B13: 87.921392 | C13: -6.1943968 | D13: 233.70836 | E13: -14.48514 | F13: 264.09044 | G13: 2425.3295 | H13: 8517.5153 | I13: 22648.736 | J13: 4713.075 | K13: -7160.9335 | L13: Q3'27
A14: + price path: post-Rubin cut 22% + -6%/yr from year 2 | B14: 94.973087 | C14: 7.0516956 | D14: 252.68045 | E14: 18.972094 | F14: 285.52891 | G14: 2425.3295 | H14: 8102.5841 | I14: 22384.539 | J14: 4418.4739 | K14: -7450.3255 | L14: Q3'27
A15: + Rubin premium at per-MW parity (1.56x GB300) | B15: 153.79048 | C15: 58.817396 | D15: 406.65016 | E15: 153.96971 | F15: 459.51468 | G15: 2425.3295 | H15: 8140.6586 | I15: 24633.629 | J15: 4445.5068 | K15: -7423.7798 | L15: Q3'27
A16: + CLT1 rent $2.2M/IT MW-yr | B16: 154.02609 | C16: 0.23561158 | D16: 407.25464 | E16: 0.60447567 | F16: 460.19774 | G16: 2425.3295 | H16: 8140.6586 | I16: 24633.629 | J16: 4447.4208 | K16: -7421.8657 | L16: Q3'27
A17: + terminal g from fundamentals | B17: 125.81957 | C17: -28.206529 | D17: 334.88909 | E17: -72.365546 | F17: 378.42467 | G17: 2425.3295 | H17: 8140.6586 | I17: 24633.629 | J17: 4447.4208 | K17: -7421.8657 | L17: Q3'27
... A61: v0.8b: funding-stack toggles (prepay / ABS / uncontracted price) added OFF; backstop built at $52.6M owned Rubin when stop-building (no base change) (= v0.8b) | B61: -0.89881401 | C61: 0 | D61: 0.01 | E61: 0 | F61: 3.970466 | G61: 2465.0795 | H61: 8209.2404 | I61: 19716.797 | J61: 4213.144 | K61: 1000 | L61: none to Q4'30
A64: Horizon per-share values (FD value/share rolled at Ke; excludes future funding dilution - see Funding tab)
A65: Scenario | B65: Today | C65: 6-month | D65: 12-month PT | E65: 3-year
A66: Base (live) | B66: 0.01 | C66: 3.7351002 | D66: 3.970466 | E66: 5.0698881
A67: Bull | B67: 355.02686 | C67: 378.92296 | D67: 401.01436 | E67: 503.03242
A68: Bear | B68: 0.01 | C68: 0 | D68: 0 | E68: 0
A71: New-MW pricing vs IREN >$20M/IT MW-yr ($M per IT MW-yr). GB300 GPU-hour engine (legacy fleet) at Oct-1 list x RealRes x Util_Res; new 2027+ MW at new-deal blend (col G)
A72: Scenario | B72: GB300 gross | C72: net leased (-$2.2M rent) | D72: net owned (-O&M) | E72: Rubin gross | F72: IREN gross / leased / owned | G72: New-deal blend gross
A73: Base (live) | B73: 27.424348 | C73: 25.224348 | D73: 26.674348 | E73: 27.267343 | F73: 20.0 / 17.8 / 19.25 | G73: 16.69175
A74: Bull | B74: 43.041696 | C74: 40.841696 | D74: 42.291696 | E74: 46.963273 | F74: 20.0 / 17.8 / 19.25 | G74: 19.092188
A75: Bear | B75: 22.272793 | C75: 20.072793 | D75: 21.522793 | E75: 21.871882 | F75: 20.0 / 17.8 / 19.25 | G75: 14.736556
A78: v0.5 BASE RANGE: 12m PT ($/share) by short-term share (of TOTAL active MW) x new-deal $/MW basis, with / without prepayment decay (STATIC). Green = base; yellow = supported tests; orange = gross-MW basis (alternative reading of slide); red = equity floored at 0
A79: Prepayment decay ON (base) | B79: ST share 0% (floor) | C79: ST share 2% | D79: ST share 5% | E79: ST share 10%
A80: IT basis $22M/IT MW | B80: 0 | C80: 0 | D80: 3.970466 | E80: 25.700617
A81: Gross-MW basis = $26.4M/IT MW | B81: 0 | C81: 5.0002958 | D81: 12.730892 | E81: 42.044423
A82: EV $B / YE27 liq $B / 1st neg - IT | B82: -5.5 / 1.0 / none to Q4'30 | C82: -3.6 / 1.0 / none to Q4'30 | D82: -0.9 / 1.0 / none to Q4'30 | E82: 5.4 / 1.0 / none to Q4'30
A83: EV $B / YE27 liq $B / 1st neg - gross | B83: -2.1 / 1.0 / none to Q4'30 | C83: -0.5 / 1.0 / none to Q4'30 | D83: 1.7 / 1.0 / none to Q4'30 | E83: 10.1 / 1.0 / none to Q4'30
A85: Prepayment decay OFF (other deals 38.5% flat) | B85: ST share 0% (floor) | C85: ST share 2% | D85: ST share 5% | E85: ST share 10%
A86: IT basis $22M/IT MW | B86: 0 | C86: 0 | D86: 4.6286253 | E86: 26.363339
A87: Gross-MW basis = $26.4M/IT MW | B87: 0.46693069 | C87: 5.6603151 | D87: 13.390912 | E87: 42.707144
A88: EV $B / YE27 liq $B / 1st neg - IT | B88: -4.7 / 1.0 / none to Q4'30 | C88: -2.8 / 1.0 / none to Q4'30 | D88: -0.1 / 1.0 / none to Q4'30 | E88: 6.2 / 1.0 / none to Q4'30
A89: EV $B / YE27 liq $B / 1st neg - gross | B89: -1.2 / 1.0 / none to Q4'30 | C89: 0.3 / 1.0 / none to Q4'30 | D89: 2.6 / 1.0 / none to Q4'30 | E89: 10.9 / 1.0 / none to Q4'30

Sheet Payback_Floor
A1: Payback check, new-deal price cases, EBITDA per IT MW by generation, and asset floor (live formulas). Inputs blue.
A3: Leased GB300 capex per IT MW ($M; GPU + network + storage, no shell) = CPM_Lease_GB300 (rack-based) | B3: =CPM_Lease_GB300 -> 36.7875 | C3: v0.7b: 6.8 racks x GB_RackPx + $6.1M network (v0.7 41.3) | E3: Owned opex per IT MW-yr (power + ops, NO rent) = OwnOpex | F3: =IF(OwnOpexOn=1,OwnOpex,LoadFactor*PUE*8760*PowerPx/1000000+OM_MW) -> 2.25
A4: Leased Vera Rubin capex per IT MW ($M) - live scenario = CPM_Lease_VR | B4: =CPM_Lease_VR -> 40.1 | C4: Capacity v2 ex $1M colo fit-out (v0.7c): $33.3 / 40.1 / 48.2M bull/base/bear (racks $6.7/7.8/9.1M; network $5.3M) | E4: Owned data hall + power/cooling $M/IT MW (in owned capex; not replaced on GPU cycle) = CPM_SP | F4: =CPM_SP -> 12.5
A5: Owned GB300 capex per IT MW ($M, incl. data hall) = CPM_Own_GB300 | B5: =CPM_Own_GB300 -> 49.2875 | C5: v0.7b: rack-based + $12.5M hall (v0.7 53) | E5: Data hall economic life (yrs; residual only) = HallLife | F5: =HallLife -> 18
A6: Owned Vera Rubin capex per IT MW ($M) = CPM_Own_VR | B6: =CPM_Own_VR -> 52.6 | C6: Capacity v2 base $52.6M (v0.7 56) | E6: GPU/server residual at refresh (% of servers+network) = GPU_Resid | F6: =GPU_Resid -> 0.15
A7: Opex per IT MW-yr (rent $2.0-2.5M + power + ops), fixed across generations | B7: 4.5 | C7: Range $4-5M; does NOT fall at the Rubin switch | E7: WACC (NPV discount rate) | F7: =WACC -> 0.11
A8: Management payback target (months) | B8: 22 | C8: Q2'26 letter: 1 year 10 months, prepayments excluded (footnote basis) | E8: Corporate opex % revenue FY29 (other COR + PD + SG&A ex-SBC; for after-tax NPV incl. overhead) | F8: =OtherCOR+INDEX(PDpct,1,2029-FYBase)+INDEX(SGApct,1,2029-FYBase) -> 0.21
A9: Asset life for unlevered IRR (yrs; capex at t0, flat EBITDA, residual at end: GPUs GPU_Resid, owned data hall at HallLife) | B9: 5 | C9: GPU life 5 yrs (model base)
A10: A) New-deal price cases - $/IT MW-yr next to implied $/GPU-hr. GB300: one linked input (ND_Px x 491 x 8,760 x ND_Occ), IT vs gross toggle. RUBIN: direct $/IT MW-yr (no IT/gross toggle)
A11: Case | B11: IT reading $M/IT MW | C11: IT $/GPU-hr | D11: Gross reading $M/IT MW | E11: Gross $/GPU-hr | F11: $/GPU-hr at 400/MW (ref only)
A12: GB300 NVL72 (491 GPUs/IT MW) | B12: =MYRate -> 16 | C12: =ND_Px -> 3.7199267 | D12: =MYRate*ND_GrossX -> 19.207824 | E12: =ND_Px*ND_GrossX -> 4.4657311
A13: Vera Rubin $14.5M/IT MW [bear] | B13: =14.5 -> 14.5 | C13: =14.5*1000000/(GPUMW_N*8760) -> 5.1726598 | D13: same (no toggle) | F13: =14.5*1000000/(RubinGPUMW_D*8760) -> 4.1381279
A14: Vera Rubin $16.2M/IT MW [base] | B14: =16.2 -> 16.2 | C14: =16.2*1000000/(GPUMW_N*8760) -> 5.7791096 | D14: same (no toggle) | F14: =16.2*1000000/(RubinGPUMW_D*8760) -> 4.6232877
A15: Vera Rubin $20M/IT MW [bull] | B15: =20 -> 20 | C15: =20*1000000/(GPUMW_N*8760) -> 7.1347032 | D15: same (no toggle) | F15: =20*1000000/(RubinGPUMW_D*8760) -> 5.7077626
A16: Vera Rubin at live RubinMW | B16: =RubinMW -> 16.2 | C16: =RubinMW*1000000/(GPUMW_N*8760) -> 5.7791096 | D16: same (no toggle) | F16: =RubinMW*1000000/(RubinGPUMW_D*8760) -> 4.6232877
A17: Benchmarks: IREN new 3-yr GB300 ~$4.65/GPU-hr (>$20M/IT MW); Rubin: Anthropic-Nscale ~$16.2M/MW (6-yr, MW basis unknown); WhiteFiber-Prime Intellect 576 VR200 ~$108.2M/3 yrs = ~$7.15/GPU-hr (~$20M/IT MW if packages counted, medium). GB300 basis not disclosed by management.
A19: B) EBITDA per IT MW-yr by generation (opex fixed across generations; Rubin = RubinMW, no toggle)
B20: GB300 IT | C20: Rubin (RubinMW) | D20: Change | E20: GB300 gross | F20: Rubin (RubinMW) | G20: Change
A21: Revenue per IT MW-yr | B21: =B12 -> 16 | C21: =RubinMW -> 16.2 | D21: =C21/B21-1 -> 0.0125 | E21: =D12 -> 19.207824 | F21: =RubinMW -> 16.2 | G21: =F21/E21-1 -> -0.15659369
A22: Opex per IT MW-yr (PB_Opex) | B22: =PB_Opex -> 4.5 | C22: =PB_Opex -> 4.5 | E22: =PB_Opex -> 4.5 | F22: =PB_Opex -> 4.5
A23: EBITDA per IT MW-yr | B23: =B21-B22 -> 11.5 | C23: =C21-C22 -> 11.7 | D23: =C23/B23-1 -> 0.017391304 | E23: =E21-E22 -> 14.707824 | F23: =F21-F22 -> 11.7 | G23: =F23/E23-1 -> -0.20450503
A24: Memo: model's own opex/IT MW-yr - B: LEASED = RentMW x PUE + power (LoadFactor x PUE x 8,760 x PowerPx); C: OWNED = power + O&M, no rent (PB_OpexOwn) | B24: =RentMW*PUE+LoadFactor*PUE*8760*PowerPx/1000000 -> 3.4695 | C24: =PB_OpexOwn -> 2.25
A26: C) PAYBACK (months) = capex / (revenue - opex) x 12; prepayments EXCLUDED unless stated. Flag = within +/-3 months of 22. IRR = unlevered pre-tax, capex at t0, flat EBITDA over PB_Life, residual at end (col L). NPV per IT MW at WACC: N pre-tax; O after tax (site level, book D&A shield); P after tax incl. corporate opex PB_Corp
A27: Case | B27: IT / Rubin payback | C27: flag | D27: Gross (MYRate x ND_GrossX) payback | E27: flag | F27: capex $M/IT MW | G27: opex | H27: revenue IT $M | I27: EBITDA/IT MW (IT) | J27: IRR (IT, with residual) | K27: IRR (gross, with residual) | L27: residual at yr PB_Life $M/MW | M27: IRR (IT) no residual [v0.7 basis] | N27: NPV/MW pre-tax @WACC | O27: NPV/MW after tax (site) | P27: NPV/MW after tax incl. corporate opex | Q27: of which data hall $M/MW
A28: Leased GB300 (capex incl. $1.6M lease prepayment) | B28: =IFERROR(F28*1/(H28-G28)*12,999) -> 40.056522 | C28: =IF(ISNUMBER(B28),IF(ABS(B28-PB_Target)<=3,"WITHIN +/-3","outside"),"") -> outside | D28: =IFERROR(F28*1/(MYRate*ND_GrossX-G28)*12,999) -> 31.320065 | E28: =IF(ISNUMBER(D28),IF(ABS(D28-PB_Target)<=3,"WITHIN +/-3","outside"),"") -> outside | F28: =PB_CapGB+LeasePrepayOn*LeasePrepay -> 38.3875 | G28: =PB_Opex -> 4.5 | H28: =MYRate -> 16 | I28: =H28-G28 -> 11.5 | J28: =IFERROR(RATE(PB_Life,I28,-F28*1,L28),-1) -> 0.18099946 | K28: =IFERROR(RATE(PB_Life,MYRate*ND_GrossX-G28,-F28*1,L28),-1) -> 0.28669829 | L28: =PB_Resid*(F28-Q28)+Q28*MAX(0,1-PB_Life/PB_HallLife) -> 5.758125 | M28: =IFERROR(RATE(PB_Life,I28,-F28*1),-1) -> 0.15178413 | N28: =-F28*1+I28*(1-(1+PB_WACC)^-PB_Life)/PB_WACC+L28*(1+PB_WACC)^-PB_Life -> 7.5324826 | O28: =-F28*1+(I28-TaxRate*MAX(0,I28-((F28-Q28)/PB_Life+Q28*(ShellMW/(ShellMW+PowerMW)/Life_Shell+PowerMW/(ShellMW+PowerMW)/Life_Pow))))*(1-(1+PB_WACC)^-PB_Life)/PB_WACC+(PB_Resid*(F28-Q28)*(1-TaxRate)+Q28*MAX(0,1-PB_Life/PB_HallLife)-TaxRate*(Q28*MAX(0,1-PB_Life/PB_HallLife)-Q28*MAX(0,1-PB_Life*(ShellMW/(ShellMW+PowerMW)/Life_Shell+PowerMW/(ShellMW+PowerMW)/Life_Pow))))*(1+PB_WACC)^-PB_Life -> 3.0059414 | P28: =-F28*1+((I28-PB_Corp*H28)-TaxRate*MAX(0,I28-PB_Corp*H28-((F28-Q28)/PB_Life+Q28*(ShellMW/(ShellMW+PowerMW)/Life_Shell+PowerMW/(ShellMW+PowerMW)/Life_Pow))))*(1-(1+PB_WACC)^-PB_Life)/PB_WACC+(PB_Resid*(F28-Q28)*(1-TaxRate)+Q28*MAX(0,1-PB_Life/PB_HallLife)-TaxRate*(Q28*MAX(0,1-PB_Life/PB_HallLife)-Q28*MAX(0,1-PB_Life*(ShellMW/(ShellMW+PowerMW)/Life_Shell+PowerMW/(ShellMW+PowerMW)/Life_Pow))))*(1+PB_WACC)^-PB_Life -> -6.2083733 | Q28: =0 -> 0
A29: Leased Vera Rubin BASE: $16.2M rev / $40.1M capex ex fit-out (+ lease prepayment) | B29: =IFERROR(F29*1/(H29-G29)*12,999) -> 42.769231 | C29: =IF(ISNUMBER(B29),IF(ABS(B29-PB_Target)<=3,"WITHIN +/-3","outside"),"") -> outside | D29: n/a (no toggle) | E29: =IF(ISNUMBER(D29),IF(ABS(D29-PB_Target)<=3,"WITHIN +/-3","outside"),"") | F29: =40.1+LeasePrepayOn*LeasePrepay -> 41.7 | G29: =PB_Opex -> 4.5 | H29: =16.2 -> 16.2 | I29: =H29-G29 -> 11.7 | J29: =IFERROR(RATE(PB_Life,I29,-F29*1,L29),-1) -> 0.15599431 | L29: =PB_Resid*(F29-Q29)+Q29*MAX(0,1-PB_Life/PB_HallLife) -> 6.255 | M29: =IFERROR(RATE(PB_Life,I29,-F29*1),-1) -> 0.12459659 | N29: =-F29*1+I29*(1-(1+PB_WACC)^-PB_Life)/PB_WACC+L29*(1+PB_WACC)^-PB_Life -> 5.2540332 | O29: =-F29*1+(I29-TaxRate*MAX(0,I29-((F29-Q29)/PB_Life+Q29*(ShellMW/(ShellMW+PowerMW)/Life_Shell+PowerMW/(ShellMW+PowerMW)/Life_Pow))))*(1-(1+PB_WACC)^-PB_Life)/PB_WACC+(PB_Resid*(F29-Q29)*(1-TaxRate)+Q29*MAX(0,1-PB_Life/PB_HallLife)-TaxRate*(Q29*MAX(0,1-PB_Life/PB_HallLife)-Q29*MAX(0,1-PB_Life*(ShellMW/(ShellMW+PowerMW)/Life_Shell+PowerMW/(ShellMW+PowerMW)/Life_Pow))))*(1+PB_WACC)^-PB_Life -> 1.0924281 | P29: =-F29*1+((I29-PB_Corp*H29)-TaxRate*MAX(0,I29-PB_Corp*H29-((F29-Q29)/PB_Life+Q29*(ShellMW/(ShellMW+PowerMW)/Life_Shell+PowerMW/(ShellMW+PowerMW)/Life_Pow))))*(1-(1+PB_WACC)^-PB_Life)/PB_WACC+(PB_Resid*(F29-Q29)*(1-TaxRate)+Q29*MAX(0,1-PB_Life/PB_HallLife)-TaxRate*(Q29*MAX(0,1-PB_Life/PB_HallLife)-Q29*MAX(0,1-PB_Life*(ShellMW/(ShellMW+PowerMW)/Life_Shell+PowerMW/(ShellMW+PowerMW)/Life_Pow))))*(1+PB_WACC)^-PB_Life -> -8.2771143 | Q29: =0 -> 0
A30: Leased Vera Rubin BULL: $20M / $33.3M (+ lease prepayment) | B30: =IFERROR(F30*1/(H30-G30)*12,999) -> 27.019355 | C30: =IF(ISNUMBER(B30),IF(ABS(B30-PB_Target)<=3,"WITHIN +/-3","outside"),"") -> outside | D30: n/a (no toggle) | E30: =IF(ISNUMBER(D30),IF(ABS(D30-PB_Target)<=3,"WITHIN +/-3","outside"),"") | F30: =33.3+LeasePrepayOn*LeasePrepay -> 34.9 | G30: =PB_Opex -> 4.5 | H30: =20 -> 20 | I30: =H30-G30 -> 15.5 | J30: =IFERROR(RATE(PB_Life,I30,-F30*1,L30),-1) -> 0.36041626 | L30: =PB_Resid*(F30-Q30)+Q30*MAX(0,1-PB_Life/PB_HallLife) -> 5.235 | M30: =IFERROR(RATE(PB_Life,I30,-F30*1),-1) -> 0.34214898 | N30: =-F30*1+I30*(1-(1+PB_WACC)^-PB_Life)/PB_WACC+L30*(1+PB_WACC)^-PB_Life -> 25.493121 | O30: =-F30*1+(I30-TaxRate*MAX(0,I30-((F30-Q30)/PB_Life+Q30*(ShellMW/(ShellMW+PowerMW)/Life_Shell+PowerMW/(ShellMW+PowerMW)/Life_Pow))))*(1-(1+PB_WACC)^-PB_Life)/PB_WACC+(PB_Resid*(F30-Q30)*(1-TaxRate)+Q30*MAX(0,1-PB_Life/PB_HallLife)-TaxRate*(Q30*MAX(0,1-PB_Life/PB_HallLife)-Q30*MAX(0,1-PB_Life*(ShellMW/(ShellMW+PowerMW)/Life_Shell+PowerMW/(ShellMW+PowerMW)/Life_Pow))))*(1+PB_WACC)^-PB_Life -> 16.567415 | P30: =-F30*1+((I30-PB_Corp*H30)-TaxRate*MAX(0,I30-PB_Corp*H30-((F30-Q30)/PB_Life+Q30*(ShellMW/(ShellMW+PowerMW)/Life_Shell+PowerMW/(ShellMW+PowerMW)/Life_Pow))))*(1-(1+PB_WACC)^-PB_Life)/PB_WACC+(PB_Resid*(F30-Q30)*(1-TaxRate)+Q30*MAX(0,1-PB_Life/PB_HallLife)-TaxRate*(Q30*MAX(0,1-PB_Life/PB_HallLife)-Q30*MAX(0,1-PB_Life*(ShellMW/(ShellMW+PowerMW)/Life_Shell+PowerMW/(ShellMW+PowerMW)/Life_Pow))))*(1+PB_WACC)^-PB_Life -> 5.0495219 | Q30: =0 -> 0
A31: Leased Vera Rubin BEAR: $14.5M / $48.2M (+ lease prepayment) | B31: =IFERROR(F31*1/(H31-G31)*12,999) -> 59.76 | C31: =IF(ISNUMBER(B31),IF(ABS(B31-PB_Target)<=3,"WITHIN +/-3","outside"),"") -> outside | D31: n/a (no toggle) | E31: =IF(ISNUMBER(D31),IF(ABS(D31-PB_Target)<=3,"WITHIN +/-3","outside"),"") | F31: =48.2+LeasePrepayOn*LeasePrepay -> 49.8 | G31: =PB_Opex -> 4.5 | H31: =14.5 -> 14.5 | I31: =H31-G31 -> 10 | J31: =IFERROR(RATE(PB_Life,I31,-F31*1,L31),-1) -> 0.045623873 | L31: =PB_Resid*(F31-Q31)+Q31*MAX(0,1-PB_Life/PB_HallLife) -> 7.47 | M31: =IFERROR(RATE(PB_Life,I31,-F31*1),-1) -> 0.0013374963 | N31: =-F31*1+I31*(1-(1+PB_WACC)^-PB_Life)/PB_WACC+L31*(1+PB_WACC)^-PB_Life -> -8.4079484 | O31: =-F31*1+(I31-TaxRate*MAX(0,I31-((F31-Q31)/PB_Life+Q31*(ShellMW/(ShellMW+PowerMW)/Life_Shell+PowerMW/(ShellMW+PowerMW)/Life_Pow))))*(1-(1+PB_WACC)^-PB_Life)/PB_WACC+(PB_Resid*(F31-Q31)*(1-TaxRate)+Q31*MAX(0,1-PB_Life/PB_HallLife)-TaxRate*(Q31*MAX(0,1-PB_Life/PB_HallLife)-Q31*MAX(0,1-PB_Life*(ShellMW/(ShellMW+PowerMW)/Life_Shell+PowerMW/(ShellMW+PowerMW)/Life_Pow))))*(1+PB_WACC)^-PB_Life -> -9.5898251 | P31: =-F31*1+((I31-PB_Corp*H31)-TaxRate*MAX(0,I31-PB_Corp*H31-((F31-Q31)/PB_Life+Q31*(ShellMW/(ShellMW+PowerMW)/Life_Shell+PowerMW/(ShellMW+PowerMW)/Life_Pow))))*(1-(1+PB_WACC)^-PB_Life)/PB_WACC+(PB_Resid*(F31-Q31)*(1-TaxRate)+Q31*MAX(0,1-PB_Life/PB_HallLife)-TaxRate*(Q31*MAX(0,1-PB_Life/PB_HallLife)-Q31*MAX(0,1-PB_Life*(ShellMW/(ShellMW+PowerMW)/Life_Shell+PowerMW/(ShellMW+PowerMW)/Life_Pow))))*(1+PB_WACC)^-PB_Life -> -20.80569 | Q31: =0 -> 0
A32: Leased Vera Rubin: bull price $20M at base capex $40.1M (+ lease prepayment) | B32: =IFERROR(F32*1/(H32-G32)*12,999) -> 32.283871 | C32: =IF(ISNUMBER(B32),IF(ABS(B32-PB_Target)<=3,"WITHIN +/-3","outside"),"") -> outside | D32: n/a (no toggle) | E32: =IF(ISNUMBER(D32),IF(ABS(D32-PB_Target)<=3,"WITHIN +/-3","outside"),"") | F32: =40.1+LeasePrepayOn*LeasePrepay -> 41.7 | G32: =PB_Opex -> 4.5 | H32: =20 -> 20 | I32: =H32-G32 -> 15.5 | J32: =IFERROR(RATE(PB_Life,I32,-F32*1,L32),-1) -> 0.27258496 | L32: =PB_Resid*(F32-Q32)+Q32*MAX(0,1-PB_Life/PB_HallLife) -> 6.255 | M32: =IFERROR(RATE(PB_Life,I32,-F32*1),-1) -> 0.24981099 | N32: =-F32*1+I32*(1-(1+PB_WACC)^-PB_Life)/PB_WACC+L32*(1+PB_WACC)^-PB_Life -> 19.298442 | O32: =-F32*1+(I32-TaxRate*MAX(0,I32-((F32-Q32)/PB_Life+Q32*(ShellMW/(ShellMW+PowerMW)/Life_Shell+PowerMW/(ShellMW+PowerMW)/Life_Pow))))*(1-(1+PB_WACC)^-PB_Life)/PB_WACC+(PB_Resid*(F32-Q32)*(1-TaxRate)+Q32*MAX(0,1-PB_Life/PB_HallLife)-TaxRate*(Q32*MAX(0,1-PB_Life/PB_HallLife)-Q32*MAX(0,1-PB_Life*(ShellMW/(ShellMW+PowerMW)/Life_Shell+PowerMW/(ShellMW+PowerMW)/Life_Pow))))*(1+PB_WACC)^-PB_Life -> 11.513379 | P32: =-F32*1+((I32-PB_Corp*H32)-TaxRate*MAX(0,I32-PB_Corp*H32-((F32-Q32)/PB_Life+Q32*(ShellMW/(ShellMW+PowerMW)/Life_Shell+PowerMW/(ShellMW+PowerMW)/Life_Pow))))*(1-(1+PB_WACC)^-PB_Life)/PB_WACC+(PB_Resid*(F32-Q32)*(1-TaxRate)+Q32*MAX(0,1-PB_Life/PB_HallLife)-TaxRate*(Q32*MAX(0,1-PB_Life/PB_HallLife)-Q32*MAX(0,1-PB_Life*(ShellMW/(ShellMW+PowerMW)/Life_Shell+PowerMW/(ShellMW+PowerMW)/Life_Pow))))*(1+PB_WACC)^-PB_Life -> -0.0045140967 | Q32: =0 -> 0
A33: Owned GB300 (memo, rack-based servers+network + 12.5 hall), opex NO rent | B33: =IFERROR(F33*1/(H33-G33)*12,999) -> 43.014545 | C33: =IF(ISNUMBER(B33),IF(ABS(B33-PB_Target)<=3,"WITHIN +/-3","outside"),"") -> outside | D33: =IFERROR(F33*1/(MYRate*ND_GrossX-G33)*12,999) -> 34.877706 | E33: =IF(ISNUMBER(D33),IF(ABS(D33-PB_Target)<=3,"WITHIN +/-3","outside"),"") -> outside | F33: =PB_CapOwnGB -> 49.2875 | G33: =PB_OpexOwn -> 2.25 | H33: =MYRate -> 16 | I33: =H33-G33 -> 13.75 | J33: =IFERROR(RATE(PB_Life,I33,-F33*1,L33),-1) -> 0.18055757 | K33: =IFERROR(RATE(PB_Life,MYRate*ND_GrossX-G33,-F33*1,L33),-1) -> 0.25979558 | L33: =PB_Resid*(F33-Q33)+Q33*MAX(0,1-PB_Life/PB_HallLife) -> 14.545903 | M33: =IFERROR(RATE(PB_Life,I33,-F33*1),-1) -> 0.12227576 | N33: =-F33*1+I33*(1-(1+PB_WACC)^-PB_Life)/PB_WACC+L33*(1+PB_WACC)^-PB_Life -> 10.163369 | O33: =-F33*1+(I33-TaxRate*MAX(0,I33-((F33-Q33)/PB_Life+Q33*(ShellMW/(ShellMW+PowerMW)/Life_Shell+PowerMW/(ShellMW+PowerMW)/Life_Pow))))*(1-(1+PB_WACC)^-PB_Life)/PB_WACC+(PB_Resid*(F33-Q33)*(1-TaxRate)+Q33*MAX(0,1-PB_Life/PB_HallLife)-TaxRate*(Q33*MAX(0,1-PB_Life/PB_HallLife)-Q33*MAX(0,1-PB_Life*(ShellMW/(ShellMW+PowerMW)/Life_Shell+PowerMW/(ShellMW+PowerMW)/Life_Pow))))*(1+PB_WACC)^-PB_Life -> 3.9543452 | P33: =-F33*1+((I33-PB_Corp*H33)-TaxRate*MAX(0,I33-PB_Corp*H33-((F33-Q33)/PB_Life+Q33*(ShellMW/(ShellMW+PowerMW)/Life_Shell+PowerMW/(ShellMW+PowerMW)/Life_Pow))))*(1-(1+PB_WACC)^-PB_Life)/PB_WACC+(PB_Resid*(F33-Q33)*(1-TaxRate)+Q33*MAX(0,1-PB_Life/PB_HallLife)-TaxRate*(Q33*MAX(0,1-PB_Life/PB_HallLife)-Q33*MAX(0,1-PB_Life*(ShellMW/(ShellMW+PowerMW)/Life_Shell+PowerMW/(ShellMW+PowerMW)/Life_Pow))))*(1+PB_WACC)^-PB_Life -> -5.2599696 | Q33: =PB_Hall -> 12.5
A34: Owned Vera Rubin (memo, base 52.6 = 40.1 + 12.5 hall) at $16.2M, opex NO rent | B34: =IFERROR(F34*1/(H34-G34)*12,999) -> 45.247312 | C34: =IF(ISNUMBER(B34),IF(ABS(B34-PB_Target)<=3,"WITHIN +/-3","outside"),"") -> outside | D34: n/a (no toggle) | E34: =IF(ISNUMBER(D34),IF(ABS(D34-PB_Target)<=3,"WITHIN +/-3","outside"),"") | F34: =PB_CapOwnRubin -> 52.6 | G34: =PB_OpexOwn -> 2.25 | H34: =16.2 -> 16.2 | I34: =H34-G34 -> 13.95 | J34: =IFERROR(RATE(PB_Life,I34,-F34*1,L34),-1) -> 0.16174147 | L34: =PB_Resid*(F34-Q34)+Q34*MAX(0,1-PB_Life/PB_HallLife) -> 15.042778 | M34: =IFERROR(RATE(PB_Life,I34,-F34*1),-1) -> 0.1020925 | N34: =-F34*1+I34*(1-(1+PB_WACC)^-PB_Life)/PB_WACC+L34*(1+PB_WACC)^-PB_Life -> 7.8849198 | O34: =-F34*1+(I34-TaxRate*MAX(0,I34-((F34-Q34)/PB_Life+Q34*(ShellMW/(ShellMW+PowerMW)/Life_Shell+PowerMW/(ShellMW+PowerMW)/Life_Pow))))*(1-(1+PB_WACC)^-PB_Life)/PB_WACC+(PB_Resid*(F34-Q34)*(1-TaxRate)+Q34*MAX(0,1-PB_Life/PB_HallLife)-TaxRate*(Q34*MAX(0,1-PB_Life/PB_HallLife)-Q34*MAX(0,1-PB_Life*(ShellMW/(ShellMW+PowerMW)/Life_Shell+PowerMW/(ShellMW+PowerMW)/Life_Pow))))*(1+PB_WACC)^-PB_Life -> 2.0408319 | P34: =-F34*1+((I34-PB_Corp*H34)-TaxRate*MAX(0,I34-PB_Corp*H34-((F34-Q34)/PB_Life+Q34*(ShellMW/(ShellMW+PowerMW)/Life_Shell+PowerMW/(ShellMW+PowerMW)/Life_Pow))))*(1-(1+PB_WACC)^-PB_Life)/PB_WACC+(PB_Resid*(F34-Q34)*(1-TaxRate)+Q34*MAX(0,1-PB_Life/PB_HallLife)-TaxRate*(Q34*MAX(0,1-PB_Life/PB_HallLife)-Q34*MAX(0,1-PB_Life*(ShellMW/(ShellMW+PowerMW)/Life_Shell+PowerMW/(ShellMW+PowerMW)/Life_Pow))))*(1+PB_WACC)^-PB_Life -> -7.2886618 | Q34: =PB_Hall -> 12.5
A35: MODEL'S OWN: GB300-era path capex (avg PathRateIT + PathRateSP 2027) + model opex at 2027 owned share | B35: =IFERROR(F35*1/(H35-G35)*12,999) -> 39.761788 | C35: =IF(ISNUMBER(B35),IF(ABS(B35-PB_Target)<=3,"WITHIN +/-3","outside"),"") -> outside | D35: =IFERROR(F35*1/(MYRate*ND_GrossX-G35)*12,999) -> 31.788082 | E35: =IF(ISNUMBER(D35),IF(ABS(D35-PB_Target)<=3,"WITHIN +/-3","outside"),"") -> outside | F35: =AVERAGE(INDEX(PathRateIT,1,13),INDEX(PathRateIT,1,14),INDEX(PathRateIT,1,15),INDEX(PathRateIT,1,16))+AVERAGE(INDEX(PathRateSP,1,13),INDEX(PathRateSP,1,14),INDEX(PathRateSP,1,15),INDEX(PathRateSP,1,16))+(1-AVERAGE(INDEX(MW_OwnSh,1,13),INDEX(MW_OwnSh,1,14),INDEX(MW_OwnSh,1,15),INDEX(MW_OwnSh,1,16)))*LeasePrepayOn*LeasePrepay -> 42.373983 | G35: =(1-AVERAGE(INDEX(MW_OwnSh,1,13),INDEX(MW_OwnSh,1,14),INDEX(MW_OwnSh,1,15),INDEX(MW_OwnSh,1,16)))*PB_OpexModel+AVERAGE(INDEX(MW_OwnSh,1,13),INDEX(MW_OwnSh,1,14),INDEX(MW_OwnSh,1,15),INDEX(MW_OwnSh,1,16))*PB_OpexModelOwn -> 3.2116466 | H35: =MYRate -> 16 | I35: =H35-G35 -> 12.788353 | J35: =IFERROR(RATE(PB_Life,I35,-F35*1,L35),-1) -> 0.19251992 | K35: =IFERROR(RATE(PB_Life,MYRate*ND_GrossX-G35,-F35*1,L35),-1) -> 0.28655563 | L35: =PB_Resid*(F35-Q35)+Q35*MAX(0,1-PB_Life/PB_HallLife) -> 8.4189077 | M35: =IFERROR(RATE(PB_Life,I35,-F35*1),-1) -> 0.15491891 | N35: =-F35*1+I35*(1-(1+PB_WACC)^-PB_Life)/PB_WACC+L35*(1+PB_WACC)^-PB_Life -> 9.886666 | O35: =-F35*1+(I35-TaxRate*MAX(0,I35-((F35-Q35)/PB_Life+Q35*(ShellMW/(ShellMW+PowerMW)/Life_Shell+PowerMW/(ShellMW+PowerMW)/Life_Pow))))*(1-(1+PB_WACC)^-PB_Life)/PB_WACC+(PB_Resid*(F35-Q35)*(1-TaxRate)+Q35*MAX(0,1-PB_Life/PB_HallLife)-TaxRate*(Q35*MAX(0,1-PB_Life/PB_HallLife)-Q35*MAX(0,1-PB_Life*(ShellMW/(ShellMW+PowerMW)/Life_Shell+PowerMW/(ShellMW+PowerMW)/Life_Pow))))*(1+PB_WACC)^-PB_Life -> 4.4065546 | P35: =-F35*1+((I35-PB_Corp*H35)-TaxRate*MAX(0,I35-PB_Corp*H35-((F35-Q35)/PB_Life+Q35*(ShellMW/(ShellMW+PowerMW)/Life_Shell+PowerMW/(ShellMW+PowerMW)/Life_Pow))))*(1-(1+PB_WACC)^-PB_Life)/PB_WACC+(PB_Resid*(F35-Q35)*(1-TaxRate)+Q35*MAX(0,1-PB_Life/PB_HallLife)-TaxRate*(Q35*MAX(0,1-PB_Life/PB_HallLife)-Q35*MAX(0,1-PB_Life*(ShellMW/(ShellMW+PowerMW)/Life_Shell+PowerMW/(ShellMW+PowerMW)/Life_Pow))))*(1+PB_WACC)^-PB_Life -> -4.8077602 | Q35: =AVERAGE(INDEX(PathRateSP,1,13),INDEX(PathRateSP,1,14),INDEX(PathRateSP,1,15),INDEX(PathRateSP,1,16)) -> 3.6049111
A36: MODEL'S OWN: Rubin-era path capex (avg PathRateIT + PathRateSP 2029) + model opex at 2029 owned share, live RubinMW | B36: =IFERROR(F36*1/(H36-G36)*12,999) -> 45.655859 | C36: =IF(ISNUMBER(B36),IF(ABS(B36-PB_Target)<=3,"WITHIN +/-3","outside"),"") -> outside | D36: n/a (no toggle) | E36: =IF(ISNUMBER(D36),IF(ABS(D36-PB_Target)<=3,"WITHIN +/-3","outside"),"") | F36: =AVERAGE(INDEX(PathRateIT,1,21),INDEX(PathRateIT,1,22),INDEX(PathRateIT,1,23),INDEX(PathRateIT,1,24))+AVERAGE(INDEX(PathRateSP,1,21),INDEX(PathRateSP,1,22),INDEX(PathRateSP,1,23),INDEX(PathRateSP,1,24))+(1-AVERAGE(INDEX(MW_OwnSh,1,21),INDEX(MW_OwnSh,1,22),INDEX(MW_OwnSh,1,23),INDEX(MW_OwnSh,1,24)))*LeasePrepayOn*LeasePrepay -> 51.11772 | G36: =(1-AVERAGE(INDEX(MW_OwnSh,1,21),INDEX(MW_OwnSh,1,22),INDEX(MW_OwnSh,1,23),INDEX(MW_OwnSh,1,24)))*PB_OpexModel+AVERAGE(INDEX(MW_OwnSh,1,21),INDEX(MW_OwnSh,1,22),INDEX(MW_OwnSh,1,23),INDEX(MW_OwnSh,1,24))*PB_OpexModelOwn -> 2.7644267 | H36: =RubinMW -> 16.2 | I36: =H36-G36 -> 13.435573 | J36: =IFERROR(RATE(PB_Life,I36,-F36*1,L36),-1) -> 0.15601631 | L36: =PB_Resid*(F36-Q36)+Q36*MAX(0,1-PB_Life/PB_HallLife) -> 13.860735 | M36: =IFERROR(RATE(PB_Life,I36,-F36*1),-1) -> 0.098572153 | N36: =-F36*1+I36*(1-(1+PB_WACC)^-PB_Life)/PB_WACC+L36*(1+PB_WACC)^-PB_Life -> 6.7644469 | O36: =-F36*1+(I36-TaxRate*MAX(0,I36-((F36-Q36)/PB_Life+Q36*(ShellMW/(ShellMW+PowerMW)/Life_Shell+PowerMW/(ShellMW+PowerMW)/Life_Pow))))*(1-(1+PB_WACC)^-PB_Life)/PB_WACC+(PB_Resid*(F36-Q36)*(1-TaxRate)+Q36*MAX(0,1-PB_Life/PB_HallLife)-TaxRate*(Q36*MAX(0,1-PB_Life/PB_HallLife)-Q36*MAX(0,1-PB_Life*(ShellMW/(ShellMW+PowerMW)/Life_Shell+PowerMW/(ShellMW+PowerMW)/Life_Pow))))*(1+PB_WACC)^-PB_Life -> 1.345444 | P36: =-F36*1+((I36-PB_Corp*H36)-TaxRate*MAX(0,I36-PB_Corp*H36-((F36-Q36)/PB_Life+Q36*(ShellMW/(ShellMW+PowerMW)/Life_Shell+PowerMW/(ShellMW+PowerMW)/Life_Pow))))*(1-(1+PB_WACC)^-PB_Life)/PB_WACC+(PB_Resid*(F36-Q36)*(1-TaxRate)+Q36*MAX(0,1-PB_Life/PB_HallLife)-TaxRate*(Q36*MAX(0,1-PB_Life/PB_HallLife)-Q36*MAX(0,1-PB_Life*(ShellMW/(ShellMW+PowerMW)/Life_Shell+PowerMW/(ShellMW+PowerMW)/Life_Pow))))*(1+PB_WACC)^-PB_Life -> -7.9840497 | Q36: =AVERAGE(INDEX(PathRateSP,1,21),INDEX(PathRateSP,1,22),INDEX(PathRateSP,1,23),INDEX(PathRateSP,1,24)) -> 10.822852
A37: TEST: GB300 IT at $32M capex/IT MW (IT fits 22 mo only at ~$32M = 12 x 32 / (22 - 4.5)) | B37: =IFERROR(F37*1/(H37-G37)*12,999) -> 33.391304 | C37: =IF(ISNUMBER(B37),IF(ABS(B37-PB_Target)<=3,"WITHIN +/-3","outside"),"") -> outside | D37: =IFERROR(F37*1/(MYRate*ND_GrossX-G37)*12,999) -> 26.108553 | E37: =IF(ISNUMBER(D37),IF(ABS(D37-PB_Target)<=3,"WITHIN +/-3","outside"),"") -> outside | F37: =32 -> 32 | G37: =PB_Opex -> 4.5 | H37: =MYRate -> 16 | I37: =H37-G37 -> 11.5 | J37: =IFERROR(RATE(PB_Life,I37,-F37*1,L37),-1) -> 0.25725984 | K37: =IFERROR(RATE(PB_Life,MYRate*ND_GrossX-G37,-F37*1,L37),-1) -> 0.37878174 | L37: =PB_Resid*(F37-Q37)+Q37*MAX(0,1-PB_Life/PB_HallLife) -> 4.8 | M37: =IFERROR(RATE(PB_Life,I37,-F37*1),-1) -> 0.23355169 | N37: =-F37*1+I37*(1-(1+PB_WACC)^-PB_Life)/PB_WACC+L37*(1+PB_WACC)^-PB_Life -> 13.351382 | O37: =-F37*1+(I37-TaxRate*MAX(0,I37-((F37-Q37)/PB_Life+Q37*(ShellMW/(ShellMW+PowerMW)/Life_Shell+PowerMW/(ShellMW+PowerMW)/Life_Pow))))*(1-(1+PB_WACC)^-PB_Life)/PB_WACC+(PB_Resid*(F37-Q37)*(1-TaxRate)+Q37*MAX(0,1-PB_Life/PB_HallLife)-TaxRate*(Q37*MAX(0,1-PB_Life/PB_HallLife)-Q37*MAX(0,1-PB_Life*(ShellMW/(ShellMW+PowerMW)/Life_Shell+PowerMW/(ShellMW+PowerMW)/Life_Pow))))*(1+PB_WACC)^-PB_Life -> 7.7533907 | P37: =-F37*1+((I37-PB_Corp*H37)-TaxRate*MAX(0,I37-PB_Corp*H37-((F37-Q37)/PB_Life+Q37*(ShellMW/(ShellMW+PowerMW)/Life_Shell+PowerMW/(ShellMW+PowerMW)/Life_Pow))))*(1-(1+PB_WACC)^-PB_Life)/PB_WACC+(PB_Resid*(F37-Q37)*(1-TaxRate)+Q37*MAX(0,1-PB_Life/PB_HallLife)-TaxRate*(Q37*MAX(0,1-PB_Life/PB_HallLife)-Q37*MAX(0,1-PB_Life*(ShellMW/(ShellMW+PowerMW)/Life_Shell+PowerMW/(ShellMW+PowerMW)/Life_Pow))))*(1+PB_WACC)^-PB_Life -> -1.4609241 | Q37: =0 -> 0
A38: TEST: GB300 IT with lower opex $2M/IT MW-yr (ex-rent definition) | B38: =IFERROR(F38*1/(H38-G38)*12,999) -> 31.532143 | C38: =IF(ISNUMBER(B38),IF(ABS(B38-PB_Target)<=3,"WITHIN +/-3","outside"),"") -> outside | D38: =IFERROR(F38*1/(MYRate*ND_GrossX-G38)*12,999) -> 25.654028 | E38: =IF(ISNUMBER(D38),IF(ABS(D38-PB_Target)<=3,"WITHIN +/-3","outside"),"") -> outside | F38: =PB_CapGB -> 36.7875 | G38: =2 -> 2 | H38: =MYRate -> 16 | I38: =H38-G38 -> 14 | J38: =IFERROR(RATE(PB_Life,I38,-F38*1,L38),-1) -> 0.28352737 | K38: =IFERROR(RATE(PB_Life,MYRate*ND_GrossX-G38,-F38*1,L38),-1) -> 0.38838216 | L38: =PB_Resid*(F38-Q38)+Q38*MAX(0,1-PB_Life/PB_HallLife) -> 5.518125 | M38: =IFERROR(RATE(PB_Life,I38,-F38*1),-1) -> 0.26139045 | N38: =-F38*1+I38*(1-(1+PB_WACC)^-PB_Life)/PB_WACC+L38*(1+PB_WACC)^-PB_Life -> 18.229797 | O38: =-F38*1+(I38-TaxRate*MAX(0,I38-((F38-Q38)/PB_Life+Q38*(ShellMW/(ShellMW+PowerMW)/Life_Shell+PowerMW/(ShellMW+PowerMW)/Life_Pow))))*(1-(1+PB_WACC)^-PB_Life)/PB_WACC+(PB_Resid*(F38-Q38)*(1-TaxRate)+Q38*MAX(0,1-PB_Life/PB_HallLife)-TaxRate*(Q38*MAX(0,1-PB_Life/PB_HallLife)-Q38*MAX(0,1-PB_Life*(ShellMW/(ShellMW+PowerMW)/Life_Shell+PowerMW/(ShellMW+PowerMW)/Life_Pow))))*(1+PB_WACC)^-PB_Life -> 11.051015 | P38: =-F38*1+((I38-PB_Corp*H38)-TaxRate*MAX(0,I38-PB_Corp*H38-((F38-Q38)/PB_Life+Q38*(ShellMW/(ShellMW+PowerMW)/Life_Shell+PowerMW/(ShellMW+PowerMW)/Life_Pow))))*(1-(1+PB_WACC)^-PB_Life)/PB_WACC+(PB_Resid*(F38-Q38)*(1-TaxRate)+Q38*MAX(0,1-PB_Life/PB_HallLife)-TaxRate*(Q38*MAX(0,1-PB_Life/PB_HallLife)-Q38*MAX(0,1-PB_Life*(ShellMW/(ShellMW+PowerMW)/Life_Shell+PowerMW/(ShellMW+PowerMW)/Life_Pow))))*(1+PB_WACC)^-PB_Life -> 1.8367006 | Q38: =0 -> 0
A39: TEST: GB300 IT with prepayments counted as cash (55% of capex on 70% of deals = 38.5%) | B39: =IFERROR(F39*(1-0.55*0.7)/(H39-G39)*12,999) -> 23.607978 | C39: =IF(ISNUMBER(B39),IF(ABS(B39-PB_Target)<=3,"WITHIN +/-3","outside"),"") -> WITHIN +/-3 | D39: =IFERROR(F39*(1-0.55*0.7)/(MYRate*ND_GrossX-G39)*12,999) -> 18.459002 | E39: =IF(ISNUMBER(D39),IF(ABS(D39-PB_Target)<=3,"WITHIN +/-3","outside"),"") -> outside | F39: =PB_CapGB -> 36.7875 | G39: =PB_Opex -> 4.5 | H39: =MYRate -> 16 | I39: =H39-G39 -> 11.5 | J39: =IFERROR(RATE(PB_Life,I39,-F39*(1-0.55*0.7),L39),-1) -> 0.4447945 | K39: =IFERROR(RATE(PB_Life,MYRate*ND_GrossX-G39,-F39*(1-0.55*0.7),L39),-1) -> 0.60247519 | L39: =PB_Resid*(F39-Q39)+Q39*MAX(0,1-PB_Life/PB_HallLife) -> 5.518125 | M39: =IFERROR(RATE(PB_Life,I39,-F39*(1-0.55*0.7)),-1) -> 0.42038044 | N39: =-F39*(1-0.55*0.7)+I39*(1-(1+PB_WACC)^-PB_Life)/PB_WACC+L39*(1+PB_WACC)^-PB_Life -> 23.153242 | O39: =-F39*(1-0.55*0.7)+(I39-TaxRate*MAX(0,I39-((F39-Q39)/PB_Life+Q39*(ShellMW/(ShellMW+PowerMW)/Life_Shell+PowerMW/(ShellMW+PowerMW)/Life_Pow))))*(1-(1+PB_WACC)^-PB_Life)/PB_WACC+(PB_Resid*(F39-Q39)*(1-TaxRate)+Q39*MAX(0,1-PB_Life/PB_HallLife)-TaxRate*(Q39*MAX(0,1-PB_Life/PB_HallLife)-Q39*MAX(0,1-PB_Life*(ShellMW/(ShellMW+PowerMW)/Life_Shell+PowerMW/(ShellMW+PowerMW)/Life_Pow))))*(1+PB_WACC)^-PB_Life -> 18.358314 | P39: =-F39*(1-0.55*0.7)+((I39-PB_Corp*H39)-TaxRate*MAX(0,I39-PB_Corp*H39-((F39-Q39)/PB_Life+Q39*(ShellMW/(ShellMW+PowerMW)/Life_Shell+PowerMW/(ShellMW+PowerMW)/Life_Pow))))*(1-(1+PB_WACC)^-PB_Life)/PB_WACC+(PB_Resid*(F39-Q39)*(1-TaxRate)+Q39*MAX(0,1-PB_Life/PB_HallLife)-TaxRate*(Q39*MAX(0,1-PB_Life/PB_HallLife)-Q39*MAX(0,1-PB_Life*(ShellMW/(ShellMW+PowerMW)/Life_Shell+PowerMW/(ShellMW+PowerMW)/Life_Pow))))*(1+PB_WACC)^-PB_Life -> 9.1439991 | Q39: =0 -> 0
A40: Implied GB300 revenue/IT MW if management's 22 months INCLUDES prepayments (capex x 61.5% x 12 / 22 + opex) | H40: =PB_CapGB*(1-0.55*0.7)*12/PB_Target+PB_Opex -> 16.840534
A41: NOTE (v0.7b): the 2027+ new-deal price is now set from CONTRACTS ($16M/IT MW base = $3.72/GPU-hr; 5-yr deals $14.5-16M: Microsoft ~$14.5M, Astra ~$15.9M), NOT calibrated to management's 22-month payback. At $16M no row fits 22 months ex-prepayments; with prepayments counted as cash (38.5% of capex) leased GB300 does (~24 months). Management's payback therefore most likely INCLUDES prepayments and/or uses lower opex. Col D 'gross' = MYRate x ND_GrossX (sensitivity only).
A44: D) ASSET FLOOR: PV of EBITDA margin on signed RPO + stakes - net debt - capex still needed for contracted MW ($M)
A45: RPO schedule assumption: 36% ($13.5B) evenly Jul'26-Jun'28 (Q2'26 Note 2); remainder 64% spread evenly Jul'28-Jun'31 (12 qtrs; ~avg remaining tenor: Microsoft 5-yr from late 2025, Meta #2 5-yr from 2027 - assumption). Margin = model adj. EBITDA margin by quarter (FY30 margin after 2030); pre-tax; discounted at WACC from ValDate.
...

Sheet Funding
A1: LEGACY v0.4 parametric funding illustration (v0.7 plan is wired in Inputs FP_*, CashFlow, Valuation POST-FUNDING block) - ESTIMATED (illustrative; DCF value/share already reflects capex; dilution arises only from issuing equity/converts vs model value)
A4: Gap
A5: Minimum liquidity Q3'26-Q4'27 (no plug) | B5: =MIN(INDEX(Liq,1,11):INDEX(Liq,1,16)) -> 1000
A6: Minimum liquidity Q3'26-Q4'28 (no plug) | B6: =MIN(INDEX(Liq,1,11):INDEX(Liq,1,20)) -> 1000
A7: Funding need through FY27 = MinCash - min liquidity | B7: =MAX(0,MinCash-FU_Min27) -> 1000
A8: Funding need through FY28 | B8: =MAX(0,MinCash-FU_Min28) -> 1000
A9: Plan target (1 = through FY27, 2 = through FY28) | B9: 1
A10: Plan target ($M) | B10: =IF(FU_TgtSel=2,FU_Gap28,FU_Gap27) -> 1000
A11: Model FD value/share (V_PS) and implied FD shares (M) | B11: =V_PS -> 0.01
A12: FD shares at value (M) = V_EQ / V_PS | B12: =IFERROR(V_EQ/V_PS,0) -> -62109.621
A14: Source inputs (Estimated)
A15: ATM: shares remaining (M) | B15: =ATM_Rem -> 12.270507
A16: ATM: issue price = SharePx x (1 - discount/fees) | B16: =SharePx*(1-FU_ATMd) -> 237.9538
A17: ATM discount + fees | B17: 0.02
A18: Customer prepayments: incremental beyond PrepayPct ($M) | B18: 1500 | C18: Q2 letter: >$9B prepayments in 2026; 70% of deals, 50-60% of capex
A19: Prepayment price concession (% of amount, PV cost) | B19: 0
A20: ABS / GPU-backed debt: LTV on GPU net book value at Q2'27 | B20: 0.5
A21: GPU net book value at Q2'27 ($M) | B21: =INDEX(NBV_H,1,14)+INDEX(NBV_B,1,14)+INDEX(NBV_N,1,14) -> 29053.325
A22: ABS capacity ($M) = LTV x GPU NBV, capped | B22: =MIN(FU_LTV*FU_NBV,FU_ABSCap) -> 5000
A23: ABS cap ($M) | B23: 5000
A24: ABS interest rate | B24: 0.09 | C24: memo: cost in WACC; no share dilution
A25: New converts: amount ($M) | B25: 3000
A26: Conversion premium | B26: 0.35
A27: Conversion price | B27: =SharePx*(1+FU_CVPrem) -> 327.7935
A29: Per-source effect if used ALONE at full size (value/share = (V_EQ + equity-like proceeds) / (shares + new shares)) | B29: Proceeds $M | C29: New shares M | D29: Value/share $ | E29: Change $/sh | F29: Dilution %
A30: ATM (all 12.27M sh) | B30: =FU_ATMsh*FU_ATMpx -> 2919.8138 | C30: =FU_ATMsh -> 12.270507 | D30: =(V_EQ+FU_ATMsh*FU_ATMpx)/(FU_N+FU_ATMsh) -> -0.037017965 | E30: =D30-FU_V -> -0.047017965 | F30: =IFERROR(C30/FU_N,0) -> -0.0001975621
A31: Customer prepayments | B31: =FU_PreAmt -> 1500 | C31: =0 -> 0 | D31: =FU_V-FU_PreAmt*FU_PreCost/FU_N -> 0.01 | E31: =D31-FU_V -> 0 | F31: =IFERROR(C31/FU_N,0) -> 0
A32: ABS / GPU-backed debt | B32: =FU_ABSMax -> 5000 | C32: =0 -> 0 | D32: =FU_V -> 0.01 | E32: =D32-FU_V -> 0 | F32: =IFERROR(C32/FU_N,0) -> 0
A33: New converts (if converted when value > conv. price) | B33: =FU_CVAmt -> 3000 | C33: =IF(FU_V>FU_CVPx,FU_CVAmt/FU_CVPx,0) -> 0 | D33: =IF(FU_V>FU_CVPx,(V_EQ+FU_CVAmt)/(FU_N+FU_CVAmt/FU_CVPx),FU_V) -> 0.01 | E33: =D33-FU_V -> 0 | F33: =IFERROR(C33/FU_N,0) -> 0
A35: Combined plan to fill the target: order prepayments -> ATM -> ABS -> converts
A36: Prepayments used | B36: =MIN(FU_PreAmt,FU_Tgt) -> 1000
A37: ATM used ($M) | B37: =MIN(FU_ATMsh*FU_ATMpx,FU_Tgt-FU_P1) -> 0
A38: ABS used | B38: =MIN(FU_ABSMax,FU_Tgt-FU_P1-FU_P2) -> 0
A39: Converts used | B39: =MIN(FU_CVAmt,FU_Tgt-FU_P1-FU_P2-FU_P3) -> 0
A40: Unfunded remainder (needs equity plug / more sources) | B40: =FU_Tgt-FU_P1-FU_P2-FU_P3-FU_P4 -> 0
A41: New shares: ATM + converts (if converted) | B41: =IFERROR(FU_P2/FU_ATMpx,0)+IF(FU_V>FU_CVPx,FU_P4/FU_CVPx,0) -> 0
A42: Combined value/share | B42: =(V_EQ+FU_P2+IF(FU_V>FU_CVPx,FU_P4,0)-FU_P1*FU_PreCost)/(FU_N+FU_Sh) -> 0.01
A43: Change vs model value/share ($) | B43: =FU_VC-FU_V -> 0
A44: Dilution (% of FD shares) | B44: =IFERROR(FU_Sh/FU_N,0) -> 0
A45: Memo: ABS annual interest ($M) | B45: =FU_P3*FU_ABSr -> 0
...

Sheet Funding_Stack
A1: v0.8b FUNDING STACK - live toggles (Inputs: NDPrepayOn/NDPrepayPct, ABS_LTC/ABS_Spread/ABS_Term, UncPxOn/UncPx/UncRenew, BackstopMW) and static grid (self-consistent PT basis)
A3: New-deal prepayment toggle (NDPrepayOn) / share of new-build capex on non-signed MW | B3: =NDPrepayOn -> 0
A4: NDPrepayPct | B4: =NDPrepayPct -> 0.55
A5: ABS loan-to-cost on contracted-MW capex (ABS_LTC) | B5: =ABS_LTC -> 0
A6: ABS rate = SOFR + spread | B6: =SOFR+ABS_Spread -> 0.065
A7: ABS after-tax cost = rate x (1 - TaxRate) | B7: =FS_Kd*(1-TaxRate) -> 0.04823
A8: Unsold new-MW price toggle (UncPxOn) / UncPx $M per IT MW-yr | B8: =IF(UncPxOn=1,UncPx,0) -> 0
A9: Meta backstop MW | B9: =BackstopMW -> 0
A10: Stop building | B10: =StopBuild -> 0
A11: New prepayments Q3'26-Q4'30 ($M) | B11: =SUMPRODUCT((Q_Idx>=11)*(Q_Idx<=28)*CF_Prepay) -> 20079.989
A12: ABS draws Q3'26-Q4'30 ($M) | B12: =SUMPRODUCT((Q_Idx>=11)*(Q_Idx<=28)*ABS_Draw) -> 0
A13: ABS peak balance ($M) | B13: =MAX(ABS_Bal) -> 0
A14: ABS interest Q3'26-Q4'30 ($M) | B14: =SUMPRODUCT((Q_Idx>=11)*(Q_Idx<=28)*ABS_Int) -> 0
A15: Total capex Q3'26-Q4'30 ($M) | B15: =SUMPRODUCT((Q_Idx>=11)*(Q_Idx<=28)*Capex) -> 111441.91
A16: ABS share of funding mix = ABS draws / total capex Q3'26-Q4'30 | B16: =IFERROR(FS_ABS/FS_Cx,0) -> 0
A17: Base WACC implied for the rest of the mix | B17: 0.11
A18: BLENDED WACC = ABS share x after-tax ABS cost + (1 - share) x base 11% | B18: =FS_wABS*FS_Kdat+(1-FS_wABS)*FS_WBase -> 0.11
A19: Equity top-ups + ATM Q3'26-Q4'30 ($M) | B19: =SUMPRODUCT((Q_Idx>=11)*(Q_Idx<=28)*(FP_EqTop+CF_ATM)) -> 41719.014
A20: 2027 plan converts (net, $M) | B20: =SUM(CF_FPConv) -> 12644.174
A21: Self-consistent PT (live) / EV / new shares / YE27 liquidity | B21: =V_PT -> 3.970466 | C21: =V_EV -> -898.81401 | D21: =V_NewShHead -> 10991.22 | E21: =INDEX(Liq,1,16) -> 1000
A24: STATIC GRID (fs_grid.py; full recalcs) - see rows below
A25: BUILD PLAN (base 11% WACC unless stated)
A26: Layer / case | B26: Self-consistent PT $ | C26: EV $M | D26: New shares M (headline) | E26: Authority need M (vs ~82) | F26: YE27 liquidity $M | G26: Spot-issuance PT memo $ | H26: New prepayments $M | I26: ABS draws $M | J26: ABS interest $M | K26: Plan converts net $M | L26: ATM + top-ups $M | M26: WACC used
A27: base (v0.8) | B27: 3.970466 | C27: -898.81401 | D27: 10991.22 | E27: 13262.174 | F27: 1000 | G27: 88.869332 | H27: 20079.989 | I27: 0 | J27: 0 | K27: 12644.174 | L27: 41719.014 | M27: 0.11
A28: + prepay 55% | B28: 13.510189 | C28: 4052.2467 | D28: 1405.8624 | E28: 2073.266 | F28: 5634.4432 | G28: 58.101767 | H28: 51802.711 | I28: 0 | J28: 0 | K28: 12644.174 | L28: 17072.217 | M28: 0.11
A29: + ABS 50% on contracted MW | B29: 13.903524 | C29: 4052.2467 | D29: 1577.9848 | E29: 1966.6189 | F29: 5323.5951 | G29: 63.806779 | H29: 51802.711 | I29: 5129.4639 | J29: 922.64173 | K29: 7577.1556 | L29: 20018.3 | M29: 0.11
A30: + uncontracted $20M | B30: 108.36584 | C30: 30859.002 | D30: 173.68937 | E30: 223.55179 | F30: 5342.3245 | G30: 132.1827 | H30: 51802.711 | I30: 5129.4639 | J30: 922.64173 | K30: 7577.1556 | L30: 16819.261 | M30: 0.11
A31: + uncontracted $22.5M (instead of $20M) | B31: 171.02473 | C31: 49130.832 | D31: 102.43453 | E31: 134.02869 | F31: 5354.0644 | G31: 181.32948 | H31: 51802.711 | I31: 5129.4639 | J31: 922.64173 | K31: 7577.1556 | L31: 15278.917 | M31: 0.11
A32: + Meta backstop 190 MW (all layers) | B32: 159.30451 | C32: 45586.196 | D32: 102.95124 | E32: 132.90501 | F32: 5686.6768 | G32: 170.80456 | H32: 50816.423 | I32: 6026.0894 | J32: 1084.3705 | K32: 6691.4456 | L32: 14311.234 | M32: 0.11
A33: (b) all layers, blended WACC 10.67% (ABS share 5.4% of capex at after-tax SOFR+2.5%) | B33: 173.16122 | C33: 49849.25 | D33: 95.743941 | E33: 123.30074 | F33: 5686.6768 | G33: 182.60451 | H33: 50816.423 | I33: 6026.0894 | J33: 1084.3705 | K33: 6691.4456 | L33: 14311.234 | M33: 0.1066725
A34: (c) all layers, WACC 9% - UPPER BOUND: double counts cheap debt | B34: 265.95422 | C34: 78956.744 | D34: 66.907954 | E34: 84.850026 | F34: 5686.6768 | G34: 261.9086 | H34: 50816.423 | I34: 6026.0894 | J34: 1084.3705 | K34: 6691.4456 | L34: 14311.234 | M34: 0.09
A35: (d) Skeptic full stack: uncontracted $20M, prepay 55%, ABS 50%, Rubin $20M, WACC 9% | B35: 207.67705 | C35: 59560.799 | D35: 93.627018 | E35: 119.64522 | F35: 5361.6847 | G35: 212.32597 | H35: 51802.711 | I35: 5129.4639 | J35: 922.64173 | K35: 7577.1556 | L35: 16724.224 | M35: 0.09
A36: (d) Skeptic full stack: uncontracted $22.5M, prepay 55%, ABS 50%, Rubin $20M, WACC 9% | B36: 283.63632 | C36: 84726.506 | D36: 66.525018 | E36: 85.575408 | F36: 5378.3396 | G36: 276.77789 | H36: 51802.711 | I36: 5129.4639 | J36: 922.64173 | K36: 7577.1556 | L36: 15154.109 | M36: 0.09
A38: STOP BUILDING / CONTRACTED ONLY (same layers; uncontracted price layers have no MW to act on)
A39: Layer / case | B39: Self-consistent PT $ | C39: EV $M | D39: New shares M (headline) | E39: Authority need M (vs ~82) | F39: YE27 liquidity $M | G39: Spot-issuance PT memo $ | H39: New prepayments $M | I39: ABS draws $M | J39: ABS interest $M | K39: Plan converts net $M | L39: ATM + top-ups $M | M39: WACC used
A40: base (v0.8) | B40: 13.888664 | C40: 9765.2328 | D40: 138.33224 | E40: 138.33224 | F40: 3283.2818 | G40: 19.191197 | H40: 0 | I40: 0 | J40: 0 | K40: 0 | L40: 0 | M40: 0.11
A41: + prepay 55% | B41: 13.888664 | C41: 9765.2328 | D41: 138.33224 | E41: 138.33224 | F41: 3283.2818 | G41: 19.191197 | H41: 0 | I41: 0 | J41: 0 | K41: 0 | L41: 0 | M41: 0.11
A42: + ABS 50% on contracted MW | B42: 11.168929 | C42: 9765.2328 | D42: 172.01739 | E42: 172.01739 | F42: 7643.9961 | G42: 16.580054 | H42: 0 | I42: 4707.2117 | J42: 848.6396 | K42: 0 | L42: 0 | M42: 0.11
A43: + uncontracted $20M | B43: 11.168929 | C43: 9765.2328 | D43: 172.01739 | E43: 172.01739 | F43: 7643.9961 | G43: 16.580054 | H43: 0 | I43: 4707.2117 | J43: 848.6396 | K43: 0 | L43: 0 | M43: 0.11
A44: + uncontracted $22.5M (instead of $20M) | B44: 11.168929 | C44: 9765.2328 | D44: 172.01739 | E44: 172.01739 | F44: 7643.9961 | G44: 16.580054 | H44: 0 | I44: 4707.2117 | J44: 848.6396 | K44: 0 | L44: 0 | M44: 0.11
...

Sheet Outputs
A1: Outputs - key metrics at valuation-date horizons
A2: Horizon quarter = last quarter end on/before EDATE(ValDate, months). LTM = 4 quarters ending at horizon. Per-share value rolled forward at Ke.
A4: Metric | B4: Valuation qtr | C4: +6 months | D4: +1 year | E4: +3 years
A5: Quarter index | B5: =MATCH(EDATE(ValDate,0),Q_End,1) -> 11 | C5: =MATCH(EDATE(ValDate,6),Q_End,1) -> 13 | D5: =MATCH(EDATE(ValDate,12),Q_End,1) -> 15 | E5: =MATCH(EDATE(ValDate,36),Q_End,1) -> 23
A6: Quarter | B6: =INDEX(Q_Lab,1,B5) -> Q3'26 | C6: =INDEX(Q_Lab,1,C5) -> Q1'27 | D6: =INDEX(Q_Lab,1,D5) -> Q3'27 | E6: =INDEX(Q_Lab,1,E5) -> Q3'29
A7: Months from ValDate | B7: 0 | C7: 6 | D7: 12 | E7: 36
A8: Revenue - quarter ($M) | B8: =INDEX(PL_Rev,1,B$5) -> 674.68641 | C8: =INDEX(PL_Rev,1,C$5) -> 1027.6473 | D8: =INDEX(PL_Rev,1,D$5) -> 2462.2117 | E8: =INDEX(PL_Rev,1,E$5) -> 7804.0448
A9: Revenue - LTM ($M) | B9: =SUMPRODUCT(PL_Rev*(Q_Idx>B$5-4)*(Q_Idx<=B$5)) -> 1883.6864 | C9: =SUMPRODUCT(PL_Rev*(Q_Idx>C$5-4)*(Q_Idx<=C$5)) -> 3093.7268 | D9: =SUMPRODUCT(PL_Rev*(Q_Idx>D$5-4)*(Q_Idx<=D$5)) -> 5932.0826 | E9: =SUMPRODUCT(PL_Rev*(Q_Idx>E$5-4)*(Q_Idx<=E$5)) -> 26947.665
A10: Adj. EBITDA - quarter ($M) | B10: =INDEX(PL_EBITDA,1,B$5) -> 263.55961 | C10: =INDEX(PL_EBITDA,1,C$5) -> 503.88198 | D10: =INDEX(PL_EBITDA,1,D$5) -> 1282.6887 | E10: =INDEX(PL_EBITDA,1,E$5) -> 4879.0268
A11: Adj. EBITDA - LTM ($M) | B11: =SUMPRODUCT(PL_EBITDA*(Q_Idx>B$5-4)*(Q_Idx<=B$5)) -> 644.25961 | C11: =SUMPRODUCT(PL_EBITDA*(Q_Idx>C$5-4)*(Q_Idx<=C$5)) -> 1325.6728 | D11: =SUMPRODUCT(PL_EBITDA*(Q_Idx>D$5-4)*(Q_Idx<=D$5)) -> 2937.9595 | E11: =SUMPRODUCT(PL_EBITDA*(Q_Idx>E$5-4)*(Q_Idx<=E$5)) -> 16566.051
A12: EBIT - LTM ($M) | B12: =SUMPRODUCT(PL_EBIT*(Q_Idx>B$5-4)*(Q_Idx<=B$5)) -> -888.91445 | C12: =SUMPRODUCT(PL_EBIT*(Q_Idx>C$5-4)*(Q_Idx<=C$5)) -> -1120.7018 | D12: =SUMPRODUCT(PL_EBIT*(Q_Idx>D$5-4)*(Q_Idx<=D$5)) -> -1102.3992 | E12: =SUMPRODUCT(PL_EBIT*(Q_Idx>E$5-4)*(Q_Idx<=E$5)) -> 677.9823
A13: Free cash flow - LTM ($M) | B13: =SUMPRODUCT(CF_FCF*(Q_Idx>B$5-4)*(Q_Idx<=B$5)) -> -2187.8369 | C13: =SUMPRODUCT(CF_FCF*(Q_Idx>C$5-4)*(Q_Idx<=C$5)) -> -13212.663 | D13: =SUMPRODUCT(CF_FCF*(Q_Idx>D$5-4)*(Q_Idx<=D$5)) -> -28091.954 | E13: =SUMPRODUCT(CF_FCF*(Q_Idx>E$5-4)*(Q_Idx<=E$5)) -> -20429.323
A14: Net debt ($M, model) | B14: =INDEX(CF_NetDebt,1,B$5) -> 2084.3193 | C14: =INDEX(CF_NetDebt,1,C$5) -> 10440.171 | D14: =INDEX(CF_NetDebt,1,D$5) -> 26450.643 | E14: =INDEX(CF_NetDebt,1,E$5) -> 46977.217
A15: Diluted shares (M, at DilPx) | B15: =INDEX(Sh_Dil,1,B$5) -> 314.92525 | C15: =INDEX(Sh_Dil,1,C$5) -> 1065.3162 | D15: =INDEX(Sh_Dil,1,D$5) -> 1534.8116 | E15: =INDEX(Sh_Dil,1,E$5) -> 10848.154
A16: Active IT MW | B16: =INDEX(MW_Act,1,B$5) -> 182.4897 | C16: =INDEX(MW_Act,1,C$5) -> 301.7195 | D16: =INDEX(MW_Act,1,D$5) -> 629.5368 | E16: =INDEX(MW_Act,1,E$5) -> 1963.8213
A17: Energized IT MW (Capacity) | B17: =INDEX(MW_En,1,B$5) -> 216.9897 | C17: =INDEX(MW_En,1,C$5) -> 453.79225 | D17: =INDEX(MW_En,1,D$5) -> 812.6073 | E17: =INDEX(MW_En,1,E$5) -> 1963.8213
A18: Implied value per share - FD, rolled at Ke ($) | B18: =V_PS*(1+Ke)^(B$7/12) -> 0.01 | C18: =V_PS*(1+Ke)^(C$7/12) -> 0.010630146 | D18: =V_PS*(1+Ke)^(D$7/12) -> 0.0113 | E18: =V_PS*(1+Ke)^(E$7/12) -> 0.01442897
A19: Implied value per share - 308.69M-style basic ($) | B19: =V_PSB*(1+Ke)^(B$7/12) -> -2.0120311 | C19: =V_PSB*(1+Ke)^(C$7/12) -> -2.1388184 | D19: =V_PSB*(1+Ke)^(D$7/12) -> -2.2735952 | E19: =V_PSB*(1+Ke)^(E$7/12) -> -2.9031537
A21: Valuation summary
A22: DCF EV ($M) | B22: =V_EV -> -898.81401
A23: Market EV at SharePx ($M) | B23: =V_MKTEV -> 74654.719
A24: FD value / share at solved price ($) | B24: =V_PS -> 0.01
A25: 12-month PT ($) - SELF-CONSISTENT headline | B25: =V_PT -> 3.970466
A26: MEMO: PT if issuing at spot $242.81 (needs market access at today's price) | B26: =V_PTSpot -> 88.869332
A27: Shares needed vs ~82M authority (M) | B27: =V_AuthNeed -> 13262.174
A28: Upside vs SharePx | B28: =V_UP -> -0.98364785
A29: Share price ($) | B29: =SharePx -> 242.81
A30: Off-B/S weight used | B30: =OffBSWt -> 0
A31: Scenario | B31: =CHOOSE(Scen,"BULL","BASE","BEAR") -> BASE
A32: Model vs consensus (Skeptic, Oct 2 2026) | B32: FY2026 | C32: FY2027 | D32: FY2028
A33: Revenue - model | B33: =SUMIF(Q_Yr,2026,PL_Rev) -> 2465.0795 | C33: =SUMIF(Q_Yr,2027,PL_Rev) -> 8209.2404 | D33: =SUMIF(Q_Yr,2028,PL_Rev) -> 19716.797
A34: Revenue - consensus | B34: =INDEX(Cons_Rev,1,3) -> 3340 | C34: =INDEX(Cons_Rev,1,4) -> 12300 | D34: =INDEX(Cons_Rev,1,5) -> 23000
A35: Revenue - model / consensus - 1 | B35: =IF(N(B34)=0,"n/a",B33/B34-1) -> -0.26195223 | C35: =IF(N(C34)=0,"n/a",C33/C34-1) -> -0.33258208 | D35: =IF(N(D34)=0,"n/a",D33/D34-1) -> -0.14274797
A36: Adj. EBITDA - model | B36: =SUMIF(Q_Yr,2026,PL_EBITDA) -> 951.29083 | C36: =SUMIF(Q_Yr,2027,PL_EBITDA) -> 4213.144 | D36: =SUMIF(Q_Yr,2028,PL_EBITDA) -> 11402.704
A37: Adj. EBITDA - consensus | B37: =INDEX(Cons_EB,1,3) -> 1390 | C37: =INDEX(Cons_EB,1,4) -> 6730 | D37: =INDEX(Cons_EB,1,5) -> 13980
A38: Adj. EBITDA - model / consensus - 1 | B38: =IF(N(B37)=0,"n/a",B36/B37-1) -> -0.31561811 | C38: =IF(N(C37)=0,"n/a",C36/C37-1) -> -0.37397563 | D38: =IF(N(D37)=0,"n/a",D36/D37-1) -> -0.18435594
A39: Capex - model | B39: =SUMIF(Q_Yr,2026,Capex) -> 17617.717 | C39: =SUMIF(Q_Yr,2027,Capex) -> 33779.447 | D39: =SUMIF(Q_Yr,2028,Capex) -> 26949.043
A40: Capex - consensus | B40: =INDEX(Cons_Cx,1,3) -> 0 | C40: =INDEX(Cons_Cx,1,4) -> 29100 | D40: =INDEX(Cons_Cx,1,5) -> 0
A41: Capex - model / consensus - 1 | B41: =IF(N(B40)=0,"n/a",B39/B40-1) -> n/a | C41: =IF(N(C40)=0,"n/a",C39/C40-1) -> 0.16080574 | D41: =IF(N(D40)=0,"n/a",D39/D40-1) -> n/a
A43: MW sources at YE26 / YE27 (IT MW) | B43: Q4'26 | C43: Q4'27
...

Sheet Checks
A1: Checks
