Workbook

Sheet Cover
A1: Nebius (NBIS) driver-based model
A2: VERSION v0.7 – PROVISIONAL
A3: Build date: 2026-10-04. v0.3 base approved (terminal excludes Q4'30 spend for post-horizon MW and that MW; GPU capex lead 3 qtrs vs billing; history scenario-invariant; bear replacement at bear price path; bull Blackwell 6.25% cut after Rubin + next-gen -1.7%/yr).
A4: v0.7 changes: GB300 IT ($22M) and gross ($26.4M) co-equal (basis not disclosed by management); payback note + tests ($32M capex, $2M opex, prepayments counted); Rubin new deals priced directly at $18M/IT MW-yr (bull 20 / bear 16; no IT/gross toggle; short-term $40-50M tranche GB300-only); Rubin capex $41M leased (bull 41, bear 48.5; $32M outer-bull sensitivity; owned $56M), low-medium confidence; $775M facility $0 drawn in base; Aug-26 converts counted once; 2027 funding plan (remaining ATM + 2 x $5B converts on Aug-26 terms; bear ATM at -40%, converts shut) with post-funding per-share values; converts debt vs shares at the solved price (original principal), full-conversion and NSS counts; Avride burn added back when Avride is valued (bull double count fixed). v0.6 changes: multi-year new-deal $/MW flat nominal within generation through 2028 then -3%/yr (bear -6%/yr from 2027; 31% post-Rubin stress separate) - removes per-chip ageing double count; one linked new-deal input ($/GPU-hr x GPUs/IT MW x hours x occupancy); Rubin 1.2x GB300 per GPU-hr; payback and asset-floor checks (Payback_Floor tab); stake values per Filings Note 5. v0.5 changes: short-term tranche = 5% of TOTAL avg active MW at $45M x 85% occupancy (tests 2/10%, 0% floor); unsold new MW priced separately from RPO-contracted MW (sens $18/22/25); 6/30 deferred revenue released on Reported current/non-current split, new prepayments straight-line over 4 yrs; backlog floor checks; new-deal $/MW basis selector (IT $22M base; gross-equivalent $26.4M/IT MW); prepayments by customer type (signed Microsoft/Meta 0% new; new hyperscaler 30%; other 38.5% -> 22.5% for 2028+ signings); closing deferred revenue run-off deducted from EV (cash double-count fix); SFC: none in model. v0.4 changes: split capex lead (shell/power 3 qtrs, GPUs 2 qtrs ahead of billing); price path year 2+ decline (-2.5/-6/-9.5%) + post-Rubin cut in all scenarios; terminal g from fundamentals (g = RR x RONC, reinvestment deducted); Rubin premium vs GB300 open input at per-MW parity; MW-basis selector; CLT1 rent/prepay; Inferize, June-exit, Vineland-shutdown and peer-margin switches; Funding and Bridge tabs. Also: new-deal pricing for 2027+ MW (multi-year $22M/IT MW-yr + 10% short-term $45M with post-Rubin cut/recovery); customer prepayments 38.5% of new-build capex (toggle); Vineland shutdown wired to Capacity table at $14.5M/IT MW-yr + Bloom-slip toggle; Capacity proposed MW path as MWSel 4 scenario (not base); GPU history anchored to ~30k at 3/31/25.
A5: Key outputs (live, current scenario)
A6: Scenario | B6: =CHOOSE(Scen,"BULL","BASE","BEAR") -> BASE
A7: DCF EV ($M) | B7: =V_EV -> -183.73714
A8: FD value / share ($) | B8: =V_PS -> 0.01
A9: 12-month PT ($) | B9: =V_PT -> 0
A10: First quarter liquidity < 0 | B10: =Liq_NegQ -> Q1'28
A11: Market EV ($M) | B11: =V_MKTEV -> 74654.719
A13: Notes - open items
A14: OPEN: FY26 capex below the $20-25B guide (Aug 12 2026 call): v0.3 $18.1B (~$1.9B short); v0.4 split lead $16.7B (~$3.3B short); possible early 2027 shell/power or deposits not in the path. Check: Checks 'FY26 capex vs company guide'. | B14: Owner: Filings / Capacity
A15: OPEN: funding plan is ESTIMATED, not guidance. Base pre-plan YE27 liquidity -$13.5B (v0.6 -$9.5B: facility $0, Rubin capex $41M) -> plan sized at ATM 12.27M sh + 2 x $6.4B converts (Aug-26 terms) to reach ~MinCash $2B at YE27; first negative quarter moves Q2'27 -> Q1'28; 2028-30 still needs ~$36B more. | B15: Owner: Capacity
A16: OPEN: Rubin new-deal revenue $18M/IT MW-yr direct (bull 20 / bear 16; two contracts, medium-low) and Rubin capex $41M leased / $56M owned (bull 41, bear 48.5; $32M outer bull only) - LOW-MEDIUM confidence; Capacity reconciles networking ($3.6M vs GB300 $6.1M) Tuesday. Base EV swings -$5.3B / +$5.6B on Rubin revenue $16/$20M. | B16: Owner: GPU Market
A17: OPEN: AIB CLT1 prepayment (undisclosed; default $0) and Inferize price (press $100-150M, toggle off). | B17: Owner: Filings
A18: OPEN: Vineland shutdown default OFF (VinShutSel 0); scenarios/weights are Capacity judgment (prob-weighted Q4'26 loss ~$68M at $14.5M/IT MW-yr vs Capacity ~$67M); SLA credits undisclosed; genset power saving not credited. | B18: Owner: Capacity
A19: OPEN: Capacity proposed MW path is a scenario only (MWSel 4) until Capacity's Tuesday file; new-deal $/MW basis (IT vs gross) medium-low confidence; short-term share 10% is an estimate. | B19: Owner: Capacity / Filings
A20: OPEN: ARR scope / whether $3.0B ARR includes signed-not-billing tranches; unexplained ARR residual ~$0.6B shown as a line, not plugged. | B20: Owner: Filings
A21: OPEN: YE27 ~950 MW IT normalization is a placeholder pending Capacity's basis column. | B21: Owner: Capacity
A22: OPEN: Q3'26 transfer into service (model $4,702M) pending Q3 filing; depreciation start dates (material weakness) flagged. | B22: Owner: Filings
A23: FLAGS: base DCF EV ~ -$0.2B (IT) / +$2.3B (gross) -> equity value and per-share $0 on BOTH bases (DCF EV below asset floor $3.6B); bull EV $90.4B (>3x base); bear EV -$25.7B; bull YE27 liquidity -$3.4B even after plan; bear ATM 61.8M sh at $145.69 exceeds ~20% AGM issuance authority (~57.5M); FY26 capex $16.9B below $20-25B guide; FY30 margin 70.2% above peer +8pp; IT payback 28 mo vs mgmt 22 (gross 22.6) - test does not discriminate (fits IT at $32M capex, $2M opex, or prepayments counted). See Checks and Payback_Floor. | B23: Owner: Modeling / GPU Market

Sheet README
A1: Nebius (NBIS) driver model - README
A3: Save path: /workspace/nebius/model/nebius_model.xlsx. Quarterly Q1'24-Q2'26 actuals (Hist, tagged Reported/Derived/Estimated/Not disclosed + best estimate + source), Q3'26-Q4'30 forecast, FY roll-ups AI:AO.
A4: Scenario: Inputs!D4 (1 Bull / 2 Base / 3 Bear). Blue = input; orange = placeholder; yellow = estimated/consensus; black = formula.
A5: Flow: Inputs -> Sites (contracted / energized [Capacity file] / mgmt-connected; MWSel; BillLag; PUE basis) -> Pricing -> Contracts (tranches, power ceiling, Q4 bridge) -> Revenue (3 books) -> Capex_DA (vintage cohorts, PISLag, impairment, cap. interest, dep-yield) -> Financing -> PnL -> CashFlow -> Shares -> Valuation (DCF, dilution solve, EV bridge, EV/MW) -> KPIs / Outputs / Sensitivity / Checks.
A6: Circularity: no Excel iterative calc needed. Valuation solves value/share by 15 unrolled fixed-point steps; DilPxMode 1 = SharePx for quarterly dilution.
A7: Converts: DilMethod 1 if-converted all / 2 ITM only (default; step dilution at conversion prices) / 3 net-share. Converted principal is removed from debt (Checks row 1).
A8: Static snapshot tables on Outputs / Sensitivity / Valuation memo rows / Checks (bull 3x, scenario-invariance) come from LibreOffice recalcs in snap.py; re-run snap.py after changing inputs.

Sheet Bridge
A1: EV bridge v0.1 -> v0.3 -> v0.4 (STATIC, filled by snap.py)
A2: Base scenario. Each row = cumulative settings recomputed in the CURRENT model (bug fixes such as the renewal-formula bracket and scenario-invariant history are in every row). $B and $/share are FD value/share.
A4: Step | B4: DCF EV $B | C4: Change $B | D4: FD $/share | E4: Change $/sh | F4: 12m PT $ | G4: FY26 rev $M | H4: FY27 rev $M | I4: FY28 rev $M | J4: FY27 EBITDA $M | K4: YE27 liquidity $M | L4: First neg. qtr
A5: v0.1 (as reported) | B5: 45.499764 | D5: 117.21424 | F5: 132.45209 | G5: 2400.637 | H5: 8242.0189 | I5: 22266.612 | J5: 4575.8582 | K5: -4456.7617 | L5: Q4'27
A6: + fleet ratio forecast-only / capex on driver MW (FixMgmt) | B6: 48.823167 | C6: 3.3234033 | D6: 127.47273 | E6: 10.258497 | F6: 144.04419 | G6: 2400.637 | H6: 8242.0189 | I6: 22266.612 | J6: 4606.0461 | K6: -4408.0848 | L6: Q4'27
A7: + terminal on Q4'30 exit incl. Q1'31 MW (include both) | B7: 102.75467 | C7: 53.931501 | D7: 277.20861 | E7: 149.73587 | F7: 313.24573 | G7: 2400.637 | H7: 8242.0189 | I7: 22266.612 | J7: 4606.0461 | K7: -4408.0848 | L7: Q4'27
A8: + TV run-off floor | B8: 102.75467 | C8: 0 | D8: 277.20861 | E8: 0 | F8: 313.24573 | G8: 2400.637 | H8: 8242.0189 | I8: 22266.612 | J8: 4606.0461 | K8: -4408.0848 | L8: Q4'27
A9: + owned-site O&M | B9: 91.634048 | C9: -11.12062 | D9: 247.25781 | E9: -29.950795 | F9: 279.40133 | G9: 2400.637 | H9: 8242.0189 | I9: 22266.612 | J9: 4517.4726 | K9: -4518.475 | L9: Q4'27
A10: + H2'26 repricing (= v0.2) | B10: 102.45081 | C10: 10.816757 | D10: 276.36392 | E10: 29.106113 | F10: 312.29124 | G10: 2425.3295 | H10: 8517.5153 | I10: 22648.736 | J10: 4713.075 | K10: -4310.0666 | L10: Q4'27
A11: + exclude both Q4'30 spend & Q1'31 MW | B11: 86.363871 | C11: -16.086934 | D11: 233.08315 | E11: -43.280772 | F11: 263.38396 | G11: 2425.3295 | H11: 8517.5153 | I11: 22648.736 | J11: 4713.075 | K11: -4310.0666 | L11: Q4'27
A12: + GPU capex lead 3 qtrs (= v0.3) | B12: 94.115927 | C12: 7.7520558 | D12: 248.19387 | E12: 15.110715 | F12: 280.45907 | G12: 2425.3295 | H12: 8517.5153 | I12: 22648.736 | J12: 4713.075 | K12: -7264.8692 | L12: Q2'27
A13: + split capex lead: shell/power 3, GPUs 2 qtrs | B13: 87.921521 | C13: -6.1944054 | D13: 233.7087 | E13: -14.485164 | F13: 264.09084 | G13: 2425.3295 | H13: 8517.5153 | I13: 22648.736 | J13: 4713.075 | K13: -7160.9335 | L13: Q3'27
A14: + price path: post-Rubin cut 22% + -6%/yr from year 2 | B14: 94.973211 | C14: 7.0516897 | D14: 252.68078 | E14: 18.972078 | F14: 285.52928 | G14: 2425.3295 | H14: 8102.5841 | I14: 22384.539 | J14: 4418.4739 | K14: -7450.3255 | L14: Q3'27
A15: + Rubin premium at per-MW parity (1.56x GB300) | B15: 153.79061 | C15: 58.817396 | D15: 406.65048 | E15: 153.9697 | F15: 459.51504 | G15: 2425.3295 | H15: 8140.6586 | I15: 24633.629 | J15: 4445.5068 | K15: -7423.7798 | L15: Q3'27
A16: + CLT1 rent $2.2M/IT MW-yr | B16: 154.02622 | C16: 0.23561158 | D16: 407.25495 | E16: 0.60447567 | F16: 460.1981 | G16: 2425.3295 | H16: 8140.6586 | I16: 24633.629 | J16: 4447.4208 | K16: -7421.8657 | L16: Q3'27
A17: + terminal g from fundamentals | B17: 125.81969 | C17: -28.206529 | D17: 334.88941 | E17: -72.365546 | F17: 378.42503 | G17: 2425.3295 | H17: 8140.6586 | I17: 24633.629 | J17: 4447.4208 | K17: -7421.8657 | L17: Q3'27
... A34: + 2027 funding plan: ATM 12.27M sh + 2 x $6.4B converts; post-funding per-share (= v0.7) | B34: -0.18373714 | C34: 0.12485947 | D34: 0.01 | E34: 0 | F34: 0 | G34: 2423.4083 | H34: 7621.7173 | I34: 19606.895 | J34: 4078.9726 | K34: 2073.2027 | L34: Q1'28
A37: Horizon per-share values (FD value/share rolled at Ke; excludes future funding dilution - see Funding tab)
A38: Scenario | B38: Today | C38: 6-month | D38: 12-month PT | E38: 3-year
A39: Base (live) | B39: 0.01 | C39: 0 | D39: 0 | E39: 0
A40: Bull | B40: 235.23358 | C40: 248.77456 | D40: 263.27824 | E40: 330.25623
A41: Bear | B41: 0.01 | C41: 0 | D41: 0 | E41: 0
A44: New-MW pricing vs IREN >$20M/IT MW-yr ($M per IT MW-yr). GB300 GPU-hour engine (legacy fleet) at Oct-1 list x RealRes x Util_Res; new 2027+ MW at new-deal blend (col G)
A45: Scenario | B45: GB300 gross | C45: net leased (-$2.2M rent) | D45: net owned (-O&M) | E45: Rubin gross | F45: IREN gross / leased / owned | G45: New-deal blend gross
A46: Base (live) | B46: 30.157546 | C46: 27.957546 | D46: 29.407546 | E46: 23.160995 | F46: 20.0 / 17.8 / 19.25 | G46: 22.39175
A47: Bull | B47: 43.041696 | C47: 40.841696 | D47: 42.291696 | E47: 33.056023 | F47: 20.0 / 17.8 / 19.25 | G47: 25.742188
A48: Bear | B48: 22.272793 | C48: 20.072793 | D48: 21.522793 | E48: 17.105505 | F48: 20.0 / 17.8 / 19.25 | G48: 19.881353
A51: v0.5 BASE RANGE: 12m PT ($/share) by short-term share (of TOTAL active MW) x new-deal $/MW basis, with / without prepayment decay (STATIC). Green = base; yellow = supported tests; orange = gross-MW basis (alternative reading of slide); red = equity floored at 0
A52: Prepayment decay ON (base) | B52: ST share 0% (floor) | C52: ST share 2% | D52: ST share 5% | E52: ST share 10%
A53: IT basis $22M/IT MW | B53: 0 | C53: 0 | D53: 0 | E53: 0
A54: Gross-MW basis = $26.4M/IT MW | B54: 0 | C54: 0 | D54: 0 | E54: 0
A55: EV $B / YE27 liq $B / 1st neg - IT | B55: -3.3 / 1.9 / Q1'28 | C55: -2.1 / 2.0 / Q1'28 | D55: -0.2 / 2.1 / Q1'28 | E55: 2.9 / 2.2 / Q1'28
A56: EV $B / YE27 liq $B / 1st neg - gross | B56: 0.1 / 2.3 / Q1'28 | C56: 1.0 / 2.4 / Q1'28 | D56: 2.3 / 2.4 / Q1'28 | E56: 4.6 / 2.5 / Q1'28
A58: Prepayment decay OFF (other deals 38.5% flat) | B58: ST share 0% (floor) | C58: ST share 2% | D58: ST share 5% | E58: ST share 10%
A59: IT basis $22M/IT MW | B59: 0 | C59: 0 | D59: 0 | E59: 0
A60: Gross-MW basis = $26.4M/IT MW | B60: 0 | C60: 0 | D60: 0 | E60: 0.57124883
A61: EV $B / YE27 liq $B / 1st neg - IT | B61: -1.5 / 1.9 / Q1'28 | C61: -0.3 / 2.0 / Q1'28 | D61: 1.6 / 2.1 / Q1'28 | E61: 4.7 / 2.2 / Q1'28
A62: EV $B / YE27 liq $B / 1st neg - gross | B62: 1.8 / 2.3 / Q1'28 | C62: 2.7 / 2.4 / Q1'28 | D62: 4.1 / 2.4 / Q1'28 | E62: 6.4 / 2.5 / Q1'28

Sheet Payback_Floor
A1: Payback check, new-deal price cases, EBITDA per IT MW by generation, and asset floor (live formulas). Inputs blue.
A3: Leased GB300 capex per IT MW ($M; GPU + network + storage, no shell) | B3: 41.3 | C3: Capacity gpu_mw_capex.xlsx colo base (~$41M)
A4: Leased Vera Rubin capex per IT MW ($M) - base (LOW-MEDIUM confidence) | B4: 41 | C4: v0.7: flat to GB300 (SemiAnalysis TCO; Capacity at MS rack cost $42-48M); bull 41, bear 48.5, outer bull 32 (soft)
A5: Owned GB300 capex per IT MW ($M, incl. shell/power) | B5: 53 | C5: Capacity owned base 53 (range 43-70)
A6: Owned Vera Rubin capex per IT MW ($M) | B6: 56 | C6: v0.7: $53-59M (base 56); was 43
A7: Opex per IT MW-yr (rent $2.0-2.5M + power + ops), fixed across generations | B7: 4.5 | C7: Range $4-5M; does NOT fall at the Rubin switch
A8: Management payback target (months) | B8: 22 | C8: Q2'26 letter: 1 year 10 months, prepayments excluded (footnote basis)
A9: Asset life for unlevered IRR (yrs; capex at t0, flat EBITDA, no residual, pre-tax) | B9: 5 | C9: GPU life 5 yrs (model base)
A10: A) New-deal price cases - $/IT MW-yr next to implied $/GPU-hr. GB300: one linked input (ND_Px x 491 x 8,760 x ND_Occ), IT vs gross toggle. RUBIN: direct $/IT MW-yr (no IT/gross toggle)
A11: Case | B11: IT reading $M/IT MW | C11: IT $/GPU-hr | D11: Gross reading $M/IT MW | E11: Gross $/GPU-hr | F11: $/GPU-hr at 400/MW (ref only)
A12: GB300 NVL72 (491 GPUs/IT MW) | B12: =MYRate -> 22 | C12: =ND_Px -> 5.1148992 | D12: =MYRate*ND_GrossX -> 26.410758 | E12: =ND_Px*ND_GrossX -> 6.1403803
A13: Vera Rubin $16M/IT MW [bear] | B13: =16 -> 16 | C13: =16*1000000/(GPUMW_N*8760) -> 5.7077626 | D13: same (no toggle) | F13: =16*1000000/(RubinGPUMW_D*8760) -> 4.56621
A14: Vera Rubin $18M/IT MW [base] | B14: =18 -> 18 | C14: =18*1000000/(GPUMW_N*8760) -> 6.4212329 | D14: same (no toggle) | F14: =18*1000000/(RubinGPUMW_D*8760) -> 5.1369863
A15: Vera Rubin $20M/IT MW [bull] | B15: =20 -> 20 | C15: =20*1000000/(GPUMW_N*8760) -> 7.1347032 | D15: same (no toggle) | F15: =20*1000000/(RubinGPUMW_D*8760) -> 5.7077626
A16: Vera Rubin at live RubinMW | B16: =RubinMW -> 18 | C16: =RubinMW*1000000/(GPUMW_N*8760) -> 6.4212329 | D16: same (no toggle) | F16: =RubinMW*1000000/(RubinGPUMW_D*8760) -> 5.1369863
A17: Benchmarks: IREN new 3-yr GB300 ~$4.65/GPU-hr (>$20M/IT MW); Rubin: Anthropic-Nscale ~$16.2M/MW (6-yr, MW basis unknown); WhiteFiber-Prime Intellect 576 VR200 ~$108.2M/3 yrs = ~$7.15/GPU-hr (~$20M/IT MW if packages counted, medium). GB300 basis not disclosed by management.
A19: B) EBITDA per IT MW-yr by generation (opex fixed across generations; Rubin = RubinMW, no toggle)
B20: GB300 IT | C20: Rubin (RubinMW) | D20: Change | E20: GB300 gross | F20: Rubin (RubinMW) | G20: Change
A21: Revenue per IT MW-yr | B21: =B12 -> 22 | C21: =RubinMW -> 18 | D21: =C21/B21-1 -> -0.18181818 | E21: =D12 -> 26.410758 | F21: =RubinMW -> 18 | G21: =F21/E21-1 -> -0.31845954
A22: Opex per IT MW-yr (PB_Opex) | B22: =PB_Opex -> 4.5 | C22: =PB_Opex -> 4.5 | E22: =PB_Opex -> 4.5 | F22: =PB_Opex -> 4.5
A23: EBITDA per IT MW-yr | B23: =B21-B22 -> 17.5 | C23: =C21-C22 -> 13.5 | D23: =C23/B23-1 -> -0.22857143 | E23: =E21-E22 -> 21.910758 | F23: =F21-F22 -> 13.5 | G23: =F23/E23-1 -> -0.38386431
A24: Memo: model's own leased opex/IT MW = RentMW x PUE + power (PUE x 8,760 x PowerPx) + OM_MW | B24: =RentMW*PUE+PUE*8760*PowerPx/1000000+OM_MW -> 4.38375
A26: C) PAYBACK (months) = capex / (revenue - opex) x 12; prepayments EXCLUDED unless stated. Flag = within +/-3 months of 22. IRR = unlevered pre-tax, capex at t0, flat EBITDA over PB_Life, no residual
A27: Case | B27: IT / Rubin payback | C27: flag | D27: Gross $26.4M payback | E27: flag | F27: capex $M/IT MW | G27: opex | H27: revenue IT $M | I27: EBITDA/IT MW (IT) | J27: IRR (IT) | K27: IRR (gross)
A28: Leased GB300 | B28: =IFERROR(F28*1/(H28-G28)*12,999) -> 28.32 | C28: =IF(ISNUMBER(B28),IF(ABS(B28-PB_Target)<=3,"WITHIN +/-3","outside"),"") -> outside | D28: =IFERROR(F28*1/(MYRate*ND_GrossX-G28)*12,999) -> 22.619026 | E28: =IF(ISNUMBER(D28),IF(ABS(D28-PB_Target)<=3,"WITHIN +/-3","outside"),"") -> WITHIN +/-3 | F28: =PB_CapGB -> 41.3 | G28: =PB_Opex -> 4.5 | H28: =MYRate -> 22 | I28: =H28-G28 -> 17.5 | J28: =IFERROR(RATE(PB_Life,I28,-F28*1),-1) -> 0.3166364 | K28: =IFERROR(RATE(PB_Life,MYRate*ND_GrossX-G28,-F28*1),-1) -> 0.44685417
A29: Leased Vera Rubin BASE: $18M rev / $41M capex | B29: =IFERROR(F29*1/(H29-G29)*12,999) -> 36.444444 | C29: =IF(ISNUMBER(B29),IF(ABS(B29-PB_Target)<=3,"WITHIN +/-3","outside"),"") -> outside | D29: n/a (no toggle) | E29: =IF(ISNUMBER(D29),IF(ABS(D29-PB_Target)<=3,"WITHIN +/-3","outside"),"") | F29: =41 -> 41 | G29: =PB_Opex -> 4.5 | H29: =18 -> 18 | I29: =H29-G29 -> 13.5 | J29: =IFERROR(RATE(PB_Life,I29,-F29*1),-1) -> 0.19303446
A30: Leased Vera Rubin BULL: $20M / $41M | B30: =IFERROR(F30*1/(H30-G30)*12,999) -> 31.741935 | C30: =IF(ISNUMBER(B30),IF(ABS(B30-PB_Target)<=3,"WITHIN +/-3","outside"),"") -> outside | D30: n/a (no toggle) | E30: =IF(ISNUMBER(D30),IF(ABS(D30-PB_Target)<=3,"WITHIN +/-3","outside"),"") | F30: =41 -> 41 | G30: =PB_Opex -> 4.5 | H30: =20 -> 20 | I30: =H30-G30 -> 15.5 | J30: =IFERROR(RATE(PB_Life,I30,-F30*1),-1) -> 0.25811256
A31: Leased Vera Rubin BEAR: $16M / $48.5M | B31: =IFERROR(F31*1/(H31-G31)*12,999) -> 50.608696 | C31: =IF(ISNUMBER(B31),IF(ABS(B31-PB_Target)<=3,"WITHIN +/-3","outside"),"") -> outside | D31: n/a (no toggle) | E31: =IF(ISNUMBER(D31),IF(ABS(D31-PB_Target)<=3,"WITHIN +/-3","outside"),"") | F31: =48.5 -> 48.5 | G31: =PB_Opex -> 4.5 | H31: =16 -> 16 | I31: =H31-G31 -> 11.5 | J31: =IFERROR(RATE(PB_Life,I31,-F31*1),-1) -> 0.059561689
A32: Leased Vera Rubin OUTER BULL (sensitivity only; $32M capex is soft): $20M / $32M | B32: =IFERROR(F32*1/(H32-G32)*12,999) -> 24.774194 | C32: =IF(ISNUMBER(B32),IF(ABS(B32-PB_Target)<=3,"WITHIN +/-3","outside"),"") -> WITHIN +/-3 | D32: n/a (no toggle) | E32: =IF(ISNUMBER(D32),IF(ABS(D32-PB_Target)<=3,"WITHIN +/-3","outside"),"") | F32: =32 -> 32 | G32: =PB_Opex -> 4.5 | H32: =20 -> 20 | I32: =H32-G32 -> 15.5 | J32: =IFERROR(RATE(PB_Life,I32,-F32*1),-1) -> 0.39154272
A33: Owned GB300 (memo, base 53) | B33: =IFERROR(F33*1/(H33-G33)*12,999) -> 36.342857 | C33: =IF(ISNUMBER(B33),IF(ABS(B33-PB_Target)<=3,"WITHIN +/-3","outside"),"") -> outside | D33: =IFERROR(F33*1/(MYRate*ND_GrossX-G33)*12,999) -> 29.026837 | E33: =IF(ISNUMBER(D33),IF(ABS(D33-PB_Target)<=3,"WITHIN +/-3","outside"),"") -> outside | F33: =PB_CapOwnGB -> 53 | G33: =PB_Opex -> 4.5 | H33: =MYRate -> 22 | I33: =H33-G33 -> 17.5 | J33: =IFERROR(RATE(PB_Life,I33,-F33*1),-1) -> 0.19429148 | K33: =IFERROR(RATE(PB_Life,MYRate*ND_GrossX-G33,-F33*1),-1) -> 0.3035931
A34: Owned Vera Rubin (memo, base 56) at $18M | B34: =IFERROR(F34*1/(H34-G34)*12,999) -> 49.777778 | C34: =IF(ISNUMBER(B34),IF(ABS(B34-PB_Target)<=3,"WITHIN +/-3","outside"),"") -> outside | D34: n/a (no toggle) | E34: =IF(ISNUMBER(D34),IF(ABS(D34-PB_Target)<=3,"WITHIN +/-3","outside"),"") | F34: =PB_CapOwnRubin -> 56 | G34: =PB_Opex -> 4.5 | H34: =18 -> 18 | I34: =H34-G34 -> 13.5 | J34: =IFERROR(RATE(PB_Life,I34,-F34*1),-1) -> 0.065672474
A35: MODEL'S OWN: GB300-era path capex (avg PathRateIT 2027) + model opex | B35: =IFERROR(F35*1/(H35-G35)*12,999) -> 28.377577 | C35: =IF(ISNUMBER(B35),IF(ABS(B35-PB_Target)<=3,"WITHIN +/-3","outside"),"") -> outside | D35: =IFERROR(F35*1/(MYRate*ND_GrossX-G35)*12,999) -> 22.695161 | E35: =IF(ISNUMBER(D35),IF(ABS(D35-PB_Target)<=3,"WITHIN +/-3","outside"),"") -> WITHIN +/-3 | F35: =AVERAGE(INDEX(PathRateIT,1,13),INDEX(PathRateIT,1,14),INDEX(PathRateIT,1,15),INDEX(PathRateIT,1,16)) -> 41.658875 | G35: =PB_OpexModel -> 4.38375 | H35: =MYRate -> 22 | I35: =H35-G35 -> 17.61625 | J35: =IFERROR(RATE(PB_Life,I35,-F35*1),-1) -> 0.31555325 | K35: =IFERROR(RATE(PB_Life,MYRate*ND_GrossX-G35,-F35*1),-1) -> 0.44474446
A36: MODEL'S OWN: Rubin-era path capex (avg PathRateIT 2029) + model opex, live RubinMW | B36: =IFERROR(F36*1/(H36-G36)*12,999) -> 38.974819 | C36: =IF(ISNUMBER(B36),IF(ABS(B36-PB_Target)<=3,"WITHIN +/-3","outside"),"") -> outside | D36: n/a (no toggle) | E36: =IF(ISNUMBER(D36),IF(ABS(D36-PB_Target)<=3,"WITHIN +/-3","outside"),"") | F36: =AVERAGE(INDEX(PathRateIT,1,21),INDEX(PathRateIT,1,22),INDEX(PathRateIT,1,23),INDEX(PathRateIT,1,24)) -> 44.22424 | G36: =PB_OpexModel -> 4.38375 | H36: =RubinMW -> 18 | I36: =H36-G36 -> 13.61625 | J36: =IFERROR(RATE(PB_Life,I36,-F36*1),-1) -> 0.1634783
A37: TEST: GB300 IT at $32M capex/IT MW (IT fits 22 mo only at ~$32M = 12 x 32 / (22 - 4.5)) | B37: =IFERROR(F37*1/(H37-G37)*12,999) -> 21.942857 | C37: =IF(ISNUMBER(B37),IF(ABS(B37-PB_Target)<=3,"WITHIN +/-3","outside"),"") -> WITHIN +/-3 | D37: =IFERROR(F37*1/(MYRate*ND_GrossX-G37)*12,999) -> 17.525637 | E37: =IF(ISNUMBER(D37),IF(ABS(D37-PB_Target)<=3,"WITHIN +/-3","outside"),"") -> outside | F37: =32 -> 32 | G37: =PB_Opex -> 4.5 | H37: =MYRate -> 22 | I37: =H37-G37 -> 17.5 | J37: =IFERROR(RATE(PB_Life,I37,-F37*1),-1) -> 0.46615308 | K37: =IFERROR(RATE(PB_Life,MYRate*ND_GrossX-G37,-F37*1),-1) -> 0.62411873
A38: TEST: GB300 IT with lower opex $2M/IT MW-yr (ex-rent definition) | B38: =IFERROR(F38*1/(H38-G38)*12,999) -> 24.78 | C38: =IF(ISNUMBER(B38),IF(ABS(B38-PB_Target)<=3,"WITHIN +/-3","outside"),"") -> WITHIN +/-3 | D38: =IFERROR(F38*1/(MYRate*ND_GrossX-G38)*12,999) -> 20.302524 | E38: =IF(ISNUMBER(D38),IF(ABS(D38-PB_Target)<=3,"WITHIN +/-3","outside"),"") -> WITHIN +/-3 | F38: =PB_CapGB -> 41.3 | G38: =2 -> 2 | H38: =MYRate -> 22 | I38: =H38-G38 -> 20 | J38: =IFERROR(RATE(PB_Life,I38,-F38*1),-1) -> 0.39140505 | K38: =IFERROR(RATE(PB_Life,MYRate*ND_GrossX-G38,-F38*1),-1) -> 0.51764538
A39: TEST: GB300 IT with prepayments counted as cash (55% of capex on 70% of deals = 38.5%) | B39: =IFERROR(F39*(1-0.55*0.7)/(H39-G39)*12,999) -> 17.4168 | C39: =IF(ISNUMBER(B39),IF(ABS(B39-PB_Target)<=3,"WITHIN +/-3","outside"),"") -> outside | D39: =IFERROR(F39*(1-0.55*0.7)/(MYRate*ND_GrossX-G39)*12,999) -> 13.910701 | E39: =IF(ISNUMBER(D39),IF(ABS(D39-PB_Target)<=3,"WITHIN +/-3","outside"),"") -> outside | F39: =PB_CapGB -> 41.3 | G39: =PB_Opex -> 4.5 | H39: =MYRate -> 22 | I39: =H39-G39 -> 17.5 | J39: =IFERROR(RATE(PB_Life,I39,-F39*(1-0.55*0.7)),-1) -> 0.62891035 | K39: =IFERROR(RATE(PB_Life,MYRate*ND_GrossX-G39,-F39*(1-0.55*0.7)),-1) -> 0.81937141
A40: Implied GB300 revenue/IT MW if management's 22 months INCLUDES prepayments (capex x 61.5% x 12 / 22 + opex) | H40: =PB_CapGB*(1-0.55*0.7)*12/PB_Target+PB_Opex -> 18.354273
A41: NOTE (payback test): the gross reading fits management's 22 months only if capex is accurate to within ~20% (the IT reading fits at ~$32M leased GB300 capex/IT MW = 12 x 32 / (22 - 4.5)); management's opex definition is undisclosed (lower opex shortens IT payback); and if management's payback INCLUDES prepayments it would imply revenue BELOW the IT reading (~$18.4M vs $22M). The test therefore does not discriminate between IT and gross: both rows are kept co-equal, basis not disclosed by management.
A44: D) ASSET FLOOR: PV of EBITDA margin on signed RPO + stakes - net debt - capex still needed for contracted MW ($M)
A45: RPO schedule assumption: 36% ($13.5B) evenly Jul'26-Jun'28 (Q2'26 Note 2); remainder 64% spread evenly Jul'28-Jun'31 (12 qtrs; ~avg remaining tenor: Microsoft 5-yr from late 2025, Meta #2 5-yr from 2027 - assumption). Margin = model adj. EBITDA margin by quarter (FY30 margin after 2030); pre-tax; discounted at WACC from ValDate.
...

Sheet Funding
A1: LEGACY v0.4 parametric funding illustration (v0.7 plan is wired in Inputs FP_*, CashFlow, Valuation POST-FUNDING block) - ESTIMATED (illustrative; DCF value/share already reflects capex; dilution arises only from issuing equity/converts vs model value)
A4: Gap
A5: Minimum liquidity Q3'26-Q4'27 (no plug) | B5: =MIN(INDEX(Liq,1,11):INDEX(Liq,1,16)) -> 2073.2027
A6: Minimum liquidity Q3'26-Q4'28 (no plug) | B6: =MIN(INDEX(Liq,1,11):INDEX(Liq,1,20)) -> -13352.424
A7: Funding need through FY27 = MinCash - min liquidity | B7: =MAX(0,MinCash-FU_Min27) -> 0
A8: Funding need through FY28 | B8: =MAX(0,MinCash-FU_Min28) -> 15352.424
A9: Plan target (1 = through FY27, 2 = through FY28) | B9: 1
A10: Plan target ($M) | B10: =IF(FU_TgtSel=2,FU_Gap28,FU_Gap27) -> 0
A11: Model FD value/share (V_PS) and implied FD shares (M) | B11: =V_PS -> 0.01
A12: FD shares at value (M) = V_EQ / V_PS | B12: =IFERROR(V_EQ/V_PS,0) -> -925362.45
A14: Source inputs (Estimated)
A15: ATM: shares remaining (M) | B15: =ATM_Rem -> 12.270507
A16: ATM: issue price = SharePx x (1 - discount/fees) | B16: =SharePx*(1-FU_ATMd) -> 237.9538
A17: ATM discount + fees | B17: 0.02
A18: Customer prepayments: incremental beyond PrepayPct ($M) | B18: 1500 | C18: Q2 letter: >$9B prepayments in 2026; 70% of deals, 50-60% of capex
A19: Prepayment price concession (% of amount, PV cost) | B19: 0
A20: ABS / GPU-backed debt: LTV on GPU net book value at Q2'27 | B20: 0.5
A21: GPU net book value at Q2'27 ($M) | B21: =INDEX(NBV_H,1,14)+INDEX(NBV_B,1,14)+INDEX(NBV_N,1,14) -> 26559.023
A22: ABS capacity ($M) = LTV x GPU NBV, capped | B22: =MIN(FU_LTV*FU_NBV,FU_ABSCap) -> 5000
A23: ABS cap ($M) | B23: 5000
A24: ABS interest rate | B24: 0.09 | C24: memo: cost in WACC; no share dilution
A25: New converts: amount ($M) | B25: 3000
A26: Conversion premium | B26: 0.35
A27: Conversion price | B27: =SharePx*(1+FU_CVPrem) -> 327.7935
A29: Per-source effect if used ALONE at full size (value/share = (V_EQ + equity-like proceeds) / (shares + new shares)) | B29: Proceeds $M | C29: New shares M | D29: Value/share $ | E29: Change $/sh | F29: Dilution %
A30: ATM (all 12.27M sh) | B30: =FU_ATMsh*FU_ATMpx -> 2919.8138 | C30: =FU_ATMsh -> 12.270507 | D30: =(V_EQ+FU_ATMsh*FU_ATMpx)/(FU_N+FU_ATMsh) -> 0.0068447717 | E30: =D30-FU_V -> -0.0031552283 | F30: =IFERROR(C30/FU_N,0) -> -1.3260217e-05
A31: Customer prepayments | B31: =FU_PreAmt -> 1500 | C31: =0 -> 0 | D31: =FU_V-FU_PreAmt*FU_PreCost/FU_N -> 0.01 | E31: =D31-FU_V -> 0 | F31: =IFERROR(C31/FU_N,0) -> 0
A32: ABS / GPU-backed debt | B32: =FU_ABSMax -> 5000 | C32: =0 -> 0 | D32: =FU_V -> 0.01 | E32: =D32-FU_V -> 0 | F32: =IFERROR(C32/FU_N,0) -> 0
A33: New converts (if converted when value > conv. price) | B33: =FU_CVAmt -> 3000 | C33: =IF(FU_V>FU_CVPx,FU_CVAmt/FU_CVPx,0) -> 0 | D33: =IF(FU_V>FU_CVPx,(V_EQ+FU_CVAmt)/(FU_N+FU_CVAmt/FU_CVPx),FU_V) -> 0.01 | E33: =D33-FU_V -> 0 | F33: =IFERROR(C33/FU_N,0) -> 0
A35: Combined plan to fill the target: order prepayments -> ATM -> ABS -> converts
A36: Prepayments used | B36: =MIN(FU_PreAmt,FU_Tgt) -> 0
A37: ATM used ($M) | B37: =MIN(FU_ATMsh*FU_ATMpx,FU_Tgt-FU_P1) -> 0
A38: ABS used | B38: =MIN(FU_ABSMax,FU_Tgt-FU_P1-FU_P2) -> 0
A39: Converts used | B39: =MIN(FU_CVAmt,FU_Tgt-FU_P1-FU_P2-FU_P3) -> 0
A40: Unfunded remainder (needs equity plug / more sources) | B40: =FU_Tgt-FU_P1-FU_P2-FU_P3-FU_P4 -> 0
A41: New shares: ATM + converts (if converted) | B41: =IFERROR(FU_P2/FU_ATMpx,0)+IF(FU_V>FU_CVPx,FU_P4/FU_CVPx,0) -> 0
A42: Combined value/share | B42: =(V_EQ+FU_P2+IF(FU_V>FU_CVPx,FU_P4,0)-FU_P1*FU_PreCost)/(FU_N+FU_Sh) -> 0.01
A43: Change vs model value/share ($) | B43: =FU_VC-FU_V -> 0
A44: Dilution (% of FD shares) | B44: =IFERROR(FU_Sh/FU_N,0) -> 0
A45: Memo: ABS annual interest ($M) | B45: =FU_P3*FU_ABSr -> 0

Sheet Outputs
A1: Outputs - key metrics at valuation-date horizons
A2: Horizon quarter = last quarter end on/before EDATE(ValDate, months). LTM = 4 quarters ending at horizon. Per-share value rolled forward at Ke.
A4: Metric | B4: Valuation qtr | C4: +6 months | D4: +1 year | E4: +3 years
A5: Quarter index | B5: =MATCH(EDATE(ValDate,0),Q_End,1) -> 11 | C5: =MATCH(EDATE(ValDate,6),Q_End,1) -> 13 | D5: =MATCH(EDATE(ValDate,12),Q_End,1) -> 15 | E5: =MATCH(EDATE(ValDate,36),Q_End,1) -> 23
A6: Quarter | B6: =INDEX(Q_Lab,1,B5) -> Q3'26 | C6: =INDEX(Q_Lab,1,C5) -> Q1'27 | D6: =INDEX(Q_Lab,1,D5) -> Q3'27 | E6: =INDEX(Q_Lab,1,E5) -> Q3'29
A7: Months from ValDate | B7: 0 | C7: 6 | D7: 12 | E7: 36
A8: Revenue - quarter ($M) | B8: =INDEX(PL_Rev,1,B$5) -> 653.68337 | C8: =INDEX(PL_Rev,1,C$5) -> 1059.3883 | D8: =INDEX(PL_Rev,1,D$5) -> 2170.782 | E8: =INDEX(PL_Rev,1,E$5) -> 8123.4662
A9: Revenue - LTM ($M) | B9: =SUMPRODUCT(PL_Rev*(Q_Idx>B$5-4)*(Q_Idx<=B$5)) -> 1862.6834 | C9: =SUMPRODUCT(PL_Rev*(Q_Idx>C$5-4)*(Q_Idx<=C$5)) -> 3083.7967 | D9: =SUMPRODUCT(PL_Rev*(Q_Idx>D$5-4)*(Q_Idx<=D$5)) -> 5575.8715 | E9: =SUMPRODUCT(PL_Rev*(Q_Idx>E$5-4)*(Q_Idx<=E$5)) -> 27732.463
A10: Adj. EBITDA - quarter ($M) | B10: =INDEX(PL_EBITDA,1,B$5) -> 273.75168 | C10: =INDEX(PL_EBITDA,1,C$5) -> 547.36903 | D10: =INDEX(PL_EBITDA,1,D$5) -> 1159.8695 | E10: =INDEX(PL_EBITDA,1,E$5) -> 5460.4878
A11: Adj. EBITDA - LTM ($M) | B11: =SUMPRODUCT(PL_EBITDA*(Q_Idx>B$5-4)*(Q_Idx<=B$5)) -> 654.45168 | C11: =SUMPRODUCT(PL_EBITDA*(Q_Idx>C$5-4)*(Q_Idx<=C$5)) -> 1386.3889 | D11: =SUMPRODUCT(PL_EBITDA*(Q_Idx>D$5-4)*(Q_Idx<=D$5)) -> 2849.9514 | E11: =SUMPRODUCT(PL_EBITDA*(Q_Idx>E$5-4)*(Q_Idx<=E$5)) -> 18351.187
A12: EBIT - LTM ($M) | B12: =SUMPRODUCT(PL_EBIT*(Q_Idx>B$5-4)*(Q_Idx<=B$5)) -> -877.88226 | C12: =SUMPRODUCT(PL_EBIT*(Q_Idx>C$5-4)*(Q_Idx<=C$5)) -> -1069.6541 | D12: =SUMPRODUCT(PL_EBIT*(Q_Idx>D$5-4)*(Q_Idx<=D$5)) -> -1068.7157 | E12: =SUMPRODUCT(PL_EBIT*(Q_Idx>E$5-4)*(Q_Idx<=E$5)) -> 2247.9261
A13: Free cash flow - LTM ($M) | B13: =SUMPRODUCT(CF_FCF*(Q_Idx>B$5-4)*(Q_Idx<=B$5)) -> -2123.7999 | C13: =SUMPRODUCT(CF_FCF*(Q_Idx>C$5-4)*(Q_Idx<=C$5)) -> -12090.252 | D13: =SUMPRODUCT(CF_FCF*(Q_Idx>D$5-4)*(Q_Idx<=D$5)) -> -22445.528 | E13: =SUMPRODUCT(CF_FCF*(Q_Idx>E$5-4)*(Q_Idx<=E$5)) -> -24513.378
A14: Net debt ($M, model) | B14: =INDEX(CF_NetDebt,1,B$5) -> 2021.7601 | C14: =INDEX(CF_NetDebt,1,C$5) -> 9319.7963 | D14: =INDEX(CF_NetDebt,1,D$5) -> 22209.834 | E14: =INDEX(CF_NetDebt,1,E$5) -> 46068.497
A15: Diluted shares (M, at DilPx) | B15: =INDEX(Sh_Dil,1,B$5) -> 314.92525 | C15: =INDEX(Sh_Dil,1,C$5) -> 327.19575 | D15: =INDEX(Sh_Dil,1,D$5) -> 327.19575 | E15: =INDEX(Sh_Dil,1,E$5) -> 411.98313
A16: Active IT MW | B16: =INDEX(MW_Act,1,B$5) -> 173 | C16: =INDEX(MW_Act,1,C$5) -> 292.4 | D16: =INDEX(MW_Act,1,D$5) -> 545.1 | E16: =INDEX(MW_Act,1,E$5) -> 1875
A17: Energized IT MW (Capacity) | B17: =INDEX(MW_En,1,B$5) -> 207.5 | C17: =INDEX(MW_En,1,C$5) -> 416.4 | D17: =INDEX(MW_En,1,D$5) -> 684.5 | E17: =INDEX(MW_En,1,E$5) -> 1875
A18: Implied value per share - FD, rolled at Ke ($) | B18: =V_PS*(1+Ke)^(B$7/12) -> 0.01 | C18: =V_PS*(1+Ke)^(C$7/12) -> 0.010630146 | D18: =V_PS*(1+Ke)^(D$7/12) -> 0.0113 | E18: =V_PS*(1+Ke)^(E$7/12) -> 0.01442897
A19: Implied value per share - 308.69M-style basic ($) | B19: =V_PSB*(1+Ke)^(B$7/12) -> -29.976967 | C19: =V_PSB*(1+Ke)^(C$7/12) -> -31.865953 | D19: =V_PSB*(1+Ke)^(D$7/12) -> -33.873973 | E19: =V_PSB*(1+Ke)^(E$7/12) -> -43.253676
A21: Valuation summary
A22: DCF EV ($M) | B22: =V_EV -> -183.73714
A23: Market EV at SharePx ($M) | B23: =V_MKTEV -> 74654.719
A24: FD value / share at solved price ($) | B24: =V_PS -> 0.01
A25: 12-month PT ($) | B25: =V_PT -> 0
A26: Upside vs SharePx | B26: =V_UP -> -1
A27: Share price ($) | B27: =SharePx -> 242.81
A28: Off-B/S weight used | B28: =OffBSWt -> 0.5
A29: Scenario | B29: =CHOOSE(Scen,"BULL","BASE","BEAR") -> BASE
A32: Model vs consensus (Skeptic, Oct 2 2026) | B32: FY2026 | C32: FY2027 | D32: FY2028
A33: Revenue - model | B33: =SUMIF(Q_Yr,2026,PL_Rev) -> 2423.4083 | C33: =SUMIF(Q_Yr,2027,PL_Rev) -> 7621.7173 | D33: =SUMIF(Q_Yr,2028,PL_Rev) -> 19606.895
A34: Revenue - consensus | B34: =INDEX(Cons_Rev,1,3) -> 3340 | C34: =INDEX(Cons_Rev,1,4) -> 12300 | D34: =INDEX(Cons_Rev,1,5) -> 23000
A35: Revenue - model / consensus - 1 | B35: =IF(N(B34)=0,"n/a",B33/B34-1) -> -0.27442864 | C35: =IF(N(C34)=0,"n/a",C33/C34-1) -> -0.38034818 | D35: =IF(N(D34)=0,"n/a",D33/D34-1) -> -0.14752632
A36: Adj. EBITDA - model | B36: =SUMIF(Q_Yr,2026,PL_EBITDA) -> 968.51992 | C36: =SUMIF(Q_Yr,2027,PL_EBITDA) -> 4078.9726 | D36: =SUMIF(Q_Yr,2028,PL_EBITDA) -> 12202.26
A37: Adj. EBITDA - consensus | B37: =INDEX(Cons_EB,1,3) -> 1390 | C37: =INDEX(Cons_EB,1,4) -> 6730 | D37: =INDEX(Cons_EB,1,5) -> 13980
A38: Adj. EBITDA - model / consensus - 1 | B38: =IF(N(B37)=0,"n/a",B36/B37-1) -> -0.30322308 | C38: =IF(N(C37)=0,"n/a",C36/C37-1) -> -0.39391195 | D38: =IF(N(D37)=0,"n/a",D36/D37-1) -> -0.12716309
A39: Capex - model | B39: =SUMIF(Q_Yr,2026,Capex) -> 16850.342 | C39: =SUMIF(Q_Yr,2027,Capex) -> 32170.734 | D39: =SUMIF(Q_Yr,2028,Capex) -> 29456.038
A40: Capex - consensus | B40: =INDEX(Cons_Cx,1,3) -> 0 | C40: =INDEX(Cons_Cx,1,4) -> 29100 | D40: =INDEX(Cons_Cx,1,5) -> 0
A41: Capex - model / consensus - 1 | B41: =IF(N(B40)=0,"n/a",B39/B40-1) -> n/a | C41: =IF(N(C40)=0,"n/a",C39/C40-1) -> 0.10552352 | D41: =IF(N(D40)=0,"n/a",D39/D40-1) -> n/a
A43: MW sources at YE26 / YE27 (IT MW) | B43: Q4'26 | C43: Q4'27
A44: Energized - Capacity, IT-normalized (YE27 ~950 IT = PLACEHOLDER pending Capacity's Tue basis column; named 185/305/424 & 764/1,069/1,374 mixed basis + unseen) | B44: =INDEX(MW_En,1,12) -> 292.4 | C44: =INDEX(MW_En,1,16) -> 950
A45: Mgmt connected guide (800MW-1GW YE26; 1.8 GW YE27) | B45: =INDEX(MW_Gd,1,12) -> 900 | C45: =INDEX(MW_Gd,1,16) -> 1800
...

Sheet Checks
A1: Checks
A3: Check | B3: Model | C3: Target / tolerance | D3: Status | E3: Note
A4: CRITICAL: convert counted in BOTH shares and debt (solved price, chosen weight) | B4: =IF(DilMethod=1,SUMPRODUCT((((CVDebtBasis=1)*Valuation!$E$79:$E$90+(CVDebtBasis=2)*Valuation!$F$79:$F$90))),IF(DilMethod=2,SUMPRODUCT((V_PSolve>Valuation!$H$79:$H$90)*(((CVDebtBasis=1)*Valuation!$E$79:$E$90+(CVDebtBasis=2)*Valuation!$F$79:$F$90))),0))+V_CVDEBT-SUMPRODUCT((((CVDebtBasis=1)*Valuation!$E$79:$E$90+(CVDebtBasis=2)*Valuation!$F$79:$F$90))) -> 0 | C4: 0 | D4: =IF(ABS(B4)<0.5,"OK","DOUBLE COUNT") -> OK | E4: If-converted + debt-counted must equal total (CVDebtBasis: 1 original principal, 2 accreted); net-share (3) keeps principal as debt by design
A5: CRITICAL: same at SharePx (market EV) | B5: =IF(DilMethod=1,SUMPRODUCT((((CVDebtBasis=1)*Valuation!$E$79:$E$90+(CVDebtBasis=2)*Valuation!$F$79:$F$90))),IF(DilMethod=2,SUMPRODUCT((SharePx>Valuation!$H$79:$H$90)*(((CVDebtBasis=1)*Valuation!$E$79:$E$90+(CVDebtBasis=2)*Valuation!$F$79:$F$90))),0))+V_CVDmkt-SUMPRODUCT((((CVDebtBasis=1)*Valuation!$E$79:$E$90+(CVDebtBasis=2)*Valuation!$F$79:$F$90))) -> 0 | C5: 0 | D5: =IF(ABS(B5)<0.5,"OK","DOUBLE COUNT") -> OK
A6: Economic basic shares at Q3'26 (M) = 271.86 + 15.77 + 21.07 | B6: =INDEX(Sh_EconBasic,1,11) -> 308.69115 | C6: 308.69 | D6: =IF(ABS(B6-C6)<0.05,"OK","CHECK") -> OK
A7: Fully diluted at $242.81 EXCL. unsold ATM vs Filings CapStructure | B7: =V_FDmkt -> 369.22679 | C7: =FD_Filings -> 369.2 | D7: =IF(ABS(B7-C7)<2,"OK","CHECK") -> OK | E7: nebius_filings.xlsx CapStructure
A8: Fully diluted at $242.81 INCL. 12.27M ATM vs Filings | B8: =V_FDmkt+ATM_Rem -> 381.4973 | C8: =FD_FilingsATM -> 381.5 | D8: =IF(ABS(B8-C8)<2,"OK","CHECK") -> OK | E8: ATM is a funding source, not in today's count
A9: ITM convert shares at $242.81 (six ITM) | B9: =V_ITMsh -> 50.021939 | C9: =ITM_Sh_Chk -> 50.03 | D9: =IF(ABS(B9-C9)<0.5,"OK","CHECK") -> OK | E9: Steps at $324.65 / $313.46 / $183.22 / $180.31 / $138.75 / $51.45
A10: ITM convert principal at $242.81 ($M orig.) | B10: =V_ITMprin -> 7675 | C10: =ITM_Prin_Chk -> 7680 | D10: =IF(ABS(B10-C10)<15,"OK","CHECK") -> OK
A11: Market EV at $242.81 ($M), CapStructure basis vs Filings ~74.7B | B11: =V_MKTEV -> 74654.719 | C11: 74700 | D11: =IF(ABS(B11/C11-1)<0.01,"OK","CHECK") -> OK | E11: 6/30 balance + Aug notes + exchange; unrestricted cash only
A12: Dilution solve convergence |P15-P14| | B12: =V_CONV -> 0 | C12: 0.01 | D12: =IF(B12<C12,"OK","NOT CONVERGED") -> OK
A13: Microsoft implied TCV vs reported ($M) | B13: =MSFT_Chk -> 0 | C13: 0 | D13: =IF(ABS(B13)<5,"OK","CHECK") -> OK
A14: Quarters (pre-Bloom) Microsoft revenue exceeds ~$350M/qtr genset ceiling | B14: =SUMPRODUCT((MS_CeilChk>0)*(Q_Idx<IF(BloomOn=1,BloomIdx,99))) -> 0 | C14: 0 | D14: =IF(B14=0,"OK","CHECK") -> OK
A15: Q4 bridge: unseen MW vs Skeptic/Capacity 83-200 MW | B15: =BR_MW25 -> 92.646129 | C15: =UnseenChkHi -> 200 | D15: =BR_Chk -> OK - overlaps 83-200 MW
A16: History capex split = reported (sum abs diff) | B16: =SUMPRODUCT(ABS(N(+CapexChk))) -> 0 | C16: 0 | D16: =IF(B16<1,"OK","CHECK") -> OK
A17: Q2'26 book (a) share vs GPU Market 45% (40-46%) | B17: =INDEX(Book_A,1,10)/INDEX(AI_Model,1,10) -> 0.46063494 | C17: =MixA_Q2 -> 0.45 | D17: =IF(AND(ROUND(B17,2)>=0.4,ROUND(B17,2)<=0.46),"OK","CALIBRATE") -> OK
A18: Q2'26 book (b) share vs ~50% (44-57%) | B18: =INDEX(Book_B,1,10)/INDEX(AI_Model,1,10) -> 0.46986058 | C18: =MixB_Q2 -> 0.5 | D18: =IF(AND(B18>=0.44,B18<=0.57),"OK","CALIBRATE") -> OK
A19: Q2'26 book (c) share vs ~4% (1.3-9%) | B19: =INDEX(Book_C,1,10)/INDEX(AI_Model,1,10) -> 0.069504476 | C19: =MixC_Q2 -> 0.04 | D19: =IF(AND(B19>=0.013,B19<=0.09),"OK","CALIBRATE") -> OK
A20: Depreciation-yield flags (drop after chip availability) | B20: =SUM(DepYldFlag) -> 1 | C20: 0 | D20: =IF(B20=0,"OK","FLAG - review PIS dates") -> FLAG - review PIS dates | E20: Material weakness over depreciation start dates
A21: Q3'26 transfer into service | B21: =Q3TransChk -> PENDING (model 4,702) | D21: =B21 -> PENDING (model 4,702)
A22: Sites: named-site energized imports tie to Capacity file COMPANY row (sum abs diff) | B22: =SUMPRODUCT(ABS(CapTie)) -> 0 | C22: 0 | D22: =IF(B22<1,"OK","CHECK") -> OK
A23: Q2'26 tie: model AI cloud revenue vs actual $574.9M | B23: =INDEX(AI_Model,1,10) -> 574.9 | C23: =INDEX(H_AIRev,1,10) -> 574.9 | D23: =IF(ABS(B23/C23-1)<0.01,"OK","CHECK") -> OK | E23: Utilization calibrated
A24: Implied Q2'26 utilization (books b+c) | B24: =UtilQ2 -> 0.82509879 | C24: 40-100% | D24: =UtilFlag -> OK (40-100%) | E24: Flag (not forced) if outside 40-100%
A25: (a) Q2'26 revenue per GPU-hour of capacity (annualized AI rev / GPUs / 8,760) | B25: =INDEX(AI_Model,1,10)*4*1000000/INDEX(GPU_End,1,10)/8760 -> 2.9670688 | C25: =Chk_RevGPUhr -> 3.27 | D25: =IF(ABS(B25/C25-1)<=0.1,"OK","CHECK") -> OK | E25: +/-10% (GPU Market, Derived)
A26: (b) Q2'26 annualized AI rev per $ avg gross servers in service | B26: =INDEX(AI_Model,1,10)*4/AVERAGE(INDEX(H_SRV,1,9),INDEX(H_SRV,1,10)) -> 0.46501658 | C26: =Chk_RevSrv -> 0.46 | D26: =IF(ABS(B26/C26-1)<=0.1,"OK","CHECK") -> OK | E26: Filings, Derived
A27: (b3) Capacity server ceiling: Q2'26 GPUs x $45-60k (high end) vs $5.2B servers in service | B27: =INDEX(GPU_End,1,10)*Chk_SrvHi/1000000 -> 5308.5 | C27: =Chk_SrvCap -> 5197.7 | D27: =IF(B27<=C27,"OK: "&TEXT(INDEX(GPU_End,1,10)*Chk_SrvLo/1000000,"#,##0")&"-"&TEXT(B27,"#,##0")&" <= 5,198; implied $"&TEXT(C27*1000000/INDEX(GPU_End,1,10),"#,##0")&"/GPU","FLAG") -> FLAG | E27: Capacity, Estimated
A28: (b2) Modeled in-service GPU cost at 6/30 (GPUs x $/GPU) vs $5.2B servers | B28: =(INDEX(GPU_End_H,1,10)*GPUCost_H+INDEX(GPU_End_B,1,10)*GPUCost_B+INDEX(GPU_End_N,1,10)*GPUCost_N)/1000000 -> 4489.925 | C28: =Chk_SrvCap -> 5197.7 | D28: =IF(B28<=C28,"OK","FLAG: exceeds servers in service") -> OK
A29: (c) Q2'26 revenue per energized MW ($M/yr) | B29: =INDEX(AI_Model,1,10)*4/INDEX(MW_En,1,10) -> 13.292486 | C29: =Chk_RevEnMW -> 13 | D29: =IF(ABS(B29/C29-1)<=0.15,"OK","CHECK") -> OK | E29: ~$13M (2.30B / ~173 MW)
A30: Q2'26 contract (book a) IT MW as share of energized MW | B30: =INDEX(A_MW,1,10)/INDEX(MW_En,1,10) -> 0.58580925 | C30: info | D30: ="INFO" -> INFO | E30: Microsoft GPU use capped at Vineland energized IT MW (39 MW Q2'26) + Meta #1 48 MW (TCV/ACV-derived) vs 173 MW energized; v0.1 fix took Q2'26 utilization from 133% to ~92%
A31: Q2'26 energized MW (Capacity base, IT) | B31: =INDEX(MW_En,1,10) -> 173 | C31: 173 | D31: =IF(ABS(B31-C31)<3,"OK","CHECK") -> OK
A32: Q2'26 GPUs: model (Capacity 'GPUs deployed' ~80,416 + GPU anchor gap if GPUAnchorOn) | B32: =INDEX(GPU_End,1,10) -> 88475 | C32: =80416+GPUAnchorD -> 88475 | D32: =IF(ABS(B32/C32-1)<0.01,IF(GPUAnchorOn=1,"INFO: anchored to ~30k at 3/31/25 (+"&TEXT(GPUAnchorD,"#,##0")&" vs Capacity file); Q2 utilization "&TEXT(UtilQ2,"0.0%"),"OK"),"CHECK") -> INFO: anchored to ~30k at 3/31/25 (+8,059 vs Capacity file); Q2 utilization 82.5%
A33: Unexplained ARR residual at 6/30 (June run-rate basis; NOT unseen capacity) | B33: =ARR_Res -> 597.13511 | C33: =ARR_ResTeamLo&"-"&ARR_ResTeamHi -> 650-700 | D33: ="INFO: model "&TEXT(ARR_Res,"#,##0")&" = "&TEXT(ARR_ResMW_TLo,"0")&"-"&TEXT(ARR_ResMW_THi,"0")&" MW-eq at team $13.3-13.5M/MW (model June RR "&TEXT(ARR_RR,"#,##0")&" = $"&TEXT(ARR_RRMW,"0.0")&"M/MW); team-basis residual "&TEXT(ARR_ResTB_Lo,"#,##0")&"-"&TEXT(ARR_ResTB_Hi,"#,##0") -> INFO: model 597 = 44-45 MW-eq at team $13.3-13.5M/MW (model June RR 2,403 = $13.9M/MW); team-basis residual 665-699 | E33: Pending Filings on ARR scope / signed-not-billing
A34: Adj. EBITDA margin FY28 - model vs consensus (flag if > +5pp) | B34: =SUMIF(Q_Yr,2028,PL_EBITDA)/SUMIF(Q_Yr,2028,PL_Rev) -> 0.62234537 | C34: =MarginCons28 -> 0.60782609 | D34: =IF(B34-C34>0.05,"FLAG: model margin > consensus +5pp","OK") -> OK | E34: Skeptic consensus 13.98/23.0
A35: Adj. EBITDA margin FY30 - model vs peer ~62% (flag if > +8pp) | B35: =SUMIF(Q_Yr,2030,PL_EBITDA)/SUMIF(Q_Yr,2030,PL_Rev) -> 0.70212902 | C35: =MarginPeer -> 0.62 | D35: =IF(B35-C35>0.08,"FLAG: above peer +8pp - review opex/MW and revenue/MW","OK") -> FLAG: above peer +8pp - review opex/MW and revenue/MW | E35: CoreWeave ~62% placeholder
A36: FY30 margin sensitivity: PD + SG&A held at FY28 % of revenue (vs placeholder step-down) | B36: =SUMIF(Q_Yr,2030,PL_EBITDA)/SUMIF(Q_Yr,2030,PL_Rev)-(1-OpexHold)*((INDEX(PDpct,1,2028-FYBase)+INDEX(SGApct,1,2028-FYBase))-(INDEX(PDpct,1,2030-FYBase)+INDEX(SGApct,1,2030-FYBase))) -> 0.65212902 | C36: =MarginPeer -> 0.62 | D36: =IF(B36-C36>0.08,"FLAG: still above peer +8pp","INFO: within +8pp of peer") -> INFO: within +8pp of peer | E36: PD 8% + SG&A 10% (FY28) instead of 6% + 7% (FY30); toggle OpexHold=1 for full model effect (Sensitivity)
A37: FY30 opex per avg IT MW ($M/MW-yr: COR + PD + SG&A ex-SBC) | B37: =(SUMIF(Q_Yr,2030,PL_Rev)-SUMIF(Q_Yr,2030,PL_EBITDA))/(SUMIF(Q_Yr,2030,MW_Avg)/4) -> 5.6347815 | C37: info | D37: ="INFO: revenue/MW "&TEXT(SUMIF(Q_Yr,2030,PL_Rev)/(SUMIF(Q_Yr,2030,MW_Avg)/4),"0.0") -> INFO: revenue/MW 18.9
A38: FY26 capex vs company guide $20-25B (Aug 12 2026 call) | B38: =SUMIF(Q_Yr,2026,Capex) -> 16850.342 | C38: 20,000-25,000 | D38: =IF(AND(B38>=20000*0.9,B38<=25000*1.1),"OK (within guide +/-10%)","FLAG: outside guide") -> FLAG: outside guide | E38: Fact base: FY2026 capex guidance $20-25B (call transcript, CFO); GPULead calibration
A39: Bull DCF EV vs 3x base (STATIC, snap.py) | B39: =V_EVBullS -> 90449.136 | C39: =3*V_EVBaseS -> -551.21142 | D39: =IF(V_EVBaseS=0,"run snap.py",IF(B39>C39,"FLAG: bull EV > 3x base - review bull drivers","OK")) -> FLAG: bull EV > 3x base - review bull drivers | E39: Bull/base EVs from snapshot
A40: Q2'26 calibration scenario-invariant: utilization bull / bear minus base (STATIC) | B40: =MAX(ABS(V_UtBullS-V_UtBaseS),ABS(V_UtBearS-V_UtBaseS)) -> 0 | C40: 0 | D40: =IF(V_UtBaseS=0,"run snap.py",IF(B40<0.0005,"OK: all scenarios tie $574.9M at "&TEXT(V_UtBaseS,"0.0%"),"FLAG: history depends on scenario")) -> OK: all scenarios tie $574.9M at 82.5%
A41: Implied blended realization vs OD list, Q2'26 books (b)+(c) (billed GPU-hours at Q2 avg list) vs GPU Market 0.72-0.80 | B41: =(INDEX(Book_B,1,LastHist)+INDEX(Book_C,1,LastHist))*1000000/((INDEX(NCA_H,1,LastHist)*ODq_H+INDEX(NCA_B,1,LastHist)*ODq_B+INDEX(NCA_N,1,LastHist)*ODq_N)*INDEX(Q_Hrs,1,LastHist)*UtilQ2) -> 0.74385588 | C41: 0.72-0.80 | D41: =IF(AND(B41>=0.72,B41<=0.8),"OK: within GPU Market range",IF(B41<0.72,"INFO: below range","FLAG: above range")) -> OK: within GPU Market range | E41: Reserved RealRes_B 0.72 x ResSh + on-demand/spot mix
...

Sheet Inputs
A1: Inputs & Assumptions (scenario-driven)
A2: Blue = input. Fill: orange = PLACEHOLDER (no source yet), yellow = Estimated/Consensus, none = Reported/Derived. Live column = CHOOSE(Scenario, Bull, Base, Bear). Owners fill/replace their cells; never overwrite formulas.
A4: Scenario selector (1 = Bull, 2 = Base, 3 = Bear) | D4: 2 | E4: =CHOOSE(Scen,"BULL","BASE","BEAR") -> BASE
A6: Scalar input | B6: Unit | C6: Bull | D6: Base | E6: Bear | F6: LIVE | J6: Owner | K6: Status | L6: Source / method
A7: General
A8: Valuation date | B8: date | C8: — | D8: 46299 | E8: — | F8: =D8 -> 46299 | J8: Modeling | K8: Input | L8: Pitch valuation date; drives DCF discounting and Outputs horizons
A9: Last actual quarter index (10 = Q2'26) | B9: # | C9: — | D9: 10 | E9: — | F9: =D9 -> 10 | J9: Modeling | K9: Input | L9: Roll forward to 11 when Q3'26 is reported
A10: Fiscal-year base (year before first model year) | B10: yr | C10: — | D10: 2023 | E10: — | F10: =D10 -> 2023 | J10: Modeling | K10: Input | L10: Structural: annual-input column = FY - FYBase
A11: Current share price (NBIS) | B11: $/sh | C11: — | D11: 242.81 | E11: — | F11: =D11 -> 242.81 | J11: Skeptic | K11: Reported | L11: Oct 2 2026 close per Skeptic (/workspace/nebius/skeptic/01_priced_in.xlsx), medium confidence; used for convert ITM test, TSM, equity raises
A12: MW block that drives revenue (1 contracted, 2 energized est. [Capacity, default], 3 mgmt-connected guide, 4 Capacity proposed path [scenario, not base until Tuesday file]) | B12: # | C12: — | D12: 2 | E12: — | F12: =D12 -> 2 | J12: Modeling | K12: Input | L12: Default = Capacity energized base (estimated live IT load); guided path kept as comparison only
A13: Energized (live IT load) -> billing lag, MW source 2 | B13: qtrs | C13: 1 | D13: 1 | E13: 1 | F13: =CHOOSE(Scen,C13,D13,E13) -> 1 | J13: Capacity | K13: Estimated | L13: Base 1 qtr. 2 qtrs = STRESS case (Sensitivity snapshot), not the bear default
A14: IT capex method (1 = GPUs x $/GPU, 2 = flat $M per IT MW, 3 = site path: new energized IT MW x per-site $/MW by ownership & generation [default]) | B14: # | C14: — | D14: 3 | E14: — | F14: =D14 -> 3 | J14: Modeling | K14: Input | L14: Method 3 = path-consistent per Capacity gpu_mw_capex.xlsx
A15: Owned site all-in capex per IT MW - GB200 | B15: $M/MW | C15: — | D15: 42 | E15: — | F15: =D15 -> 42 | J15: Capacity | K15: Estimated | L15: /workspace/nebius/capacity/gpu_mw_capex.xlsx CapexPerMW (incl ~$10-12.5M shell+power)
A16: Owned site all-in capex per IT MW - GB300 | B16: $M/MW | C16: — | D16: 53 | E16: — | F16: =D16 -> 53 | J16: Capacity | K16: Estimated | L16: as above
A17: Owned site all-in capex per IT MW - Vera Rubin (LOW-MEDIUM confidence) | B17: $M/MW | C17: 53 | D17: 56 | E17: 59 | F17: =CHOOSE(Scen,C17,D17,E17) -> 56 | J17: Capacity | K17: Estimated | L17: v0.7: $53-59M (base 56) = leased $41-48.5M + shell/power; was $43M. Capacity reconciles networking Tuesday
A18: Owned site capex per IT MW - Hopper/B200/B300 (GB200 proxy) | B18: $M/MW | C18: — | D18: 42 | E18: — | F18: =D18 -> 42 | J18: Capacity | K18: Estimated | L18: proxy
A19: Leased/colo capex per IT MW - GB200 (and Hopper/B200/B300 stand-ins); IT only, rent in opex | B19: $M/MW | C19: — | D19: 30 | E19: — | F19: =D19 -> 30 | J19: Capacity | K19: Estimated | L19: gpu_mw_capex.xlsx (Capacity), medium confidence
A20: Leased/colo capex per IT MW - GB300 (Vineland, most leased builds) | B20: $M/MW | C20: — | D20: 41 | E20: — | F20: =D20 -> 41 | J20: Capacity | K20: Estimated | L20: gpu_mw_capex.xlsx (Capacity), medium confidence
A21: Leased/colo capex per IT MW - Vera Rubin (LOW-MEDIUM confidence) | B21: $M/MW | C21: 41 | D21: 41 | E21: 48.5 | F21: =CHOOSE(Scen,C21,D21,E21) -> 41 | J21: Capacity/Skeptic | K21: Estimated | L21: v0.7: base $41M flat to GB300 (SemiAnalysis TCO 1.51-1.56x/GPU-hr at 320 vs 491 GPUs/IT MW -> ~0.98-1.02x GB300 per MW; Capacity at Morgan Stanley rack cost: leased $42-48M); bull $41M; bear $48.5M (Skeptic $45-52M midpoint: 0.65x racks/MW x MS 1.68-1.95x rack cost). $32M = OUTER-BULL sensitivity only (soft: ~$6.0M rack ~1.2x GB300; networking $3.6M looks low vs GB300 $6.1M - Capacity reconciles Tuesday)
A22: v0.2 fix: GPU fleet MW-ratio only in forecast + capex follows DRIVER MW (1 = on) | B22: 0/1 | C22: — | D22: 1 | E22: — | F22: =D22 -> 1 | J22: Modeling | K22: Input | L22: Off = v0.1 behaviour (history fleet scaled by selected MW block; capex followed energized path only)
A23: Terminal basis: 2 = EXCLUDE BOTH Q4'30-onward spend for MW billing after Q4'30 and that MW (terminal = Q4'30 exit run-rate x 4) [default, conservative]; 1 = INCLUDE BOTH (memo only: run-rate scaled x(MW Q4'30 + MW billing Q1'31)/MW Q4'30, unsourced ~1.2x step-up); 0 = v0.1 (FY2030 x (1+TG), Q4'30 spend charged) | B23: 0/1/2 | C23: — | D23: 2 | E23: — | F23: =D23 -> 2 | J23: Modeling | K23: Input | L23: v0.2 decision (Oct 4): do not credit unbilled capacity on an unsourced step-up; 'include both' EV shown as memo row in Valuation
A24: Terminal value floor: max(Gordon/blend, run-off value of existing fleet with no reinvestment) (1 = on) | B24: 0/1 | C24: — | D24: 1 | E24: — | F24: =D24 -> 1 | J24: Modeling | K24: Input | L24: Operator would stop replacing GPUs at negative NPV; TV cannot be below run-off (>= 0)
A25: Owned-site O&M (facility staff, maintenance, insurance, property tax) | B25: $M/IT MW-yr | C25: — | D25: 0.75 | E25: — | F25: =D25 -> 0.75 | J25: Capacity | K25: Placeholder | L25: Leased sites carry this inside rent; owned sites had none in v0.1. Placeholder pending Capacity
A26: H2'26 repricing: Q2 list avg (H100 $2.95->$3.85 Jun-26), legacy reserved book renews +30% at 50%/12 months, new GPUs at current list (1 = on) | B26: 0/1 | C26: — | D26: 1 | E26: — | F26: =D26 -> 1 | J26: GPU Market | K26: Input | L26: Off = v0.1 (Q2 at Jun list; reserved = lagged list)
A27: Reserved renewal repricing vs expiring contract | B27: % | C27: — | D27: 0.3 | E27: — | F27: =D27 -> 0.3 | J27: Filings | K27: Reported | L27: Q2'26 letter: >30% repricing on renewals
A28: H100 on-demand list - Q2'26 average | B28: $/GPU-hr | C28: — | D28: =(2*2.95+3.85)/3 -> 3.25 | E28: — | F28: =D28 -> 3.25 | J28: GPU Market | K28: Derived | L28: Archived nebius.com/prices: $2.95 Apr-May -> $3.85 from Jun 2026 (Reported pages); Q2 avg derived
A29: Team June run-rate per MW - low | B29: $M/MW-yr | C29: — | D29: 13.3 | E29: — | F29: =D29 -> 13.3 | J29: Modeling | K29: Estimated | L29: June list + renewals signed by 6/30
A30: Team June run-rate per MW - high | B30: $M/MW-yr | C30: — | D30: 13.5 | E30: — | F30: =D30 -> 13.5 | J30: Modeling | K30: Estimated
A31: Team estimate: unexplained ARR residual - low | B31: $M | C31: — | D31: 650 | E31: — | F31: =D31 -> 650 | J31: Modeling | K31: Estimated | L31: ~45-50 MW
A32: Team estimate: unexplained ARR residual - high | B32: $M | C32: — | D32: 700 | E32: — | F32: =D32 -> 700 | J32: Modeling | K32: Estimated
A33: Consensus FY28 adj. EBITDA margin (13.98 / 23.0) | B33: % | C33: — | D33: =13.98/23 -> 0.60782609 | E33: — | F33: =D33 -> 0.60782609 | J33: Skeptic | K33: Estimated | L33: 01_priced_in.xlsx
A34: Peer adj. EBITDA margin reference (CoreWeave ~62%) | B34: % | C34: — | D34: 0.62 | E34: — | F34: =D34 -> 0.62 | J34: GPU Market | K34: Placeholder | L34: pending GPU Market comps
A35: Cap Microsoft GPU consumption at Vineland energized IT MW (Capacity) (1 = on) | B35: 0/1 | C35: — | D35: 1 | E35: — | F35: =D35 -> 1 | J35: Modeling | K35: Input | L35: Fix for Q2'26 utilization: MSFT delivered-tranche MW (53 MW) exceeded Vineland energized (39 MW / 19,157 GPUs)
A36: GPU end-of-life replacement capex in forecast (1 = on) | B36: 0/1 | C36: — | D36: 1 | E36: — | F36: =D36 -> 1 | J36: Modeling | K36: Input | L36: Cohort reaching GPU life is replaced at original cost (fleet persists in Capacity file)
A37: History MW basis: 1 = Capacity named-site (173 MW Q2'26) [default]; 2 = company-implied (~190 MW, ~$12M rev/installed MW) applied to history AND forward path (+uplift); 3 = MISMATCH test: history at 190, forward on 173 path | B37: # | C37: — | D37: 1 | E37: — | F37: =D37 -> 1 | J37: Capacity/Skeptic | K37: Input | L37: Revenue/MW in history and the forward MW path must use the same basis (2); 3 only quantifies Skeptic's ~11% claim
A38: Company-implied installed MW at Q2'26 (Q2 letter ~$12M revenue per installed MW) | B38: MW | C38: — | D38: 190 | E38: — | F38: =D38 -> 190 | J38: Filings | K38: Derived | L38: ~$2.3B annualized / ~$12M per MW
A39: AIB CLT1 colocation rent (12-yr), per IT MW-yr | B39: $M/IT MW-yr | C39: — | D39: 2.2 | E39: — | F39: =D39 -> 2.2 | J39: Capacity | K39: Estimated | L39: CLT1-sourced ~$2.2M per MW-yr (Capacity); applied via differential vs generic leased rent (RentMW x PUE)
A40: Nebius prepayment to AIB to fund CLT1 build (outflow Q4'26-Q2'27, equal thirds) | B40: $M | C40: — | D40: 0 | E40: — | F40: =D40 -> 0 | J40: Filings | K40: Placeholder | L40: Amount undisclosed (AIB 8-K Sep 30 2026); sensitivity $250M / $500M; liquidity only
A41: Inferize acquisition cash outflow Q4'26 (1 = on) | B41: 0/1 | C41: — | D41: 0 | E41: — | F41: =D41 -> 0 | J41: Filings | K41: Placeholder | L41: 6-K Oct 1 2026: terms undisclosed; PRESS-REPORTED $100-150M (unconfirmed)
A42: Inferize purchase price (press-reported, unconfirmed) | B42: $M | C42: — | D42: 130 | E42: — | F42: =D42 -> 130 | J42: Filings | K42: Placeholder | L42: Press $100-150M; liquidity only
...

Sheet Timeline
A1: Timeline (one column per quarter, Q1'24-Q4'30)
A3: Quarter | F3: Q1'24 | G3: Q2'24 | H3: Q3'24 | I3: Q4'24 | J3: Q1'25 | K3: Q2'25 | L3: Q3'25 | M3: Q4'25 | N3: Q1'26 | O3: Q2'26 | P3: Q3'26 | Q3: Q4'26 | R3: Q1'27 | S3: Q2'27 | T3: Q3'27 | U3: Q4'27 | V3: Q1'28 | W3: Q2'28 | X3: Q3'28 | Y3: Q4'28 | Z3: Q1'29 | AA3: Q2'29 | AB3: Q3'29 | AC3: Q4'29 | AD3: Q1'30 | AE3: Q2'30 | AF3: Q3'30 | AG3: Q4'30
A4: Period end | E4: 45291 | F4: 45382 | G4: 45473 | H4: 45565 | I4: 45657 | J4: 45747 | K4: 45838 | L4: 45930 | M4: 46022 | N4: 46112 | O4: 46203 | P4: 46295 | Q4: 46387 | R4: 46477 | S4: 46568 | T4: 46660 | U4: 46752 | V4: 46843 | W4: 46934 | X4: 47026 | Y4: 47118 | Z4: 47208 | AA4: 47299 | AB4: 47391 | AC4: 47483 | AD4: 47573 | AE4: 47664 | AF4: 47756 | AG4: 47848
A5: Index | E5: 0 | F5: 1 | G5: 2 | H5: 3 | I5: 4 | J5: 5 | K5: 6 | L5: 7 | M5: 8 | N5: 9 | O5: 10 | P5: 11 | Q5: 12 | R5: 13 | S5: 14 | T5: 15 | U5: 16 | V5: 17 | W5: 18 | X5: 19 | Y5: 20 | Z5: 21 | AA5: 22 | AB5: 23 | AC5: 24 | AD5: 25 | AE5: 26 | AF5: 27 | AG5: 28
A6: A/F | F6: =IF(F5<=LastHist,"A","F") -> A | G6: =IF(G5<=LastHist,"A","F") -> A | H6: =IF(H5<=LastHist,"A","F") -> A | I6: =IF(I5<=LastHist,"A","F") -> A | J6: =IF(J5<=LastHist,"A","F") -> A | K6: =IF(K5<=LastHist,"A","F") -> A | L6: =IF(L5<=LastHist,"A","F") -> A | M6: =IF(M5<=LastHist,"A","F") -> A | ... AG6: =IF(AG5<=LastHist,"A","F") -> F
A7: Fiscal year | F7: =YEAR(F4) -> 2024 | G7: =YEAR(G4) -> 2024 | H7: =YEAR(H4) -> 2024 | I7: =YEAR(I4) -> 2024 | J7: =YEAR(J4) -> 2025 | K7: =YEAR(K4) -> 2025 | L7: =YEAR(L4) -> 2025 | M7: =YEAR(M4) -> 2025 | ... AG7: =YEAR(AG4) -> 2030
A8: Days | F8: =F4-E4 -> 91 | G8: =G4-F4 -> 91 | H8: =H4-G4 -> 92 | I8: =I4-H4 -> 92 | J8: =J4-I4 -> 90 | K8: =K4-J4 -> 91 | L8: =L4-K4 -> 92 | M8: =M4-L4 -> 92 | ... AG8: =AG4-AF4 -> 92
A9: Hours | F9: =F8*24 -> 2184 | G9: =G8*24 -> 2184 | H9: =H8*24 -> 2208 | I9: =I8*24 -> 2208 | J9: =J8*24 -> 2160 | K9: =K8*24 -> 2184 | L9: =L8*24 -> 2208 | M9: =M8*24 -> 2208 | ... AG9: =AG8*24 -> 2208

Sheet Hist
A1: Historical inputs Q1'24-Q2'26 with Reported / Derived / Estimated / Not disclosed tags
A2: Each metric = 5 rows: value as disclosed | tag | best estimate (numeric) | method/source | VALUE USED (= value if disclosed, else best estimate). No silent gaps: every quarter carries a tag. Other tabs link to the VALUE USED row only.
A3: Metric | B3: Unit | C3: Owner | D3: Notes | F3: Q1'24 | G3: Q2'24 | H3: Q3'24 | I3: Q4'24 | J3: Q1'25 | K3: Q2'25 | L3: Q3'25 | M3: Q4'25 | N3: Q1'26 | O3: Q2'26
F4: 45382 | G4: 45473 | H4: 45565 | I4: 45657 | J4: 45747 | K4: 45838 | L4: 45930 | M4: 46022 | N4: 46112 | O4: 46203
A6: Group revenue | B6: $M | C6: Filings | D6: Continuing ops. Q1'24 figure is on the pre-restatement basis (Q1'25 PR) - flag. | F6: 11.4 | G6: 14.5 | H6: 32.1 | I6: 35.2 | J6: 50.9 | K6: 105.1 | L6: 146.1 | M6: 227.7 | N6: 399 | O6: 582.3
A7: tag | F7: Reported | G7: Reported | H7: Reported | I7: Reported | J7: Reported | K7: Reported | L7: Reported | M7: Reported | N7: Reported | O7: Reported
A8: best estimate
A9: method / source | F9: Q1'25 6-K PR comparatives (pre-Toloka-deconsolidation basis) | G9: Q2'25 6-K PR comparative | H9: Q3'25 6-K PR comparative (restated) | I9: Q4'25 6-K PR comparative | J9: Q1'26 6-K PR comparative (restated) | K9: Q2'26 6-K PR comparative | L9: Q3'25 6-K PR | M9: Q4'25 6-K PR | N9: Q1'26 6-K PR | O9: Q2'26 6-K PR (acc. 0001104659-26-094568)
A10: VALUE USED | F10: =IF(F7="Not disclosed",F8,F6) -> 11.4 | G10: =IF(G7="Not disclosed",G8,G6) -> 14.5 | H10: =IF(H7="Not disclosed",H8,H6) -> 32.1 | I10: =IF(I7="Not disclosed",I8,I6) -> 35.2 | J10: =IF(J7="Not disclosed",J8,J6) -> 50.9 | K10: =IF(K7="Not disclosed",K8,K6) -> 105.1 | L10: =IF(L7="Not disclosed",L8,L6) -> 146.1 | M10: =IF(M7="Not disclosed",M8,M6) -> 227.7 | ... O10: =IF(O7="Not disclosed",O8,O6) -> 582.3
A12: Nebius AI cloud revenue | B12: $M | C12: Filings | D12: Segment disclosure; earlier quarters derived from YoY growth or estimated as % of group | F12: n.d. | G12: n.d. | H12: n.d. | I12: n.d. | J12: 41.4 | K12: 93.6 | L12: n.d. | M12: 214.2 | N12: 389.7 | O12: 574.9
A13: tag | F13: Not disclosed | G13: Not disclosed | H13: Not disclosed | I13: Not disclosed | J13: Derived | K13: Derived | L13: Not disclosed | M13: Reported | N13: Reported | O13: Reported
A14: best estimate | F14: 10.3 | G14: 13.1 | H14: 28.9 | I14: 31.7 | L14: 138.8
A15: method / source | F15: Est = 90% of group revenue (pre-2025 mix; Avride/TripleTen remainder) | G15: Est = 90% of group revenue (pre-2025 mix; Avride/TripleTen remainder) | H15: Est = 90% of group revenue (pre-2025 mix; Avride/TripleTen remainder) | I15: Est = 90% of group revenue (pre-2025 mix; Avride/TripleTen remainder) | J15: Derived: Q1'26 $389.7M / (1+841%) | K15: Derived: Q2'26 $574.9M / (1+514%) | L15: Est = 95% of group revenue | M15: Q4'25 letter | N15: Q1'26 letter | O15: Q2'26 letter
A16: VALUE USED | F16: =IF(F13="Not disclosed",F14,F12) -> 10.3 | G16: =IF(G13="Not disclosed",G14,G12) -> 13.1 | H16: =IF(H13="Not disclosed",H14,H12) -> 28.9 | I16: =IF(I13="Not disclosed",I14,I12) -> 31.7 | J16: =IF(J13="Not disclosed",J14,J12) -> 41.4 | K16: =IF(K13="Not disclosed",K14,K12) -> 93.6 | L16: =IF(L13="Not disclosed",L14,L12) -> 138.8 | M16: =IF(M13="Not disclosed",M14,M12) -> 214.2 | ... O16: =IF(O13="Not disclosed",O14,O12) -> 574.9
A18: ARR (last-month AI cloud revenue x 12) | B18: $M | C18: Filings | D18: Mgmt definition; Q2'25/Q1'25 derived from stated YoY growth | F18: n.d. | G18: n.d. | H18: n.d. | I18: 90 | J18: 248 | K18: 430 | L18: 551 | M18: 1250 | N18: 1920 | O18: 3000
