Workbook

Sheet Cover
A1: Nebius (NBIS) driver-based model
A2: VERSION v0.7b – PROVISIONAL (debug & fix of v0.7)
A3: Build date: 2026-10-04. v0.3 base approved (terminal excludes Q4'30 spend for post-horizon MW and that MW; GPU capex lead 3 qtrs vs billing; history scenario-invariant; bear replacement at bear price path; bull Blackwell 6.25% cut after Rubin + next-gen -1.7%/yr).
A4: v0.7b changes (each a Bridge step): capitalised interest out of UFCF tax/terminal D&A; owned-site opex $2.25M/IT MW-yr all-in (no rent); data hall $12.5M/IT MW split 30% shell 20y / 70% power 10y; retired GPUs 15% after-tax residual (bear 0%); Capacity v2 MW (YE26 ~302 / YE27 ~1,082 IT MW); GB300 capex from rack price 491/72 x $4.5M + $6.1M network = $36.8M leased / $49.3M owned; converts in debt at carrying value (Note 12); Rubin capex v2 $41.1M leased (34.3/49.2) / $52.6M owned (45.8/60.7); lease prepayments $1.6M per new leased IT MW; GB300 2027+ new-deal price $16M/IT MW from contracts (bull mix-shift $18M, bear $14.5M; $22M IT / $26.4M gross kept as sensitivities); new prepayments at Q2'26 pace $1.2B/qtr through Q4'28 (guidance case $4.5B H2'26 = sensitivity); bear: 25% of deferred revenue treated as debt-like (PLACEHOLDER - refundable amount not disclosed). Payback table rebuilt (owned rows no rent; IRR/NPV with residual, after tax, incl. corporate opex).
A5: Key outputs (live, current scenario)
A6: Scenario | B6: =CHOOSE(Scen,"BULL","BASE","BEAR") -> BASE
A7: DCF EV ($M) | B7: =V_EV -> 7854.5901
A8: FD value / share ($) | B8: =V_PS -> 0.01
A9: 12-month PT ($) | B9: =V_PT -> 2.2868836
A10: First quarter liquidity < 0 | B10: =Liq_NegQ -> Q3'27
A11: Market EV ($M) | B11: =V_MKTEV -> 74654.719
A13: Notes - open items
A14: OPEN: FY26 capex below the $20-25B guide (Aug 12 2026 call): v0.3 $18.1B (~$1.9B short); v0.4 split lead $16.7B (~$3.3B short); possible early 2027 shell/power or deposits not in the path. Check: Checks 'FY26 capex vs company guide'. | B14: Owner: Filings / Capacity
A15: OPEN: liquidity - the 2027 funding plan (ATM 12.27M sh + 2 x $6.4B converts) was sized on Capacity v1 and no longer closes the FY27 gap: YE27 liquidity -$5.0B (base, Q2-pace prepayments), -$3.3B (guidance-case prepayments); first negative quarter Q3'27 / Q4'27. | B15: Owner: Capacity
A16: OPEN: billing lag - model uses EnLag 1 qtr for all sites: billing/energized IT MW 72% YE26 (217/302), 75% YE27 (813/1,082) vs Capacity v2 85% (258/302) / 79% (853/1,082); capex at energization. Rubin $18M/IT MW = $6.42/GPU-hr at 320 GPUs/MW vs GB300 $16M = $3.72 at 491 (1.73x per GPU-hr). | B16: Owner: GPU Market
A17: OPEN: AIB CLT1 prepayment (undisclosed; default $0) and Inferize price (press $100-150M, toggle off). | B17: Owner: Filings
A18: OPEN: Vineland shutdown default OFF (VinShutSel 0); scenarios/weights are Capacity judgment (prob-weighted Q4'26 loss ~$68M at $14.5M/IT MW-yr vs Capacity ~$67M); SLA credits undisclosed; genset power saving not credited. | B18: Owner: Capacity
A19: OPEN: Capacity proposed MW path is a scenario only (MWSel 4) until Capacity's Tuesday file; new-deal $/MW basis (IT vs gross) medium-low confidence; short-term share 10% is an estimate. | B19: Owner: Capacity / Filings
A20: OPEN: ARR scope / whether $3.0B ARR includes signed-not-billing tranches; unexplained ARR residual ~$0.6B shown as a line, not plugged. | B20: Owner: Filings
A21: OPEN: YE27 ~950 MW IT normalization is a placeholder pending Capacity's basis column. | B21: Owner: Capacity
A22: OPEN: Q3'26 transfer into service (model $4,702M) pending Q3 filing; depreciation start dates (material weakness) flagged. | B22: Owner: Filings
A23: FLAGS: base equity value pre-funding ~0 (DCF EV $7.9B < net debt incl. converts at carrying); PT driven by post-funding per-share; bull EV >> base (bull = $18M ND, Rubin capex bull); bear EV < 0 (equity floored at 0); FY26 capex $17.6B below $20-25B guide; share issuance need ~98M (base) / ~202M (bear) vs ~82M authority (INFO; no cap applied). See Checks. | B23: Owner: Modeling / GPU Market

Sheet README
A1: Nebius (NBIS) driver model - README
A3: Save path: /workspace/nebius/model/nebius_model.xlsx. Quarterly Q1'24-Q2'26 actuals (Hist, tagged Reported/Derived/Estimated/Not disclosed + best estimate + source), Q3'26-Q4'30 forecast, FY roll-ups AI:AO.
A4: Scenario: Inputs!D4 (1 Bull / 2 Base / 3 Bear). Blue = input; orange = placeholder; yellow = estimated/consensus; black = formula.
A5: Flow: Inputs -> Sites (contracted / energized [Capacity file] / mgmt-connected; MWSel; BillLag; PUE basis) -> Pricing -> Contracts (tranches, power ceiling, Q4 bridge) -> Revenue (3 books) -> Capex_DA (vintage cohorts, PISLag, impairment, cap. interest, dep-yield) -> Financing -> PnL -> CashFlow -> Shares -> Valuation (DCF, dilution solve, EV bridge, EV/MW) -> KPIs / Outputs / Sensitivity / Checks.
A6: Circularity: no Excel iterative calc needed. Valuation solves value/share by 15 unrolled fixed-point steps; DilPxMode 1 = SharePx for quarterly dilution.
A7: Converts: DilMethod 1 if-converted all / 2 ITM only (default; step dilution at conversion prices) / 3 net-share. Converted principal is removed from debt (Checks row 1).
A8: Static snapshot tables on Outputs / Sensitivity / Valuation memo rows / Checks (bull 3x, scenario-invariance) come from LibreOffice recalcs in snap.py; re-run snap.py after changing inputs.

Sheet Bridge
A1: EV bridge v0.1 -> v0.3 -> v0.4 (STATIC, filled by snap.py)
A2: Base scenario. Each row = cumulative settings recomputed in the CURRENT model (bug fixes such as the renewal-formula bracket and scenario-invariant history are in every row). $B and $/share are FD value/share.
A4: Step | B4: DCF EV $B | C4: Change $B | D4: FD $/share | E4: Change $/sh | F4: 12m PT $ | G4: FY26 rev $M | H4: FY27 rev $M | I4: FY28 rev $M | J4: FY27 EBITDA $M | K4: YE27 liquidity $M | L4: First neg. qtr
A5: v0.1 (as reported) | B5: 41.053548 | D5: 103.5364 | F5: 116.99613 | G5: 2400.637 | H5: 8242.0189 | I5: 22266.612 | J5: 4575.8582 | K5: -4456.7617 | L5: Q4'27
A6: + fleet ratio forecast-only / capex on driver MW (FixMgmt) | B6: 46.917572 | C6: 5.8640242 | D6: 121.61057 | E6: 18.074176 | F6: 137.41995 | G6: 2400.637 | H6: 8242.0189 | I6: 22266.612 | J6: 4606.0461 | K6: -4408.0848 | L6: Q4'27
A7: + terminal on Q4'30 exit incl. Q1'31 MW (include both) | B7: 100.18581 | C7: 53.268235 | D7: 270.29726 | E7: 148.68669 | F7: 305.43591 | G7: 2400.637 | H7: 8242.0189 | I7: 22266.612 | J7: 4606.0461 | K7: -4408.0848 | L7: Q4'27
A8: + TV run-off floor | B8: 100.18581 | C8: 0 | D8: 270.29726 | E8: 0 | F8: 305.43591 | G8: 2400.637 | H8: 8242.0189 | I8: 22266.612 | J8: 4606.0461 | K8: -4408.0848 | L8: Q4'27
A9: + owned-site O&M | B9: 89.065186 | C9: -11.12062 | D9: 240.34647 | E9: -29.950795 | F9: 271.59151 | G9: 2400.637 | H9: 8242.0189 | I9: 22266.612 | J9: 4517.4726 | K9: -4518.475 | L9: Q4'27
A10: + H2'26 repricing (= v0.2) | B10: 99.881943 | C10: 10.816757 | D10: 269.45258 | E10: 29.106113 | F10: 304.48142 | G10: 2425.3295 | H10: 8517.5153 | I10: 22648.736 | J10: 4713.075 | K10: -4310.0666 | L10: Q4'27
A11: + exclude both Q4'30 spend & Q1'31 MW | B11: 86.363741 | C11: -13.518202 | D11: 233.0828 | E11: -36.369776 | F11: 263.38357 | G11: 2425.3295 | H11: 8517.5153 | I11: 22648.736 | J11: 4713.075 | K11: -4310.0666 | L11: Q4'27
A12: + GPU capex lead 3 qtrs (= v0.3) | B12: 94.115788 | C12: 7.7520471 | D12: 248.1935 | E12: 15.110692 | F12: 280.45865 | G12: 2425.3295 | H12: 8517.5153 | I12: 22648.736 | J12: 4713.075 | K12: -7264.9716 | L12: Q2'27
A13: + split capex lead: shell/power 3, GPUs 2 qtrs | B13: 87.921392 | C13: -6.1943968 | D13: 233.70836 | E13: -14.48514 | F13: 264.09044 | G13: 2425.3295 | H13: 8517.5153 | I13: 22648.736 | J13: 4713.075 | K13: -7160.9335 | L13: Q3'27
A14: + price path: post-Rubin cut 22% + -6%/yr from year 2 | B14: 94.973087 | C14: 7.0516956 | D14: 252.68045 | E14: 18.972094 | F14: 285.52891 | G14: 2425.3295 | H14: 8102.5841 | I14: 22384.539 | J14: 4418.4739 | K14: -7450.3255 | L14: Q3'27
A15: + Rubin premium at per-MW parity (1.56x GB300) | B15: 153.79048 | C15: 58.817396 | D15: 406.65016 | E15: 153.96971 | F15: 459.51468 | G15: 2425.3295 | H15: 8140.6586 | I15: 24633.629 | J15: 4445.5068 | K15: -7423.7798 | L15: Q3'27
A16: + CLT1 rent $2.2M/IT MW-yr | B16: 154.02609 | C16: 0.23561158 | D16: 407.25464 | E16: 0.60447567 | F16: 460.19774 | G16: 2425.3295 | H16: 8140.6586 | I16: 24633.629 | J16: 4447.4208 | K16: -7421.8657 | L16: Q3'27
A17: + terminal g from fundamentals | B17: 125.81957 | C17: -28.206529 | D17: 334.88909 | E17: -72.365546 | F17: 378.42467 | G17: 2425.3295 | H17: 8140.6586 | I17: 24633.629 | J17: 4447.4208 | K17: -7421.8657 | L17: Q3'27
... A47: + new prepayments at Q2'26 pace $1.2B/qtr through Q4'28 (was % of capex) (= v0.7b) | B47: 7.8545901 | C47: -1.2031381 | D47: 0.01 | E47: 0 | F47: 2.2868836 | G47: 2465.0795 | H47: 7505.4653 | I47: 20180.665 | J47: 3713.4637 | K47: -4956.4832 | L47: Q3'27
A50: Horizon per-share values (FD value/share rolled at Ke; excludes future funding dilution - see Funding tab)
A51: Scenario | B51: Today | C51: 6-month | D51: 12-month PT | E51: 3-year
A52: Base (live) | B52: 0.01 | C52: 2.1513191 | D52: 2.2868836 | E52: 2.9201217
A53: Bull | B53: 329.74111 | C53: 345.10183 | D53: 365.22144 | E53: 458.13378
A54: Bear | B54: 0.01 | C54: 0 | D54: 0 | E54: 0
A57: New-MW pricing vs IREN >$20M/IT MW-yr ($M per IT MW-yr). GB300 GPU-hour engine (legacy fleet) at Oct-1 list x RealRes x Util_Res; new 2027+ MW at new-deal blend (col G)
A58: Scenario | B58: GB300 gross | C58: net leased (-$2.2M rent) | D58: net owned (-O&M) | E58: Rubin gross | F58: IREN gross / leased / owned | G58: New-deal blend gross
A59: Base (live) | B59: 27.424348 | C59: 25.224348 | D59: 26.674348 | E59: 21.061899 | F59: 20.0 / 17.8 / 19.25 | G59: 16.69175
A60: Bull | B60: 43.041696 | C60: 40.841696 | D60: 42.291696 | E60: 33.056023 | F60: 20.0 / 17.8 / 19.25 | G60: 19.092188
A61: Bear | B61: 22.272793 | C61: 20.072793 | D61: 21.522793 | E61: 17.105505 | F61: 20.0 / 17.8 / 19.25 | G61: 14.736556
A64: v0.5 BASE RANGE: 12m PT ($/share) by short-term share (of TOTAL active MW) x new-deal $/MW basis, with / without prepayment decay (STATIC). Green = base; yellow = supported tests; orange = gross-MW basis (alternative reading of slide); red = equity floored at 0
A65: Prepayment decay ON (base) | B65: ST share 0% (floor) | C65: ST share 2% | D65: ST share 5% | E65: ST share 10%
A66: IT basis $22M/IT MW | B66: 0 | C66: 0 | D66: 2.2868836 | E66: 44.079308
A67: Gross-MW basis = $26.4M/IT MW | B67: 0 | C67: 2.4794153 | D67: 25.305107 | E67: 57.302274
A68: EV $B / YE27 liq $B / 1st neg - IT | B68: -5.2 / -5.2 / Q3'27 | C68: 0.1 / -5.1 / Q3'27 | D68: 7.9 / -5.0 / Q3'27 | E68: 20.0 / -4.7 / Q3'27
A69: EV $B / YE27 liq $B / 1st neg - gross | B69: 3.5 / -4.8 / Q3'27 | C69: 7.9 / -4.8 / Q3'27 | D69: 14.5 / -4.6 / Q3'27 | E69: 23.8 / -4.5 / Q3'27
A71: Prepayment decay OFF (other deals 38.5% flat) | B71: ST share 0% (floor) | C71: ST share 2% | D71: ST share 5% | E71: ST share 10%
A72: IT basis $22M/IT MW | B72: 0 | C72: 0 | D72: 5.1536804 | E72: 46.946105
A73: Gross-MW basis = $26.4M/IT MW | B73: 0 | C73: 5.3462121 | D73: 28.171904 | E73: 60.205257
A74: EV $B / YE27 liq $B / 1st neg - IT | B74: -4.3 / -5.2 / Q3'27 | C74: 0.9 / -5.1 / Q3'27 | D74: 8.7 / -5.0 / Q3'27 | E74: 20.8 / -4.7 / Q3'27
A75: EV $B / YE27 liq $B / 1st neg - gross | B75: 4.3 / -4.8 / Q3'27 | C75: 8.7 / -4.8 / Q3'27 | D75: 15.3 / -4.6 / Q3'27 | E75: 24.6 / -4.5 / Q3'27

Sheet Payback_Floor
A1: Payback check, new-deal price cases, EBITDA per IT MW by generation, and asset floor (live formulas). Inputs blue.
A3: Leased GB300 capex per IT MW ($M; GPU + network + storage, no shell) = CPM_Lease_GB300 (rack-based) | B3: =CPM_Lease_GB300 -> 36.7875 | C3: v0.7b: 6.8 racks x GB_RackPx + $6.1M network (v0.7 41.3) | E3: Owned opex per IT MW-yr (power + ops, NO rent) = OwnOpex | F3: =IF(OwnOpexOn=1,OwnOpex,LoadFactor*PUE*8760*PowerPx/1000000+OM_MW) -> 2.25
A4: Leased Vera Rubin capex per IT MW ($M) - live scenario = CPM_Lease_VR | B4: =CPM_Lease_VR -> 41.1 | C4: Capacity v2: $34.3 / 41.1 / 49.2M bull/base/bear (racks $6.7/7.8/9.1M; network $5.3M) | E4: Owned data hall + power/cooling $M/IT MW (in owned capex; not replaced on GPU cycle) = CPM_SP | F4: =CPM_SP -> 12.5
A5: Owned GB300 capex per IT MW ($M, incl. data hall) = CPM_Own_GB300 | B5: =CPM_Own_GB300 -> 49.2875 | C5: v0.7b: rack-based + $12.5M hall (v0.7 53) | E5: Data hall economic life (yrs; residual only) = HallLife | F5: =HallLife -> 18
A6: Owned Vera Rubin capex per IT MW ($M) = CPM_Own_VR | B6: =CPM_Own_VR -> 52.6 | C6: Capacity v2 base $52.6M (v0.7 56) | E6: GPU/server residual at refresh (% of servers+network) = GPU_Resid | F6: =GPU_Resid -> 0.15
A7: Opex per IT MW-yr (rent $2.0-2.5M + power + ops), fixed across generations | B7: 4.5 | C7: Range $4-5M; does NOT fall at the Rubin switch | E7: WACC (NPV discount rate) | F7: =WACC -> 0.11
A8: Management payback target (months) | B8: 22 | C8: Q2'26 letter: 1 year 10 months, prepayments excluded (footnote basis) | E8: Corporate opex % revenue FY29 (other COR + PD + SG&A ex-SBC; for after-tax NPV incl. overhead) | F8: =OtherCOR+INDEX(PDpct,1,2029-FYBase)+INDEX(SGApct,1,2029-FYBase) -> 0.21
A9: Asset life for unlevered IRR (yrs; capex at t0, flat EBITDA, residual at end: GPUs GPU_Resid, owned data hall at HallLife) | B9: 5 | C9: GPU life 5 yrs (model base)
A10: A) New-deal price cases - $/IT MW-yr next to implied $/GPU-hr. GB300: one linked input (ND_Px x 491 x 8,760 x ND_Occ), IT vs gross toggle. RUBIN: direct $/IT MW-yr (no IT/gross toggle)
A11: Case | B11: IT reading $M/IT MW | C11: IT $/GPU-hr | D11: Gross reading $M/IT MW | E11: Gross $/GPU-hr | F11: $/GPU-hr at 400/MW (ref only)
A12: GB300 NVL72 (491 GPUs/IT MW) | B12: =MYRate -> 16 | C12: =ND_Px -> 3.7199267 | D12: =MYRate*ND_GrossX -> 19.207824 | E12: =ND_Px*ND_GrossX -> 4.4657311
A13: Vera Rubin $16M/IT MW [bear] | B13: =16 -> 16 | C13: =16*1000000/(GPUMW_N*8760) -> 5.7077626 | D13: same (no toggle) | F13: =16*1000000/(RubinGPUMW_D*8760) -> 4.56621
A14: Vera Rubin $18M/IT MW [base] | B14: =18 -> 18 | C14: =18*1000000/(GPUMW_N*8760) -> 6.4212329 | D14: same (no toggle) | F14: =18*1000000/(RubinGPUMW_D*8760) -> 5.1369863
A15: Vera Rubin $20M/IT MW [bull] | B15: =20 -> 20 | C15: =20*1000000/(GPUMW_N*8760) -> 7.1347032 | D15: same (no toggle) | F15: =20*1000000/(RubinGPUMW_D*8760) -> 5.7077626
A16: Vera Rubin at live RubinMW | B16: =RubinMW -> 18 | C16: =RubinMW*1000000/(GPUMW_N*8760) -> 6.4212329 | D16: same (no toggle) | F16: =RubinMW*1000000/(RubinGPUMW_D*8760) -> 5.1369863
A17: Benchmarks: IREN new 3-yr GB300 ~$4.65/GPU-hr (>$20M/IT MW); Rubin: Anthropic-Nscale ~$16.2M/MW (6-yr, MW basis unknown); WhiteFiber-Prime Intellect 576 VR200 ~$108.2M/3 yrs = ~$7.15/GPU-hr (~$20M/IT MW if packages counted, medium). GB300 basis not disclosed by management.
A19: B) EBITDA per IT MW-yr by generation (opex fixed across generations; Rubin = RubinMW, no toggle)
B20: GB300 IT | C20: Rubin (RubinMW) | D20: Change | E20: GB300 gross | F20: Rubin (RubinMW) | G20: Change
A21: Revenue per IT MW-yr | B21: =B12 -> 16 | C21: =RubinMW -> 18 | D21: =C21/B21-1 -> 0.125 | E21: =D12 -> 19.207824 | F21: =RubinMW -> 18 | G21: =F21/E21-1 -> -0.062881874
A22: Opex per IT MW-yr (PB_Opex) | B22: =PB_Opex -> 4.5 | C22: =PB_Opex -> 4.5 | E22: =PB_Opex -> 4.5 | F22: =PB_Opex -> 4.5
A23: EBITDA per IT MW-yr | B23: =B21-B22 -> 11.5 | C23: =C21-C22 -> 13.5 | D23: =C23/B23-1 -> 0.17391304 | E23: =E21-E22 -> 14.707824 | F23: =F21-F22 -> 13.5 | G23: =F23/E23-1 -> -0.082121187
A24: Memo: model's own opex/IT MW-yr - B: LEASED = RentMW x PUE + power (LoadFactor x PUE x 8,760 x PowerPx); C: OWNED = power + O&M, no rent (PB_OpexOwn) | B24: =RentMW*PUE+LoadFactor*PUE*8760*PowerPx/1000000 -> 3.4695 | C24: =PB_OpexOwn -> 2.25
A26: C) PAYBACK (months) = capex / (revenue - opex) x 12; prepayments EXCLUDED unless stated. Flag = within +/-3 months of 22. IRR = unlevered pre-tax, capex at t0, flat EBITDA over PB_Life, residual at end (col L). NPV per IT MW at WACC: N pre-tax; O after tax (site level, book D&A shield); P after tax incl. corporate opex PB_Corp
A27: Case | B27: IT / Rubin payback | C27: flag | D27: Gross (MYRate x ND_GrossX) payback | E27: flag | F27: capex $M/IT MW | G27: opex | H27: revenue IT $M | I27: EBITDA/IT MW (IT) | J27: IRR (IT, with residual) | K27: IRR (gross, with residual) | L27: residual at yr PB_Life $M/MW | M27: IRR (IT) no residual [v0.7 basis] | N27: NPV/MW pre-tax @WACC | O27: NPV/MW after tax (site) | P27: NPV/MW after tax incl. corporate opex | Q27: of which data hall $M/MW
A28: Leased GB300 (capex incl. $1.6M lease prepayment) | B28: =IFERROR(F28*1/(H28-G28)*12,999) -> 40.056522 | C28: =IF(ISNUMBER(B28),IF(ABS(B28-PB_Target)<=3,"WITHIN +/-3","outside"),"") -> outside | D28: =IFERROR(F28*1/(MYRate*ND_GrossX-G28)*12,999) -> 31.320065 | E28: =IF(ISNUMBER(D28),IF(ABS(D28-PB_Target)<=3,"WITHIN +/-3","outside"),"") -> outside | F28: =PB_CapGB+LeasePrepayOn*LeasePrepay -> 38.3875 | G28: =PB_Opex -> 4.5 | H28: =MYRate -> 16 | I28: =H28-G28 -> 11.5 | J28: =IFERROR(RATE(PB_Life,I28,-F28*1,L28),-1) -> 0.18099946 | K28: =IFERROR(RATE(PB_Life,MYRate*ND_GrossX-G28,-F28*1,L28),-1) -> 0.28669829 | L28: =PB_Resid*(F28-Q28)+Q28*MAX(0,1-PB_Life/PB_HallLife) -> 5.758125 | M28: =IFERROR(RATE(PB_Life,I28,-F28*1),-1) -> 0.15178413 | N28: =-F28*1+I28*(1-(1+PB_WACC)^-PB_Life)/PB_WACC+L28*(1+PB_WACC)^-PB_Life -> 7.5324826 | O28: =-F28*1+(I28-TaxRate*MAX(0,I28-((F28-Q28)/PB_Life+Q28*(ShellMW/(ShellMW+PowerMW)/Life_Shell+PowerMW/(ShellMW+PowerMW)/Life_Pow))))*(1-(1+PB_WACC)^-PB_Life)/PB_WACC+(PB_Resid*(F28-Q28)*(1-TaxRate)+Q28*MAX(0,1-PB_Life/PB_HallLife)-TaxRate*(Q28*MAX(0,1-PB_Life/PB_HallLife)-Q28*MAX(0,1-PB_Life*(ShellMW/(ShellMW+PowerMW)/Life_Shell+PowerMW/(ShellMW+PowerMW)/Life_Pow))))*(1+PB_WACC)^-PB_Life -> 3.0059414 | P28: =-F28*1+((I28-PB_Corp*H28)-TaxRate*MAX(0,I28-PB_Corp*H28-((F28-Q28)/PB_Life+Q28*(ShellMW/(ShellMW+PowerMW)/Life_Shell+PowerMW/(ShellMW+PowerMW)/Life_Pow))))*(1-(1+PB_WACC)^-PB_Life)/PB_WACC+(PB_Resid*(F28-Q28)*(1-TaxRate)+Q28*MAX(0,1-PB_Life/PB_HallLife)-TaxRate*(Q28*MAX(0,1-PB_Life/PB_HallLife)-Q28*MAX(0,1-PB_Life*(ShellMW/(ShellMW+PowerMW)/Life_Shell+PowerMW/(ShellMW+PowerMW)/Life_Pow))))*(1+PB_WACC)^-PB_Life -> -6.2083733 | Q28: =0 -> 0
A29: Leased Vera Rubin BASE: $18M rev / $41.1M capex (+ lease prepayment) | B29: =IFERROR(F29*1/(H29-G29)*12,999) -> 37.955556 | C29: =IF(ISNUMBER(B29),IF(ABS(B29-PB_Target)<=3,"WITHIN +/-3","outside"),"") -> outside | D29: n/a (no toggle) | E29: =IF(ISNUMBER(D29),IF(ABS(D29-PB_Target)<=3,"WITHIN +/-3","outside"),"") | F29: =41.1+LeasePrepayOn*LeasePrepay -> 42.7 | G29: =PB_Opex -> 4.5 | H29: =18 -> 18 | I29: =H29-G29 -> 13.5 | J29: =IFERROR(RATE(PB_Life,I29,-F29*1,L29),-1) -> 0.20249548 | L29: =PB_Resid*(F29-Q29)+Q29*MAX(0,1-PB_Life/PB_HallLife) -> 6.405 | M29: =IFERROR(RATE(PB_Life,I29,-F29*1),-1) -> 0.17499413 | N29: =-F29*1+I29*(1-(1+PB_WACC)^-PB_Life)/PB_WACC+L29*(1+PB_WACC)^-PB_Life -> 10.995665 | O29: =-F29*1+(I29-TaxRate*MAX(0,I29-((F29-Q29)/PB_Life+Q29*(ShellMW/(ShellMW+PowerMW)/Life_Shell+PowerMW/(ShellMW+PowerMW)/Life_Pow))))*(1-(1+PB_WACC)^-PB_Life)/PB_WACC+(PB_Resid*(F29-Q29)*(1-TaxRate)+Q29*MAX(0,1-PB_Life/PB_HallLife)-TaxRate*(Q29*MAX(0,1-PB_Life/PB_HallLife)-Q29*MAX(0,1-PB_Life*(ShellMW/(ShellMW+PowerMW)/Life_Shell+PowerMW/(ShellMW+PowerMW)/Life_Pow))))*(1+PB_WACC)^-PB_Life -> 5.2854276 | P29: =-F29*1+((I29-PB_Corp*H29)-TaxRate*MAX(0,I29-PB_Corp*H29-((F29-Q29)/PB_Life+Q29*(ShellMW/(ShellMW+PowerMW)/Life_Shell+PowerMW/(ShellMW+PowerMW)/Life_Pow))))*(1-(1+PB_WACC)^-PB_Life)/PB_WACC+(PB_Resid*(F29-Q29)*(1-TaxRate)+Q29*MAX(0,1-PB_Life/PB_HallLife)-TaxRate*(Q29*MAX(0,1-PB_Life/PB_HallLife)-Q29*MAX(0,1-PB_Life*(ShellMW/(ShellMW+PowerMW)/Life_Shell+PowerMW/(ShellMW+PowerMW)/Life_Pow))))*(1+PB_WACC)^-PB_Life -> -5.0806765 | Q29: =0 -> 0
A30: Leased Vera Rubin BULL: $20M / $34.3M (+ lease prepayment) | B30: =IFERROR(F30*1/(H30-G30)*12,999) -> 27.793548 | C30: =IF(ISNUMBER(B30),IF(ABS(B30-PB_Target)<=3,"WITHIN +/-3","outside"),"") -> outside | D30: n/a (no toggle) | E30: =IF(ISNUMBER(D30),IF(ABS(D30-PB_Target)<=3,"WITHIN +/-3","outside"),"") | F30: =34.3+LeasePrepayOn*LeasePrepay -> 35.9 | G30: =PB_Opex -> 4.5 | H30: =20 -> 20 | I30: =H30-G30 -> 15.5 | J30: =IFERROR(RATE(PB_Life,I30,-F30*1,L30),-1) -> 0.34565325 | L30: =PB_Resid*(F30-Q30)+Q30*MAX(0,1-PB_Life/PB_HallLife) -> 5.385 | M30: =IFERROR(RATE(PB_Life,I30,-F30*1),-1) -> 0.32671706 | N30: =-F30*1+I30*(1-(1+PB_WACC)^-PB_Life)/PB_WACC+L30*(1+PB_WACC)^-PB_Life -> 24.582139 | O30: =-F30*1+(I30-TaxRate*MAX(0,I30-((F30-Q30)/PB_Life+Q30*(ShellMW/(ShellMW+PowerMW)/Life_Shell+PowerMW/(ShellMW+PowerMW)/Life_Pow))))*(1-(1+PB_WACC)^-PB_Life)/PB_WACC+(PB_Resid*(F30-Q30)*(1-TaxRate)+Q30*MAX(0,1-PB_Life/PB_HallLife)-TaxRate*(Q30*MAX(0,1-PB_Life/PB_HallLife)-Q30*MAX(0,1-PB_Life*(ShellMW/(ShellMW+PowerMW)/Life_Shell+PowerMW/(ShellMW+PowerMW)/Life_Pow))))*(1+PB_WACC)^-PB_Life -> 15.824175 | P30: =-F30*1+((I30-PB_Corp*H30)-TaxRate*MAX(0,I30-PB_Corp*H30-((F30-Q30)/PB_Life+Q30*(ShellMW/(ShellMW+PowerMW)/Life_Shell+PowerMW/(ShellMW+PowerMW)/Life_Pow))))*(1-(1+PB_WACC)^-PB_Life)/PB_WACC+(PB_Resid*(F30-Q30)*(1-TaxRate)+Q30*MAX(0,1-PB_Life/PB_HallLife)-TaxRate*(Q30*MAX(0,1-PB_Life/PB_HallLife)-Q30*MAX(0,1-PB_Life*(ShellMW/(ShellMW+PowerMW)/Life_Shell+PowerMW/(ShellMW+PowerMW)/Life_Pow))))*(1+PB_WACC)^-PB_Life -> 4.3062813 | Q30: =0 -> 0
A31: Leased Vera Rubin BEAR: $16M / $49.2M (+ lease prepayment) | B31: =IFERROR(F31*1/(H31-G31)*12,999) -> 53.008696 | C31: =IF(ISNUMBER(B31),IF(ABS(B31-PB_Target)<=3,"WITHIN +/-3","outside"),"") -> outside | D31: n/a (no toggle) | E31: =IF(ISNUMBER(D31),IF(ABS(D31-PB_Target)<=3,"WITHIN +/-3","outside"),"") | F31: =49.2+LeasePrepayOn*LeasePrepay -> 50.8 | G31: =PB_Opex -> 4.5 | H31: =16 -> 16 | I31: =H31-G31 -> 11.5 | J31: =IFERROR(RATE(PB_Life,I31,-F31*1,L31),-1) -> 0.082093483 | L31: =PB_Resid*(F31-Q31)+Q31*MAX(0,1-PB_Life/PB_HallLife) -> 7.62 | M31: =IFERROR(RATE(PB_Life,I31,-F31*1),-1) -> 0.042770005 | N31: =-F31*1+I31*(1-(1+PB_WACC)^-PB_Life)/PB_WACC+L31*(1+PB_WACC)^-PB_Life -> -3.7750852 | O31: =-F31*1+(I31-TaxRate*MAX(0,I31-((F31-Q31)/PB_Life+Q31*(ShellMW/(ShellMW+PowerMW)/Life_Shell+PowerMW/(ShellMW+PowerMW)/Life_Pow))))*(1-(1+PB_WACC)^-PB_Life)/PB_WACC+(PB_Resid*(F31-Q31)*(1-TaxRate)+Q31*MAX(0,1-PB_Life/PB_HallLife)-TaxRate*(Q31*MAX(0,1-PB_Life/PB_HallLife)-Q31*MAX(0,1-PB_Life*(ShellMW/(ShellMW+PowerMW)/Life_Shell+PowerMW/(ShellMW+PowerMW)/Life_Pow))))*(1+PB_WACC)^-PB_Life -> -6.2195323 | P31: =-F31*1+((I31-PB_Corp*H31)-TaxRate*MAX(0,I31-PB_Corp*H31-((F31-Q31)/PB_Life+Q31*(ShellMW/(ShellMW+PowerMW)/Life_Shell+PowerMW/(ShellMW+PowerMW)/Life_Pow))))*(1-(1+PB_WACC)^-PB_Life)/PB_WACC+(PB_Resid*(F31-Q31)*(1-TaxRate)+Q31*MAX(0,1-PB_Life/PB_HallLife)-TaxRate*(Q31*MAX(0,1-PB_Life/PB_HallLife)-Q31*MAX(0,1-PB_Life*(ShellMW/(ShellMW+PowerMW)/Life_Shell+PowerMW/(ShellMW+PowerMW)/Life_Pow))))*(1+PB_WACC)^-PB_Life -> -17.360001 | Q31: =0 -> 0
A32: Leased Vera Rubin: bull price $20M at base capex $41.1M (+ lease prepayment) | B32: =IFERROR(F32*1/(H32-G32)*12,999) -> 33.058065 | C32: =IF(ISNUMBER(B32),IF(ABS(B32-PB_Target)<=3,"WITHIN +/-3","outside"),"") -> outside | D32: n/a (no toggle) | E32: =IF(ISNUMBER(D32),IF(ABS(D32-PB_Target)<=3,"WITHIN +/-3","outside"),"") | F32: =41.1+LeasePrepayOn*LeasePrepay -> 42.7 | G32: =PB_Opex -> 4.5 | H32: =20 -> 20 | I32: =H32-G32 -> 15.5 | J32: =IFERROR(RATE(PB_Life,I32,-F32*1,L32),-1) -> 0.26177605 | L32: =PB_Resid*(F32-Q32)+Q32*MAX(0,1-PB_Life/PB_HallLife) -> 6.405 | M32: =IFERROR(RATE(PB_Life,I32,-F32*1),-1) -> 0.23834846 | N32: =-F32*1+I32*(1-(1+PB_WACC)^-PB_Life)/PB_WACC+L32*(1+PB_WACC)^-PB_Life -> 18.38746 | O32: =-F32*1+(I32-TaxRate*MAX(0,I32-((F32-Q32)/PB_Life+Q32*(ShellMW/(ShellMW+PowerMW)/Life_Shell+PowerMW/(ShellMW+PowerMW)/Life_Pow))))*(1-(1+PB_WACC)^-PB_Life)/PB_WACC+(PB_Resid*(F32-Q32)*(1-TaxRate)+Q32*MAX(0,1-PB_Life/PB_HallLife)-TaxRate*(Q32*MAX(0,1-PB_Life/PB_HallLife)-Q32*MAX(0,1-PB_Life*(ShellMW/(ShellMW+PowerMW)/Life_Shell+PowerMW/(ShellMW+PowerMW)/Life_Pow))))*(1+PB_WACC)^-PB_Life -> 10.770139 | P32: =-F32*1+((I32-PB_Corp*H32)-TaxRate*MAX(0,I32-PB_Corp*H32-((F32-Q32)/PB_Life+Q32*(ShellMW/(ShellMW+PowerMW)/Life_Shell+PowerMW/(ShellMW+PowerMW)/Life_Pow))))*(1-(1+PB_WACC)^-PB_Life)/PB_WACC+(PB_Resid*(F32-Q32)*(1-TaxRate)+Q32*MAX(0,1-PB_Life/PB_HallLife)-TaxRate*(Q32*MAX(0,1-PB_Life/PB_HallLife)-Q32*MAX(0,1-PB_Life*(ShellMW/(ShellMW+PowerMW)/Life_Shell+PowerMW/(ShellMW+PowerMW)/Life_Pow))))*(1+PB_WACC)^-PB_Life -> -0.74775468 | Q32: =0 -> 0
A33: Owned GB300 (memo, rack-based servers+network + 12.5 hall), opex NO rent | B33: =IFERROR(F33*1/(H33-G33)*12,999) -> 43.014545 | C33: =IF(ISNUMBER(B33),IF(ABS(B33-PB_Target)<=3,"WITHIN +/-3","outside"),"") -> outside | D33: =IFERROR(F33*1/(MYRate*ND_GrossX-G33)*12,999) -> 34.877706 | E33: =IF(ISNUMBER(D33),IF(ABS(D33-PB_Target)<=3,"WITHIN +/-3","outside"),"") -> outside | F33: =PB_CapOwnGB -> 49.2875 | G33: =PB_OpexOwn -> 2.25 | H33: =MYRate -> 16 | I33: =H33-G33 -> 13.75 | J33: =IFERROR(RATE(PB_Life,I33,-F33*1,L33),-1) -> 0.18055757 | K33: =IFERROR(RATE(PB_Life,MYRate*ND_GrossX-G33,-F33*1,L33),-1) -> 0.25979558 | L33: =PB_Resid*(F33-Q33)+Q33*MAX(0,1-PB_Life/PB_HallLife) -> 14.545903 | M33: =IFERROR(RATE(PB_Life,I33,-F33*1),-1) -> 0.12227576 | N33: =-F33*1+I33*(1-(1+PB_WACC)^-PB_Life)/PB_WACC+L33*(1+PB_WACC)^-PB_Life -> 10.163369 | O33: =-F33*1+(I33-TaxRate*MAX(0,I33-((F33-Q33)/PB_Life+Q33*(ShellMW/(ShellMW+PowerMW)/Life_Shell+PowerMW/(ShellMW+PowerMW)/Life_Pow))))*(1-(1+PB_WACC)^-PB_Life)/PB_WACC+(PB_Resid*(F33-Q33)*(1-TaxRate)+Q33*MAX(0,1-PB_Life/PB_HallLife)-TaxRate*(Q33*MAX(0,1-PB_Life/PB_HallLife)-Q33*MAX(0,1-PB_Life*(ShellMW/(ShellMW+PowerMW)/Life_Shell+PowerMW/(ShellMW+PowerMW)/Life_Pow))))*(1+PB_WACC)^-PB_Life -> 3.9543452 | P33: =-F33*1+((I33-PB_Corp*H33)-TaxRate*MAX(0,I33-PB_Corp*H33-((F33-Q33)/PB_Life+Q33*(ShellMW/(ShellMW+PowerMW)/Life_Shell+PowerMW/(ShellMW+PowerMW)/Life_Pow))))*(1-(1+PB_WACC)^-PB_Life)/PB_WACC+(PB_Resid*(F33-Q33)*(1-TaxRate)+Q33*MAX(0,1-PB_Life/PB_HallLife)-TaxRate*(Q33*MAX(0,1-PB_Life/PB_HallLife)-Q33*MAX(0,1-PB_Life*(ShellMW/(ShellMW+PowerMW)/Life_Shell+PowerMW/(ShellMW+PowerMW)/Life_Pow))))*(1+PB_WACC)^-PB_Life -> -5.2599696 | Q33: =PB_Hall -> 12.5
A34: Owned Vera Rubin (memo, base 52.6 = 40.1 + 12.5 hall) at $18M, opex NO rent | B34: =IFERROR(F34*1/(H34-G34)*12,999) -> 40.07619 | C34: =IF(ISNUMBER(B34),IF(ABS(B34-PB_Target)<=3,"WITHIN +/-3","outside"),"") -> outside | D34: n/a (no toggle) | E34: =IF(ISNUMBER(D34),IF(ABS(D34-PB_Target)<=3,"WITHIN +/-3","outside"),"") | F34: =PB_CapOwnRubin -> 52.6 | G34: =PB_OpexOwn -> 2.25 | H34: =18 -> 18 | I34: =H34-G34 -> 15.75 | J34: =IFERROR(RATE(PB_Life,I34,-F34*1,L34),-1) -> 0.20428523 | L34: =PB_Resid*(F34-Q34)+Q34*MAX(0,1-PB_Life/PB_HallLife) -> 15.042778 | M34: =IFERROR(RATE(PB_Life,I34,-F34*1),-1) -> 0.15157627 | N34: =-F34*1+I34*(1-(1+PB_WACC)^-PB_Life)/PB_WACC+L34*(1+PB_WACC)^-PB_Life -> 14.537534 | O34: =-F34*1+(I34-TaxRate*MAX(0,I34-((F34-Q34)/PB_Life+Q34*(ShellMW/(ShellMW+PowerMW)/Life_Shell+PowerMW/(ShellMW+PowerMW)/Life_Pow))))*(1-(1+PB_WACC)^-PB_Life)/PB_WACC+(PB_Resid*(F34-Q34)*(1-TaxRate)+Q34*MAX(0,1-PB_Life/PB_HallLife)-TaxRate*(Q34*MAX(0,1-PB_Life/PB_HallLife)-Q34*MAX(0,1-PB_Life*(ShellMW/(ShellMW+PowerMW)/Life_Shell+PowerMW/(ShellMW+PowerMW)/Life_Pow))))*(1+PB_WACC)^-PB_Life -> 6.9770719 | P34: =-F34*1+((I34-PB_Corp*H34)-TaxRate*MAX(0,I34-PB_Corp*H34-((F34-Q34)/PB_Life+Q34*(ShellMW/(ShellMW+PowerMW)/Life_Shell+PowerMW/(ShellMW+PowerMW)/Life_Pow))))*(1-(1+PB_WACC)^-PB_Life)/PB_WACC+(PB_Resid*(F34-Q34)*(1-TaxRate)+Q34*MAX(0,1-PB_Life/PB_HallLife)-TaxRate*(Q34*MAX(0,1-PB_Life/PB_HallLife)-Q34*MAX(0,1-PB_Life*(ShellMW/(ShellMW+PowerMW)/Life_Shell+PowerMW/(ShellMW+PowerMW)/Life_Pow))))*(1+PB_WACC)^-PB_Life -> -3.3890322 | Q34: =PB_Hall -> 12.5
A35: MODEL'S OWN: GB300-era path capex (avg PathRateIT + PathRateSP 2027) + model opex at 2027 owned share | B35: =IFERROR(F35*1/(H35-G35)*12,999) -> 39.788694 | C35: =IF(ISNUMBER(B35),IF(ABS(B35-PB_Target)<=3,"WITHIN +/-3","outside"),"") -> outside | D35: =IFERROR(F35*1/(MYRate*ND_GrossX-G35)*12,999) -> 31.809593 | E35: =IF(ISNUMBER(D35),IF(ABS(D35-PB_Target)<=3,"WITHIN +/-3","outside"),"") -> outside | F35: =AVERAGE(INDEX(PathRateIT,1,13),INDEX(PathRateIT,1,14),INDEX(PathRateIT,1,15),INDEX(PathRateIT,1,16))+AVERAGE(INDEX(PathRateSP,1,13),INDEX(PathRateSP,1,14),INDEX(PathRateSP,1,15),INDEX(PathRateSP,1,16))+(1-AVERAGE(INDEX(MW_OwnSh,1,13),INDEX(MW_OwnSh,1,14),INDEX(MW_OwnSh,1,15),INDEX(MW_OwnSh,1,16)))*LeasePrepayOn*LeasePrepay -> 42.402657 | G35: =(1-AVERAGE(INDEX(MW_OwnSh,1,13),INDEX(MW_OwnSh,1,14),INDEX(MW_OwnSh,1,15),INDEX(MW_OwnSh,1,16)))*PB_OpexModel+AVERAGE(INDEX(MW_OwnSh,1,13),INDEX(MW_OwnSh,1,14),INDEX(MW_OwnSh,1,15),INDEX(MW_OwnSh,1,16))*PB_OpexModelOwn -> 3.2116466 | H35: =MYRate -> 16 | I35: =H35-G35 -> 12.788353 | J35: =IFERROR(RATE(PB_Life,I35,-F35*1,L35),-1) -> 0.19225416 | K35: =IFERROR(RATE(PB_Life,MYRate*ND_GrossX-G35,-F35*1,L35),-1) -> 0.28624124 | L35: =PB_Resid*(F35-Q35)+Q35*MAX(0,1-PB_Life/PB_HallLife) -> 8.4232088 | M35: =IFERROR(RATE(PB_Life,I35,-F35*1),-1) -> 0.15463117 | N35: =-F35*1+I35*(1-(1+PB_WACC)^-PB_Life)/PB_WACC+L35*(1+PB_WACC)^-PB_Life -> 9.8605446 | O35: =-F35*1+(I35-TaxRate*MAX(0,I35-((F35-Q35)/PB_Life+Q35*(ShellMW/(ShellMW+PowerMW)/Life_Shell+PowerMW/(ShellMW+PowerMW)/Life_Pow))))*(1-(1+PB_WACC)^-PB_Life)/PB_WACC+(PB_Resid*(F35-Q35)*(1-TaxRate)+Q35*MAX(0,1-PB_Life/PB_HallLife)-TaxRate*(Q35*MAX(0,1-PB_Life/PB_HallLife)-Q35*MAX(0,1-PB_Life*(ShellMW/(ShellMW+PowerMW)/Life_Shell+PowerMW/(ShellMW+PowerMW)/Life_Pow))))*(1+PB_WACC)^-PB_Life -> 4.3852429 | P35: =-F35*1+((I35-PB_Corp*H35)-TaxRate*MAX(0,I35-PB_Corp*H35-((F35-Q35)/PB_Life+Q35*(ShellMW/(ShellMW+PowerMW)/Life_Shell+PowerMW/(ShellMW+PowerMW)/Life_Pow))))*(1-(1+PB_WACC)^-PB_Life)/PB_WACC+(PB_Resid*(F35-Q35)*(1-TaxRate)+Q35*MAX(0,1-PB_Life/PB_HallLife)-TaxRate*(Q35*MAX(0,1-PB_Life/PB_HallLife)-Q35*MAX(0,1-PB_Life*(ShellMW/(ShellMW+PowerMW)/Life_Shell+PowerMW/(ShellMW+PowerMW)/Life_Pow))))*(1+PB_WACC)^-PB_Life -> -4.8290718 | Q35: =AVERAGE(INDEX(PathRateSP,1,13),INDEX(PathRateSP,1,14),INDEX(PathRateSP,1,15),INDEX(PathRateSP,1,16)) -> 3.6049111
A36: MODEL'S OWN: Rubin-era path capex (avg PathRateIT + PathRateSP 2029) + model opex at 2029 owned share, live RubinMW | B36: =IFERROR(F36*1/(H36-G36)*12,999) -> 40.269274 | C36: =IF(ISNUMBER(B36),IF(ABS(B36-PB_Target)<=3,"WITHIN +/-3","outside"),"") -> outside | D36: n/a (no toggle) | E36: =IF(ISNUMBER(D36),IF(ABS(D36-PB_Target)<=3,"WITHIN +/-3","outside"),"") | F36: =AVERAGE(INDEX(PathRateIT,1,21),INDEX(PathRateIT,1,22),INDEX(PathRateIT,1,23),INDEX(PathRateIT,1,24))+AVERAGE(INDEX(PathRateSP,1,21),INDEX(PathRateSP,1,22),INDEX(PathRateSP,1,23),INDEX(PathRateSP,1,24))+(1-AVERAGE(INDEX(MW_OwnSh,1,21),INDEX(MW_OwnSh,1,22),INDEX(MW_OwnSh,1,23),INDEX(MW_OwnSh,1,24)))*LeasePrepayOn*LeasePrepay -> 51.127123 | G36: =(1-AVERAGE(INDEX(MW_OwnSh,1,21),INDEX(MW_OwnSh,1,22),INDEX(MW_OwnSh,1,23),INDEX(MW_OwnSh,1,24)))*PB_OpexModel+AVERAGE(INDEX(MW_OwnSh,1,21),INDEX(MW_OwnSh,1,22),INDEX(MW_OwnSh,1,23),INDEX(MW_OwnSh,1,24))*PB_OpexModelOwn -> 2.7644267 | H36: =RubinMW -> 18 | I36: =H36-G36 -> 15.235573 | J36: =IFERROR(RATE(PB_Life,I36,-F36*1,L36),-1) -> 0.20006036 | L36: =PB_Resid*(F36-Q36)+Q36*MAX(0,1-PB_Life/PB_HallLife) -> 13.862145 | M36: =IFERROR(RATE(PB_Life,I36,-F36*1),-1) -> 0.14954458 | N36: =-F36*1+I36*(1-(1+PB_WACC)^-PB_Life)/PB_WACC+L36*(1+PB_WACC)^-PB_Life -> 13.408495 | O36: =-F36*1+(I36-TaxRate*MAX(0,I36-((F36-Q36)/PB_Life+Q36*(ShellMW/(ShellMW+PowerMW)/Life_Shell+PowerMW/(ShellMW+PowerMW)/Life_Pow))))*(1-(1+PB_WACC)^-PB_Life)/PB_WACC+(PB_Resid*(F36-Q36)*(1-TaxRate)+Q36*MAX(0,1-PB_Life/PB_HallLife)-TaxRate*(Q36*MAX(0,1-PB_Life/PB_HallLife)-Q36*MAX(0,1-PB_Life*(ShellMW/(ShellMW+PowerMW)/Life_Shell+PowerMW/(ShellMW+PowerMW)/Life_Pow))))*(1+PB_WACC)^-PB_Life -> 6.274695 | P36: =-F36*1+((I36-PB_Corp*H36)-TaxRate*MAX(0,I36-PB_Corp*H36-((F36-Q36)/PB_Life+Q36*(ShellMW/(ShellMW+PowerMW)/Life_Shell+PowerMW/(ShellMW+PowerMW)/Life_Pow))))*(1-(1+PB_WACC)^-PB_Life)/PB_WACC+(PB_Resid*(F36-Q36)*(1-TaxRate)+Q36*MAX(0,1-PB_Life/PB_HallLife)-TaxRate*(Q36*MAX(0,1-PB_Life/PB_HallLife)-Q36*MAX(0,1-PB_Life*(ShellMW/(ShellMW+PowerMW)/Life_Shell+PowerMW/(ShellMW+PowerMW)/Life_Pow))))*(1+PB_WACC)^-PB_Life -> -4.0914091 | Q36: =AVERAGE(INDEX(PathRateSP,1,21),INDEX(PathRateSP,1,22),INDEX(PathRateSP,1,23),INDEX(PathRateSP,1,24)) -> 10.822852
A37: TEST: GB300 IT at $32M capex/IT MW (IT fits 22 mo only at ~$32M = 12 x 32 / (22 - 4.5)) | B37: =IFERROR(F37*1/(H37-G37)*12,999) -> 33.391304 | C37: =IF(ISNUMBER(B37),IF(ABS(B37-PB_Target)<=3,"WITHIN +/-3","outside"),"") -> outside | D37: =IFERROR(F37*1/(MYRate*ND_GrossX-G37)*12,999) -> 26.108553 | E37: =IF(ISNUMBER(D37),IF(ABS(D37-PB_Target)<=3,"WITHIN +/-3","outside"),"") -> outside | F37: =32 -> 32 | G37: =PB_Opex -> 4.5 | H37: =MYRate -> 16 | I37: =H37-G37 -> 11.5 | J37: =IFERROR(RATE(PB_Life,I37,-F37*1,L37),-1) -> 0.25725984 | K37: =IFERROR(RATE(PB_Life,MYRate*ND_GrossX-G37,-F37*1,L37),-1) -> 0.37878174 | L37: =PB_Resid*(F37-Q37)+Q37*MAX(0,1-PB_Life/PB_HallLife) -> 4.8 | M37: =IFERROR(RATE(PB_Life,I37,-F37*1),-1) -> 0.23355169 | N37: =-F37*1+I37*(1-(1+PB_WACC)^-PB_Life)/PB_WACC+L37*(1+PB_WACC)^-PB_Life -> 13.351382 | O37: =-F37*1+(I37-TaxRate*MAX(0,I37-((F37-Q37)/PB_Life+Q37*(ShellMW/(ShellMW+PowerMW)/Life_Shell+PowerMW/(ShellMW+PowerMW)/Life_Pow))))*(1-(1+PB_WACC)^-PB_Life)/PB_WACC+(PB_Resid*(F37-Q37)*(1-TaxRate)+Q37*MAX(0,1-PB_Life/PB_HallLife)-TaxRate*(Q37*MAX(0,1-PB_Life/PB_HallLife)-Q37*MAX(0,1-PB_Life*(ShellMW/(ShellMW+PowerMW)/Life_Shell+PowerMW/(ShellMW+PowerMW)/Life_Pow))))*(1+PB_WACC)^-PB_Life -> 7.7533907 | P37: =-F37*1+((I37-PB_Corp*H37)-TaxRate*MAX(0,I37-PB_Corp*H37-((F37-Q37)/PB_Life+Q37*(ShellMW/(ShellMW+PowerMW)/Life_Shell+PowerMW/(ShellMW+PowerMW)/Life_Pow))))*(1-(1+PB_WACC)^-PB_Life)/PB_WACC+(PB_Resid*(F37-Q37)*(1-TaxRate)+Q37*MAX(0,1-PB_Life/PB_HallLife)-TaxRate*(Q37*MAX(0,1-PB_Life/PB_HallLife)-Q37*MAX(0,1-PB_Life*(ShellMW/(ShellMW+PowerMW)/Life_Shell+PowerMW/(ShellMW+PowerMW)/Life_Pow))))*(1+PB_WACC)^-PB_Life -> -1.4609241 | Q37: =0 -> 0
A38: TEST: GB300 IT with lower opex $2M/IT MW-yr (ex-rent definition) | B38: =IFERROR(F38*1/(H38-G38)*12,999) -> 31.532143 | C38: =IF(ISNUMBER(B38),IF(ABS(B38-PB_Target)<=3,"WITHIN +/-3","outside"),"") -> outside | D38: =IFERROR(F38*1/(MYRate*ND_GrossX-G38)*12,999) -> 25.654028 | E38: =IF(ISNUMBER(D38),IF(ABS(D38-PB_Target)<=3,"WITHIN +/-3","outside"),"") -> outside | F38: =PB_CapGB -> 36.7875 | G38: =2 -> 2 | H38: =MYRate -> 16 | I38: =H38-G38 -> 14 | J38: =IFERROR(RATE(PB_Life,I38,-F38*1,L38),-1) -> 0.28352737 | K38: =IFERROR(RATE(PB_Life,MYRate*ND_GrossX-G38,-F38*1,L38),-1) -> 0.38838216 | L38: =PB_Resid*(F38-Q38)+Q38*MAX(0,1-PB_Life/PB_HallLife) -> 5.518125 | M38: =IFERROR(RATE(PB_Life,I38,-F38*1),-1) -> 0.26139045 | N38: =-F38*1+I38*(1-(1+PB_WACC)^-PB_Life)/PB_WACC+L38*(1+PB_WACC)^-PB_Life -> 18.229797 | O38: =-F38*1+(I38-TaxRate*MAX(0,I38-((F38-Q38)/PB_Life+Q38*(ShellMW/(ShellMW+PowerMW)/Life_Shell+PowerMW/(ShellMW+PowerMW)/Life_Pow))))*(1-(1+PB_WACC)^-PB_Life)/PB_WACC+(PB_Resid*(F38-Q38)*(1-TaxRate)+Q38*MAX(0,1-PB_Life/PB_HallLife)-TaxRate*(Q38*MAX(0,1-PB_Life/PB_HallLife)-Q38*MAX(0,1-PB_Life*(ShellMW/(ShellMW+PowerMW)/Life_Shell+PowerMW/(ShellMW+PowerMW)/Life_Pow))))*(1+PB_WACC)^-PB_Life -> 11.051015 | P38: =-F38*1+((I38-PB_Corp*H38)-TaxRate*MAX(0,I38-PB_Corp*H38-((F38-Q38)/PB_Life+Q38*(ShellMW/(ShellMW+PowerMW)/Life_Shell+PowerMW/(ShellMW+PowerMW)/Life_Pow))))*(1-(1+PB_WACC)^-PB_Life)/PB_WACC+(PB_Resid*(F38-Q38)*(1-TaxRate)+Q38*MAX(0,1-PB_Life/PB_HallLife)-TaxRate*(Q38*MAX(0,1-PB_Life/PB_HallLife)-Q38*MAX(0,1-PB_Life*(ShellMW/(ShellMW+PowerMW)/Life_Shell+PowerMW/(ShellMW+PowerMW)/Life_Pow))))*(1+PB_WACC)^-PB_Life -> 1.8367006 | Q38: =0 -> 0
A39: TEST: GB300 IT with prepayments counted as cash (55% of capex on 70% of deals = 38.5%) | B39: =IFERROR(F39*(1-0.55*0.7)/(H39-G39)*12,999) -> 23.607978 | C39: =IF(ISNUMBER(B39),IF(ABS(B39-PB_Target)<=3,"WITHIN +/-3","outside"),"") -> WITHIN +/-3 | D39: =IFERROR(F39*(1-0.55*0.7)/(MYRate*ND_GrossX-G39)*12,999) -> 18.459002 | E39: =IF(ISNUMBER(D39),IF(ABS(D39-PB_Target)<=3,"WITHIN +/-3","outside"),"") -> outside | F39: =PB_CapGB -> 36.7875 | G39: =PB_Opex -> 4.5 | H39: =MYRate -> 16 | I39: =H39-G39 -> 11.5 | J39: =IFERROR(RATE(PB_Life,I39,-F39*(1-0.55*0.7),L39),-1) -> 0.4447945 | K39: =IFERROR(RATE(PB_Life,MYRate*ND_GrossX-G39,-F39*(1-0.55*0.7),L39),-1) -> 0.60247519 | L39: =PB_Resid*(F39-Q39)+Q39*MAX(0,1-PB_Life/PB_HallLife) -> 5.518125 | M39: =IFERROR(RATE(PB_Life,I39,-F39*(1-0.55*0.7)),-1) -> 0.42038044 | N39: =-F39*(1-0.55*0.7)+I39*(1-(1+PB_WACC)^-PB_Life)/PB_WACC+L39*(1+PB_WACC)^-PB_Life -> 23.153242 | O39: =-F39*(1-0.55*0.7)+(I39-TaxRate*MAX(0,I39-((F39-Q39)/PB_Life+Q39*(ShellMW/(ShellMW+PowerMW)/Life_Shell+PowerMW/(ShellMW+PowerMW)/Life_Pow))))*(1-(1+PB_WACC)^-PB_Life)/PB_WACC+(PB_Resid*(F39-Q39)*(1-TaxRate)+Q39*MAX(0,1-PB_Life/PB_HallLife)-TaxRate*(Q39*MAX(0,1-PB_Life/PB_HallLife)-Q39*MAX(0,1-PB_Life*(ShellMW/(ShellMW+PowerMW)/Life_Shell+PowerMW/(ShellMW+PowerMW)/Life_Pow))))*(1+PB_WACC)^-PB_Life -> 18.358314 | P39: =-F39*(1-0.55*0.7)+((I39-PB_Corp*H39)-TaxRate*MAX(0,I39-PB_Corp*H39-((F39-Q39)/PB_Life+Q39*(ShellMW/(ShellMW+PowerMW)/Life_Shell+PowerMW/(ShellMW+PowerMW)/Life_Pow))))*(1-(1+PB_WACC)^-PB_Life)/PB_WACC+(PB_Resid*(F39-Q39)*(1-TaxRate)+Q39*MAX(0,1-PB_Life/PB_HallLife)-TaxRate*(Q39*MAX(0,1-PB_Life/PB_HallLife)-Q39*MAX(0,1-PB_Life*(ShellMW/(ShellMW+PowerMW)/Life_Shell+PowerMW/(ShellMW+PowerMW)/Life_Pow))))*(1+PB_WACC)^-PB_Life -> 9.1439991 | Q39: =0 -> 0
A40: Implied GB300 revenue/IT MW if management's 22 months INCLUDES prepayments (capex x 61.5% x 12 / 22 + opex) | H40: =PB_CapGB*(1-0.55*0.7)*12/PB_Target+PB_Opex -> 16.840534
A41: NOTE (v0.7b): the 2027+ new-deal price is now set from CONTRACTS ($16M/IT MW base = $3.72/GPU-hr; 5-yr deals $14.5-16M: Microsoft ~$14.5M, Astra ~$15.9M), NOT calibrated to management's 22-month payback. At $16M no row fits 22 months ex-prepayments; with prepayments counted as cash (38.5% of capex) leased GB300 does (~24 months). Management's payback therefore most likely INCLUDES prepayments and/or uses lower opex. Col D 'gross' = MYRate x ND_GrossX (sensitivity only).
A44: D) ASSET FLOOR: PV of EBITDA margin on signed RPO + stakes - net debt - capex still needed for contracted MW ($M)
A45: RPO schedule assumption: 36% ($13.5B) evenly Jul'26-Jun'28 (Q2'26 Note 2); remainder 64% spread evenly Jul'28-Jun'31 (12 qtrs; ~avg remaining tenor: Microsoft 5-yr from late 2025, Meta #2 5-yr from 2027 - assumption). Margin = model adj. EBITDA margin by quarter (FY30 margin after 2030); pre-tax; discounted at WACC from ValDate.
...

Sheet Funding
A1: LEGACY v0.4 parametric funding illustration (v0.7 plan is wired in Inputs FP_*, CashFlow, Valuation POST-FUNDING block) - ESTIMATED (illustrative; DCF value/share already reflects capex; dilution arises only from issuing equity/converts vs model value)
A4: Gap
A5: Minimum liquidity Q3'26-Q4'27 (no plug) | B5: =MIN(INDEX(Liq,1,11):INDEX(Liq,1,16)) -> -4956.4832
A6: Minimum liquidity Q3'26-Q4'28 (no plug) | B6: =MIN(INDEX(Liq,1,11):INDEX(Liq,1,20)) -> -19023.847
A7: Funding need through FY27 = MinCash - min liquidity | B7: =MAX(0,MinCash-FU_Min27) -> 6956.4832
A8: Funding need through FY28 | B8: =MAX(0,MinCash-FU_Min28) -> 21023.847
A9: Plan target (1 = through FY27, 2 = through FY28) | B9: 1
A10: Plan target ($M) | B10: =IF(FU_TgtSel=2,FU_Gap28,FU_Gap27) -> 6956.4832
A11: Model FD value/share (V_PS) and implied FD shares (M) | B11: =V_PS -> 0.01
A12: FD shares at value (M) = V_EQ / V_PS | B12: =IFERROR(V_EQ/V_PS,0) -> -136519.21
A14: Source inputs (Estimated)
A15: ATM: shares remaining (M) | B15: =ATM_Rem -> 12.270507
A16: ATM: issue price = SharePx x (1 - discount/fees) | B16: =SharePx*(1-FU_ATMd) -> 237.9538
A17: ATM discount + fees | B17: 0.02
A18: Customer prepayments: incremental beyond PrepayPct ($M) | B18: 1500 | C18: Q2 letter: >$9B prepayments in 2026; 70% of deals, 50-60% of capex
A19: Prepayment price concession (% of amount, PV cost) | B19: 0
A20: ABS / GPU-backed debt: LTV on GPU net book value at Q2'27 | B20: 0.5
A21: GPU net book value at Q2'27 ($M) | B21: =INDEX(NBV_H,1,14)+INDEX(NBV_B,1,14)+INDEX(NBV_N,1,14) -> 29065.825
A22: ABS capacity ($M) = LTV x GPU NBV, capped | B22: =MIN(FU_LTV*FU_NBV,FU_ABSCap) -> 5000
A23: ABS cap ($M) | B23: 5000
A24: ABS interest rate | B24: 0.09 | C24: memo: cost in WACC; no share dilution
A25: New converts: amount ($M) | B25: 3000
A26: Conversion premium | B26: 0.35
A27: Conversion price | B27: =SharePx*(1+FU_CVPrem) -> 327.7935
A29: Per-source effect if used ALONE at full size (value/share = (V_EQ + equity-like proceeds) / (shares + new shares)) | B29: Proceeds $M | C29: New shares M | D29: Value/share $ | E29: Change $/sh | F29: Dilution %
A30: ATM (all 12.27M sh) | B30: =FU_ATMsh*FU_ATMpx -> 2919.8138 | C30: =FU_ATMsh -> 12.270507 | D30: =(V_EQ+FU_ATMsh*FU_ATMpx)/(FU_N+FU_ATMsh) -> -0.011388591 | E30: =D30-FU_V -> -0.021388591 | F30: =IFERROR(C30/FU_N,0) -> -8.9881177e-05
A31: Customer prepayments | B31: =FU_PreAmt -> 1500 | C31: =0 -> 0 | D31: =FU_V-FU_PreAmt*FU_PreCost/FU_N -> 0.01 | E31: =D31-FU_V -> 0 | F31: =IFERROR(C31/FU_N,0) -> 0
A32: ABS / GPU-backed debt | B32: =FU_ABSMax -> 5000 | C32: =0 -> 0 | D32: =FU_V -> 0.01 | E32: =D32-FU_V -> 0 | F32: =IFERROR(C32/FU_N,0) -> 0
A33: New converts (if converted when value > conv. price) | B33: =FU_CVAmt -> 3000 | C33: =IF(FU_V>FU_CVPx,FU_CVAmt/FU_CVPx,0) -> 0 | D33: =IF(FU_V>FU_CVPx,(V_EQ+FU_CVAmt)/(FU_N+FU_CVAmt/FU_CVPx),FU_V) -> 0.01 | E33: =D33-FU_V -> 0 | F33: =IFERROR(C33/FU_N,0) -> 0
A35: Combined plan to fill the target: order prepayments -> ATM -> ABS -> converts
A36: Prepayments used | B36: =MIN(FU_PreAmt,FU_Tgt) -> 1500
A37: ATM used ($M) | B37: =MIN(FU_ATMsh*FU_ATMpx,FU_Tgt-FU_P1) -> 2919.8138
A38: ABS used | B38: =MIN(FU_ABSMax,FU_Tgt-FU_P1-FU_P2) -> 2536.6695
A39: Converts used | B39: =MIN(FU_CVAmt,FU_Tgt-FU_P1-FU_P2-FU_P3) -> 0
A40: Unfunded remainder (needs equity plug / more sources) | B40: =FU_Tgt-FU_P1-FU_P2-FU_P3-FU_P4 -> 0
A41: New shares: ATM + converts (if converted) | B41: =IFERROR(FU_P2/FU_ATMpx,0)+IF(FU_V>FU_CVPx,FU_P4/FU_CVPx,0) -> 12.270507
A42: Combined value/share | B42: =(V_EQ+FU_P2+IF(FU_V>FU_CVPx,FU_P4,0)-FU_P1*FU_PreCost)/(FU_N+FU_Sh) -> -0.011388591
A43: Change vs model value/share ($) | B43: =FU_VC-FU_V -> -0.021388591
A44: Dilution (% of FD shares) | B44: =IFERROR(FU_Sh/FU_N,0) -> -8.9881177e-05
A45: Memo: ABS annual interest ($M) | B45: =FU_P3*FU_ABSr -> 228.30025

Sheet Outputs
A1: Outputs - key metrics at valuation-date horizons
A2: Horizon quarter = last quarter end on/before EDATE(ValDate, months). LTM = 4 quarters ending at horizon. Per-share value rolled forward at Ke.
A4: Metric | B4: Valuation qtr | C4: +6 months | D4: +1 year | E4: +3 years
A5: Quarter index | B5: =MATCH(EDATE(ValDate,0),Q_End,1) -> 11 | C5: =MATCH(EDATE(ValDate,6),Q_End,1) -> 13 | D5: =MATCH(EDATE(ValDate,12),Q_End,1) -> 15 | E5: =MATCH(EDATE(ValDate,36),Q_End,1) -> 23
A6: Quarter | B6: =INDEX(Q_Lab,1,B5) -> Q3'26 | C6: =INDEX(Q_Lab,1,C5) -> Q1'27 | D6: =INDEX(Q_Lab,1,D5) -> Q3'27 | E6: =INDEX(Q_Lab,1,E5) -> Q3'29
A7: Months from ValDate | B7: 0 | C7: 6 | D7: 12 | E7: 36
A8: Revenue - quarter ($M) | B8: =INDEX(PL_Rev,1,B$5) -> 674.68641 | C8: =INDEX(PL_Rev,1,C$5) -> 1027.6473 | D8: =INDEX(PL_Rev,1,D$5) -> 2114.2851 | E8: =INDEX(PL_Rev,1,E$5) -> 8222.0589
A9: Revenue - LTM ($M) | B9: =SUMPRODUCT(PL_Rev*(Q_Idx>B$5-4)*(Q_Idx<=B$5)) -> 1883.6864 | C9: =SUMPRODUCT(PL_Rev*(Q_Idx>C$5-4)*(Q_Idx<=C$5)) -> 3093.7268 | D9: =SUMPRODUCT(PL_Rev*(Q_Idx>D$5-4)*(Q_Idx<=D$5)) -> 5417.4054 | E9: =SUMPRODUCT(PL_Rev*(Q_Idx>E$5-4)*(Q_Idx<=E$5)) -> 28191.091
A10: Adj. EBITDA - quarter ($M) | B10: =INDEX(PL_EBITDA,1,B$5) -> 263.55961 | C10: =INDEX(PL_EBITDA,1,C$5) -> 503.88198 | D10: =INDEX(PL_EBITDA,1,D$5) -> 1035.6608 | E10: =INDEX(PL_EBITDA,1,E$5) -> 5209.258
A11: Adj. EBITDA - LTM ($M) | B11: =SUMPRODUCT(PL_EBITDA*(Q_Idx>B$5-4)*(Q_Idx<=B$5)) -> 644.25961 | C11: =SUMPRODUCT(PL_EBITDA*(Q_Idx>C$5-4)*(Q_Idx<=C$5)) -> 1325.6728 | D11: =SUMPRODUCT(PL_EBITDA*(Q_Idx>D$5-4)*(Q_Idx<=D$5)) -> 2572.5386 | E11: =SUMPRODUCT(PL_EBITDA*(Q_Idx>E$5-4)*(Q_Idx<=E$5)) -> 17542.11
A12: EBIT - LTM ($M) | B12: =SUMPRODUCT(PL_EBIT*(Q_Idx>B$5-4)*(Q_Idx<=B$5)) -> -888.91445 | C12: =SUMPRODUCT(PL_EBIT*(Q_Idx>C$5-4)*(Q_Idx<=C$5)) -> -1120.7018 | D12: =SUMPRODUCT(PL_EBIT*(Q_Idx>D$5-4)*(Q_Idx<=D$5)) -> -1447.0662 | E12: =SUMPRODUCT(PL_EBIT*(Q_Idx>E$5-4)*(Q_Idx<=E$5)) -> 1594.5792
A13: Free cash flow - LTM ($M) | B13: =SUMPRODUCT(CF_FCF*(Q_Idx>B$5-4)*(Q_Idx<=B$5)) -> -2187.8369 | C13: =SUMPRODUCT(CF_FCF*(Q_Idx>C$5-4)*(Q_Idx<=C$5)) -> -13212.663 | D13: =SUMPRODUCT(CF_FCF*(Q_Idx>D$5-4)*(Q_Idx<=D$5)) -> -28473.198 | E13: =SUMPRODUCT(CF_FCF*(Q_Idx>E$5-4)*(Q_Idx<=E$5)) -> -19545.543
A14: Net debt ($M, model) | B14: =INDEX(CF_NetDebt,1,B$5) -> 2084.3193 | C14: =INDEX(CF_NetDebt,1,C$5) -> 10440.171 | D14: =INDEX(CF_NetDebt,1,D$5) -> 26641.264 | E14: =INDEX(CF_NetDebt,1,E$5) -> 46717.607
A15: Diluted shares (M, at DilPx) | B15: =INDEX(Sh_Dil,1,B$5) -> 314.92525 | C15: =INDEX(Sh_Dil,1,C$5) -> 327.19575 | D15: =INDEX(Sh_Dil,1,D$5) -> 334.23396 | E15: =INDEX(Sh_Dil,1,E$5) -> 414.74756
A16: Active IT MW | B16: =INDEX(MW_Act,1,B$5) -> 182.4897 | C16: =INDEX(MW_Act,1,C$5) -> 301.7195 | D16: =INDEX(MW_Act,1,D$5) -> 629.5368 | E16: =INDEX(MW_Act,1,E$5) -> 1963.8213
A17: Energized IT MW (Capacity) | B17: =INDEX(MW_En,1,B$5) -> 216.9897 | C17: =INDEX(MW_En,1,C$5) -> 453.79225 | D17: =INDEX(MW_En,1,D$5) -> 812.6073 | E17: =INDEX(MW_En,1,E$5) -> 1963.8213
A18: Implied value per share - FD, rolled at Ke ($) | B18: =V_PS*(1+Ke)^(B$7/12) -> 0.01 | C18: =V_PS*(1+Ke)^(C$7/12) -> 0.010630146 | D18: =V_PS*(1+Ke)^(D$7/12) -> 0.0113 | E18: =V_PS*(1+Ke)^(E$7/12) -> 0.01442897
A19: Implied value per share - 308.69M-style basic ($) | B19: =V_PSB*(1+Ke)^(B$7/12) -> -4.4225176 | C19: =V_PSB*(1+Ke)^(C$7/12) -> -4.7012007 | D19: =V_PSB*(1+Ke)^(D$7/12) -> -4.9974449 | E19: =V_PSB*(1+Ke)^(E$7/12) -> -6.3812374
A21: Valuation summary
A22: DCF EV ($M) | B22: =V_EV -> 7854.5901
A23: Market EV at SharePx ($M) | B23: =V_MKTEV -> 74654.719
A24: FD value / share at solved price ($) | B24: =V_PS -> 0.01
A25: 12-month PT ($) | B25: =V_PT -> 2.2868836
A26: Upside vs SharePx | B26: =V_UP -> -0.99058159
A27: Share price ($) | B27: =SharePx -> 242.81
A28: Off-B/S weight used | B28: =OffBSWt -> 0.5
A29: Scenario | B29: =CHOOSE(Scen,"BULL","BASE","BEAR") -> BASE
A32: Model vs consensus (Skeptic, Oct 2 2026) | B32: FY2026 | C32: FY2027 | D32: FY2028
A33: Revenue - model | B33: =SUMIF(Q_Yr,2026,PL_Rev) -> 2465.0795 | C33: =SUMIF(Q_Yr,2027,PL_Rev) -> 7505.4653 | D33: =SUMIF(Q_Yr,2028,PL_Rev) -> 20180.665
A34: Revenue - consensus | B34: =INDEX(Cons_Rev,1,3) -> 3340 | C34: =INDEX(Cons_Rev,1,4) -> 12300 | D34: =INDEX(Cons_Rev,1,5) -> 23000
A35: Revenue - model / consensus - 1 | B35: =IF(N(B34)=0,"n/a",B33/B34-1) -> -0.26195223 | C35: =IF(N(C34)=0,"n/a",C33/C34-1) -> -0.38979957 | D35: =IF(N(D34)=0,"n/a",D33/D34-1) -> -0.1225798
A36: Adj. EBITDA - model | B36: =SUMIF(Q_Yr,2026,PL_EBITDA) -> 951.29083 | C36: =SUMIF(Q_Yr,2027,PL_EBITDA) -> 3713.4637 | D36: =SUMIF(Q_Yr,2028,PL_EBITDA) -> 11755.244
A37: Adj. EBITDA - consensus | B37: =INDEX(Cons_EB,1,3) -> 1390 | C37: =INDEX(Cons_EB,1,4) -> 6730 | D37: =INDEX(Cons_EB,1,5) -> 13980
A38: Adj. EBITDA - model / consensus - 1 | B38: =IF(N(B37)=0,"n/a",B36/B37-1) -> -0.31561811 | C38: =IF(N(C37)=0,"n/a",C36/C37-1) -> -0.44822233 | D38: =IF(N(D37)=0,"n/a",D36/D37-1) -> -0.15913851
A39: Capex - model | B39: =SUMIF(Q_Yr,2026,Capex) -> 17617.717 | C39: =SUMIF(Q_Yr,2027,Capex) -> 33802.871 | D39: =SUMIF(Q_Yr,2028,Capex) -> 26970.82
A40: Capex - consensus | B40: =INDEX(Cons_Cx,1,3) -> 0 | C40: =INDEX(Cons_Cx,1,4) -> 29100 | D40: =INDEX(Cons_Cx,1,5) -> 0
A41: Capex - model / consensus - 1 | B41: =IF(N(B40)=0,"n/a",B39/B40-1) -> n/a | C41: =IF(N(C40)=0,"n/a",C39/C40-1) -> 0.1616107 | D41: =IF(N(D40)=0,"n/a",D39/D40-1) -> n/a
A43: MW sources at YE26 / YE27 (IT MW) | B43: Q4'26 | C43: Q4'27
A44: Energized - Capacity, IT-normalized (YE27 ~950 IT = PLACEHOLDER pending Capacity's Tue basis column; named 185/305/424 & 764/1,069/1,374 mixed basis + unseen) | B44: =INDEX(MW_En,1,12) -> 301.7195 | C44: =INDEX(MW_En,1,16) -> 1081.9108
A45: Mgmt connected guide (800MW-1GW YE26; 1.8 GW YE27) | B45: =INDEX(MW_Gd,1,12) -> 900 | C45: =INDEX(MW_Gd,1,16) -> 1800
...

Sheet Checks
A1: Checks
A3: Check | B3: Model | C3: Target / tolerance | D3: Status | E3: Note
A4: CRITICAL: convert counted in BOTH shares and debt (solved price, chosen weight) | B4: =IF(DilMethod=1,SUMPRODUCT((((CVDebtBasis=1)*Valuation!$E$80:$E$91+(CVDebtBasis>=2)*Valuation!$F$80:$F$91))),IF(DilMethod=2,SUMPRODUCT((V_PSolve>Valuation!$H$80:$H$91)*(((CVDebtBasis=1)*Valuation!$E$80:$E$91+(CVDebtBasis>=2)*Valuation!$F$80:$F$91))),0))+V_CVDEBT-SUMPRODUCT((((CVDebtBasis=1)*Valuation!$E$80:$E$91+(CVDebtBasis>=2)*Valuation!$F$80:$F$91))) -> 0 | C4: 0 | D4: =IF(ABS(B4)<0.5,"OK","DOUBLE COUNT") -> OK | E4: If-converted + debt-counted must equal total (CVDebtBasis: 1 original principal, 2 accreted); net-share (3) keeps principal as debt by design
A5: CRITICAL: same at SharePx (market EV) | B5: =IF(DilMethod=1,SUMPRODUCT((((CVDebtBasis=1)*Valuation!$E$80:$E$91+(CVDebtBasis>=2)*Valuation!$F$80:$F$91))),IF(DilMethod=2,SUMPRODUCT((SharePx>Valuation!$H$80:$H$91)*(((CVDebtBasis=1)*Valuation!$E$80:$E$91+(CVDebtBasis>=2)*Valuation!$F$80:$F$91))),0))+V_CVDmkt-SUMPRODUCT((((CVDebtBasis=1)*Valuation!$E$80:$E$91+(CVDebtBasis>=2)*Valuation!$F$80:$F$91))) -> 0 | C5: 0 | D5: =IF(ABS(B5)<0.5,"OK","DOUBLE COUNT") -> OK
A6: Economic basic shares at Q3'26 (M) = 271.86 + 15.77 + 21.07 | B6: =INDEX(Sh_EconBasic,1,11) -> 308.69115 | C6: 308.69 | D6: =IF(ABS(B6-C6)<0.05,"OK","CHECK") -> OK
A7: Fully diluted at $242.81 EXCL. unsold ATM vs Filings CapStructure | B7: =V_FDmkt -> 369.22679 | C7: =FD_Filings -> 369.2 | D7: =IF(ABS(B7-C7)<2,"OK","CHECK") -> OK | E7: nebius_filings.xlsx CapStructure
A8: Fully diluted at $242.81 INCL. 12.27M ATM vs Filings | B8: =V_FDmkt+ATM_Rem -> 381.4973 | C8: =FD_FilingsATM -> 381.5 | D8: =IF(ABS(B8-C8)<2,"OK","CHECK") -> OK | E8: ATM is a funding source, not in today's count
A9: ITM convert shares at $242.81 (six ITM) | B9: =V_ITMsh -> 50.021939 | C9: =ITM_Sh_Chk -> 50.03 | D9: =IF(ABS(B9-C9)<0.5,"OK","CHECK") -> OK | E9: Steps at $324.65 / $313.46 / $183.22 / $180.31 / $138.75 / $51.45
A10: ITM convert principal at $242.81 ($M orig.) | B10: =V_ITMprin -> 7675 | C10: =ITM_Prin_Chk -> 7680 | D10: =IF(ABS(B10-C10)<15,"OK","CHECK") -> OK
A11: Market EV at $242.81 ($M), CapStructure basis vs Filings ~74.7B | B11: =V_MKTEV -> 74654.719 | C11: 74700 | D11: =IF(ABS(B11/C11-1)<0.01,"OK","CHECK") -> OK | E11: 6/30 balance + Aug notes + exchange; unrestricted cash only
A12: Dilution solve convergence |P15-P14| | B12: =V_CONV -> 0 | C12: 0.01 | D12: =IF(B12<C12,"OK","NOT CONVERGED") -> OK
A13: Microsoft implied TCV vs reported ($M) | B13: =MSFT_Chk -> 0 | C13: 0 | D13: =IF(ABS(B13)<5,"OK","CHECK") -> OK
A14: Quarters (pre-Bloom) Microsoft revenue exceeds ~$350M/qtr genset ceiling | B14: =SUMPRODUCT((MS_CeilChk>0)*(Q_Idx<IF(BloomOn=1,BloomIdx,99))) -> 0 | C14: 0 | D14: =IF(B14=0,"OK","CHECK") -> OK
A15: Q4 bridge: unseen MW vs Skeptic/Capacity 83-200 MW | B15: =BR_MW25 -> 92.646129 | C15: =UnseenChkHi -> 200 | D15: =BR_Chk -> OK - overlaps 83-200 MW
A16: History capex split = reported (sum abs diff) | B16: =SUMPRODUCT(ABS(N(+CapexChk))) -> 0 | C16: 0 | D16: =IF(B16<1,"OK","CHECK") -> OK
A17: Q2'26 book (a) share vs GPU Market 45% (40-46%) | B17: =INDEX(Book_A,1,10)/INDEX(AI_Model,1,10) -> 0.46063494 | C17: =MixA_Q2 -> 0.45 | D17: =IF(AND(ROUND(B17,2)>=0.4,ROUND(B17,2)<=0.46),"OK","CALIBRATE") -> OK
A18: Q2'26 book (b) share vs ~50% (44-57%) | B18: =INDEX(Book_B,1,10)/INDEX(AI_Model,1,10) -> 0.46991652 | C18: =MixB_Q2 -> 0.5 | D18: =IF(AND(B18>=0.44,B18<=0.57),"OK","CALIBRATE") -> OK
A19: Q2'26 book (c) share vs ~4% (1.3-9%) | B19: =INDEX(Book_C,1,10)/INDEX(AI_Model,1,10) -> 0.06944854 | C19: =MixC_Q2 -> 0.04 | D19: =IF(AND(B19>=0.013,B19<=0.09),"OK","CALIBRATE") -> OK
A20: Depreciation-yield flags (drop after chip availability) | B20: =SUM(DepYldFlag) -> 1 | C20: 0 | D20: =IF(B20=0,"OK","FLAG - review PIS dates") -> FLAG - review PIS dates | E20: Material weakness over depreciation start dates
A21: Q3'26 transfer into service | B21: =Q3TransChk -> PENDING (model 4,702) | D21: =B21 -> PENDING (model 4,702)
A22: Sites: named-site energized imports tie to Capacity file COMPANY row (sum abs diff) | B22: =SUMPRODUCT(ABS(CapTie)) -> 0 | C22: 0 | D22: =IF(B22<1,"OK","CHECK") -> OK
A23: Q2'26 tie: model AI cloud revenue vs actual $574.9M | B23: =INDEX(AI_Model,1,10) -> 574.9 | C23: =INDEX(H_AIRev,1,10) -> 574.9 | D23: =IF(ABS(B23/C23-1)<0.01,"OK","CHECK") -> OK | E23: Utilization calibrated
A24: Implied Q2'26 utilization (books b+c) | B24: =UtilQ2 -> 0.75031956 | C24: 40-100% | D24: =UtilFlag -> OK (40-100%) | E24: Flag (not forced) if outside 40-100%
A25: (a) Q2'26 revenue per GPU-hour of capacity (annualized AI rev / GPUs / 8,760) | B25: =INDEX(AI_Model,1,10)*4*1000000/INDEX(GPU_End,1,10)/8760 -> 2.8618773 | C25: =Chk_RevGPUhr -> 3.27 | D25: =IF(ABS(B25/C25-1)<=0.1,"OK","CHECK") -> CHECK | E25: +/-10% (GPU Market, Derived)
A26: (b) Q2'26 annualized AI rev per $ avg gross servers in service | B26: =INDEX(AI_Model,1,10)*4/AVERAGE(INDEX(H_SRV,1,9),INDEX(H_SRV,1,10)) -> 0.46501658 | C26: =Chk_RevSrv -> 0.46 | D26: =IF(ABS(B26/C26-1)<=0.1,"OK","CHECK") -> OK | E26: Filings, Derived
A27: (b3) Capacity server ceiling: Q2'26 GPUs x $45-60k (high end) vs $5.2B servers in service | B27: =INDEX(GPU_End,1,10)*Chk_SrvHi/1000000 -> 5503.62 | C27: =Chk_SrvCap -> 5197.7 | D27: =IF(B27<=C27,"OK: "&TEXT(INDEX(GPU_End,1,10)*Chk_SrvLo/1000000,"#,##0")&"-"&TEXT(B27,"#,##0")&" <= 5,198; implied $"&TEXT(C27*1000000/INDEX(GPU_End,1,10),"#,##0")&"/GPU","FLAG") -> FLAG | E27: Capacity, Estimated
A28: (b2) Modeled in-service GPU cost at 6/30 (GPUs x $/GPU) vs $5.2B servers | B28: =(INDEX(GPU_End_H,1,10)*GPUCost_H+INDEX(GPU_End_B,1,10)*GPUCost_B+INDEX(GPU_End_N,1,10)*GPUCost_N)/1000000 -> 4753.62 | C28: =Chk_SrvCap -> 5197.7 | D28: =IF(B28<=C28,"OK","FLAG: exceeds servers in service") -> OK
A29: (c) Q2'26 revenue per energized MW ($M/yr) | B29: =INDEX(AI_Model,1,10)*4/INDEX(MW_En,1,10) -> 12.601259 | C29: =Chk_RevEnMW -> 13 | D29: =IF(ABS(B29/C29-1)<=0.15,"OK","CHECK") -> OK | E29: ~$13M (2.30B / ~173 MW)
A30: Q2'26 contract (book a) IT MW as share of energized MW | B30: =INDEX(A_MW,1,10)/INDEX(MW_En,1,10) -> 0.55534641 | C30: info | D30: ="INFO" -> INFO | E30: Microsoft GPU use capped at Vineland energized IT MW (39 MW Q2'26) + Meta #1 48 MW (TCV/ACV-derived) vs 173 MW energized; v0.1 fix took Q2'26 utilization from 133% to ~92%
A31: Q2'26 energized MW (Capacity base, IT) | B31: =INDEX(MW_En,1,10) -> 182.4897 | C31: 173 | D31: =IF(ABS(B31-C31)<3,"OK","CHECK") -> CHECK
A32: Q2'26 GPUs: model (Capacity 'GPUs deployed' ~80,416 + GPU anchor gap if GPUAnchorOn) | B32: =INDEX(GPU_End,1,10) -> 91727 | C32: =80416+GPUAnchorD -> 82990 | D32: =IF(ABS(B32/C32-1)<0.01,IF(GPUAnchorOn=1,"INFO: anchored to ~30k at 3/31/25 (+"&TEXT(GPUAnchorD,"#,##0")&" vs Capacity file); Q2 utilization "&TEXT(UtilQ2,"0.0%"),"OK"),"CHECK") -> CHECK
A33: Unexplained ARR residual at 6/30 (June run-rate basis; NOT unseen capacity) | B33: =ARR_Res -> 543.05136 | C33: =ARR_ResTeamLo&"-"&ARR_ResTeamHi -> 650-700 | D33: ="INFO: model "&TEXT(ARR_Res,"#,##0")&" = "&TEXT(ARR_ResMW_TLo,"0")&"-"&TEXT(ARR_ResMW_THi,"0")&" MW-eq at team $13.3-13.5M/MW (model June RR "&TEXT(ARR_RR,"#,##0")&" = $"&TEXT(ARR_RRMW,"0.0")&"M/MW); team-basis residual "&TEXT(ARR_ResTB_Lo,"#,##0")&"-"&TEXT(ARR_ResTB_Hi,"#,##0") -> INFO: model 543 = 40-41 MW-eq at team $13.3-13.5M/MW (model June RR 2,457 = $13.5M/MW); team-basis residual 536-573 | E33: Pending Filings on ARR scope / signed-not-billing
A34: Adj. EBITDA margin FY28 - model vs consensus (flag if > +5pp) | B34: =SUMIF(Q_Yr,2028,PL_EBITDA)/SUMIF(Q_Yr,2028,PL_Rev) -> 0.58250032 | C34: =MarginCons28 -> 0.60782609 | D34: =IF(B34-C34>0.05,"FLAG: model margin > consensus +5pp","OK") -> OK | E34: Skeptic consensus 13.98/23.0
A35: Adj. EBITDA margin FY30 - model vs peer ~62% (flag if > +8pp) | B35: =SUMIF(Q_Yr,2030,PL_EBITDA)/SUMIF(Q_Yr,2030,PL_Rev) -> 0.66407305 | C35: =MarginPeer -> 0.62 | D35: =IF(B35-C35>0.08,"FLAG: above peer +8pp - review opex/MW and revenue/MW","OK") -> OK | E35: CoreWeave ~62% placeholder
A36: FY30 margin sensitivity: PD + SG&A held at FY28 % of revenue (vs placeholder step-down) | B36: =SUMIF(Q_Yr,2030,PL_EBITDA)/SUMIF(Q_Yr,2030,PL_Rev)-(1-OpexHold)*((INDEX(PDpct,1,2028-FYBase)+INDEX(SGApct,1,2028-FYBase))-(INDEX(PDpct,1,2030-FYBase)+INDEX(SGApct,1,2030-FYBase))) -> 0.61407305 | C36: =MarginPeer -> 0.62 | D36: =IF(B36-C36>0.08,"FLAG: still above peer +8pp","INFO: within +8pp of peer") -> INFO: within +8pp of peer | E36: PD 8% + SG&A 10% (FY28) instead of 6% + 7% (FY30); toggle OpexHold=1 for full model effect (Sensitivity)
A37: FY30 opex per avg IT MW ($M/MW-yr: COR + PD + SG&A ex-SBC) | B37: =(SUMIF(Q_Yr,2030,PL_Rev)-SUMIF(Q_Yr,2030,PL_EBITDA))/(SUMIF(Q_Yr,2030,MW_Avg)/4) -> 6.238265 | C37: info | D37: ="INFO: revenue/MW "&TEXT(SUMIF(Q_Yr,2030,PL_Rev)/(SUMIF(Q_Yr,2030,MW_Avg)/4),"0.0") -> INFO: revenue/MW 18.6
A38: FY26 capex vs company guide $20-25B (Aug 12 2026 call) | B38: =SUMIF(Q_Yr,2026,Capex) -> 17617.717 | C38: 20,000-25,000 | D38: =IF(AND(B38>=20000*0.9,B38<=25000*1.1),"OK (within guide +/-10%)","FLAG: outside guide") -> FLAG: outside guide | E38: Fact base: FY2026 capex guidance $20-25B (call transcript, CFO); GPULead calibration
A39: Bull DCF EV vs 3x base (STATIC, snap.py) | B39: =V_EVBullS -> 125122.52 | C39: =3*V_EVBaseS -> 23563.77 | D39: =IF(V_EVBaseS=0,"run snap.py",IF(B39>C39,"FLAG: bull EV > 3x base - review bull drivers","OK")) -> FLAG: bull EV > 3x base - review bull drivers | E39: Bull/base EVs from snapshot
A40: Q2'26 calibration scenario-invariant: utilization bull / bear minus base (STATIC) | B40: =MAX(ABS(V_UtBullS-V_UtBaseS),ABS(V_UtBearS-V_UtBaseS)) -> 0 | C40: 0 | D40: =IF(V_UtBaseS=0,"run snap.py",IF(B40<0.0005,"OK: all scenarios tie $574.9M at "&TEXT(V_UtBaseS,"0.0%"),"FLAG: history depends on scenario")) -> OK: all scenarios tie $574.9M at 75.0%
A41: Implied blended realization vs OD list, Q2'26 books (b)+(c) (billed GPU-hours at Q2 avg list) vs GPU Market 0.72-0.80 | B41: =(INDEX(Book_B,1,LastHist)+INDEX(Book_C,1,LastHist))*1000000/((INDEX(NCA_H,1,LastHist)*ODq_H+INDEX(NCA_B,1,LastHist)*ODq_B+INDEX(NCA_N,1,LastHist)*ODq_N)*INDEX(Q_Hrs,1,LastHist)*UtilQ2) -> 0.74376734 | C41: 0.72-0.80 | D41: =IF(AND(B41>=0.72,B41<=0.8),"OK: within GPU Market range",IF(B41<0.72,"INFO: below range","FLAG: above range")) -> OK: within GPU Market range | E41: Reserved RealRes_B 0.72 x ResSh + on-demand/spot mix
...

Sheet Inputs
A1: Inputs & Assumptions (scenario-driven)
A2: Blue = input. Fill: orange = PLACEHOLDER (no source yet), yellow = Estimated/Consensus, none = Reported/Derived. Live column = CHOOSE(Scenario, Bull, Base, Bear). Owners fill/replace their cells; never overwrite formulas.
A4: Scenario selector (1 = Bull, 2 = Base, 3 = Bear) | D4: 2 | E4: =CHOOSE(Scen,"BULL","BASE","BEAR") -> BASE
A6: Scalar input | B6: Unit | C6: Bull | D6: Base | E6: Bear | F6: LIVE | J6: Owner | K6: Status | L6: Source / method
A7: General
A8: Valuation date | B8: date | C8: — | D8: 46299 | E8: — | F8: =D8 -> 46299 | J8: Modeling | K8: Input | L8: Pitch valuation date; drives DCF discounting and Outputs horizons
A9: Last actual quarter index (10 = Q2'26) | B9: # | C9: — | D9: 10 | E9: — | F9: =D9 -> 10 | J9: Modeling | K9: Input | L9: Roll forward to 11 when Q3'26 is reported
