Workbook

Sheet Cover
A1: Nebius (NBIS) driver-based model
A2: VERSION v0.4 - PROVISIONAL (not final; open items below)
A3: Build date: 2026-10-04. v0.3 base approved (terminal excludes Q4'30 spend for post-horizon MW and that MW; GPU capex lead 3 qtrs vs billing; history scenario-invariant; bear replacement at bear price path; bull Blackwell 6.25% cut after Rubin + next-gen -1.7%/yr).
A4: v0.4 changes: split capex lead (shell/power 3 qtrs, GPUs 2 qtrs ahead of billing); price path year 2+ decline (-2.5/-6/-9.5%) + post-Rubin cut in all scenarios; terminal g from fundamentals (g = RR x RONC, reinvestment deducted); Rubin premium vs GB300 open input at per-MW parity; MW-basis selector; CLT1 rent/prepay; Inferize, June-exit, Vineland-shutdown and peer-margin switches; Funding and Bridge tabs. Also: new-deal pricing for 2027+ MW (multi-year $22M/IT MW-yr + 10% short-term $45M with post-Rubin cut/recovery); customer prepayments 38.5% of new-build capex (toggle); Vineland shutdown wired to Capacity table at $14.5M/IT MW-yr + Bloom-slip toggle; Capacity proposed MW path as MWSel 4 scenario (not base); GPU history anchored to ~30k at 3/31/25.
A5: Key outputs (live, current scenario)
A6: Scenario | B6: =CHOOSE(Scen,"BULL","BASE","BEAR") -> BASE
A7: DCF EV ($M) | B7: =V_EV -> 31798.188
A8: FD value / share ($) | B8: =V_PS -> 70.60249
A9: 12-month PT ($) | B9: =V_PT -> 79.780813
A10: First quarter liquidity < 0 | B10: =Liq_NegQ -> Q3'27
A11: Market EV ($M) | B11: =V_MKTEV -> 74654.719
A13: Notes - open items
A14: OPEN: FY26 capex below the $20-25B guide (Aug 12 2026 call): v0.3 $18.1B (~$1.9B short); v0.4 split lead $16.7B (~$3.3B short); possible early 2027 shell/power or deposits not in the path. Check: Checks 'FY26 capex vs company guide'. | B14: Owner: Filings / Capacity
A15: OPEN: first negative-liquidity quarter (Q2'27 uniform 3-qtr lead vs Q3'27 split lead) is PROVISIONAL pending June MW. | B15: Owner: Capacity
A16: OPEN: Rubin $/GPU-hr premium vs GB300 (no public price; default per-MW parity). New-deal pricing check vs IREN ~$20M/IT MW-yr flags model GB300 contract rate. | B16: Owner: GPU Market
A17: OPEN: AIB CLT1 prepayment (undisclosed; default $0) and Inferize price (press $100-150M, toggle off). | B17: Owner: Filings
A18: OPEN: Vineland shutdown default OFF (VinShutSel 0); scenarios/weights are Capacity judgment (prob-weighted Q4'26 loss ~$68M at $14.5M/IT MW-yr vs Capacity ~$67M); SLA credits undisclosed; genset power saving not credited. | B18: Owner: Capacity
A19: OPEN: Capacity proposed MW path is a scenario only (MWSel 4) until Capacity's Tuesday file; new-deal $/MW basis (IT vs gross) medium-low confidence; short-term share 10% is an estimate. | B19: Owner: Capacity / Filings
A20: OPEN: ARR scope / whether $3.0B ARR includes signed-not-billing tranches; unexplained ARR residual ~$0.6B shown as a line, not plugged. | B20: Owner: Filings
A21: OPEN: YE27 ~950 MW IT normalization is a placeholder pending Capacity's basis column. | B21: Owner: Capacity
A22: OPEN: Q3'26 transfer into service (model $4,702M) pending Q3 filing; depreciation start dates (material weakness) flagged. | B22: Owner: Filings
A23: FLAGS: bull EV > 3x base (bull: multi-year $25M + short-term $50M/IT MW-yr, 6.25% cut); FY30 adj. EBITDA margin 69.9% (just inside peer +8pp; 64.9% if PD/SG&A held at FY28 %); FY26 capex $16.7B below $20-25B guide; bear EV < 0 (equity floored at 0). See Checks. | B23: Owner: Modeling / GPU Market

Sheet README
A1: Nebius (NBIS) driver model - README
A3: Save path: /workspace/nebius/model/nebius_model.xlsx. Quarterly Q1'24-Q2'26 actuals (Hist, tagged Reported/Derived/Estimated/Not disclosed + best estimate + source), Q3'26-Q4'30 forecast, FY roll-ups AI:AO.
A4: Scenario: Inputs!D4 (1 Bull / 2 Base / 3 Bear). Blue = input; orange = placeholder; yellow = estimated/consensus; black = formula.
A5: Flow: Inputs -> Sites (contracted / energized [Capacity file] / mgmt-connected; MWSel; BillLag; PUE basis) -> Pricing -> Contracts (tranches, power ceiling, Q4 bridge) -> Revenue (3 books) -> Capex_DA (vintage cohorts, PISLag, impairment, cap. interest, dep-yield) -> Financing -> PnL -> CashFlow -> Shares -> Valuation (DCF, dilution solve, EV bridge, EV/MW) -> KPIs / Outputs / Sensitivity / Checks.
A6: Circularity: no Excel iterative calc needed. Valuation solves value/share by 15 unrolled fixed-point steps; DilPxMode 1 = SharePx for quarterly dilution.
A7: Converts: DilMethod 1 if-converted all / 2 ITM only (default; step dilution at conversion prices) / 3 net-share. Converted principal is removed from debt (Checks row 1).
A8: Static snapshot tables on Outputs / Sensitivity / Valuation memo rows / Checks (bull 3x, scenario-invariance) come from LibreOffice recalcs in snap.py; re-run snap.py after changing inputs.

Sheet Bridge
A1: EV bridge v0.1 -> v0.3 -> v0.4 (STATIC, filled by snap.py)
A2: Base scenario. Each row = cumulative settings recomputed in the CURRENT model (bug fixes such as the renewal-formula bracket and scenario-invariant history are in every row). $B and $/share are FD value/share.
A4: Step | B4: DCF EV $B | C4: Change $B | D4: FD $/share | E4: Change $/sh | F4: 12m PT $ | G4: FY26 rev $M | H4: FY27 rev $M | I4: FY28 rev $M | J4: FY27 EBITDA $M | K4: YE27 liquidity $M | L4: First neg. qtr
A5: v0.1 (as reported) | B5: 45.499764 | D5: 117.21424 | F5: 132.45209 | G5: 2400.637 | H5: 8242.0189 | I5: 22266.612 | J5: 4575.8582 | K5: -4456.7617 | L5: Q4'27
A6: + fleet ratio forecast-only / capex on driver MW (FixMgmt) | B6: 48.823167 | C6: 3.3234033 | D6: 127.47273 | E6: 10.258497 | F6: 144.04419 | G6: 2400.637 | H6: 8242.0189 | I6: 22266.612 | J6: 4606.0461 | K6: -4408.0848 | L6: Q4'27
A7: + terminal on Q4'30 exit incl. Q1'31 MW (include both) | B7: 102.75467 | C7: 53.931501 | D7: 277.20861 | E7: 149.73587 | F7: 313.24573 | G7: 2400.637 | H7: 8242.0189 | I7: 22266.612 | J7: 4606.0461 | K7: -4408.0848 | L7: Q4'27
A8: + TV run-off floor | B8: 102.75467 | C8: 0 | D8: 277.20861 | E8: 0 | F8: 313.24573 | G8: 2400.637 | H8: 8242.0189 | I8: 22266.612 | J8: 4606.0461 | K8: -4408.0848 | L8: Q4'27
A9: + owned-site O&M | B9: 91.634048 | C9: -11.12062 | D9: 247.25781 | E9: -29.950795 | F9: 279.40133 | G9: 2400.637 | H9: 8242.0189 | I9: 22266.612 | J9: 4517.4726 | K9: -4518.475 | L9: Q4'27
A10: + H2'26 repricing (= v0.2) | B10: 102.45081 | C10: 10.816757 | D10: 276.36392 | E10: 29.106113 | F10: 312.29124 | G10: 2425.3295 | H10: 8517.5153 | I10: 22648.736 | J10: 4713.075 | K10: -4310.0666 | L10: Q4'27
A11: + exclude both Q4'30 spend & Q1'31 MW | B11: 86.363871 | C11: -16.086934 | D11: 233.08315 | E11: -43.280772 | F11: 263.38396 | G11: 2425.3295 | H11: 8517.5153 | I11: 22648.736 | J11: 4713.075 | K11: -4310.0666 | L11: Q4'27
A12: + GPU capex lead 3 qtrs (= v0.3) | B12: 94.115927 | C12: 7.7520558 | D12: 248.19387 | E12: 15.110715 | F12: 280.45907 | G12: 2425.3295 | H12: 8517.5153 | I12: 22648.736 | J12: 4713.075 | K12: -7264.8692 | L12: Q2'27
A13: + split capex lead: shell/power 3, GPUs 2 qtrs | B13: 87.921521 | C13: -6.1944054 | D13: 233.7087 | E13: -14.485164 | F13: 264.09084 | G13: 2425.3295 | H13: 8517.5153 | I13: 22648.736 | J13: 4713.075 | K13: -7160.9335 | L13: Q3'27
A14: + price path: post-Rubin cut 22% + -6%/yr from year 2 | B14: 94.973211 | C14: 7.0516897 | D14: 252.68078 | E14: 18.972078 | F14: 285.52928 | G14: 2425.3295 | H14: 8102.5841 | I14: 22384.539 | J14: 4418.4739 | K14: -7450.3255 | L14: Q3'27
A15: + Rubin premium at per-MW parity (1.56x GB300) | B15: 153.79061 | C15: 58.817396 | D15: 406.65048 | E15: 153.9697 | F15: 459.51504 | G15: 2425.3295 | H15: 8140.6586 | I15: 24633.629 | J15: 4445.5068 | K15: -7423.7798 | L15: Q3'27
A16: + CLT1 rent $2.2M/IT MW-yr | B16: 154.02622 | C16: 0.23561158 | D16: 407.25495 | E16: 0.60447567 | F16: 460.1981 | G16: 2425.3295 | H16: 8140.6586 | I16: 24633.629 | J16: 4447.4208 | K16: -7421.8657 | L16: Q3'27
A17: + terminal g from fundamentals | B17: 125.81969 | C17: -28.206529 | D17: 334.88941 | E17: -72.365546 | F17: 378.42503 | G17: 2425.3295 | H17: 8140.6586 | I17: 24633.629 | J17: 4447.4208 | K17: -7421.8657 | L17: Q3'27
... A20: + GPU history anchor ~30k at 3/31/25 (= v0.4) | B20: 31.798188 | C20: -0.086589062 | D20: 70.60249 | E20: -0.27124604 | F20: 79.780813 | G20: 2423.4083 | H20: 7320.2931 | I20: 19024.884 | J20: 3864.9613 | K20: -8054.4407 | L20: Q3'27
A23: Horizon per-share values (FD value/share rolled at Ke; excludes future funding dilution - see Funding tab)
A24: Scenario | B24: Today | C24: 6-month | D24: 12-month PT | E24: 3-year
A25: Base (live) | B25: 70.60249 | C25: 75.051476 | D25: 79.780813 | E25: 101.87212
A26: Bull | B26: 478.55841 | C26: 506.45862 | D26: 535.98542 | E26: 672.34011
A27: Bear | B27: 0.01 | C27: 0.010723805 | D27: 0.0115 | E27: 0.01520875
A30: New-MW pricing vs IREN >$20M/IT MW-yr ($M per IT MW-yr). GB300 GPU-hour engine (legacy fleet) at Oct-1 list x RealRes x Util_Res; new 2027+ MW at new-deal blend (col G)
A31: Scenario | B31: GB300 gross | C31: net leased (-$2.2M rent) | D31: net owned (-O&M) | E31: Rubin gross | F31: IREN gross / leased / owned | G31: New-deal blend gross
A32: Base (live) | B32: 30.157546 | C32: 27.957546 | D32: 29.407546 | E32: 30.157546 | F32: 20.0 / 17.8 / 19.25 | G32: 22.221
A33: Bull | B33: 43.041696 | C33: 40.841696 | D33: 42.291696 | E33: 43.041696 | F33: 20.0 / 17.8 / 19.25 | G33: 26.835938
A34: Bear | B34: 22.272793 | C34: 20.072793 | D34: 21.522793 | E34: 22.272793 | F34: 20.0 / 17.8 / 19.25 | G34: 19.365

Sheet Funding
A1: Funding plan for the liquidity gap - parametric, ESTIMATED (illustrative; DCF value/share already reflects capex; dilution arises only from issuing equity/converts vs model value)
A4: Gap
A5: Minimum liquidity Q3'26-Q4'27 (no plug) | B5: =MIN(INDEX(Liq,1,11):INDEX(Liq,1,16)) -> -8054.4407
A6: Minimum liquidity Q3'26-Q4'28 (no plug) | B6: =MIN(INDEX(Liq,1,11):INDEX(Liq,1,20)) -> -16951.945
A7: Funding need through FY27 = MinCash - min liquidity | B7: =MAX(0,MinCash-FU_Min27) -> 10054.441
A8: Funding need through FY28 | B8: =MAX(0,MinCash-FU_Min28) -> 18951.945
A9: Plan target (1 = through FY27, 2 = through FY28) | B9: 1
A10: Plan target ($M) | B10: =IF(FU_TgtSel=2,FU_Gap28,FU_Gap27) -> 10054.441
A11: Model FD value/share (V_PS) and implied FD shares (M) | B11: =V_PS -> 70.60249
A12: FD shares at value (M) = V_EQ / V_PS | B12: =IFERROR(V_EQ/V_PS,0) -> 318.3266
A14: Source inputs (Estimated)
A15: ATM: shares remaining (M) | B15: =ATM_Rem -> 12.270507
A16: ATM: issue price = SharePx x (1 - discount/fees) | B16: =SharePx*(1-FU_ATMd) -> 237.9538
A17: ATM discount + fees | B17: 0.02
A18: Customer prepayments: incremental beyond PrepayPct ($M) | B18: 1500 | C18: Q2 letter: >$9B prepayments in 2026; 70% of deals, 50-60% of capex
A19: Prepayment price concession (% of amount, PV cost) | B19: 0
A20: ABS / GPU-backed debt: LTV on GPU net book value at Q2'27 | B20: 0.5
A21: GPU net book value at Q2'27 ($M) | B21: =INDEX(NBV_H,1,14)+INDEX(NBV_B,1,14)+INDEX(NBV_N,1,14) -> 25049.023
A22: ABS capacity ($M) = LTV x GPU NBV, capped | B22: =MIN(FU_LTV*FU_NBV,FU_ABSCap) -> 5000
A23: ABS cap ($M) | B23: 5000
A24: ABS interest rate | B24: 0.09 | C24: memo: cost in WACC; no share dilution
A25: New converts: amount ($M) | B25: 3000
A26: Conversion premium | B26: 0.35
A27: Conversion price | B27: =SharePx*(1+FU_CVPrem) -> 327.7935
A29: Per-source effect if used ALONE at full size (value/share = (V_EQ + equity-like proceeds) / (shares + new shares)) | B29: Proceeds $M | C29: New shares M | D29: Value/share $ | E29: Change $/sh | F29: Dilution %
A30: ATM (all 12.27M sh) | B30: =FU_ATMsh*FU_ATMpx -> 2919.8138 | C30: =FU_ATMsh -> 12.270507 | D30: =(V_EQ+FU_ATMsh*FU_ATMpx)/(FU_N+FU_ATMsh) -> 76.813934 | E30: =D30-FU_V -> 6.2114441 | F30: =IFERROR(C30/FU_N,0) -> 0.038546911
A31: Customer prepayments | B31: =FU_PreAmt -> 1500 | C31: =0 -> 0 | D31: =FU_V-FU_PreAmt*FU_PreCost/FU_N -> 70.60249 | E31: =D31-FU_V -> 0 | F31: =IFERROR(C31/FU_N,0) -> 0
A32: ABS / GPU-backed debt | B32: =FU_ABSMax -> 5000 | C32: =0 -> 0 | D32: =FU_V -> 70.60249 | E32: =D32-FU_V -> 0 | F32: =IFERROR(C32/FU_N,0) -> 0
A33: New converts (if converted when value > conv. price) | B33: =FU_CVAmt -> 3000 | C33: =IF(FU_V>FU_CVPx,FU_CVAmt/FU_CVPx,0) -> 0 | D33: =IF(FU_V>FU_CVPx,(V_EQ+FU_CVAmt)/(FU_N+FU_CVAmt/FU_CVPx),FU_V) -> 70.60249 | E33: =D33-FU_V -> 0 | F33: =IFERROR(C33/FU_N,0) -> 0
A35: Combined plan to fill the target: order prepayments -> ATM -> ABS -> converts
A36: Prepayments used | B36: =MIN(FU_PreAmt,FU_Tgt) -> 1500
A37: ATM used ($M) | B37: =MIN(FU_ATMsh*FU_ATMpx,FU_Tgt-FU_P1) -> 2919.8138
A38: ABS used | B38: =MIN(FU_ABSMax,FU_Tgt-FU_P1-FU_P2) -> 5000
A39: Converts used | B39: =MIN(FU_CVAmt,FU_Tgt-FU_P1-FU_P2-FU_P3) -> 634.62691
A40: Unfunded remainder (needs equity plug / more sources) | B40: =FU_Tgt-FU_P1-FU_P2-FU_P3-FU_P4 -> 0
A41: New shares: ATM + converts (if converted) | B41: =IFERROR(FU_P2/FU_ATMpx,0)+IF(FU_V>FU_CVPx,FU_P4/FU_CVPx,0) -> 12.270507
A42: Combined value/share | B42: =(V_EQ+FU_P2+IF(FU_V>FU_CVPx,FU_P4,0)-FU_P1*FU_PreCost)/(FU_N+FU_Sh) -> 76.813934
A43: Change vs model value/share ($) | B43: =FU_VC-FU_V -> 6.2114441
A44: Dilution (% of FD shares) | B44: =IFERROR(FU_Sh/FU_N,0) -> 0.038546911
A45: Memo: ABS annual interest ($M) | B45: =FU_P3*FU_ABSr -> 450

Sheet Outputs
A1: Outputs - key metrics at valuation-date horizons
A2: Horizon quarter = last quarter end on/before EDATE(ValDate, months). LTM = 4 quarters ending at horizon. Per-share value rolled forward at Ke.
A4: Metric | B4: Valuation qtr | C4: +6 months | D4: +1 year | E4: +3 years
A5: Quarter index | B5: =MATCH(EDATE(ValDate,0),Q_End,1) -> 11 | C5: =MATCH(EDATE(ValDate,6),Q_End,1) -> 13 | D5: =MATCH(EDATE(ValDate,12),Q_End,1) -> 15 | E5: =MATCH(EDATE(ValDate,36),Q_End,1) -> 23
A6: Quarter | B6: =INDEX(Q_Lab,1,B5) -> Q3'26 | C6: =INDEX(Q_Lab,1,C5) -> Q1'27 | D6: =INDEX(Q_Lab,1,D5) -> Q3'27 | E6: =INDEX(Q_Lab,1,E5) -> Q3'29
A7: Months from ValDate | B7: 0 | C7: 6 | D7: 12 | E7: 36
A8: Revenue - quarter ($M) | B8: =INDEX(PL_Rev,1,B$5) -> 653.68337 | C8: =INDEX(PL_Rev,1,C$5) -> 1031.8302 | D8: =INDEX(PL_Rev,1,D$5) -> 2078.1607 | E8: =INDEX(PL_Rev,1,E$5) -> 7930.671
A9: Revenue - LTM ($M) | B9: =SUMPRODUCT(PL_Rev*(Q_Idx>B$5-4)*(Q_Idx<=B$5)) -> 1862.6834 | C9: =SUMPRODUCT(PL_Rev*(Q_Idx>C$5-4)*(Q_Idx<=C$5)) -> 3056.2386 | D9: =SUMPRODUCT(PL_Rev*(Q_Idx>D$5-4)*(Q_Idx<=D$5)) -> 5407.2922 | E9: =SUMPRODUCT(PL_Rev*(Q_Idx>E$5-4)*(Q_Idx<=E$5)) -> 27077.234
A10: Adj. EBITDA - quarter ($M) | B10: =INDEX(PL_EBITDA,1,B$5) -> 273.75168 | C10: =INDEX(PL_EBITDA,1,C$5) -> 527.80279 | D10: =INDEX(PL_EBITDA,1,D$5) -> 1094.1084 | E10: =INDEX(PL_EBITDA,1,E$5) -> 5308.1796
A11: Adj. EBITDA - LTM ($M) | B11: =SUMPRODUCT(PL_EBITDA*(Q_Idx>B$5-4)*(Q_Idx<=B$5)) -> 654.45168 | C11: =SUMPRODUCT(PL_EBITDA*(Q_Idx>C$5-4)*(Q_Idx<=C$5)) -> 1366.8227 | D11: =SUMPRODUCT(PL_EBITDA*(Q_Idx>D$5-4)*(Q_Idx<=D$5)) -> 2730.2601 | E11: =SUMPRODUCT(PL_EBITDA*(Q_Idx>E$5-4)*(Q_Idx<=E$5)) -> 17837.489
A12: EBIT - LTM ($M) | B12: =SUMPRODUCT(PL_EBIT*(Q_Idx>B$5-4)*(Q_Idx<=B$5)) -> -877.88226 | C12: =SUMPRODUCT(PL_EBIT*(Q_Idx>C$5-4)*(Q_Idx<=C$5)) -> -1088.8246 | D12: =SUMPRODUCT(PL_EBIT*(Q_Idx>D$5-4)*(Q_Idx<=D$5)) -> -1150.6926 | E12: =SUMPRODUCT(PL_EBIT*(Q_Idx>E$5-4)*(Q_Idx<=E$5)) -> 4011.6486
A13: Free cash flow - LTM ($M) | B13: =SUMPRODUCT(CF_FCF*(Q_Idx>B$5-4)*(Q_Idx<=B$5)) -> -2389.4603 | C13: =SUMPRODUCT(CF_FCF*(Q_Idx>C$5-4)*(Q_Idx<=C$5)) -> -9536.4181 | D13: =SUMPRODUCT(CF_FCF*(Q_Idx>D$5-4)*(Q_Idx<=D$5)) -> -17500.64 | E13: =SUMPRODUCT(CF_FCF*(Q_Idx>E$5-4)*(Q_Idx<=E$5)) -> -12798.456
A14: Net debt ($M, model) | B14: =INDEX(CF_NetDebt,1,B$5) -> 2101.5381 | C14: =INDEX(CF_NetDebt,1,C$5) -> 9453.4087 | D14: =INDEX(CF_NetDebt,1,D$5) -> 16316.63 | E14: =INDEX(CF_NetDebt,1,E$5) -> 29154.149
A15: Diluted shares (M, at DilPx) | B15: =INDEX(Sh_Dil,1,B$5) -> 318.3266 | C15: =INDEX(Sh_Dil,1,C$5) -> 318.3266 | D15: =INDEX(Sh_Dil,1,D$5) -> 334.02128 | E15: =INDEX(Sh_Dil,1,E$5) -> 385.03266
A16: Active IT MW | B16: =INDEX(MW_Act,1,B$5) -> 173 | C16: =INDEX(MW_Act,1,C$5) -> 292.4 | D16: =INDEX(MW_Act,1,D$5) -> 545.1 | E16: =INDEX(MW_Act,1,E$5) -> 1875
A17: Energized IT MW (Capacity) | B17: =INDEX(MW_En,1,B$5) -> 207.5 | C17: =INDEX(MW_En,1,C$5) -> 416.4 | D17: =INDEX(MW_En,1,D$5) -> 684.5 | E17: =INDEX(MW_En,1,E$5) -> 1875
A18: Implied value per share - FD, rolled at Ke ($) | B18: =V_PS*(1+Ke)^(B$7/12) -> 70.60249 | C18: =V_PS*(1+Ke)^(C$7/12) -> 75.051476 | D18: =V_PS*(1+Ke)^(D$7/12) -> 79.780813 | E18: =V_PS*(1+Ke)^(E$7/12) -> 101.87212
A19: Implied value per share - 308.69M-style basic ($) | B19: =V_PSB*(1+Ke)^(B$7/12) -> 72.204103 | C19: =V_PSB*(1+Ke)^(C$7/12) -> 76.754014 | D19: =V_PSB*(1+Ke)^(D$7/12) -> 81.590636 | E19: =V_PSB*(1+Ke)^(E$7/12) -> 104.18308
A21: Valuation summary
A22: DCF EV ($M) | B22: =V_EV -> 31798.188
A23: Market EV at SharePx ($M) | B23: =V_MKTEV -> 74654.719
A24: FD value / share at solved price ($) | B24: =V_PS -> 70.60249
A25: 12-month PT ($) | B25: =V_PT -> 79.780813
A26: Upside vs SharePx | B26: =V_UP -> -0.67142699
A27: Share price ($) | B27: =SharePx -> 242.81
A28: Off-B/S weight used | B28: =OffBSWt -> 0.5
A29: Scenario | B29: =CHOOSE(Scen,"BULL","BASE","BEAR") -> BASE
A32: Model vs consensus (Skeptic, Oct 2 2026) | B32: FY2026 | C32: FY2027 | D32: FY2028
A33: Revenue - model | B33: =SUMIF(Q_Yr,2026,PL_Rev) -> 2423.4083 | C33: =SUMIF(Q_Yr,2027,PL_Rev) -> 7320.2931 | D33: =SUMIF(Q_Yr,2028,PL_Rev) -> 19024.884
A34: Revenue - consensus | B34: =INDEX(Cons_Rev,1,3) -> 3340 | C34: =INDEX(Cons_Rev,1,4) -> 12300 | D34: =INDEX(Cons_Rev,1,5) -> 23000
A35: Revenue - model / consensus - 1 | B35: =IF(N(B34)=0,"n/a",B33/B34-1) -> -0.27442864 | C35: =IF(N(C34)=0,"n/a",C33/C34-1) -> -0.40485422 | D35: =IF(N(D34)=0,"n/a",D33/D34-1) -> -0.17283112
A36: Adj. EBITDA - model | B36: =SUMIF(Q_Yr,2026,PL_EBITDA) -> 968.51992 | C36: =SUMIF(Q_Yr,2027,PL_EBITDA) -> 3864.9613 | D36: =SUMIF(Q_Yr,2028,PL_EBITDA) -> 11759.932
A37: Adj. EBITDA - consensus | B37: =INDEX(Cons_EB,1,3) -> 1390 | C37: =INDEX(Cons_EB,1,4) -> 6730 | D37: =INDEX(Cons_EB,1,5) -> 13980
A38: Adj. EBITDA - model / consensus - 1 | B38: =IF(N(B37)=0,"n/a",B36/B37-1) -> -0.30322308 | C38: =IF(N(C37)=0,"n/a",C36/C37-1) -> -0.42571154 | D38: =IF(N(D37)=0,"n/a",D36/D37-1) -> -0.15880314
A39: Capex - model | B39: =SUMIF(Q_Yr,2026,Capex) -> 16720.342 | C39: =SUMIF(Q_Yr,2027,Capex) -> 27433.206 | D39: =SUMIF(Q_Yr,2028,Capex) -> 23663.898
A40: Capex - consensus | B40: =INDEX(Cons_Cx,1,3) -> 0 | C40: =INDEX(Cons_Cx,1,4) -> 29100 | D40: =INDEX(Cons_Cx,1,5) -> 0
A41: Capex - model / consensus - 1 | B41: =IF(N(B40)=0,"n/a",B39/B40-1) -> n/a | C41: =IF(N(C40)=0,"n/a",C39/C40-1) -> -0.057278149 | D41: =IF(N(D40)=0,"n/a",D39/D40-1) -> n/a
A43: MW sources at YE26 / YE27 (IT MW) | B43: Q4'26 | C43: Q4'27
A44: Energized - Capacity, IT-normalized (YE27 ~950 IT = PLACEHOLDER pending Capacity's Tue basis column; named 185/305/424 & 764/1,069/1,374 mixed basis + unseen) | B44: =INDEX(MW_En,1,12) -> 292.4 | C44: =INDEX(MW_En,1,16) -> 950
A45: Mgmt connected guide (800MW-1GW YE26; 1.8 GW YE27) | B45: =INDEX(MW_Gd,1,12) -> 900 | C45: =INDEX(MW_Gd,1,16) -> 1800
...

Sheet Checks
A1: Checks
A3: Check | B3: Model | C3: Target / tolerance | D3: Status | E3: Note
A4: CRITICAL: convert counted in BOTH shares and debt (solved price, chosen weight) | B4: =IF(DilMethod=1,SUM(Valuation!$F$73:$F$80),IF(DilMethod=2,SUMPRODUCT((V_PSolve>Valuation!$H$73:$H$80)*Valuation!$F$73:$F$80),0))+V_CVDEBT-SUM(Valuation!$F$73:$F$80) -> 0 | C4: 0 | D4: =IF(ABS(B4)<0.5,"OK","DOUBLE COUNT") -> OK | E4: If-converted principal + debt-counted principal must equal total accreted balance; net-share (3) keeps principal as debt by design
A5: CRITICAL: same at SharePx (market EV) | B5: =IF(DilMethod=1,SUM(Valuation!$F$73:$F$80),IF(DilMethod=2,SUMPRODUCT((SharePx>Valuation!$H$73:$H$80)*Valuation!$F$73:$F$80),0))+V_CVDmkt-SUM(Valuation!$F$73:$F$80) -> 0 | C5: 0 | D5: =IF(ABS(B5)<0.5,"OK","DOUBLE COUNT") -> OK
A6: Economic basic shares at Q3'26 (M) = 271.86 + 15.77 + 21.07 | B6: =INDEX(Sh_EconBasic,1,11) -> 308.69115 | C6: 308.69 | D6: =IF(ABS(B6-C6)<0.05,"OK","CHECK") -> OK
A7: Fully diluted at $242.81 EXCL. unsold ATM vs Filings CapStructure | B7: =V_FDmkt -> 369.22679 | C7: =FD_Filings -> 369.2 | D7: =IF(ABS(B7-C7)<2,"OK","CHECK") -> OK | E7: nebius_filings.xlsx CapStructure
A8: Fully diluted at $242.81 INCL. 12.27M ATM vs Filings | B8: =V_FDmkt+ATM_Rem -> 381.4973 | C8: =FD_FilingsATM -> 381.5 | D8: =IF(ABS(B8-C8)<2,"OK","CHECK") -> OK | E8: ATM is a funding source, not in today's count
A9: ITM convert shares at $242.81 (six ITM) | B9: =V_ITMsh -> 50.021939 | C9: =ITM_Sh_Chk -> 50.03 | D9: =IF(ABS(B9-C9)<0.5,"OK","CHECK") -> OK | E9: Steps at $324.65 / $313.46 / $183.22 / $180.31 / $138.75 / $51.45
A10: ITM convert principal at $242.81 ($M orig.) | B10: =V_ITMprin -> 7675 | C10: =ITM_Prin_Chk -> 7680 | D10: =IF(ABS(B10-C10)<15,"OK","CHECK") -> OK
A11: Market EV at $242.81 ($M), CapStructure basis vs Filings ~74.7B | B11: =V_MKTEV -> 74654.719 | C11: 74700 | D11: =IF(ABS(B11/C11-1)<0.01,"OK","CHECK") -> OK | E11: 6/30 balance + Aug notes + exchange; unrestricted cash only
A12: Dilution solve convergence |P15-P14| | B12: =V_CONV -> 0 | C12: 0.01 | D12: =IF(B12<C12,"OK","NOT CONVERGED") -> OK
A13: Microsoft implied TCV vs reported ($M) | B13: =MSFT_Chk -> 0 | C13: 0 | D13: =IF(ABS(B13)<5,"OK","CHECK") -> OK
A14: Quarters (pre-Bloom) Microsoft revenue exceeds ~$350M/qtr genset ceiling | B14: =SUMPRODUCT((MS_CeilChk>0)*(Q_Idx<IF(BloomOn=1,BloomIdx,99))) -> 0 | C14: 0 | D14: =IF(B14=0,"OK","CHECK") -> OK
A15: Q4 bridge: unseen MW vs Skeptic/Capacity 83-200 MW | B15: =BR_MW25 -> 92.646129 | C15: =UnseenChkHi -> 200 | D15: =BR_Chk -> OK - overlaps 83-200 MW
A16: History capex split = reported (sum abs diff) | B16: =SUMPRODUCT(ABS(N(+CapexChk))) -> 0 | C16: 0 | D16: =IF(B16<1,"OK","CHECK") -> OK
A17: Q2'26 book (a) share vs GPU Market 45% (40-46%) | B17: =INDEX(Book_A,1,10)/INDEX(AI_Model,1,10) -> 0.46063494 | C17: =MixA_Q2 -> 0.45 | D17: =IF(AND(ROUND(B17,2)>=0.4,ROUND(B17,2)<=0.46),"OK","CALIBRATE") -> OK
A18: Q2'26 book (b) share vs ~50% (44-57%) | B18: =INDEX(Book_B,1,10)/INDEX(AI_Model,1,10) -> 0.46986058 | C18: =MixB_Q2 -> 0.5 | D18: =IF(AND(B18>=0.44,B18<=0.57),"OK","CALIBRATE") -> OK
A19: Q2'26 book (c) share vs ~4% (1.3-9%) | B19: =INDEX(Book_C,1,10)/INDEX(AI_Model,1,10) -> 0.069504476 | C19: =MixC_Q2 -> 0.04 | D19: =IF(AND(B19>=0.013,B19<=0.09),"OK","CALIBRATE") -> OK
A20: Depreciation-yield flags (drop after chip availability) | B20: =SUM(DepYldFlag) -> 1 | C20: 0 | D20: =IF(B20=0,"OK","FLAG - review PIS dates") -> FLAG - review PIS dates | E20: Material weakness over depreciation start dates
A21: Q3'26 transfer into service | B21: =Q3TransChk -> PENDING (model 4,702) | D21: =B21 -> PENDING (model 4,702)
A22: Sites: named-site energized imports tie to Capacity file COMPANY row (sum abs diff) | B22: =SUMPRODUCT(ABS(CapTie)) -> 0 | C22: 0 | D22: =IF(B22<1,"OK","CHECK") -> OK
A23: Q2'26 tie: model AI cloud revenue vs actual $574.9M | B23: =INDEX(AI_Model,1,10) -> 574.9 | C23: =INDEX(H_AIRev,1,10) -> 574.9 | D23: =IF(ABS(B23/C23-1)<0.01,"OK","CHECK") -> OK | E23: Utilization calibrated
A24: Implied Q2'26 utilization (books b+c) | B24: =UtilQ2 -> 0.82509879 | C24: 40-100% | D24: =UtilFlag -> OK (40-100%) | E24: Flag (not forced) if outside 40-100%
A25: (a) Q2'26 revenue per GPU-hour of capacity (annualized AI rev / GPUs / 8,760) | B25: =INDEX(AI_Model,1,10)*4*1000000/INDEX(GPU_End,1,10)/8760 -> 2.9670688 | C25: =Chk_RevGPUhr -> 3.27 | D25: =IF(ABS(B25/C25-1)<=0.1,"OK","CHECK") -> OK | E25: +/-10% (GPU Market, Derived)
A26: (b) Q2'26 annualized AI rev per $ avg gross servers in service | B26: =INDEX(AI_Model,1,10)*4/AVERAGE(INDEX(H_SRV,1,9),INDEX(H_SRV,1,10)) -> 0.46501658 | C26: =Chk_RevSrv -> 0.46 | D26: =IF(ABS(B26/C26-1)<=0.1,"OK","CHECK") -> OK | E26: Filings, Derived
A27: (b3) Capacity server ceiling: Q2'26 GPUs x $45-60k (high end) vs $5.2B servers in service | B27: =INDEX(GPU_End,1,10)*Chk_SrvHi/1000000 -> 5308.5 | C27: =Chk_SrvCap -> 5197.7 | D27: =IF(B27<=C27,"OK: "&TEXT(INDEX(GPU_End,1,10)*Chk_SrvLo/1000000,"#,##0")&"-"&TEXT(B27,"#,##0")&" <= 5,198; implied $"&TEXT(C27*1000000/INDEX(GPU_End,1,10),"#,##0")&"/GPU","FLAG") -> FLAG | E27: Capacity, Estimated
A28: (b2) Modeled in-service GPU cost at 6/30 (GPUs x $/GPU) vs $5.2B servers | B28: =(INDEX(GPU_End_H,1,10)*GPUCost_H+INDEX(GPU_End_B,1,10)*GPUCost_B+INDEX(GPU_End_N,1,10)*GPUCost_N)/1000000 -> 4489.925 | C28: =Chk_SrvCap -> 5197.7 | D28: =IF(B28<=C28,"OK","FLAG: exceeds servers in service") -> OK
A29: (c) Q2'26 revenue per energized MW ($M/yr) | B29: =INDEX(AI_Model,1,10)*4/INDEX(MW_En,1,10) -> 13.292486 | C29: =Chk_RevEnMW -> 13 | D29: =IF(ABS(B29/C29-1)<=0.15,"OK","CHECK") -> OK | E29: ~$13M (2.30B / ~173 MW)
A30: Q2'26 contract (book a) IT MW as share of energized MW | B30: =INDEX(A_MW,1,10)/INDEX(MW_En,1,10) -> 0.58580925 | C30: info | D30: ="INFO" -> INFO | E30: Microsoft GPU use capped at Vineland energized IT MW (39 MW Q2'26) + Meta #1 48 MW (TCV/ACV-derived) vs 173 MW energized; v0.1 fix took Q2'26 utilization from 133% to ~92%
A31: Q2'26 energized MW (Capacity base, IT) | B31: =INDEX(MW_En,1,10) -> 173 | C31: 173 | D31: =IF(ABS(B31-C31)<3,"OK","CHECK") -> OK
A32: Q2'26 GPUs: model (Capacity 'GPUs deployed' ~80,416 + GPU anchor gap if GPUAnchorOn) | B32: =INDEX(GPU_End,1,10) -> 88475 | C32: =80416+GPUAnchorD -> 88475 | D32: =IF(ABS(B32/C32-1)<0.01,IF(GPUAnchorOn=1,"INFO: anchored to ~30k at 3/31/25 (+"&TEXT(GPUAnchorD,"#,##0")&" vs Capacity file); Q2 utilization "&TEXT(UtilQ2,"0.0%"),"OK"),"CHECK") -> INFO: anchored to ~30k at 3/31/25 (+8,059 vs Capacity file); Q2 utilization 82.5%
A33: Unexplained ARR residual at 6/30 (June run-rate basis; NOT unseen capacity) | B33: =ARR_Res -> 597.13511 | C33: =ARR_ResTeamLo&"-"&ARR_ResTeamHi -> 650-700 | D33: ="INFO: model "&TEXT(ARR_Res,"#,##0")&" = "&TEXT(ARR_ResMW_TLo,"0")&"-"&TEXT(ARR_ResMW_THi,"0")&" MW-eq at team $13.3-13.5M/MW (model June RR "&TEXT(ARR_RR,"#,##0")&" = $"&TEXT(ARR_RRMW,"0.0")&"M/MW); team-basis residual "&TEXT(ARR_ResTB_Lo,"#,##0")&"-"&TEXT(ARR_ResTB_Hi,"#,##0") -> INFO: model 597 = 44-45 MW-eq at team $13.3-13.5M/MW (model June RR 2,403 = $13.9M/MW); team-basis residual 665-699 | E33: Pending Filings on ARR scope / signed-not-billing
A34: Adj. EBITDA margin FY28 - model vs consensus (flag if > +5pp) | B34: =SUMIF(Q_Yr,2028,PL_EBITDA)/SUMIF(Q_Yr,2028,PL_Rev) -> 0.61813423 | C34: =MarginCons28 -> 0.60782609 | D34: =IF(B34-C34>0.05,"FLAG: model margin > consensus +5pp","OK") -> OK | E34: Skeptic consensus 13.98/23.0
A35: Adj. EBITDA margin FY30 - model vs peer ~62% (flag if > +8pp) | B35: =SUMIF(Q_Yr,2030,PL_EBITDA)/SUMIF(Q_Yr,2030,PL_Rev) -> 0.69929485 | C35: =MarginPeer -> 0.62 | D35: =IF(B35-C35>0.08,"FLAG: above peer +8pp - review opex/MW and revenue/MW","OK") -> OK | E35: CoreWeave ~62% placeholder
A36: FY30 margin sensitivity: PD + SG&A held at FY28 % of revenue (vs placeholder step-down) | B36: =SUMIF(Q_Yr,2030,PL_EBITDA)/SUMIF(Q_Yr,2030,PL_Rev)-(1-OpexHold)*((INDEX(PDpct,1,2028-FYBase)+INDEX(SGApct,1,2028-FYBase))-(INDEX(PDpct,1,2030-FYBase)+INDEX(SGApct,1,2030-FYBase))) -> 0.64929485 | C36: =MarginPeer -> 0.62 | D36: =IF(B36-C36>0.08,"FLAG: still above peer +8pp","INFO: within +8pp of peer") -> INFO: within +8pp of peer | E36: PD 8% + SG&A 10% (FY28) instead of 6% + 7% (FY30); toggle OpexHold=1 for full model effect (Sensitivity)
A37: FY30 opex per avg IT MW ($M/MW-yr: COR + PD + SG&A ex-SBC) | B37: =(SUMIF(Q_Yr,2030,PL_Rev)-SUMIF(Q_Yr,2030,PL_EBITDA))/(SUMIF(Q_Yr,2030,MW_Avg)/4) -> 5.542766 | C37: info | D37: ="INFO: revenue/MW "&TEXT(SUMIF(Q_Yr,2030,PL_Rev)/(SUMIF(Q_Yr,2030,MW_Avg)/4),"0.0") -> INFO: revenue/MW 18.4
A38: FY26 capex vs company guide $20-25B (Aug 12 2026 call) | B38: =SUMIF(Q_Yr,2026,Capex) -> 16720.342 | C38: 20,000-25,000 | D38: =IF(AND(B38>=20000*0.9,B38<=25000*1.1),"OK (within guide +/-10%)","FLAG: outside guide") -> FLAG: outside guide | E38: Fact base: FY2026 capex guidance $20-25B (call transcript, CFO); GPULead calibration
A39: Bull DCF EV vs 3x base (STATIC, snap.py) | B39: =V_EVBullS -> 181982.52 | C39: =3*V_EVBaseS -> 95394.565 | D39: =IF(V_EVBaseS=0,"run snap.py",IF(B39>C39,"FLAG: bull EV > 3x base - review bull drivers","OK")) -> FLAG: bull EV > 3x base - review bull drivers | E39: Bull/base EVs from snapshot
A40: Q2'26 calibration scenario-invariant: utilization bull / bear minus base (STATIC) | B40: =MAX(ABS(V_UtBullS-V_UtBaseS),ABS(V_UtBearS-V_UtBaseS)) -> 0 | C40: 0 | D40: =IF(V_UtBaseS=0,"run snap.py",IF(B40<0.0005,"OK: all scenarios tie $574.9M at "&TEXT(V_UtBaseS,"0.0%"),"FLAG: history depends on scenario")) -> OK: all scenarios tie $574.9M at 82.5%
A41: Implied blended realization vs OD list, Q2'26 books (b)+(c) (billed GPU-hours at Q2 avg list) vs GPU Market 0.72-0.80 | B41: =(INDEX(Book_B,1,LastHist)+INDEX(Book_C,1,LastHist))*1000000/((INDEX(NCA_H,1,LastHist)*ODq_H+INDEX(NCA_B,1,LastHist)*ODq_B+INDEX(NCA_N,1,LastHist)*ODq_N)*INDEX(Q_Hrs,1,LastHist)*UtilQ2) -> 0.74385588 | C41: 0.72-0.80 | D41: =IF(AND(B41>=0.72,B41<=0.8),"OK: within GPU Market range",IF(B41<0.72,"INFO: below range","FLAG: above range")) -> OK: within GPU Market range | E41: Reserved RealRes_B 0.72 x ResSh + on-demand/spot mix
...

Sheet Inputs
A1: Inputs & Assumptions (scenario-driven)
A2: Blue = input. Fill: orange = PLACEHOLDER (no source yet), yellow = Estimated/Consensus, none = Reported/Derived. Live column = CHOOSE(Scenario, Bull, Base, Bear). Owners fill/replace their cells; never overwrite formulas.
A4: Scenario selector (1 = Bull, 2 = Base, 3 = Bear) | D4: 2 | E4: =CHOOSE(Scen,"BULL","BASE","BEAR") -> BASE
A6: Scalar input | B6: Unit | C6: Bull | D6: Base | E6: Bear | F6: LIVE | J6: Owner | K6: Status | L6: Source / method
A7: General
A8: Valuation date | B8: date | C8: — | D8: 46299 | E8: — | F8: =D8 -> 46299 | J8: Modeling | K8: Input | L8: Pitch valuation date; drives DCF discounting and Outputs horizons
A9: Last actual quarter index (10 = Q2'26) | B9: # | C9: — | D9: 10 | E9: — | F9: =D9 -> 10 | J9: Modeling | K9: Input | L9: Roll forward to 11 when Q3'26 is reported
A10: Fiscal-year base (year before first model year) | B10: yr | C10: — | D10: 2023 | E10: — | F10: =D10 -> 2023 | J10: Modeling | K10: Input | L10: Structural: annual-input column = FY - FYBase
A11: Current share price (NBIS) | B11: $/sh | C11: — | D11: 242.81 | E11: — | F11: =D11 -> 242.81 | J11: Skeptic | K11: Reported | L11: Oct 2 2026 close per Skeptic (/workspace/nebius/skeptic/01_priced_in.xlsx), medium confidence; used for convert ITM test, TSM, equity raises
A12: MW block that drives revenue (1 contracted, 2 energized est. [Capacity, default], 3 mgmt-connected guide, 4 Capacity proposed path [scenario, not base until Tuesday file]) | B12: # | C12: — | D12: 2 | E12: — | F12: =D12 -> 2 | J12: Modeling | K12: Input | L12: Default = Capacity energized base (estimated live IT load); guided path kept as comparison only
A13: Energized (live IT load) -> billing lag, MW source 2 | B13: qtrs | C13: 1 | D13: 1 | E13: 1 | F13: =CHOOSE(Scen,C13,D13,E13) -> 1 | J13: Capacity | K13: Estimated | L13: Base 1 qtr. 2 qtrs = STRESS case (Sensitivity snapshot), not the bear default
A14: IT capex method (1 = GPUs x $/GPU, 2 = flat $M per IT MW, 3 = site path: new energized IT MW x per-site $/MW by ownership & generation [default]) | B14: # | C14: — | D14: 3 | E14: — | F14: =D14 -> 3 | J14: Modeling | K14: Input | L14: Method 3 = path-consistent per Capacity gpu_mw_capex.xlsx
A15: Owned site all-in capex per IT MW - GB200 | B15: $M/MW | C15: — | D15: 42 | E15: — | F15: =D15 -> 42 | J15: Capacity | K15: Estimated | L15: /workspace/nebius/capacity/gpu_mw_capex.xlsx CapexPerMW (incl ~$10-12.5M shell+power)
A16: Owned site all-in capex per IT MW - GB300 | B16: $M/MW | C16: — | D16: 53 | E16: — | F16: =D16 -> 53 | J16: Capacity | K16: Estimated | L16: as above
A17: Owned site all-in capex per IT MW - Vera Rubin | B17: $M/MW | C17: — | D17: 43 | E17: — | F17: =D17 -> 43 | J17: Capacity | K17: Estimated | L17: as above
A18: Owned site capex per IT MW - Hopper/B200/B300 (GB200 proxy) | B18: $M/MW | C18: — | D18: 42 | E18: — | F18: =D18 -> 42 | J18: Capacity | K18: Estimated | L18: proxy
A19: Leased/colo capex per IT MW - GB200 (and Hopper/B200/B300 stand-ins); IT only, rent in opex | B19: $M/MW | C19: — | D19: 30 | E19: — | F19: =D19 -> 30 | J19: Capacity | K19: Estimated | L19: gpu_mw_capex.xlsx (Capacity), medium confidence
A20: Leased/colo capex per IT MW - GB300 (Vineland, most leased builds) | B20: $M/MW | C20: — | D20: 41 | E20: — | F20: =D20 -> 41 | J20: Capacity | K20: Estimated | L20: gpu_mw_capex.xlsx (Capacity), medium confidence
A21: Leased/colo capex per IT MW - Vera Rubin | B21: $M/MW | C21: — | D21: 32 | E21: — | F21: =D21 -> 32 | J21: Capacity | K21: Estimated | L21: midpoint $31-33M; gpu_mw_capex.xlsx (Capacity)
A22: v0.2 fix: GPU fleet MW-ratio only in forecast + capex follows DRIVER MW (1 = on) | B22: 0/1 | C22: — | D22: 1 | E22: — | F22: =D22 -> 1 | J22: Modeling | K22: Input | L22: Off = v0.1 behaviour (history fleet scaled by selected MW block; capex followed energized path only)
A23: Terminal basis: 2 = EXCLUDE BOTH Q4'30-onward spend for MW billing after Q4'30 and that MW (terminal = Q4'30 exit run-rate x 4) [default, conservative]; 1 = INCLUDE BOTH (memo only: run-rate scaled x(MW Q4'30 + MW billing Q1'31)/MW Q4'30, unsourced ~1.2x step-up); 0 = v0.1 (FY2030 x (1+TG), Q4'30 spend charged) | B23: 0/1/2 | C23: — | D23: 2 | E23: — | F23: =D23 -> 2 | J23: Modeling | K23: Input | L23: v0.2 decision (Oct 4): do not credit unbilled capacity on an unsourced step-up; 'include both' EV shown as memo row in Valuation
A24: Terminal value floor: max(Gordon/blend, run-off value of existing fleet with no reinvestment) (1 = on) | B24: 0/1 | C24: — | D24: 1 | E24: — | F24: =D24 -> 1 | J24: Modeling | K24: Input | L24: Operator would stop replacing GPUs at negative NPV; TV cannot be below run-off (>= 0)
A25: Owned-site O&M (facility staff, maintenance, insurance, property tax) | B25: $M/IT MW-yr | C25: — | D25: 0.75 | E25: — | F25: =D25 -> 0.75 | J25: Capacity | K25: Placeholder | L25: Leased sites carry this inside rent; owned sites had none in v0.1. Placeholder pending Capacity
... A27: Reserved renewal repricing vs expiring contract | B27: % | C27: — | D27: 0.3 | E27: — | F27: =D27 -> 0.3 | J27: Filings | K27: Reported | L27: Q2'26 letter: >30% repricing on renewals
A28: H100 on-demand list - Q2'26 average | B28: $/GPU-hr | C28: — | D28: =(2*2.95+3.85)/3 -> 3.25 | E28: — | F28: =D28 -> 3.25 | J28: GPU Market | K28: Derived | L28: Archived nebius.com/prices: $2.95 Apr-May -> $3.85 from Jun 2026 (Reported pages); Q2 avg derived
A29: Team June run-rate per MW - low | B29: $M/MW-yr | C29: — | D29: 13.3 | E29: — | F29: =D29 -> 13.3 | J29: Modeling | K29: Estimated | L29: June list + renewals signed by 6/30
A30: Team June run-rate per MW - high | B30: $M/MW-yr | C30: — | D30: 13.5 | E30: — | F30: =D30 -> 13.5 | J30: Modeling | K30: Estimated
A31: Team estimate: unexplained ARR residual - low | B31: $M | C31: — | D31: 650 | E31: — | F31: =D31 -> 650 | J31: Modeling | K31: Estimated | L31: ~45-50 MW
A32: Team estimate: unexplained ARR residual - high | B32: $M | C32: — | D32: 700 | E32: — | F32: =D32 -> 700 | J32: Modeling | K32: Estimated
A33: Consensus FY28 adj. EBITDA margin (13.98 / 23.0) | B33: % | C33: — | D33: =13.98/23 -> 0.60782609 | E33: — | F33: =D33 -> 0.60782609 | J33: Skeptic | K33: Estimated | L33: 01_priced_in.xlsx
A34: Peer adj. EBITDA margin reference (CoreWeave ~62%) | B34: % | C34: — | D34: 0.62 | E34: — | F34: =D34 -> 0.62 | J34: GPU Market | K34: Placeholder | L34: pending GPU Market comps
A35: Cap Microsoft GPU consumption at Vineland energized IT MW (Capacity) (1 = on) | B35: 0/1 | C35: — | D35: 1 | E35: — | F35: =D35 -> 1 | J35: Modeling | K35: Input | L35: Fix for Q2'26 utilization: MSFT delivered-tranche MW (53 MW) exceeded Vineland energized (39 MW / 19,157 GPUs)
A36: GPU end-of-life replacement capex in forecast (1 = on) | B36: 0/1 | C36: — | D36: 1 | E36: — | F36: =D36 -> 1 | J36: Modeling | K36: Input | L36: Cohort reaching GPU life is replaced at original cost (fleet persists in Capacity file)
A37: History MW basis: 1 = Capacity named-site (173 MW Q2'26) [default]; 2 = company-implied (~190 MW, ~$12M rev/installed MW) applied to history AND forward path (+uplift); 3 = MISMATCH test: history at 190, forward on 173 path | B37: # | C37: — | D37: 1 | E37: — | F37: =D37 -> 1 | J37: Capacity/Skeptic | K37: Input | L37: Revenue/MW in history and the forward MW path must use the same basis (2); 3 only quantifies Skeptic's ~11% claim
A38: Company-implied installed MW at Q2'26 (Q2 letter ~$12M revenue per installed MW) | B38: MW | C38: — | D38: 190 | E38: — | F38: =D38 -> 190 | J38: Filings | K38: Derived | L38: ~$2.3B annualized / ~$12M per MW
A39: AIB CLT1 colocation rent (12-yr), per IT MW-yr | B39: $M/IT MW-yr | C39: — | D39: 2.2 | E39: — | F39: =D39 -> 2.2 | J39: Capacity | K39: Estimated | L39: CLT1-sourced ~$2.2M per MW-yr (Capacity); applied via differential vs generic leased rent (RentMW x PUE)
A40: Nebius prepayment to AIB to fund CLT1 build (outflow Q4'26-Q2'27, equal thirds) | B40: $M | C40: — | D40: 0 | E40: — | F40: =D40 -> 0 | J40: Filings | K40: Placeholder | L40: Amount undisclosed (AIB 8-K Sep 30 2026); sensitivity $250M / $500M; liquidity only
A41: Inferize acquisition cash outflow Q4'26 (1 = on) | B41: 0/1 | C41: — | D41: 0 | E41: — | F41: =D41 -> 0 | J41: Filings | K41: Placeholder | L41: 6-K Oct 1 2026: terms undisclosed; PRESS-REPORTED $100-150M (unconfirmed)
A42: Inferize purchase price (press-reported, unconfirmed) | B42: $M | C42: — | D42: 130 | E42: — | F42: =D42 -> 130 | J42: Filings | K42: Placeholder | L42: Press $100-150M; liquidity only
A43: Q3'26 starts from June exit run-rate: AI cloud revenue >= reported ARR / 4 before new MW (overlay held flat in $) | B43: 0/1 | C43: — | D43: 0 | E43: — | F43: =D43 -> 0 | J43: Filings | K43: Input | L43: Filings: ARR = June recognized AI cloud revenue x 12 (no signed-not-billing). Overlay not tied to MW; power/rent not added (EBITDA margin on overlay = 1 - other COR - PD - SG&A %)
...

Sheet Timeline
A1: Timeline (one column per quarter, Q1'24-Q4'30)
A3: Quarter | F3: Q1'24 | G3: Q2'24 | H3: Q3'24 | I3: Q4'24 | J3: Q1'25 | K3: Q2'25 | L3: Q3'25 | M3: Q4'25 | N3: Q1'26 | O3: Q2'26 | P3: Q3'26 | Q3: Q4'26 | R3: Q1'27 | S3: Q2'27 | T3: Q3'27 | U3: Q4'27 | V3: Q1'28 | W3: Q2'28 | X3: Q3'28 | Y3: Q4'28 | Z3: Q1'29 | AA3: Q2'29 | AB3: Q3'29 | AC3: Q4'29 | AD3: Q1'30 | AE3: Q2'30 | AF3: Q3'30 | AG3: Q4'30
A4: Period end | E4: 45291 | F4: 45382 | G4: 45473 | H4: 45565 | I4: 45657 | J4: 45747 | K4: 45838 | L4: 45930 | M4: 46022 | N4: 46112 | O4: 46203 | P4: 46295 | Q4: 46387 | R4: 46477 | S4: 46568 | T4: 46660 | U4: 46752 | V4: 46843 | W4: 46934 | X4: 47026 | Y4: 47118 | Z4: 47208 | AA4: 47299 | AB4: 47391 | AC4: 47483 | AD4: 47573 | AE4: 47664 | AF4: 47756 | AG4: 47848
A5: Index | E5: 0 | F5: 1 | G5: 2 | H5: 3 | I5: 4 | J5: 5 | K5: 6 | L5: 7 | M5: 8 | N5: 9 | O5: 10 | P5: 11 | Q5: 12 | R5: 13 | S5: 14 | T5: 15 | U5: 16 | V5: 17 | W5: 18 | X5: 19 | Y5: 20 | Z5: 21 | AA5: 22 | AB5: 23 | AC5: 24 | AD5: 25 | AE5: 26 | AF5: 27 | AG5: 28
A6: A/F | F6: =IF(F5<=LastHist,"A","F") -> A | G6: =IF(G5<=LastHist,"A","F") -> A | H6: =IF(H5<=LastHist,"A","F") -> A | I6: =IF(I5<=LastHist,"A","F") -> A | J6: =IF(J5<=LastHist,"A","F") -> A | K6: =IF(K5<=LastHist,"A","F") -> A | L6: =IF(L5<=LastHist,"A","F") -> A | M6: =IF(M5<=LastHist,"A","F") -> A | ... AG6: =IF(AG5<=LastHist,"A","F") -> F
A7: Fiscal year | F7: =YEAR(F4) -> 2024 | G7: =YEAR(G4) -> 2024 | H7: =YEAR(H4) -> 2024 | I7: =YEAR(I4) -> 2024 | J7: =YEAR(J4) -> 2025 | K7: =YEAR(K4) -> 2025 | L7: =YEAR(L4) -> 2025 | M7: =YEAR(M4) -> 2025 | ... AG7: =YEAR(AG4) -> 2030
A8: Days | F8: =F4-E4 -> 91 | G8: =G4-F4 -> 91 | H8: =H4-G4 -> 92 | I8: =I4-H4 -> 92 | J8: =J4-I4 -> 90 | K8: =K4-J4 -> 91 | L8: =L4-K4 -> 92 | M8: =M4-L4 -> 92 | ... AG8: =AG4-AF4 -> 92
A9: Hours | F9: =F8*24 -> 2184 | G9: =G8*24 -> 2184 | H9: =H8*24 -> 2208 | I9: =I8*24 -> 2208 | J9: =J8*24 -> 2160 | K9: =K8*24 -> 2184 | L9: =L8*24 -> 2208 | M9: =M8*24 -> 2208 | ... AG9: =AG8*24 -> 2208

Sheet Hist
A1: Historical inputs Q1'24-Q2'26 with Reported / Derived / Estimated / Not disclosed tags
A2: Each metric = 5 rows: value as disclosed | tag | best estimate (numeric) | method/source | VALUE USED (= value if disclosed, else best estimate). No silent gaps: every quarter carries a tag. Other tabs link to the VALUE USED row only.
A3: Metric | B3: Unit | C3: Owner | D3: Notes | F3: Q1'24 | G3: Q2'24 | H3: Q3'24 | I3: Q4'24 | J3: Q1'25 | K3: Q2'25 | L3: Q3'25 | M3: Q4'25 | N3: Q1'26 | O3: Q2'26
F4: 45382 | G4: 45473 | H4: 45565 | I4: 45657 | J4: 45747 | K4: 45838 | L4: 45930 | M4: 46022 | N4: 46112 | O4: 46203
A6: Group revenue | B6: $M | C6: Filings | D6: Continuing ops. Q1'24 figure is on the pre-restatement basis (Q1'25 PR) - flag. | F6: 11.4 | G6: 14.5 | H6: 32.1 | I6: 35.2 | J6: 50.9 | K6: 105.1 | L6: 146.1 | M6: 227.7 | N6: 399 | O6: 582.3
A7: tag | F7: Reported | G7: Reported | H7: Reported | I7: Reported | J7: Reported | K7: Reported | L7: Reported | M7: Reported | N7: Reported | O7: Reported
A8: best estimate
A9: method / source | F9: Q1'25 6-K PR comparatives (pre-Toloka-deconsolidation basis) | G9: Q2'25 6-K PR comparative | H9: Q3'25 6-K PR comparative (restated) | I9: Q4'25 6-K PR comparative | J9: Q1'26 6-K PR comparative (restated) | K9: Q2'26 6-K PR comparative | L9: Q3'25 6-K PR | M9: Q4'25 6-K PR | N9: Q1'26 6-K PR | O9: Q2'26 6-K PR (acc. 0001104659-26-094568)
A10: VALUE USED | F10: =IF(F7="Not disclosed",F8,F6) -> 11.4 | G10: =IF(G7="Not disclosed",G8,G6) -> 14.5 | H10: =IF(H7="Not disclosed",H8,H6) -> 32.1 | I10: =IF(I7="Not disclosed",I8,I6) -> 35.2 | J10: =IF(J7="Not disclosed",J8,J6) -> 50.9 | K10: =IF(K7="Not disclosed",K8,K6) -> 105.1 | L10: =IF(L7="Not disclosed",L8,L6) -> 146.1 | M10: =IF(M7="Not disclosed",M8,M6) -> 227.7 | ... O10: =IF(O7="Not disclosed",O8,O6) -> 582.3
A12: Nebius AI cloud revenue | B12: $M | C12: Filings | D12: Segment disclosure; earlier quarters derived from YoY growth or estimated as % of group | F12: n.d. | G12: n.d. | H12: n.d. | I12: n.d. | J12: 41.4 | K12: 93.6 | L12: n.d. | M12: 214.2 | N12: 389.7 | O12: 574.9
A13: tag | F13: Not disclosed | G13: Not disclosed | H13: Not disclosed | I13: Not disclosed | J13: Derived | K13: Derived | L13: Not disclosed | M13: Reported | N13: Reported | O13: Reported
A14: best estimate | F14: 10.3 | G14: 13.1 | H14: 28.9 | I14: 31.7 | L14: 138.8
A15: method / source | F15: Est = 90% of group revenue (pre-2025 mix; Avride/TripleTen remainder) | G15: Est = 90% of group revenue (pre-2025 mix; Avride/TripleTen remainder) | H15: Est = 90% of group revenue (pre-2025 mix; Avride/TripleTen remainder) | I15: Est = 90% of group revenue (pre-2025 mix; Avride/TripleTen remainder) | J15: Derived: Q1'26 $389.7M / (1+841%) | K15: Derived: Q2'26 $574.9M / (1+514%) | L15: Est = 95% of group revenue | M15: Q4'25 letter | N15: Q1'26 letter | O15: Q2'26 letter
A16: VALUE USED | F16: =IF(F13="Not disclosed",F14,F12) -> 10.3 | G16: =IF(G13="Not disclosed",G14,G12) -> 13.1 | H16: =IF(H13="Not disclosed",H14,H12) -> 28.9 | I16: =IF(I13="Not disclosed",I14,I12) -> 31.7 | J16: =IF(J13="Not disclosed",J14,J12) -> 41.4 | K16: =IF(K13="Not disclosed",K14,K12) -> 93.6 | L16: =IF(L13="Not disclosed",L14,L12) -> 138.8 | M16: =IF(M13="Not disclosed",M14,M12) -> 214.2 | ... O16: =IF(O13="Not disclosed",O14,O12) -> 574.9
A18: ARR (last-month AI cloud revenue x 12) | B18: $M | C18: Filings | D18: Mgmt definition; Q2'25/Q1'25 derived from stated YoY growth | F18: n.d. | G18: n.d. | H18: n.d. | I18: 90 | J18: 248 | K18: 430 | L18: 551 | M18: 1250 | N18: 1920 | O18: 3000
A19: tag | F19: Not disclosed | G19: Not disclosed | H19: Not disclosed | I19: Reported | J19: Derived | K19: Derived | L19: Reported | M19: Reported | N19: Reported | O19: Reported
A20: best estimate | F20: 41.04 | G20: 52.2 | H20: 115.56
A21: method / source | F21: Est = AI cloud revenue est x 4 (run-rate proxy) | G21: Est = AI cloud revenue est x 4 (run-rate proxy) | H21: Est = AI cloud revenue est x 4 (run-rate proxy) | I21: Q4'25 letter ARR chart (Dec-24 $90M) | J21: Derived: $1.92B / (1+674%) | K21: Derived: $3.0B / (1+598%) | L21: Q4'25 letter: 'more than doubled from $551M' | M21: Q4'25 letter | N21: Q1'26 letter ($1.92B) | O21: Q2'26 letter
A22: VALUE USED | F22: =IF(F19="Not disclosed",F20,F18) -> 41.04 | G22: =IF(G19="Not disclosed",G20,G18) -> 52.2 | H22: =IF(H19="Not disclosed",H20,H18) -> 115.56 | I22: =IF(I19="Not disclosed",I20,I18) -> 90 | J22: =IF(J19="Not disclosed",J20,J18) -> 248 | K22: =IF(K19="Not disclosed",K20,K18) -> 430 | L22: =IF(L19="Not disclosed",L20,L18) -> 551 | M22: =IF(M19="Not disclosed",M20,M18) -> 1250 | ... O22: =IF(O19="Not disclosed",O20,O18) -> 3000
A24: Cost of revenues | B24: $M | C24: Filings | D24: GAAP incl. SBC. Q1'24/Q2'24 estimated by splitting (revenue - adj. EBITDA) on Q3'24 mix | F24: n.d. | G24: n.d. | H24: 9.9 | I24: 21.1 | J24: 24.7 | K24: 30.1 | L24: 42.9 | M24: 68.5 | N24: 103.8 | O24: 133.6
A25: tag | F25: Not disclosed | G25: Not disclosed | H25: Reported | I25: Reported | J25: Reported | K25: Reported | L25: Reported | M25: Reported | N25: Reported | O25: Reported
A26: best estimate | F26: 9.1 | G26: 8.1
A27: method / source | F27: Est: (rev - adj EBITDA) x Q3'24 COR share | G27: Est: (rev - adj EBITDA) x Q3'24 COR share | H27: Q3'25 6-K PR comparative (restated) | I27: Q4'25 6-K PR comparative | J27: Q1'26 6-K PR comparative (restated) | K27: Q2'26 6-K PR comparative | L27: Q3'25 6-K PR | M27: Q4'25 6-K PR | N27: Q1'26 6-K PR | O27: Q2'26 6-K PR (acc. 0001104659-26-094568)
A28: VALUE USED | F28: =IF(F25="Not disclosed",F26,F24) -> 9.1 | G28: =IF(G25="Not disclosed",G26,G24) -> 8.1 | H28: =IF(H25="Not disclosed",H26,H24) -> 9.9 | I28: =IF(I25="Not disclosed",I26,I24) -> 21.1 | J28: =IF(J25="Not disclosed",J26,J24) -> 24.7 | K28: =IF(K25="Not disclosed",K26,K24) -> 30.1 | L28: =IF(L25="Not disclosed",L26,L24) -> 42.9 | M28: =IF(M25="Not disclosed",M26,M24) -> 68.5 | ... O28: =IF(O25="Not disclosed",O26,O24) -> 133.6
A30: Product development | B30: $M | C30: Filings | D30: GAAP incl. SBC. Q1'24/Q2'24 estimated by splitting (revenue - adj. EBITDA) on Q3'24 mix; Q2'26 incl. $115.9M one-off Eigen AI | F30: n.d. | G30: n.d. | H30: 31.4 | I30: 31.9 | J30: 36.5 | K30: 42.8 | L30: 44.9 | M30: 53.1 | N30: 67.4 | O30: 191
A31: tag | F31: Not disclosed | G31: Not disclosed | H31: Reported | I31: Reported | J31: Reported | K31: Reported | L31: Reported | M31: Reported | N31: Reported | O31: Reported
A32: best estimate | F32: 29 | G32: 25.6
A33: method / source | F33: Est: (rev - adj EBITDA) x Q3'24 PD share | G33: Est: (rev - adj EBITDA) x Q3'24 PD share | H33: Q3'25 6-K PR comparative (restated) | I33: Q4'25 6-K PR comparative | J33: Q1'26 6-K PR comparative (restated) | K33: Q2'26 6-K PR comparative | L33: Q3'25 6-K PR | M33: Q4'25 6-K PR | N33: Q1'26 6-K PR | O33: Q2'26 6-K PR (acc. 0001104659-26-094568)
A34: VALUE USED | F34: =IF(F31="Not disclosed",F32,F30) -> 29 | G34: =IF(G31="Not disclosed",G32,G30) -> 25.6 | H34: =IF(H31="Not disclosed",H32,H30) -> 31.4 | I34: =IF(I31="Not disclosed",I32,I30) -> 31.9 | J34: =IF(J31="Not disclosed",J32,J30) -> 36.5 | K34: =IF(K31="Not disclosed",K32,K30) -> 42.8 | L34: =IF(L31="Not disclosed",L32,L30) -> 44.9 | M34: =IF(M31="Not disclosed",M32,M30) -> 53.1 | ... O34: =IF(O31="Not disclosed",O32,O30) -> 191
A36: Sales, general & administrative | B36: $M | C36: Filings | D36: GAAP incl. SBC. Q1'24/Q2'24 estimated by splitting (revenue - adj. EBITDA) on Q3'24 mix | F36: n.d. | G36: n.d. | H36: 47.9 | I36: 85.4 | J36: 60.9 | K36: 68.2 | L36: 89.5 | M36: 159.9 | N36: 143.8 | O36: 173.9
A37: tag | F37: Not disclosed | G37: Not disclosed | H37: Reported | I37: Reported | J37: Reported | K37: Reported | L37: Reported | M37: Reported | N37: Reported | O37: Reported
A38: best estimate | F38: 44.2 | G38: 39
A39: method / source | F39: Est: (rev - adj EBITDA) x Q3'24 SG&A share | G39: Est: (rev - adj EBITDA) x Q3'24 SG&A share | H39: Q3'25 6-K PR comparative (restated) | I39: Q4'25 6-K PR comparative | J39: Q1'26 6-K PR comparative (restated) | K39: Q2'26 6-K PR comparative | L39: Q3'25 6-K PR | M39: Q4'25 6-K PR | N39: Q1'26 6-K PR | O39: Q2'26 6-K PR (acc. 0001104659-26-094568)
A40: VALUE USED | F40: =IF(F37="Not disclosed",F38,F36) -> 44.2 | G40: =IF(G37="Not disclosed",G38,G36) -> 39 | H40: =IF(H37="Not disclosed",H38,H36) -> 47.9 | I40: =IF(I37="Not disclosed",I38,I36) -> 85.4 | J40: =IF(J37="Not disclosed",J38,J36) -> 60.9 | K40: =IF(K37="Not disclosed",K38,K36) -> 68.2 | L40: =IF(L37="Not disclosed",L38,L36) -> 89.5 | M40: =IF(M37="Not disclosed",M38,M36) -> 159.9 | ... O40: =IF(O37="Not disclosed",O38,O36) -> 173.9
A42: Depreciation & amortization | B42: $M | C42: Filings | F42: 8.9 | G42: 11.4 | H42: 23.5 | I42: 33.3 | J42: 49.1 | K42: 75.2 | L42: 99 | M42: 180.7 | N42: 212 | O42: 259.7
A43: tag | F43: Reported | G43: Reported | H43: Reported | I43: Reported | J43: Reported | K43: Reported | L43: Reported | M43: Reported | N43: Reported | O43: Reported
A44: best estimate
A45: method / source | F45: Q1'25 6-K PR comparatives (pre-Toloka-deconsolidation basis) | G45: Q2'25 6-K PR comparative | H45: Q3'25 6-K PR comparative (restated) | I45: Q4'25 6-K PR comparative | J45: Q1'26 6-K PR comparative (restated) | K45: Q2'26 6-K PR comparative | L45: Q3'25 6-K PR | M45: Q4'25 6-K PR | N45: Q1'26 6-K PR | O45: Q2'26 6-K PR (acc. 0001104659-26-094568)
A46: VALUE USED | F46: =IF(F43="Not disclosed",F44,F42) -> 8.9 | G46: =IF(G43="Not disclosed",G44,G42) -> 11.4 | H46: =IF(H43="Not disclosed",H44,H42) -> 23.5 | I46: =IF(I43="Not disclosed",I44,I42) -> 33.3 | J46: =IF(J43="Not disclosed",J44,J42) -> 49.1 | K46: =IF(K43="Not disclosed",K44,K42) -> 75.2 | L46: =IF(L43="Not disclosed",L44,L42) -> 99 | M46: =IF(M43="Not disclosed",M44,M42) -> 180.7 | ... O46: =IF(O43="Not disclosed",O44,O42) -> 259.7
A48: D&A excluding 4->5 yr life change | B48: $M | C48: Filings | D48: Q1'26 benefit $43.1M, Q2'26 $43.0M (FY26 guided $167.6M); = reported + benefit | F48: 8.9 | G48: 11.4 | H48: 23.5 | I48: 33.3 | J48: 49.1 | K48: 75.2 | L48: 99 | M48: 180.7 | N48: 255.1 | O48: 302.7
...

Sheet Sites
A1: Sites
A2: Site-by-site MW: three blocks (contracted / energized estimate [Capacity] / mgmt-guided). Selector Inputs!MWSel picks the revenue driver. All MW converted to IT basis via PUE where basis = Facility.
A3: Line item | B3: Unit | C3: Owner | D3: Tag / source / method | E3: Open | F3: =Timeline!F3 -> Q1'24 | G3: =Timeline!G3 -> Q2'24 | H3: =Timeline!H3 -> Q3'24 | I3: =Timeline!I3 -> Q4'24 | J3: =Timeline!J3 -> Q1'25 | K3: =Timeline!K3 -> Q2'25 | L3: =Timeline!L3 -> Q3'25 | M3: =Timeline!M3 -> Q4'25 | ... AG3: =Timeline!AG3 -> Q4'30 | AI3: FY2024 | AJ3: FY2025 | AK3: FY2026 | AL3: FY2027 | AM3: FY2028 | AN3: FY2029 | AO3: FY2030
A4: Period end | F4: =Timeline!F4 -> 45382 | G4: =Timeline!G4 -> 45473 | H4: =Timeline!H4 -> 45565 | I4: =Timeline!I4 -> 45657 | J4: =Timeline!J4 -> 45747 | K4: =Timeline!K4 -> 45838 | L4: =Timeline!L4 -> 45930 | M4: =Timeline!M4 -> 46022 | ... AG4: =Timeline!AG4 -> 47848
A5: Index | E5: 0 | F5: =Timeline!F5 -> 1 | G5: =Timeline!G5 -> 2 | H5: =Timeline!H5 -> 3 | I5: =Timeline!I5 -> 4 | J5: =Timeline!J5 -> 5 | K5: =Timeline!K5 -> 6 | L5: =Timeline!L5 -> 7 | M5: =Timeline!M5 -> 8 | ... AG5: =Timeline!AG5 -> 28
A6: A = actual / F = forecast | F6: =Timeline!F6 -> A | G6: =Timeline!G6 -> A | H6: =Timeline!H6 -> A | I6: =Timeline!I6 -> A | J6: =Timeline!J6 -> A | K6: =Timeline!K6 -> A | L6: =Timeline!L6 -> A | M6: =Timeline!M6 -> A | ... AG6: =Timeline!AG6 -> F
A7: Fiscal year | F7: =Timeline!F7 -> 2024 | G7: =Timeline!G7 -> 2024 | H7: =Timeline!H7 -> 2024 | I7: =Timeline!I7 -> 2024 | J7: =Timeline!J7 -> 2025 | K7: =Timeline!K7 -> 2025 | L7: =Timeline!L7 -> 2025 | M7: =Timeline!M7 -> 2025 | ... AG7: =Timeline!AG7 -> 2030 | AI7: 2024 | AJ7: 2025 | AK7: 2026 | AL7: 2027 | AM7: 2028 | AN7: 2029 | AO7: 2030
A10: Site metadata (ownership switches shell+power between capex [Owned] and rent [Leased-colo / Build-to-suit lease]; MW basis flag converts Facility MW to IT MW via PUE)
A11: Site | B11: Ownership | C11: MW basis | D11: Capacity-file basis / notes | E11: Risk grade | F11: IT factor | G11: Owned? | H11: Go-live idx - early (bull) | I11: Go-live idx - base | J11: Go-live idx - late (bear) | K11: Go-live (live) | L11: Evidence tag | M11: Owner / due | N11: GPU generation | O11: Capex $M/IT MW | P11: of which shell+power
A12: Vineland NJ (DataOne) | B12: Build-to-suit lease | C12: IT | D12: file basis: IT; Vineland leased from DataOne; Bloom PPA power | E12: Red | F12: =IF(C12="Facility",1/PUE,1) -> 1 | G12: =IF(B12="Owned",1,0) -> 0 | H12: 8 | I12: 8 | J12: 8 | K12: =IF(N(CHOOSE(Scen,H12,I12,J12))=0,"n/a",INDEX(Q_Lab,1,CHOOSE(Scen,H12,I12,J12))) -> Q4'25 | M12: Capacity & Power - due Tue Oct 6 (prefill = first non-zero energized qtr in Capacity file) | N12: GB300 NVL72 | O12: =IF(B12="Owned",IF(N12="GB300 NVL72",CPM_Own_GB300,IF(N12="Vera Rubin NVL72",CPM_Own_VR,IF(N12="GB200 NVL72",CPM_Own_GB200,CPM_Own_Other))),IF(N12="GB300 NVL72",CPM_Lease_GB300,IF(N12="Vera Rubin NVL72",CPM_Lease_VR,CPM_Lease))) -> 41 | P12: =IF(B12="Owned",CPM_SP,0) -> 0
A13: Independence MO (Eastgate) | B13: Owned | C13: Facility | D13: file basis: stated/unknown | E13: Green | F13: =IF(C13="Facility",1/PUE,1) -> 0.8 | G13: =IF(B13="Owned",1,0) -> 1 | H13: 15 | I13: 15 | J13: 16 | K13: =IF(N(CHOOSE(Scen,H13,I13,J13))=0,"n/a",INDEX(Q_Lab,1,CHOOSE(Scen,H13,I13,J13))) -> Q3'27 | M13: Capacity & Power - due Tue Oct 6 (prefill = first non-zero energized qtr in Capacity file) | N13: Vera Rubin NVL72 | O13: =IF(B13="Owned",IF(N13="GB300 NVL72",CPM_Own_GB300,IF(N13="Vera Rubin NVL72",CPM_Own_VR,IF(N13="GB200 NVL72",CPM_Own_GB200,CPM_Own_Other))),IF(N13="GB300 NVL72",CPM_Lease_GB300,IF(N13="Vera Rubin NVL72",CPM_Lease_VR,CPM_Lease))) -> 43 | P13: =IF(B13="Owned",CPM_SP,0) -> 11.25
A14: Butler Twp PA (Highridge) | B14: Owned | C14: Facility | D14: file basis: stated/unknown | E14: Red | F14: =IF(C14="Facility",1/PUE,1) -> 0.8 | G14: =IF(B14="Owned",1,0) -> 1 | H14: 16 | I14: 16 | J14: 20 | K14: =IF(N(CHOOSE(Scen,H14,I14,J14))=0,"n/a",INDEX(Q_Lab,1,CHOOSE(Scen,H14,I14,J14))) -> Q4'27 | M14: Capacity & Power - due Tue Oct 6 (prefill = first non-zero energized qtr in Capacity file) | N14: Vera Rubin NVL72 | O14: =IF(B14="Owned",IF(N14="GB300 NVL72",CPM_Own_GB300,IF(N14="Vera Rubin NVL72",CPM_Own_VR,IF(N14="GB200 NVL72",CPM_Own_GB200,CPM_Own_Other))),IF(N14="GB300 NVL72",CPM_Lease_GB300,IF(N14="Vera Rubin NVL72",CPM_Lease_VR,CPM_Lease))) -> 43 | P14: =IF(B14="Owned",CPM_SP,0) -> 11.25
A15: Birmingham AL (BHM01, Oxmoor) | B15: Owned | C15: Facility | D15: file basis: stated/unknown | E15: Yellow | F15: =IF(C15="Facility",1/PUE,1) -> 0.8 | G15: =IF(B15="Owned",1,0) -> 1 | H15: 13 | I15: 13 | J15: 15 | K15: =IF(N(CHOOSE(Scen,H15,I15,J15))=0,"n/a",INDEX(Q_Lab,1,CHOOSE(Scen,H15,I15,J15))) -> Q1'27 | M15: Capacity & Power - due Tue Oct 6 (prefill = first non-zero energized qtr in Capacity file) | N15: Vera Rubin NVL72 | O15: =IF(B15="Owned",IF(N15="GB300 NVL72",CPM_Own_GB300,IF(N15="Vera Rubin NVL72",CPM_Own_VR,IF(N15="GB200 NVL72",CPM_Own_GB200,CPM_Own_Other))),IF(N15="GB300 NVL72",CPM_Lease_GB300,IF(N15="Vera Rubin NVL72",CPM_Lease_VR,CPM_Lease))) -> 43 | P15: =IF(B15="Owned",CPM_SP,0) -> 11.25
A16: Bethune FR (Azur Datacenter, ex-Bridgestone) | B16: Leased-colo | C16: Facility | D16: file basis: stated/unknown; Bethune 0/30/60 MW YE26 (Capacity) | E16: Yellow | F16: =IF(C16="Facility",1/PUE,1) -> 0.8 | G16: =IF(B16="Owned",1,0) -> 0 | H16: 12 | I16: 12 | J16: 13 | K16: =IF(N(CHOOSE(Scen,H16,I16,J16))=0,"n/a",INDEX(Q_Lab,1,CHOOSE(Scen,H16,I16,J16))) -> Q4'26 | M16: Capacity & Power - due Tue Oct 6 (prefill = first non-zero energized qtr in Capacity file) | N16: GB300 NVL72 | O16: =IF(B16="Owned",IF(N16="GB300 NVL72",CPM_Own_GB300,IF(N16="Vera Rubin NVL72",CPM_Own_VR,IF(N16="GB200 NVL72",CPM_Own_GB200,CPM_Own_Other))),IF(N16="GB300 NVL72",CPM_Lease_GB300,IF(N16="Vera Rubin NVL72",CPM_Lease_VR,CPM_Lease))) -> 41 | P16: =IF(B16="Owned",CPM_SP,0) -> 0
A17: Lappeenranta FI (Pajarila / Polarnode) | B17: Owned | C17: Facility | D17: file basis: stated/unknown | E17: Green | F17: =IF(C17="Facility",1/PUE,1) -> 0.8 | G17: =IF(B17="Owned",1,0) -> 1 | H17: 14 | I17: 14 | J17: 16 | K17: =IF(N(CHOOSE(Scen,H17,I17,J17))=0,"n/a",INDEX(Q_Lab,1,CHOOSE(Scen,H17,I17,J17))) -> Q2'27 | M17: Capacity & Power - due Tue Oct 6 (prefill = first non-zero energized qtr in Capacity file) | N17: Vera Rubin NVL72 | O17: =IF(B17="Owned",IF(N17="GB300 NVL72",CPM_Own_GB300,IF(N17="Vera Rubin NVL72",CPM_Own_VR,IF(N17="GB200 NVL72",CPM_Own_GB200,CPM_Own_Other))),IF(N17="GB300 NVL72",CPM_Lease_GB300,IF(N17="Vera Rubin NVL72",CPM_Lease_VR,CPM_Lease))) -> 43 | P17: =IF(B17="Owned",CPM_SP,0) -> 11.25
A18: Mantsala FI #1 | B18: Owned | C18: IT | D18: file basis: stated/unknown | E18: Green | F18: =IF(C18="Facility",1/PUE,1) -> 1 | G18: =IF(B18="Owned",1,0) -> 1 | H18: 1 | I18: 1 | J18: 1 | K18: =IF(N(CHOOSE(Scen,H18,I18,J18))=0,"n/a",INDEX(Q_Lab,1,CHOOSE(Scen,H18,I18,J18))) -> Q1'24 | M18: Capacity & Power - due Tue Oct 6 (prefill = first non-zero energized qtr in Capacity file) | N18: GB300 NVL72 | O18: =IF(B18="Owned",IF(N18="GB300 NVL72",CPM_Own_GB300,IF(N18="Vera Rubin NVL72",CPM_Own_VR,IF(N18="GB200 NVL72",CPM_Own_GB200,CPM_Own_Other))),IF(N18="GB300 NVL72",CPM_Lease_GB300,IF(N18="Vera Rubin NVL72",CPM_Lease_VR,CPM_Lease))) -> 53 | P18: =IF(B18="Owned",CPM_SP,0) -> 11.25
A19: Mantsala FI #2 (Kapuli) | B19: Owned | C19: Facility | D19: file basis: stated/unknown | E19: Yellow | F19: =IF(C19="Facility",1/PUE,1) -> 0.8 | G19: =IF(B19="Owned",1,0) -> 1 | H19: 16 | I19: 16 | J19: 17 | K19: =IF(N(CHOOSE(Scen,H19,I19,J19))=0,"n/a",INDEX(Q_Lab,1,CHOOSE(Scen,H19,I19,J19))) -> Q4'27 | M19: Capacity & Power - due Tue Oct 6 (prefill = first non-zero energized qtr in Capacity file) | N19: Vera Rubin NVL72 | O19: =IF(B19="Owned",IF(N19="GB300 NVL72",CPM_Own_GB300,IF(N19="Vera Rubin NVL72",CPM_Own_VR,IF(N19="GB200 NVL72",CPM_Own_GB200,CPM_Own_Other))),IF(N19="GB300 NVL72",CPM_Lease_GB300,IF(N19="Vera Rubin NVL72",CPM_Lease_VR,CPM_Lease))) -> 43 | P19: =IF(B19="Owned",CPM_SP,0) -> 11.25
A20: Kansas City MO (Patmos) | B20: Leased-colo | C20: IT | D20: file basis: stated/unknown | E20: Green | F20: =IF(C20="Facility",1/PUE,1) -> 1 | G20: =IF(B20="Owned",1,0) -> 0 | H20: 6 | I20: 6 | J20: 6 | K20: =IF(N(CHOOSE(Scen,H20,I20,J20))=0,"n/a",INDEX(Q_Lab,1,CHOOSE(Scen,H20,I20,J20))) -> Q2'25 | M20: Capacity & Power - due Tue Oct 6 (prefill = first non-zero energized qtr in Capacity file) | N20: B200 (HGX) | O20: =IF(B20="Owned",IF(N20="GB300 NVL72",CPM_Own_GB300,IF(N20="Vera Rubin NVL72",CPM_Own_VR,IF(N20="GB200 NVL72",CPM_Own_GB200,CPM_Own_Other))),IF(N20="GB300 NVL72",CPM_Lease_GB300,IF(N20="Vera Rubin NVL72",CPM_Lease_VR,CPM_Lease))) -> 30 | P20: =IF(B20="Owned",CPM_SP,0) -> 0
A21: Paris (Equinix PA10) | B21: Leased-colo | C21: IT | D21: file basis: stated/unknown | E21: Green | F21: =IF(C21="Facility",1/PUE,1) -> 1 | G21: =IF(B21="Owned",1,0) -> 0 | H21: 4 | I21: 4 | J21: 4 | K21: =IF(N(CHOOSE(Scen,H21,I21,J21))=0,"n/a",INDEX(Q_Lab,1,CHOOSE(Scen,H21,I21,J21))) -> Q4'24 | M21: Capacity & Power - due Tue Oct 6 (prefill = first non-zero energized qtr in Capacity file) | N21: Hopper H100/H200 | O21: =IF(B21="Owned",IF(N21="GB300 NVL72",CPM_Own_GB300,IF(N21="Vera Rubin NVL72",CPM_Own_VR,IF(N21="GB200 NVL72",CPM_Own_GB200,CPM_Own_Other))),IF(N21="GB300 NVL72",CPM_Lease_GB300,IF(N21="Vera Rubin NVL72",CPM_Lease_VR,CPM_Lease))) -> 30 | P21: =IF(B21="Owned",CPM_SP,0) -> 0
