Workbook

Sheet README
A1: Peer KPI comps - Oracle Corporation (ORCL), Oracle Cloud Infrastructure (OCI) perimeter. Built 2026-10-05 (ET) for the Nebius (NBIS) project. File: /workspace/nebius/peers/oracle/oracle_kpis.xlsx; builder: build_orcl_kpis.py on shared engine /workspace/nebius/peers/peer_kpi_template.py.
A2: TEMPLATE: identical row IDs/definitions/tags to peers/coreweave/crwv_kpis.xlsx (I01-I27, K01-K40) + phase-2 extensions I28-I32 / K41-K45; Oracle memo rows I40+ / M01+.
A3: FISCAL MAPPING: Oracle FY ends 31-May. Fiscal quarters end Aug/Nov/Feb/May, one month BEFORE calendar quarter-ends. Each calendar column uses the Oracle fiscal quarter ending one month earlier (Q1'24 = FQ3 FY24 ended 29-Feb-24 ... Q2'26 = FQ4 FY26 ended 31-May-26). Extra column Q3'26† = FQ1 FY27 (ended 31-Aug-26; latest filed) shown for currency. See Fiscal_Map.
A4: PERIMETER: OCI is NOT a reported segment. I01 = 'Cloud infrastructure' revenue line (IaaS, includes non-AI OCI). Capex, depreciation, PP&E, debt, RPO are company-wide. Segment-allocation estimates are tagged ESTIMATED (orange) and labelled: capex attributed to OCI at 100% (P05, upper bound), incremental OCI revenue attributed to delivered AI MW (K43), MW delivered from earnings calls.
A5: MW: Oracle discloses MW DELIVERED per quarter (calls/PR), not installed MW -> K01-K04/K14/K15 n/d; capex/MW uses MW delivered.
A6: TAGS / COLOURS: blue = Reported; black = Derived; orange = Estimated; grey n/d. KPI tag = weakest input.
A7: Multi-peer Comparison tab: /workspace/nebius/peers/comparison.xlsx (built by peers/build_comparison.py).

Sheet KPIs
A1: KPIs - Oracle OCI (ORCL) - Cloud Infrastructure perimeter - quarterly, Nebius definitions (Definitions tab). Value row = live formula; row below = tag (weakest input). Row 2 = fiscal quarter mapped to each calendar column.
E2: FQ2 FY24 (Nov-23) | F2: FQ3 FY24 (Feb-24) | G2: FQ4 FY24 (May-24) | H2: FQ1 FY25 (Aug-24) | I2: FQ2 FY25 (Nov-24) | J2: FQ3 FY25 (Feb-25) | K2: FQ4 FY25 (May-25) | L2: FQ1 FY26 (Aug-25) | M2: FQ2 FY26 (Nov-25) | N2: FQ3 FY26 (Feb-26) | O2: FQ4 FY26 (May-26) | P2: FQ1 FY27 (Aug-26)
A3: ID | B3: KPI | C3: Unit | D3: Def | E3: Q4'23* | F3: Q1'24 | G3: Q2'24 | H3: Q3'24 | I3: Q4'24 | J3: Q1'25 | K3: Q2'25 | L3: Q3'25 | M3: Q4'25 | N3: Q1'26 | O3: Q2'26 | P3: Q3'26† | Q3: Method / caveat (Oracle OCI (ORCL) - Cloud Infrastructure perimeter)
A4: A. Revenue per MW ($M per MW-year, annualized: quarterly revenue x 4 / MW)
A5: K01 | B5: Revenue per active MW - period-end MW | C5: $M/MW-yr | D5: D1 | E5: n/d | F5: n/d | G5: n/d | H5: n/d | I5: n/d | J5: n/d | K5: n/d | L5: n/d | M5: n/d | N5: n/d | O5: n/d | P5: n/d | Q5: n/d - no installed OCI MW. See K43 (incremental OCI revenue per delivered MW).
B6: tag | E6: n/d | F6: n/d | G6: n/d | H6: n/d | I6: n/d | J6: n/d | K6: n/d | L6: n/d | M6: n/d | N6: n/d | O6: n/d | P6: n/d
A7: K02 | B7: Revenue per active MW - average MW | C7: $M/MW-yr | D7: D1 | E7: n/d | F7: n/d | G7: n/d | H7: n/d | I7: n/d | J7: n/d | K7: n/d | L7: n/d | M7: n/d | N7: n/d | O7: n/d | P7: n/d | Q7: n/d (no installed MW).
B8: tag | E8: n/d | F8: n/d | G8: n/d | H8: n/d | I8: n/d | J8: n/d | K8: n/d | L8: n/d | M8: n/d | N8: n/d | O8: n/d | P8: n/d
A9: K03 | B9: Revenue per contracted MW | C9: $M/MW-yr | D9: D1 | E9: n/d | F9: n/d | G9: n/d | H9: n/d | I9: n/d | J9: n/d | K9: n/d | L9: n/d | M9: n/d | N9: n/d | O9: n/d | P9: n/d | Q9: n/d (no contracted MW; >10GW 'secured through partners' per calls).
B10: tag | E10: n/d | F10: n/d | G10: n/d | H10: n/d | I10: n/d | J10: n/d | K10: n/d | L10: n/d | M10: n/d | N10: n/d | O10: n/d | P10: n/d
A11: K04 | B11: Contracted / active MW (build-out multiple) | C11: x | D11: D1 | E11: n/d | F11: n/d | G11: n/d | H11: n/d | I11: n/d | J11: n/d | K11: n/d | L11: n/d | M11: n/d | N11: n/d | O11: n/d | P11: n/d | Q11: n/d
B12: tag | E12: n/d | F12: n/d | G12: n/d | H12: n/d | I12: n/d | J12: n/d | K12: n/d | L12: n/d | M12: n/d | N12: n/d | O12: n/d | P12: n/d
A13: K05 | B13: Adj. EBITDA per active MW (average MW) | C13: $M/MW-yr | D13: D1 | E13: n/d | F13: n/d | G13: n/d | H13: n/d | I13: n/d | J13: n/d | K13: n/d | L13: n/d | M13: n/d | N13: n/d | O13: n/d | P13: n/d | Q13: n/d - no OCI EBITDA. FQ3 FY26 call: ~32% gross margin on delivered AI capacity (management, not filed).
B14: tag | E14: n/d | F14: n/d | G14: n/d | H14: n/d | I14: n/d | J14: n/d | K14: n/d | L14: n/d | M14: n/d | N14: n/d | O14: n/d | P14: n/d
A15: B. Revenue per GPU and implied utilization
A16: K06 | B16: Revenue per GPU ($K per GPU-year, avg GPUs) | C16: $K/GPU-yr | D16: D2 | E16: n/d | F16: n/d | G16: n/d | H16: n/d | I16: n/d | J16: n/d | K16: n/d | L16: n/d | M16: n/d | N16: n/d | O16: n/d | P16: n/d | Q16: n/d (no GPU fleet count).
B17: tag | E17: n/d | F17: n/d | G17: n/d | H17: n/d | I17: n/d | J17: n/d | K17: n/d | L17: n/d | M17: n/d | N17: n/d | O17: n/d | P17: n/d
A18: K07 | B18: Implied blended realized price ($/GPU-hr) | C18: $/GPU-hr | D18: D2 | E18: n/d | F18: n/d | G18: n/d | H18: n/d | I18: n/d | J18: n/d | K18: n/d | L18: n/d | M18: n/d | N18: n/d | O18: n/d | P18: n/d | Q18: n/d
B19: tag | E19: n/d | F19: n/d | G19: n/d | H19: n/d | I19: n/d | J19: n/d | K19: n/d | L19: n/d | M19: n/d | N19: n/d | O19: n/d | P19: n/d
A20: K08 | B20: Fleet-weighted on-demand list price ($/GPU-hr) | C20: $/GPU-hr | D20: D3 | E20: n/d | F20: n/d | G20: n/d | H20: n/d | I20: n/d | J20: n/d | K20: n/d | L20: n/d | M20: n/d | N20: n/d | O20: n/d | P20: n/d | Q20: n/d (fleet mix unknown). OCI list Aug-Oct 2026: H100/H200 $10, B200 $14, B300 $15, GB200 $16, GB300 $18 per GPU-hr (inputs I12/I13) - ~1.6x CRWV's H100 list.
B21: tag | E21: n/d | F21: n/d | G21: n/d | H21: n/d | I21: n/d | J21: n/d | K21: n/d | L21: n/d | M21: n/d | N21: n/d | O21: n/d | P21: n/d
A22: K09 | B22: Implied utilization (realized $/GPU-hr / weighted list) | C22: % | D22: D3 | E22: n/d | F22: n/d | G22: n/d | H22: n/d | I22: n/d | J22: n/d | K22: n/d | L22: n/d | M22: n/d | N22: n/d | O22: n/d | P22: n/d | Q22: n/d. Oracle states physical GPU utilization instead (K41: 97.5% / 97.9%).
B23: tag | E23: n/d | F23: n/d | G23: n/d | H23: n/d | I23: n/d | J23: n/d | K23: n/d | L23: n/d | M23: n/d | N23: n/d | O23: n/d | P23: n/d
A24: C. Capex per MW ($M per MW)
A25: K10 | B25: Cash capex per new active MW | C25: $M/MW | D25: D4 | E25: n/d | F25: n/d | G25: n/d | H25: n/d | I25: n/d | J25: n/d | K25: n/d | L25: =IFERROR(Inputs!L46/Inputs!L13,"n/d") -> 77.290909 | M25: =IFERROR(Inputs!M46/Inputs!M13,"n/d") -> 30.0825 | N25: =IFERROR(Inputs!N46/Inputs!N13,"n/d") -> 46.5875 | O25: =IFERROR(Inputs!O46/Inputs!O13,"n/d") -> 56.872414 | P25: =IFERROR(Inputs!P46/Inputs!P13,"n/d") -> 33.528235 | Q25: SEGMENT-ALLOCATION ESTIMATE: (company capex x 100% OCI share, P05) / AI MW delivered in the quarter. Upper bound (100% allocation); capex leads delivery by 1-3 quarters; excludes leased shells (I51) -> compare with CRWV's leased-DC capex/MW, not owned-shell builds.
B26: tag | E26: n/d | F26: n/d | G26: n/d | H26: n/d | I26: n/d | J26: n/d | K26: n/d | L26: Estimated | M26: Estimated | N26: Estimated | O26: Estimated | P26: Estimated
A27: K11 | B27: Cash capex per new active MW (incl. estimated MW) | C27: $M/MW | D27: D4 | E27: n/d | F27: n/d | G27: n/d | H27: n/d | I27: n/d | J27: n/d | K27: n/d | L27: n/d | M27: n/d | N27: n/d | O27: n/d | P27: n/d
B28: tag | E28: n/d | F28: n/d | G28: n/d | H28: n/d | I28: n/d | J28: n/d | K28: n/d | L28: n/d | M28: n/d | N28: n/d | O28: n/d | P28: n/d
A29: K12 | B29: In-service additions per new active MW | C29: $M/MW | D29: D4 | E29: n/d | F29: n/d | G29: n/d | H29: n/d | I29: n/d | J29: n/d | K29: n/d | L29: n/d | M29: n/d | N29: n/d | O29: n/d | P29: n/d | Q29: n/d (in-service additions only annual).
B30: tag | E30: n/d | F30: n/d | G30: n/d | H30: n/d | I30: n/d | J30: n/d | K30: n/d | L30: n/d | M30: n/d | N30: n/d | O30: n/d | P30: n/d
A31: K13 | B31: Trailing-4Q cash capex per trailing-4Q new active MW | C31: $M/MW | D31: D4 | E31: n/d | F31: n/d | G31: n/d | H31: n/d | I31: n/d | J31: n/d | K31: n/d | L31: n/d | M31: n/d | N31: n/d | O31: =IFERROR(SUM(Inputs!L46:O46)/Inputs!O47,"n/d") -> 46.385833 | P31: =IFERROR(SUM(Inputs!M46:P46)/Inputs!P47,"n/d") -> 39 | Q31: Trailing-4Q OCI-attributed capex / trailing-4Q MW delivered. Q2'26 = FY26 capex 55.7B / '>1.2GW' (upper bound on $/MW since MW is a lower bound and capex allocation 100%). ESTIMATED.
B32: tag | E32: n/d | F32: n/d | G32: n/d | H32: n/d | I32: n/d | J32: n/d | K32: n/d | L32: n/d | M32: n/d | N32: n/d | O32: Estimated | P32: Estimated
A33: K14 | B33: Net PP&E per active MW (EoP) | C33: $M/MW | D33: D4 | E33: n/d | F33: n/d | G33: n/d | H33: n/d | I33: n/d | J33: n/d | K33: n/d | L33: n/d | M33: n/d | N33: n/d | O33: n/d | P33: n/d | Q33: n/d (no installed MW).
B34: tag | E34: n/d | F34: n/d | G34: n/d | H34: n/d | I34: n/d | J34: n/d | K34: n/d | L34: n/d | M34: n/d | N34: n/d | O34: n/d | P34: n/d
A35: K15 | B35: Gross in-service PP&E per active MW (EoP) | C35: $M/MW | D35: D4 | E35: n/d | F35: n/d | G35: n/d | H35: n/d | I35: n/d | J35: n/d | K35: n/d | L35: n/d | M35: n/d | N35: n/d | O35: n/d | P35: n/d | Q35: n/d (no installed MW).
B36: tag | E36: n/d | F36: n/d | G36: n/d | H36: n/d | I36: n/d | J36: n/d | K36: n/d | L36: n/d | M36: n/d | N36: n/d | O36: n/d | P36: n/d
A37: D. D&A useful lives and depreciation yield
A38: K16 | B38: Useful life - GPU / server equipment | C38: years | D38: D5 | E38: n/d | F38: =IFERROR(Inputs!F32,"n/d") -> 5 | G38: =IFERROR(Inputs!G32,"n/d") -> 5 | H38: =IFERROR(Inputs!H32,"n/d") -> 6 | I38: =IFERROR(Inputs!I32,"n/d") -> 6 | J38: =IFERROR(Inputs!J32,"n/d") -> 6 | K38: =IFERROR(Inputs!K32,"n/d") -> 6 | L38: =IFERROR(Inputs!L32,"n/d") -> 6 | M38: =IFERROR(Inputs!M32,"n/d") -> 6 | ... P38: =IFERROR(Inputs!P32,"n/d") -> 6 | Q38: Servers & networking: 4->5 yrs (FY23), 5->6 yrs effective FY25 (Jun-2024; +$733M FY25 opex benefit). No change through Aug-26 10-Q. CRWV 6, Nebius 5 (from 2026), IREN 5.
B39: tag | E39: n/d | F39: Reported | G39: Reported | H39: Reported | I39: Reported | J39: Reported | K39: Reported | L39: Reported | M39: Reported | N39: Reported | O39: Reported | P39: Reported
A40: K17 | B40: Depreciation yield (D&A x4 / avg in-service gross PP&E) | C40: % | D40: D5 | E40: n/d | F40: n/d | G40: n/d | H40: n/d | I40: n/d | J40: n/d | K40: n/d | L40: n/d | M40: n/d | N40: n/d | O40: n/d | P40: =IFERROR(Inputs!P6*4/((Inputs!O49+Inputs!P49)/2)*100,"n/d") -> 13.449246 | Q40: Quarterly yield computable only where gross & CIP exist at both ends (May-26 -> Aug-26). Annual version in memo M05.
...

Sheet Inputs
A1: Inputs - Oracle OCI (ORCL) - Cloud Infrastructure perimeter. Reported (blue), derived (black), estimated (orange), n/d (grey). Per-cell source detail on Sources tab. Row 2 = fiscal quarter / period end mapped to each calendar column.
E2: FQ2 FY24 (Nov-23) | F2: FQ3 FY24 (Feb-24) | G2: FQ4 FY24 (May-24) | H2: FQ1 FY25 (Aug-24) | I2: FQ2 FY25 (Nov-24) | J2: FQ3 FY25 (Feb-25) | K2: FQ4 FY25 (May-25) | L2: FQ1 FY26 (Aug-25) | M2: FQ2 FY26 (Nov-25) | N2: FQ3 FY26 (Feb-26) | O2: FQ4 FY26 (May-26) | P2: FQ1 FY27 (Aug-26)
A3: ID | B3: Item | C3: Unit | D3: Tag mix | E3: Q4'23* | F3: Q1'24 | G3: Q2'24 | H3: Q3'24 | I3: Q4'24 | J3: Q1'25 | K3: Q2'25 | L3: Q3'25 | M3: Q4'25 | N3: Q1'26 | O3: Q2'26 | P3: Q3'26† | Q3: Source summary / notes
A4: I01 | B4: OCI revenue = 'Cloud infrastructure' revenue (IaaS) | C4: $M | D4: Derived/Reported | E4: n/d | F4: 1779.9 | G4: 1970.4 | H4: 2154 | I4: 2434 | J4: 2652 | K4: 2995 | L4: 3347 | M4: 4079 | N4: 4888 | O4: 5787 | P4: 7388 | Q4: FQ3 FY25 earnings PR (8-K Ex.99.1, 2025-03-10); FQ4 FY25 earnings PR (8-K Ex.99.1, 2025-06-11); FQ4 FY26 earnings PR (8-K Ex.99.1, 2026-06); FQ1 FY27 earnings PR (8-K Ex.99.1, 2026-09-10) | NOTE: OCI is not a reported segment: 'Cloud infrastructure' is a revenue line inside the Cloud & license segment. Includes non-AI OCI (general compute, database on OCI, multicloud) - AI share not disclosed (FQ3 FY26 call: AI infrastructure revenue +243% YoY, no level).
A5: I02 | B5: Adj. EBITDA of OCI | C5: $M | D5: n/d | E5: n/d | F5: n/d | G5: n/d | H5: n/d | I5: n/d | J5: n/d | K5: n/d | L5: n/d | M5: n/d | N5: n/d | O5: n/d | P5: n/d | Q5: | NOTE: n/d - no segment EBITDA/margin for OCI. FQ3 FY26 call: gross margin on delivered AI capacity ~32% (company statement, not a filed metric).
A6: I03 | B6: Depreciation (company-wide, cash-flow statement; excl. intangible amortization) | C6: $M | D6: Derived/Reported | E6: n/d | F6: 808 | G6: 811 | H6: 804 | I6: 908 | J6: 1003 | K6: 1152 | L6: 1351 | M6: 1704 | N6: 2153 | O6: 2415 | P6: 3156 | Q6: FQ3 FY24 earnings PR (8-K Ex.99.1, 2024-03-11); FQ4 FY24 earnings PR (8-K Ex.99.1, 2024-06-11); FQ1 FY25 earnings PR (8-K Ex.99.1, 2024-09-09); FQ2 FY25 earnings PR (8-K Ex.99.1, 2024-12-09); FQ3 FY25 earnings PR (8-K Ex.99.1, 2025-03-10); FQ4 FY25 earnings PR (8-K Ex.99.1, 2025-06-11); FQ1 FY26 earnings PR (8-K Ex.99.1, 2025-09-09); FQ2 FY26 earnings PR (8-K Ex.99.1, 2025-12-10); FQ3 FY26 earnings PR (8-K Ex.99.1, 2026-03-10); FQ4 FY26 earnings PR (8-K Ex.99.1, 2026-06); FQ1 FY27 earnings PR (8-K Ex.99.1, 2026-09-10) | NOTE: Company-wide PP&E depreciation (OCI not separable).
A7: I50 | B7: Cash capex, company-wide (capital expenditures, CF statement) | C7: $M | D7: Derived/Reported | E7: n/d | F7: 1674 | G7: 2798 | H7: 2303 | I7: 3970 | J7: 5862 | K7: 9080 | L7: 8502 | M7: 12033 | N7: 18635 | O7: 16493 | P7: 28499 | Q7: FQ3 FY24 earnings PR (8-K Ex.99.1, 2024-03-11); FQ4 FY24 earnings PR (8-K Ex.99.1, 2024-06-11); FQ1 FY25 earnings PR (8-K Ex.99.1, 2024-09-09); FQ2 FY25 earnings PR (8-K Ex.99.1, 2024-12-09); FQ3 FY25 earnings PR (8-K Ex.99.1, 2025-03-10); FQ4 FY25 earnings PR (8-K Ex.99.1, 2025-06-11); FQ1 FY26 earnings PR (8-K Ex.99.1, 2025-09-09); FQ2 FY26 earnings PR (8-K Ex.99.1, 2025-12-10); FQ3 FY26 earnings PR (8-K Ex.99.1, 2026-03-10); FQ4 FY26 earnings PR (8-K Ex.99.1, 2026-06); FQ1 FY27 earnings PR (8-K Ex.99.1, 2026-09-10) | NOTE: Excludes leased data-center shells (operating leases; see I43/I51) and GPUs obtained via unconditional purchase commitments / leases.
A8: I05 | B8: Gross PP&E (EoP) | C8: $M | D8: Reported | E8: n/d | F8: n/d | G8: 34818 | H8: n/d | I8: n/d | J8: n/d | K8: 59554 | L8: n/d | M8: n/d | N8: n/d | O8: 122651 | P8: 153596 | Q8: 10-K FY24 (FYE 31-May-2024); 10-K FY25 (FYE 31-May-2025); 10-K FY26 (FYE 31-May-2026); 10-Q FQ1 FY27 (Aug-26), filed 2026-09
A9: I06 | B9: Construction in progress (EoP) | C9: $M | D9: Reported | E9: n/d | F9: n/d | G9: 5634 | H9: n/d | I9: n/d | J9: n/d | K9: 16510 | L9: n/d | M9: n/d | N9: n/d | O9: 39973 | P9: 48546 | Q9: 10-K FY24 (FYE 31-May-2024); 10-K FY25 (FYE 31-May-2025); 10-K FY26 (FYE 31-May-2026); 10-Q FQ1 FY27 (Aug-26), filed 2026-09
A10: I07 | B10: PP&E, net (EoP) | C10: $M | D10: Reported | E10: 18009 | F10: 19117 | G10: 21536 | H10: 23094 | I10: 26432 | J10: 31970 | K10: 43522 | L10: 53194 | M10: 67875 | N10: 83617 | O10: 99957 | P10: 127845 | Q10: 10-Q FQ3 FY24 (Feb-24); 10-K FY24 (FYE 31-May-2024); 10-Q FQ1 FY25 (Aug-24); 10-Q FQ2 FY25 (Nov-24); 10-Q FQ3 FY25 (Feb-25); 10-K FY25 (FYE 31-May-2025); 10-Q FQ1 FY26 (Aug-25); 10-Q FQ2 FY26 (Nov-25); 10-Q FQ3 FY26 (Feb-26); 10-K FY26 (FYE 31-May-2026); 10-Q FQ1 FY27 (Aug-26), filed 2026-09
A11: I08 | B11: Computer, network, machinery & equipment, gross (EoP) | C11: $M | D11: Reported | E11: n/d | F11: n/d | G11: 20989 | H11: n/d | I11: n/d | J11: n/d | K11: 30345 | L11: n/d | M11: n/d | N11: n/d | O11: 59634 | P11: 77755 | Q11: 10-K FY24 (FYE 31-May-2024); 10-K FY25 (FYE 31-May-2025); 10-K FY26 (FYE 31-May-2026); 10-Q FQ1 FY27 (Aug-26), filed 2026-09
A12: I09 | B12: Installed / active OCI (AI) MW (EoP) | C12: MW | D12: n/d | E12: n/d | F12: n/d | G12: n/d | H12: n/d | I12: n/d | J12: n/d | K12: n/d | L12: n/d | M12: n/d | N12: n/d | O12: n/d | P12: n/d | Q12: | NOTE: n/d - Oracle discloses MW DELIVERED per quarter (I09N), never an installed base. Cumulative deliveries since Jun-25 in I45E (Estimated).
A13: I09N | B13: AI capacity delivered to customers in quarter | C13: MW | D13: Estimated/Reported | E13: n/d | F13: n/d | G13: n/d | H13: n/d | I13: n/d | J13: n/d | K13: n/d | L13: 110 | M13: 400 | N13: 400 | O13: 290 | P13: 850 | Q13: Analyst assumption (this workbook) - segment allocation; Oracle FQ2 FY26 earnings call transcript (Motley Fool, 2025-12-10); Oracle FQ3 FY26 earnings call - CEO blog 'From the Q3 earnings call' (+ transcript 2026-03-10); Oracle FQ1 FY27 earnings call transcript (Motley Fool, 2026-09-11); FQ1 FY27 earnings PR (8-K Ex.99.1, 2026-09-10) | NOTE: MW basis (IT vs gross) not stated; >300k GPUs in 850MW (~353 GPUs/MW) vs Nebius GB200 538/IT-MW suggests gross/facility MW. Abilene: 618MW = ~75% of site delivered by Aug-26.
A14: I10 | B14: Contracted MW (EoP) | C14: MW | D14: n/d | E14: n/d | F14: n/d | G14: n/d | H14: n/d | I14: n/d | J14: n/d | K14: n/d | L14: n/d | M14: n/d | N14: n/d | O14: n/d | P14: n/d | Q14: | NOTE: n/d as a filed metric. Calls: '>10 GW secured through partners'. Stargate/Abilene ~1.2GW site (618MW delivered = 75%).
A15: I11 | B15: GPUs deployed (fleet, EoP) | C15: GPUs | D15: n/d | E15: n/d | F15: n/d | G15: n/d | H15: n/d | I15: n/d | J15: n/d | K15: n/d | L15: n/d | M15: n/d | N15: n/d | O15: n/d | P15: n/d | Q15: | NOTE: n/d fleet count. FQ1 FY27: '>300k GPUs' in the 850MW delivered that quarter (I46); Abilene 131k GPUs delivered in FQ1 FY27.
A16: I12 | B16: OCI H100 on-demand list price (BM.GPU.H100.8 / 8) | C16: $/GPU-hr | D16: Reported | E16: n/d | F16: n/d | G16: n/d | H16: n/d | I16: n/d | J16: n/d | K16: n/d | L16: n/d | M16: n/d | N16: n/d | O16: n/d | P16: 10 | Q16: Nebius workspace: /workspace/nebius/parts/price_history_raw.csv + price_snapshot_2026-10-04.csv (OCI list, GPU Market agent; observations Aug-Oct 2026 only) | NOTE: No earlier snapshots in the price set -> n/d before Q3'26.
A17: I13 | B17: OCI GB200 list price | C17: $/GPU-hr | D17: Reported | E17: n/d | F17: n/d | G17: n/d | H17: n/d | I17: n/d | J17: n/d | K17: n/d | L17: n/d | M17: n/d | N17: n/d | O17: n/d | P17: 16 | Q17: Nebius workspace: /workspace/nebius/parts/price_history_raw.csv + price_snapshot_2026-10-04.csv (OCI list, GPU Market agent; observations Aug-Oct 2026 only)
A18: I14 | B18: RPO (company-wide, ASC 606, EoP) | C18: $B | D18: Reported | E18: 65.5 | F18: 80.2 | G18: 97.9 | H18: 99.1 | I18: 97.3 | J18: 130.2 | K18: 137.8 | L18: 455.3 | M18: 523.3 | N18: 552.6 | O18: 638 | P18: 664 | Q18: SEC companyfacts XBRL CIK 0001341439 (local copy comps_raw/cf_0001341439.json); 10-Q FQ3 FY24 (Feb-24); 10-K FY24 (FYE 31-May-2024); 10-Q FQ1 FY25 (Aug-24); 10-Q FQ2 FY25 (Nov-24); 10-Q FQ3 FY25 (Feb-25); 10-K FY25 (FYE 31-May-2025); 10-Q FQ1 FY26 (Aug-25); 10-Q FQ2 FY26 (Nov-25); 10-Q FQ3 FY26 (Feb-26); 10-K FY26 (FYE 31-May-2026); 10-Q FQ1 FY27 (Aug-26), filed 2026-09 | NOTE: Company-wide (incl. SaaS/license support). Growth from FQ1 FY26 'primarily attributable to certain significant cloud contracts' (10-K FY26) - i.e., OCI AI contracts (OpenAI/Stargate, Meta, xAI etc.).
A19: I15 | B19: Backlog incl. non-RPO | C19: $B | D19: n/d | E19: n/d | F19: n/d | G19: n/d | H19: n/d | I19: n/d | J19: n/d | K19: n/d | L19: n/d | M19: n/d | N19: n/d | O19: n/d | P19: n/d | Q19: | NOTE: Oracle reports RPO only.
A20: I16 | B20: RPO % within 24 months (ESTIMATED: 12m % + half of 13-36m %) | C20: % | D20: Estimated | E20: n/d | F20: 60.5 | G20: 57 | H20: 57 | I20: 58.5 | J20: 51 | K20: 53.5 | L20: 22.5 | M20: 25 | N20: 27.5 | O20: 29 | P20: 31.5 | Q20: 10-Q FQ3 FY24 (Feb-24); 10-K FY24 (FYE 31-May-2024); 10-Q FQ1 FY25 (Aug-24); 10-Q FQ2 FY25 (Nov-24); 10-Q FQ3 FY25 (Feb-25); 10-K FY25 (FYE 31-May-2025); 10-Q FQ1 FY26 (Aug-25); 10-Q FQ2 FY26 (Nov-25); 10-Q FQ3 FY26 (Feb-26); 10-K FY26 (FYE 31-May-2026); 10-Q FQ1 FY27 (Aug-26), filed 2026-09 | NOTE: Oracle discloses <=12m and 13-36m buckets; 24m share interpolated linearly within the 13-36m bucket (assumption).
A21: I17 | B21: Largest customer, % of revenue | C21: % | D21: n/d | E21: n/d | F21: n/d | G21: n/d | H21: n/d | I21: n/d | J21: n/d | K21: n/d | L21: n/d | M21: n/d | N21: n/d | O21: n/d | P21: n/d | Q21: | NOTE: No customer >=10% of revenue in FY24-FY26 (10-K concentration note) -> largest <10% (not disclosed).
A22: I18 | B22: 2nd-largest customer % | C22: % | D22: n/d | E22: n/d | F22: n/d | G22: n/d | H22: n/d | I22: n/d | J22: n/d | K22: n/d | L22: n/d | M22: n/d | N22: n/d | O22: n/d | P22: n/d
A23: I19 | B23: 3rd-largest customer % | C23: % | D23: n/d | E23: n/d | F23: n/d | G23: n/d | H23: n/d | I23: n/d | J23: n/d | K23: n/d | L23: n/d | M23: n/d | N23: n/d | O23: n/d | P23: n/d
A24: I20 | B24: Customers >=10% of revenue (count; fiscal-year basis) | C24: # | D24: Reported | E24: n/d | F24: n/d | G24: 0 | H24: n/d | I24: n/d | J24: n/d | K24: 0 | L24: n/d | M24: n/d | N24: n/d | O24: 0 | P24: n/d | Q24: 10-K FY24 (FYE 31-May-2024); 10-K FY25 (FYE 31-May-2025); 10-K FY26 (FYE 31-May-2026)
A25: I21 | B25: Interest expense (P&L, as reported) | C25: $M | D25: Reported | E25: n/d | F25: 876 | G25: 878 | H25: 842 | I25: 866 | J25: 892 | K25: 978 | L25: 923 | M25: 1057 | N25: 1180 | O25: 1438 | P25: 1428 | Q25: FQ3 FY24 earnings PR (8-K Ex.99.1, 2024-03-11); FQ4 FY24 earnings PR (8-K Ex.99.1, 2024-06-11); FQ1 FY25 earnings PR (8-K Ex.99.1, 2024-09-09); FQ2 FY25 earnings PR (8-K Ex.99.1, 2024-12-09); FQ3 FY25 earnings PR (8-K Ex.99.1, 2025-03-10); FQ4 FY25 earnings PR (8-K Ex.99.1, 2025-06-11); FQ1 FY26 earnings PR (8-K Ex.99.1, 2025-09-09); FQ2 FY26 earnings PR (8-K Ex.99.1, 2025-12-10); FQ3 FY26 earnings PR (8-K Ex.99.1, 2026-03-10); FQ4 FY26 earnings PR (8-K Ex.99.1, 2026-06); FQ1 FY27 earnings PR (8-K Ex.99.1, 2026-09-10) | NOTE: As reported (after any capitalized interest; Oracle does not disclose capitalized interest in PRs/10-Qs in this set).
A26: I22 | B26: Capitalized interest | C26: $M | D26: n/d | E26: n/d | F26: n/d | G26: n/d | H26: n/d | I26: n/d | J26: n/d | K26: n/d | L26: n/d | M26: n/d | N26: n/d | O26: n/d | P26: n/d
A27: I23 | B27: Total borrowings, carrying value (notes payable & other borrowings, current + non-current) | C27: $M | D27: Reported | E27: n/d | F27: 87980 | G27: 86869 | H27: 84515 | I27: 88624 | J27: 96276 | K27: 92568 | L27: 91315 | M27: 108075 | N27: 134605 | O27: 129541 | P27: 125337 | Q27: FQ3 FY24 earnings PR (8-K Ex.99.1, 2024-03-11); FQ4 FY24 earnings PR (8-K Ex.99.1, 2024-06-11); FQ1 FY25 earnings PR (8-K Ex.99.1, 2024-09-09); FQ2 FY25 earnings PR (8-K Ex.99.1, 2024-12-09); FQ3 FY25 earnings PR (8-K Ex.99.1, 2025-03-10); FQ4 FY25 earnings PR (8-K Ex.99.1, 2025-06-11); FQ1 FY26 earnings PR (8-K Ex.99.1, 2025-09-09); FQ2 FY26 earnings PR (8-K Ex.99.1, 2025-12-10); FQ3 FY26 earnings PR (8-K Ex.99.1, 2026-03-10); FQ4 FY26 earnings PR (8-K Ex.99.1, 2026-06); FQ1 FY27 earnings PR (8-K Ex.99.1, 2026-09-10) | NOTE: Balance-sheet carrying value (net of unamortized discount/issuance costs); 10-K debt tables (Debt_Facilities) are at principal -> check row shows the difference.
A28: I24 | B28: Company-reported weighted average interest rate | C28: % | D28: n/d | E28: n/d | F28: n/d | G28: n/d | H28: n/d | I28: n/d | J28: n/d | K28: n/d | L28: n/d | M28: n/d | N28: n/d | O28: n/d | P28: n/d
A29: I25 | B29: Company-definition capex | C29: $M | D29: n/d | E29: n/d | F29: n/d | G29: n/d | H29: n/d | I29: n/d | J29: n/d | K29: n/d | L29: n/d | M29: n/d | N29: n/d | O29: n/d | P29: n/d
A30: I26 | B30: Days in quarter | C30: days | D30: Reported | E30: n/d | F30: 91 | G30: 92 | H30: 92 | I30: 91 | J30: 90 | K30: 92 | L30: 92 | M30: 91 | N30: 90 | O30: 92 | P30: 92 | Q30: calendar
A31: I27 | B31: Data center regions | C31: # | D31: n/d | E31: n/d | F31: n/d | G31: n/d | H31: n/d | I31: n/d | J31: n/d | K31: n/d | L31: n/d | M31: n/d | N31: n/d | O31: n/d | P31: n/d
A32: I28 | B32: Useful life - servers & networking equipment | C32: years | D32: Reported | E32: n/d | F32: 5 | G32: 5 | H32: 6 | I32: 6 | J32: 6 | K32: 6 | L32: 6 | M32: 6 | N32: 6 | O32: 6 | P32: 6 | Q32: 10-K FY24 (FYE 31-May-2024); 10-Q FQ1 FY25 (Aug-24); 10-Q FQ2 FY25 (Nov-24); 10-Q FQ3 FY25 (Feb-25); 10-K FY25 (FYE 31-May-2025); 10-K FY26 (FYE 31-May-2026) | NOTE: PP&E table: computer, network, machinery & equipment 1-5 yrs (FY24) -> 1-6 yrs (FY25-FY26, Aug-26 10-Q).
A33: I29 | B33: Company-reported GPU utilization | C33: % | D33: Reported | E33: n/d | F33: n/d | G33: n/d | H33: n/d | I33: n/d | J33: n/d | K33: n/d | L33: n/d | M33: n/d | N33: n/d | O33: 97.5 | P33: 97.9 | Q33: Oracle FQ4 FY26 earnings call - CEO blog 'From the Q4 earnings call'; Oracle FQ1 FY27 earnings call transcript (Motley Fool, 2026-09-11) | NOTE: Physical GPU utilization of delivered fleet (management statement on call, not in filings).
A34: I30 | B34: RPO % expected to be recognized within 12 months | C34: % | D34: Reported | E34: n/d | F34: 43 | G34: 39 | H34: 38 | I34: 39 | J34: 31 | K34: 33 | L34: 10 | M34: 10 | N34: 12 | O34: 12 | P34: 13 | Q34: 10-Q FQ3 FY24 (Feb-24); 10-K FY24 (FYE 31-May-2024); 10-Q FQ1 FY25 (Aug-24); 10-Q FQ2 FY25 (Nov-24); 10-Q FQ3 FY25 (Feb-25); 10-K FY25 (FYE 31-May-2025); 10-Q FQ1 FY26 (Aug-25); 10-Q FQ2 FY26 (Nov-25); 10-Q FQ3 FY26 (Feb-26); 10-K FY26 (FYE 31-May-2026); 10-Q FQ1 FY27 (Aug-26), filed 2026-09
A35: I31 | B35: GPU-compute hardware, gross | C35: $M | D35: n/d | E35: n/d | F35: n/d | G35: n/d | H35: n/d | I35: n/d | J35: n/d | K35: n/d | L35: n/d | M35: n/d | N35: n/d | O35: n/d | P35: n/d | Q35: | NOTE: n/d (I08 covers all computer/network equipment, not GPU-only).
A36: I32 | B36: OCI cost of revenue | C36: $M | D36: n/d | E36: n/d | F36: n/d | G36: n/d | H36: n/d | I36: n/d | J36: n/d | K36: n/d | L36: n/d | M36: n/d | N36: n/d | O36: n/d | P36: n/d | Q36: | NOTE: n/d (Oracle reports cloud services & license support expenses combined).
A37: I40 | B37: Total revenue (company) | C37: $M | D37: Derived/Reported | E37: n/d | F37: 13280 | G37: 14287 | H37: 13307 | I37: 14059 | J37: 14130 | K37: 15903 | L37: 14926 | M37: 16058 | N37: 17190 | O37: 19184 | P37: 19345 | Q37: SEC companyfacts XBRL CIK 0001341439 (local copy comps_raw/cf_0001341439.json)
A38: I43 | B38: Operating lease liabilities (EoP) | C38: $M | D38: Reported | E38: n/d | F38: n/d | G38: 7545 | H38: n/d | I38: n/d | J38: n/d | K38: 13450 | L38: 16290 | M38: 18679 | N38: 21310 | O38: 30190 | P38: 34621 | Q38: 10-K FY24 (FYE 31-May-2024); 10-K FY25 (FYE 31-May-2025); 10-Q FQ1 FY26 (Aug-25); 10-Q FQ2 FY26 (Nov-25); 10-Q FQ3 FY26 (Feb-26); 10-K FY26 (FYE 31-May-2026); 10-Q FQ1 FY27 (Aug-26), filed 2026-09
A39: I46 | B39: GPUs delivered in quarter | C39: GPUs | D39: Reported | E39: n/d | F39: n/d | G39: n/d | H39: n/d | I39: n/d | J39: n/d | K39: n/d | L39: n/d | M39: n/d | N39: n/d | O39: n/d | P39: 300000 | Q39: FQ1 FY27 earnings PR (8-K Ex.99.1, 2026-09-10)
A40: I51 | B40: Lease commitments not yet commenced (substantially all data centers) | C40: $B | D40: Reported | E40: n/d | F40: n/d | G40: n/d | H40: n/d | I40: n/d | J40: 48.4 | K40: 43.4 | L40: 99.8 | M40: 248 | N40: 261 | O40: 260 | P40: 288 | Q40: 10-Q FQ3 FY25 (Feb-25); 10-K FY25 (FYE 31-May-2025); 10-Q FQ1 FY26 (Aug-25); 10-Q FQ2 FY26 (Nov-25); 10-Q FQ3 FY26 (Feb-26); 10-K FY26 (FYE 31-May-2026); 10-Q FQ1 FY27 (Aug-26), filed 2026-09 | NOTE: Off-balance-sheet DC lease commitments = Oracle's contracted capacity pipeline (capacity built by partners e.g. Crusoe/Blue Owl at Abilene). Not in capex.
...

Sheet Debt_Facilities
A1: Debt by facility - Oracle OCI (ORCL) - Cloud Infrastructure perimeter. Principal ($M) and effective interest rate (%) as printed in each period-end debt table. Excludes leases. Weighted rates exclude facilities without a disclosed rate from the denominator.
A2: Annual snapshots only (10-K tables list every note with effective rate; 10-Qs list only new issuances). Principal = 'Amount' column; check row vs Inputs I23 = unamortized discount/issuance costs & fair-value adjustments (carrying basis). Floating-rate senior notes included in 'Senior notes' (flagged [floating]); term loans (SOFR+1.35-1.70%) in 'Other term loans'; commercial paper in 'Revolver / commercial paper'. Quarterly funding cost: K36 (interest expense x4 / avg carrying debt).
A4: Facility | B4: Category | C4: May-24 principal | D4: May-24 eff. rate % | E4: May-25 principal | F4: May-25 eff. rate % | G4: May-26 principal | H4: May-26 eff. rate %
A5: $2,000, 3.40%, due July 2024 | B5: Senior notes | C5: 2000 | D5: 3.43
A6: $2,000, 2.95%, due November 2024 | B6: Senior notes | C6: 2000 | D6: 3.01
A7: $3,500, 2.50%, due April 2025 | B7: Senior notes | C7: 3500 | D7: 2.54
A8: $2,500, 2.95%, due May 2025 | B8: Senior notes | C8: 2500 | D8: 3.05
A9: €750, 3.125%, due July 2025 | B9: Senior notes | C9: 808 | D9: 3.17 | E9: 841 | F9: 3.17
A10: $1,000, 5.80%, due November 2025 | B10: Senior notes | C10: 1000 | D10: 5.93 | E10: 1000 | F10: 5.93
A11: $2,750, 1.65%, due March 2026 | B11: Senior notes | C11: 2750 | D11: 1.67 | E11: 2750 | F11: 1.67
A12: $3,000, 2.65%, due July 2026 | B12: Senior notes | C12: 3000 | D12: 2.73 | E12: 3000 | F12: 2.73 | G12: 3000 | H12: 2.73
A13: $2,250, 2.80%, due April 2027 | B13: Senior notes | C13: 2250 | D13: 2.87 | E13: 2250 | F13: 2.87 | G13: 2250 | H13: 2.87
A14: $2,750, 3.25%, due November 2027 | B14: Senior notes | C14: 2750 | D14: 3.29 | E14: 2750 | F14: 3.29 | G14: 2750 | H14: 3.29
A15: $2,000, 2.30%, due March 2028 | B15: Senior notes | C15: 2000 | D15: 2.36 | E15: 2000 | F15: 2.36 | G15: 2000 | H15: 2.36
A16: $750, 4.50%, due May 2028 | B16: Senior notes | C16: 750 | D16: 4.6 | E16: 750 | F16: 4.6 | G16: 750 | H16: 4.6
A17: $1,250, 6.15%, due November 2029 | B17: Senior notes | C17: 1250 | D17: 6.21 | E17: 1250 | F17: 6.21 | G17: 1250 | H17: 6.21
A18: $3,250, 2.95%, due April 2030 | B18: Senior notes | C18: 3250 | D18: 3 | E18: 3250 | F18: 3 | G18: 3250 | H18: 3
A19: $750, 4.65%, due May 2030 | B19: Senior notes | C19: 750 | D19: 4.75 | E19: 750 | F19: 4.75 | G19: 750 | H19: 4.75
A20: $500, 3.25%, due May 2030 | B20: Senior notes | C20: 500 | D20: 3.35 | E20: 500 | F20: 3.35 | G20: 500 | H20: 3.35
A21: $3,250, 2.875%, due March 2031 | B21: Senior notes | C21: 3250 | D21: 2.92 | E21: 3250 | F21: 2.92 | G21: 3250 | H21: 2.92
A22: $2,250, 6.25%, due November 2032 | B22: Senior notes | C22: 2250 | D22: 6.32 | E22: 2250 | F22: 6.32 | G22: 2250 | H22: 6.32
A23: $1,500, 4.90%, due February 2033 | B23: Senior notes | C23: 1500 | D23: 4.95 | E23: 1500 | F23: 4.95 | G23: 1500 | H23: 4.95
... A43: $1,500, 4.10%, due March 2061 | B43: Senior notes | C43: 1500 | D43: 4.13 | E43: 1500 | F43: 4.13 | G43: 1500 | H43: 4.13
A44: $790, SOFR plus 1.70%, due August 2025 | B44: Other term loans | C44: 790 | D44: 6.99
A45: $170, SOFR plus 1.70%, due August 2025 | B45: Other term loans | C45: 170 | D45: 6.98
A46: $3,570, SOFR plus 1.70%, due August 2027 | B46: Other term loans | C46: 3570 | D46: 6.99
A47: $1,100, SOFR plus 1.70%, due August 2027 | B47: Other term loans | C47: 1100 | D47: 6.98
A48: Commercial paper notes | B48: Revolver / commercial paper | C48: 401 | D48: 5.43 | E48: 2294 | F48: 4.88 | G48: 1468 | H48: 4.35
A49: Other borrowings due August 2025 | B49: Other borrowings | C49: 113 | D49: 3.53 | E49: 113 | F49: 3.53
A50: $1,500, 4.80%, due August 2028 | B50: Senior notes | E50: 1500 | F50: 4.94 | G50: 1500 | H50: 4.94
A51: $1,500, 4.20%, due September 2029 | B51: Senior notes | E51: 1500 | F51: 4.27 | G51: 1500 | H51: 4.27
A52: $1,250, 5.25%, due February 2032 | B52: Senior notes | E52: 1250 | F52: 5.36 | G52: 1250 | H52: 5.36
A53: $1,750, 4.70%, due September 2034 | B53: Senior notes | E53: 1750 | F53: 4.77 | G53: 1750 | H53: 4.77
A54: $1,750, 5.50%, due August 2035 | B54: Senior notes | E54: 1750 | F54: 5.55 | G54: 1750 | H54: 5.55
A55: $1,750, 5.375%, due September 2054 | B55: Senior notes | E55: 1750 | F55: 5.43 | G55: 1750 | H55: 5.43
A56: $1,750, 6.00%, due August 2055 | B56: Senior notes | E56: 1750 | F56: 6.04 | G56: 1750 | H56: 6.04
A57: $1,250, 5.50%, due September 2064 | B57: Senior notes | E57: 1250 | F57: 5.55 | G57: 1250 | H57: 5.55
A58: $1,000, 6.125%, due August 2065 | B58: Senior notes | E58: 1000 | F58: 6.17 | G58: 1000 | H58: 6.17
A59: $500, Compounded SOFR plus 0.76%, due August 2028 [floating] | B59: Senior notes | E59: 500 | F59: 5.28 | G59: 500 | H59: 4.43
A60: $5,630, SOFR plus 1.35%, due August 2027 | B60: Other term loans | E60: 5419 | F60: 6.1 | G60: 5137 | H60: 5.29
...

Sheet Sources
A1: Input ID | B1: Item | C1: Period | D1: Value | E1: Tag | F1: Document | G1: Section / page / formula | H1: URL
A2: I01 | B2: OCI revenue = 'Cloud infrastructure' revenue (IaaS) | C2: Q1'24 | D2: 1779.9 | E2: Derived | F2: FQ3 FY25 earnings PR (8-K Ex.99.1, 2025-03-10) | G2: calc: FQ3 FY25 2,652 / 1.49 (PR: cloud infrastructure +49% USD); headline '$1.8 billion' (FQ3 FY24 PR) | H2: https://www.sec.gov/Archives/edgar/data/1341439/000095017025036295/orcl-ex99_1.htm
A3: I01 | B3: OCI revenue = 'Cloud infrastructure' revenue (IaaS) | C3: Q2'24 | D3: 1970.4 | E3: Derived | F3: FQ4 FY25 earnings PR (8-K Ex.99.1, 2025-06-11) | G3: calc: FQ4 FY25 2,995 / 1.52 (+52% USD); headline '$2.0 billion' (FQ4 FY24 PR) | H3: https://www.sec.gov/Archives/edgar/data/1341439/000095017025084831/orcl-ex99_1.htm
A4: I01 | B4: OCI revenue = 'Cloud infrastructure' revenue (IaaS) | C4: Q3'24 | D4: 2154 | E4: Reported | F4: FQ4 FY26 earnings PR (8-K Ex.99.1, 2026-06) | G4: FQ4 FY26 PR revenue-by-offering table (FY25 quarters) | H4: https://www.sec.gov/Archives/edgar/data/1341439/000119312526265848/orcl-ex99_1.htm
A5: I01 | B5: OCI revenue = 'Cloud infrastructure' revenue (IaaS) | C5: Q4'24 | D5: 2434 | E5: Reported | F5: FQ4 FY26 earnings PR (8-K Ex.99.1, 2026-06) | G5: same | H5: https://www.sec.gov/Archives/edgar/data/1341439/000119312526265848/orcl-ex99_1.htm
A6: I01 | B6: OCI revenue = 'Cloud infrastructure' revenue (IaaS) | C6: Q1'25 | D6: 2652 | E6: Reported | F6: FQ4 FY26 earnings PR (8-K Ex.99.1, 2026-06) | G6: same | H6: https://www.sec.gov/Archives/edgar/data/1341439/000119312526265848/orcl-ex99_1.htm
A7: I01 | B7: OCI revenue = 'Cloud infrastructure' revenue (IaaS) | C7: Q2'25 | D7: 2995 | E7: Reported | F7: FQ4 FY26 earnings PR (8-K Ex.99.1, 2026-06) | G7: same | H7: https://www.sec.gov/Archives/edgar/data/1341439/000119312526265848/orcl-ex99_1.htm
A8: I01 | B8: OCI revenue = 'Cloud infrastructure' revenue (IaaS) | C8: Q3'25 | D8: 3347 | E8: Reported | F8: FQ1 FY27 earnings PR (8-K Ex.99.1, 2026-09-10) | G8: FQ1 FY27 PR table (FY26 quarters) | H8: https://www.sec.gov/Archives/edgar/data/1341439/000119312526387905/orcl-ex99_1.htm
A9: I01 | B9: OCI revenue = 'Cloud infrastructure' revenue (IaaS) | C9: Q4'25 | D9: 4079 | E9: Reported | F9: FQ1 FY27 earnings PR (8-K Ex.99.1, 2026-09-10) | G9: same | H9: https://www.sec.gov/Archives/edgar/data/1341439/000119312526387905/orcl-ex99_1.htm
A10: I01 | B10: OCI revenue = 'Cloud infrastructure' revenue (IaaS) | C10: Q1'26 | D10: 4888 | E10: Reported | F10: FQ1 FY27 earnings PR (8-K Ex.99.1, 2026-09-10) | G10: same | H10: https://www.sec.gov/Archives/edgar/data/1341439/000119312526387905/orcl-ex99_1.htm
A11: I01 | B11: OCI revenue = 'Cloud infrastructure' revenue (IaaS) | C11: Q2'26 | D11: 5787 | E11: Reported | F11: FQ1 FY27 earnings PR (8-K Ex.99.1, 2026-09-10) | G11: same | H11: https://www.sec.gov/Archives/edgar/data/1341439/000119312526387905/orcl-ex99_1.htm
A12: I01 | B12: OCI revenue = 'Cloud infrastructure' revenue (IaaS) | C12: Q3'26† | D12: 7388 | E12: Reported | F12: FQ1 FY27 earnings PR (8-K Ex.99.1, 2026-09-10) | G12: FQ1 FY27 PR 'Cloud infrastructure 7,388' | H12: https://www.sec.gov/Archives/edgar/data/1341439/000119312526387905/orcl-ex99_1.htm
A13: I03 | B13: Depreciation (company-wide, cash-flow statement; excl. intangible amortization) | C13: Q1'24 | D13: 808 | E13: Derived | F13: FQ3 FY24 earnings PR (8-K Ex.99.1, 2024-03-11) | G13: calc: 9M FY24 2,318 - 6M 1,510 (XBRL Depreciation YTD) | H13: https://www.sec.gov/Archives/edgar/data/1341439/000095017024029250/orcl-ex99_1.htm
... A113: I23 | B113: Total borrowings, carrying value (notes payable & other borrowings, current + non-current) | C113: Q3'26† | D113: 125337 | E113: Reported | F113: FQ1 FY27 earnings PR (8-K Ex.99.1, 2026-09-10) | G113: 7,625 + 117,712 | H113: https://www.sec.gov/Archives/edgar/data/1341439/000119312526387905/orcl-ex99_1.htm
A114: I26 | B114: Days in quarter | C114: Q1'24 | D114: 91 | E114: Reported | F114: calendar | G114: calendar
A115: I26 | B115: Days in quarter | C115: Q2'24 | D115: 92 | E115: Reported | F115: calendar | G115: calendar
A116: I26 | B116: Days in quarter | C116: Q3'24 | D116: 92 | E116: Reported | F116: calendar | G116: calendar
A117: I26 | B117: Days in quarter | C117: Q4'24 | D117: 91 | E117: Reported | F117: calendar | G117: calendar
A118: I26 | B118: Days in quarter | C118: Q1'25 | D118: 90 | E118: Reported | F118: calendar | G118: calendar
A119: I26 | B119: Days in quarter | C119: Q2'25 | D119: 92 | E119: Reported | F119: calendar | G119: calendar
A120: I26 | B120: Days in quarter | C120: Q3'25 | D120: 92 | E120: Reported | F120: calendar | G120: calendar
A121: I26 | B121: Days in quarter | C121: Q4'25 | D121: 91 | E121: Reported | F121: calendar | G121: calendar
A122: I26 | B122: Days in quarter | C122: Q1'26 | D122: 90 | E122: Reported | F122: calendar | G122: calendar
A123: I26 | B123: Days in quarter | C123: Q2'26 | D123: 92 | E123: Reported | F123: calendar | G123: calendar
A124: I26 | B124: Days in quarter | C124: Q3'26† | D124: 92 | E124: Reported | F124: calendar | G124: calendar
A125: I28 | B125: Useful life - servers & networking equipment | C125: Q1'24 | D125: 5 | E125: Reported | F125: 10-K FY24 (FYE 31-May-2024) | G125: 10-K FY24: servers 4 -> 5 yrs effective FY23 | H125: https://www.sec.gov/Archives/edgar/data/1341439/000095017024075605/orcl-20240531.htm
A126: I28 | B126: Useful life - servers & networking equipment | C126: Q2'24 | D126: 5 | E126: Reported | F126: 10-K FY24 (FYE 31-May-2024) | G126: same | H126: https://www.sec.gov/Archives/edgar/data/1341439/000095017024075605/orcl-20240531.htm
A127: I28 | B127: Useful life - servers & networking equipment | C127: Q3'24 | D127: 6 | E127: Reported | F127: 10-Q FQ1 FY25 (Aug-24) | G127: FQ1 FY25 10-Q: servers & networking 5 -> 6 yrs effective FY25 (+$733M FY25 opex benefit, 10-K FY25) | H127: https://www.sec.gov/Archives/edgar/data/1341439/000095017024104905/orcl-20240831.htm
A128: I28 | B128: Useful life - servers & networking equipment | C128: Q4'24 | D128: 6 | E128: Reported | F128: 10-Q FQ2 FY25 (Nov-24) | G128: same | H128: https://www.sec.gov/Archives/edgar/data/1341439/000095017024134973/orcl-20241130.htm
A129: I28 | B129: Useful life - servers & networking equipment | C129: Q1'25 | D129: 6 | E129: Reported | F129: 10-Q FQ3 FY25 (Feb-25) | G129: same | H129: https://www.sec.gov/Archives/edgar/data/1341439/000095017025037143/orcl-20250228.htm
A130: I28 | B130: Useful life - servers & networking equipment | C130: Q2'25 | D130: 6 | E130: Reported | F130: 10-K FY25 (FYE 31-May-2025) | G130: same | H130: https://www.sec.gov/Archives/edgar/data/1341439/000095017025087926/orcl-20250531.htm
A131: I28 | B131: Useful life - servers & networking equipment | C131: Q3'25 | D131: 6 | E131: Reported | F131: 10-K FY25 (FYE 31-May-2025) | G131: same | H131: https://www.sec.gov/Archives/edgar/data/1341439/000095017025087926/orcl-20250531.htm
A132: I28 | B132: Useful life - servers & networking equipment | C132: Q4'25 | D132: 6 | E132: Reported | F132: 10-K FY25 (FYE 31-May-2025) | G132: same | H132: https://www.sec.gov/Archives/edgar/data/1341439/000095017025087926/orcl-20250531.htm
A133: I28 | B133: Useful life - servers & networking equipment | C133: Q1'26 | D133: 6 | E133: Reported | F133: 10-K FY25 (FYE 31-May-2025) | G133: same | H133: https://www.sec.gov/Archives/edgar/data/1341439/000095017025087926/orcl-20250531.htm
A134: I28 | B134: Useful life - servers & networking equipment | C134: Q2'26 | D134: 6 | E134: Reported | F134: 10-K FY26 (FYE 31-May-2026) | G134: same | H134: https://www.sec.gov/Archives/edgar/data/1341439/000119312526277521/orcl-20260531.htm
A135: I28 | B135: Useful life - servers & networking equipment | C135: Q3'26† | D135: 6 | E135: Reported | F135: 10-K FY26 (FYE 31-May-2026) | G135: same | H135: https://www.sec.gov/Archives/edgar/data/1341439/000119312526277521/orcl-20260531.htm
A136: I29 | B136: Company-reported GPU utilization | C136: Q2'26 | D136: 97.5 | E136: Reported | F136: Oracle FQ4 FY26 earnings call - CEO blog 'From the Q4 earnings call' | G136: FQ4 FY26 call: 97.5% | H136: https://blogs.oracle.com/ceo/from-the-q4-earnings-call
... A175: P05 | B175: Share of company capex attributed to OCI / AI infrastructure | C175: param | D175: 100 | E175: Estimated | F175: Analyst assumption (this workbook) - segment allocation | G175: UPPER-BOUND ASSUMPTION: all capex attributed to OCI (Oracle does not split capex; management describes the build as overwhelmingly revenue-generating cloud infrastructure equipment). Lower share scales K10/K13/M06 proportionally. | H175: n/a
A176: DEBT | B176: $2,000, 3.40%, due July 2024 (principal / eff. rate) | C176: May-24 | D176: 2000.0 / 3.43% | E176: Reported | F176: 10-K FY24 (FYE 31-May-2024) | G176: Notes to consolidated financial statements - Notes payable and other borrowings table (amount; effective interest rate) | H176: https://www.sec.gov/Archives/edgar/data/1341439/000095017024075605/orcl-20240531.htm
A177: DEBT | B177: $2,000, 2.95%, due November 2024 (principal / eff. rate) | C177: May-24 | D177: 2000.0 / 3.01% | E177: Reported | F177: 10-K FY24 (FYE 31-May-2024) | G177: Notes to consolidated financial statements - Notes payable and other borrowings table (amount; effective interest rate) | H177: https://www.sec.gov/Archives/edgar/data/1341439/000095017024075605/orcl-20240531.htm
...

Sheet Definitions
A1: Def | B1: KPI group | C1: Definition used (formula, units) | D1: Mirrored from (Nebius workspace) | E1: Oracle OCI (ORCL) - Cloud Infrastructure perimeter application / basis notes
A2: D1 | B2: Revenue per MW | C2: Quarterly revenue x 4 / MW, $M per MW-year. Denominators: (a) active MW at period end; (b) average of opening/closing active MW; (c) contracted MW. EBITDA/MW same construction. K43 = YoY incremental revenue x4 / MW added in the same 4 quarters. K45 = segment cash gross margin. | D2: /workspace/nebius/model/nebius_model.xlsx KPIs rows 'Revenue per BILLING / contracted / energized MW' (=AIRev*4/MW); /workspace/nebius/parts/comps_rev_per_mw.csv; capacity/gpu_mw_capex.md s.4 MW basis. | E2: No installed MW -> revenue/MW n/d. K43 = YoY incremental OCI revenue x4 / AI MW delivered over the trailing 4 quarters (ESTIMATED allocation).
A3: D2 | B3: Revenue per GPU | C3: Quarterly revenue x 4000 / average GPUs ($K per GPU-year); implied $/GPU-hr = revenue / (avg GPUs x days x 24). | D3: nebius_model.xlsx KPIs 'Revenue per GPU ($K per GPU-yr)' and 'Implied blended $/GPU-hr'. | E3: No GPU fleet count. Only '>300k GPUs' in the 850MW delivered in FQ1 FY27.
A4: D3 | B4: Implied utilization | C4: Implied blended $/GPU-hr / fleet-weighted on-demand list price. K41 = company-reported physical GPU utilization (new row). | D4: nebius_model.xlsx KPIs 'Fleet-weighted on-demand list price' / 'Implied utilization (blended $/hr / weighted list)'; prices /workspace/nebius/parts/price_history_quarterly.csv & price_history_raw.csv. | E4: OCI list prices observed Aug-Oct 2026 only. Reported physical GPU utilization 97.5-97.9% (K41).
A5: D4 | B5: Capex per MW | C5: Cash purchases of PP&E / new active MW in the quarter ($M per MW); in-service additions per new MW; trailing-4Q; stock checks net PP&E / MW and in-service gross PP&E / MW. K44 = annualized revenue / average gross compute hardware. | D5: nebius_model.xlsx KPIs 'Capex per new active MW'; Hist 'Capex (purchases of PP&E + intangibles, cash)'; capacity/gpu_mw_capex.xlsx 'Nebius checks' and 'Peers'. | E5: Company capex attributed 100% to OCI (assumption P05) / MW delivered in quarter (calls). Large DC shells are partner-built and leased (I51 $288B not-yet-commenced), so capex is mostly IT equipment.
A6: D5 | B6: D&A useful lives | C6: Disclosed useful-life table and any change in estimate; depreciation yield = D&A x 4 / average in-service gross PP&E; implied life = 1/yield. | D6: /workspace/nebius/filings/nebius_filings.xlsx D&A_Policy; nebius_model.xlsx Capex_DA 'Depreciation yield - REPORTED basis'. | E6: Servers & networking 6 yrs since FY25 (5 before, 4 before FY23).
A7: D6 | B7: Backlog / RPO | C7: RPO = ASC 606 remaining performance obligations ($B, EoP); % within 24 months (K22) and 12 months (K42); backlog incl. non-RPO contracted value shown separately; RPO / (quarterly revenue x 4). | D7: nebius_model.xlsx Hist 'Remaining performance obligations'; nebius_filings.xlsx Quarterly 'RPO'. | E7: Company-wide RPO; 12m and 13-36m buckets reported -> 24m share Estimated.
A8: D7 | B8: Customer concentration | C8: Each customer >=10% of quarter revenue, top-N combined, count of >=10% customers. | D8: nebius_filings.xlsx Quarterly 'Customer concentration (>10% of revenue, quarter)'. | E8: No >=10% customer at fiscal-year level.
A9: D8 | B9: Funding cost | C9: Weighted effective cost of debt = sum(principal x effective rate) / sum(principal with a disclosed rate), EoP, excl. leases; split by facility type; cross-checks: interest x4 / avg principal; company-reported rate. | D9: /workspace/nebius/parts/comps_sources.csv 'Wtd effective cost of debt (%)'; shared/findings_log.xlsx cost-of-debt row (Nebius 5.1%). | E9: Investment-grade unsecured notes; annual note-level table. Quarterly cost via interest expense / average carrying debt.

Sheet Fiscal_Map
A1: Template column | B1: Calendar quarter-end used | C1: Company fiscal quarter | D1: Fiscal period end | E1: Offset vs calendar | F1: Notes
A2: Q4'23* | B2: 2023-11-30 | C2: FQ2 FY24 | D2: 2023-11-30 | E2: -1 month (fiscal quarter ends one month before Dec-23) | F2: opening-balance column
A3: Q1'24 | B3: 2024-02-29 | C3: FQ3 FY24 | D3: 2024-02-29 | E3: -1 month (fiscal quarter ends one month before Mar-24)
A4: Q2'24 | B4: 2024-05-31 | C4: FQ4 FY24 | D4: 2024-05-31 | E4: -1 month (fiscal quarter ends one month before Jun-24)
A5: Q3'24 | B5: 2024-08-31 | C5: FQ1 FY25 | D5: 2024-08-31 | E5: -1 month (fiscal quarter ends one month before Sep-24)
A6: Q4'24 | B6: 2024-11-30 | C6: FQ2 FY25 | D6: 2024-11-30 | E6: -1 month (fiscal quarter ends one month before Dec-24)
A7: Q1'25 | B7: 2025-02-28 | C7: FQ3 FY25 | D7: 2025-02-28 | E7: -1 month (fiscal quarter ends one month before Mar-25)
A8: Q2'25 | B8: 2025-05-31 | C8: FQ4 FY25 | D8: 2025-05-31 | E8: -1 month (fiscal quarter ends one month before Jun-25)
A9: Q3'25 | B9: 2025-08-31 | C9: FQ1 FY26 | D9: 2025-08-31 | E9: -1 month (fiscal quarter ends one month before Sep-25)
A10: Q4'25 | B10: 2025-11-30 | C10: FQ2 FY26 | D10: 2025-11-30 | E10: -1 month (fiscal quarter ends one month before Dec-25)
A11: Q1'26 | B11: 2026-02-28 | C11: FQ3 FY26 | D11: 2026-02-28 | E11: -1 month (fiscal quarter ends one month before Mar-26)
A12: Q2'26 | B12: 2026-05-31 | C12: FQ4 FY26 | D12: 2026-05-31 | E12: -1 month (fiscal quarter ends one month before Jun-26)
A13: Q3'26† | B13: 2026-08-31 | C13: FQ1 FY27 | D13: 2026-08-31 | E13: -1 month (fiscal quarter ends one month before Sep-26) | F13: EXTRA column: latest filed quarter (FQ1 FY27)

Sheet Notes_Gaps
A1: # | B1: Type | C1: Note / gap | D1: Impact | E1: Possible fix
A2: 1 | B2: Gap | C2: OCI is not a segment: no OCI capex, D&A, PP&E, EBITDA, cost of revenue, or customer data. All OCI-perimeter capex/MW figures are allocation ESTIMATES. | D2: K05, K10, K13, K43, M06 Estimated; K44/K45 n/d. | E2: Oracle analyst-day disclosures; NVIDIA/AMD allocation data.
A3: 2 | B3: Gap | C3: No installed MW or GPU fleet count - only MW delivered per quarter (calls, partly lower bounds/approximations) and '>300k GPUs' for FQ1 FY27. | D3: Revenue/MW, revenue/GPU, implied utilization n/d. K43 relies on call datapoints. | E3: Site-level (Abilene 1.2GW, Stargate sites) press + partner filings (Crusoe, Blue Owl, Vantage).
A4: 3 | B4: Gap | C4: Debt tables only annual (10-K); quarterly via carrying balances. | D4: K28-K35 annual snapshots.
A5: 4 | B5: Gap | C5: RPO is company-wide; no OCI split, no customer concentration. OpenAI ~$300B is media-reported only. | D5: Backlog concentration n/d.
A6: 5 | B6: Gap | C6: List prices only Aug-Oct 2026. | D6: K08/K09 n/d historically. | E6: Wayback snapshots of oracle.com/cloud/price-list.
A7: 6 | B7: Caveat | C7: Calendar mapping: Oracle quarters end 1 month before calendar quarters (Q2'26 column = Mar-May 2026). | D7: Comparisons vs CRWV/IREN/Nebius Q2'26 are 1 month earlier.
A8: 7 | B8: Caveat | C8: FQ3/FQ4 FY24 OCI revenue derived from FY25 growth rates (rounding +/-0.5%).
A9: 8 | B9: Note | C9: Contract announcements (sourced): FQ3 FY25 PR - multi-billion contracts with OpenAI, xAI, Meta, NVIDIA, AMD; Stargate first contract expected (Mar-25); FQ1 FY26 PR - four multi-billion contracts with three customers, RPO +$317B; FQ2 FY26 - Meta and others (RPO +$68B); Abilene 618MW (75%) delivered by Aug-26 incl. 131k GPUs in FQ1 FY27.
A10: 9 | B10: Note | C10: Off-balance-sheet: $288B not-yet-commenced DC lease commitments (Aug-26) + $19B unconditional purchase commitments for cloud infrastructure assets entered after May-26 (10-K FY26). | D10: Economic leverage far above $125B borrowings.
A11: 10 | B11: Note | C11: FQ1 FY27: capex $28.5B in one quarter; ~$19.9B ATM equity raised; OCI $7.4B (+121%); FY27 revenue guide >= $90B (call).

Sheet Comparison
A1: Per-peer stub. The multi-peer Comparison tab (Nebius, CoreWeave, IREN, Oracle OCI) lives in /workspace/nebius/peers/comparison.xlsx (built by peers/build_comparison.py from each peer workbook's KPIs tab).
A3: ID | B3: KPI | C3: Unit | D3: Oracle OCI (ORCL) - Cloud Infrastructure perimeter Q1'26 | E3: Oracle OCI (ORCL) - Cloud Infrastructure perimeter Q2'26 | F3: Oracle OCI (ORCL) - Cloud Infrastructure perimeter Q3'26†
A4: K01 | B4: =KPIs!B5 -> Revenue per active MW - period-end MW | C4: =KPIs!C5 -> $M/MW-yr | D4: =KPIs!N5 -> n/d | E4: =KPIs!O5 -> n/d | F4: =KPIs!P5 -> n/d
A5: K02 | B5: =KPIs!B7 -> Revenue per active MW - average MW | C5: =KPIs!C7 -> $M/MW-yr | D5: =KPIs!N7 -> n/d | E5: =KPIs!O7 -> n/d | F5: =KPIs!P7 -> n/d
A6: K03 | B6: =KPIs!B9 -> Revenue per contracted MW | C6: =KPIs!C9 -> $M/MW-yr | D6: =KPIs!N9 -> n/d | E6: =KPIs!O9 -> n/d | F6: =KPIs!P9 -> n/d
A7: K05 | B7: =KPIs!B13 -> Adj. EBITDA per active MW (average MW) | C7: =KPIs!C13 -> $M/MW-yr | D7: =KPIs!N13 -> n/d | E7: =KPIs!O13 -> n/d | F7: =KPIs!P13 -> n/d
A8: K06 | B8: =KPIs!B16 -> Revenue per GPU ($K per GPU-year, avg GPUs) | C8: =KPIs!C16 -> $K/GPU-yr | D8: =KPIs!N16 -> n/d | E8: =KPIs!O16 -> n/d | F8: =KPIs!P16 -> n/d
A9: K07 | B9: =KPIs!B18 -> Implied blended realized price ($/GPU-hr) | C9: =KPIs!C18 -> $/GPU-hr | D9: =KPIs!N18 -> n/d | E9: =KPIs!O18 -> n/d | F9: =KPIs!P18 -> n/d
A10: K09 | B10: =KPIs!B22 -> Implied utilization (realized $/GPU-hr / weighted list) | C10: =KPIs!C22 -> % | D10: =KPIs!N22 -> n/d | E10: =KPIs!O22 -> n/d | F10: =KPIs!P22 -> n/d
A11: K10 | B11: =KPIs!B25 -> Cash capex per new active MW | C11: =KPIs!C25 -> $M/MW | D11: =KPIs!N25 -> 46.5875 | E11: =KPIs!O25 -> 56.872414 | F11: =KPIs!P25 -> 33.528235
A12: K12 | B12: =KPIs!B29 -> In-service additions per new active MW | C12: =KPIs!C29 -> $M/MW | D12: =KPIs!N29 -> n/d | E12: =KPIs!O29 -> n/d | F12: =KPIs!P29 -> n/d
A13: K13 | B13: =KPIs!B31 -> Trailing-4Q cash capex per trailing-4Q new active MW | C13: =KPIs!C31 -> $M/MW | D13: =KPIs!N31 -> n/d | E13: =KPIs!O31 -> 46.385833 | F13: =KPIs!P31 -> 39
A14: K14 | B14: =KPIs!B33 -> Net PP&E per active MW (EoP) | C14: =KPIs!C33 -> $M/MW | D14: =KPIs!N33 -> n/d | E14: =KPIs!O33 -> n/d | F14: =KPIs!P33 -> n/d
A15: K15 | B15: =KPIs!B35 -> Gross in-service PP&E per active MW (EoP) | C15: =KPIs!C35 -> $M/MW | D15: =KPIs!N35 -> n/d | E15: =KPIs!O35 -> n/d | F15: =KPIs!P35 -> n/d
A16: K16 | B16: =KPIs!B38 -> Useful life - GPU / server equipment | C16: =KPIs!C38 -> years | D16: =KPIs!N38 -> 6 | E16: =KPIs!O38 -> 6 | F16: =KPIs!P38 -> 6
A17: K17 | B17: =KPIs!B40 -> Depreciation yield (D&A x4 / avg in-service gross PP&E) | C17: =KPIs!C40 -> % | D17: =KPIs!N40 -> n/d | E17: =KPIs!O40 -> n/d | F17: =KPIs!P40 -> 13.449246
A18: K20 | B18: =KPIs!B47 -> RPO (ASC 606, EoP) | C18: =KPIs!C47 -> $B | D18: =KPIs!N47 -> 552.6 | E18: =KPIs!O47 -> 638 | F18: =KPIs!P47 -> 664
A19: K21 | B19: =KPIs!B49 -> Revenue backlog (company metric / incl. contracted non-RPO, EoP) | C19: =KPIs!C49 -> $B | D19: =KPIs!N49 -> n/d | E19: =KPIs!O49 -> n/d | F19: =KPIs!P49 -> n/d
A20: K22 | B20: =KPIs!B51 -> RPO % recognized within 24 months | C20: =KPIs!C51 -> % | D20: =KPIs!N51 -> 27.5 | E20: =KPIs!O51 -> 29 | F20: =KPIs!P51 -> 31.5
A21: K24 | B21: =KPIs!B56 -> Largest customer % of revenue | C21: =KPIs!C56 -> % | D21: =KPIs!N56 -> n/d | E21: =KPIs!O56 -> n/d | F21: =KPIs!P56 -> n/d
A22: K26 | B22: =KPIs!B60 -> Top-N >=10% customers combined % | C22: =KPIs!C60 -> % | D22: =KPIs!N60 -> n/d | E22: =KPIs!O60 -> n/d | F22: =KPIs!P60 -> n/d
A23: K27 | B23: =KPIs!B62 -> Number of customers >=10% of revenue | C23: =KPIs!C62 -> # | D23: =KPIs!N62 -> n/d | E23: =KPIs!O62 -> 0 | F23: =KPIs!P62 -> n/d
A24: K28 | B24: =KPIs!B65 -> Weighted effective cost of debt (principal-weighted, EoP) - all facilities | C24: =KPIs!C65 -> % | D24: =KPIs!N65 -> n/d | E24: =KPIs!O65 -> 4.8282005 | F24: =KPIs!P65 -> n/d
A25: K30 | B25: =KPIs!B69 -> of which Senior notes - weighted eff. rate | C25: =KPIs!C69 -> % | D25: =KPIs!N69 -> n/d | E25: =KPIs!O69 -> 4.8146761 | F25: =KPIs!P69 -> n/d
A26: K31 | B26: =KPIs!B71 -> of which Converts - weighted eff. rate | C26: =KPIs!C71 -> % | D26: =KPIs!N71 -> n/d | E26: =KPIs!O71 -> n/d | F26: =KPIs!P71 -> n/d
A27: K36 | B27: =KPIs!B81 -> Implied cash cost: interest x4 / avg principal | C27: =KPIs!C81 -> % | D27: =KPIs!N81 -> 3.8898962 | E27: =KPIs!O81 -> 4.3551672 | F27: =KPIs!P81 -> 4.4821444
A28: K41 | B28: =KPIs!B92 -> Company-reported GPU utilization (physical) | C28: =KPIs!C92 -> % | D28: =KPIs!N92 -> n/d | E28: =KPIs!O92 -> 97.5 | F28: =KPIs!P92 -> 97.9
A29: K42 | B29: =KPIs!B94 -> RPO % recognized within 12 months | C29: =KPIs!C94 -> % | D29: =KPIs!N94 -> 12 | E29: =KPIs!O94 -> 12 | F29: =KPIs!P94 -> 13
A30: K43 | B30: =KPIs!B96 -> Incremental annualized revenue per incremental MW (YoY) | C30: =KPIs!C96 -> $M/MW-yr | D30: =KPIs!N96 -> n/d | E30: =KPIs!O96 -> 9.3066667 | F30: =KPIs!P96 -> 8.3319588
A31: K44 | B31: =KPIs!B98 -> Annualized revenue / avg gross GPU-compute hardware in service | C31: =KPIs!C98 -> x | D31: =KPIs!N98 -> n/d | E31: =KPIs!O98 -> n/d | F31: =KPIs!P98 -> n/d
A32: K45 | B32: =KPIs!B100 -> Segment gross margin (revenue - cost of revenue excl. D&A) / revenue | C32: =KPIs!C100 -> % | D32: =KPIs!N100 -> n/d | E32: =KPIs!O100 -> n/d | F32: =KPIs!P100 -> n/d
