Workbook

Sheet README
A1: Nebius Capacity & Power — FINAL billed IT MW vs connected MW (YE26 / FY27) — locked for Sunday
A2: Built: Thu Oct 8 2026 ~9:45 AM ET (re-cut v4: FY27 engine-linked v0.9e). Public sources only; nobody contacted. Tags: R Reported / D Derived / E Estimated.
A3: FOR JUDGES: Connected is not billing. We estimate ~941 MW connected at YE26 (E; mgmt guide 800 MW–1 GW, R) but only ~258 MW of IT billing (D), about 27%. Revenue runs on billed MW.
A5: Company totals tie to locked anchors (see Final_Table checks): YE26 billed 257.7 base / 284.2 high; FY27 avg billed 531.8 base / 659.2 high (v0.9e engine-linked; Vineland 182.3 MW-yr; supersede 536.5 / 663.8, 475.0 / 645.4); YE26 energized IT 301.7; YE26 connected 941 base / 561 low.
A6: NON-TIE flagged: site YE26 connected HIGH sums to 1,156 vs company 1,195 (39 MW residual = France 2nd n/d + range; not invented).
A8: Method (site billed, D): replicates the two locked methods exactly.
A9: YE26 billed (base/high) = capacity v2 row 147 method: other sites' IT-normalized energized at Q3'26 (1-quarter lag) + Vineland at billed tranches (4 delivered x 26.7 IT, E).
A10: FY27 avg billed: Vineland (base and high) = engine-linked 182.3 MW-yr (v0.9e Contracts MS_Rev FY27 $2,643.8M ÷ ~$14.5M; Judge_Slide A19). Other sites = model v0.9d method (Revenue!F12 'Active IT MW (average)', Judge_Slide B25): IT-normalized energized lagged 1Q, quarter-average of start/end, averaged over Q1-Q4'27 = (E_Q3'26 + 2E_Q4'26 + 2E_Q1'27 + 2E_Q2'27 + E_Q3'27)/8 per site.
A11: IT-normalized = energized / Gross-IT factor where the site figure is treated as gross; else as stated (nebius_capacity.xlsx Basis).
A12: Connected is on gross/shell (facility power) basis; billed is on IT basis. On a like-for-like IT basis, 941 connected ≈ 697–784 IT MW (÷1.20–1.35, D) — still ~2.7–3.0x billing.
A14: Q3 results: late Oct–mid Nov (Oct 22 or Nov 10 per third-party calendars; not company-announced) [E]. Short form: late Oct–mid Nov (est.). It may land before the ~Nov 6–9 NJDEP genset filing deadline.
A15: Inputs in blue (static copies of Derived/Estimated values from capacity v2, ye26_active_vs_connected.xlsx, model v0.9d); formulas in black.
A16: Tabs: Final_Table, Quarterly_IT, Definitions, Change_vs_Oct5, Sources.

Sheet Final_Table
A1: FINAL: YE26 / FY27 billed IT MW vs connected MW by site (locked for Sunday)
A2: Thu Oct 8 2026 ~9:45 AM ET (re-cut v4: FY27 engine-linked v0.9e). Billed = revenue-generating IT MW (D). Connected = built & equipped halls with power, gross/shell basis (E). Q3 results: late Oct–mid Nov (est.).
A3: FOR JUDGES: Connected is not billing. ~941 MW connected at YE26 (E; guide 800 MW–1 GW, R) vs ~258 MW billing (D), about 27%. Revenue runs on billed MW.
A5: Site | B5: Owned/leased | C5: Customer | D5: YE26 connected LOW (E) | E5: YE26 connected BASE (E) | F5: YE26 connected HIGH (E) | G5: YE26 energized IT base (ref, D) | H5: YE26 billed IT BASE (D) | I5: YE26 billed IT HIGH (D) | J5: FY27 avg billed IT BASE (D; Vineland engine-linked 182.3) | K5: FY27 avg billed IT HIGH (D; Vineland engine-linked 182.3) | L5: YE27 connected (E; fixed sites only) | M5: YE26 gap: connected base − billed base | N5: Confidence | O5: One-line reason | P5: R/D/E tag | Q5: Source
A6: Vineland NJ (DataOne) | B6: leased (build-to-suit) | C6: Microsoft | D6: 300 | E6: 300 | F6: 300 | G6: =Quarterly_IT!E2 -> 81.8 | H6: =Quarterly_IT!$B$30 -> 106.66667 | I6: =Quarterly_IT!$B$30 -> 106.66667 | J6: =Quarterly_IT!$B$44 -> 182.32922 | K6: =Quarterly_IT!$B$44 -> 182.32922 | L6: 300 | M6: =IF(ISNUMBER(E6),E6-IF(ISNUMBER(H6),H6,0),"n/d") -> 193.33333 | N6: Med (YE26) / Low-Med (FY27) | O6: 4 of 9 tranches delivered (R); MW/tranche E (26.7 IT). YE26 billed-tranche 106.7; FY27 engine-linked 182.3 MW-yr (v0.9e); FY27 hinges on Bloom T5–T9 (Case B -$966M @~35%); smaller early tranches cut revenue and MW together | P6: Connected E (site split); billed D on E site inputs; Vineland tranches delivered R, MW/tranche E | Q6: 20-F; Q2'26 letter/call; nebius_capacity.xlsx Vineland tranche track; vineland_watch.md
A7: Independence MO (Eastgate) | B7: owned | C7: unassigned (Meta #2 candidate, assumed) | D7: 0 | E7: 100 | F7: 200 | G7: =Quarterly_IT!E3 -> 0 | H7: =Quarterly_IT!D3 -> 0 | I7: =Quarterly_IT!J3 -> 0 | J7: =(Quarterly_IT!D3+2*Quarterly_IT!E3+2*Quarterly_IT!F3+2*Quarterly_IT!G3+Quarterly_IT!H3)/8 -> 4.629625 | K7: =(Quarterly_IT!J3+2*Quarterly_IT!K3+2*Quarterly_IT!L3+2*Quarterly_IT!M3+Quarterly_IT!N3)/8 -> 9.2592625 | L7: n/d | M7: =IF(ISNUMBER(E7),E7-IF(ISNUMBER(H7),H7,0),"n/d") -> 100 | N7: High (billed) / Low (connected) | O7: No IT before ~Q3'27, so YE26 billed 0 is solid; YE26 connected 100 = utility feed/shell plug only | P7: Connected E (site split); billed D on E site inputs | Q7: owned_campus_power_path.md; Independence city FAQs/deck
A8: Butler Twp PA (Highridge) | B8: owned | C8: unassigned | D8: 0 | E8: 0 | F8: 0 | G8: =Quarterly_IT!E4 -> 0 | H8: =Quarterly_IT!D4 -> 0 | I8: =Quarterly_IT!J4 -> 0 | J8: =(Quarterly_IT!D4+2*Quarterly_IT!E4+2*Quarterly_IT!F4+2*Quarterly_IT!G4+Quarterly_IT!H4)/8 -> 0 | K8: =(Quarterly_IT!J4+2*Quarterly_IT!K4+2*Quarterly_IT!L4+2*Quarterly_IT!M4+Quarterly_IT!N4)/8 -> 0 | L8: n/d | M8: =IF(ISNUMBER(E8),E8-IF(ISNUMBER(H8),H8,0),"n/d") -> 0 | N8: High | O8: PPL 230 kV switchyard/laterals late-2027 to 2029; nothing bills through FY27 | P8: Connected E (site split); billed D on E site inputs | Q8: owned_campus_power_path.md; PPL filings
A9: Birmingham AL (BHM01, Oxmoor) | B9: owned | C9: unassigned | D9: 0 | E9: 50 | F9: 100 | G9: =Quarterly_IT!E5 -> 0 | H9: =Quarterly_IT!D5 -> 0 | I9: =Quarterly_IT!J5 -> 0 | J9: =(Quarterly_IT!D5+2*Quarterly_IT!E5+2*Quarterly_IT!F5+2*Quarterly_IT!G5+Quarterly_IT!H5)/8 -> 11.574075 | K9: =(Quarterly_IT!J5+2*Quarterly_IT!K5+2*Quarterly_IT!L5+2*Quarterly_IT!M5+Quarterly_IT!N5)/8 -> 20.833325 | L9: n/d | M9: =IF(ISNUMBER(E9),E9-IF(ISNUMBER(H9),H9,0),"n/d") -> 50 | N9: Med | O9: 115 kV NLT Dec 31 2026, 230 kV Oct 2027 (R); first revenue MW 2027; litigation Mar 2027 | P9: Connected E (site split); billed D on E site inputs | Q9: owned_campus_power_path.md; Alabama Power filings
A10: Bethune FR (Azur Datacenter, ex-Bridgestone) | B10: leased | C10: Meta (likely, press) | D10: 30 | E10: 120 | F10: 120 | G10: =Quarterly_IT!E6 -> 23.0769 | H10: =Quarterly_IT!D6 -> 0 | I10: =Quarterly_IT!J6 -> 0 | J10: =(Quarterly_IT!D6+2*Quarterly_IT!E6+2*Quarterly_IT!F6+2*Quarterly_IT!G6+Quarterly_IT!H6)/8 -> 54.519238 | K10: =(Quarterly_IT!J6+2*Quarterly_IT!K6+2*Quarterly_IT!L6+2*Quarterly_IT!M6+Quarterly_IT!N6)/8 -> 86.538438 | L10: n/d | M10: =IF(ISNUMBER(E10),E10-IF(ISNUMBER(H10),H10,0),"n/d") -> 120 | N10: Low-Med | O10: Mgmt says 120 MW by YE26 (R) vs model energized 30; ICPE decision pending; 1Q lag puts YE26 billed at 0 | P10: Connected E (site split); billed D on E site inputs | Q10: nebius_capacity.xlsx; CCO remarks; unseen_capacity.md
A11: Lappeenranta FI (Pajarila / Polarnode) | B11: owned | C11: unassigned | D11: 0 | E11: 0 | F11: 0 | G11: =Quarterly_IT!E7 -> 0 | H11: =Quarterly_IT!D7 -> 0 | I11: =Quarterly_IT!J7 -> 0 | J11: =(Quarterly_IT!D7+2*Quarterly_IT!E7+2*Quarterly_IT!F7+2*Quarterly_IT!G7+Quarterly_IT!H7)/8 -> 7.6087 | K11: =(Quarterly_IT!J7+2*Quarterly_IT!K7+2*Quarterly_IT!L7+2*Quarterly_IT!M7+Quarterly_IT!N7)/8 -> 15.2174 | L11: n/d | M11: =IF(ISNUMBER(E11),E11-IF(ISNUMBER(H11),H11,0),"n/d") -> 0 | N11: Med | O11: First building H1'27; substation spring 2027 | P11: Connected E (site split); billed D on E site inputs | Q11: site_tracker_wed.xlsx; Fira/Polarnode
A12: Mantsala FI #1 | B12: owned | C12: self-serve (assumed) | D12: 75 | E12: 75 | F12: 75 | G12: =Quarterly_IT!E8 -> 68.1818 | H12: =Quarterly_IT!D8 -> 68.1818 | I12: =Quarterly_IT!J8 -> 68.1818 | J12: =(Quarterly_IT!D8+2*Quarterly_IT!E8+2*Quarterly_IT!F8+2*Quarterly_IT!G8+Quarterly_IT!H8)/8 -> 68.1818 | K12: =(Quarterly_IT!J8+2*Quarterly_IT!K8+2*Quarterly_IT!L8+2*Quarterly_IT!M8+Quarterly_IT!N8)/8 -> 68.1818 | L12: 75 | M12: =IF(ISNUMBER(E12),E12-IF(ISNUMBER(H12),H12,0),"n/d") -> 6.8182 | N12: High | O12: 75 MW built early 2026 (R); IT-normalized at PUE 1.1 (E) | P12: Connected E (site split); billed D on E site inputs | Q12: 20-F; nebius_capacity.xlsx
A13: Mantsala FI #2 (Kapuli) | B13: owned | C13: unassigned | D13: 0 | E13: 0 | F13: 0 | G13: =Quarterly_IT!E9 -> 0 | H13: =Quarterly_IT!D9 -> 0 | I13: =Quarterly_IT!J9 -> 0 | J13: =(Quarterly_IT!D9+2*Quarterly_IT!E9+2*Quarterly_IT!F9+2*Quarterly_IT!G9+Quarterly_IT!H9)/8 -> 0 | K13: =(Quarterly_IT!J9+2*Quarterly_IT!K9+2*Quarterly_IT!L9+2*Quarterly_IT!M9+Quarterly_IT!N9)/8 -> 0 | L13: n/d | M13: =IF(ISNUMBER(E13),E13-IF(ISNUMBER(H13),H13,0),"n/d") -> 0 | N13: Med | O13: Substation autumn 2027; nothing bills in FY27 on 1Q lag | P13: Connected E (site split); billed D on E site inputs | Q13: site_tracker_wed.xlsx
A14: Kansas City MO (Patmos) | B14: leased | C14: self-serve (assumed) | D14: 20 | E14: 40 | F14: 40 | G14: =Quarterly_IT!E10 -> 20 | H14: =Quarterly_IT!D10 -> 20 | I14: =Quarterly_IT!J10 -> 35 | J14: =(Quarterly_IT!D10+2*Quarterly_IT!E10+2*Quarterly_IT!F10+2*Quarterly_IT!G10+Quarterly_IT!H10)/8 -> 20 | K14: =(Quarterly_IT!J10+2*Quarterly_IT!K10+2*Quarterly_IT!L10+2*Quarterly_IT!M10+Quarterly_IT!N10)/8 -> 35 | L14: n/d | M14: =IF(ISNUMBER(E14),E14-IF(ISNUMBER(H14),H14,0),"n/d") -> 20 | N14: Med | O14: Operational; Nebius share of facility not disclosed (5-35 range) | P14: Connected E (site split); billed D on E site inputs | Q14: nebius_capacity.xlsx; Patmos
A15: Paris (Equinix PA10) | B15: leased | C15: self-serve (assumed) | D15: 5 | E15: 5 | F15: 5 | G15: =Quarterly_IT!E11 -> 5 | H15: =Quarterly_IT!D11 -> 5 | I15: =Quarterly_IT!J11 -> 5 | J15: =(Quarterly_IT!D11+2*Quarterly_IT!E11+2*Quarterly_IT!F11+2*Quarterly_IT!G11+Quarterly_IT!H11)/8 -> 5 | K15: =(Quarterly_IT!J11+2*Quarterly_IT!K11+2*Quarterly_IT!L11+2*Quarterly_IT!M11+Quarterly_IT!N11)/8 -> 5 | L15: 5 | M15: =IF(ISNUMBER(E15),E15-IF(ISNUMBER(H15),H15,0),"n/d") -> 0 | N15: Med | O15: Operational; 5 MW is third-party figure | P15: Connected E (site split); billed D on E site inputs | Q15: site_tracker_wed.xlsx
A16: Keflavik IS (Verne) | B16: leased | C16: self-serve (assumed) | D16: 10 | E16: 10 | F16: 10 | G16: =Quarterly_IT!E12 -> 10 | H16: =Quarterly_IT!D12 -> 10 | I16: =Quarterly_IT!J12 -> 10 | J16: =(Quarterly_IT!D12+2*Quarterly_IT!E12+2*Quarterly_IT!F12+2*Quarterly_IT!G12+Quarterly_IT!H12)/8 -> 10 | K16: =(Quarterly_IT!J12+2*Quarterly_IT!K12+2*Quarterly_IT!L12+2*Quarterly_IT!M12+Quarterly_IT!N12)/8 -> 10 | L16: 10 | M16: =IF(ISNUMBER(E16),E16-IF(ISNUMBER(H16),H16,0),"n/d") -> 0 | N16: High | O16: 10 MW live since Mar 2025 (R) | P16: Connected E (site split); billed D on E site inputs | Q16: site_tracker_wed.xlsx
A17: London Longcross (Ark LP01) | B17: leased | C17: self-serve (assumed) | D17: 16 | E17: 19 | F17: 19 | G17: =Quarterly_IT!E13 -> 13.4615 | H17: =Quarterly_IT!D13 -> 12.3077 | I17: =Quarterly_IT!J13 -> 12.3077 | J17: =(Quarterly_IT!D13+2*Quarterly_IT!E13+2*Quarterly_IT!F13+2*Quarterly_IT!G13+Quarterly_IT!H13)/8 -> 14.038462 | K17: =(Quarterly_IT!J13+2*Quarterly_IT!K13+2*Quarterly_IT!L13+2*Quarterly_IT!M13+Quarterly_IT!N13)/8 -> 14.326937 | L17: 19 | M17: =IF(ISNUMBER(E17),E17-IF(ISNUMBER(H17),H17,0),"n/d") -> 6.6923 | N17: High | O17: 16->19 MW contract (R); stated basis treated as gross (/1.3) | P17: Connected E (site split); billed D on E site inputs | Q17: nebius_capacity.xlsx Basis
A18: Harlow UK (Kao Data KLON-02/03) | B18: leased | C18: n/d | D18: 2.2 | E18: 22 | F18: 22 | G18: =Quarterly_IT!E14 -> 2.2 | H18: =Quarterly_IT!D14 -> 0 | I18: =Quarterly_IT!J14 -> 0 | J18: =(Quarterly_IT!D14+2*Quarterly_IT!E14+2*Quarterly_IT!F14+2*Quarterly_IT!G14+Quarterly_IT!H14)/8 -> 9.9 | K18: =(Quarterly_IT!J14+2*Quarterly_IT!K14+2*Quarterly_IT!L14+2*Quarterly_IT!M14+Quarterly_IT!N14)/8 -> 14.85 | L18: n/d | M18: =IF(ISNUMBER(E18),E18-IF(ISNUMBER(H18),H18,0),"n/d") -> 22 | N18: Med | O18: 22 MW contract (R); ramp timing E | P18: Connected E (site split); billed D on E site inputs | Q18: unseen_capacity.md; Kao Data
A19: Newport UK (Vantage CWL1) | B19: leased | C19: n/d | D19: 0 | E19: 10 | F19: 20 | G19: =Quarterly_IT!E15 -> 5 | H19: =Quarterly_IT!D15 -> 0 | I19: =Quarterly_IT!J15 -> 0 | J19: =(Quarterly_IT!D15+2*Quarterly_IT!E15+2*Quarterly_IT!F15+2*Quarterly_IT!G15+Quarterly_IT!H15)/8 -> 14.25 | K19: =(Quarterly_IT!J15+2*Quarterly_IT!K15+2*Quarterly_IT!L15+2*Quarterly_IT!M15+Quarterly_IT!N15)/8 -> 22.875 | L19: n/d | M19: =IF(ISNUMBER(E19),E19-IF(ISNUMBER(H19),H19,0),"n/d") -> 10 | N19: Low | O19: Nebius MW not disclosed; UK residual 43 MW (D) split E | P19: Connected E (site split); billed D on E site inputs | Q19: site_tracker_wed.md
A20: UK 3rd new deployment (lead: Green Mountain LON-East, Romford) | B20: leased (if confirmed) | C20: n/d | D20: 0 | E20: 5 | F20: 10 | G20: =Quarterly_IT!E16 -> 0 | H20: =Quarterly_IT!D16 -> 0 | I20: =Quarterly_IT!J16 -> 0 | J20: =(Quarterly_IT!D16+2*Quarterly_IT!E16+2*Quarterly_IT!F16+2*Quarterly_IT!G16+Quarterly_IT!H16)/8 -> 1.375 | K20: =(Quarterly_IT!J16+2*Quarterly_IT!K16+2*Quarterly_IT!L16+2*Quarterly_IT!M16+Quarterly_IT!N16)/8 -> 2.75 | L20: n/d | M20: =IF(ISNUMBER(E20),E20-IF(ISNUMBER(H20),H20,0),"n/d") -> 5 | N20: Low | O20: Site identity unconfirmed (GM 14 MW to unnamed neocloud) | P20: Connected E (site split); billed D on E site inputs | Q20: site_tracker_wed.md
A21: Modi'in IL (Mega Or) | B21: leased | C21: n/d | D21: 8 | E21: 8 | F21: 8 | G21: =Quarterly_IT!E17 -> 8 | H21: =Quarterly_IT!D17 -> 8 | I21: =Quarterly_IT!J17 -> 8 | J21: =(Quarterly_IT!D17+2*Quarterly_IT!E17+2*Quarterly_IT!F17+2*Quarterly_IT!G17+Quarterly_IT!H17)/8 -> 8 | K21: =(Quarterly_IT!J17+2*Quarterly_IT!K17+2*Quarterly_IT!L17+2*Quarterly_IT!M17+Quarterly_IT!N17)/8 -> 8 | L21: 8 | M21: =IF(ISNUMBER(E21),E21-IF(ISNUMBER(H21),H21,0),"n/d") -> 0 | N21: High | O21: 8 MW live Oct 2025 (R) | P21: Connected E (site split); billed D on E site inputs | Q21: site_tracker_wed.xlsx
A22: Masmiyya IL (Mega DC) | B22: leased | C22: n/d | D22: 5.5 | E22: 22 | F22: 22 | G22: =Quarterly_IT!E18 -> 5.5 | H22: =Quarterly_IT!D18 -> 0 | I22: =Quarterly_IT!J18 -> 0 | J22: =(Quarterly_IT!D18+2*Quarterly_IT!E18+2*Quarterly_IT!F18+2*Quarterly_IT!G18+Quarterly_IT!H18)/8 -> 11 | K22: =(Quarterly_IT!J18+2*Quarterly_IT!K18+2*Quarterly_IT!L18+2*Quarterly_IT!M18+Quarterly_IT!N18)/8 -> 16.5 | L22: n/d | M22: =IF(ISNUMBER(E22),E22-IF(ISNUMBER(H22),H22,0),"n/d") -> 22 | N22: Med | O22: 22 MW contracted (R); ramp E | P22: Connected E (site split); billed D on E site inputs | Q22: unseen_capacity.md
A23: Beit Shemesh IL (Mega DC) | B23: leased | C23: n/d | D23: 0 | E23: 0 | F23: 0 | G23: =Quarterly_IT!E19 -> 0 | H23: =Quarterly_IT!D19 -> 0 | I23: =Quarterly_IT!J19 -> 0 | J23: =(Quarterly_IT!D19+2*Quarterly_IT!E19+2*Quarterly_IT!F19+2*Quarterly_IT!G19+Quarterly_IT!H19)/8 -> 15.9375 | K23: =(Quarterly_IT!J19+2*Quarterly_IT!K19+2*Quarterly_IT!L19+2*Quarterly_IT!M19+Quarterly_IT!N19)/8 -> 22 | L23: n/d | M23: =IF(ISNUMBER(E23),E23-IF(ISNUMBER(H23),H23,0),"n/d") -> 0 | N23: Med | O23: 58 MW; landlord completion Q2'27 (R) | P23: Connected E (site split); billed D on E site inputs | Q23: site_tracker_wed.xlsx
A24: Madrid-Getafe ES (Merlin Edged) | B24: leased | C24: n/d | D24: 13.5 | E24: 18 | F24: 18 | G24: =Quarterly_IT!E20 -> 13.5 | H24: =Quarterly_IT!D20 -> 7.5 | I24: =Quarterly_IT!J20 -> 9 | J24: =(Quarterly_IT!D20+2*Quarterly_IT!E20+2*Quarterly_IT!F20+2*Quarterly_IT!G20+Quarterly_IT!H20)/8 -> 15.5625 | K24: =(Quarterly_IT!J20+2*Quarterly_IT!K20+2*Quarterly_IT!L20+2*Quarterly_IT!M20+Quarterly_IT!N20)/8 -> 16.875 | L24: n/d | M24: =IF(ISNUMBER(E24),E24-IF(ISNUMBER(H24),H24,0),"n/d") -> 10.5 | N24: Med | O24: 18 MW contract (R); ramp E | P24: Connected E (site split); billed D on E site inputs | Q24: unseen_capacity.md
A25: Tallinn EE (Greenergy Huuru) | B25: leased | C25: n/d | D25: 11 | E25: 22 | F25: 22 | G25: =Quarterly_IT!E21 -> 11 | H25: =Quarterly_IT!D21 -> 0 | I25: =Quarterly_IT!J21 -> 0 | J25: =(Quarterly_IT!D21+2*Quarterly_IT!E21+2*Quarterly_IT!F21+2*Quarterly_IT!G21+Quarterly_IT!H21)/8 -> 15.125 | K25: =(Quarterly_IT!J21+2*Quarterly_IT!K21+2*Quarterly_IT!L21+2*Quarterly_IT!M21+Quarterly_IT!N21)/8 -> 19.25 | L25: n/d | M25: =IF(ISNUMBER(E25),E25-IF(ISNUMBER(H25),H25,0),"n/d") -> 22 | N25: Med | O25: 22 MW first phase later 2026 (R) | P25: Connected E (site split); billed D on E site inputs | Q25: unseen_capacity.md
A26: Minnesota colo (us-north1, Woodbury) | B26: leased | C26: n/d | D26: 15 | E26: 15 | F26: 15 | G26: =Quarterly_IT!E22 -> 10 | H26: =Quarterly_IT!D22 -> 10 | I26: =Quarterly_IT!J22 -> 15 | J26: =(Quarterly_IT!D22+2*Quarterly_IT!E22+2*Quarterly_IT!F22+2*Quarterly_IT!G22+Quarterly_IT!H22)/8 -> 10 | K26: =(Quarterly_IT!J22+2*Quarterly_IT!K22+2*Quarterly_IT!L22+2*Quarterly_IT!M22+Quarterly_IT!N22)/8 -> 15 | L26: n/d | M26: =IF(ISNUMBER(E26),E26-IF(ISNUMBER(H26),H26,0),"n/d") -> 5 | N26: Low | O26: Tenant MW n/d; IronGate MSP01 inference | P26: Connected E (site split); billed D on E site inputs | Q26: site_tracker_wed.md
A27: Oklahoma colo (unnamed) | B27: leased | C27: n/d | D27: 50 | E27: 100 | F27: 150 | G27: =Quarterly_IT!E23 -> 25 | H27: =Quarterly_IT!D23 -> 10 | I27: =Quarterly_IT!J23 -> 15 | J27: =(Quarterly_IT!D23+2*Quarterly_IT!E23+2*Quarterly_IT!F23+2*Quarterly_IT!G23+Quarterly_IT!H23)/8 -> 51.25 | K27: =(Quarterly_IT!J23+2*Quarterly_IT!K23+2*Quarterly_IT!L23+2*Quarterly_IT!M23+Quarterly_IT!N23)/8 -> 71.25 | L27: n/d | M27: =IF(ISNUMBER(E27),E27-IF(ISNUMBER(H27),H27,0),"n/d") -> 90 | N27: Low | O27: Map '>100 MW' category only; town/landlord n/d | P27: Connected E (site split); billed D on E site inputs | Q27: site_tracker_wed.md
A28: France 2nd colo (unnamed; possibly eu-west2) | B28: leased | C28: n/d | D28: n/d | E28: n/d | F28: n/d | G28: n/d | H28: n/d | I28: n/d | J28: n/d | K28: n/d | L28: n/d | M28: =IF(ISNUMBER(E28),E28-IF(ISNUMBER(H28),H28,0),"n/d") -> n/d | N28: n/d | O28: Region live (R) but site/MW not disclosed; not invented | P28: Connected E (site split); billed D on E site inputs | Q28: site_tracker_wed.md
A29: AIB CLT1 (Moore, Spartanburg County SC; Lockhart Power) | B29: leased | C29: n/d | D29: 0 | E29: 0 | F29: 0 | G29: =Quarterly_IT!E25 -> 0 | H29: =Quarterly_IT!D25 -> 0 | I29: =Quarterly_IT!J25 -> 0 | J29: =(Quarterly_IT!D25+2*Quarterly_IT!E25+2*Quarterly_IT!F25+2*Quarterly_IT!G25+Quarterly_IT!H25)/8 -> 1.5625 | K29: =(Quarterly_IT!J25+2*Quarterly_IT!K25+2*Quarterly_IT!L25+2*Quarterly_IT!M25+Quarterly_IT!N25)/8 -> 3.125 | L29: n/d | M29: =IF(ISNUMBER(E29),E29-IF(ISNUMBER(H29),H29,0),"n/d") -> 0 | N29: Med | O29: 50 MW critical IT (R, AIB PR Sep 30 2026); halls ~2027 | P29: Connected E (site split); billed D on E site inputs | Q29: AIB PR Sep 30 2026
A30: COMPANY TOTAL (sites; France 2nd n/d excluded) | D30: =SUM(D6:D29) -> 561.2 | E30: =SUM(E6:E29) -> 941 | F30: =SUM(F6:F29) -> 1156 | G30: =SUM(G6:G29) -> 301.7202 | H30: =SUM(H6:H29) -> 257.65617 | I30: =SUM(I6:I29) -> 284.15617 | J30: =SUM(J6:J29) -> 531.84362 | K30: =SUM(K6:K29) -> 659.16138 | L30: n/d (company 1,882 base, see below) | M30: =SUM(M6:M29) -> 683.34383 | N30: see checks | P30: E / D
A32: LOCKED COMPANY ANCHORS and TIE CHECKS
A33: Anchor | B33: Locked value | C33: Tag | D33: Site-sum (formula) | E33: Diff | F33: Tie? | G33: Source
A34: YE26 billed IT BASE | B34: 257.7 | C34: D (team lock; workbook 257.66) | D34: =H30 -> 257.65617 | E34: =D34-B34 -> -0.043833333 | F34: =IF(ABS(E34)<0.5,"TIE","NON-TIE (flagged)") -> TIE | G34: vineland_watch.md §0c; capacity v2 row 147; model Judge_Slide B34
A35: YE26 billed IT HIGH | B35: 284.2 | C35: D (team lock) | D35: =I30 -> 284.15617 | E35: =D35-B35 -> -0.043833333 | F35: =IF(ABS(E35)<0.5,"TIE","NON-TIE (flagged)") -> TIE | G35: model Judge_Slide B35
A36: FY27 avg billed IT BASE | B36: 531.84 | C36: D (team lock v0.9e, engine-linked) | D36: =J30 -> 531.84362 | E36: =D36-B36 -> 0.0036167595 | F36: =IF(ABS(E36)<0.5,"TIE","NON-TIE (flagged)") -> TIE | G36: nebius_model.xlsx v0.9e Judge_Slide B25 (=Drivers!B34) 531.841; non-Vineland 349.5 + Vineland engine 182.3
A37: FY27 avg billed IT HIGH | B37: 659.16 | C37: D (team lock v0.9e, engine-linked) | D37: =K30 -> 659.16138 | E37: =D37-B37 -> 0.0013792595 | F37: =IF(ABS(E37)<0.5,"TIE","NON-TIE (flagged)") -> TIE | G37: nebius_model.xlsx v0.9e Judge_Slide B26 (=Drivers!C34) 659.157; non-Vineland high 476.8 + Vineland engine 182.3
A38: YE26 energized IT BASE | B38: 301.72 | C38: D | D38: =G30 -> 301.7202 | E38: =D38-B38 -> 0.0002 | F38: =IF(ABS(E38)<0.5,"TIE","NON-TIE (flagged)") -> TIE | G38: capacity v2 Quarterly MW row 136
A39: YE26 connected BASE | B39: 941 | C39: E | D39: =E30 -> 941 | E39: =D39-B39 -> 0 | F39: =IF(ABS(E39)<0.5,"TIE","NON-TIE (flagged)") -> TIE | G39: capacity v2 Quarterly MW row 142; unseen_capacity.md
A40: YE26 connected LOW | B40: 561 | C40: E | D40: =D30 -> 561.2 | E40: =D40-B40 -> 0.2 | F40: =IF(ABS(E40)<0.5,"TIE","NON-TIE (flagged)") -> TIE | G40: capacity v2 row 141
A41: YE26 connected HIGH | B41: 1195 | C41: E | D41: =F30 -> 1156 | E41: =D41-B41 -> -39 | F41: =IF(ABS(E41)<0.5,"TIE","NON-TIE (flagged)") -> NON-TIE (flagged) | G41: capacity v2 row 143 — residual ~39 MW not attributed (France 2nd n/d + range)
A42: MEMO — superseded Oct 8 ~9:50 ET: A19 typed $2,711M, pre engine link — FY27 BASE 536.48 | C42: D (superseded) | D42: =J30-J6+Quarterly_IT!$B$36 -> 536.47992
...

Sheet Quarterly_IT
A1: Site | B1: Treated as | C1: Gross/IT factor | D1: Base IT Q3'26 | E1: Base IT Q4'26 | F1: Base IT Q1'27 | G1: Base IT Q2'27 | H1: Base IT Q3'27 | I1: Base IT Q4'27 | J1: High IT Q3'26 | K1: High IT Q4'26 | L1: High IT Q1'27 | M1: High IT Q2'27 | N1: High IT Q3'27 | O1: High IT Q4'27 | P1: Tag | Q1: Source
A2: Vineland NJ (DataOne) | B2: IT | C2: 1.2 | D2: 66 | E2: 81.8 | F2: 118.5 | G2: 168.5 | H2: 200 | I2: 235 | J2: 75 | K2: 106.6 | L2: 180 | M2: 230 | N2: 240 | O2: 240 | P2: D (from E site energized paths) | Q2: nebius_capacity.xlsx 'Quarterly MW' energized base/high ÷ Basis factor
A3: Independence MO (Eastgate) | B3: gross | C3: 1.35 | D3: 0 | E3: 0 | F3: 0 | G3: 0 | H3: 37.037 | I3: 92.5926 | J3: 0 | K3: 0 | L3: 0 | M3: 0 | N3: 74.0741 | O3: 148.1481 | P3: D (from E site energized paths) | Q3: nebius_capacity.xlsx 'Quarterly MW' energized base/high ÷ Basis factor
A4: Butler Twp PA (Highridge) | B4: gross | C4: 1.35 | D4: 0 | E4: 0 | F4: 0 | G4: 0 | H4: 0 | I4: 48.1481 | J4: 0 | K4: 0 | L4: 0 | M4: 0 | N4: 0 | O4: 96.2963 | P4: D (from E site energized paths) | Q4: nebius_capacity.xlsx 'Quarterly MW' energized base/high ÷ Basis factor
A5: Birmingham AL (BHM01, Oxmoor) | B5: gross | C5: 1.35 | D5: 0 | E5: 0 | F5: 9.2593 | G5: 18.5185 | H5: 37.037 | I5: 55.5556 | J5: 0 | K5: 0 | L5: 18.5185 | M5: 37.037 | N5: 55.5556 | O5: 74.0741 | P5: D (from E site energized paths) | Q5: nebius_capacity.xlsx 'Quarterly MW' energized base/high ÷ Basis factor
A6: Bethune FR (Azur Datacenter, ex-Bridgestone) | B6: gross | C6: 1.3 | D6: 0 | E6: 23.0769 | F6: 56.5385 | G6: 92.3077 | H6: 92.3077 | I6: 138.4615 | J6: 0 | K6: 46.1538 | L6: 92.3077 | M6: 138.4615 | N6: 138.4615 | O6: 184.6154 | P6: D (from E site energized paths) | Q6: nebius_capacity.xlsx 'Quarterly MW' energized base/high ÷ Basis factor
A7: Lappeenranta FI (Pajarila / Polarnode) | B7: gross | C7: 1.15 | D7: 0 | E7: 0 | F7: 0 | G7: 15.2174 | H7: 30.4348 | I7: 45.6522 | J7: 0 | K7: 0 | L7: 0 | M7: 30.4348 | N7: 60.8696 | O7: 60.8696 | P7: D (from E site energized paths) | Q7: nebius_capacity.xlsx 'Quarterly MW' energized base/high ÷ Basis factor
A8: Mantsala FI #1 | B8: gross | C8: 1.1 | D8: 68.1818 | E8: 68.1818 | F8: 68.1818 | G8: 68.1818 | H8: 68.1818 | I8: 68.1818 | J8: 68.1818 | K8: 68.1818 | L8: 68.1818 | M8: 68.1818 | N8: 68.1818 | O8: 68.1818 | P8: D (from E site energized paths) | Q8: nebius_capacity.xlsx 'Quarterly MW' energized base/high ÷ Basis factor
A9: Mantsala FI #2 (Kapuli) | B9: gross | C9: 1.15 | D9: 0 | E9: 0 | F9: 0 | G9: 0 | H9: 0 | I9: 15.2174 | J9: 0 | K9: 0 | L9: 0 | M9: 0 | N9: 0 | O9: 30.4348 | P9: D (from E site energized paths) | Q9: nebius_capacity.xlsx 'Quarterly MW' energized base/high ÷ Basis factor
A10: Kansas City MO (Patmos) | B10: IT | C10: 1.35 | D10: 20 | E10: 20 | F10: 20 | G10: 20 | H10: 20 | I10: 30 | J10: 35 | K10: 35 | L10: 35 | M10: 35 | N10: 35 | O10: 40 | P10: D (from E site energized paths) | Q10: nebius_capacity.xlsx 'Quarterly MW' energized base/high ÷ Basis factor
A11: Paris (Equinix PA10) | B11: IT | C11: 1.35 | D11: 5 | E11: 5 | F11: 5 | G11: 5 | H11: 5 | I11: 5 | J11: 5 | K11: 5 | L11: 5 | M11: 5 | N11: 5 | O11: 5 | P11: D (from E site energized paths) | Q11: nebius_capacity.xlsx 'Quarterly MW' energized base/high ÷ Basis factor
A12: Keflavik IS (Verne) | B12: IT | C12: 1.15 | D12: 10 | E12: 10 | F12: 10 | G12: 10 | H12: 10 | I12: 10 | J12: 10 | K12: 10 | L12: 10 | M12: 10 | N12: 10 | O12: 10 | P12: D (from E site energized paths) | Q12: nebius_capacity.xlsx 'Quarterly MW' energized base/high ÷ Basis factor
A13: London Longcross (Ark LP01) | B13: gross | C13: 1.3 | D13: 12.3077 | E13: 13.4615 | F13: 14.6154 | G13: 14.6154 | H13: 14.6154 | I13: 14.6154 | J13: 12.3077 | K13: 14.6154 | L13: 14.6154 | M13: 14.6154 | N13: 14.6154 | O13: 14.6154 | P13: D (from E site energized paths) | Q13: nebius_capacity.xlsx 'Quarterly MW' energized base/high ÷ Basis factor
... A23: Oklahoma colo (unnamed) | B23: IT | C23: 1.3 | D23: 10 | E23: 25 | F23: 50 | G23: 75 | H23: 100 | I23: 100 | J23: 15 | K23: 40 | L23: 75 | M23: 100 | N23: 125 | O23: 125 | P23: D (from E site energized paths) | Q23: nebius_capacity.xlsx 'Quarterly MW' energized base/high ÷ Basis factor
A24: France 2nd colo (unnamed; possibly eu-west2) | B24: IT | C24: 1.3 | D24: n/d | E24: n/d | F24: n/d | G24: n/d | H24: n/d | I24: n/d | J24: n/d | K24: n/d | L24: n/d | M24: n/d | N24: n/d | O24: n/d | P24: D (from E site energized paths) | Q24: nebius_capacity.xlsx 'Quarterly MW' energized base/high ÷ Basis factor
A25: AIB CLT1 (Moore, Spartanburg County SC; Lockhart Power) | B25: IT | C25: 1.3 | D25: 0 | E25: 0 | F25: 0 | G25: 0 | H25: 12.5 | I25: 25 | J25: 0 | K25: 0 | L25: 0 | M25: 0 | N25: 25 | O25: 50 | P25: D (from E site energized paths) | Q25: nebius_capacity.xlsx 'Quarterly MW' energized base/high ÷ Basis factor
A27: Vineland billed tranches (YE26)
A28: Tranches delivered by YE26 (T1 Nov-25, T2 Feb-26, T3-T4 Jul/Aug-26) | B28: 4 | C28: R (20-F; Q2-26 letter/call)
A29: IT MW per tranche (240 IT / 9, equal split) | B29: =240/9 -> 26.666667 | C29: E (sizes not disclosed)
A30: Vineland YE26 billed IT MW | B30: =B28*B29 -> 106.66667 | C30: D
A32: Vineland FY27 avg billed — billed-tranche basis (same as revenue engine / Judge_Slide A19)
A33: T1–T4 IT MW billed full year 2027 | B33: 107 | C33: D (model v0.9d Judge_Slide A19: 107 MW x $14.5M = $1,551.5M; 4 x 26.7 E)
A34: T5–T9 2027 revenue $M (T5–T6 from Q2'27, T7–T9 from Q3'27) | B34: 1159.5 | C34: D (vineland_watch.md §2; Judge_Slide A19)
A35: Microsoft rate $M per IT MW-yr | B35: 14.5 | C35: D ($17,392.9M / 5 yrs / 240 IT MW)
A36: Vineland FY27 avg billed IT MW (tranche basis) — USED IN FINAL TABLE | B36: =B33+B34/B35 -> 186.96552 | C36: D
A37: memo: same, from tranche months (4x26.67 full yr + 26.67x(2x9+3x6)/12) | B37: =4*B29+B29*(2*9+3*6)/12 -> 186.66667 | C37: D (0.3 MW rounding vs 107)
A38: memo: BULL tranche timing (T5–T6 from Q1'27, T7–T9 from Q2'27) | B38: =4*B29+B29*(2*12+3*9)/12 -> 220 | C38: D (tranche track bull starts)
A39: memo: Judge_Slide A27 basis (quarter-average of quarter-end delivered tranches 106.7/106.7/160/240/240) | B39: =((106.667+106.667)/2+(106.667+160)/2+(160+240)/2+(240+240)/2)/4 -> 170.00012 | C39: D
A40: memo: SUPERSEDED Oct 8 — Vineland FY27 on energized-lagged basis (did not match revenue engine) | B40: =(D2+2*E2+2*F2+2*G2+H2)/8 -> 125.45 | C40: D (superseded)
A41: memo: Contracts engine cross-check (model v0.9d Contracts r141/r142): MSFT 2027 billing IT MW quarter avg 185.6; 2027 revenue capped $2,643.8M (T3–T4 ramp, Q1'27 genset cap 102.4) | B41: 185.605 | C41: D (static copy)
A42: memo: SUPERSEDED Oct 8 — Vineland FY27 HIGH on energized-lagged basis | B42: =(J2+2*K2+2*L2+2*M2+N2)/8 -> 168.525 | C42: D (superseded)
A44: Vineland FY27 billed MW-yr — ENGINE-LINKED (v0.9e lock): engine Microsoft FY27 revenue ÷ $/IT MW-yr — USED IN FINAL TABLE | B44: 182.32922 | C44: D (static copy of /workspace/nebius/model/nebius_model.xlsx v0.9e Judge_Slide B19 = Drivers!B33; Contracts MS_Rev FY27)
A45: memo: engine Microsoft FY27 revenue $M (Contracts tab, capped; T3–T4 ramp + Q1'27 genset cap) | B45: 2643.76 | C45: D (v0.9e Contracts; ~$14.5M/IT MW-yr)
A46: memo: engine-basis BULL Bloom timing ≈ engine + (bull − base tranche-months) = +33.3 MW-yr for one-quarter-earlier T5–T9 starts | B46: =B44+(B38-B37) -> 215.66255 | C46: D (approx.; assumes engine ramp/cap unchanged)

Sheet Definitions
A1: Term | B1: Definition (one line) | C1: Tag | D1: Source
A2: connected | B2: Power delivered into fully built and equipped data-center halls (shell + fit-out ready); can sit idle until GPUs arrive. NOT contracted land+power (~5 GW); NOT substation/grid access alone; NOT billing. | C2: R (definition); E (941 and site splits) | D2: Q2'25 letter ('fully provisioned… can be activated immediately upon GPU installation'); Q3'25 letter ('power connected to built data centers'); Q1'26 letter
A3: active | B3: Power consumed by installed, operational IT. | C3: R (definition); D (site MW) | D3: Q1'26 letter; nebius_capacity.xlsx
A4: billed | B4: Revenue-generating IT MW (team metric): active IT lagged ~1 quarter for onboarding/acceptance; Vineland at delivered Microsoft tranches. | C4: D | D4: vineland_watch.md §0c; model v0.9d
A5: contracted (contrast) | B5: Land plus power rights (~5 GW target). Not connected, not billing. | C5: R | D5: Company materials; Filings
A6: YE26 connected guide | B6: 800 MW–1 GW (management). Our 941 is an Estimated reconstruction inside the guide. | C6: R (guide) / E (941) | D6: Q1'26 / Q2'26 letters; Q2'26 call

Sheet Change_vs_Oct5
A1: Item | B1: Oct 5 value | C1: Oct 8 final | D1: Changed? | E1: Note
A2: YE26 billed base / high | B2: ~258 / ~284 (257.7 / 284.2) | C2: 257.7 / 284.2 | D2: No | E2: Now split by site (new); totals tie
A3: FY27 avg billed BASE / HIGH (v0.9e engine-linked) | B3: ~475 / ~645 | C3: 531.8 / 659.2 (531.84 / 659.16) | D3: YES (v0.9e lock Oct 8 ~9:50 ET) | E3: Vineland 182.3 MW-yr engine-linked; 536.5 / 663.8 superseded (A19 typed $2,711M)
A4: FY27 avg billed BASE (interim) | B4: ~475 (474.96) | C4: 536.5 (536.48) — superseded ~9:50 ET | D4: interim | E4: Vineland moved to billed-tranche basis (125.5 → 187.0) to match revenue engine; 475 kept as superseded memo
A5: FY27 avg billed HIGH | B5: ~645 (645.4) | C5: 663.8 (663.80) | D5: YES (team decision Oct 8) | E5: Vineland in high moved to billed-tranche basis (168.5 → 187.0, base Bloom timing); 645.4 superseded memo; 696.8 bull memo
A6: MW needed at $16M vs paths | B6: gap vs high 645 ≈ 123 | C6: 768.75 needed: gap 232 (base, 1.43x) / 105 (high, 1.16x) / 72 (bull) | D6: Derived change | E6: Street $12.3B (E) ÷ $16M (E)
A7: YE26 energized IT base / low / high | B7: 301.7 / 189.5 / 414.0 | C7: same | D7: No
A8: YE26 connected low / base / high | B8: 561 / 941 / 1,195 (E) | C8: same | D8: No | E8: Site high sum 1,156: 39 MW residual still unattributed
A9: Vineland pair | B9: 300 connected vs ~82 active | C9: same | D9: No | E9: 218 is only the gap; ~107 IT = T1–T4 genset ceiling
A10: MSFT tranches | B10: 4 of 9 live; T5–T9 Bloom-gated | C10: same | D10: No | E10: Oct 8 refresh: no new primary evidence
A11: Case B | B11: ≈ −$966M 2027 revenue @ ~35% | C11: same | D11: No
A12: YE27 connected (company) | B12: 1,882 base (E) | C12: same | D12: No | E12: Site-level only for fixed/fully built sites; others n/d
A13: Q3 results date | B13: ~Nov 10 (est.) | C13: late Oct–mid Nov (Oct 22 or Nov 10 per third-party calendars; not company-announced) | D13: Convention only | E13: Team lock Oct 8: may precede Nov 6–9 NJDEP deadline
A14: Street FY27 $/billed MW (base) | B14: ~$25.9M | C14: ~$22.9M | D14: Derived change | E14: $12.3B consensus (E) ÷ 536.5; Modeling to confirm
A15: Non-Vineland FY27 avg billed base | B15: ~288 (slide-implied) | C15: ~349.5 | D15: Derived change | E15: Slide-implied non-Vineland $/MW ~−17.6%
A16: Final_Table!C54 band label | B16: E (top of disclosed comps band $9.7–16.2M) | C16: E (top of disclosed comps band $9.7–16.7M) | D16: Text only | E16: Oct 8 3:25 PM, per Grok: band label updated to the locked $9.7–16.7M; no values or formulas changed
A17: Final_Table!C54 band label | B17: E (top of disclosed comps band $9.7–16.7M) | C17: E (top of disclosed comps band $9.7–16.7M as reported; hurdles per IT MW) | D17: Text only | E17: Oct 9 AM, per Grok Oct 8 11:44 PM: added "as reported" (Lambda/Bitdeer MW basis unstated); no values or formulas changed

Sheet Sources
A1: Source | B1: Used for
A2: /workspace/nebius/capacity/nebius_capacity.xlsx (v2) | B2: Quarterly MW energized base/high per site, Basis factors, rows 135-148 company series, Vineland tranche track
A3: /workspace/nebius/capacity/ye26_active_vs_connected.xlsx (Oct 5) | B3: YE26 connected L/B/H site splits (E) summing to 941
A4: /workspace/nebius/capacity/site_tracker_wed.xlsx/.md | B4: Owned/leased, customer, colo MW gaps, billing lock notes
A5: /workspace/nebius/capacity/owned_campus_power_path.md | B5: Independence / Butler / Birmingham power path; connected = feed/shell not IT
A6: /workspace/nebius/capacity/gpu_mw_capex.xlsx | B6: PUE / IT-gross conversion context
A7: /workspace/nebius/capacity/uncontracted_split.csv | B7: Contracted vs uncontracted flags (context)
A8: /workspace/nebius/model/nebius_model_recalc_preview_v09d.xlsx | B8: Judge_Slide B25/B26/B34/B35 locks; Revenue!F12 quarter-average method
A9: /workspace/nebius/capacity/vineland_watch.md (§0c, §1c Oct 8) | B9: Locked billing path; Vineland status Oct 8
A10: Nebius Q2'25, Q3'25, Q1'26, Q2'26 shareholder letters; FY25 20-F | B10: Connected definition; YE26 guide 800 MW–1 GW; Microsoft 9 tranches
