Workbook

Sheet README
A1: Nebius (NBIS) capacity model - built 2026-10-04 (ET) by Capacity & Power analyst. Public information only. Script: /workspace/nebius/capacity/build_capacity.py
A3: DEFINITIONS (Nebius, Q1-26 letter): contracted = power secured by contracted land and power commitments; connected = power connected into fully built and equipped DCs; active = power consumed by installed operational IT equipment, available for revenue.
A4: 'Energized MW' in this workbook = my estimate of power physically live at the site (closest to 'active'). It is NOT 'connected' (built-and-equipped, may not be powered) and NOT 'contracted'.
A5: MW BASIS: Nebius never states IT vs gross. Site rows use the stated basis (mostly unknown/gross). Vineland energized rows are IT MW (alt-data power-bounded); Modi'in and AIB are IT. Company totals therefore mix bases (1.1-1.45x PUE ambiguity).
A7: MAPPING FOR MODELING: Energized low -> Bear; Energized base (midpoint formula) -> Base; Energized high -> Bull. Contracted MW is not a revenue driver.
A8: BILLING LAG (Estimated): revenue/billing lags energization by >= 1 quarter for new capacity (commission DC, network, clusters, platform, onboarding: Q2-26 call "takes a few months"; active through 1H27). Exception: Vineland T1-T4 billing at reported delivery dates.
A9: Rates context (Q2-26 letter): ~$12M/MW/yr 2026 installed base; >$20M/MW Q2 new deals ($20-25M ACV/MW); >$40M/MW Q3 short-term deals.
A10: CAPEX (corrected): FY26 capex guide $20-25B (CFO, Q2-26 call Aug 12 2026; not in an SEC filing). On +580-780 MW connected (220 -> 800-1,000) = $25.6-43.1M per connected MW (Derived: 20,000/780 and 25,000/580). Earlier $16-20B figure superseded.
A12: YE2026 ENERGIZED (identified sites, this model): see Quarterly MW Q4 2026 company rows. Revised from prior ~330/600/800 after alt-data: Vineland capped at the generator ceiling (~107 MW IT) until Bloom is confirmed; Bethune 120 MW at risk; Birmingham/Independence revenue 2027.
A13: PLUG ROW: = mgmt reported/guided figure - identified base. At YE26 it shows the MW that must come from undisclosed sites (MN, OK, France 2nd, UK 3rd) or from counting built-but-unpowered halls as "connected" for the guide to be met. It is a reconciliation, not an estimate.
A14: GPUs: energized base MW x GPUs/MW (gpu_mw_capex.xlsx base rows; gross column for stated-basis sites, IT column for IT-basis sites). Reported GPU counts ran ahead of powered MW (delivered-not-powered): never back MW out of GPU counts.
A15: GPU vintage: generation per site is mostly ASSUMED (Nebius rarely discloses per site). 2027+ owned sites assumed Vera Rubin. Cohort rows = quarterly MW additions for vintage depreciation (servers 5-yr life from Jan 2026 per 20-F).
... A18: Verification grades and rationale: /workspace/nebius/capacity/site_verification.md. Alt-data: /workspace/nebius/capacity/altdata/altdata_timelines.xlsx.

Sheet Summary
A1: SUMMARY (v2) - Nebius energized / connected / leased MW. Base = midpoint; IT/gross via Basis tab. All projections Estimated.
A3: Metric | B3: YE26 low | C3: YE26 base | D3: YE26 high | E3: YE27 low | G3: YE27 base | H3: YE27 high | I3: Tag | J3: Source / note
A4: Energized MW - stated basis (mixed) | B4: ='Quarterly MW'!P124 -> 200 | C4: ='Quarterly MW'!P126 -> 319.5 | D4: ='Quarterly MW'!P125 -> 439 | E4: ='Quarterly MW'!T124 -> 864 | G4: ='Quarterly MW'!T126 -> 1212.5 | H4: ='Quarterly MW'!T125 -> 1561 | I4: Derived/Estimated
A5: Energized MW - IT-normalized | B5: ='Quarterly MW'!P135 -> 189.48951 | C5: ='Quarterly MW'!P136 -> 301.72028 | D5: ='Quarterly MW'!P137 -> 413.95105 | E5: ='Quarterly MW'!T135 -> 794.61375 | G5: ='Quarterly MW'!T136 -> 1081.9246 | H5: ='Quarterly MW'!T137 -> 1369.2355 | I5: Derived/Estimated
A6: Energized MW - gross-normalized | B6: ='Quarterly MW'!P138 -> 226 | C6: ='Quarterly MW'!P139 -> 368.6 | D6: ='Quarterly MW'!P140 -> 511.2 | E6: ='Quarterly MW'!T138 -> 989.85 | G6: ='Quarterly MW'!T139 -> 1363.975 | H6: ='Quarterly MW'!T140 -> 1738.1 | I6: Derived/Estimated
A7: Connected MW (gross/shell, bottom-up) | B7: ='Quarterly MW'!P141 -> 561 | C7: ='Quarterly MW'!P142 -> 941 | D7: ='Quarterly MW'!P143 -> 1195 | E7: ='Quarterly MW'!T141 -> 1249 | G7: ='Quarterly MW'!T142 -> 1882 | H7: ='Quarterly MW'!T143 -> 2517 | I7: Derived/Estimated
A8: Modeling placeholder YE27 energized IT MW | G8: 950
A9: Ours (IT base) minus 950 placeholder | G9: =G5-G8 -> 131.9246
A10: Mgmt guide: connected | C10: 800-1,000 | G10: ~1,800-2,000 (YE26 + >1 GW/yr)
A11: Vineland Bloom slips 2Q: IT MW lost at YE27 | G11: ='Quarterly MW'!T146 -> 66.5
A12: Billing MW (IT) at quarter-end: base / Bloom-slip | C12: ='Quarterly MW'!P147 -> 257.65618 | G12: ='Quarterly MW'!T147 -> 852.61375 | H12: ='Quarterly MW'!T148 -> 772.61375
A14: LEASED vs OWNED IT MW (for Note 12 $12.05B signed-not-commenced lease check: leased IT MW x $2.0-2.5M/IT MW/yr)
A15: Site | B15: Owned/leased | C15: Contracted MW (stated) | D15: Contracted IT MW | E15: Energized IT YE25 (base) | F15: Energized IT YE26 (base) | G15: Energized IT YE27 (base) | H15: Contracted IT not yet energized at YE26 | I15: Tag | J15: Note
A16: Vineland NJ (DataOne) | B16: leased | C16: ='Quarterly MW'!T3 -> 300 | D16: 240 | E16: =N('Quarterly MW'!L6) -> 26.2 | F16: =N('Quarterly MW'!P6) -> 81.8 | G16: =N('Quarterly MW'!T6) -> 235 | H16: =IF(ISNUMBER(D16),MAX(0,D16-N(F16)),"n/d") -> 158.2 | I16: Derived/Estimated | J16: Operating PUE 1.2 for liquid-cooled GB300 (team ceiling formula); design ratio 300/240 = 1.25
A17: Bethune FR (Azur Datacenter, ex-Bridgestone) | B17: leased | C17: ='Quarterly MW'!T23 -> 240 | D17: =IF(ISNUMBER('Quarterly MW'!T23),'Quarterly MW'!T23/Basis!$G$6,"n/d") -> 184.61538 | E17: =N('Quarterly MW'!L26)/Basis!$G$6 -> 0 | F17: =N('Quarterly MW'!P26)/Basis!$G$6 -> 23.076923 | G17: =N('Quarterly MW'!T26)/Basis!$G$6 -> 138.46154 | H17: =IF(ISNUMBER(D17),MAX(0,D17-N(F17)),"n/d") -> 161.53846 | I17: Derived/Estimated | J17: Northern France climate; peer range
A18: Kansas City MO (Patmos) | B18: leased | C18: ='Quarterly MW'!T43 -> 40 | D18: =IF(ISNUMBER('Quarterly MW'!T43),'Quarterly MW'!T43,"n/d") -> 40 | E18: =N('Quarterly MW'!L46) -> 20 | F18: =N('Quarterly MW'!P46) -> 20 | G18: =N('Quarterly MW'!T46) -> 30 | H18: =IF(ISNUMBER(D18),MAX(0,D18-N(F18)),"n/d") -> 20 | I18: Derived/Estimated | J18: Air-cooled Hopper/B200 retrofit; colo leases usually priced on critical IT
A19: Paris (Equinix PA10) | B19: leased | C19: ='Quarterly MW'!T48 -> 5 | D19: =IF(ISNUMBER('Quarterly MW'!T48),'Quarterly MW'!T48,"n/d") -> 5 | E19: =N('Quarterly MW'!L51) -> 5 | F19: =N('Quarterly MW'!P51) -> 5 | G19: =N('Quarterly MW'!T51) -> 5 | H19: =IF(ISNUMBER(D19),MAX(0,D19-N(F19)),"n/d") -> 0 | I19: Derived/Estimated | J19: Equinix urban colo
A20: Keflavik IS (Verne) | B20: leased | C20: ='Quarterly MW'!T53 -> 10 | D20: =IF(ISNUMBER('Quarterly MW'!T53),'Quarterly MW'!T53,"n/d") -> 10 | E20: =N('Quarterly MW'!L56) -> 10 | F20: =N('Quarterly MW'!P56) -> 10 | G20: =N('Quarterly MW'!T56) -> 10 | H20: =IF(ISNUMBER(D20),MAX(0,D20-N(F20)),"n/d") -> 0 | I20: Derived/Estimated | J20: Iceland free cooling
A21: London Longcross (Ark LP01) | B21: leased | C21: ='Quarterly MW'!T58 -> 19 | D21: =IF(ISNUMBER('Quarterly MW'!T58),'Quarterly MW'!T58/Basis!$G$13,"n/d") -> 14.615385 | E21: =N('Quarterly MW'!L61)/Basis!$G$13 -> 12.307692 | F21: =N('Quarterly MW'!P61)/Basis!$G$13 -> 13.461538 | G21: =N('Quarterly MW'!T61)/Basis!$G$13 -> 14.615385 | H21: =IF(ISNUMBER(D21),MAX(0,D21-N(F21)),"n/d") -> 1.1538462 | I21: Derived/Estimated | J21: Air-cooled HGX B300
A22: Harlow UK (Kao Data KLON-02/03) | B22: leased | C22: ='Quarterly MW'!T63 -> 22 | D22: =IF(ISNUMBER('Quarterly MW'!T63),'Quarterly MW'!T63,"n/d") -> 22 | E22: =N('Quarterly MW'!L66) -> 0 | F22: =N('Quarterly MW'!P66) -> 2.2 | G22: =N('Quarterly MW'!T66) -> 22 | H22: =IF(ISNUMBER(D22),MAX(0,D22-N(F22)),"n/d") -> 19.8 | I22: Derived/Estimated | J22: Kao Data design PUE ~1.2 (Estimated)
A23: Newport UK (Vantage CWL1) | B23: leased | C23: ='Quarterly MW'!T68 -> n/d | D23: 43 | E23: =N('Quarterly MW'!L71) -> 0 | F23: =N('Quarterly MW'!P71) -> 5 | G23: =N('Quarterly MW'!T71) -> 31.5 | H23: =IF(ISNUMBER(D23),MAX(0,D23-N(F23)),"n/d") -> 38 | I23: Derived/Estimated | J23: UK colo
A24: UK 3rd new deployment (lead: Green Mountain LON-East, Romford) | B24: leased | C24: ='Quarterly MW'!T73 -> n/d | D24: n/d | E24: =N('Quarterly MW'!L76) -> 0 | F24: =N('Quarterly MW'!P76) -> 0 | G24: =N('Quarterly MW'!T76) -> 7 | H24: =IF(ISNUMBER(D24),MAX(0,D24-N(F24)),"n/d") -> n/d | I24: Derived/Estimated | J24: UK colo
A25: Modi'in IL (Mega Or) | B25: leased | C25: ='Quarterly MW'!T78 -> 8 | D25: =IF(ISNUMBER('Quarterly MW'!T78),'Quarterly MW'!T78,"n/d") -> 8 | E25: =N('Quarterly MW'!L81) -> 8 | F25: =N('Quarterly MW'!P81) -> 8 | G25: =N('Quarterly MW'!T81) -> 8 | H25: =IF(ISNUMBER(D25),MAX(0,D25-N(F25)),"n/d") -> 0 | I25: Derived/Estimated | J25: Israel climate
A26: Masmiyya IL (Mega DC) | B26: leased | C26: ='Quarterly MW'!T83 -> 22 | D26: =IF(ISNUMBER('Quarterly MW'!T83),'Quarterly MW'!T83,"n/d") -> 22 | E26: =N('Quarterly MW'!L86) -> 0 | F26: =N('Quarterly MW'!P86) -> 5.5 | G26: =N('Quarterly MW'!T86) -> 22 | H26: =IF(ISNUMBER(D26),MAX(0,D26-N(F26)),"n/d") -> 16.5 | I26: Derived/Estimated | J26: Israel climate
A27: Beit Shemesh IL (Mega DC) | B27: leased | C27: ='Quarterly MW'!T88 -> 58 | D27: =IF(ISNUMBER('Quarterly MW'!T88),'Quarterly MW'!T88,"n/d") -> 58 | E27: =N('Quarterly MW'!L91) -> 0 | F27: =N('Quarterly MW'!P91) -> 0 | G27: =N('Quarterly MW'!T91) -> 58 | H27: =IF(ISNUMBER(D27),MAX(0,D27-N(F27)),"n/d") -> 58 | I27: Derived/Estimated | J27: Israel climate
A28: Madrid-Getafe ES (Merlin Edged) | B28: leased | C28: ='Quarterly MW'!T93 -> 18 | D28: =IF(ISNUMBER('Quarterly MW'!T93),'Quarterly MW'!T93,"n/d") -> 18 | E28: =N('Quarterly MW'!L96) -> 0 | F28: =N('Quarterly MW'!P96) -> 13.5 | G28: =N('Quarterly MW'!T96) -> 18 | H28: =IF(ISNUMBER(D28),MAX(0,D28-N(F28)),"n/d") -> 4.5 | I28: Derived/Estimated | J28: Madrid climate
A29: Tallinn EE (Greenergy Huuru) | B29: leased | C29: ='Quarterly MW'!T98 -> 22 | D29: =IF(ISNUMBER('Quarterly MW'!T98),'Quarterly MW'!T98,"n/d") -> 22 | E29: =N('Quarterly MW'!L101) -> 0 | F29: =N('Quarterly MW'!P101) -> 11 | G29: =N('Quarterly MW'!T101) -> 22 | H29: =IF(ISNUMBER(D29),MAX(0,D29-N(F29)),"n/d") -> 11 | I29: Derived/Estimated | J29: Baltic climate
A30: Minnesota colo (us-north1, Woodbury) | B30: leased | C30: ='Quarterly MW'!T103 -> n/d | D30: n/d | E30: =N('Quarterly MW'!L106) -> 0 | F30: =N('Quarterly MW'!P106) -> 10 | G30: =N('Quarterly MW'!T106) -> 10 | H30: =IF(ISNUMBER(D30),MAX(0,D30-N(F30)),"n/d") -> n/d | I30: Derived/Estimated | J30: US colo
A31: Oklahoma colo (unnamed) | B31: leased | C31: ='Quarterly MW'!T108 -> n/d | D31: n/d | E31: =N('Quarterly MW'!L111) -> 0 | F31: =N('Quarterly MW'!P111) -> 25 | G31: =N('Quarterly MW'!T111) -> 100 | H31: =IF(ISNUMBER(D31),MAX(0,D31-N(F31)),"n/d") -> n/d | I31: Derived/Estimated | J31: US colo, liquid cooling
A32: France 2nd colo (unnamed; possibly eu-west2) | B32: leased | C32: ='Quarterly MW'!T113 -> n/d | D32: n/d | E32: n/d | F32: n/d | G32: n/d | H32: =IF(ISNUMBER(D32),MAX(0,D32-N(F32)),"n/d") -> n/d | I32: Derived/Estimated | J32: n/d
A33: AIB CLT1 (Moore, Spartanburg County SC; Lockhart Power) | B33: leased | C33: ='Quarterly MW'!T118 -> 50 | D33: =IF(ISNUMBER('Quarterly MW'!T118),'Quarterly MW'!T118,"n/d") -> 50 | E33: =N('Quarterly MW'!L121) -> 0 | F33: =N('Quarterly MW'!P121) -> 0 | G33: =N('Quarterly MW'!T121) -> 25 | H33: =IF(ISNUMBER(D33),MAX(0,D33-N(F33)),"n/d") -> 50 | I33: Derived/Estimated | J33: 65/50 = 1.30
A34: TOTAL leased | D34: =SUM(D16:D33) -> 737.23077 | E34: =SUM(E16:E33) -> 81.507692 | F34: =SUM(F16:F33) -> 233.53846 | G34: =SUM(G16:G33) -> 756.57692 | H34: =SUM(H16:H33) -> 538.69231
A35: TOTAL owned (IT-normalized energized) | E35: =N('Quarterly MW'!L11)/Basis!$G$3+N('Quarterly MW'!L16)/Basis!$G$4+N('Quarterly MW'!L21)/Basis!$G$5+N('Quarterly MW'!L31)/Basis!$G$7+N('Quarterly MW'!L36)/Basis!$G$8+N('Quarterly MW'!L41)/Basis!$G$9 -> 56.818182 | F35: =N('Quarterly MW'!P11)/Basis!$G$3+N('Quarterly MW'!P16)/Basis!$G$4+N('Quarterly MW'!P21)/Basis!$G$5+N('Quarterly MW'!P31)/Basis!$G$7+N('Quarterly MW'!P36)/Basis!$G$8+N('Quarterly MW'!P41)/Basis!$G$9 -> 68.181818 | G35: =N('Quarterly MW'!T11)/Basis!$G$3+N('Quarterly MW'!T16)/Basis!$G$4+N('Quarterly MW'!T21)/Basis!$G$5+N('Quarterly MW'!T31)/Basis!$G$7+N('Quarterly MW'!T36)/Basis!$G$8+N('Quarterly MW'!T41)/Basis!$G$9 -> 325.34768
A36: Illustrative: rent on leased contracted IT MW not yet energized at YE26, $M/yr @ $2.0M / $2.5M | B36: =H34*2 -> 1077.3846 | C36: =H34*2.5 -> 1346.7308
A38: LEASES SIGNED NOT COMMENCED (Q2'26 6-K Ex.99.2 lease note) vs our leased IT MW
A39: Leases signed not commenced at 6/30/26, undiscounted $M | B39: 12054.1 | I39: Reported | J39: Q2'26 interim FS (6-K Ex.99.2) lease note; primarily DC facilities + equipment; commencing 2026-2027; terms up to 12 yrs; $612.4M prepaid
A40: Same at 12/31/25, $M (terms up to 11 yrs; $271.0M prepaid) | B40: 9759.6 | I40: Reported | J40: FY25 20-F Note 8
A41: ROU assets 6/30/26 $M (YE25 918.8; H1 additions 996.2) | B41: 1855.1 | I41: Reported | J41: Q2'26 interim FS lease note
A42: Term assumption (yrs) - Filings check uses 12 (max disclosed) | B42: 12 | I42: Estimated | J42: Filings team check; disclosed as "up to 12 years"
A43: Alt term assumption (yrs) | B43: 10 | I43: Estimated | J43: sensitivity: average term below the maximum
...

Sheet Sites
A1: Site | B1: Country | C1: Ownership type | D1: Contract tag | E1: Contract tag evidence | F1: Contracted MW | G1: MW basis (IT/gross/unknown) | H1: PUE (where disclosed) | I1: Mgmt go-live | J1: My evidence-based go-live | K1: Risk grade | L1: GPU generation | M1: YE26 energized low | N1: YE26 energized high | O1: YE26 energized base | P1: Key sources
A2: Vineland NJ (DataOne) | B2: USA | C2: Build-to-suit (DataOne owns shell; Nebius tenant) | D2: Microsoft | E2: Reported: 6-K Sep 2025 / 20-F: MSFT served from Vineland | F2: 300 | G2: Contracted 300 = gross (Estimated); energized rows = IT MW (altdata power-bounded) | H2: not disclosed (IT est. uses PUE 1.2-1.35, Estimated) | I2: Phase 1 summer 2025; all 9 MSFT tranches during 2025-26; Vineland in 2026 connected power (Q2-26 call) | J2: ~107 MW IT ceiling on rented gensets through YE26; Bloom-powered remainder 1H-2H 2027 | K2: Yellow/Red | L2: GB300 NVL72 (assumed; not disclosed by Nebius) | M2: ='Quarterly MW'!P4 -> 57 | N2: ='Quarterly MW'!P5 -> 106.6 | O2: ='Quarterly MW'!P6 -> 81.8 | P2: https://www.sec.gov/Archives/edgar/data/1513845/000110465925088312/tm2525580d1_6k.htm; https://www.sec.gov/Archives/edgar/data/1513845/000110465926052948/nbis-20251231x20f.htm; https://www.sec.gov/Archives/edgar/data/1513845/000110465926094568/tm2622968d1_ex99-2.htm; https://www.fool.com/earnings/call-transcripts/2026/08/19/nebius-nbis-q2-2026-earnings-call-transcript/ (cached /workspace/nebius/src/q2t.txt); https://www.enr.com/articles/63695-inside-the-vineland-data-center-power-dispute; https://newjerseymonitor.com/2026/10/01/nj-data-center-polluted-air-for-nearly-a-year-before-regulators-intervened/; https://www.nj.gov/governor/news/2026/20260922a.shtml; https://hntrbrk.com/breaking-news/vineland; https://whyy.org/articles/vineland-planning-board-approves-data-center-plan/; /workspace/nebius/capacity/altdata/altdata_timelines.xlsx (Timeline, Vineland_MW)
A3: Independence MO (Eastgate) | B3: USA | C3: Owned greenfield | D3: unassigned (Meta #2 candidate - assumed) | E3: assumed: Meta #2 = multiple undisclosed locations; Phase 1 Q3-27 is after Meta #2 1H27 tranches | F3: 1200 | G3: unknown (likely gross/utility) | H3: not disclosed | I3: Operational 2027 (Q1-26 letter); IPL initial power 2H26 | J3: Phase 1 ~Q3 2027; 600 MW not before 2029 | K3: Green | L3: Vera Rubin NVL72 (assumed; company-level VR statement) | M3: ='Quarterly MW'!P9 -> 0 | N3: ='Quarterly MW'!P10 -> 0 | O3: ='Quarterly MW'!P11 -> 0 | P3: https://nebius.com/independencemo; https://www.independencemo.gov/sites/default/files/2026-02/Nebius%20x%20Independence%2C%20MO.cleaned.pdf; https://citizenportal.ai/articles/7477161 (Independence PUAB: IPP PPA/ESA timeline); https://ded.mo.gov/press-room/nebius-breaks-ground-gigawatt-scale-ai-factory-independence; https://www.sec.gov/Archives/edgar/data/1513845/000110465926059872/tm2614392d1_ex99-2.htm; /workspace/nebius/capacity/altdata/altdata_timelines.xlsx (Timeline, Vineland_MW)
A4: Butler Twp PA (Highridge) | B4: USA | C4: Owned greenfield | D4: unassigned | E4: not disclosed | F4: 1200 | G4: unknown (PPL ESA = utility/gross) | H4: not disclosed | I4: 260 MW by Oct 2027; 660 MW Jan 2029; 1,000+ MW Nov 2029 | J4: First MW Q4 2027 at best; base ~Q2 2028-2029 (PPL lines late-27 to early-29; 3-yr build) | K4: Red | L4: Vera Rubin NVL72 (assumed) | M4: ='Quarterly MW'!P14 -> 0 | N4: ='Quarterly MW'!P15 -> 0 | O4: ='Quarterly MW'!P16 -> 0 | P4: https://nebius.com/schuylkillcountypa; https://www.republicanherald.com/2026/09/01/nebius-gets-green-light-to-expand-its-data-center-plan-in-butler-twp/; https://www.republicanherald.com/2026/04/24/butler-twp-switchyard-to-anchor-data-center-in-ppl-powerline-overhaul/; https://www.datacenterdynamics.com/en/news/nebius-details-plans-for-12gw-data-center-campus-in-pennsylvania/; /workspace/nebius/capacity/altdata/altdata_timelines.xlsx (Timeline, Vineland_MW)
A5: Birmingham AL (BHM01, Oxmoor) | B5: USA | C5: Owned brownfield | D5: unassigned | E5: not disclosed | F5: 300 | G5: unknown (300 MW is press figure, not Nebius) | H5: not disclosed | I5: Initial-phase energization Q4 2026 (Nebius page); operational 2027 (Q1-26 letter) | J5: 115 kV NLT Dec 31 2026; first revenue MW 2027; 230 kV Oct 2027 | K5: Yellow | L5: Vera Rubin NVL72 (assumed) | M5: ='Quarterly MW'!P19 -> 0 | N5: ='Quarterly MW'!P20 -> 0 | O5: ='Quarterly MW'!P21 -> 0 | P5: https://nebius.com/birminghamal; https://abc3340.com/resources/pdf/9222f76a-3063-46e4-aee7-796b30ed611f-NebiusResponsestoCityLetter_Redacted.pdf; https://bhamnow.com/2026/05/18/40-million-permits-birmingham-data-center/; https://www.wbhm.org/local-news/2026-09-18/action-picks-up-in-lawsuits-targeting-birmingham-data-center; /workspace/nebius/capacity/altdata/altdata_timelines.xlsx (Timeline, Vineland_MW)
A6: Bethune FR (Azur Datacenter, ex-Bridgestone) | B6: France | C6: Colocation (20-F); Azur finances/builds | D6: Meta (#2 likely) - press | E6: La Voix du Nord 2026-09-24: part of site 'fera travailler l'IA de Meta' (Estimated mapping to Meta #2) | F6: 240 | G6: unknown | H6: not disclosed | I6: First capacity late summer 2026; ~120 MW YE26; 240 MW 2027 | J6: Start Q4 2026 (~27 MW initial); 120 MW ~1H27; prefect ICPE decision pending | K6: Yellow | L6: GB300 NVL72 (Estimated: EUR4M/rack per press) | M6: ='Quarterly MW'!P24 -> 0 | N6: ='Quarterly MW'!P25 -> 60 | O6: ='Quarterly MW'!P26 -> 30 | P6: https://www.reuters.com/technology/amsterdam-based-ai-firm-nebius-build-240mw-data-centre-near-lille-france-2026-02-12/; https://www.lavoixdunord.fr/1740138/article/2026-09-24/la-premiere-ia-factory-des-hauts-de-france-va-bientot-prendre-vie-bethune; https://www.nordfranceinvest.com/success-story/dutch-company-nebius-is-setting-up-the-first-ai-data-center-in-the-hauts-de-france-region/; https://presseagence.fr/bethune-numerique-un-projet-de-datacenter-soumis-a-consultation-publique/; /workspace/nebius/capacity/altdata/altdata_timelines.xlsx (Timeline, Vineland_MW)
A7: Lappeenranta FI (Pajarila / Polarnode) | B7: Finland | C7: Owned per Nebius; Polarnode says Nebius 'operates' its campus (conflict) | D7: unassigned | E7: not disclosed | F7: 310 | G7: unknown | H7: not disclosed | I7: First capacity to customers 2027 | J7: First building H1 2027 (Fira); substation spring 2027 | K7: Green | L7: Vera Rubin NVL72 (assumed; PR: Blackwell & Rubin) | M7: ='Quarterly MW'!P29 -> 0 | N7: ='Quarterly MW'!P30 -> 0 | O7: ='Quarterly MW'!P31 -> 0 | P7: https://nebius.com/newsroom/nebius-to-construct-310-mw-ai-factory-in-finland; https://fira.fi/en/tiedote/construction-and-project-development-company-fira-selected-as-main-contractor-for-one-of-europes-largest-ai-data-center-projects/; https://www.caverion.com/newsroom/releases/2026/caverion-to-deliver-eur-15-million-substation-for-nebius-data-center-in-finland-creating-jobs-for-more-than-80-professionals/
A8: Mantsala FI #1 | B8: Finland | C8: Owned | D8: self-serve (assumed); Meta #1 site not disclosed | E8: assumed | F8: 75 | G8: unknown; PUE ~1.1 (company) | H8: ~1.1 (Nebius, company statement) | I8: 75 MW end-2025/early-2026 | J8: 75 MW built (completed early 2026) | K8: Green | L8: Hopper (first 25 MW) + GB300 NVL72 (expansion, Estimated split) | M8: ='Quarterly MW'!P34 -> 75 | N8: ='Quarterly MW'!P35 -> 75 | O8: ='Quarterly MW'!P36 -> 75 | P8: https://assets.nebius.com/assets/6590d0a0-0fc4-4396-bc3f-f52a9ccb770e/20260331%20Nebius%20to%20construct%20310%20MW%20AI%20factory%20in%20Finland.pdf; /workspace/nebius/capacity/altdata/altdata_timelines.xlsx (Timeline, Vineland_MW)
A9: Mantsala FI #2 (Kapuli) | B9: Finland | C9: Owned (implied) | D9: unassigned | E9: not disclosed | F9: 70 | G9: unknown (70 MW substation) | H9: not disclosed | I9: Capacity 'from 2027' | J9: Q4 2027 earliest (substation completes autumn 2027) | K9: Yellow | L9: Vera Rubin NVL72 (assumed) | M9: ='Quarterly MW'!P39 -> 0 | N9: ='Quarterly MW'!P40 -> 0 | O9: ='Quarterly MW'!P41 -> 0 | P9: https://www.assemblincaverion.com/news-and-media/news/2026/caverion-finland-strengthens-its-position-in-the-data-centre-market-and-will-deliver-a-eur-15-million-substation-for-ai-cloud-company-nebius/; https://www.datacenterdynamics.com/en/news/nebius-expands-european-presence-announces-deployment-in-estonia-and-second-data-center-in-m%C3%A4nts%C3%A4l%C3%A4-finland/
A10: Kansas City MO (Patmos) | B10: USA | C10: Colocation | D10: self-serve (assumed) | E10: assumed | F10: 40 | G10: unknown | H10: not disclosed | I10: 5 MW live Apr 2025; expandable to 40 MW | J10: Operational; Nebius share of 35 MW facility not disclosed | K10: Green | L10: H200 (first 5 MW) + B200 (rest) | M10: ='Quarterly MW'!P44 -> 5 | N10: ='Quarterly MW'!P45 -> 35 | O10: ='Quarterly MW'!P46 -> 20 | P10: https://www.datacenterdynamics.com/en/news/nebius-to-deploy-5mw-nvidia-h200-cluster-at-patmos-data-center-in-kansas-city-missouri/; https://www.datacenterdynamics.com/en/news/patmos-adds-10mw-of-capacity-at-kansas-city-data-center/; https://careers.nebius.com/?gh_jid=4975997101
A11: Paris (Equinix PA10) | B11: France | C11: Colocation | D11: self-serve (assumed) | E11: assumed | F11: 5 | G11: unknown; MW not disclosed (5 = 3rd-party) | H11: not disclosed | I11: Live Nov 2024 | J11: Operational | K11: Green | L11: Hopper H100/H200 | M11: ='Quarterly MW'!P49 -> 5 | N11: ='Quarterly MW'!P50 -> 5 | O11: ='Quarterly MW'!P51 -> 5 | P11: https://dcatlas.io/en/explore/facilities/nebius-equinix-paris (3rd-party, low confidence); https://docs.nebius.com/overview/regions (accessed 2026-10-04)
A12: Keflavik IS (Verne) | B12: Iceland | C12: Colocation | D12: self-serve (assumed) | E12: assumed | F12: 10 | G12: unknown | H12: not disclosed | I12: Live Mar 2025 | J12: Operational (private region) | K12: Green | L12: Hopper H100/H200 | M12: ='Quarterly MW'!P54 -> 10 | N12: ='Quarterly MW'!P55 -> 10 | O12: ='Quarterly MW'!P56 -> 10 | P12: https://nebius.com/blog/posts/300-mw-new-jersey-and-iceland-regions; https://docs.nebius.com/overview/regions (accessed 2026-10-04)
A13: London Longcross (Ark LP01) | B13: UK | C13: Colocation | D13: self-serve (assumed) | E13: assumed | F13: 19 | G13: unknown (GPU/MW fit suggests gross) | H13: not disclosed | I13: Launched Nov 2025; 16 MW live + 3 MW in delivery (Jun 2026); LP02 36 MW (Nebius share n/d) | J13: 19 MW by ~Q4 2026; LP02 share/timing not disclosed | K13: Green | L13: B300 (HGX) | M13: ='Quarterly MW'!P59 -> 16 | N13: ='Quarterly MW'!P60 -> 19 | O13: ='Quarterly MW'!P61 -> 17.5 | P13: https://datacentrenews.uk/story/nebius-fills-ark-s-longcross-data-centre-to-capacity; https://www.datacenterdynamics.com/en/news/ark-dc-to-add-new-building-to-longcross-data-center-campus-outside-london-uk/; https://docs.nebius.com/overview/regions (accessed 2026-10-04)
A14: Harlow UK (Kao Data KLON-02/03) | B14: UK | C14: Colocation (10-yr) | D14: self-serve (assumed) | E14: assumed | F14: 22 | G14: unknown | H14: not disclosed | I14: UK 65 MW fully ramped 2027 | J14: KLON-03 completion end-2026; MW early 2027 | K14: Green | L14: B300 (HGX) (assumed; docs uk-south2 lists RTX PRO 6000) | M14: ='Quarterly MW'!P64 -> 0 | N14: ='Quarterly MW'!P65 -> 4.4 | O14: ='Quarterly MW'!P66 -> 2.2 | P14: https://www.datacenterdynamics.com/en/news/nebius-signs-22mw-capacity-agreement-with-kao-data-in-the-uk/; https://www.linkedin.com/posts/infratil_klon-03-development-update-activity-7404073674942656512-l6mm; https://nebius.com/newsroom/nebius-expands-in-uk-with-more-nvidia-powered-infrastructure-more-customers-and-more-cloud-capabilities-for-agentic-and-enterprise-ai
A15: Newport UK (Vantage CWL1) | B15: UK | C15: Colocation (Vantage) | D15: self-serve (assumed) | E15: assumed | F15: not disclosed | G15: not stated (MW not disclosed) | H15: not disclosed | I15: Announced Aug 13 2026; part of UK 65 MW fully ramped 2027 | J15: Newport + UK 3rd = 65 - 22 (Harlow) = 43 MW by 2027 (Derived); Newport ~29 if LON-East is the 3rd site (low) | K15: Yellow | L15: not disclosed (B300/GB300 assumed) | M15: ='Quarterly MW'!P69 -> 0 | N15: ='Quarterly MW'!P70 -> 10 | O15: ='Quarterly MW'!P71 -> 5 | P15: https://vantage-dc.com/news/vantage-data-centers-and-nebius-expand-uk-ai-infrastructure-with-first-deployment-in-south-wales-ai-growth-zone/; https://nebius.com/newsroom/nebius-expands-in-uk-with-more-nvidia-powered-infrastructure-more-customers-and-more-cloud-capabilities-for-agentic-and-enterprise-ai; https://boards-api.greenhouse.io/v1/boards/nebius/jobs?content=true (accessed 2026-10-04) (Newport jobs 4883814101 Jun 19, 4959471101 Aug 27)
A16: UK 3rd new deployment (lead: Green Mountain LON-East, Romford) | B16: UK | C16: not disclosed | D16: unassigned | E16: not disclosed | F16: not disclosed | G16: unknown | H16: not disclosed | I16: Part of 65 MW UK by 2027 | J16: Lead only: Green Mountain LON-East 14 MW to unnamed neocloud (Sep 1 2026) + Nebius East London job (Feb 2); low confidence | K16: Red | L16: not disclosed | M16: ='Quarterly MW'!P74 -> 0 | N16: ='Quarterly MW'!P75 -> 0 | O16: ='Quarterly MW'!P76 -> 0 | P16: https://nebius.com/newsroom/nebius-expands-in-uk-with-more-nvidia-powered-infrastructure-more-customers-and-more-cloud-capabilities-for-agentic-and-enterprise-ai; https://www.datacenterdynamics.com/en/news/green-mountain-secures-neocloud-customer-at-data-center-in-london-uk/
A17: Modi'in IL (Mega Or) | B17: Israel | C17: Colocation | D17: self-serve (assumed); 25% to Israel Innovation Authority | E17: Reported (IIA share) | F17: 8 | G17: IT (4,000 B200 / 8 MW = 500/MW fits IT model) | H17: not disclosed | I17: Launched Oct 2025 | J17: Operational | K17: Green | L17: B200 (HGX) | M17: ='Quarterly MW'!P79 -> 8 | N17: ='Quarterly MW'!P80 -> 8 | O17: ='Quarterly MW'!P81 -> 8 | P17: https://nebius.com/newsroom/nebius-brings-nvidia-blackwell-to-israel-with-one-of-the-country-s-first-ai-infrastructure-deployments; https://www.datacenterdynamics.com/en/news/nebius-signs-80mw-data-center-lease-with-mega-or-in-israel/
A18: Masmiyya IL (Mega DC) | B18: Israel | C18: Colocation (5-yr) | D18: unassigned | E18: not disclosed | F18: 22 | G18: unknown | H18: not disclosed | I18: Delivery Q3 2026 (landlord) | J18: Mega Or Q2-26 deck: Yoav construction completion Q4 2026 -> Q4-26/Q2-27 | K18: Yellow | L18: GB300 NVL72 (assumed) | M18: ='Quarterly MW'!P84 -> 0 | N18: ='Quarterly MW'!P85 -> 11 | O18: ='Quarterly MW'!P86 -> 5.5 | P18: https://www.datacenterdynamics.com/en/news/nebius-signs-80mw-data-center-lease-with-mega-or-in-israel/; https://www.calcalistech.com/ctechnews/article/25ue6vi49; https://www.deeptase.co.il/en/analysis/4873
A19: Beit Shemesh IL (Mega DC) | B19: Israel | C19: Colocation (5-yr) | D19: unassigned | E19: not disclosed | F19: 58 | G19: unknown | H19: not disclosed | I19: Staged Q3 2026 - Q1 2027 (landlord) | J19: Mega Or Q2-26 deck: completion Q2 2027 -> staged Q1-Q4 2027 | K19: Yellow | L19: GB300 NVL72 (assumed) | M19: ='Quarterly MW'!P89 -> 0 | N19: ='Quarterly MW'!P90 -> 0 | O19: ='Quarterly MW'!P91 -> 0 | P19: https://www.datacenterdynamics.com/en/news/nebius-signs-80mw-data-center-lease-with-mega-or-in-israel/; https://www.calcalistech.com/ctechnews/article/25ue6vi49; https://www.deeptase.co.il/en/analysis/4873
A20: Madrid-Getafe ES (Merlin Edged) | B20: Spain | C20: Colocation | D20: self-serve (assumed) | E20: assumed | F20: 18 | G20: unknown | H20: not disclosed | I20: Phase 1 live Sep 2026; phases 2-3 'coming weeks' | J20: Phase 1 live; 18 MW by Q4 2026-Q1 2027 | K20: Green | L20: B300 (HGX) (RTX PRO 6000 phase 1 not modeled) | M20: ='Quarterly MW'!P94 -> 9 | N20: ='Quarterly MW'!P95 -> 18 | O20: ='Quarterly MW'!P96 -> 13.5 | P20: https://www.linkedin.com/feed/update/urn:li:activity:7505906816590073857; https://www.merlinproperties.com/dia-a-dia/firmamos-un-contrato-de-18-mw-con-nebius-para-nuestro-date-center-madrid-getafe/; https://docs.nebius.com/overview/regions (accessed 2026-10-04)
A21: Tallinn EE (Greenergy Huuru) | B21: Estonia | C21: Colocation | D21: unassigned | E21: not disclosed | F21: 22 | G21: unknown | H21: not disclosed | I21: 22 MW first phase later in 2026 | J21: Q4 2026-Q2 2027; Estonian govt security review discussed at Cabinet (Aug 2026) | K21: Yellow | L21: GB300 NVL72 (assumed) | M21: ='Quarterly MW'!P99 -> 0 | N21: ='Quarterly MW'!P100 -> 22 | O21: ='Quarterly MW'!P101 -> 11 | P21: https://news.err.ee/1610109073/baltics-first-ai-factory-to-open-in-estonia; https://www.datacenterdynamics.com/en/news/nebius-expands-european-presence-announces-deployment-in-estonia-and-second-data-center-in-m%C3%A4nts%C3%A4l%C3%A4-finland/
A22: Minnesota colo (us-north1, Woodbury) | B22: USA | C22: Colocation (20-F) | D22: self-serve (assumed) | E22: assumed | F22: not disclosed | G22: unknown | H22: not disclosed | I22: Secured Feb 2026 | J22: us-north1 Woodbury; likely IronGate MSP01 (15 MW live, fully leased; inference) | K22: Yellow | L22: B300 (HGX) | M22: ='Quarterly MW'!P104 -> 5 | N22: ='Quarterly MW'!P105 -> 15 | O22: ='Quarterly MW'!P106 -> 10 | P22: https://www.sec.gov/Archives/edgar/data/1513845/000110465926052948/nbis-20251231x20f.htm; https://docs.nebius.com/overview/regions (accessed 2026-10-04); https://woodburynewsnet.org/7933/business/what-woodbury-residents-should-know-about-irongates-two-data-centers/; https://boards-api.greenhouse.io/v1/boards/nebius/jobs?content=true (accessed 2026-10-04)
A23: Oklahoma colo (unnamed) | B23: USA | C23: Colocation (20-F) | D23: unassigned | E23: not disclosed | F23: >100 (map category) | G23: unknown | H23: not disclosed | I23: Secured Feb 2026 | J23: Q2-26 letter map: Sites >100MW; 8 on-site roles since Mar 2 2026; town/landlord not found | K23: Yellow/Red | L23: not disclosed | M23: ='Quarterly MW'!P109 -> 10 | N23: ='Quarterly MW'!P110 -> 40 | O23: ='Quarterly MW'!P111 -> 25 | P23: https://www.sec.gov/Archives/edgar/data/1513845/000110465926052948/nbis-20251231x20f.htm; https://assets.nebius.com/assets/a6ecfd85-a6cb-4967-8ef7-9a25bd261f9c/SHLQ226.pdf (p.2 map); https://boards-api.greenhouse.io/v1/boards/nebius/jobs?content=true (accessed 2026-10-04)
A24: France 2nd colo (unnamed; possibly eu-west2) | B24: France | C24: Colocation (20-F) | D24: unassigned | E24: not disclosed | F24: not disclosed | G24: unknown | H24: not disclosed | I24: Secured Feb 2026 | J24: eu-west2 (France, B300) live in docs - mapping is inference; MW n/d -> in plug | K24: Yellow | L24: B300 (HGX) (inference) | M24: ='Quarterly MW'!P114 -> n/d | N24: ='Quarterly MW'!P115 -> n/d | O24: ='Quarterly MW'!P116 -> n/d | P24: https://www.sec.gov/Archives/edgar/data/1513845/000110465926052948/nbis-20251231x20f.htm; https://docs.nebius.com/overview/regions (accessed 2026-10-04)
A25: AIB CLT1 (Moore, Spartanburg County SC; Lockhart Power) | B25: USA | C25: Colocation/lease (12-yr) | D25: unassigned | E25: not disclosed | F25: 50 | G25: IT (50 MW critical IT on 65 MW utility ESA) | H25: 65/50 = 1.30 implied (Derived) | I25: Hall 1 (25 MW) ~month 10, Hall 2 ~month 14 after Oct 1 2026 ESA start | J25: Hall 1 ~Q3-Q4 2027; permits only submitted; project financing not arranged | K25: Red | L25: Vera Rubin NVL72 (assumed) | M25: ='Quarterly MW'!P119 -> 0 | N25: ='Quarterly MW'!P120 -> 0 | O25: ='Quarterly MW'!P121 -> 0 | P25: http://archive.fast-edgar.com/20260930/AB2ZM22DL222P26L222Q2MY2R6GDZ222ZQ82/ea030723301ex99-1.htm (AIB 8-K Ex.99.1, Sep 30 2026); https://www.globenewswire.com/news-release/2026/09/30/3371855/0/en/aib-data-centers-signs-contract-with-nebius-for-ai-data-center-capacity.html; https://www.sec.gov/Archives/edgar/data/2070542/000121390026036810/ea0282624-10k_blockchain.htm

Sheet Quarterly MW
A1: Site | B1: Block | C1: Basis | D1: Tag (hist / proj) | E1: Q1 2024 | F1: Q2 2024 | G1: Q3 2024 | H1: Q4 2024 | I1: Q1 2025 | J1: Q2 2025 | K1: Q3 2025 | L1: Q4 2025 | M1: Q1 2026 | N1: Q2 2026 | O1: Q3 2026 | P1: Q4 2026 | Q1: Q1 2027 | R1: Q2 2027 | S1: Q3 2027 | T1: Q4 2027 | U1: Q1 2028 | V1: Q2 2028 | W1: Q3 2028 | X1: Q4 2028 | Y1: Q1 2029 | Z1: Q2 2029 | AA1: Q3 2029 | AB1: Q4 2029 | AC1: Q1 2030 | AD1: Q2 2030 | AE1: Q3 2030 | AF1: Q4 2030
A2: History Q1'24-Q2'26 (tags per cell in Tags_Sources); projections Q3'26-Q4'30 = Estimated. Base = midpoint of low/high (formula). Blue = input, black = formula.
A3: Vineland NJ (DataOne) | B3: Contracted MW | C3: gross/unknown | I3: 300 | J3: 300 | K3: 300 | L3: 300 | M3: 300 | N3: 300 | O3: 300 | P3: 300 | Q3: 300 | R3: 300 | S3: 300 | T3: 300 | U3: 300 | V3: 300 | W3: 300 | X3: 300 | Y3: 300 | Z3: 300 | AA3: 300 | AB3: 300 | AC3: 300 | AD3: 300 | AE3: 300 | AF3: 300
A4: Vineland NJ (DataOne) | B4: Energized MW low | C4: IT | E4: 0 | F4: 0 | G4: 0 | H4: 0 | I4: 0 | J4: 0 | K4: 0 | L4: =ROUND((5+16*1.982)*0.8/1.35,1) -> 21.8 | M4: 30 | N4: 33 | O4: 57 | P4: 57 | Q4: 57 | R4: 107 | S4: 160 | T4: 230 | U4: 230 | V4: 230 | W4: 230 | X4: 230 | Y4: 230 | Z4: 230 | AA4: 230 | AB4: 230 | AC4: 230 | AD4: 230 | AE4: 230 | AF4: 230
A5: Vineland NJ (DataOne) | B5: Energized MW high | C5: IT | E5: 0 | F5: 0 | G5: 0 | H5: 0 | I5: 0 | J5: 0 | K5: 0 | L5: =ROUND((5+16*1.982)/1.2,1) -> 30.6 | M5: 45 | N5: 45 | O5: 75 | P5: =ROUND((5+62*1.982)/1.2,1) -> 106.6 | Q5: 180 | R5: 230 | S5: 240 | T5: 240 | U5: 240 | V5: 240 | W5: 240 | X5: 240 | Y5: 240 | Z5: 240 | AA5: 240 | AB5: 240 | AC5: 240 | AD5: 240 | AE5: 240 | AF5: 240
A6: Vineland NJ (DataOne) | B6: Energized MW base (=midpoint) | C6: IT | E6: =(E4+E5)/2 -> 0 | F6: =(F4+F5)/2 -> 0 | G6: =(G4+G5)/2 -> 0 | H6: =(H4+H5)/2 -> 0 | I6: =(I4+I5)/2 -> 0 | J6: =(J4+J5)/2 -> 0 | K6: =(K4+K5)/2 -> 0 | L6: =(L4+L5)/2 -> 26.2 | ... AF6: =(AF4+AF5)/2 -> 235
A7: Vineland NJ (DataOne) | B7: Mgmt figure | C7: as stated | L7: 100 | P7: 300
A8: Independence MO (Eastgate) | B8: Contracted MW | C8: gross/unknown | L8: 1200 | M8: 1200 | N8: 1200 | O8: 1200 | P8: 1200 | Q8: 1200 | R8: 1200 | S8: 1200 | T8: 1200 | U8: 1200 | V8: 1200 | W8: 1200 | X8: 1200 | Y8: 1200 | Z8: 1200 | AA8: 1200 | AB8: 1200 | AC8: 1200 | AD8: 1200 | AE8: 1200 | AF8: 1200
A9: Independence MO (Eastgate) | B9: Energized MW low | C9: stated/unknown | E9: 0 | F9: 0 | G9: 0 | H9: 0 | I9: 0 | J9: 0 | K9: 0 | L9: 0 | M9: 0 | N9: 0 | O9: 0 | P9: 0 | Q9: 0 | R9: 0 | S9: 0 | T9: 50 | U9: 50 | V9: 100 | W9: 100 | X9: 200 | Y9: 200 | Z9: 300 | AA9: 300 | AB9: 500 | AC9: 500 | AD9: 500 | AE9: 500 | AF9: 700
A10: Independence MO (Eastgate) | B10: Energized MW high | C10: stated/unknown | E10: 0 | F10: 0 | G10: 0 | H10: 0 | I10: 0 | J10: 0 | K10: 0 | L10: 0 | M10: 0 | N10: 0 | O10: 0 | P10: 0 | Q10: 0 | R10: 0 | S10: 100 | T10: 200 | U10: 200 | V10: 250 | W10: 250 | X10: 250 | Y10: 250 | Z10: 600 | AA10: 600 | AB10: 800 | AC10: 800 | AD10: 800 | AE10: 800 | AF10: 1200
A11: Independence MO (Eastgate) | B11: Energized MW base (=midpoint) | C11: stated/unknown | E11: =(E9+E10)/2 -> 0 | F11: =(F9+F10)/2 -> 0 | G11: =(G9+G10)/2 -> 0 | H11: =(H9+H10)/2 -> 0 | I11: =(I9+I10)/2 -> 0 | J11: =(J9+J10)/2 -> 0 | K11: =(K9+K10)/2 -> 0 | L11: =(L9+L10)/2 -> 0 | ... AF11: =(AF9+AF10)/2 -> 950
A12: Independence MO (Eastgate) | B12: Mgmt figure | C12: as stated | O12: IPL 200 MW late Q3 2026 | T12: operational 2027
A13: Butler Twp PA (Highridge) | B13: Contracted MW | C13: gross/unknown | N13: 1200 | O13: 1200 | P13: 1200 | Q13: 1200 | R13: 1200 | S13: 1200 | T13: 1200 | U13: 1200 | V13: 1200 | W13: 1200 | X13: 1200 | Y13: 1200 | Z13: 1200 | AA13: 1200 | AB13: 1200 | AC13: 1200 | AD13: 1200 | AE13: 1200 | AF13: 1200
A14: Butler Twp PA (Highridge) | B14: Energized MW low | C14: stated/unknown | E14: 0 | F14: 0 | G14: 0 | H14: 0 | I14: 0 | J14: 0 | K14: 0 | L14: 0 | M14: 0 | N14: 0 | O14: 0 | P14: 0 | Q14: 0 | R14: 0 | S14: 0 | T14: 0 | U14: 0 | V14: 0 | W14: 0 | X14: 130 | Y14: 130 | Z14: 260 | AA14: 260 | AB14: 400 | AC14: 400 | AD14: 400 | AE14: 400 | AF14: 660
A15: Butler Twp PA (Highridge) | B15: Energized MW high | C15: stated/unknown | E15: 0 | F15: 0 | G15: 0 | H15: 0 | I15: 0 | J15: 0 | K15: 0 | L15: 0 | M15: 0 | N15: 0 | O15: 0 | P15: 0 | Q15: 0 | R15: 0 | S15: 0 | T15: 130 | U15: 260 | V15: 260 | W15: 260 | X15: 400 | Y15: 400 | Z15: 660 | AA15: 660 | AB15: 1000 | AC15: 1000 | AD15: 1000 | AE15: 1000 | AF15: 1200
A16: Butler Twp PA (Highridge) | B16: Energized MW base (=midpoint) | C16: stated/unknown | E16: =(E14+E15)/2 -> 0 | F16: =(F14+F15)/2 -> 0 | G16: =(G14+G15)/2 -> 0 | H16: =(H14+H15)/2 -> 0 | I16: =(I14+I15)/2 -> 0 | J16: =(J14+J15)/2 -> 0 | K16: =(K14+K15)/2 -> 0 | L16: =(L14+L15)/2 -> 0 | ... AF16: =(AF14+AF15)/2 -> 930
A17: Butler Twp PA (Highridge) | B17: Mgmt figure | C17: as stated | T17: 260 | Y17: 660 | AB17: 1000
A18: Birmingham AL (BHM01, Oxmoor) | B18: Contracted MW | C18: gross/unknown | K18: 300 | L18: 300 | M18: 300 | N18: 300 | O18: 300 | P18: 300 | Q18: 300 | R18: 300 | S18: 300 | T18: 300 | U18: 300 | V18: 300 | W18: 300 | X18: 300 | Y18: 300 | Z18: 300 | AA18: 300 | AB18: 300 | AC18: 300 | AD18: 300 | AE18: 300 | AF18: 300
A19: Birmingham AL (BHM01, Oxmoor) | B19: Energized MW low | C19: stated/unknown | E19: 0 | F19: 0 | G19: 0 | H19: 0 | I19: 0 | J19: 0 | K19: 0 | L19: 0 | M19: 0 | N19: 0 | O19: 0 | P19: 0 | Q19: 0 | R19: 0 | S19: 25 | T19: 50 | U19: 50 | V19: 100 | W19: 100 | X19: 200 | Y19: 200 | Z19: 200 | AA19: 200 | AB19: 300 | AC19: 300 | AD19: 300 | AE19: 300 | AF19: 300
A20: Birmingham AL (BHM01, Oxmoor) | B20: Energized MW high | C20: stated/unknown | E20: 0 | F20: 0 | G20: 0 | H20: 0 | I20: 0 | J20: 0 | K20: 0 | L20: 0 | M20: 0 | N20: 0 | O20: 0 | P20: 0 | Q20: 25 | R20: 50 | S20: 75 | T20: 100 | U20: 100 | V20: 200 | W20: 200 | X20: 300 | Y20: 300 | Z20: 300 | AA20: 300 | AB20: 300 | AC20: 300 | AD20: 300 | AE20: 300 | AF20: 300
A21: Birmingham AL (BHM01, Oxmoor) | B21: Energized MW base (=midpoint) | C21: stated/unknown | E21: =(E19+E20)/2 -> 0 | F21: =(F19+F20)/2 -> 0 | G21: =(G19+G20)/2 -> 0 | H21: =(H19+H20)/2 -> 0 | I21: =(I19+I20)/2 -> 0 | J21: =(J19+J20)/2 -> 0 | K21: =(K19+K20)/2 -> 0 | L21: =(L19+L20)/2 -> 0 | ... AF21: =(AF19+AF20)/2 -> 300
A22: Birmingham AL (BHM01, Oxmoor) | B22: Mgmt figure | C22: as stated | P22: initial energization (MW n/d)
A23: Bethune FR (Azur Datacenter, ex-Bridgestone) | B23: Contracted MW | C23: gross/unknown | M23: 240 | N23: 240 | O23: 240 | P23: 240 | Q23: 240 | R23: 240 | S23: 240 | T23: 240 | U23: 240 | V23: 240 | W23: 240 | X23: 240 | Y23: 240 | Z23: 240 | AA23: 240 | AB23: 240 | AC23: 240 | AD23: 240 | AE23: 240 | AF23: 240
A24: Bethune FR (Azur Datacenter, ex-Bridgestone) | B24: Energized MW low | C24: stated/unknown | E24: 0 | F24: 0 | G24: 0 | H24: 0 | I24: 0 | J24: 0 | K24: 0 | L24: 0 | M24: 0 | N24: 0 | O24: 0 | P24: 0 | Q24: 27 | R24: 60 | S24: 60 | T24: 120 | U24: 120 | V24: 120 | W24: 120 | X24: 240 | Y24: 240 | Z24: 240 | AA24: 240 | AB24: 240 | AC24: 240 | AD24: 240 | AE24: 240 | AF24: 240
A25: Bethune FR (Azur Datacenter, ex-Bridgestone) | B25: Energized MW high | C25: stated/unknown | E25: 0 | F25: 0 | G25: 0 | H25: 0 | I25: 0 | J25: 0 | K25: 0 | L25: 0 | M25: 0 | N25: 0 | O25: 0 | P25: 60 | Q25: 120 | R25: 180 | S25: 180 | T25: 240 | U25: 240 | V25: 240 | W25: 240 | X25: 240 | Y25: 240 | Z25: 240 | AA25: 240 | AB25: 240 | AC25: 240 | AD25: 240 | AE25: 240 | AF25: 240
A26: Bethune FR (Azur Datacenter, ex-Bridgestone) | B26: Energized MW base (=midpoint) | C26: stated/unknown | E26: =(E24+E25)/2 -> 0 | F26: =(F24+F25)/2 -> 0 | G26: =(G24+G25)/2 -> 0 | H26: =(H24+H25)/2 -> 0 | I26: =(I24+I25)/2 -> 0 | J26: =(J24+J25)/2 -> 0 | K26: =(K24+K25)/2 -> 0 | L26: =(L24+L25)/2 -> 0 | ... AF26: =(AF24+AF25)/2 -> 240
A27: Bethune FR (Azur Datacenter, ex-Bridgestone) | B27: Mgmt figure | C27: as stated | O27: first capacity | P27: 120 | T27: 240
A28: Lappeenranta FI (Pajarila / Polarnode) | B28: Contracted MW | C28: gross/unknown | M28: 310 | N28: 310 | O28: 310 | P28: 310 | Q28: 310 | R28: 310 | S28: 310 | T28: 310 | U28: 310 | V28: 310 | W28: 310 | X28: 310 | Y28: 310 | Z28: 310 | AA28: 310 | AB28: 310 | AC28: 310 | AD28: 310 | AE28: 310 | AF28: 310
A29: Lappeenranta FI (Pajarila / Polarnode) | B29: Energized MW low | C29: stated/unknown | E29: 0 | F29: 0 | G29: 0 | H29: 0 | I29: 0 | J29: 0 | K29: 0 | L29: 0 | M29: 0 | N29: 0 | O29: 0 | P29: 0 | Q29: 0 | R29: 0 | S29: 0 | T29: 35 | U29: 35 | V29: 70 | W29: 70 | X29: 140 | Y29: 140 | Z29: 140 | AA29: 140 | AB29: 220 | AC29: 220 | AD29: 220 | AE29: 220 | AF29: 310
A30: Lappeenranta FI (Pajarila / Polarnode) | B30: Energized MW high | C30: stated/unknown | E30: 0 | F30: 0 | G30: 0 | H30: 0 | I30: 0 | J30: 0 | K30: 0 | L30: 0 | M30: 0 | N30: 0 | O30: 0 | P30: 0 | Q30: 0 | R30: 35 | S30: 70 | T30: 70 | U30: 70 | V30: 140 | W30: 140 | X30: 200 | Y30: 200 | Z30: 200 | AA30: 200 | AB30: 310 | AC30: 310 | AD30: 310 | AE30: 310 | AF30: 310
A31: Lappeenranta FI (Pajarila / Polarnode) | B31: Energized MW base (=midpoint) | C31: stated/unknown | E31: =(E29+E30)/2 -> 0 | F31: =(F29+F30)/2 -> 0 | G31: =(G29+G30)/2 -> 0 | H31: =(H29+H30)/2 -> 0 | I31: =(I29+I30)/2 -> 0 | J31: =(J29+J30)/2 -> 0 | K31: =(K29+K30)/2 -> 0 | L31: =(L29+L30)/2 -> 0 | ... AF31: =(AF29+AF30)/2 -> 310
A32: Lappeenranta FI (Pajarila / Polarnode) | B32: Mgmt figure | C32: as stated | T32: first capacity 2027
A33: Mantsala FI #1 | B33: Contracted MW | C33: gross/unknown | H33: 75 | I33: 75 | J33: 75 | K33: 75 | L33: 75 | M33: 75 | N33: 75 | O33: 75 | P33: 75 | Q33: 75 | R33: 75 | S33: 75 | T33: 75 | U33: 75 | V33: 75 | W33: 75 | X33: 75 | Y33: 75 | Z33: 75 | AA33: 75 | AB33: 75 | AC33: 75 | AD33: 75 | AE33: 75 | AF33: 75
A34: Mantsala FI #1 | B34: Energized MW low | C34: stated/unknown | E34: 25 | F34: 25 | G34: 25 | H34: 25 | I34: 25 | J34: 25 | K34: 25 | L34: 50 | M34: 75 | N34: 75 | O34: 75 | P34: 75 | Q34: 75 | R34: 75 | S34: 75 | T34: 75 | U34: 75 | V34: 75 | W34: 75 | X34: 75 | Y34: 75 | Z34: 75 | AA34: 75 | AB34: 75 | AC34: 75 | AD34: 75 | AE34: 75 | AF34: 75
A35: Mantsala FI #1 | B35: Energized MW high | C35: stated/unknown | E35: 25 | F35: 25 | G35: 25 | H35: 25 | I35: 25 | J35: 25 | K35: 50 | L35: 75 | M35: 75 | N35: 75 | O35: 75 | P35: 75 | Q35: 75 | R35: 75 | S35: 75 | T35: 75 | U35: 75 | V35: 75 | W35: 75 | X35: 75 | Y35: 75 | Z35: 75 | AA35: 75 | AB35: 75 | AC35: 75 | AD35: 75 | AE35: 75 | AF35: 75
A36: Mantsala FI #1 | B36: Energized MW base (=midpoint) | C36: stated/unknown | E36: =(E34+E35)/2 -> 25 | F36: =(F34+F35)/2 -> 25 | G36: =(G34+G35)/2 -> 25 | H36: =(H34+H35)/2 -> 25 | I36: =(I34+I35)/2 -> 25 | J36: =(J34+J35)/2 -> 25 | K36: =(K34+K35)/2 -> 37.5 | L36: =(L34+L35)/2 -> 62.5 | ... AF36: =(AF34+AF35)/2 -> 75
A37: Mantsala FI #1 | B37: Mgmt figure | C37: as stated | L37: 75
A38: Mantsala FI #2 (Kapuli) | B38: Contracted MW | C38: gross/unknown | N38: 70 | O38: 70 | P38: 70 | Q38: 70 | R38: 70 | S38: 70 | T38: 70 | U38: 70 | V38: 70 | W38: 70 | X38: 70 | Y38: 70 | Z38: 70 | AA38: 70 | AB38: 70 | AC38: 70 | AD38: 70 | AE38: 70 | AF38: 70
A39: Mantsala FI #2 (Kapuli) | B39: Energized MW low | C39: stated/unknown | E39: 0 | F39: 0 | G39: 0 | H39: 0 | I39: 0 | J39: 0 | K39: 0 | L39: 0 | M39: 0 | N39: 0 | O39: 0 | P39: 0 | Q39: 0 | R39: 0 | S39: 0 | T39: 0 | U39: 35 | V39: 70 | W39: 70 | X39: 70 | Y39: 70 | Z39: 70 | AA39: 70 | AB39: 70 | AC39: 70 | AD39: 70 | AE39: 70 | AF39: 70
A40: Mantsala FI #2 (Kapuli) | B40: Energized MW high | C40: stated/unknown | E40: 0 | F40: 0 | G40: 0 | H40: 0 | I40: 0 | J40: 0 | K40: 0 | L40: 0 | M40: 0 | N40: 0 | O40: 0 | P40: 0 | Q40: 0 | R40: 0 | S40: 0 | T40: 35 | U40: 70 | V40: 70 | W40: 70 | X40: 70 | Y40: 70 | Z40: 70 | AA40: 70 | AB40: 70 | AC40: 70 | AD40: 70 | AE40: 70 | AF40: 70
...

Sheet GPUs deployed
A1: Generation | B1: GPUs per IT MW (base) | C1: GPUs per gross MW (base) | D1: Source cell | E1: Tag
A2: Hopper H100/H200 | B2: 713 | C2: 548.5 | D2: GPUsPerMW!I6 / L6 | E2: Estimated
A3: B200 (HGX) | B3: 508.6 | C3: 391.2 | D3: GPUsPerMW!I9 / L9 | E3: Estimated
A4: B300 (HGX) | B4: 501.6 | C4: 385.8 | D4: GPUsPerMW!I15 / L15 | E4: Estimated
A5: GB300 NVL72 | B5: 491.2 | C5: 409.3 | D5: GPUsPerMW!I18 / L18 | E5: Estimated
A6: Vera Rubin NVL72 | B6: 320 | C6: 267 | D6: GPUsPerMW!I21 / L21 | E6: Estimated
A8: RTX PRO 6000 not modeled in gpu_mw_capex.xlsx -> Madrid phase 1 / KC RTX share treated as B300/B200 (Estimated).
A10: Site | B10: Generation | C10: MW basis col | D10: Note | E10: Q1 2024 | F10: Q2 2024 | G10: Q3 2024 | H10: Q4 2024 | I10: Q1 2025 | J10: Q2 2025 | K10: Q3 2025 | L10: Q4 2025 | M10: Q1 2026 | N10: Q2 2026 | O10: Q3 2026 | P10: Q4 2026 | Q10: Q1 2027 | R10: Q2 2027 | S10: Q3 2027 | T10: Q4 2027 | U10: Q1 2028 | V10: Q2 2028 | W10: Q3 2028 | X10: Q4 2028 | Y10: Q1 2029 | Z10: Q2 2029 | AA10: Q3 2029 | AB10: Q4 2029 | AC10: Q1 2030 | AD10: Q2 2030 | AE10: Q3 2030 | AF10: Q4 2030
A11: Vineland NJ (DataOne) | B11: GB300 NVL72 | C11: IT | E11: =ROUND('Quarterly MW'!E6*$B$5,0) -> 0 | F11: =ROUND('Quarterly MW'!F6*$B$5,0) -> 0 | G11: =ROUND('Quarterly MW'!G6*$B$5,0) -> 0 | H11: =ROUND('Quarterly MW'!H6*$B$5,0) -> 0 | I11: =ROUND('Quarterly MW'!I6*$B$5,0) -> 0 | J11: =ROUND('Quarterly MW'!J6*$B$5,0) -> 0 | K11: =ROUND('Quarterly MW'!K6*$B$5,0) -> 0 | L11: =ROUND('Quarterly MW'!L6*$B$5,0) -> 12869 | ... AF11: =ROUND('Quarterly MW'!AF6*$B$5,0) -> 115432
A12: Independence MO (Eastgate) | B12: Vera Rubin NVL72 | C12: gross | E12: =ROUND('Quarterly MW'!E11*$C$6,0) -> 0 | F12: =ROUND('Quarterly MW'!F11*$C$6,0) -> 0 | G12: =ROUND('Quarterly MW'!G11*$C$6,0) -> 0 | H12: =ROUND('Quarterly MW'!H11*$C$6,0) -> 0 | I12: =ROUND('Quarterly MW'!I11*$C$6,0) -> 0 | J12: =ROUND('Quarterly MW'!J11*$C$6,0) -> 0 | K12: =ROUND('Quarterly MW'!K11*$C$6,0) -> 0 | L12: =ROUND('Quarterly MW'!L11*$C$6,0) -> 0 | ... AF12: =ROUND('Quarterly MW'!AF11*$C$6,0) -> 253650
A13: Butler Twp PA (Highridge) | B13: Vera Rubin NVL72 | C13: gross | E13: =ROUND('Quarterly MW'!E16*$C$6,0) -> 0 | F13: =ROUND('Quarterly MW'!F16*$C$6,0) -> 0 | G13: =ROUND('Quarterly MW'!G16*$C$6,0) -> 0 | H13: =ROUND('Quarterly MW'!H16*$C$6,0) -> 0 | I13: =ROUND('Quarterly MW'!I16*$C$6,0) -> 0 | J13: =ROUND('Quarterly MW'!J16*$C$6,0) -> 0 | K13: =ROUND('Quarterly MW'!K16*$C$6,0) -> 0 | L13: =ROUND('Quarterly MW'!L16*$C$6,0) -> 0 | ... AF13: =ROUND('Quarterly MW'!AF16*$C$6,0) -> 248310
A14: Birmingham AL (BHM01, Oxmoor) | B14: Vera Rubin NVL72 | C14: gross | E14: =ROUND('Quarterly MW'!E21*$C$6,0) -> 0 | F14: =ROUND('Quarterly MW'!F21*$C$6,0) -> 0 | G14: =ROUND('Quarterly MW'!G21*$C$6,0) -> 0 | H14: =ROUND('Quarterly MW'!H21*$C$6,0) -> 0 | I14: =ROUND('Quarterly MW'!I21*$C$6,0) -> 0 | J14: =ROUND('Quarterly MW'!J21*$C$6,0) -> 0 | K14: =ROUND('Quarterly MW'!K21*$C$6,0) -> 0 | L14: =ROUND('Quarterly MW'!L21*$C$6,0) -> 0 | ... AF14: =ROUND('Quarterly MW'!AF21*$C$6,0) -> 80100
A15: Bethune FR (Azur Datacenter, ex-Bridgestone) | B15: GB300 NVL72 | C15: gross | E15: =ROUND('Quarterly MW'!E26*$C$5,0) -> 0 | F15: =ROUND('Quarterly MW'!F26*$C$5,0) -> 0 | G15: =ROUND('Quarterly MW'!G26*$C$5,0) -> 0 | H15: =ROUND('Quarterly MW'!H26*$C$5,0) -> 0 | I15: =ROUND('Quarterly MW'!I26*$C$5,0) -> 0 | J15: =ROUND('Quarterly MW'!J26*$C$5,0) -> 0 | K15: =ROUND('Quarterly MW'!K26*$C$5,0) -> 0 | L15: =ROUND('Quarterly MW'!L26*$C$5,0) -> 0 | ... AF15: =ROUND('Quarterly MW'!AF26*$C$5,0) -> 98232
A16: Lappeenranta FI (Pajarila / Polarnode) | B16: Vera Rubin NVL72 | C16: gross | E16: =ROUND('Quarterly MW'!E31*$C$6,0) -> 0 | F16: =ROUND('Quarterly MW'!F31*$C$6,0) -> 0 | G16: =ROUND('Quarterly MW'!G31*$C$6,0) -> 0 | H16: =ROUND('Quarterly MW'!H31*$C$6,0) -> 0 | I16: =ROUND('Quarterly MW'!I31*$C$6,0) -> 0 | J16: =ROUND('Quarterly MW'!J31*$C$6,0) -> 0 | K16: =ROUND('Quarterly MW'!K31*$C$6,0) -> 0 | L16: =ROUND('Quarterly MW'!L31*$C$6,0) -> 0 | ... AF16: =ROUND('Quarterly MW'!AF31*$C$6,0) -> 82770
A17: Mantsala FI #1 | B17: Hopper first 25 MW + GB300 above | C17: gross | E17: =ROUND(MIN('Quarterly MW'!E36,25)*$C$2+MAX('Quarterly MW'!E36-25,0)*$C$5,0) -> 13713 | F17: =ROUND(MIN('Quarterly MW'!F36,25)*$C$2+MAX('Quarterly MW'!F36-25,0)*$C$5,0) -> 13713 | G17: =ROUND(MIN('Quarterly MW'!G36,25)*$C$2+MAX('Quarterly MW'!G36-25,0)*$C$5,0) -> 13713 | H17: =ROUND(MIN('Quarterly MW'!H36,25)*$C$2+MAX('Quarterly MW'!H36-25,0)*$C$5,0) -> 13713 | I17: =ROUND(MIN('Quarterly MW'!I36,25)*$C$2+MAX('Quarterly MW'!I36-25,0)*$C$5,0) -> 13713 | J17: =ROUND(MIN('Quarterly MW'!J36,25)*$C$2+MAX('Quarterly MW'!J36-25,0)*$C$5,0) -> 13713 | K17: =ROUND(MIN('Quarterly MW'!K36,25)*$C$2+MAX('Quarterly MW'!K36-25,0)*$C$5,0) -> 18829 | L17: =ROUND(MIN('Quarterly MW'!L36,25)*$C$2+MAX('Quarterly MW'!L36-25,0)*$C$5,0) -> 29061 | ... AF17: =ROUND(MIN('Quarterly MW'!AF36,25)*$C$2+MAX('Quarterly MW'!AF36-25,0)*$C$5,0) -> 34178
A18: Mantsala FI #2 (Kapuli) | B18: Vera Rubin NVL72 | C18: gross | E18: =ROUND('Quarterly MW'!E41*$C$6,0) -> 0 | F18: =ROUND('Quarterly MW'!F41*$C$6,0) -> 0 | G18: =ROUND('Quarterly MW'!G41*$C$6,0) -> 0 | H18: =ROUND('Quarterly MW'!H41*$C$6,0) -> 0 | I18: =ROUND('Quarterly MW'!I41*$C$6,0) -> 0 | J18: =ROUND('Quarterly MW'!J41*$C$6,0) -> 0 | K18: =ROUND('Quarterly MW'!K41*$C$6,0) -> 0 | L18: =ROUND('Quarterly MW'!L41*$C$6,0) -> 0 | ... AF18: =ROUND('Quarterly MW'!AF41*$C$6,0) -> 18690
A19: Kansas City MO (Patmos) | B19: H200 first 10 MW + B200 above (v2) | C19: gross | E19: =ROUND(MIN('Quarterly MW'!E46,10)*$C$2+MAX('Quarterly MW'!E46-10,0)*$C$3,0) -> 0 | F19: =ROUND(MIN('Quarterly MW'!F46,10)*$C$2+MAX('Quarterly MW'!F46-10,0)*$C$3,0) -> 0 | G19: =ROUND(MIN('Quarterly MW'!G46,10)*$C$2+MAX('Quarterly MW'!G46-10,0)*$C$3,0) -> 0 | H19: =ROUND(MIN('Quarterly MW'!H46,10)*$C$2+MAX('Quarterly MW'!H46-10,0)*$C$3,0) -> 0 | I19: =ROUND(MIN('Quarterly MW'!I46,10)*$C$2+MAX('Quarterly MW'!I46-10,0)*$C$3,0) -> 5485 | J19: =ROUND(MIN('Quarterly MW'!J46,10)*$C$2+MAX('Quarterly MW'!J46-10,0)*$C$3,0) -> 5485 | K19: =ROUND(MIN('Quarterly MW'!K46,10)*$C$2+MAX('Quarterly MW'!K46-10,0)*$C$3,0) -> 5485 | L19: =ROUND(MIN('Quarterly MW'!L46,10)*$C$2+MAX('Quarterly MW'!L46-10,0)*$C$3,0) -> 9397 | ... AF19: =ROUND(MIN('Quarterly MW'!AF46,10)*$C$2+MAX('Quarterly MW'!AF46-10,0)*$C$3,0) -> 13309
A20: Paris (Equinix PA10) | B20: Hopper H100/H200 | C20: gross | E20: =ROUND('Quarterly MW'!E51*$C$2,0) -> 0 | F20: =ROUND('Quarterly MW'!F51*$C$2,0) -> 0 | G20: =ROUND('Quarterly MW'!G51*$C$2,0) -> 0 | H20: =ROUND('Quarterly MW'!H51*$C$2,0) -> 2743 | I20: =ROUND('Quarterly MW'!I51*$C$2,0) -> 2743 | J20: =ROUND('Quarterly MW'!J51*$C$2,0) -> 2743 | K20: =ROUND('Quarterly MW'!K51*$C$2,0) -> 2743 | L20: =ROUND('Quarterly MW'!L51*$C$2,0) -> 2743 | ... AF20: =ROUND('Quarterly MW'!AF51*$C$2,0) -> 2743
A21: Keflavik IS (Verne) | B21: Hopper H100/H200 | C21: gross | E21: =ROUND('Quarterly MW'!E56*$C$2,0) -> 0 | F21: =ROUND('Quarterly MW'!F56*$C$2,0) -> 0 | G21: =ROUND('Quarterly MW'!G56*$C$2,0) -> 0 | H21: =ROUND('Quarterly MW'!H56*$C$2,0) -> 0 | I21: =ROUND('Quarterly MW'!I56*$C$2,0) -> 5485 | J21: =ROUND('Quarterly MW'!J56*$C$2,0) -> 5485 | K21: =ROUND('Quarterly MW'!K56*$C$2,0) -> 5485 | L21: =ROUND('Quarterly MW'!L56*$C$2,0) -> 5485 | ... AF21: =ROUND('Quarterly MW'!AF56*$C$2,0) -> 5485
A22: London Longcross (Ark LP01) | B22: B300 (HGX) | C22: gross | E22: =ROUND('Quarterly MW'!E61*$C$4,0) -> 0 | F22: =ROUND('Quarterly MW'!F61*$C$4,0) -> 0 | G22: =ROUND('Quarterly MW'!G61*$C$4,0) -> 0 | H22: =ROUND('Quarterly MW'!H61*$C$4,0) -> 0 | I22: =ROUND('Quarterly MW'!I61*$C$4,0) -> 0 | J22: =ROUND('Quarterly MW'!J61*$C$4,0) -> 0 | K22: =ROUND('Quarterly MW'!K61*$C$4,0) -> 0 | L22: =ROUND('Quarterly MW'!L61*$C$4,0) -> 6173 | ... AF22: =ROUND('Quarterly MW'!AF61*$C$4,0) -> 7330
A23: Harlow UK (Kao Data KLON-02/03) | B23: B300 (HGX) | C23: gross | E23: =ROUND('Quarterly MW'!E66*$C$4,0) -> 0 | F23: =ROUND('Quarterly MW'!F66*$C$4,0) -> 0 | G23: =ROUND('Quarterly MW'!G66*$C$4,0) -> 0 | H23: =ROUND('Quarterly MW'!H66*$C$4,0) -> 0 | I23: =ROUND('Quarterly MW'!I66*$C$4,0) -> 0 | J23: =ROUND('Quarterly MW'!J66*$C$4,0) -> 0 | K23: =ROUND('Quarterly MW'!K66*$C$4,0) -> 0 | L23: =ROUND('Quarterly MW'!L66*$C$4,0) -> 0 | ... AF23: =ROUND('Quarterly MW'!AF66*$C$4,0) -> 8488
A24: Newport UK (Vantage CWL1) | B24: GB300 NVL72 | C24: gross | E24: =ROUND('Quarterly MW'!E71*$C$5,0) -> 0 | F24: =ROUND('Quarterly MW'!F71*$C$5,0) -> 0 | G24: =ROUND('Quarterly MW'!G71*$C$5,0) -> 0 | H24: =ROUND('Quarterly MW'!H71*$C$5,0) -> 0 | I24: =ROUND('Quarterly MW'!I71*$C$5,0) -> 0 | J24: =ROUND('Quarterly MW'!J71*$C$5,0) -> 0 | K24: =ROUND('Quarterly MW'!K71*$C$5,0) -> 0 | L24: =ROUND('Quarterly MW'!L71*$C$5,0) -> 0 | ... AF24: =ROUND('Quarterly MW'!AF71*$C$5,0) -> 12893
A25: UK 3rd new deployment (lead: Green Mountain LON-East, Romford) | B25: GB300 NVL72 | C25: gross | E25: =ROUND('Quarterly MW'!E76*$C$5,0) -> 0 | F25: =ROUND('Quarterly MW'!F76*$C$5,0) -> 0 | G25: =ROUND('Quarterly MW'!G76*$C$5,0) -> 0 | H25: =ROUND('Quarterly MW'!H76*$C$5,0) -> 0 | I25: =ROUND('Quarterly MW'!I76*$C$5,0) -> 0 | J25: =ROUND('Quarterly MW'!J76*$C$5,0) -> 0 | K25: =ROUND('Quarterly MW'!K76*$C$5,0) -> 0 | L25: =ROUND('Quarterly MW'!L76*$C$5,0) -> 0 | ... AF25: =ROUND('Quarterly MW'!AF76*$C$5,0) -> 2865
A26: Modi'in IL (Mega Or) | B26: B200 (HGX) | C26: IT | E26: =ROUND('Quarterly MW'!E81*$B$3,0) -> 0 | F26: =ROUND('Quarterly MW'!F81*$B$3,0) -> 0 | G26: =ROUND('Quarterly MW'!G81*$B$3,0) -> 0 | H26: =ROUND('Quarterly MW'!H81*$B$3,0) -> 0 | I26: =ROUND('Quarterly MW'!I81*$B$3,0) -> 0 | J26: =ROUND('Quarterly MW'!J81*$B$3,0) -> 0 | K26: =ROUND('Quarterly MW'!K81*$B$3,0) -> 0 | L26: =ROUND('Quarterly MW'!L81*$B$3,0) -> 4069 | ... AF26: =ROUND('Quarterly MW'!AF81*$B$3,0) -> 4069
A27: Masmiyya IL (Mega DC) | B27: GB300 NVL72 | C27: gross | E27: =ROUND('Quarterly MW'!E86*$C$5,0) -> 0 | F27: =ROUND('Quarterly MW'!F86*$C$5,0) -> 0 | G27: =ROUND('Quarterly MW'!G86*$C$5,0) -> 0 | H27: =ROUND('Quarterly MW'!H86*$C$5,0) -> 0 | I27: =ROUND('Quarterly MW'!I86*$C$5,0) -> 0 | J27: =ROUND('Quarterly MW'!J86*$C$5,0) -> 0 | K27: =ROUND('Quarterly MW'!K86*$C$5,0) -> 0 | L27: =ROUND('Quarterly MW'!L86*$C$5,0) -> 0 | ... AF27: =ROUND('Quarterly MW'!AF86*$C$5,0) -> 9005
A28: Beit Shemesh IL (Mega DC) | B28: GB300 NVL72 | C28: gross | E28: =ROUND('Quarterly MW'!E91*$C$5,0) -> 0 | F28: =ROUND('Quarterly MW'!F91*$C$5,0) -> 0 | G28: =ROUND('Quarterly MW'!G91*$C$5,0) -> 0 | H28: =ROUND('Quarterly MW'!H91*$C$5,0) -> 0 | I28: =ROUND('Quarterly MW'!I91*$C$5,0) -> 0 | J28: =ROUND('Quarterly MW'!J91*$C$5,0) -> 0 | K28: =ROUND('Quarterly MW'!K91*$C$5,0) -> 0 | L28: =ROUND('Quarterly MW'!L91*$C$5,0) -> 0 | ... AF28: =ROUND('Quarterly MW'!AF91*$C$5,0) -> 23739
A29: Madrid-Getafe ES (Merlin Edged) | B29: B300 (HGX) | C29: gross | E29: =ROUND('Quarterly MW'!E96*$C$4,0) -> 0 | F29: =ROUND('Quarterly MW'!F96*$C$4,0) -> 0 | G29: =ROUND('Quarterly MW'!G96*$C$4,0) -> 0 | H29: =ROUND('Quarterly MW'!H96*$C$4,0) -> 0 | I29: =ROUND('Quarterly MW'!I96*$C$4,0) -> 0 | J29: =ROUND('Quarterly MW'!J96*$C$4,0) -> 0 | K29: =ROUND('Quarterly MW'!K96*$C$4,0) -> 0 | L29: =ROUND('Quarterly MW'!L96*$C$4,0) -> 0 | ... AF29: =ROUND('Quarterly MW'!AF96*$C$4,0) -> 6944
A30: Tallinn EE (Greenergy Huuru) | B30: GB300 NVL72 | C30: gross | E30: =ROUND('Quarterly MW'!E101*$C$5,0) -> 0 | F30: =ROUND('Quarterly MW'!F101*$C$5,0) -> 0 | G30: =ROUND('Quarterly MW'!G101*$C$5,0) -> 0 | H30: =ROUND('Quarterly MW'!H101*$C$5,0) -> 0 | I30: =ROUND('Quarterly MW'!I101*$C$5,0) -> 0 | J30: =ROUND('Quarterly MW'!J101*$C$5,0) -> 0 | K30: =ROUND('Quarterly MW'!K101*$C$5,0) -> 0 | L30: =ROUND('Quarterly MW'!L101*$C$5,0) -> 0 | ... AF30: =ROUND('Quarterly MW'!AF101*$C$5,0) -> 9005
A31: Minnesota colo (us-north1, Woodbury) | B31: B300 (HGX) | C31: gross | E31: =ROUND('Quarterly MW'!E106*$C$4,0) -> 0 | F31: =ROUND('Quarterly MW'!F106*$C$4,0) -> 0 | G31: =ROUND('Quarterly MW'!G106*$C$4,0) -> 0 | H31: =ROUND('Quarterly MW'!H106*$C$4,0) -> 0 | I31: =ROUND('Quarterly MW'!I106*$C$4,0) -> 0 | J31: =ROUND('Quarterly MW'!J106*$C$4,0) -> 0 | K31: =ROUND('Quarterly MW'!K106*$C$4,0) -> 0 | L31: =ROUND('Quarterly MW'!L106*$C$4,0) -> 0 | ... AF31: =ROUND('Quarterly MW'!AF106*$C$4,0) -> 3858
A32: Oklahoma colo (unnamed) | B32: GB300 NVL72 | C32: gross | E32: =ROUND('Quarterly MW'!E111*$C$5,0) -> 0 | F32: =ROUND('Quarterly MW'!F111*$C$5,0) -> 0 | G32: =ROUND('Quarterly MW'!G111*$C$5,0) -> 0 | H32: =ROUND('Quarterly MW'!H111*$C$5,0) -> 0 | I32: =ROUND('Quarterly MW'!I111*$C$5,0) -> 0 | J32: =ROUND('Quarterly MW'!J111*$C$5,0) -> 0 | K32: =ROUND('Quarterly MW'!K111*$C$5,0) -> 0 | L32: =ROUND('Quarterly MW'!L111*$C$5,0) -> 0 | ... AF32: =ROUND('Quarterly MW'!AF111*$C$5,0) -> 40930
A33: AIB CLT1 (Moore, Spartanburg County SC; Lockhart Power) | B33: Vera Rubin NVL72 | C33: IT | E33: =ROUND('Quarterly MW'!E121*$B$6,0) -> 0 | F33: =ROUND('Quarterly MW'!F121*$B$6,0) -> 0 | G33: =ROUND('Quarterly MW'!G121*$B$6,0) -> 0 | H33: =ROUND('Quarterly MW'!H121*$B$6,0) -> 0 | I33: =ROUND('Quarterly MW'!I121*$B$6,0) -> 0 | J33: =ROUND('Quarterly MW'!J121*$B$6,0) -> 0 | K33: =ROUND('Quarterly MW'!K121*$B$6,0) -> 0 | L33: =ROUND('Quarterly MW'!L121*$B$6,0) -> 0 | ... AF33: =ROUND('Quarterly MW'!AF121*$B$6,0) -> 16000
A34: TOTAL modeled GPUs (identified sites) | E34: =SUM(E11:E33) -> 13713 | F34: =SUM(F11:F33) -> 13713 | G34: =SUM(G11:G33) -> 13713 | H34: =SUM(H11:H33) -> 16456 | I34: =SUM(I11:I33) -> 27426 | J34: =SUM(J11:J33) -> 27426 | K34: =SUM(K11:K33) -> 32542 | L34: =SUM(L11:L33) -> 69797 | ... AF34: =SUM(AF11:AF33) -> 1098025
A35: Reported GPU counts (company) | D35: GPU counts have run AHEAD of powered MW (delivered-not-powered); do not back MW out of them | G35: 10000 | H35: 20000 | I35: 30000
A36: Reported site GPU counts | D36: Modi'in 4,000 HGX B200 (Oct 2025); Longcross 4,000 B300 phase 1 (+3,000 phase 2, timing n/d); Mantsala 'up to 60,000' = potential, not deployed | L36: =4000+4000 -> 8000

Sheet GPU vintage
A1: Site | B1: Row type | C1: Generation (assumed) | D1: Note | E1: Q1 2024 | F1: Q2 2024 | G1: Q3 2024 | H1: Q4 2024 | I1: Q1 2025 | J1: Q2 2025 | K1: Q3 2025 | L1: Q4 2025 | M1: Q1 2026 | N1: Q2 2026 | O1: Q3 2026 | P1: Q4 2026 | Q1: Q1 2027 | R1: Q2 2027 | S1: Q3 2027 | T1: Q4 2027 | U1: Q1 2028 | V1: Q2 2028 | W1: Q3 2028 | X1: Q4 2028 | Y1: Q1 2029 | Z1: Q2 2029 | AA1: Q3 2029 | AB1: Q4 2029 | AC1: Q1 2030 | AD1: Q2 2030 | AE1: Q3 2030 | AF1: Q4 2030
