Workbook

Sheet README
A1: price_or_mw.xlsx - Nebius Peer KPIs - PRICE-OR-MW TEST - built 2026-10-05 ET; CORRECTED 2026-10-05 (YE26 high ÷ 284.2); RE-BASED 2026-10-08 ~10:00 ET to model v0.9e locks (patch_price_or_mw.py). Recalc: 0 errors.
A3: QUESTION: FY27 consensus (or mgmt run-rate) ÷ average billed IT MW → implied $/billed IT MW. Do peers land at ~$13-18M (Nebius Street ~$26M = unsupported premium) or are peers just as rich?
A5: NEBIUS BENCHMARK (model v0.9e): Street FY27 $12.3B (S1) / FY27 avg billed IT MW 531.84 (model/nebius_model.xlsx Drivers!B34) = ~$23.1M blended (memo). PEER COMPARATOR = ex-Microsoft ~$27.6M (($12.3B - $2,643.8M) / (531.84 - 182.33)). High path 659.16: $18.7M blended. YE26 ARR guide $7-9B / YE26 billing 258-284 MW = $25-35M.
A7: HEADLINE RESULT: Peers land in ~$11-16M on base paths - NOT as rich as Nebius Street ex-Microsoft (~$27.6M). Confidence MEDIUM.
A8: CoreWeave: $26.26B / ~2,325 avg active MW (E) ≈ $11.3M (range ~$9.5-13.5 across MW paths).
A9: IREN: YE26 ARR $4B / 300 IT MW = $13.3M (R/R); FY27 ARR-path proxy ≈ $14-18M (E).
A10: Oracle: FQ1 Cloud Infra annualized $29.6B / ~2,050 cum. delivered MW ≈ $14.4M (D/E; AI/non-AI and gross-MW caveats).
A12: Microsoft-Nebius: $14.49M per IT MW [E, house] = model Contracts!E12 only (ruling Oct 9 2026; Nebius_Check rows 16-24). Earlier 11.6 (300 MW site size) / 17.1 (GPU-derived) readings are superseded - history only (Nebius_Check row 25).
A13: K02b: Comparison.xlsx now has K02 (energized avg MW) AND K02b (billed IT avg MW) so the slide can show both.
A15: TABS: Implied_Price (headline + verdict) | MW_Paths | Revenue_Sources | Nebius_Check | Sources | README.
A16: TAGS: R reported; P press/secondary; D derived; E estimated; n-d not disclosed. Blue = hard-coded input.
A17: CORRECTION / BASIS: All Nebius $/MW in this pack are on BILLED IT MW (K02b basis). YE26 guide: low=$7B/MW_Paths!E9(257.7); high=$9B/MW_Paths!E10(284.2 Judge_Slide B35 / Capacity HIGH billing). Street FY27 uses model v0.9e FY27 avg billed IT MW 531.8 (Drivers B34; MW_Paths row 31), not energized.
... A21: 2026-10-08 PM: CONTRACT COMP BAND (separate metric: TCV / term / MW, not revenue per billed MW): $9.7-16.7M per MW-yr - low IREN-Microsoft $9.7M; top Lambda-Anthropic ~$16.7M ($35B / 6-yr / ~350 MW; press inputs, IT vs gross unstated; Medium confidence) - comparison.xlsx Contracts_$MWyr NEW2 (2026-10-08; was $9.7-16.2M, Nscale-Anthropic top).

Sheet Implied_Price
A1: PRICE-OR-MW TEST: FY27 revenue (or run-rate guide) ÷ average billed IT MW → implied $M per billed IT MW-yr. Compare peers to Nebius Street EX-MICROSOFT ~$27.6M (blended Street ~$23.1M on model v0.9e 531.8 MW is memo).
A2: Question: do peers land at ~$13-18M (Nebius alone at an unsupported premium) or are peers just as rich?
A4: Company | B4: Revenue $M | C4: Rev tag | D4: Avg billed IT MW | E4: MW tag | F4: Implied $M/MW | G4: vs Nebius Street ex-MSFT (~$27.6M) | H4: Premium/(discount) | I4: Verdict vs $13-18 band | J4: Notes
A5: Nebius STREET blended (consensus / FY27 avg billed, model v0.9e) | B5: =Revenue_Sources!C4 -> 12300 | C5: E | D5: =MW_Paths!J31 -> 531.84098 | E5: D | F5: =B5/D5 -> 23.127214 | G5: =F5-Nebius_Check!$B$37 -> -4.5005442 | H5: =F5/Nebius_Check!$B$37-1 -> -0.16289936 | I5: =IF(AND(F5>=13,F5<=18),"IN $13-18 band",IF(F5>18,"ABOVE (rich like/above Nebius Street)","BELOW $13-18")) -> ABOVE (rich like/above Nebius Street) | J5: MEMO (blended, incl. Microsoft $14.5M anchor): $12.3B / 531.84 (model/nebius_model.xlsx Drivers!B34) = ~$23.1M. Use row 18 (ex-MSFT) against peers.
A6: Nebius YE26 ARR guide / YE26 billing (low) | B6: =Revenue_Sources!C5 -> 7000 | C6: R | D6: =MW_Paths!E9 -> 257.7 | E6: E | F6: =B6/D6 -> 27.163368 | G6: =F6-Nebius_Check!$B$37 -> -0.46438964 | H6: =F6/Nebius_Check!$B$37-1 -> -0.016808807 | I6: =IF(AND(F6>=13,F6<=18),"IN $13-18 band",IF(F6>18,"ABOVE (rich like/above Nebius Street)","BELOW $13-18")) -> ABOVE (rich like/above Nebius Street) | J6: Guide test: $7B / YE26 BASE billing ~257.7 (Capacity Q4'26 Billing MW IT base = MW_Paths!E9)
A7: Nebius YE26 ARR guide / YE26 billing (high) | B7: =Revenue_Sources!C6 -> 9000 | C7: R | D7: =MW_Paths!E10 -> 284.2 | E7: E | F7: =B7/D7 -> 31.66784 | G7: =F7-Nebius_Check!$B$37 -> 4.0400817 | H7: =F7/Nebius_Check!$B$37-1 -> 0.1462327 | I7: =IF(AND(F7>=13,F7<=18),"IN $13-18 band",IF(F7>18,"ABOVE (rich like/above Nebius Street)","BELOW $13-18")) -> ABOVE (rich like/above Nebius Street) | J7: CORRECTION 2026-10-05: $9B / YE26 HIGH billing 284.2 (Judge_Slide B35) → ~$31.7M (in $25-32 Judge band). Was wrongly =E9 (257.7) → $34.9.
A8: CoreWeave STREET / BASE MW path | B8: =Revenue_Sources!C7 -> 26260 | C8: E | D8: =MW_Paths!G13 -> 2325 | E8: E | F8: =B8/D8 -> 11.294624 | G8: =F8-Nebius_Check!$B$37 -> -16.333134 | H8: =F8/Nebius_Check!$B$37-1 -> -0.59118566 | I8: =IF(AND(F8>=13,F8<=18),"IN $13-18 band",IF(F8>18,"ABOVE (rich like/above Nebius Street)","BELOW $13-18")) -> BELOW $13-18 | J8: Active power path YE26 1.85 GW P → YE27 2.8 GW E; avg 2.325 GW
A9: CoreWeave STREET / LOW MW path | B9: =Revenue_Sources!C7 -> 26260 | C9: E | D9: =MW_Paths!G14 -> 1950 | E9: E | F9: =B9/D9 -> 13.466667 | G9: =F9-Nebius_Check!$B$37 -> -14.161091 | H9: =F9/Nebius_Check!$B$37-1 -> -0.51256752 | I9: =IF(AND(F9>=13,F9<=18),"IN $13-18 band",IF(F9>18,"ABOVE (rich like/above Nebius Street)","BELOW $13-18")) -> IN $13-18 band | J9: YE26 1.7 GW R (Q1 guide) → YE27 2.2 GW E
A10: CoreWeave STREET / HIGH MW path | B10: =Revenue_Sources!C7 -> 26260 | C10: E | D10: =MW_Paths!G15 -> 2750 | E10: E | F10: =B10/D10 -> 9.5490909 | G10: =F10-Nebius_Check!$B$37 -> -18.078667 | H10: =F10/Nebius_Check!$B$37-1 -> -0.65436606 | I10: =IF(AND(F10>=13,F10<=18),"IN $13-18 band",IF(F10>18,"ABOVE (rich like/above Nebius Street)","BELOW $13-18")) -> BELOW $13-18 | J10: Faster MW → lower $/MW
A11: CoreWeave YE27 ARR guide $30B / BASE YE27 EoP MW | B11: =Revenue_Sources!C9 -> 30000 | C11: R | D11: =MW_Paths!F13 -> 2800 | E11: E | F11: =B11/D11 -> 10.714286 | G11: =F11-Nebius_Check!$B$37 -> -16.913472 | H11: =F11/Nebius_Check!$B$37-1 -> -0.61219127 | I11: =IF(AND(F11>=13,F11<=18),"IN $13-18 band",IF(F11>18,"ABOVE (rich like/above Nebius Street)","BELOW $13-18")) -> BELOW $13-18 | J11: Exit run-rate test (not FY27 average revenue)
A12: IREN YE26 ARR $4B / YE26 300 IT MW | B12: =Revenue_Sources!C10 -> 4000 | C12: R | D12: =MW_Paths!C20 -> 300 | E12: R | F12: =B12/D12 -> 13.333333 | G12: =F12-Nebius_Check!$B$37 -> -14.294425 | H12: =F12/Nebius_Check!$B$37-1 -> -0.51739358 | I12: =IF(AND(F12>=13,F12<=18),"IN $13-18 band",IF(F12>18,"ABOVE (rich like/above Nebius Street)","BELOW $13-18")) -> IN $13-18 band | J12: Cleanest IREN like-for-like: mgmt ARR / mgmt IT MW target
A13: IREN YE27 ARR at $20M pricing / YE27 800 IT MW | B13: =Revenue_Sources!C13 -> 16000 | C13: E | D13: =MW_Paths!D20 -> 800 | E13: R | F13: =B13/D13 -> 20 | G13: =F13-Nebius_Check!$B$37 -> -7.6277579 | H13: =F13/Nebius_Check!$B$37-1 -> -0.27609037 | I13: =IF(AND(F13>=13,F13<=18),"IN $13-18 band",IF(F13>18,"ABOVE (rich like/above Nebius Street)","BELOW $13-18")) -> ABOVE (rich like/above Nebius Street) | J13: Uses IREN's own >$20M/IT MW 3-yr pricing on full YE27 capacity
A14: IREN YE27 ARR at YE26 $/MW / YE27 800 IT MW | B14: =Revenue_Sources!C14 -> 10667 | C14: E | D14: =MW_Paths!D20 -> 800 | E14: R | F14: =B14/D14 -> 13.33375 | G14: =F14-Nebius_Check!$B$37 -> -14.294008 | H14: =F14/Nebius_Check!$B$37-1 -> -0.5173785 | I14: =IF(AND(F14>=13,F14<=18),"IN $13-18 band",IF(F14>18,"ABOVE (rich like/above Nebius Street)","BELOW $13-18")) -> IN $13-18 band | J14: Same unit price as YE26 ARR/MW
A15: IREN FY27 recognized (avg of YE26 ARR & YE27@$20M) / avg MW | B15: =(Revenue_Sources!C10+Revenue_Sources!C13)/2 -> 10000 | C15: E | D15: =MW_Paths!E20 -> 550 | E15: D | F15: =B15/D15 -> 18.181818 | G15: =F15-Nebius_Check!$B$37 -> -9.4459397 | H15: =F15/Nebius_Check!$B$37-1 -> -0.34190034 | I15: =IF(AND(F15>=13,F15<=18),"IN $13-18 band",IF(F15>18,"ABOVE (rich like/above Nebius Street)","BELOW $13-18")) -> ABOVE (rich like/above Nebius Street) | J15: Proxy for calendar-2027 recognized AI revenue; no Street AI-only consensus on box
A16: Oracle FQ1'27 Cloud Infra annualized / cum. AI MW at Aug-26 | B16: =Revenue_Sources!C16 -> 29552 | C16: D | D16: =MW_Paths!C25 -> 2050 | E16: E | F16: =B16/D16 -> 14.41561 | G16: =F16-Nebius_Check!$B$37 -> -13.212148 | H16: =F16/Nebius_Check!$B$37-1 -> -0.47822006 | I16: =IF(AND(F16>=13,F16<=18),"IN $13-18 band",IF(F16>18,"ABOVE (rich like/above Nebius Street)","BELOW $13-18")) -> IN $13-18 band | J16: Numerator includes non-AI OCI; denominator = cumulative delivered since Jun-25 (not stock), likely gross MW
A17: Oracle FQ1'27 annualized / FY27 avg cum. delivered (BASE) | B17: =Revenue_Sources!C16 -> 29552 | C17: D | D17: =MW_Paths!E25 -> 3275 | E17: E | F17: =B17/D17 -> 9.0235115 | G17: =F17-Nebius_Check!$B$37 -> -18.604246 | H17: =F17/Nebius_Check!$B$37-1 -> -0.67338966 | I17: =IF(AND(F17>=13,F17<=18),"IN $13-18 band",IF(F17>18,"ABOVE (rich like/above Nebius Street)","BELOW $13-18")) -> BELOW $13-18 | J17: Same numerator on growing delivered base → lower $/MW; still conflates AI vs non-AI
A18: Nebius STREET NON-MICROSOFT (peer comparator) | B18: =Revenue_Sources!C20 -> 9656.2264 | C18: E/D | D18: =MW_Paths!J35 -> 349.51176 | E18: D | F18: =B18/D18 -> 27.627758 | G18: =F18-Nebius_Check!$B$37 -> 0 | H18: =F18/Nebius_Check!$B$37-1 -> 0 | I18: =IF(AND(F18>=13,F18<=18),"IN $13-18 band",IF(F18>18,"ABOVE (rich like/above Nebius Street)","BELOW $13-18")) -> ABOVE (rich like/above Nebius Street) | J18: THE PEER BENCHMARK (model v0.9e): ($12.3B - $2.6438B Microsoft) / (531.8 - 182.3 Vineland billed MW-yr) = ~$27.6M (= Drivers B9). Peers' $/MW has no $14.5M Microsoft anchor.
A19: SENSITIVITY - CoreWeave $/MW across MW and revenue
B20: MW LOW 1,950 | C20: MW BASE 2,325 | D20: MW HIGH 2,750 | E20: MW at $8.24 ARR ($30B→3,640)
A21: Rev $26.26B (Street) | B21: =Revenue_Sources!C7/1950 -> 13.466667 | C21: =Revenue_Sources!C7/2325 -> 11.294624 | D21: =Revenue_Sources!C7/2750 -> 9.5490909 | E21: =Revenue_Sources!C7/(Revenue_Sources!C9/8.24) -> 7.2127467
A22: Rev $28.0B (later aggregator) | B22: =28000/1950 -> 14.358974 | C22: =28000/2325 -> 12.043011 | D22: =28000/2750 -> 10.181818 | E22: =28000/(Revenue_Sources!C9/8.24) -> 7.6906667
A23: YE27 ARR $30B as if FY27 rev | B23: =Revenue_Sources!C9/1950 -> 15.384615 | C23: =Revenue_Sources!C9/2325 -> 12.903226 | D23: =Revenue_Sources!C9/2750 -> 10.909091 | E23: =Revenue_Sources!C9/(Revenue_Sources!C9/8.24) -> 8.24
A24: Nebius STREET blended / FY27 avg billed HIGH (model v0.9e) | B24: =Revenue_Sources!C4 -> 12300 | C24: E | D24: =MW_Paths!J32 -> 659.157 | E24: D | F24: =B24/D24 -> 18.660198 | G24: =F24-Nebius_Check!$B$37 -> -8.9675602 | H24: =F24/Nebius_Check!$B$37-1 -> -0.32458516 | I24: =IF(AND(F24>=13,F24<=18),"IN $13-18 band",IF(F24>18,"ABOVE (rich like/above Nebius Street)","BELOW $13-18")) -> ABOVE (rich like/above Nebius Street) | J24: High path: $12.3B / 659.16 (model/nebius_model.xlsx Drivers!C34). Ex-MSFT high = Nebius_Check B41.
A25: HEADLINE TABLE (ready to DM)
A26: Company | B26: FY27 rev $B | C26: Avg billed IT MW | D26: Implied $/MW | E26: Tag | F26: vs Nebius ex-MSFT ~$27.6M
A27: Nebius Street (blended memo) | B27: =B5/1000 -> 12.3 | C27: =D5 -> 531.84098 | D27: =F5 -> 23.127214 | E27: E (cons) / D/E (MW) | F27: =D27-Nebius_Check!$B$37 -> -4.5005442
A28: CoreWeave | B28: =B8/1000 -> 26.26 | C28: =D8 -> 2325 | D28: =F8 -> 11.294624 | E28: E / E | F28: =D28-Nebius_Check!$B$37 -> -16.333134
A29: IREN (ARR path) | B29: =B15/1000 -> 10 | C29: =D15 -> 550 | D29: =F15 -> 18.181818 | E29: E / D | F29: =D29-Nebius_Check!$B$37 -> -9.4459397
A30: IREN (YE26 ARR/MW) | B30: =B12/1000 -> 4 | C30: =D12 -> 300 | D30: =F12 -> 13.333333 | E30: R / R | F30: =D30-Nebius_Check!$B$37 -> -14.294425
A31: Oracle OCI (run-rate / cum MW) | B31: =B16/1000 -> 29.552 | C31: =D16 -> 2050 | D31: =F16 -> 14.41561 | E31: D / E | F31: =D31-Nebius_Check!$B$37 -> -13.212148
A32: Nebius Street ex-MSFT (PEER BENCHMARK) | B32: =B18/1000 -> 9.6562264 | C32: =D18 -> 349.51176 | D32: =F18 -> 27.627758 | E32: E/D / D | F32: =D32-Nebius_Check!$B$37 -> 0
A33: VERDICT
A34: Peers come out in the ~$11-16M per billed IT MW band on base paths. The like-for-like Nebius figure is Street EX-MICROSOFT ~$27.6M (($12.3B - $2.64B) / (531.8 - 182.3) billed IT MW, model v0.9e) - ~1.7-2.4x the peer band. Blended Street is ~$23.1M (memo; pulled down by the $14.5M Microsoft anchor). CoreWeave Street / base MW ≈ $11-13M; IREN YE26 ARR/IT MW = $13.3M (R/R) and FY27 ARR-path proxy ≈ $14-18M; Oracle ≈ $14M (AI/non-AI and gross-MW caveats). High path: $12.3B / 659.2 = $18.7M blended, ex-MSFT $20.3M. At $16M comps the Street needs 769 MW = 1.45x base / 1.17x high. YE26 Nebius guide ($7-9B / ~258-284 billing MW) implies $25-35M. Confidence MEDIUM: CoreWeave YE27 MW Estimated; IREN lacks AI GAAP consensus; Oracle perimeter impure; Vineland MW per tranche is E. CONTRACT COMP BAND (separate metric: TCV / term / MW, not revenue per billed MW): $9.7-16.7M per MW-yr - low IREN-Microsoft $9.7M; top Lambda-Anthropic ~$16.7M ($35B / 6-yr / ~350 MW; press inputs, IT vs gross unstated; Medium confidence) - comparison.xlsx Contracts_$MWyr NEW2 (2026-10-08; was $9.7-16.2M, Nscale-Anthropic top). The $13-18 band in col I is this test's slide hypothesis band for revenue per billed MW, not the contract band.

Sheet MW_Paths
A1: Billed / active IT MW paths. Prefer billed/billing over installed. Blue = input. CoreWeave 'active power' ≈ billed. Oracle = cumulative AI capacity delivered (not a clean billed-IT stock).
A3: NEBIUS - Capacity Billing MW (IT) base row + model lag method
A4: Item | B4: Q1'26 | C4: Q2'26 | D4: Q3'26 | E4: Q4'26 | F4: Q1'27 | G4: Q2'27 | H4: Q3'27 | I4: Q4'27 | J4: FY27 avg | K4: Tag | L4: Source
A5: Capacity 'Billing MW (IT) - base' quarter-end | B5: 165.5 | C5: 186.8 | D5: 250.2 | E5: 257.7 | F5: 326.6 | G5: 495.3 | H5: 701 | I5: 852.6 | J5: =AVERAGE(F5:I5) -> 593.875 | K5: E | L5: S2 row 147
A6: MODEL billing IT MW (nebius_model KPIs 'BILLING IT MW'; quarter averages) - HISTORY ONLY (v0.9d energized-lag path; not used - see row 31) | F6: 255.1 | G6: 375.63 | H6: 541.66 | I6: 721.07 | J6: =AVERAGE(F6:I6) -> 473.365 | K6: D | L6: HISTORY ONLY (v0.9d model KPIs row BILLING, energized-lag); not used since Oct 8; Q4'26 open=212.74
A7: SENSITIVITY: Capacity energized IT base lagged 1q, qtr avg (NOT Street denom) | F7: 223.23 | G7: 330.66 | H7: 478.91 | I7: 674.04 | J7: =AVERAGE(F7:I7) -> 426.71 | K7: D/E
A8: SENSITIVITY: Capacity energized IT high lagged 1q, qtr avg | F8: 532.29 | G8: 752.68 | H8: 963.24 | I8: 1220.5 | J8: =AVERAGE(F8:I8) -> 867.1775 | K8: D/E
A9: YE26 billing IT MW (Capacity base Q4'26) | E9: 257.7 | K9: E | L9: S2
A10: YE26 billing IT MW (Capacity HIGH / Judge_Slide B35) | E10: 284.2 | K10: D/E | L10: Judge_Slide B35 = 284.2; Capacity v2 high energized IT lagged 1q to billing (Vineland billed tranches). See Judge_Slide A29/A35; owned_campus_power_path.md High ~284. [Sources S14]
A11: COREWEAVE - active power (company metric; ≈ billed / revenue-generating)
A12: Item | B12: YE25 | C12: Q1'26 | D12: Q2'26 | E12: YE26E | F12: YE27E | G12: FY27 avg (linear) | H12: Tag | I12: Source / method
A13: BASE path | B13: 850 | C13: 1000 | D13: 1500 | E13: 1850 | F13: 2800 | G13: =(E13+F13)/2 -> 2325 | H13: R/P/E | I13: YE25/Q1/Q2 R (S5); YE26 1850 P (Q2 call coverage; Q1 guide was 1700 R); YE27 2800 E (interp: contracted 4.2 GW x ~67% active by YE27, between 1.85 and NVIDIA 5GW multi-year)
A14: LOW path (slower YE27 conversion) | B14: 850 | C14: 1000 | D14: 1500 | E14: 1700 | F14: 2200 | G14: =(E14+F14)/2 -> 1950 | H14: R/E | I14: YE26 = Q1 guide 1.7 GW R; YE27 2.2 GW E (modest add)
A15: HIGH path | B15: 850 | C15: 1000 | D15: 1500 | E15: 2000 | F15: 3500 | G15: =(E15+F15)/2 -> 2750 | H15: E | I15: YE26 2.0 GW E; YE27 3.5 GW E (faster toward 5GW NVIDIA buildout)
A16: Memo: YE27 MW if YE27 ARR $30B at Q2'26 rev/avg MW $8.24 | F16: =Revenue_Sources!C9/8.24 -> 3640.7767 | H16: E | I16: Implies ~3,640 MW if unit revenue stays at Q2'26 diluted level - upper bound on MW / lower bound on $/MW
A18: IREN AI Cloud - IT MW cumulative delivery targets (company; billed ≈ delivered after acceptance lag)
A19: Item | B19: Jun-26 reported | C19: YE26 target | D19: YE27 target | E19: FY27 avg (linear YE26→YE27) | F19: Tag | G19: Source
A20: IT MW (company target) | B20: 40 | C20: 300 | D20: 800 | E20: =(C20+D20)/2 -> 550 | F20: R/D | G20: S7: 0.3 GW IT 2026 / 0.8 GW IT 2027; Jun-26 ~40 MW operating (R, basis unstated)
A21: Gross MW (company target, memo) | B21: n-d | C21: 480 | D21: 1200 | E21: =(C21+D21)/2 -> 840 | F21: R/D | G21: S7 Jul-20: 480 MW gross YE26 / 1.2 GW gross YE27
A23: ORACLE - cumulative AI capacity DELIVERED (not billed-IT stock; MW basis unlabeled, likely gross)
A24: Item | B24: FQ4'26 (May) | C24: FQ1'27 (Aug) | D24: FY27E EoP (May'27) | E24: FY27 avg (linear) | F24: Tag | G24: Source
A25: Cumulative AI MW delivered since Jun-2025 (BASE) | B25: 1200 | C25: 2050 | D25: 4500 | E25: =(C25+D25)/2 -> 3275 | F25: E | G25: S11: 1200 at May-26, 2050 at Aug-26 (incl. 850 delivered FQ1). YE27 4500 E = +~2.5 GW over remaining 3 qtrs of FY27 at ~similar pace to FQ1's 850 (decelerating)
A26: LOW (slower delivery) | B26: 1200 | C26: 2050 | D26: 3200 | E26: =(C26+D26)/2 -> 2625 | F26: E
A27: HIGH | B27: 1200 | C27: 2050 | D27: 6000 | E27: =(C27+D27)/2 -> 4025 | F27: E
A28: Memo: if 850 MW/qtr continues x4 through FY27 from May-26 base | D28: =1200+850*4 -> 4600 | E28: =(1200+(1200+850*4))/2 -> 2900 | F28: E
A30: NEBIUS FY27 avg billed IT MW - MODEL v0.9e (engine-linked: non-Vineland path + Vineland billed MW-yr = engine Microsoft revenue / $14.5M)
A31: FY27 avg billed IT MW - BASE (model v0.9e) - STREET DENOMINATOR | J31: 531.84098 | K31: D | L31: model/nebius_model.xlsx Drivers!B34 = Drivers!B30 349.51 + Drivers!B33 182.33
A32: FY27 avg billed IT MW - HIGH (model v0.9e) | J32: 659.157 | K32: D | L32: model/nebius_model.xlsx Drivers!C34 = Drivers!C30 476.83 + 182.33
A33: Vineland / Microsoft FY27 billed MW-yr (revenue basis = Microsoft revenue / $14.5M) | J33: 182.32922 | K33: D | L33: model/nebius_model.xlsx Drivers!B33 (alt Contracts row 141 billing-MW avg 185.6, memo)
A34: Microsoft (Vineland) FY27 revenue $M in the model engine (Contracts MS_Rev) | J34: 2643.7736 | K34: D | L34: model/nebius_model.xlsx Drivers!B32 = SUMIF(Q_Yr,2027,MS_Rev), Contracts row 145
A35: NON-Microsoft FY27 avg billed IT MW - BASE | J35: =J31-J33 -> 349.51176 | K35: D | L35: base less Vineland billed MW-yr (= model/nebius_model.xlsx Drivers!B30)
A36: NON-Microsoft FY27 avg billed IT MW - HIGH | J36: =J32-J33 -> 476.82779 | K36: D | L36: high less Vineland (= Drivers!C30; Vineland identical on both paths)

Sheet Revenue_Sources
A1: FY27 (or nearest run-rate) revenue inputs. Blue = hard-coded. Tags: R reported, P press/secondary, D derived, E estimated, n-d not disclosed.
A3: Company | B3: Metric | C3: Value $M | D3: Tag | E3: Period / basis | F3: Source | G3: Notes
A4: Nebius | B4: Street FY27 consensus revenue | C4: 12300 | D4: E | E4: CY2027 | F4: S1 | G4: Yahoo/MarketScreener mean, 21 analysts, as-of 2026-10-04
A5: Nebius | B5: YE26 ARR guide - low | C5: 7000 | D5: R | E5: YE26 run-rate | F5: S3 | G5: Dec AI cloud x 12
A6: Nebius | B6: YE26 ARR guide - high | C6: 9000 | D6: R | E6: YE26 run-rate | F6: S3
A7: CoreWeave | B7: Street FY27 consensus revenue | C7: 26260 | D7: E | E7: CY2027 | F7: S4 | G7: Team pack Oct-4; later aggregators 26.8-28.0
A8: CoreWeave | B8: YE26 ARR guide (call coverage) | C8: 18500 | D8: P | E8: YE26 run-rate mid | F8: S5 | G8: Q2'26 call coverage $18-19B ARR exit 2026
A9: CoreWeave | B9: YE27 ARR guide (mgmt reiterated) | C9: 30000 | D9: R | E9: YE27 run-rate floor | F9: S5 | G9: 'annualized revenue should exceed $30B by end of 2027' (Q1'26, reiterated)
A10: IREN | B10: YE26 AI Cloud ARR target (operating) | C10: 4000 | D10: R | E10: YE26 run-rate | F10: S7 | G10: >$4bn ARR targeted operational by Dec 31 2026; 85% contracted Jul-20
A11: IREN | B11: Operating ARR (as of Aug 26 2026) | C11: 1000 | D11: R | E11: Aug-26 run-rate | F11: S7
A12: IREN | B12: FY27 AI GAAP revenue (Street) | C12: n-d | D12: n-d | E12: FY27 | F12: S9 | G12: No AI-only consensus on box. Redburn $2.8B = total company fiscal FY27 (YE Jun-30), P
A13: IREN | B13: Memo: YE27 ARR if 800 IT MW at $20M (own 3-yr pricing) | C13: 16000 | D13: E | E13: YE27 run-rate | F13: S7/S8 | G13: 800 x 20; not a company guide
A14: IREN | B14: Memo: YE27 ARR if 800 IT MW at $13.3M (same as YE26 ARR/MW) | C14: 10667 | D14: E | E14: YE27 run-rate | F14: S7 | G14: 800 x (4000/300)
A15: Oracle | B15: FQ1 FY27 Cloud Infrastructure (IaaS) revenue | C15: 7388 | D15: R | E15: Qtr ended Aug-31-26 | F15: S10 | G15: Includes non-AI OCI
A16: Oracle | B16: FQ1 FY27 Cloud Infra annualized (x4) | C16: 29552 | D16: D | E16: Run-rate | F16: S10 | G16: Not a FY27 guide; growth still high
A17: Oracle | B17: FY27 total company revenue guide | C17: 90000 | D17: R | E17: FY27 (YE May-31) | F17: S10 | G17: 'at least $90 billion' - whole company, not OCI/AI
A18: Oracle | B18: Cloud Infra FY26 (full year) | C18: 18101 | D18: R | E18: FY26 | F18: S10
A19: Nebius | B19: FY27 Microsoft (Vineland) revenue - model v0.9e engine | C19: =MW_Paths!J34 -> 2643.7736 | D19: D | E19: CY2027 | F19: model/nebius_model.xlsx | G19: Drivers!B32 (Contracts MS_Rev row 145: T1-T4 + ramp + Q1'27 genset cap + T5-T9 Bloom starts)
A20: Nebius | B20: Street FY27 ex-Microsoft revenue | C20: =C4-C19 -> 9656.2264 | D20: E/D | E20: CY2027 | F20: S1 less row 19 | G20: Peer comparator numerator (peers have no $14.5M Microsoft anchor)

Sheet Nebius_Check
A1: Verify Nebius Street $12.3B / FY27 avg billed IT MW (model v0.9e 531.8) -> ~$23.1M blended; NON-Microsoft ~$27.6M (peer comparator); YE26 guide $25-32M. Microsoft-Nebius = $14.49M per IT MW [E, house] (model Contracts!E12) only.
A2: CORRECTION 2026-10-05 ET: Implied_Price YE26 high ARR row now uses MW_Paths!E10=284.2 (was both rows on 257.7). Source: model/nebius_model.xlsx Judge_Slide B35.
A3: Check | B3: Value | C3: Tag | D3: Source / note
A4: FY27 consensus revenue ($M) | B4: =Revenue_Sources!C4 -> 12300 | C4: E | D4: S1
A5: FY27 avg billed IT MW - BASE, model v0.9e (STREET DENOMINATOR) | B5: =MW_Paths!J31 -> 531.84098 | C5: D/E | D5: model/nebius_model.xlsx Drivers!B34 = 531.84 (engine-linked)
A6: Implied $M per billed IT MW (Street) | B6: =B4/B5 -> 23.127214 | C6: D | D6: Blended (incl. Microsoft $14.5M anchor) - memo; = model/nebius_model.xlsx Drivers!B10 23.1272
A7: FY27 avg billing - Capacity quarter-end row (memo) | B7: =MW_Paths!J5 -> 593.875 | C7: E | D7: 593.9; NOT the Street denominator
A8: Implied $M/MW if used Capacity qtr-end avg | B8: =B4/B7 -> 20.711429 | C8: D | D8: Lower (~$20.7) - do not use for Street compare
A9: model v0.9e Judge_Slide / Drivers printed Street blended $/MW (Drivers B10 = Judge_Slide B16) | B9: 23.127214 | C9: D | D9: model/nebius_model.xlsx Drivers!B10
A10: Delta vs model v0.9e (should be ~0) | B10: =B6-B9 -> 0 | C10: D
A11: YE26 ARR low ($7B) / YE26 BASE billing 257.7 | B11: =Revenue_Sources!C5/MW_Paths!E9 -> 27.163368 | C11: D | D11: S3 / MW_Paths!E9 = Capacity base Q4'26
A12: YE26 ARR high ($9B) / YE26 BASE billing 257.7 (memo — NOT the headline high-path pairing) | B12: =Revenue_Sources!C6/MW_Paths!E9 -> 34.924331 | C12: D | D12: Memo only; Headline Implied_Price high row uses HIGH MW
A13: YE26 ARR high ($9B) / YE26 HIGH billing 284.2 (HEADLINE high-path) | B13: =Revenue_Sources!C6/MW_Paths!E10 -> 31.66784 | C13: D | D13: Judge_Slide B35/B41; expect ~$31.7 → $25-32 band with low/high cross
A14: YE26 ARR low ($7B) / YE26 HIGH billing 284.2 | B14: =Revenue_Sources!C5/MW_Paths!E10 -> 24.630542 | C14: D | D14: Judge_Slide ~$24.6; with r13 → Judge $25-32 on high billing
A16: MICROSOFT-NEBIUS $ PER IT MW-YR (ruling Oct 9 2026): $14.49M per IT MW [E, house] (model Contracts!E12) only
A17: Neither Nebius nor Microsoft states a contract MW; the current figure uses the house estimate of 240 IT MW (model Inputs!F216 MSFT_MW). 300 MW is Vineland's site size.
A18: TCV committed ($M) | B18: 17392.9 | C18: R | D18: S12 (6-K 2025-09-08; = model Inputs!F215 MSFT_TCV)
A19: Term (years) | B19: 5 | C19: R | D19: 6-K 2025-09-08
A20: ACV = TCV/term ($M/yr) | B20: =B18/B19 -> 3478.58 | C20: D
A21: IT MW - house estimate (model v0.9e Inputs!F216 MSFT_MW) | B21: 240 | C21: E | D21: model/nebius_model.xlsx Inputs!F216; not stated by Nebius/Microsoft
A22: → $M per IT MW-yr [E, house] = model Contracts!E12 (CURRENT) | B22: =B20/B21 -> 14.494083 | C22: E | D22: $14.49M per IT MW [E, house]; agrees with the Drivers 14.5 input (model Inputs!F111)
A23: Model v0.9e Contracts!E12 printed value | B23: 14.494083 | C23: D | D23: model/nebius_model.xlsx Contracts!E12 = MSFT_TCV / (5 x MSFT_MW)
A24: Delta derived - model (should be 0) | B24: =B22-B23 -> 0 | C24: D
A25: HISTORY (superseded Oct 9 2026, not current values): 11.60 = ACV / 300 MW (Vineland site size, not a stated contract MW); 17.08 = ACV / GPU-derived 203.6 IT MW (100,000 GB300 / 491; retired). Do not quote.
A27: Q2'26 AI cloud revenue per avg ENERGIZED MW (K02) | B27: =574.9*4/AVERAGE(181.5,193) -> 12.280908 | C27: D/E | D27: Comparison K02 = 12.28 E (energized 181.5 / 193, Capacity base case Quarterly MW!M130/N130; was 13.35 on v1 171.5 / 173)
A28: Q2'26 AI cloud revenue per avg BILLING IT MW (K02b) | B28: =574.9*4/AVERAGE(165.459207459207,186.822843822844) -> 13.055448 | C28: D/E | D28: New Comparison K02b
A30: Alignment rule for the team: quote Microsoft-Nebius only as '$14.49M per IT MW [E, house] (Contracts!E12)' (11.6 / 17.1 superseded, history only). K02 (energized) = 12.28; K02b (billed IT) ≈ 13.0. Street FY27 is ~$23.1M blended / ~$27.6M ex-Microsoft on BILLED IT MW (model v0.9e 531.8), not energized.
A32: NON-MICROSOFT Street $/billed IT MW (PEER COMPARATOR - peers carry no $14.5M Microsoft anchor)
A33: Street FY27 revenue ($M) | B33: =B4 -> 12300 | C33: E | D33: S1 (= model/nebius_model.xlsx Judge_Slide!B72)
A34: less Microsoft (Vineland) FY27 revenue ($M) | B34: =MW_Paths!J34 -> 2643.7736 | C34: D | D34: Revenue_Sources r19 = Drivers!B32
A35: FY27 avg billed IT MW - BASE (model v0.9e) | B35: =MW_Paths!J31 -> 531.84098 | C35: D | D35: Drivers!B34
A36: less Vineland/Microsoft FY27 billed MW-yr | B36: =MW_Paths!J33 -> 182.32922 | C36: D | D36: Drivers!B33
A37: NON-MSFT $M per billed IT MW - BASE (HEADLINE peer comparator) | B37: =(B33-B34)/(B35-B36) -> 27.627758 | C37: D | D37: calc: (12,300 - 2,643.8) / (531.84 - 182.33) = (12,300 - 2,643.8) / 349.51
A38: Grok Bot figure (Oct 8, v0.9e message) | B38: 27.6 | C38: memo | D38: for reconciliation only (rounded)
A39: Delta derived - Grok Bot (should be ~0) | B39: =B37-B38 -> 0.027757898 | C39: D
A40: Street / FY27 avg billed HIGH (model v0.9e) - blended | B40: =B33/MW_Paths!J32 -> 18.660198 | C40: D | D40: $12.3B / 659.16 (high path)
A41: NON-MSFT $M per billed IT MW - HIGH | B41: =(B33-B34)/MW_Paths!J36 -> 20.250972 | C41: D | D41: Microsoft carve-out identical on the high path
A42: Model v0.9e printed non-MSFT hurdle (Drivers B9) | B42: 27.627758 | C42: D | D42: model/nebius_model.xlsx Drivers!B9 (Judge_Slide B20)
A43: Delta derived - model (should be 0) | B43: =B37-B42 -> 0 | C43: D
A44: MW needed at $16M comps = Street / $16M | B44: =B33/16 -> 768.75 | C44: D | D44: model/nebius_model.xlsx Drivers!B37
...

Sheet Sources
A1: ID | B1: What | C1: URL / local path
A2: S1 | B2: Nebius FY27 consensus revenue $12.30B (21 analysts, range $8.81-17.99); MarketScreener 12.302 agrees. As of 2026-10-04. | C2: https://finance.yahoo.com/quote/NBIS/analysis/ ; https://www.marketscreener.com/quote/stock/NEBIUS-GROUP-8037501/finances/ ; skeptic/01_priced_in_v3.xlsx
A3: S2 | B3: Nebius FY27 avg billed IT MW 531.84 = model v0.9e Drivers B34 (engine-linked: non-Vineland path 349.5 + Vineland billed MW-yr 182.3). Capacity 'Billing MW (IT) - base' quarter-end FY27 avg = 593.9 (memo). History: the Oct-5 pack used the model energized-lag path (MW_Paths row 6). | C3: S2 model/nebius_model.xlsx Drivers rows 29-39 / Judge_Slide rows 16, 25-29; capacity/nebius_capacity.xlsx Quarterly MW rows 136/147
A4: S3 | B4: Nebius YE26 ARR guide $7-9B (Dec AI cloud x 12, reaffirmed Aug 12 2026); YE26 connected 800MW-1GW. | C4: Q2'26 letter https://www.sec.gov/Archives/edgar/data/1513845/000110465926094568/tm2622968d1_ex99-2.htm
A5: S4 | B5: CoreWeave FY27 consensus revenue $26.26B / EBITDA $16.64B (Yahoo + MarketScreener, 40 analysts rev). As of 2026-10-04. (Later aggregators ~$26.8-28.0B - we use team's Oct-4 pack.) | C5: skeptic/01_priced_in_v3.xlsx ; https://finance.yahoo.com/quote/CRWV/analysis/ ; https://ca.marketscreener.com/quote/stock/COREWEAVE-INC-185380761/calendar/
A6: S5 | B6: CoreWeave active power: YE25 >850 MW (R); Q1'26 >1 GW (R); Q2'26 1.5 GW (R); contracted ~3.7 GW Q2 / ~4.2 GW by Aug 11 (R). Q1'26 call: plan 1.7 GW YE26 (R, CNBC). Q2'26 call coverage: exit 2026 >1.85 GW active, $18-19B ARR; YE27 ARR >$30B reiterated (P, secondary). | C6: Q2'26 PR https://www.sec.gov/Archives/edgar/data/1769628/000176962826000366/ ; convert deck comps_raw/crwv_0917__crwv2026convertpresentat.htm.txt ; CNBC 2026-05-07; Tickeron Q2 summary
A7: S6 | B7: CoreWeave NVIDIA partnership: 'Build and deliver more than 5GW of cloud infrastructure'; CEO: 'well on our way to more than 8 GW by 2030'. | C7: comps_raw/crwv_0917__crwv2026convertpresentat.htm.txt ; Q1'26 PR
A8: S7 | B8: IREN: cumulative IT delivery target 0.3 GW (2026) / 0.8 GW (2027) (R). Also 480 MW gross YE26 / 1.2 GW gross YE27. YE26 ARR target >$4bn (85% under contract Jul-20); operating ARR $1bn as of Aug 26 2026. | C8: FY26 PR https://www.sec.gov/Archives/edgar/data/1878848/000187884826000051/irenreportsfy26results.htm ; Jul-20 8-K https://www.sec.gov/Archives/edgar/data/1878848/000114036126028871/ef20078253_ex99-1.htm
A9: S8 | B9: IREN 3-yr contracts >$20M revenue per MW (IT); discussions ~$25M per MW (IT). Microsoft deal $9.7B / 5 yr / 200 IT MW = $9.7M/IT MW-yr. | C9: FY26 PR (S7); Nov-3 2025 PR
A10: S9 | B10: IREN AI Cloud GAAP revenue: no FY27 Street AI-only consensus found on box. Redburn initiates Neutral, forecasts $2.8B fiscal FY27 total company revenue (P, secondary; fiscal YE Jun-30). | C10: https://blockspace.media/insight/iren-neutral-40-target-revenue-forecast-2029/
A11: S10 | B11: Oracle FQ1 FY27 (qtr ended Aug 31 2026): Cloud Infrastructure revenue $7.388B (+121%); delivered 850 MW additional datacenter capacity; >300k GPUs to AI Cloud customers. FY27 total revenue guide ≥$90B. RPO $664B. | C11: https://www.sec.gov/Archives/edgar/data/1341439/... orcl-ex99_1.htm ; comps_raw/orcl_q1pr__orcl-ex99_1.htm.txt
A12: S11 | B12: Oracle cumulative AI MW delivered since 1-Jun-2025: ~2,050 MW by Aug-26 (E; peers/oracle/oracle_kpis.xlsx I45E). MW basis unlabeled; 353 GPUs/MW vs GB200 538/IT suggests gross/facility. Includes non-AI OCI in Cloud Infrastructure revenue. | C12: peers/oracle/oracle_kpis.xlsx Inputs I09N/I45E
... A14: S13 | B14: Nebius Q2'26 AI cloud revenue $574.9M (R); energized MW 181.5/193 (Capacity base case, E; Quarterly MW!M130/N130); billing IT MW Q1/Q2'26 = 165.5/186.8 (Capacity row 147). | C14: filings/nebius_kpi_history.xlsx ; capacity/nebius_capacity.xlsx
A15: S14 | B15: YE26 HIGH billing IT MW = 284.2 (Judge_Slide B35; Capacity v2 high energized IT lagged 1q, Vineland billed tranches). Used for Implied_Price high ARR row after 2026-10-05 correction. | C15: D/E | D15: model/nebius_model.xlsx Judge_Slide B35 (v0.9e); FY27 high path 659.2 = Drivers C34
