Workbook

Sheet README
A1: Nebius Group (NBIS) consolidated KPI history | B1: Built 2026-10-05 08:31 ET by Filings & Capital. Script: /workspace/nebius/filings/kpi/kpi_build.py. Public information only.
A2: Tabs | B2: KPI (main grid, 10 quarters), Prices_Monthly (market inputs feeding quarter averages), Checks (tie-outs), Sources (one row per populated cell: tag, source with URL, note).
A3: Tags | B3: Reported = number as printed in an SEC filing / company page / snapshot. Derived = live formula on Reported inputs (or arithmetic on reported totals, math shown). Estimated = a team model value or a formula using one (method in Sources). n.d. = not disclosed / input missing; never filled.
A4: Colours | B4: Blue = Reported input; black = formula on Reported/Derived inputs; orange italic = Estimated (input, or a formula that uses an Estimated input); grey = n.d.
A5: ARR | B5: Annualized run-rate revenue = Nebius AI cloud revenue from the last month of the quarter x 12 (Q2-26 shareholder letter, footnote 4; same wording Q1-26). Q3-25/Q4-25 letters: "revenue from the last month of the quarter multiplied by 12"; Q1-25 letter: "revenue for last month of the period multiplied by twelve". 2024 values read from the Oct-2024 investor presentation chart; Dec-24 $90M from Q4-24 PR.
A6: MW basis | B6: Energized MW is the Capacity & Power team ESTIMATE of power physically live (closest to Nebius "active power"); not "connected" (built and equipped) or "contracted" (land + power secured). Nebius never states IT vs gross. Vineland, Modi'in and AIB rows are IT MW; others as stated (mostly gross/unknown), so totals mix bases (1.1-1.45x PUE ambiguity). Management figures: YE24 25 MW CONNECTED; YE25 ~170 MW ACTIVE.
A7: Quarter-end vs average | B7: Stock measures (MW, GPUs, PP&E) are quarter-end. Per-unit revenue KPIs are shown on average (opening+closing)/2 and, where noted, quarter-end. With fast build-outs the two can differ a lot (e.g., Q4-25 GPUs 31.8k -> 69.0k).
A8: GPUs | B8: Modeled = energized base MW x GPUs per MW by generation (capacity/gpu_mw_capex.xlsx); company counts are sparse: only actual is ~30,000 deployed at 31-Mar-25 (FY24 20-F; the earlier ~38k from the Feb-25 call was a forward-looking target, superseded); Q3-24 ~10k and Q4-24 >20k are Estimated/targets and ran ahead of powered MW. Generation per site mostly assumed by the Capacity team.
A9: Implied utilization | B9: AI cloud revenue / (average modeled GPUs x hours in quarter x fleet-weighted blended LIST price). It mixes utilization with the realized-vs-list discount (commit deals up to 35% below list; large contracts lower), and revenue includes non-GPU-hour items. Hopper priced at H100 list; GB300 (no public price) proxied by B300 list (Q2-26) or B200 list (earlier, floor). Treat as an index, not a measured utilization.
A10: Capex per MW | B10: Cash capex / change in energized MW. Capex largely funds capacity not yet energized (assets not yet in use rose $2.4B -> $7.8B in 1H26), so quarterly ratios are "n.m." when MW added <= 5 MW; use trailing-4Q and the placed-in-service basis (change in gross in-service PP&E / MW added).
A11: June step-up | B11: ARR/12 (implied last-month revenue) vs AI cloud quarter monthly average. Q2-26: $250M vs $191.6M (+30%); Q1-26: $160M vs $129.9M.
A12: Restatements | B12: Revenue/OCF on latest restated basis (Toloka deconsolidated Q2-25, in discontinued ops). Small company rounding differences noted in Sources (e.g., Q2-25 OCF 167.7 vs 167.9; Q3-24 34.9 vs 34.8).
A13: Inputs | B13: Filings: /workspace/nebius/filings/nebius_filings.xlsx (Quarterly tab via quarterly_rows.json) + edgar/*.txt. Capacity: /workspace/nebius/capacity/nebius_capacity.xlsx (Quarterly MW rows 119-125, GPUs deployed rows 11-31). Market: /workspace/nebius/market/gpu_price_history.xlsx (Price_History_Quarterly, Price_History_Monthly, Monthly_FFill, H100_Nebius_vs_Medians).

Sheet KPI
A1: Nebius Group (NBIS) - consolidated tagged KPI history, Q1 2024 - Q2 2026. $M unless noted. Blue = Reported input; black = formula on Reported/Derived inputs; orange italic = Estimated (input, or formula using an Estimated input); grey = n.d. Per-cell sources in Sources tab.
A3: Metric | B3: Unit | C3: Q1 2024 | D3: Q2 2024 | E3: Q3 2024 | F3: Q4 2024 | G3: Q1 2025 | H3: Q2 2025 | I3: Q3 2025 | J3: Q4 2025 | K3: Q1 2026 | L3: Q2 2026 | M3: Basis / caveat | N3: Owner / origin
A4: A. Financials (Filings & Capital: nebius_filings.xlsx Quarterly tab; SEC filings)
A5: Group revenue (continuing ops, restated) | B5: $M | C5: 9.7 | D5: 14.5 | E5: 32.1 | F5: 35.2 | G5: 50.9 | H5: 105.1 | I5: 146.1 | J5: 227.7 | K5: 399 | L5: 582.3 | N5: Filings & Capital
A6: Nebius AI cloud segment revenue | B6: $M | C6: n.d. | D6: n.d. | E6: 27.1 | F6: 23.8 | G6: 41.4 | H6: 93.7 | I6: 131.1 | J6: 214.1 | K6: 389.7 | L6: 574.9 | M6: Segment revenue; Q1/Q2 2024 split not disclosed (H1-24 total 17.4). | N6: Filings & Capital
A7: ARR (as stated; last-month revenue x12) | B7: $M | C7: 32 | D7: 45 | E7: 121 | F7: 90 | G7: 249 | H7: 430 | I7: 551 | J7: 1250 | K7: 1920 | L7: 3000 | M7: Pre-Q1-26 letters: "revenue from the last month of the quarter x12"; Q1-26 on: "Nebius AI cloud revenue from the last month of the quarter multiplied by 12". 2024 values from Oct-24 investor presentation chart. | N7: Filings & Capital
A8: Adjusted EBITDA - group | B8: $M | C8: -58.4 | D8: -58.1 | E8: -45.9 | F8: -63.9 | G8: -53.7 | H8: -21 | I8: -5.2 | J8: 15 | K8: 129.5 | L8: 236.2 | N8: Filings & Capital
A9: Adjusted EBITDA - Nebius AI cloud segment | B9: $M | C9: n.d. | D9: n.d. | E9: -21.5 | F9: -38.5 | G9: -27.4 | H9: 9.5 | I9: 25.1 | J9: 51.8 | K9: 174 | L9: 285.7 | N9: Filings & Capital
A10: Depreciation & amortization | B10: $M | C10: 8.9 | D10: 11.4 | E10: 23.5 | F10: 33.3 | G10: 49.1 | H10: 75.2 | I10: 99 | J10: 180.7 | K10: 212 | L10: 259.7 | N10: Filings & Capital
A11: Capex - cash purchases of PP&E and intangibles | B11: $M | C11: 58.9 | D11: 159 | E11: 172.1 | F11: 417.5 | G11: 543.9 | H11: 510.6 | I11: 955.5 | J11: 2056 | K11: 2472.9 | L11: 5657.4 | M11: Cash flow statement, continuing ops. | N11: Filings & Capital
A12: PP&E, net (period end) | B12: $M | C12: n.d. | D12: 328.3 | E12: 475.3 | F12: 846.7 | G12: 1334.1 | H12: 1789.4 | I12: 3314.4 | J12: 5553.3 | K12: 7131.7 | L12: 13045.2 | N12: Filings & Capital
A13: Cash & cash equivalents (period end) | B13: $M | C13: n.d. | D13: 2325.5 | E13: 2288.2 | F13: 2434.7 | G13: 1447 | H13: 1679.3 | I13: 4794.8 | J13: 3678.1 | K13: 9298.2 | L13: 8042.1 | N13: Filings & Capital
A14: Total debt, carrying (period end) | B14: $M | C14: n.d. | D14: 6.5 | E14: 6.2 | F14: 6.1 | G14: 6.2 | H14: 986.2 | I14: 4106.8 | J14: 4127.7 | K14: 8450.4 | L14: 8545.7 | N14: Filings & Capital
A15: Deferred revenue, total (period end) | B15: $M | C15: n.d. | D15: n.d. | E15: n.d. | F15: 16.3 | G15: 19 | H15: 19.3 | I15: 15.6 | J15: 1577.5 | K15: 4778.1 | L15: 5975.2 | N15: Filings & Capital
A16: Remaining performance obligations (period end) | B16: $M | C16: n.d. | D16: n.d. | E16: n.d. | F16: n.d. | G16: n.d. | H16: n.d. | I16: n.d. | J16: 21333 | K16: 33585.3 | L16: 37490.6 | N16: Filings & Capital
A17: Shares issued & outstanding (period end; excl. NVIDIA pre-funded warrant) | B17: shares | C17: n.d. | D17: 293850159 | E17: 199340118 | F17: 235753600 | G17: 238108831 | H17: 238705092 | I17: 251807222 | J17: 253016971 | K17: 253898194 | L17: 271855218 | M17: Excludes 21,065,936 NVIDIA pre-funded warrant shares (unexercised). | N17: Filings & Capital
A18: Weighted-average shares - basic | B18: shares | C18: n.d. | D18: n.d. | E18: 246595139 | F18: 217546859 | G18: 237916047 | H18: 238520244 | I18: 245256157 | J18: 252412097 | K18: 258298911 | L18: 280381615 | N18: Filings & Capital
A19: Customer concentration (>10% of revenue) | B19: text | C19: n.d. | D19: n.d. | E19: n.d. | F19: FY24: A 27%, C 11% | G19: n.d. | H19: A 39%, B 15% | I19: n.d. | J19: FY25: A 25%, B 15% | K19: n.d. | L19: C 24%, D 21%, E 14% | N19: Filings & Capital
A20: Net cash from operating activities - continuing ops | B20: $M | C20: -63 | D20: -99 | E20: -34.8 | F20: -73.1 | G20: -184.1 | H20: -167.7 | I20: -80.6 | J20: 834.3 | K20: 2258 | L20: 2246.1 | M20: Quarterly; latest restated basis (Toloka in discontinued ops). | N20: Filings & Capital (new)
A21: Change in deferred revenue (cash flow statement, operating) | B21: $M | C21: n.d. | D21: n.d. | E21: 3.7 | F21: -0.4 | G21: 2.4 | H21: 0.6 | I21: -3.8 | J21: 1566.5 | K21: 3198 | L21: 1197 | M21: Increase = cash collected ahead of revenue (customer prepayments). | N21: Filings & Capital (new)
A22: OCF excluding change in deferred revenue | B22: $M | C22: n.d. | D22: n.d. | E22: =E20-E21 | F22: =F20-F21 | G22: =G20-G21 | H22: =H20-H21 | I22: =I20-I21 | J22: =J20-J21 | K22: =K20-K21 | L22: =L20-L21 | M22: OCF minus change in deferred revenue (prepayment-free operating cash). | N22: Derived
A23: Server and network equipment, gross (in service) | B23: $M | C23: n.d. | D23: n.d. | E23: n.d. | F23: 794.9 | G23: n.d. | H23: n.d. | I23: n.d. | J23: 3123.6 | K23: 4692.7 | L23: 5197.7 | M23: PP&E note breakdown only in 20-F and 2026 interim statements; 2024/2025 interim OFRs give no breakdown. | N23: Filings & Capital (new)
A24: Assets not yet in use (gross; under installation incl. prepayments) | B24: $M | C24: n.d. | D24: n.d. | E24: n.d. | F24: 163.8 | G24: n.d. | H24: n.d. | I24: n.d. | J24: 2417.4 | K24: 2427.9 | L24: 7836.4 | M24: FY24 20-F showed 163.9 for Dec-24 (later 163.8) | N24: Filings & Capital (new)
A25: PP&E, gross (total before accumulated depreciation) | B25: $M | C25: n.d. | D25: n.d. | E25: n.d. | F25: 1083 | G25: n.d. | H25: n.d. | I25: n.d. | J25: 6190.3 | K25: 7976.6 | L25: 14149.5 | N25: Filings & Capital (new)
A26: PP&E gross in service (= gross - assets not yet in use) | B26: $M | C26: n.d. | D26: n.d. | E26: n.d. | F26: =F25-F24 | G26: n.d. | H26: n.d. | I26: n.d. | J26: =J25-J24 | K26: =K25-K24 | L26: =L25-L24 | N26: Derived
A27: Change in assets not yet in use (QoQ) | B27: $M | C27: n.d. | D27: n.d. | E27: n.d. | F27: n.d. | G27: n.d. | H27: n.d. | I27: n.d. | J27: n.d. | K27: =K24-J24 | L27: =L24-K24 | M27: Derived: period-end ANIU minus prior period-end ANIU from Note 7. Positive = net additions to installation pipeline (purchases/prepayments exceed transfers into service). Only where consecutive breakdowns exist (Q4-24→Q4-25 annual gap skipped; Q1-26 and Q2-26 QoQ). | N27: Derived
A28: Servers placed in service (QoQ change in server & network equipment, gross) | B28: $M | C28: n.d. | D28: n.d. | E28: n.d. | F28: n.d. | G28: n.d. | H28: n.d. | I28: n.d. | J28: n.d. | K28: =K23-J23 | L28: =L23-K23 | M28: Derived: QoQ change in Server and network equipment, gross (Note 7). Proxy for servers transferred into service; does not equal -Δ ANIU because new purchases enter ANIU first. Available Q1-26 (vs YE25) and Q2-26 (vs Q1-26). | N28: Derived
A29: B. Capacity & Power (capacity/nebius_capacity.xlsx; Capacity & Power team - tags carried)
A30: Energized MW - company total incl. plug (Capacity base case) | B30: MW | C30: 25 | D30: 25 | E30: 25 | F30: 25 | G30: 50 | H30: 50 | I30: 62.5 | J30: 170 | K30: 181.5 | L30: 193 | M30: Ties to mgmt figures where given (YE25 ~170 MW active). Capacity Quarterly MW row 130 (Total incl. plug). MIXED basis: Vineland, Modi'in, AIB = IT MW; other sites as stated (mostly gross/unknown). Closest to Nebius "active" power; NOT connected or contracted. | N30: Capacity & Power
A31: Energized MW - identified sites, low | B31: MW | C31: 25 | D31: 25 | E31: 25 | F31: 30 | G31: 45 | H31: 45 | I31: 45 | J31: 115.8 | K31: 154 | L31: 157 | M31: Excludes plug for undisclosed sites. Capacity Quarterly MW row 124. | N31: Capacity & Power
A32: Energized MW - identified sites, high | B32: MW | C32: 25 | D32: 25 | E32: 25 | F32: 30 | G32: 55 | H32: 55 | I32: 80 | J32: 179.6 | K32: 209 | L32: 229 | M32: Excludes plug. Capacity Quarterly MW row 125. | N32: Capacity & Power
A33: MW as stated by management | B33: MW | C33: n.d. | D33: n.d. | E33: n.d. | F33: 25 | G33: n.d. | H33: n.d. | I33: n.d. | J33: 170 | K33: n.d. | L33: n.d. | M33: YE24 = connected (Q3-25 letter chart); YE25 = ACTIVE (Q4-25 letter). Different definitions. | N33: Capacity & Power / filings
A34: GPUs deployed - modeled (Capacity: energized MW x GPUs/MW) | B34: GPUs | C34: 13713 | D34: 13713 | E34: 13713 | F34: 16456 | G34: 27426 | H34: 27426 | I34: 32542 | J34: 69797 | K34: 84323 | L34: 89153 | M34: Modeled from MW, not a company count. Company counts ran ahead of powered MW. | N34: Capacity & Power
A35: of which Hopper (H100-class; Mantsala first 25 MW, Paris, Keflavik) | B35: GPUs | C35: 13713 | D35: 13713 | E35: 13713 | F35: 16456 | G35: 21941 | H35: 21941 | I35: 21941 | J35: 21941 | K35: 21941 | L35: 21941 | M35: Generation per site mostly ASSUMED by Capacity team (GPU vintage tab). | N35: Capacity & Power (split by Filings)
A36: of which H200 (Kansas City first 10 MW @ 548.5 GPUs/MW) | B36: GPUs | C36: 0 | D36: 0 | E36: 0 | F36: 0 | G36: 5485 | H36: 5485 | I36: 5485 | J36: 5485 | K36: 5485 | L36: 5485 | M36: Generation per site mostly ASSUMED by Capacity team (GPU vintage tab). | N36: Capacity & Power (split by Filings)
A37: of which B200 (Kansas City expansion, Modi'in) | B37: GPUs | C37: 0 | D37: 0 | E37: 0 | F37: 0 | G37: 0 | H37: 0 | I37: 0 | J37: 7981 | K37: 7981 | L37: 7981 | M37: Generation per site mostly ASSUMED by Capacity team (GPU vintage tab). | N37: Capacity & Power (split by Filings)
A38: of which B300 HGX (Longcross) | B38: GPUs | C38: 0 | D38: 0 | E38: 0 | F38: 0 | G38: 0 | H38: 0 | I38: 0 | J38: 6173 | K38: 10031 | L38: 10031 | M38: Generation per site mostly ASSUMED by Capacity team (GPU vintage tab). | N38: Capacity & Power (split by Filings)
A39: of which GB300 NVL72 (Vineland, Mantsala expansion) | B39: GPUs | C39: 0 | D39: 0 | E39: 0 | F39: 0 | G39: 0 | H39: 0 | I39: 5116 | J39: 28217 | K39: 38885 | L39: 43715 | M39: Generation per site mostly ASSUMED by Capacity team (GPU vintage tab). | N39: Capacity & Power (split by Filings)
A40: GPU count as stated by company (for comparison) | B40: GPUs | C40: n.d. | D40: n.d. | E40: 10000 | F40: 20000 | G40: 30000 | H40: n.d. | I40: n.d. | J40: n.d. | K40: n.d. | L40: n.d. | M40: Not used in formulas. | N40: Capacity & Power / filings
A41: C. GPU list pricing (GPU Market & Comps: market/gpu_price_history.xlsx)
...

Sheet Prices_Monthly
A1: Nebius public on-demand list prices, $/GPU-hr, monthly (GPU Market & Comps team: gpu_price_history.xlsx). Blue = observed in a Wayback/live snapshot that month (Reported); orange italic = carried forward from the last observation (Estimated, forward-fill); grey = no observation yet.
A3: SKU | B3: 2024-01 | C3: 2024-02 | D3: 2024-03 | E3: 2024-04 | F3: 2024-05 | G3: 2024-06 | H3: 2024-07 | I3: 2024-08 | J3: 2024-09 | K3: 2024-10 | L3: 2024-11 | M3: 2024-12 | N3: 2025-01 | O3: 2025-02 | P3: 2025-03 | Q3: 2025-04 | R3: 2025-05 | S3: 2025-06 | T3: 2025-07 | U3: 2025-08 | V3: 2025-09 | W3: 2025-10 | X3: 2025-11 | Y3: 2025-12 | Z3: 2026-01 | AA3: 2026-02 | AB3: 2026-03 | AC3: 2026-04 | AD3: 2026-05 | AE3: 2026-06
A4: Nebius H100 SXM on-demand | B4: 4.85 | C4: 4.85 | D4: 4.85 | E4: 4.85 | F4: 4.85 | G4: 4.85 | H4: 4.85 | I4: 4.85 | J4: 3.5 | K4: 3.5 | L4: 2.95 | M4: 2.95 | N4: 2.95 | O4: 2.95 | P4: 2.95 | Q4: 2.95 | R4: 2.95 | S4: 2.95 | T4: 2.95 | U4: 2.95 | V4: 2.95 | W4: 2.95 | X4: 2.95 | Y4: 2.95 | Z4: 2.95 | AA4: 2.95 | AB4: 2.95 | AC4: 2.95 | AD4: 2.95 | AE4: 3.85
A5: Nebius H200 on-demand | B5: n.d. | C5: n.d. | D5: n.d. | E5: n.d. | F5: n.d. | G5: n.d. | H5: n.d. | I5: n.d. | J5: n.d. | K5: 4.85 | L5: 3.5 | M5: 3.5 | N5: 3.5 | O5: 3.5 | P5: 3.5 | Q5: 3.5 | R5: 3.5 | S5: 3.5 | T5: 3.5 | U5: 3.5 | V5: 3.5 | W5: 3.5 | X5: 3.5 | Y5: 3.5 | Z5: 3.5 | AA5: 3.5 | AB5: 3.5 | AC5: 3.5 | AD5: 3.5 | AE5: 4.5
A6: Nebius B200 on-demand | B6: n.d. | C6: n.d. | D6: n.d. | E6: n.d. | F6: n.d. | G6: n.d. | H6: n.d. | I6: n.d. | J6: n.d. | K6: n.d. | L6: n.d. | M6: n.d. | N6: n.d. | O6: n.d. | P6: n.d. | Q6: n.d. | R6: n.d. | S6: n.d. | T6: 5.5 | U6: 5.5 | V6: 5.5 | W6: 5.5 | X6: 5.5 | Y6: 5.5 | Z6: 5.5 | AA6: 5.5 | AB6: 5.5 | AC6: 5.5 | AD6: 5.5 | AE6: 7.15
A7: Nebius B300 on-demand | B7: n.d. | C7: n.d. | D7: n.d. | E7: n.d. | F7: n.d. | G7: n.d. | H7: n.d. | I7: n.d. | J7: n.d. | K7: n.d. | L7: n.d. | M7: n.d. | N7: n.d. | O7: n.d. | P7: n.d. | Q7: n.d. | R7: n.d. | S7: n.d. | T7: n.d. | U7: n.d. | V7: n.d. | W7: n.d. | X7: n.d. | Y7: n.d. | Z7: n.d. | AA7: n.d. | AB7: n.d. | AC7: 6.1 | AD7: 6.1 | AE7: 7.85

Sheet Checks
A1: Checks: Q2 2026 tie-outs to filings and cross-team references (live formulas).
A3: Check | B3: Workbook value (formula) | C3: Expected | D3: Difference | E3: Result | F3: Expected source
A4: AI cloud segment revenue Q2-26 ($M) | B4: =KPI!L6 | C4: 574.9 | D4: =B4-C4 | E4: =IF(ABS(D4)<=0.25,"PASS","CHECK") | F4: 6-K 2026-08-12 acc 0001104659-26-094844 nbis-20260812xex99d2.htm Note 15 segment table | https://www.sec.gov/Archives/edgar/data/1513845/000110465926094844/nbis-20260812xex99d2.htm
A5: ARR end-Jun-26 ($M) | B5: =KPI!L7 | C5: 3000 | D5: =B5-C5 | E5: =IF(ABS(D5)<=0.25,"PASS","CHECK") | F5: 6-K 2026-08-12 acc 0001104659-26-094568 tm2622968d1_ex99-2.htm p.9 ("ARR reached $3.0 billion") | https://www.sec.gov/Archives/edgar/data/1513845/000110465926094568/tm2622968d1_ex99-2.htm
A6: Deferred revenue 30-Jun-26 ($M) = current 979.4 + non-current 4,995.8 | B6: =KPI!L15 | C6: =979.4+4995.8 | D6: =B6-C6 | E6: =IF(ABS(D6)<=0.25,"PASS","CHECK") | F6: 6-K 2026-08-12 acc 0001104659-26-094844 nbis-20260812xex99d2.htm balance sheet p.F-3 | https://www.sec.gov/Archives/edgar/data/1513845/000110465926094844/nbis-20260812xex99d2.htm
A7: RPO 30-Jun-26 ($M) | B7: =KPI!L16 | C7: 37490.6 | D7: =B7-C7 | E7: =IF(ABS(D7)<=0.25,"PASS","CHECK") | F7: 6-K 2026-08-12 acc 0001104659-26-094844 nbis-20260812xex99d2.htm Note 1 p.F-19 | https://www.sec.gov/Archives/edgar/data/1513845/000110465926094844/nbis-20260812xex99d2.htm
A8: Segment sum = group revenue Q2-26 (574.9+1.0+10.0-3.6) | B8: =KPI!L5 | C8: =574.9+1.0+10.0-3.6 | D8: =B8-C8 | E8: =IF(ABS(D8)<=0.25,"PASS","CHECK") | F8: 6-K 2026-08-12 acc 0001104659-26-094844 nbis-20260812xex99d2.htm Note 15 | https://www.sec.gov/Archives/edgar/data/1513845/000110465926094844/nbis-20260812xex99d2.htm
A9: ARR/12 = June AI cloud revenue ($M) | B9: =KPI!L68 | C9: 250 | D9: =B9-C9 | E9: =IF(ABS(D9)<=0.25,"PASS","CHECK") | F9: Q2-26 letter (ARR $3.0B / 12)
A10: Q2-26 AI cloud monthly average ($M) | B10: =KPI!L69 | C10: =574.9/3 | D10: =B10-C10 | E10: =IF(ABS(D10)<=0.25,"PASS","CHECK") | F10: arithmetic
A11: FY25 OCF: sum of quarters = 401.9 (20-F) | B11: =SUM(KPI!G20:J20) | C11: 401.9 | D11: =B11-C11 | E11: =IF(ABS(D11)<=0.25,"PASS","CHECK") | F11: 20-F 2026-04-30 acc 0001104659-26-052948 nbis-20251231x20f.htm cash flow statement p.F-12 | https://www.sec.gov/Archives/edgar/data/1513845/000110465926052948/nbis-20251231x20f.htm
A12: 1H26 OCF: sum = 4,504.1 | B12: =SUM(KPI!K20:L20) | C12: 4504.1 | D12: =B12-C12 | E12: =IF(ABS(D12)<=0.25,"PASS","CHECK") | F12: 6-K 2026-08-12 acc 0001104659-26-094568 tm2622968d1_ex99-1.htm cash flow statement | https://www.sec.gov/Archives/edgar/data/1513845/000110465926094568/tm2622968d1_ex99-1.htm
A13: 1H26 change in deferred revenue = 4,395.0 | B13: =SUM(KPI!K21:L21) | C13: 4395 | D13: =B13-C13 | E13: =IF(ABS(D13)<=0.25,"PASS","CHECK") | F13: 6-K 2026-08-12 acc 0001104659-26-094568 tm2622968d1_ex99-1.htm cash flow statement | https://www.sec.gov/Archives/edgar/data/1513845/000110465926094568/tm2622968d1_ex99-1.htm
A14: Deferred revenue YE24 ($M) | B14: =KPI!F15 | C14: 16.3 | D14: =B14-C14 | E14: =IF(ABS(D14)<=0.25,"PASS","CHECK") | F14: 6-K 2025-08-07 acc 0001104659-25-075028 tm2522866d1_ex99-1.htm BS comparative Dec-24 | https://www.sec.gov/Archives/edgar/data/1513845/000110465925075028/tm2522866d1_ex99-1.htm / 20-F 2026-04-30 acc 0001104659-26-052948 nbis-20251231x20f.htm BS | https://www.sec.gov/Archives/edgar/data/1513845/000110465926052948/nbis-20251231x20f.htm
A15: Deferred revenue 30-Jun-25 ($M) | B15: =KPI!H15 | C15: 19.3 | D15: =B15-C15 | E15: =IF(ABS(D15)<=0.25,"PASS","CHECK") | F15: 6-K 2025-08-07 acc 0001104659-25-075028 tm2522866d1_ex99-1.htm BS Jun-30-2025 | https://www.sec.gov/Archives/edgar/data/1513845/000110465925075028/tm2522866d1_ex99-1.htm
A16: Q1-26 servers placed in service = 4692.7-3123.6 | B16: =KPI!K28 | C16: =4692.7-3123.6 | D16: =B16-C16 | E16: =IF(ABS(D16)<=0.25,"PASS","CHECK") | F16: 6-K 2026-05-20 acc 0001104659-26-064092 nbis-20260331xex99d2.htm Note 7 | https://www.sec.gov/Archives/edgar/data/1513845/000110465926064092/nbis-20260331xex99d2.htm vs YE25
A17: Q2-26 servers placed in service = 5197.7-4692.7 | B17: =KPI!L28 | C17: =5197.7-4692.7 | D17: =B17-C17 | E17: =IF(ABS(D17)<=0.25,"PASS","CHECK") | F17: 6-K 2026-08-12 acc 0001104659-26-094844 nbis-20260812xex99d2.htm Note 7 | https://www.sec.gov/Archives/edgar/data/1513845/000110465926094844/nbis-20260812xex99d2.htm vs Q1FS
A18: Q1-26 Δ ANIU = 2427.9-2417.4 | B18: =KPI!K27 | C18: =2427.9-2417.4 | D18: =B18-C18 | E18: =IF(ABS(D18)<=0.25,"PASS","CHECK") | F18: 6-K 2026-05-20 acc 0001104659-26-064092 nbis-20260331xex99d2.htm Note 7 | https://www.sec.gov/Archives/edgar/data/1513845/000110465926064092/nbis-20260331xex99d2.htm
A19: Q2-26 Δ ANIU = 7836.4-2427.9 | B19: =KPI!L27 | C19: =7836.4-2427.9 | D19: =B19-C19 | E19: =IF(ABS(D19)<=0.25,"PASS","CHECK") | F19: 6-K 2026-08-12 acc 0001104659-26-094844 nbis-20260812xex99d2.htm Note 7 | https://www.sec.gov/Archives/edgar/data/1513845/000110465926094844/nbis-20260812xex99d2.htm
A20: FY24 OCF: sum of quarters = (269.9) | B20: =SUM(KPI!C20:F20) | C20: -269.9 | D20: =B20-C20 | E20: =IF(ABS(D20)<=0.25,"PASS","CHECK") | F20: 20-F 2026-04-30 acc 0001104659-26-052948 nbis-20251231x20f.htm cash flow statement | https://www.sec.gov/Archives/edgar/data/1513845/000110465926052948/nbis-20251231x20f.htm
A21: PP&E gross - accumulated depreciation = net 30-Jun-26 | B21: =KPI!L25-1104.3 | C21: =KPI!L12 | D21: =B21-C21 | E21: =IF(ABS(D21)<=0.25,"PASS","CHECK") | F21: 6-K 2026-08-12 acc 0001104659-26-094844 nbis-20260812xex99d2.htm Note 7 p.F-23 | https://www.sec.gov/Archives/edgar/data/1513845/000110465926094844/nbis-20260812xex99d2.htm
A22: Energized MW Q2-26 (Capacity team reference ~193) | B22: =KPI!L30 | C22: 193 | D22: =B22-C22 | E22: =IF(ABS(D22)<=0.5,"PASS","CHECK") | F22: Capacity & Power Quarterly MW row 130 Q2-26
A23: Modeled GPUs Q2-26 (Capacity team reference ~89,153) | B23: =KPI!L34 | C23: 89153 | D23: =B23-C23 | E23: =IF(ABS(D23)<=100,"PASS","CHECK") | F23: Capacity & Power GPUs deployed row 34 Q2-26 (tolerance 100)
A24: GPU generation split sums to total Q2-26 | B24: =SUM(KPI!L35:L39) | C24: =KPI!L34 | D24: =B24-C24 | E24: =IF(ABS(D24)<=0.25,"PASS","CHECK") | F24: internal
A26: Filings & Capital n.d. notes (2026-10-05)
A27: RPO before YE25: FIRST disclosure = YE25 20-F $21,333.0 [R] at 12/31/25. No RPO $ in FY24 20-F or 2025 quarterly 6-Ks/letters searched. Leave Q1’24–Q3’25 n.d. Detail: kpi_nd_notes.md
A28: Mid-2025 PP&E Note 7: Q1’25 / Q2’25 / Q3’25 LACK servers & ANIU roll. Disclosed at YE24, YE25, Q1’26, Q2’26 (H1’26) only. Do not invent fills. Detail: kpi_nd_notes.md

Sheet Sources
A1: Sheet | B1: Cell | C1: Metric | D1: Period | E1: Value / formula | F1: Tag | G1: Source (form date acc doc ref | URL, or file/sheet/cell) | H1: Note / derivation
A2: Prices_Monthly | B2: B4 | C2: Nebius H100 SXM on-demand | D2: 2024-01 | E2: 4.85 | F2: Estimated | G2: /workspace/nebius/market/gpu_price_history.xlsx Monthly_FFill 'Nebius | H100 SXM 80GB | on-demand | PAYG' 2024-01 | H2: no snapshot this month; carried forward from last observation (market-team forward-fill)
A3: Prices_Monthly | B3: C4 | C3: Nebius H100 SXM on-demand | D3: 2024-02 | E3: 4.85 | F3: Estimated | G3: /workspace/nebius/market/gpu_price_history.xlsx Monthly_FFill 'Nebius | H100 SXM 80GB | on-demand | PAYG' 2024-02 | H3: no snapshot this month; carried forward from last observation (market-team forward-fill)
A4: Prices_Monthly | B4: D4 | C4: Nebius H100 SXM on-demand | D4: 2024-03 | E4: 4.85 | F4: Reported | G4: /workspace/nebius/market/gpu_price_history.xlsx Price_History_Monthly 'Nebius | H100 SXM 80GB | on-demand | PAYG' 2024-03 (snapshot rows in Price_History_Long; nebius.com/prices via web.archive.org)
A5: Prices_Monthly | B5: E4 | C5: Nebius H100 SXM on-demand | D5: 2024-04 | E5: 4.85 | F5: Estimated | G5: /workspace/nebius/market/gpu_price_history.xlsx Monthly_FFill 'Nebius | H100 SXM 80GB | on-demand | PAYG' 2024-04 | H5: no snapshot this month; carried forward from last observation (market-team forward-fill)
A6: Prices_Monthly | B6: F4 | C6: Nebius H100 SXM on-demand | D6: 2024-05 | E6: 4.85 | F6: Reported | G6: /workspace/nebius/market/gpu_price_history.xlsx Price_History_Monthly 'Nebius | H100 SXM 80GB | on-demand | PAYG' 2024-05 (snapshot rows in Price_History_Long; nebius.com/prices via web.archive.org)
A7: Prices_Monthly | B7: G4 | C7: Nebius H100 SXM on-demand | D7: 2024-06 | E7: 4.85 | F7: Estimated | G7: /workspace/nebius/market/gpu_price_history.xlsx Monthly_FFill 'Nebius | H100 SXM 80GB | on-demand | PAYG' 2024-06 | H7: no snapshot this month; carried forward from last observation (market-team forward-fill)
A8: Prices_Monthly | B8: H4 | C8: Nebius H100 SXM on-demand | D8: 2024-07 | E8: 4.85 | F8: Reported | G8: /workspace/nebius/market/gpu_price_history.xlsx Price_History_Monthly 'Nebius | H100 SXM 80GB | on-demand | PAYG' 2024-07 (snapshot rows in Price_History_Long; nebius.com/prices via web.archive.org)
A9: Prices_Monthly | B9: I4 | C9: Nebius H100 SXM on-demand | D9: 2024-08 | E9: 4.85 | F9: Reported | G9: /workspace/nebius/market/gpu_price_history.xlsx Price_History_Monthly 'Nebius | H100 SXM 80GB | on-demand | PAYG' 2024-08 (snapshot rows in Price_History_Long; nebius.com/prices via web.archive.org)
A10: Prices_Monthly | B10: J4 | C10: Nebius H100 SXM on-demand | D10: 2024-09 | E10: 3.5 | F10: Reported | G10: /workspace/nebius/market/gpu_price_history.xlsx Price_History_Monthly 'Nebius | H100 SXM 80GB | on-demand | PAYG' 2024-09 (snapshot rows in Price_History_Long; nebius.com/prices via web.archive.org)
A11: Prices_Monthly | B11: K4 | C11: Nebius H100 SXM on-demand | D11: 2024-10 | E11: 3.5 | F11: Reported | G11: /workspace/nebius/market/gpu_price_history.xlsx Price_History_Monthly 'Nebius | H100 SXM 80GB | on-demand | PAYG' 2024-10 (snapshot rows in Price_History_Long; nebius.com/prices via web.archive.org)
A12: Prices_Monthly | B12: L4 | C12: Nebius H100 SXM on-demand | D12: 2024-11 | E12: 2.95 | F12: Reported | G12: /workspace/nebius/market/gpu_price_history.xlsx Price_History_Monthly 'Nebius | H100 SXM 80GB | on-demand | PAYG' 2024-11 (snapshot rows in Price_History_Long; nebius.com/prices via web.archive.org)
A13: Prices_Monthly | B13: M4 | C13: Nebius H100 SXM on-demand | D13: 2024-12 | E13: 2.95 | F13: Reported | G13: /workspace/nebius/market/gpu_price_history.xlsx Price_History_Monthly 'Nebius | H100 SXM 80GB | on-demand | PAYG' 2024-12 (snapshot rows in Price_History_Long; nebius.com/prices via web.archive.org)
A14: Prices_Monthly | B14: N4 | C14: Nebius H100 SXM on-demand | D14: 2025-01 | E14: 2.95 | F14: Reported | G14: /workspace/nebius/market/gpu_price_history.xlsx Price_History_Monthly 'Nebius | H100 SXM 80GB | on-demand | PAYG' 2025-01 (snapshot rows in Price_History_Long; nebius.com/prices via web.archive.org)
A15: Prices_Monthly | B15: O4 | C15: Nebius H100 SXM on-demand | D15: 2025-02 | E15: 2.95 | F15: Estimated | G15: /workspace/nebius/market/gpu_price_history.xlsx Monthly_FFill 'Nebius | H100 SXM 80GB | on-demand | PAYG' 2025-02 | H15: no snapshot this month; carried forward from last observation (market-team forward-fill)
A16: Prices_Monthly | B16: P4 | C16: Nebius H100 SXM on-demand | D16: 2025-03 | E16: 2.95 | F16: Reported | G16: /workspace/nebius/market/gpu_price_history.xlsx Price_History_Monthly 'Nebius | H100 SXM 80GB | on-demand | PAYG' 2025-03 (snapshot rows in Price_History_Long; nebius.com/prices via web.archive.org)
A17: Prices_Monthly | B17: Q4 | C17: Nebius H100 SXM on-demand | D17: 2025-04 | E17: 2.95 | F17: Reported | G17: /workspace/nebius/market/gpu_price_history.xlsx Price_History_Monthly 'Nebius | H100 SXM 80GB | on-demand | PAYG' 2025-04 (snapshot rows in Price_History_Long; nebius.com/prices via web.archive.org)
A18: Prices_Monthly | B18: R4 | C18: Nebius H100 SXM on-demand | D18: 2025-05 | E18: 2.95 | F18: Reported | G18: /workspace/nebius/market/gpu_price_history.xlsx Price_History_Monthly 'Nebius | H100 SXM 80GB | on-demand | PAYG' 2025-05 (snapshot rows in Price_History_Long; nebius.com/prices via web.archive.org)
A19: Prices_Monthly | B19: S4 | C19: Nebius H100 SXM on-demand | D19: 2025-06 | E19: 2.95 | F19: Reported | G19: /workspace/nebius/market/gpu_price_history.xlsx Price_History_Monthly 'Nebius | H100 SXM 80GB | on-demand | PAYG' 2025-06 (snapshot rows in Price_History_Long; nebius.com/prices via web.archive.org)
A20: Prices_Monthly | B20: T4 | C20: Nebius H100 SXM on-demand | D20: 2025-07 | E20: 2.95 | F20: Reported | G20: /workspace/nebius/market/gpu_price_history.xlsx Price_History_Monthly 'Nebius | H100 SXM 80GB | on-demand | PAYG' 2025-07 (snapshot rows in Price_History_Long; nebius.com/prices via web.archive.org)
A21: Prices_Monthly | B21: U4 | C21: Nebius H100 SXM on-demand | D21: 2025-08 | E21: 2.95 | F21: Reported | G21: /workspace/nebius/market/gpu_price_history.xlsx Price_History_Monthly 'Nebius | H100 SXM 80GB | on-demand | PAYG' 2025-08 (snapshot rows in Price_History_Long; nebius.com/prices via web.archive.org)
A22: Prices_Monthly | B22: V4 | C22: Nebius H100 SXM on-demand | D22: 2025-09 | E22: 2.95 | F22: Reported | G22: /workspace/nebius/market/gpu_price_history.xlsx Price_History_Monthly 'Nebius | H100 SXM 80GB | on-demand | PAYG' 2025-09 (snapshot rows in Price_History_Long; nebius.com/prices via web.archive.org)
A23: Prices_Monthly | B23: W4 | C23: Nebius H100 SXM on-demand | D23: 2025-10 | E23: 2.95 | F23: Reported | G23: /workspace/nebius/market/gpu_price_history.xlsx Price_History_Monthly 'Nebius | H100 SXM 80GB | on-demand | PAYG' 2025-10 (snapshot rows in Price_History_Long; nebius.com/prices via web.archive.org)
A24: Prices_Monthly | B24: X4 | C24: Nebius H100 SXM on-demand | D24: 2025-11 | E24: 2.95 | F24: Reported | G24: /workspace/nebius/market/gpu_price_history.xlsx Price_History_Monthly 'Nebius | H100 SXM 80GB | on-demand | PAYG' 2025-11 (snapshot rows in Price_History_Long; nebius.com/prices via web.archive.org)
A25: Prices_Monthly | B25: Y4 | C25: Nebius H100 SXM on-demand | D25: 2025-12 | E25: 2.95 | F25: Reported | G25: /workspace/nebius/market/gpu_price_history.xlsx Price_History_Monthly 'Nebius | H100 SXM 80GB | on-demand | PAYG' 2025-12 (snapshot rows in Price_History_Long; nebius.com/prices via web.archive.org)
A26: Prices_Monthly | B26: Z4 | C26: Nebius H100 SXM on-demand | D26: 2026-01 | E26: 2.95 | F26: Reported | G26: /workspace/nebius/market/gpu_price_history.xlsx Price_History_Monthly 'Nebius | H100 SXM 80GB | on-demand | PAYG' 2026-01 (snapshot rows in Price_History_Long; nebius.com/prices via web.archive.org)
A27: Prices_Monthly | B27: AA4 | C27: Nebius H100 SXM on-demand | D27: 2026-02 | E27: 2.95 | F27: Reported | G27: /workspace/nebius/market/gpu_price_history.xlsx Price_History_Monthly 'Nebius | H100 SXM 80GB | on-demand | PAYG' 2026-02 (snapshot rows in Price_History_Long; nebius.com/prices via web.archive.org)
... A31: Prices_Monthly | B31: AE4 | C31: Nebius H100 SXM on-demand | D31: 2026-06 | E31: 3.85 | F31: Reported | G31: /workspace/nebius/market/gpu_price_history.xlsx Price_History_Monthly 'Nebius | H100 SXM 80GB | on-demand | PAYG' 2026-06 (snapshot rows in Price_History_Long; nebius.com/prices via web.archive.org)
A32: Prices_Monthly | B32: B5 | C32: Nebius H200 on-demand | D32: 2024-01 | E32: n.d. | F32: not disclosed | G32: /workspace/nebius/market/gpu_price_history.xlsx (no observation) | H32: SKU not listed / no snapshot
A33: Prices_Monthly | B33: C5 | C33: Nebius H200 on-demand | D33: 2024-02 | E33: n.d. | F33: not disclosed | G33: /workspace/nebius/market/gpu_price_history.xlsx (no observation) | H33: SKU not listed / no snapshot
A34: Prices_Monthly | B34: D5 | C34: Nebius H200 on-demand | D34: 2024-03 | E34: n.d. | F34: not disclosed | G34: /workspace/nebius/market/gpu_price_history.xlsx (no observation) | H34: SKU not listed / no snapshot
A35: Prices_Monthly | B35: E5 | C35: Nebius H200 on-demand | D35: 2024-04 | E35: n.d. | F35: not disclosed | G35: /workspace/nebius/market/gpu_price_history.xlsx (no observation) | H35: SKU not listed / no snapshot
A36: Prices_Monthly | B36: F5 | C36: Nebius H200 on-demand | D36: 2024-05 | E36: n.d. | F36: not disclosed | G36: /workspace/nebius/market/gpu_price_history.xlsx (no observation) | H36: SKU not listed / no snapshot
A37: Prices_Monthly | B37: G5 | C37: Nebius H200 on-demand | D37: 2024-06 | E37: n.d. | F37: not disclosed | G37: /workspace/nebius/market/gpu_price_history.xlsx (no observation) | H37: SKU not listed / no snapshot
A38: Prices_Monthly | B38: H5 | C38: Nebius H200 on-demand | D38: 2024-07 | E38: n.d. | F38: not disclosed | G38: /workspace/nebius/market/gpu_price_history.xlsx (no observation) | H38: SKU not listed / no snapshot
A39: Prices_Monthly | B39: I5 | C39: Nebius H200 on-demand | D39: 2024-08 | E39: n.d. | F39: not disclosed | G39: /workspace/nebius/market/gpu_price_history.xlsx (no observation) | H39: SKU not listed / no snapshot
A40: Prices_Monthly | B40: J5 | C40: Nebius H200 on-demand | D40: 2024-09 | E40: n.d. | F40: not disclosed | G40: /workspace/nebius/market/gpu_price_history.xlsx (no observation) | H40: SKU not listed / no snapshot
A41: Prices_Monthly | B41: K5 | C41: Nebius H200 on-demand | D41: 2024-10 | E41: 4.85 | F41: Reported | G41: /workspace/nebius/market/gpu_price_history.xlsx Price_History_Monthly 'Nebius | H200 141GB | on-demand | PAYG' 2024-10 (snapshot rows in Price_History_Long; nebius.com/prices via web.archive.org)
A42: Prices_Monthly | B42: L5 | C42: Nebius H200 on-demand | D42: 2024-11 | E42: 3.5 | F42: Reported | G42: /workspace/nebius/market/gpu_price_history.xlsx Price_History_Monthly 'Nebius | H200 141GB | on-demand | PAYG' 2024-11 (snapshot rows in Price_History_Long; nebius.com/prices via web.archive.org)
A43: Prices_Monthly | B43: M5 | C43: Nebius H200 on-demand | D43: 2024-12 | E43: 3.5 | F43: Reported | G43: /workspace/nebius/market/gpu_price_history.xlsx Price_History_Monthly 'Nebius | H200 141GB | on-demand | PAYG' 2024-12 (snapshot rows in Price_History_Long; nebius.com/prices via web.archive.org)
...
